Workbook

Sheet README
A1: RBL Bank — Book Growth Analysis (BBRL liabilities): page-wise metric extraction
A2: Source: 01_Book_Growth_Analysis.pdf (1 page, 2 data blocks) | ₹ Cr | MEB = month-end balance, MAB = monthly average balance
A3: ⚠ DRAFT ONLY — Requires review and approval by a qualified Alvarez and Marsal professional before use.
A5: Sheet map
A6: B1_MEB_Periods | B6: Block 1 — MEB by product × customer segment for CM, LY, LM, LQ, with printed growth tables and sign checks
A7: B1_Metrics | B7: Notation + exhaustive metrics for Block 1
A8: B2_Balance_Movement | B8: Block 2 — Balance Movement: MAB by segment × product across CD, PD, CM, LM, LY, LYCM and the < ₹3 Cr / Individual < ₹3 Cr sub-books
A9: B2_Metrics | B9: Notation + exhaustive metrics for Block 2
A11: Colour legend
A12: Blue text | B12: Hard-coded input transcribed from the PDF
A13: Blue italic on grey | B13: Budget / projected value (ᴾ) transcribed from the PDF
A14: Black text | B14: Formula on the same sheet
A15: Green text | B15: Link to another sheet
A16: Yellow fill | B16: Data flag to review
A18: Key assumptions (confirm with client)
A19: 1 | B19: Printed growth % and 'Growth in Allocated Segment' are signed in the PDF (e.g. MASS CA CM vs LY = −49.12%) and tie to recomputed values. 'Growth in Allocated Segment' is the change in segment share, in pp, not a growth rate.
A20: 2 | B20: Filter context: BBB Flag = BBRL, all other filters = All. Report header was not captured; title taken from file name.
A21: 3 | B21: '< 3 Cr' and '< 3 Ind Cr' columns are the sub-book of customers below ₹3 Cr and of individual customers below ₹3 Cr (as printed: 'CM < 3 Cr*'). The < 3 Cr book grew only +8.5% YoY while the ≥ ₹3 Cr remainder grew +114% — growth is large-ticket.
A22: 4 | B22: CD / PD read as current-day / previous-day MAB; CM = current month; LM = last month; LQ = last quarter-end month; LY = last year; LYCM = last-year current-month basis. CM vs LM and CM vs LY diffs on the MAB page tie to LM* and LY* here.
A23: 5 | B23: Cross-page: Balance Movement CD* / CM* grand total (115,448.64) equals the MAB page grand total; Block-1 CM MEB grand total (113,109.81) is a different measure (MEB).
A24: Confidentiality | B24: Client-confidential RBL Bank data.
A26: ⚠ DRAFT ONLY — Requires review and approval by a qualified Alvarez and Marsal professional before use.

Sheet B1_MEB_Periods
A1: Block 1 — MEB by product × customer segment (CM, LY, LM, LQ)
A2: Source: Book Growth Analysis.pdf | ₹ Cr | month-end balances; all actuals | shares recomputed
A3: ⚠ DRAFT ONLY — Requires review and approval by a qualified Alvarez and Marsal professional before use.
A5: CM MEB
A6: # | B6: Product | C6: INSIGNIA | D6: SIGNATURE | E6: ASPIRE | F6: MASS | G6: Printed total | H6: Σ segments | I6: Gap | J6: Share INSIGNIA | K6: Share SIGNATURE | L6: Share ASPIRE | M6: Share MASS | N6: Product share of GT
A7: 1 | B7: CA | C7: 3849.97 | D7: 438.94 | E7: 515.22 | F7: 1393.38 | G7: 6197.51 | H7: =SUM(C7:F7) -> 6197.51 | I7: =G7-H7 -> 0 | J7: =C7/$G7 -> 0.62121239 | K7: =D7/$G7 -> 0.070825219 | L7: =E7/$G7 -> 0.083133387 | M7: =F7/$G7 -> 0.224829 | N7: =G7/$G$11 -> 0.054791976
A8: 2 | B8: SA | C8: 11257.45 | D8: 3129.55 | E8: 1601 | F8: 3434.88 | G8: 19422.88 | H8: =SUM(C8:F8) -> 19422.88 | I8: =G8-H8 -> 0 | J8: =C8/$G8 -> 0.57959736 | K8: =D8/$G8 -> 0.16112698 | L8: =E8/$G8 -> 0.082428558 | M8: =F8/$G8 -> 0.1768471 | N8: =G8/$G$11 -> 0.17171702
A9: 3 | B9: Deposits | C9: 52910.64 | D9: 7509.46 | E9: 6510.42 | F9: 20542.05 | G9: 87472.57 | H9: =SUM(C9:F9) -> 87472.57 | I9: =G9-H9 -> 0 | J9: =C9/$G9 -> 0.60488265 | K9: =D9/$G9 -> 0.085849313 | L9: =E9/$G9 -> 0.074428132 | M9: =F9/$G9 -> 0.2348399 | N9: =G9/$G$11 -> 0.77334203
A10: 4 | B10: ODFD | C10: 8.78 | D10: 3.34 | E10: 1.51 | F10: 3.22 | G10: 16.84 | H10: =SUM(C10:F10) -> 16.85 | I10: =G10-H10 -> -0.01 | J10: =C10/$G10 -> 0.52137767 | K10: =D10/$G10 -> 0.19833729 | L10: =E10/$G10 -> 0.089667458 | M10: =F10/$G10 -> 0.1912114 | N10: =G10/$G$11 -> 0.00014888187
A11: 5 | B11: Grand Total (printed) | C11: 68026.83 | D11: 11081.29 | E11: 8628.16 | F11: 25373.53 | G11: 113109.81 | H11: =SUM(C11:F11) -> 113109.81 | I11: =G11-H11 -> 0 | J11: =C11/$G11 -> 0.6014229 | K11: =D11/$G11 -> 0.09796931 | L11: =E11/$G11 -> 0.07628127 | M11: =F11/$G11 -> 0.22432652 | N11: =G11/$G$11 -> 1
B12: Σ products (computed) | C12: =SUM(C7:C10) -> 68026.84 | D12: =SUM(D7:D10) -> 11081.29 | E12: =SUM(E7:E10) -> 8628.15 | F12: =SUM(F7:F10) -> 25373.53 | G12: =SUM(G7:G10) -> 113109.8 | H12: =SUM(C12:F12) -> 113109.81
B13: Gap: printed GT − Σ products | C13: =C11-C12 -> -0.01 | D13: =D11-D12 -> 0 | E13: =E11-E12 -> 0.01 | F13: =F11-F12 -> 0 | G13: =G11-G12 -> 0.01
A14: LY MEB
A15: # | B15: Product | C15: INSIGNIA | D15: SIGNATURE | E15: ASPIRE | F15: MASS | G15: Printed total | H15: Σ segments | I15: Gap | J15: Share INSIGNIA | K15: Share SIGNATURE | L15: Share ASPIRE | M15: Share MASS | N15: Product share of GT
A16: 1 | B16: CA | C16: 4906.99 | D16: 551.97 | E16: 645.42 | F16: 2738.8 | G16: 8843.18 | H16: =SUM(C16:F16) -> 8843.18 | I16: =G16-H16 -> 0 | J16: =C16/$G16 -> 0.55488976 | K16: =D16/$G16 -> 0.062417592 | L16: =E16/$G16 -> 0.072985057 | M16: =F16/$G16 -> 0.30970759 | N16: =G16/$G$20 -> 0.10072599
A17: 2 | B17: SA | C17: 11203.79 | D17: 3115.25 | E17: 1566.72 | F17: 3717.23 | G17: 19602.98 | H17: =SUM(C17:F17) -> 19602.99 | I17: =G17-H17 -> -0.01 | J17: =C17/$G17 -> 0.57153504 | K17: =D17/$G17 -> 0.15891716 | L17: =E17/$G17 -> 0.079922542 | M17: =F17/$G17 -> 0.18962576 | N17: =G17/$G$20 -> 0.22328276
A18: 3 | B18: Deposits | C18: 24996.33 | D18: 6013.38 | E18: 5541.37 | F18: 22778.25 | G18: 59329.33 | H18: =SUM(C18:F18) -> 59329.33 | I18: =G18-H18 -> 0 | J18: =C18/$G18 -> 0.42131489 | K18: =D18/$G18 -> 0.10135594 | L18: =E18/$G18 -> 0.093400178 | M18: =F18/$G18 -> 0.38392899 | N18: =G18/$G$20 -> 0.67577564
A19: 4 | B19: ODFD | C19: 9 | D19: 4.74 | E19: 1.64 | F19: 3.54 | G19: 18.92 | H19: =SUM(C19:F19) -> 18.92 | I19: =G19-H19 -> 0 | J19: =C19/$G19 -> 0.4756871 | K19: =D19/$G19 -> 0.25052854 | L19: =E19/$G19 -> 0.086680761 | M19: =F19/$G19 -> 0.18710359 | N19: =G19/$G$20 -> 0.00021550345
A20: 5 | B20: Grand Total (printed) | C20: 41116.12 | D20: 9685.33 | E20: 7755.15 | F20: 29237.82 | G20: 87794.42 | H20: =SUM(C20:F20) -> 87794.42 | I20: =G20-H20 -> 0 | J20: =C20/$G20 -> 0.4683227 | K20: =D20/$G20 -> 0.11031829 | L20: =E20/$G20 -> 0.088333063 | M20: =F20/$G20 -> 0.33302595 | N20: =G20/$G$20 -> 1
B21: Σ products (computed) | C21: =SUM(C16:C19) -> 41116.11 | D21: =SUM(D16:D19) -> 9685.34 | E21: =SUM(E16:E19) -> 7755.15 | F21: =SUM(F16:F19) -> 29237.82 | G21: =SUM(G16:G19) -> 87794.41 | H21: =SUM(C21:F21) -> 87794.42
B22: Gap: printed GT − Σ products | C22: =C20-C21 -> 0.01 | D22: =D20-D21 -> -0.01 | E22: =E20-E21 -> 0 | F22: =F20-F21 -> 0 | G22: =G20-G21 -> 0.01
A23: LM MEB
A24: # | B24: Product | C24: INSIGNIA | D24: SIGNATURE | E24: ASPIRE | F24: MASS | G24: Printed total | H24: Σ segments | I24: Gap | J24: Share INSIGNIA | K24: Share SIGNATURE | L24: Share ASPIRE | M24: Share MASS | N24: Product share of GT
A25: 1 | B25: CA | C25: 3774.25 | D25: 491.11 | E25: 534.41 | F25: 1638.21 | G25: 6437.98 | H25: =SUM(C25:F25) -> 6437.98 | I25: =G25-H25 -> 0 | J25: =C25/$G25 -> 0.58624755 | K25: =D25/$G25 -> 0.076283244 | L25: =E25/$G25 -> 0.083008956 | M25: =F25/$G25 -> 0.25446025 | N25: =G25/$G$29 -> 0.068930303
A26: 2 | B26: SA | C26: 11110.84 | D26: 3152.62 | E26: 1582.89 | F26: 3424.5 | G26: 19270.85 | H26: =SUM(C26:F26) -> 19270.85 | I26: =G26-H26 -> 0 | J26: =C26/$G26 -> 0.57656201 | K26: =D26/$G26 -> 0.16359527 | L26: =E26/$G26 -> 0.082139086 | M26: =F26/$G26 -> 0.17770363 | N26: =G26/$G$29 -> 0.20632955
A27: 3 | B27: Deposits | C27: 33926.56 | D27: 6675.19 | E27: 5916 | F27: 21149.29 | G27: 67667.04 | H27: =SUM(C27:F27) -> 67667.04 | I27: =G27-H27 -> 0 | J27: =C27/$G27 -> 0.50137497 | K27: =D27/$G27 -> 0.098647584 | L27: =E27/$G27 -> 0.087428089 | M27: =F27/$G27 -> 0.31254936 | N27: =G27/$G$29 -> 0.72449892
A28: 4 | B28: ODFD | C28: 12.81 | D28: 3.45 | E28: 2.71 | F28: 3.56 | G28: 22.52 | H28: =SUM(C28:F28) -> 22.53 | I28: =G28-H28 -> -0.01 | J28: =C28/$G28 -> 0.56882771 | K28: =D28/$G28 -> 0.15319716 | L28: =E28/$G28 -> 0.12033748 | M28: =F28/$G28 -> 0.15808171 | N28: =G28/$G$29 -> 0.00024111762
A29: 5 | B29: Grand Total (printed) | C29: 48824.46 | D29: 10322.37 | E29: 8036.01 | F29: 26215.56 | G29: 93398.4 | H29: =SUM(C29:F29) -> 93398.4 | I29: =G29-H29 -> 0 | J29: =C29/$G29 -> 0.52275478 | K29: =D29/$G29 -> 0.11051977 | L29: =E29/$G29 -> 0.086040125 | M29: =F29/$G29 -> 0.28068532 | N29: =G29/$G$29 -> 1
B30: Σ products (computed) | C30: =SUM(C25:C28) -> 48824.46 | D30: =SUM(D25:D28) -> 10322.37 | E30: =SUM(E25:E28) -> 8036.01 | F30: =SUM(F25:F28) -> 26215.56 | G30: =SUM(G25:G28) -> 93398.39 | H30: =SUM(C30:F30) -> 93398.4
B31: Gap: printed GT − Σ products | C31: =C29-C30 -> 0 | D31: =D29-D30 -> 0 | E31: =E29-E30 -> 0 | F31: =F29-F30 -> 0 | G31: =G29-G30 -> 0.01
A32: LQ MEB
A33: # | B33: Product | C33: INSIGNIA | D33: SIGNATURE | E33: ASPIRE | F33: MASS | G33: Printed total | H33: Σ segments | I33: Gap | J33: Share INSIGNIA | K33: Share SIGNATURE | L33: Share ASPIRE | M33: Share MASS | N33: Product share of GT
A34: 1 | B34: CA | C34: 3879.65 | D34: 462.67 | E34: 563.06 | F34: 2036.22 | G34: 6941.6 | H34: =SUM(C34:F34) -> 6941.6 | I34: =G34-H34 -> 0 | J34: =C34/$G34 -> 0.55889852 | K34: =D34/$G34 -> 0.066651781 | L34: =E34/$G34 -> 0.081113864 | M34: =F34/$G34 -> 0.29333583 | N34: =G34/$G$38 -> 0.080470171
A35: 2 | B35: SA | C35: 11051.02 | D35: 3122.71 | E35: 1621.02 | F35: 3334.89 | G35: 19129.64 | H35: =SUM(C35:F35) -> 19129.64 | I35: =G35-H35 -> 0 | J35: =C35/$G35 -> 0.57769095 | K35: =D35/$G35 -> 0.16323935 | L35: =E35/$G35 -> 0.084738657 | M35: =F35/$G35 -> 0.17433104 | N35: =G35/$G$38 -> 0.22175945
A36: 3 | B36: Deposits | C36: 26052.53 | D36: 6330.66 | E36: 5724.89 | F36: 22061.57 | G36: 60169.66 | H36: =SUM(C36:F36) -> 60169.65 | I36: =G36-H36 -> 0.01 | J36: =C36/$G36 -> 0.4329845 | K36: =D36/$G36 -> 0.10521349 | L36: =E36/$G36 -> 0.095145793 | M36: =F36/$G36 -> 0.36665605 | N36: =G36/$G$38 -> 0.69751395
A37: 4 | B37: ODFD | C37: 13.73 | D37: 3.46 | E37: 1.45 | F37: 3.48 | G37: 22.12 | H37: =SUM(C37:F37) -> 22.12 | I37: =G37-H37 -> 0 | J37: =C37/$G37 -> 0.62070524 | K37: =D37/$G37 -> 0.15641953 | L37: =E37/$G37 -> 0.065551537 | M37: =F37/$G37 -> 0.15732369 | N37: =G37/$G$38 -> 0.00025642506
A38: 5 | B38: Grand Total (printed) | C38: 40996.93 | D38: 9919.5 | E38: 7910.42 | F38: 27436.17 | G38: 86263.02 | H38: =SUM(C38:F38) -> 86263.02 | I38: =G38-H38 -> 0 | J38: =C38/$G38 -> 0.47525498 | K38: =D38/$G38 -> 0.11499134 | L38: =E38/$G38 -> 0.091701172 | M38: =F38/$G38 -> 0.31805251 | N38: =G38/$G$38 -> 1
B39: Σ products (computed) | C39: =SUM(C34:C37) -> 40996.93 | D39: =SUM(D34:D37) -> 9919.5 | E39: =SUM(E34:E37) -> 7910.42 | F39: =SUM(F34:F37) -> 27436.16 | G39: =SUM(G34:G37) -> 86263.02 | H39: =SUM(C39:F39) -> 86263.01
B40: Gap: printed GT − Σ products | C40: =C38-C39 -> 0 | D40: =D38-D39 -> 0 | E40: =E38-E39 -> 0 | F40: =F38-F39 -> 0.01 | G40: =G38-G39 -> 0
A42: CM vs LY: computed growth and share shift vs printed (signed as printed)
...

Sheet B1_Metrics
A1: Block 1 — MEB by product × segment: notation and metrics
A2: Format: Notation → Exhaustive metrics table | Example column = live Excel formula on the block sheet (green = cross-sheet)
A3: ⚠ DRAFT ONLY — Requires review and approval by a qualified Alvarez and Marsal professional before use.
A5: Notation
B6: Symbol | C6: Meaning
B7: MEB | C7: Month-end balance, ₹ Cr
B8: B(p, s, t) | C8: MEB of product p (CA, SA, Deposits, ODFD) in segment s (INSIGNIA, SIGNATURE, ASPIRE, MASS) at period t
B9: t | C9: CM = current month; LM = last month; LQ = last quarter-end month; LY = same month last year
B10: T(p,t) / T(s,t) | C10: Product total across segments / segment total across products
B11: GT(t) | C11: Grand Total MEB
B12: sh(s|p,t) | C12: Segment share within product = B(p,s,t) ÷ T(p,t)
B13: g(x) | C13: Growth = x(CM) ÷ x(t) − 1
B14: Δsh | C14: Share shift in pp = (sh(CM) − sh(t)) × 100 — this is what the page calls 'Growth in Allocated Segment'
B15: CASA | C15: CA + SA
B16: ± | C16: Printed values are signed; computed values are compared sign-for-sign
B17: Values are ₹ Cr month-end balances; growth in %, share shifts in pp; all periods actual.
A19: Exhaustive metrics table
A20: # | B20: Metric family | C20: Pipeline-ready metric | D20: Definition / formula | E20: Applies to | F20: Example
A21: 1 | B21: Fact lookup | C21: Product × segment MEB | D21: B(p,s,t) | E21: 4 products × 4 segments × 4 periods (64 cells) | F21: ="Deposits INSIGNIA CM / LM / LQ / LY "&TEXT(B1_MEB_Periods!C9,"#,##0.00;-#,##0.00;0.00")&" / "&TEXT(B1_MEB_Periods!C27,"#,##0.00;-#,##0.00;0.00")&" / "&TEXT(B1_MEB_Periods!C36,"#,##0.00;-#,##0.00;0.00")&" / "&TEXT(B1_MEB_Periods!C18,"#,##0.00;-#,##0.00;0.00") -> Deposits INSIGNIA CM / LM / LQ / LY 52,910.64 / 33,926.56 / 26,052.53 / 24,996.33
A22: 2 | B22: Fact lookup | C22: Product totals | D22: T(p,t) as printed | E22: 4 × 4 | F22: ="CM: CA "&TEXT(B1_MEB_Periods!G7,"#,##0.00;-#,##0.00;0.00")&"; SA "&TEXT(B1_MEB_Periods!G8,"#,##0.00;-#,##0.00;0.00")&"; Deposits "&TEXT(B1_MEB_Periods!G9,"#,##0.00;-#,##0.00;0.00")&"; ODFD "&TEXT(B1_MEB_Periods!G10,"#,##0.00;-#,##0.00;0.00") -> CM: CA 6,197.51; SA 19,422.88; Deposits 87,472.57; ODFD 16.84
A23: 3 | B23: Fact lookup | C23: Segment totals | D23: T(s,t) as printed | E23: 4 × 4 | F23: ="CM: "&TEXT(B1_MEB_Periods!C11,"#,##0.00;-#,##0.00;0.00")&" / "&TEXT(B1_MEB_Periods!D11,"#,##0.00;-#,##0.00;0.00")&" / "&TEXT(B1_MEB_Periods!E11,"#,##0.00;-#,##0.00;0.00")&" / "&TEXT(B1_MEB_Periods!F11,"#,##0.00;-#,##0.00;0.00") -> CM: 68,026.83 / 11,081.29 / 8,628.16 / 25,373.53
A24: 4 | B24: Fact lookup | C24: Grand Total | D24: GT(t) | E24: 4 periods | F24: ="CM / LM / LQ / LY "&TEXT(B1_MEB_Periods!G11,"#,##0.00;-#,##0.00;0.00")&" / "&TEXT(B1_MEB_Periods!G29,"#,##0.00;-#,##0.00;0.00")&" / "&TEXT(B1_MEB_Periods!G38,"#,##0.00;-#,##0.00;0.00")&" / "&TEXT(B1_MEB_Periods!G20,"#,##0.00;-#,##0.00;0.00") -> CM / LM / LQ / LY 113,109.81 / 93,398.40 / 86,263.02 / 87,794.42
A25: 5 | B25: Roll-up check | C25: Products to Grand Total | D25: GT(t) − Σp T(p,t) | E25: 4 periods × 5 columns | F25: ="CM "&TEXT(B1_MEB_Periods!C13,"#,##0.00;-#,##0.00;0.00")&" / "&TEXT(B1_MEB_Periods!D13,"#,##0.00;-#,##0.00;0.00")&" / "&TEXT(B1_MEB_Periods!E13,"#,##0.00;-#,##0.00;0.00")&" / "&TEXT(B1_MEB_Periods!F13,"#,##0.00;-#,##0.00;0.00")&" / "&TEXT(B1_MEB_Periods!G13,"#,##0.00;-#,##0.00;0.00") -> CM -0.01 / 0.00 / 0.01 / 0.00 / 0.01
A26: 6 | B26: Roll-up check | C26: Segments to product total | D26: T(p,t) − Σs B(p,s,t) | E26: 20 rows | F26: ="CM "&TEXT(B1_MEB_Periods!I7,"#,##0.00;-#,##0.00;0.00")&" / "&TEXT(B1_MEB_Periods!I8,"#,##0.00;-#,##0.00;0.00")&" / "&TEXT(B1_MEB_Periods!I9,"#,##0.00;-#,##0.00;0.00")&" / "&TEXT(B1_MEB_Periods!I10,"#,##0.00;-#,##0.00;0.00")&" / "&TEXT(B1_MEB_Periods!I11,"#,##0.00;-#,##0.00;0.00") -> CM 0.00 / 0.00 / 0.00 / -0.01 / 0.00
A27: 7 | B27: Mix & share | C27: Segment share within product | D27: sh(s|p,CM) | E27: 4 products + GT × 4 segments × 4 periods | F27: ="Deposits CM "&TEXT(B1_MEB_Periods!J9,"0.0%")&" / "&TEXT(B1_MEB_Periods!K9,"0.0%")&" / "&TEXT(B1_MEB_Periods!L9,"0.0%")&" / "&TEXT(B1_MEB_Periods!M9,"0.0%")&"; LY "&TEXT(B1_MEB_Periods!J18,"0.0%")&" / "&TEXT(B1_MEB_Periods!K18,"0.0%")&" / "&TEXT(B1_MEB_Periods!L18,"0.0%")&" / "&TEXT(B1_MEB_Periods!M18,"0.0%") -> Deposits CM 60.5% / 8.6% / 7.4% / 23.5%; LY 42.1% / 10.1% / 9.3% / 38.4%
A28: 8 | B28: Mix & share | C28: Segment share of Grand Total | D28: T(s,CM) ÷ GT(CM) | E28: 4 segments × 4 periods | F28: ="CM "&TEXT(B1_MEB_Periods!J11,"0.0%")&" / "&TEXT(B1_MEB_Periods!K11,"0.0%")&" / "&TEXT(B1_MEB_Periods!L11,"0.0%")&" / "&TEXT(B1_MEB_Periods!M11,"0.0%")&"; LY "&TEXT(B1_MEB_Periods!J20,"0.0%")&" / "&TEXT(B1_MEB_Periods!K20,"0.0%")&" / "&TEXT(B1_MEB_Periods!L20,"0.0%")&" / "&TEXT(B1_MEB_Periods!M20,"0.0%") -> CM 60.1% / 9.8% / 7.6% / 22.4%; LY 46.8% / 11.0% / 8.8% / 33.3%
A29: 9 | B29: Mix & share | C29: Product share of Grand Total | D29: T(p,t) ÷ GT(t) | E29: 4 products × 4 periods | F29: ="CM "&TEXT(B1_MEB_Periods!N7,"0.0%")&" / "&TEXT(B1_MEB_Periods!N8,"0.0%")&" / "&TEXT(B1_MEB_Periods!N9,"0.0%")&" / "&TEXT(B1_MEB_Periods!N10,"0.0%")&" (CA / SA / Dep / ODFD)" -> CM 5.5% / 17.2% / 77.3% / 0.0% (CA / SA / Dep / ODFD)
A30: 10 | B30: Mix & share | C30: CASA share of book | D30: (T(CA) + T(SA)) ÷ GT | E30: 4 periods | F30: ="CM "&TEXT((B1_MEB_Periods!G7+B1_MEB_Periods!G8)/B1_MEB_Periods!G11,"0.0%")&"; LM "&TEXT((B1_MEB_Periods!G25+B1_MEB_Periods!G26)/B1_MEB_Periods!G29,"0.0%")&"; LY "&TEXT((B1_MEB_Periods!G16+B1_MEB_Periods!G17)/B1_MEB_Periods!G20,"0.0%") -> CM 22.7%; LM 27.5%; LY 32.4%
A31: 11 | B31: Mix & share | C31: Share shift ('Growth in Allocated Segment') | D31: Δsh = (sh(CM) − sh(t)) × 100 | E31: 5 rows × 4 segments × 3 comparisons | F31: ="vs LY, GT row: "&TEXT(B1_MEB_Periods!H48,"+0.0"" pp"";-0.0"" pp"";0.0"" pp""")&" / "&TEXT(B1_MEB_Periods!I48,"+0.0"" pp"";-0.0"" pp"";0.0"" pp""")&" / "&TEXT(B1_MEB_Periods!J48,"+0.0"" pp"";-0.0"" pp"";0.0"" pp""")&" / "&TEXT(B1_MEB_Periods!K48,"+0.0"" pp"";-0.0"" pp"";0.0"" pp""")&"; vs LM "&TEXT(B1_MEB_Periods!H56,"+0.0"" pp"";-0.0"" pp"";0.0"" pp""")&" / "&TEXT(B1_MEB_Periods!I56,"+0.0"" pp"";-0.0"" pp"";0.0"" pp""")&" / "&TEXT(B1_MEB_Periods!J56,"+0.0"" pp"";-0.0"" pp"";0.0"" pp""")&" / "&TEXT(B1_MEB_Periods!K56,"+0.0"" pp"";-0.0"" pp"";0.0"" pp""") -> vs LY, GT row: +13.3 pp / -1.2 pp / -1.2 pp / -10.9 pp; vs LM +7.9 pp / -1.3 pp / -1.0 pp / -5.6 pp
A32: 12 | B32: Growth & momentum | C32: YoY growth by segment × product | D32: g = B(CM) ÷ B(LY) − 1 | E32: 5 × 5 cells | F32: ="CA "&TEXT(B1_MEB_Periods!C44,"+0.0%;-0.0%;0.0%")&" / "&TEXT(B1_MEB_Periods!D44,"+0.0%;-0.0%;0.0%")&" / "&TEXT(B1_MEB_Periods!E44,"+0.0%;-0.0%;0.0%")&" / "&TEXT(B1_MEB_Periods!F44,"+0.0%;-0.0%;0.0%")&" / "&TEXT(B1_MEB_Periods!G44,"+0.0%;-0.0%;0.0%")&"; Deposits "&TEXT(B1_MEB_Periods!C46,"+0.0%;-0.0%;0.0%")&" / "&TEXT(B1_MEB_Periods!D46,"+0.0%;-0.0%;0.0%")&" / "&TEXT(B1_MEB_Periods!E46,"+0.0%;-0.0%;0.0%")&" / "&TEXT(B1_MEB_Periods!F46,"+0.0%;-0.0%;0.0%")&" / "&TEXT(B1_MEB_Periods!G46,"+0.0%;-0.0%;0.0%") -> CA -21.5% / -20.5% / -20.2% / -49.1% / -29.9%; Deposits +111.7% / +24.9% / +17.5% / -9.8% / +47.4%
A33: 13 | B33: Growth & momentum | C33: YoY growth — totals | D33: g(T(s)) and g(GT) | E33: 4 segments + GT | F33: =TEXT(B1_MEB_Periods!C48,"+0.0%;-0.0%;0.0%")&" / "&TEXT(B1_MEB_Periods!D48,"+0.0%;-0.0%;0.0%")&" / "&TEXT(B1_MEB_Periods!E48,"+0.0%;-0.0%;0.0%")&" / "&TEXT(B1_MEB_Periods!F48,"+0.0%;-0.0%;0.0%")&" / "&TEXT(B1_MEB_Periods!G48,"+0.0%;-0.0%;0.0%") -> +65.5% / +14.4% / +11.3% / -13.2% / +28.8%
A34: 14 | B34: Growth & momentum | C34: MoM growth | D34: g = B(CM) ÷ B(LM) − 1 | E34: 5 × 5 | F34: ="GT row "&TEXT(B1_MEB_Periods!C56,"+0.0%;-0.0%;0.0%")&" / "&TEXT(B1_MEB_Periods!D56,"+0.0%;-0.0%;0.0%")&" / "&TEXT(B1_MEB_Periods!E56,"+0.0%;-0.0%;0.0%")&" / "&TEXT(B1_MEB_Periods!F56,"+0.0%;-0.0%;0.0%")&" / "&TEXT(B1_MEB_Periods!G56,"+0.0%;-0.0%;0.0%")&"; Deposits "&TEXT(B1_MEB_Periods!C54,"+0.0%;-0.0%;0.0%")&" / "&TEXT(B1_MEB_Periods!D54,"+0.0%;-0.0%;0.0%")&" / "&TEXT(B1_MEB_Periods!E54,"+0.0%;-0.0%;0.0%")&" / "&TEXT(B1_MEB_Periods!F54,"+0.0%;-0.0%;0.0%")&" / "&TEXT(B1_MEB_Periods!G54,"+0.0%;-0.0%;0.0%") -> GT row +39.3% / +7.4% / +7.4% / -3.2% / +21.1%; Deposits +56.0% / +12.5% / +10.0% / -2.9% / +29.3%
A35: 15 | B35: Growth & momentum | C35: QoQ growth | D35: g = B(CM) ÷ B(LQ) − 1 | E35: 5 × 5 | F35: ="GT row "&TEXT(B1_MEB_Periods!C64,"+0.0%;-0.0%;0.0%")&" / "&TEXT(B1_MEB_Periods!D64,"+0.0%;-0.0%;0.0%")&" / "&TEXT(B1_MEB_Periods!E64,"+0.0%;-0.0%;0.0%")&" / "&TEXT(B1_MEB_Periods!F64,"+0.0%;-0.0%;0.0%")&" / "&TEXT(B1_MEB_Periods!G64,"+0.0%;-0.0%;0.0%")&"; CA "&TEXT(B1_MEB_Periods!C60,"+0.0%;-0.0%;0.0%")&" / "&TEXT(B1_MEB_Periods!D60,"+0.0%;-0.0%;0.0%")&" / "&TEXT(B1_MEB_Periods!E60,"+0.0%;-0.0%;0.0%")&" / "&TEXT(B1_MEB_Periods!F60,"+0.0%;-0.0%;0.0%")&" / "&TEXT(B1_MEB_Periods!G60,"+0.0%;-0.0%;0.0%") -> GT row +65.9% / +11.7% / +9.1% / -7.5% / +31.1%; CA -0.8% / -5.1% / -8.5% / -31.6% / -10.7%
A36: 16 | B36: Growth & momentum | C36: YoY growth ex deposits (CASA + ODFD) | D36: (GT − T(Dep))(CM) ÷ (GT − T(Dep))(LY) − 1 | E36: Window | F36: =TEXT((B1_MEB_Periods!G11-B1_MEB_Periods!G9)/(B1_MEB_Periods!G20-B1_MEB_Periods!G18)-1,"+0.0%;-0.0%;0.0%") -> -9.9%
A37: 17 | B37: Growth & momentum | C37: YoY growth ex INSIGNIA | D37: (GT − T(INSIGNIA))(CM) ÷ same (LY) − 1 | E37: Window | F37: =TEXT((B1_MEB_Periods!G11-B1_MEB_Periods!C11)/(B1_MEB_Periods!G20-B1_MEB_Periods!C20)-1,"+0.0%;-0.0%;0.0%") -> -3.4%
A38: 18 | B38: Growth & momentum | C38: Absolute change | D38: B(CM) − B(t) | E38: 5 × 5 × 3 | F38: ="YoY: INSIGNIA Dep "&TEXT(B1_MEB_Periods!C9-B1_MEB_Periods!C18,"#,##0.00;-#,##0.00;0.00")&"; MASS Dep "&TEXT(B1_MEB_Periods!F9-B1_MEB_Periods!F18,"#,##0.00;-#,##0.00;0.00")&"; GT "&TEXT(B1_MEB_Periods!G11-B1_MEB_Periods!G20,"#,##0.00;-#,##0.00;0.00") -> YoY: INSIGNIA Dep 27,914.31; MASS Dep -2,236.20; GT 25,315.39
A39: 19 | B39: Attribution | C39: Contribution to YoY growth | D39: ΔB(p,s) ÷ ΔGT | E39: 16 cells + totals | F39: ="INSIGNIA Dep "&TEXT((B1_MEB_Periods!C9-B1_MEB_Periods!C18)/(B1_MEB_Periods!G11-B1_MEB_Periods!G20),"0.0%")&"; MASS Dep "&TEXT((B1_MEB_Periods!F9-B1_MEB_Periods!F18)/(B1_MEB_Periods!G11-B1_MEB_Periods!G20),"0.0%")&"; CA total "&TEXT((B1_MEB_Periods!G7-B1_MEB_Periods!G16)/(B1_MEB_Periods!G11-B1_MEB_Periods!G20),"0.0%") -> INSIGNIA Dep 110.3%; MASS Dep -8.8%; CA total -10.5%
A40: 20 | B40: Attribution | C40: Contribution to MoM growth | D40: ΔB(p,s) ÷ ΔGT (LM basis) | E40: 16 cells | F40: ="INSIGNIA Dep "&TEXT((B1_MEB_Periods!C9-B1_MEB_Periods!C27)/(B1_MEB_Periods!G11-B1_MEB_Periods!G29),"0.0%")&"; MASS Dep "&TEXT((B1_MEB_Periods!F9-B1_MEB_Periods!F27)/(B1_MEB_Periods!G11-B1_MEB_Periods!G29),"0.0%") -> INSIGNIA Dep 96.3%; MASS Dep -3.1%
A41: 21 | B41: Concentration | C41: INSIGNIA share of deposits | D41: B(Dep, INSIGNIA) ÷ T(Dep) | E41: 4 periods | F41: ="LY / LQ / LM / CM "&TEXT(B1_MEB_Periods!J18,"0.0%")&" / "&TEXT(B1_MEB_Periods!J36,"0.0%")&" / "&TEXT(B1_MEB_Periods!J27,"0.0%")&" / "&TEXT(B1_MEB_Periods!J9,"0.0%") -> LY / LQ / LM / CM 42.1% / 43.3% / 50.1% / 60.5%
A42: 22 | B42: Concentration | C42: HHI of segment mix | D42: Σ (100 × sh(s|GT))² | E42: 4 periods | F42: ="LY / CM "&TEXT(SUMPRODUCT((B1_MEB_Periods!C20:F20/B1_MEB_Periods!G20)^2)*10000,"#,##0")&" / "&TEXT(SUMPRODUCT((B1_MEB_Periods!C11:F11/B1_MEB_Periods!G11)^2)*10000,"#,##0") -> LY / CM 3,502 / 4,274
...

Sheet B2_Balance_Movement
A1: Block 2 — Balance Movement (MAB) by segment × product
A2: Source: Book Growth Analysis.pdf, 'Balance Movement' (R/Z/C/B MEB/MAB toggle = MAB) | ₹ Cr
A3: ⚠ DRAFT ONLY — Requires review and approval by a qualified Alvarez and Marsal professional before use.
A5: A. Source data (blue) with line-level live calculations
A6: # | B6: Segment | C6: Product | D6: CD* | E6: CD < 3 Cr* | F6: CD < 3 Ind Cr* | G6: PD* | H6: PD < 3 Cr* | I6: PD < 3 Ind Cr* | J6: CM* | K6: CM < 3 Cr* | L6: CM < 3 Ind Cr* | M6: LM* | N6: LM < 3 Cr* | O6: LM < 3 Ind Cr* | P6: LY* | Q6: LY < 3 Cr* | R6: LY < 3 Ind Cr* | S6: LYCM* | T6: LYCM < 3 Cr* | U6: LYCM < 3 Ind Cr* | V6: < 3 Cr share of CM | W6: < 3 Ind Cr share of CM | X6: CM vs LM growth | Y6: CM vs LY growth | Z6: CM vs LYCM growth | AA6: CD − PD (daily Δ) | AB6: CM MAB ÷ CM MEB (Block 1) | AC6: Share of CM grand total
A7: 1 | B7: INSIGNIA | C7: CA | D7: 3632 | E7: 1993 | F7: 165 | G7: 3623 | H7: 1992 | I7: 164 | J7: 3632.2 | K7: 1993.14 | L7: 164.65 | M7: 3654.79 | N7: 2007 | O7: 166.48 | P7: 3771.85 | Q7: 2005.68 | R7: 168.68 | S7: 3520.74 | T7: 1820.98 | U7: 152.38 | V7: =K7/J7 -> 0.54874181 | W7: =L7/J7 -> 0.045330654 | X7: =J7/M7-1 -> -0.0061809297 | Y7: =J7/P7-1 -> -0.037024272 | Z7: =J7/S7-1 -> 0.031658117 | AA7: =D7-G7 -> 9 | AB7: =J7/B1_MEB_Periods!C7 -> 0.94343592 | AC7: =J7/$J$27 -> 0.031461609
A8: 2 | B8: INSIGNIA | C8: SA | D8: 11292 | E8: 8238 | F8: 7636 | G8: 11277 | H8: 8224 | I8: 7623 | J8: 11292.23 | K8: 8237.78 | L8: 7636.22 | M8: 11009.63 | N8: 8255.49 | O8: 7660.36 | P8: 10755.15 | Q8: 8328.96 | R8: 7737.18 | S8: 10769.1 | T8: 8986.49 | U8: 8276.84 | V8: =K8/J8 -> 0.7295087 | W8: =L8/J8 -> 0.67623667 | X8: =J8/M8-1 -> 0.025668438 | Y8: =J8/P8-1 -> 0.049937007 | Z8: =J8/S8-1 -> 0.048576947 | AA8: =D8-G8 -> 15 | AB8: =J8/B1_MEB_Periods!C8 -> 1.0030895 | AC8: =J8/$J$27 -> 0.09781172
A9: 3 | B9: INSIGNIA | C9: Deposits | D9: 53834 | E9: 25134 | F9: 17074 | G9: 53779 | H9: 25067 | I9: 17004 | J9: 53834.13 | K9: 25133.69 | L9: 17073.96 | M9: 34820.85 | N9: 24584.69 | O9: 16922.51 | P9: 24851.69 | Q9: 22642.5 | R9: 15771.57 | S9: 21769.31 | T9: 20035.28 | U9: 14567.77 | V9: =K9/J9 -> 0.46687278 | W9: =L9/J9 -> 0.31715865 | X9: =J9/M9-1 -> 0.54603147 | Y9: =J9/P9-1 -> 1.1662161 | Z9: =J9/S9-1 -> 1.4729369 | AA9: =D9-G9 -> 55 | AB9: =J9/B1_MEB_Periods!C9 -> 1.0174538 | AC9: =J9/$J$27 -> 0.46630372
A10: 4 | B10: INSIGNIA | C10: ODFD | D10: 11 | E10: 11 | F10: 4 | G10: 12 | H10: 12 | I10: 4 | J10: 10.93 | K10: 10.93 | L10: 3.63 | M10: 12.92 | N10: 9.84 | O10: 3.22 | P10: 14.31 | Q10: 14.31 | R10: 2.71 | S10: 5.1 | T10: 5.1 | U10: 3.59 | V10: =K10/J10 -> 1 | W10: =L10/J10 -> 0.33211345 | X10: =J10/M10-1 -> -0.15402477 | Y10: =J10/P10-1 -> -0.23619846 | Z10: =J10/S10-1 -> 1.1431373 | AA10: =D10-G10 -> -1 | AB10: =J10/B1_MEB_Periods!C10 -> 1.2448747 | AC10: =J10/$J$27 -> 9.4674134e-05
A11: 5 | B11: SIGNATURE | C11: CA | D11: 464 | E11: 405 | F11: 22 | G11: 465 | H11: 405 | I11: 22 | J11: 464.43 | K11: 404.88 | L11: 22.31 | M11: 448.61 | N11: 407.99 | O11: 23.14 | P11: 451.09 | Q11: 414.86 | R11: 21.05 | S11: 403.49 | T11: 377.86 | U11: 19.1 | V11: =K11/J11 -> 0.87177831 | W11: =L11/J11 -> 0.048037379 | X11: =J11/M11-1 -> 0.035264484 | Y11: =J11/P11-1 -> 0.029572813 | Z11: =J11/S11-1 -> 0.15103224 | AA11: =D11-G11 -> -1 | AB11: =J11/B1_MEB_Periods!D7 -> 1.0580717 | AC11: =J11/$J$27 -> 0.0040228278
A12: 6 | B12: SIGNATURE | C12: SA | D12: 3163 | E12: 2821 | F12: 2634 | G12: 3158 | H12: 2816 | I12: 2630 | J12: 3162.61 | K12: 2820.83 | L12: 2634.12 | M12: 3131.39 | N12: 2840.13 | O12: 2648.78 | P12: 2975.19 | Q12: 2750.52 | R12: 2555.06 | S12: 2889.62 | T12: 2766.81 | U12: 2554.14 | V12: =K12/J12 -> 0.89193103 | W12: =L12/J12 -> 0.83289435 | X12: =J12/M12-1 -> 0.0099700133 | Y12: =J12/P12-1 -> 0.062994296 | Z12: =J12/S12-1 -> 0.09447263 | AA12: =D12-G12 -> 5 | AB12: =J12/B1_MEB_Periods!D8 -> 1.0105638 | AC12: =J12/$J$27 -> 0.027394086
A13: 7 | B13: SIGNATURE | C13: Deposits | D13: 7691 | E13: 6488 | F13: 5165 | G13: 7685 | H13: 6479 | I13: 5156 | J13: 7691.48 | K13: 6488.34 | L13: 5164.5 | M13: 6971.53 | N13: 6415.62 | O13: 5117.17 | P13: 5987.47 | Q13: 5815.5 | R13: 4671.18 | S13: 5563.27 | T13: 5436.99 | U13: 4478.53 | V13: =K13/J13 -> 0.84357497 | W13: =L13/J13 -> 0.67145725 | X13: =J13/M13-1 -> 0.10327001 | Y13: =J13/P13-1 -> 0.284596 | Z13: =J13/S13-1 -> 0.3825466 | AA13: =D13-G13 -> 6 | AB13: =J13/B1_MEB_Periods!D9 -> 1.0242388 | AC13: =J13/$J$27 -> 0.066622526
A14: 8 | B14: SIGNATURE | C14: ODFD | D14: 3 | E14: 3 | F14: 1 | G14: 3 | H14: 3 | I14: 1 | J14: 3.39 | K14: 3.39 | L14: 1.34 | M14: 3.54 | N14: 3.54 | O14: 1.42 | P14: 4.75 | Q14: 4.75 | R14: 2.01 | S14: 1.8 | T14: 1.8 | U14: 1.57 | V14: =K14/J14 -> 1 | W14: =L14/J14 -> 0.39528024 | X14: =J14/M14-1 -> -0.042372881 | Y14: =J14/P14-1 -> -0.28631579 | Z14: =J14/S14-1 -> 0.88333333 | AA14: =D14-G14 -> 0 | AB14: =J14/B1_MEB_Periods!D10 -> 1.0149701 | AC14: =J14/$J$27 -> 2.9363707e-05
A15: 9 | B15: ASPIRE | C15: CA | D15: 512 | E15: 487 | F15: 25 | G15: 512 | H15: 483 | I15: 25 | J15: 512.41 | K15: 486.51 | L15: 24.9 | M15: 519.02 | N15: 492.3 | O15: 25.79 | P15: 519.49 | Q15: 501.14 | R15: 22.5 | S15: 492.75 | T15: 452.15 | U15: 25.58 | V15: =K15/J15 -> 0.94945454 | W15: =L15/J15 -> 0.048593899 | X15: =J15/M15-1 -> -0.01273554 | Y15: =J15/P15-1 -> -0.013628751 | Z15: =J15/S15-1 -> 0.039898529 | AA15: =D15-G15 -> 0 | AB15: =J15/B1_MEB_Periods!E7 -> 0.99454602 | AC15: =J15/$J$27 -> 0.0044384239
A16: 10 | B16: ASPIRE | C16: SA | D16: 1601 | E16: 1459 | F16: 1358 | G16: 1597 | H16: 1458 | I16: 1357 | J16: 1600.8 | K16: 1459.24 | L16: 1357.7 | M16: 1571.98 | N16: 1438.74 | O16: 1340.47 | P16: 1489.31 | Q16: 1406.7 | R16: 1308.01 | S16: 1397.93 | T16: 1331.13 | U16: 1238.57 | V16: =K16/J16 -> 0.91156922 | W16: =L16/J16 -> 0.84813843 | X16: =J16/M16-1 -> 0.018333567 | Y16: =J16/P16-1 -> 0.07486017 | Z16: =J16/S16-1 -> 0.14512172 | AA16: =D16-G16 -> 4 | AB16: =J16/B1_MEB_Periods!E8 -> 0.99987508 | AC16: =J16/$J$27 -> 0.013865906
A17: 11 | B17: ASPIRE | C17: Deposits | D17: 6650 | E17: 5238 | F17: 4198 | G17: 6644 | H17: 5232 | I17: 4193 | J17: 6649.5 | K17: 5238.19 | L17: 4198.4 | M17: 6048.97 | N17: 5222.25 | O17: 4195.7 | P17: 5465.44 | Q17: 4833.6 | R17: 3976.14 | S17: 4964.08 | T17: 4556.55 | U17: 3827.28 | V17: =K17/J17 -> 0.78775697 | W17: =L17/J17 -> 0.63138582 | X17: =J17/M17-1 -> 0.099278059 | Y17: =J17/P17-1 -> 0.21664495 | Z17: =J17/S17-1 -> 0.33952313 | AA17: =D17-G17 -> 6 | AB17: =J17/B1_MEB_Periods!E9 -> 1.0213627 | AC17: =J17/$J$27 -> 0.057597041
A18: 12 | B18: ASPIRE | C18: ODFD | D18: 2 | E18: 2 | F18: 1 | G18: 2 | H18: 2 | I18: 1 | J18: 1.57 | K18: 1.57 | L18: 0.85 | M18: 2.12 | N18: 2.12 | O18: 0.8 | P18: 2.07 | Q18: 2.07 | R18: 1.29 | S18: 0.96 | T18: 0.96 | U18: 0.67 | V18: =K18/J18 -> 1 | W18: =L18/J18 -> 0.54140127 | X18: =J18/M18-1 -> -0.25943396 | Y18: =J18/P18-1 -> -0.24154589 | Z18: =J18/S18-1 -> 0.63541667 | AA18: =D18-G18 -> 0 | AB18: =J18/B1_MEB_Periods!E10 -> 1.0397351 | AC18: =J18/$J$27 -> 1.3599121e-05
A19: 13 | B19: MASS | C19: CA | D19: 1430 | E19: 949 | F19: 38 | G19: 1429 | H19: 946 | I19: 38 | J19: 1429.87 | K19: 949.08 | L19: 37.56 | M19: 1488.67 | N19: 928.15 | O19: 36.43 | P19: 1517.97 | Q19: 912.73 | R19: 30.39 | S19: 1018.29 | T19: 754.52 | U19: 28.11 | V19: =K19/J19 -> 0.66375265 | W19: =L19/J19 -> 0.026268122 | X19: =J19/M19-1 -> -0.039498344 | Y19: =J19/P19-1 -> -0.058038038 | Z19: =J19/S19-1 -> 0.40418741 | AA19: =D19-G19 -> 1 | AB19: =J19/B1_MEB_Periods!F7 -> 1.0261881 | AC19: =J19/$J$27 -> 0.012385334
A20: 14 | B20: MASS | C20: SA | D20: 3425 | E20: 2873 | F20: 2673 | G20: 3420 | H20: 2869 | I20: 2669 | J20: 3424.93 | K20: 2873.5 | L20: 2672.71 | M20: 3310.68 | N20: 2779.41 | O20: 2576.04 | P20: 3585.5 | Q20: 2632.36 | R20: 2430.85 | S20: 2760.59 | T20: 2248.48 | U20: 2070.45 | V20: =K20/J20 -> 0.83899525 | W20: =L20/J20 -> 0.78036923 | X20: =J20/M20-1 -> 0.034509527 | Y20: =J20/P20-1 -> -0.044783154 | Z20: =J20/S20-1 -> 0.24065145 | AA20: =D20-G20 -> 5 | AB20: =J20/B1_MEB_Periods!F8 -> 0.99710325 | AC20: =J20/$J$27 -> 0.029666265
A21: 15 | B21: MASS | C21: Deposits | D21: 21726 | E21: 7994 | F21: 3431 | G21: 21745 | H21: 7983 | I21: 3422 | J21: 21726.17 | K21: 7994.29 | L21: 3430.71 | M21: 21873.22 | N21: 7730.07 | O21: 3287.99 | P21: 21698.96 | Q21: 6791.36 | R21: 2802.95 | S21: 17832.35 | T21: 5330.82 | U21: 2456.2 | V21: =K21/J21 -> 0.36795671 | W21: =L21/J21 -> 0.1579068 | X21: =J21/M21-1 -> -0.0067228328 | Y21: =J21/P21-1 -> 0.0012539771 | Z21: =J21/S21-1 -> 0.21835709 | AA21: =D21-G21 -> -19 | AB21: =J21/B1_MEB_Periods!F9 -> 1.0576437 | AC21: =J21/$J$27 -> 0.18818905
A22: 16 | B22: MASS | C22: ODFD | D22: 12 | E22: 8 | F22: 3 | G22: 12 | H22: 8 | I22: 3 | J22: 11.98 | K22: 8.27 | L22: 2.91 | M22: 12.86 | N22: 3.93 | O22: 2.95 | P22: 8.7 | Q22: 8.7 | R22: 3.07 | S22: 7 | T22: 7 | U22: 2.99 | V22: =K22/J22 -> 0.6903172 | W22: =L22/J22 -> 0.24290484 | X22: =J22/M22-1 -> -0.068429238 | Y22: =J22/P22-1 -> 0.37701149 | Z22: =J22/S22-1 -> 0.71142857 | AA22: =D22-G22 -> 0 | AB22: =J22/B1_MEB_Periods!F10 -> 3.7204969 | AC22: =J22/$J$27 -> 0.00010376909
B24: Σ all lines (computed) | D24: =SUM(D7:D22) -> 115448 | E24: =SUM(E7:E22) -> 64103 | F24: =SUM(F7:F22) -> 44428 | G24: =SUM(G7:G22) -> 115363 | H24: =SUM(H7:H22) -> 63979 | I24: =SUM(I7:I22) -> 44312 | J24: =SUM(J7:J22) -> 115448.63 | K24: =SUM(K7:K22) -> 64103.63 | ... U24: =SUM(U7:U22) -> 39703.77
B25: Grand Total (printed) | D25: 115449 | E25: 64104 | F25: 44426 | G25: 115364 | H25: 63980 | I25: 44312 | J25: 115448.64 | K25: 64103.64 | L25: 44426.48 | M25: 94880.79 | N25: 63121.29 | O25: 44009.26 | P25: 83098.91 | Q25: 59065.73 | R25: 41504.63 | S25: 73396.38 | T25: 54112.92 | U25: 39703.76 | V25: =K25/J25 -> 0.55525678 | W25: =L25/J25 -> 0.38481597 | X25: =J25/M25-1 -> 0.2167757 | Y25: =J25/P25-1 -> 0.38929187 | Z25: =J25/S25-1 -> 0.57294733 | AA25: =D25-G25 -> 85
B26: Gap printed − computed | D26: =D25-D24 -> 1 | E26: =E25-E24 -> 1 | F26: =F25-F24 -> -2 | G26: =G25-G24 -> 1 | H26: =H25-H24 -> 1 | I26: =I25-I24 -> 0 | J26: =J25-J24 -> 0.01 | K26: =K25-K24 -> 0.01 | ... U26: =U25-U24 -> -0.01
B27: Grand Total used for shares | D27: =D25 -> 115449 | E27: =E25 -> 64104 | F27: =F25 -> 44426 | G27: =G25 -> 115364 | H27: =H25 -> 63980 | I27: =I25 -> 44312 | J27: =J25 -> 115448.64 | K27: =K25 -> 64103.64 | ... U27: =U25 -> 39703.76
A29: B. Roll-ups by segment and by product (SUMIFS)
A30: # | B30: Level | C30: Item | D30: CD* | E30: CD < 3 Cr* | F30: CD < 3 Ind Cr* | G30: PD* | H30: PD < 3 Cr* | I30: PD < 3 Ind Cr* | J30: CM* | K30: CM < 3 Cr* | L30: CM < 3 Ind Cr* | M30: LM* | N30: LM < 3 Cr* | O30: LM < 3 Ind Cr* | P30: LY* | Q30: LY < 3 Cr* | R30: LY < 3 Ind Cr* | S30: LYCM* | T30: LYCM < 3 Cr* | U30: LYCM < 3 Ind Cr* | V30: < 3 Cr share of CM | W30: < 3 Ind Cr share of CM | X30: CM vs LM growth | Y30: CM vs LY growth | Z30: CM vs LYCM growth | AA30: CD − PD | AC30: Share of CM grand total
A31: 1 | B31: Segment | C31: INSIGNIA | D31: =SUMIFS(D$7:D$22,$B$7:$B$22,$C31) -> 68769 | E31: =SUMIFS(E$7:E$22,$B$7:$B$22,$C31) -> 35376 | F31: =SUMIFS(F$7:F$22,$B$7:$B$22,$C31) -> 24879 | G31: =SUMIFS(G$7:G$22,$B$7:$B$22,$C31) -> 68691 | H31: =SUMIFS(H$7:H$22,$B$7:$B$22,$C31) -> 35295 | I31: =SUMIFS(I$7:I$22,$B$7:$B$22,$C31) -> 24795 | J31: =SUMIFS(J$7:J$22,$B$7:$B$22,$C31) -> 68769.49 | K31: =SUMIFS(K$7:K$22,$B$7:$B$22,$C31) -> 35375.54 | ... U31: =SUMIFS(U$7:U$22,$B$7:$B$22,$C31) -> 23000.58 | V31: =K31/J31 -> 0.51440748 | W31: =L31/J31 -> 0.36176595 | X31: =J31/M31-1 -> 0.38933343 | Y31: =J31/P31-1 -> 0.74572868 | Z31: =J31/S31-1 -> 0.90686039 | AA31: =D31-G31 -> 78 | AC31: =J31/$J$27 -> 0.59567172
A32: 2 | B32: Segment | C32: SIGNATURE | D32: =SUMIFS(D$7:D$22,$B$7:$B$22,$C32) -> 11321 | E32: =SUMIFS(E$7:E$22,$B$7:$B$22,$C32) -> 9717 | F32: =SUMIFS(F$7:F$22,$B$7:$B$22,$C32) -> 7822 | G32: =SUMIFS(G$7:G$22,$B$7:$B$22,$C32) -> 11311 | H32: =SUMIFS(H$7:H$22,$B$7:$B$22,$C32) -> 9703 | I32: =SUMIFS(I$7:I$22,$B$7:$B$22,$C32) -> 7809 | J32: =SUMIFS(J$7:J$22,$B$7:$B$22,$C32) -> 11321.91 | K32: =SUMIFS(K$7:K$22,$B$7:$B$22,$C32) -> 9717.44 | ... U32: =SUMIFS(U$7:U$22,$B$7:$B$22,$C32) -> 7053.34 | V32: =K32/J32 -> 0.85828628 | W32: =L32/J32 -> 0.69089668 | X32: =J32/M32-1 -> 0.072651342 | Y32: =J32/P32-1 -> 0.20209269 | Z32: =J32/S32-1 -> 0.2781305 | AA32: =D32-G32 -> 10 | AC32: =J32/$J$27 -> 0.098068804
A33: 3 | B33: Segment | C33: ASPIRE | D33: =SUMIFS(D$7:D$22,$B$7:$B$22,$C33) -> 8765 | E33: =SUMIFS(E$7:E$22,$B$7:$B$22,$C33) -> 7186 | F33: =SUMIFS(F$7:F$22,$B$7:$B$22,$C33) -> 5582 | G33: =SUMIFS(G$7:G$22,$B$7:$B$22,$C33) -> 8755 | H33: =SUMIFS(H$7:H$22,$B$7:$B$22,$C33) -> 7175 | I33: =SUMIFS(I$7:I$22,$B$7:$B$22,$C33) -> 5576 | J33: =SUMIFS(J$7:J$22,$B$7:$B$22,$C33) -> 8764.28 | K33: =SUMIFS(K$7:K$22,$B$7:$B$22,$C33) -> 7185.51 | ... U33: =SUMIFS(U$7:U$22,$B$7:$B$22,$C33) -> 5092.1 | V33: =K33/J33 -> 0.81986313 | W33: =L33/J33 -> 0.63688632 | X33: =J33/M33-1 -> 0.076416497 | Y33: =J33/P33-1 -> 0.17227349 | Z33: =J33/S33-1 -> 0.27838943 | AA33: =D33-G33 -> 10 | AC33: =J33/$J$27 -> 0.07591497
A34: 4 | B34: Segment | C34: MASS | D34: =SUMIFS(D$7:D$22,$B$7:$B$22,$C34) -> 26593 | E34: =SUMIFS(E$7:E$22,$B$7:$B$22,$C34) -> 11824 | F34: =SUMIFS(F$7:F$22,$B$7:$B$22,$C34) -> 6145 | G34: =SUMIFS(G$7:G$22,$B$7:$B$22,$C34) -> 26606 | H34: =SUMIFS(H$7:H$22,$B$7:$B$22,$C34) -> 11806 | I34: =SUMIFS(I$7:I$22,$B$7:$B$22,$C34) -> 6132 | J34: =SUMIFS(J$7:J$22,$B$7:$B$22,$C34) -> 26592.95 | K34: =SUMIFS(K$7:K$22,$B$7:$B$22,$C34) -> 11825.14 | ... U34: =SUMIFS(U$7:U$22,$B$7:$B$22,$C34) -> 4557.75 | V34: =K34/J34 -> 0.44467199 | W34: =L34/J34 -> 0.23103454 | X34: =J34/M34-1 -> -0.0034655615 | Y34: =J34/P34-1 -> -0.0081376652 | Z34: =J34/S34-1 -> 0.2301169 | AA34: =D34-G34 -> -13 | AC34: =J34/$J$27 -> 0.23034442
A35: 5 | B35: Product | C35: CA | D35: =SUMIFS(D$7:D$22,$C$7:$C$22,$C35) -> 6038 | E35: =SUMIFS(E$7:E$22,$C$7:$C$22,$C35) -> 3834 | F35: =SUMIFS(F$7:F$22,$C$7:$C$22,$C35) -> 250 | G35: =SUMIFS(G$7:G$22,$C$7:$C$22,$C35) -> 6029 | H35: =SUMIFS(H$7:H$22,$C$7:$C$22,$C35) -> 3826 | I35: =SUMIFS(I$7:I$22,$C$7:$C$22,$C35) -> 249 | J35: =SUMIFS(J$7:J$22,$C$7:$C$22,$C35) -> 6038.91 | K35: =SUMIFS(K$7:K$22,$C$7:$C$22,$C35) -> 3833.61 | ... U35: =SUMIFS(U$7:U$22,$C$7:$C$22,$C35) -> 225.17 | V35: =K35/J35 -> 0.6348182 | W35: =L35/J35 -> 0.041302156 | X35: =J35/M35-1 -> -0.011811314 | Y35: =J35/P35-1 -> -0.035379528 | Z35: =J35/S35-1 -> 0.1110598 | AA35: =D35-G35 -> 9 | AC35: =J35/$J$27 -> 0.052308195
A36: 6 | B36: Product | C36: SA | D36: =SUMIFS(D$7:D$22,$C$7:$C$22,$C36) -> 19481 | E36: =SUMIFS(E$7:E$22,$C$7:$C$22,$C36) -> 15391 | F36: =SUMIFS(F$7:F$22,$C$7:$C$22,$C36) -> 14301 | G36: =SUMIFS(G$7:G$22,$C$7:$C$22,$C36) -> 19452 | H36: =SUMIFS(H$7:H$22,$C$7:$C$22,$C36) -> 15367 | I36: =SUMIFS(I$7:I$22,$C$7:$C$22,$C36) -> 14279 | J36: =SUMIFS(J$7:J$22,$C$7:$C$22,$C36) -> 19480.57 | K36: =SUMIFS(K$7:K$22,$C$7:$C$22,$C36) -> 15391.35 | ... U36: =SUMIFS(U$7:U$22,$C$7:$C$22,$C36) -> 14140 | V36: =K36/J36 -> 0.79008725 | W36: =L36/J36 -> 0.73410326 | X36: =J36/M36-1 -> 0.024016909 | Y36: =J36/P36-1 -> 0.035916757 | Z36: =J36/S36-1 -> 0.093355088 | AA36: =D36-G36 -> 29 | AC36: =J36/$J$27 -> 0.16873798
A37: 7 | B37: Product | C37: Deposits | D37: =SUMIFS(D$7:D$22,$C$7:$C$22,$C37) -> 89901 | E37: =SUMIFS(E$7:E$22,$C$7:$C$22,$C37) -> 44854 | F37: =SUMIFS(F$7:F$22,$C$7:$C$22,$C37) -> 29868 | G37: =SUMIFS(G$7:G$22,$C$7:$C$22,$C37) -> 89853 | H37: =SUMIFS(H$7:H$22,$C$7:$C$22,$C37) -> 44761 | I37: =SUMIFS(I$7:I$22,$C$7:$C$22,$C37) -> 29775 | J37: =SUMIFS(J$7:J$22,$C$7:$C$22,$C37) -> 89901.28 | K37: =SUMIFS(K$7:K$22,$C$7:$C$22,$C37) -> 44854.51 | ... U37: =SUMIFS(U$7:U$22,$C$7:$C$22,$C37) -> 25329.78 | V37: =K37/J37 -> 0.49893072 | W37: =L37/J37 -> 0.3322263 | X37: =J37/M37-1 -> 0.28956228 | Y37: =J37/P37-1 -> 0.54992694 | Z37: =J37/S37-1 -> 0.79339827 | AA37: =D37-G37 -> 48 | AC37: =J37/$J$27 -> 0.77871233
A38: 8 | B38: Product | C38: ODFD | D38: =SUMIFS(D$7:D$22,$C$7:$C$22,$C38) -> 28 | E38: =SUMIFS(E$7:E$22,$C$7:$C$22,$C38) -> 24 | F38: =SUMIFS(F$7:F$22,$C$7:$C$22,$C38) -> 9 | G38: =SUMIFS(G$7:G$22,$C$7:$C$22,$C38) -> 29 | H38: =SUMIFS(H$7:H$22,$C$7:$C$22,$C38) -> 25 | I38: =SUMIFS(I$7:I$22,$C$7:$C$22,$C38) -> 9 | J38: =SUMIFS(J$7:J$22,$C$7:$C$22,$C38) -> 27.87 | K38: =SUMIFS(K$7:K$22,$C$7:$C$22,$C38) -> 24.16 | ... U38: =SUMIFS(U$7:U$22,$C$7:$C$22,$C38) -> 8.82 | V38: =K38/J38 -> 0.86688195 | W38: =L38/J38 -> 0.31324004 | X38: =J38/M38-1 -> -0.11354962 | Y38: =J38/P38-1 -> -0.065705665 | Z38: =J38/S38-1 -> 0.87550471 | AA38: =D38-G38 -> -1 | AC38: =J38/$J$27 -> 0.00024140605
A41: Data points to flag before metrics (live checks)
A42: # | B42: Flag | C42: Check value (live) | D42: Unit | E42: Implication / action
A43: 1 | B43: Printed Grand Total vs Σ lines — max absolute gap across the 18 columns: | C43: =MAX(ABS(MIN(D26:U26)),MAX(D26:U26)) -> 2 | D43: ₹ Cr | E43: Rounding (CD/PD columns are printed to whole ₹ Cr).
A44: 2 | B44: CM* grand total equals the MAB page grand total (115,448.64) and CM vs LM / CM vs LY diffs there equal CM − LM* and CM − LY* here. | C44: =J25-M25 -> 20567.85 | D44: ₹ Cr | E44: Confirms LM* / LY* are the comparison bases used on the MAB page.
A45: 3 | B45: Customers below ₹3 Cr hold only about half of CM MAB; < 3 Cr share of CM MAB: | C45: =V25 -> 0.55525678 | D45: % | E45: The ≥ ₹3 Cr book (large / institutional) drives growth.
...

Sheet B2_Metrics
A1: Block 2 — Balance Movement (MAB): notation and metrics
A2: Format: Notation → Exhaustive metrics table | Example column = live Excel formula on the block sheet (green = cross-sheet)
A3: ⚠ DRAFT ONLY — Requires review and approval by a qualified Alvarez and Marsal professional before use.
A5: Notation
B6: Symbol | C6: Meaning
B7: MAB | C7: Monthly average balance, ₹ Cr
B8: M(s,p,v) | C8: MAB of segment s, product p for view v
B9: v | C9: CD = current day (MTD); PD = previous day; CM = current month; LM = last month; LY = last year; LYCM = last-year current-month basis
B10: v < 3 Cr / v < 3 Ind Cr | C10: Sub-book of view v for customers below ₹3 Cr, and for individual customers below ₹3 Cr
B11: GT(v) | C11: Grand Total MAB for view v
B12: g(v) | C12: M(CM) ÷ M(v) − 1
B13: sh3 / shI | C13: < 3 Cr share = v < 3 Cr ÷ v; individual share = v < 3 Ind Cr ÷ v
B14: MAB/MEB | C14: CM MAB ÷ CM MEB from Block 1
B15: Values are ₹ Cr monthly average balances; growth in %, shares in %.
A17: Exhaustive metrics table
A18: # | B18: Metric family | C18: Pipeline-ready metric | D18: Definition / formula | E18: Applies to | F18: Example
A19: 1 | B19: Fact lookup | C19: Segment × product MAB | D19: M(s,p,v) | E19: 16 lines × 18 views (288 cells) | F19: ="INSIGNIA Deposits CM / LM / LY / LYCM "&TEXT(B2_Balance_Movement!J9,"#,##0.00;-#,##0.00;0.00")&" / "&TEXT(B2_Balance_Movement!M9,"#,##0.00;-#,##0.00;0.00")&" / "&TEXT(B2_Balance_Movement!P9,"#,##0.00;-#,##0.00;0.00")&" / "&TEXT(B2_Balance_Movement!S9,"#,##0.00;-#,##0.00;0.00") -> INSIGNIA Deposits CM / LM / LY / LYCM 53,834.13 / 34,820.85 / 24,851.69 / 21,769.31
A20: 2 | B20: Fact lookup | C20: Grand Total MAB | D20: GT(v) | E20: 18 views | F20: ="CD / CM / LM / LY / LYCM "&TEXT(B2_Balance_Movement!D25,"#,##0.00;-#,##0.00;0.00")&" / "&TEXT(B2_Balance_Movement!J25,"#,##0.00;-#,##0.00;0.00")&" / "&TEXT(B2_Balance_Movement!M25,"#,##0.00;-#,##0.00;0.00")&" / "&TEXT(B2_Balance_Movement!P25,"#,##0.00;-#,##0.00;0.00")&" / "&TEXT(B2_Balance_Movement!S25,"#,##0.00;-#,##0.00;0.00") -> CD / CM / LM / LY / LYCM 115,449.00 / 115,448.64 / 94,880.79 / 83,098.91 / 73,396.38
A21: 3 | B21: Roll-up check | C21: Lines to Grand Total | D21: GT(v) − Σ M(s,p,v) | E21: 18 views | F21: ="max |gap| "&TEXT(MAX(ABS(MIN(B2_Balance_Movement!D26:U26)),MAX(B2_Balance_Movement!D26:U26)),"#,##0.00;-#,##0.00;0.00") -> max |gap| 2.00
A22: 4 | B22: Volume aggregates | C22: Segment MAB | D22: Σp M(s,p,CM) | E22: 4 segments × 18 views | F22: ="CM "&TEXT(B2_Balance_Movement!J31,"#,##0.00;-#,##0.00;0.00")&" / "&TEXT(B2_Balance_Movement!J32,"#,##0.00;-#,##0.00;0.00")&" / "&TEXT(B2_Balance_Movement!J33,"#,##0.00;-#,##0.00;0.00")&" / "&TEXT(B2_Balance_Movement!J34,"#,##0.00;-#,##0.00;0.00") -> CM 68,769.49 / 11,321.91 / 8,764.28 / 26,592.95
A23: 5 | B23: Volume aggregates | C23: Product MAB | D23: Σs M(s,p,CM) | E23: 4 products × 18 views | F23: ="CM "&TEXT(B2_Balance_Movement!J35,"#,##0.00;-#,##0.00;0.00")&" / "&TEXT(B2_Balance_Movement!J36,"#,##0.00;-#,##0.00;0.00")&" / "&TEXT(B2_Balance_Movement!J37,"#,##0.00;-#,##0.00;0.00")&" / "&TEXT(B2_Balance_Movement!J38,"#,##0.00;-#,##0.00;0.00") -> CM 6,038.91 / 19,480.57 / 89,901.28 / 27.87
A24: 6 | B24: Volume aggregates | C24: CASA MAB | D24: M(CA) + M(SA) | E24: 18 views | F24: ="CM "&TEXT(B2_Balance_Movement!J35+B2_Balance_Movement!J36,"#,##0.00;-#,##0.00;0.00")&"; LY "&TEXT(B2_Balance_Movement!P35+B2_Balance_Movement!P36,"#,##0.00;-#,##0.00;0.00") -> CM 25,519.48; LY 25,065.55
A25: 7 | B25: Mix & share | C25: Segment share of GT | D25: Σp M(s,p,CM) ÷ GT(CM) | E25: 4 segments | F25: =TEXT(B2_Balance_Movement!AC31,"0.0%")&" / "&TEXT(B2_Balance_Movement!AC32,"0.0%")&" / "&TEXT(B2_Balance_Movement!AC33,"0.0%")&" / "&TEXT(B2_Balance_Movement!AC34,"0.0%") -> 59.6% / 9.8% / 7.6% / 23.0%
A26: 8 | B26: Mix & share | C26: Product share of GT | D26: Σs M(s,p,CM) ÷ GT(CM) | E26: 4 products | F26: =TEXT(B2_Balance_Movement!AC35,"0.0%")&" / "&TEXT(B2_Balance_Movement!AC36,"0.0%")&" / "&TEXT(B2_Balance_Movement!AC37,"0.0%")&" / "&TEXT(B2_Balance_Movement!AC38,"0.0%") -> 5.2% / 16.9% / 77.9% / 0.0%
A27: 9 | B27: Mix & share | C27: CASA ratio | D27: CASA ÷ GT | E27: 6 period views | F27: ="CM "&TEXT((B2_Balance_Movement!J35+B2_Balance_Movement!J36)/B2_Balance_Movement!J25,"0.0%")&"; LM "&TEXT((B2_Balance_Movement!M35+B2_Balance_Movement!M36)/B2_Balance_Movement!M25,"0.0%")&"; LY "&TEXT((B2_Balance_Movement!P35+B2_Balance_Movement!P36)/B2_Balance_Movement!P25,"0.0%") -> CM 22.1%; LM 26.5%; LY 30.2%
A28: 10 | B28: Mix & share | C28: < 3 Cr sub-book share | D28: sh3 = M < 3 Cr ÷ M | E28: 16 lines + roll-ups | F28: ="GT "&TEXT(B2_Balance_Movement!V25,"0.0%")&"; INSIGNIA "&TEXT(B2_Balance_Movement!V31,"0.0%")&"; MASS "&TEXT(B2_Balance_Movement!V34,"0.0%") -> GT 55.5%; INSIGNIA 51.4%; MASS 44.5%
A29: 11 | B29: Mix & share | C29: Individual < 3 Cr share | D29: shI = M < 3 Ind Cr ÷ M | E29: 16 lines + roll-ups | F29: ="GT "&TEXT(B2_Balance_Movement!W25,"0.0%")&"; SA "&TEXT(B2_Balance_Movement!W36,"0.0%")&"; Deposits "&TEXT(B2_Balance_Movement!W37,"0.0%") -> GT 38.5%; SA 73.4%; Deposits 33.2%
A30: 12 | B30: Growth & momentum | C30: MoM growth | D30: g(LM) | E30: 16 lines + roll-ups | F30: ="GT "&TEXT(B2_Balance_Movement!X25,"+0.0%;-0.0%;0.0%")&"; segments "&TEXT(B2_Balance_Movement!X31,"+0.0%;-0.0%;0.0%")&" / "&TEXT(B2_Balance_Movement!X32,"+0.0%;-0.0%;0.0%")&" / "&TEXT(B2_Balance_Movement!X33,"+0.0%;-0.0%;0.0%")&" / "&TEXT(B2_Balance_Movement!X34,"+0.0%;-0.0%;0.0%") -> GT +21.7%; segments +38.9% / +7.3% / +7.6% / -0.3%
A31: 13 | B31: Growth & momentum | C31: YoY growth | D31: g(LY) | E31: 16 lines + roll-ups | F31: ="GT "&TEXT(B2_Balance_Movement!Y25,"+0.0%;-0.0%;0.0%")&"; segments "&TEXT(B2_Balance_Movement!Y31,"+0.0%;-0.0%;0.0%")&" / "&TEXT(B2_Balance_Movement!Y32,"+0.0%;-0.0%;0.0%")&" / "&TEXT(B2_Balance_Movement!Y33,"+0.0%;-0.0%;0.0%")&" / "&TEXT(B2_Balance_Movement!Y34,"+0.0%;-0.0%;0.0%") -> GT +38.9%; segments +74.6% / +20.2% / +17.2% / -0.8%
A32: 14 | B32: Growth & momentum | C32: Growth vs LYCM basis | D32: g(LYCM) | E32: 16 lines + roll-ups | F32: ="GT "&TEXT(B2_Balance_Movement!Z25,"+0.0%;-0.0%;0.0%")&"; products "&TEXT(B2_Balance_Movement!Z35,"+0.0%;-0.0%;0.0%")&" / "&TEXT(B2_Balance_Movement!Z36,"+0.0%;-0.0%;0.0%")&" / "&TEXT(B2_Balance_Movement!Z37,"+0.0%;-0.0%;0.0%")&" / "&TEXT(B2_Balance_Movement!Z38,"+0.0%;-0.0%;0.0%") -> GT +57.3%; products +11.1% / +9.3% / +79.3% / +87.6%
A33: 15 | B33: Growth & momentum | C33: Product YoY growth | D33: g(LY) by product | E33: 4 products | F33: =TEXT(B2_Balance_Movement!Y35,"+0.0%;-0.0%;0.0%")&" / "&TEXT(B2_Balance_Movement!Y36,"+0.0%;-0.0%;0.0%")&" / "&TEXT(B2_Balance_Movement!Y37,"+0.0%;-0.0%;0.0%")&" / "&TEXT(B2_Balance_Movement!Y38,"+0.0%;-0.0%;0.0%")&" (CA / SA / Dep / ODFD)" -> -3.5% / +3.6% / +55.0% / -6.6% (CA / SA / Dep / ODFD)
A34: 16 | B34: Growth & momentum | C34: Sub-book YoY growth | D34: v < 3 Cr (CM) ÷ v < 3 Cr (LY) − 1 | E34: GT and lines | F34: ="< 3 Cr "&TEXT(B2_Balance_Movement!K25/B2_Balance_Movement!Q25-1,"+0.0%;-0.0%;0.0%")&"; < 3 Ind Cr "&TEXT(B2_Balance_Movement!L25/B2_Balance_Movement!R25-1,"+0.0%;-0.0%;0.0%")&"; ≥ 3 Cr book "&TEXT((B2_Balance_Movement!J25-B2_Balance_Movement!K25)/(B2_Balance_Movement!P25-B2_Balance_Movement!Q25)-1,"+0.0%;-0.0%;0.0%") -> < 3 Cr +8.5%; < 3 Ind Cr +7.0%; ≥ 3 Cr book +113.6%
A35: 17 | B35: Attribution | C35: Contribution to YoY GT growth | D35: (M(CM) − M(LY)) ÷ (GT(CM) − GT(LY)) | E35: 16 lines | F35: ="INSIGNIA Dep "&TEXT((B2_Balance_Movement!J9-B2_Balance_Movement!P9)/(B2_Balance_Movement!J25-B2_Balance_Movement!P25),"0.0%")&"; MASS Dep "&TEXT((B2_Balance_Movement!J21-B2_Balance_Movement!P21)/(B2_Balance_Movement!J25-B2_Balance_Movement!P25),"0.0%") -> INSIGNIA Dep 89.6%; MASS Dep 0.1%
A36: 18 | B36: Attribution | C36: Contribution to MoM GT growth | D36: (M(CM) − M(LM)) ÷ (GT(CM) − GT(LM)) | E36: 16 lines | F36: ="INSIGNIA Dep "&TEXT((B2_Balance_Movement!J9-B2_Balance_Movement!M9)/(B2_Balance_Movement!J25-B2_Balance_Movement!M25),"0.0%") -> INSIGNIA Dep 92.4%
A37: 19 | B37: Daily movement | C37: CD − PD | D37: Day-on-day MTD MAB change | E37: 16 lines + GT | F37: ="GT "&TEXT(B2_Balance_Movement!AA25,"#,##0.00;-#,##0.00;0.00")&"; INSIGNIA Dep "&TEXT(B2_Balance_Movement!AA9,"#,##0.00;-#,##0.00;0.00")&"; MASS Dep "&TEXT(B2_Balance_Movement!AA21,"#,##0.00;-#,##0.00;0.00") -> GT 85.00; INSIGNIA Dep 55.00; MASS Dep -19.00
A38: 20 | B38: Daily movement | C38: CD vs CM | D38: CD* − CM* | E38: GT | F38: =TEXT(B2_Balance_Movement!D25-B2_Balance_Movement!J25,"#,##0.00;-#,##0.00;0.00")&" (rounding; CD = CM to date)" -> 0.36 (rounding; CD = CM to date)
A39: 21 | B39: Cross-basis | C39: MAB ÷ MEB | D39: M(s,p,CM) ÷ B(s,p,CM) from Block 1 | E39: 16 lines | F39: ="INSIGNIA Dep "&TEXT(B2_Balance_Movement!AB9,"0.00""x""")&"; MASS Dep "&TEXT(B2_Balance_Movement!AB21,"0.00""x""")&"; INSIGNIA CA "&TEXT(B2_Balance_Movement!AB7,"0.00""x""") -> INSIGNIA Dep 1.02x; MASS Dep 1.06x; INSIGNIA CA 0.94x
A40: 22 | B40: Cross-basis | C40: GT MAB − GT MEB | D40: GT(CM) − GT MEB (Block 1) | E40: Page | F40: =TEXT(B2_Balance_Movement!J25-B1_MEB_Periods!G11,"#,##0.00;-#,##0.00;0.00") -> 2,338.83
A41: 23 | B41: Reconciliation | C41: Tie to MAB page | D41: CM − LM = 'CM vs LM MAB Diff' (20,567.85); CM − LY = 32,349.73 | E41: GT | F41: ="CM − LM "&TEXT(B2_Balance_Movement!J25-B2_Balance_Movement!M25,"#,##0.00;-#,##0.00;0.00")&"; CM − LY "&TEXT(B2_Balance_Movement!J25-B2_Balance_Movement!P25,"#,##0.00;-#,##0.00;0.00") -> CM − LM 20,567.85; CM − LY 32,349.73
A42: 24 | B42: Data integrity | C42: Threshold definition | D42: '< 3 Cr' as printed | E42: Page | F42: Sub-book = customers below ₹3 Cr; ≥ ₹3 Cr book = total − sub-book
...
