Workbook

Sheet README
A1: RBL Bank — Overall & Segment-wise MAB (BBRL): page-wise metric extraction
A2: Source: 02_Overall_and_Segment_wise_MAB.pdf (1 page, 5 tables; data to 29-Aug-2026) | ₹ Cr monthly average balances
A3: ⚠ DRAFT ONLY — Requires review and approval by a qualified Alvarez and Marsal professional before use.
A5: Sheet map
A6: B1_MAB_Tables | B6: All five MAB tables (Product, Customer Segment, RM Segment, Derived Segment, BAU Identifier) with line-level calcs, roll-up checks and a cross-check of the printed diffs against the Book Growth page
A7: B1_Metrics | B7: Notation + exhaustive metrics
A9: Colour legend
A10: Blue text | B10: Hard-coded input transcribed from the PDF
A11: Blue italic on grey | B11: Budget / projected value (ᴾ) transcribed from the PDF
A12: Black text | B12: Formula on the same sheet
A13: Green text | B13: Link to another sheet
A14: Yellow fill | B14: Data flag to review
A16: Key assumptions (confirm with client)
A17: 1 | B17: All 'Diff' columns are signed in the PDF (negatives shown in brackets, e.g. CA CM vs LM = (72.18)). For Product and Customer-Segment rows the printed LM and LY diffs are re-derived from the Book Growth page (LM* / LY* MAB) and tie.
A18: 2 | B18: '< 3 Cr' / 'Indi < 3 Cr' columns (as printed: 'CM MAB <3 Cr') are the sub-book of customers below ₹3 Cr and individual customers within it.
A19: 3 | B19: 'M-1' comparison base is not defined on the page (its diff is larger than the LM diff, so it is an earlier base). Flagged; not used for growth rates.
A20: 4 | B20: Reference LM/LY MAB values are taken from the Book Growth page of the same pack (Balance Movement LM* / LY*) and typed as inputs.
A21: Confidentiality | B21: Client-confidential RBL Bank data.
A23: ⚠ DRAFT ONLY — Requires review and approval by a qualified Alvarez and Marsal professional before use.

Sheet B1_MAB_Tables
A1: Block 1 — MAB tables: Product, Customer Segment, RM Segment, Derived Segment, BAU
A2: Source: Overall & Segment wise MAB.pdf | ₹ Cr | Balance date 29-Aug-2026 | diffs signed as printed
A3: ⚠ DRAFT ONLY — Requires review and approval by a qualified Alvarez and Marsal professional before use.
A5: A. Source data (blue) with line-level live calculations
A6: # | B6: Table | C6: Group | D6: Line | E6: CM MAB | F6: CM MAB < 3 Cr | G6: CM MAB Indi < 3 Cr | H6: CM vs LM MAB Diff | I6: CM vs LM < 3 Cr Diff | J6: CM vs LM Indi < 3 Cr Diff | K6: CM vs M-1 MAB Diff | L6: CM vs M-1 < 3 Cr Diff | M6: CM vs M-1 Indi < 3 Cr Diff | N6: CM vs LY MAB Diff | O6: CM vs LY < 3 Cr Diff | P6: CM vs LY Indi < 3 Cr Diff | Q6: < 3 Cr share of CM | R6: Indi < 3 Cr share of CM | S6: LM diff ÷ CM | T6: M-1 diff ÷ CM | U6: LY diff ÷ CM | V6: Share of GT (CM) | W6: Roll-up check (Total − Σ lines) | X6: Ref LM MAB (Book Growth) | Y6: Recomputed LM diff = CM − ref | Z6: Ref LY MAB / recomputed LY diff | AA6: Printed − recomputed LM diff
A7: 1 | B7: Product | C7: CASA | D7: CA | E7: 6038.91 | F7: 3833.62 | G7: 249.42 | H7: -72.18 | I7: -1.83 | J7: -2.42 | K7: -39.68 | L7: 100.15 | M7: -0.63 | N7: -221.48 | O7: -0.79 | P7: 6.81 | Q7: =F7/E7 -> 0.63481986 | R7: =G7/E7 -> 0.041302156 | S7: =H7/E7 -> -0.011952488 | T7: =K7/E7 -> -0.0065707222 | U7: =N7/E7 -> -0.036675493 | V7: =E7/E$13 -> 0.052308195 | X7: 6111.09 | Y7: =E7-X7 -> -72.18 | Z7: =TEXT(6260.4,"#,##0.00")&" / "&TEXT(E7-6260.4,"+#,##0.00;-#,##0.00") -> 6,260.40 / -221.49 | AA7: =H7-Y7 -> 2.8421709e-13
A8: 2 | B8: Product | C8: CASA | D8: SA | E8: 19480.57 | F8: 15391.35 | G8: 14300.75 | H8: 456.88 | I8: 77.59 | J8: 75.1 | K8: 224.55 | L8: 393.84 | M8: 356.15 | N8: 675.43 | O8: 272.81 | P8: 269.65 | Q8: =F8/E8 -> 0.79008725 | R8: =G8/E8 -> 0.73410326 | S8: =H8/E8 -> 0.023453113 | T8: =K8/E8 -> 0.01152687 | U8: =N8/E8 -> 0.034671983 | V8: =E8/E$13 -> 0.16873798 | X8: 19023.68 | Y8: =E8-X8 -> 456.89 | Z8: =TEXT(18805.15,"#,##0.00")&" / "&TEXT(E8-18805.15,"+#,##0.00;-#,##0.00") -> 18,805.15 / +675.42 | AA8: =H8-Y8 -> -0.01
A9: 3 | B9: Product | C9: CASA | D9: Total | E9: 25519.48 | F9: 19224.97 | G9: 14550.17 | H9: 384.7 | I9: 75.76 | J9: 72.68 | K9: 184.87 | L9: 494 | M9: 355.52 | N9: 453.95 | O9: 272.02 | P9: 276.46 | Q9: =F9/E9 -> 0.7533449 | R9: =G9/E9 -> 0.57015934 | S9: =H9/E9 -> 0.015074759 | T9: =K9/E9 -> 0.0072442699 | U9: =N9/E9 -> 0.017788372 | V9: =E9/E$13 -> 0.22104617 | W9: =E9-E7-E8 -> 0
A10: 4 | B10: Product | C10: TD | D10: Deposits | E10: 89901.29 | F10: 44854.51 | G10: 29867.57 | H10: 20186.72 | I10: 901.88 | J10: 344.19 | K10: 27858.44 | L10: 1665.79 | M10: 747.89 | N10: 31897.74 | O10: 4771.55 | P10: 2645.73 | Q10: =F10/E10 -> 0.49893066 | R10: =G10/E10 -> 0.33222627 | S10: =H10/E10 -> 0.22454316 | T10: =K10/E10 -> 0.30987809 | U10: =N10/E10 -> 0.35480848 | V10: =E10/E$13 -> 0.77871242 | X10: 69714.57 | Y10: =E10-X10 -> 20186.72 | Z10: =TEXT(58003.56,"#,##0.00")&" / "&TEXT(E10-58003.56,"+#,##0.00;-#,##0.00") -> 58,003.56 / +31,897.73 | AA10: =H10-Y10 -> 0
A11: 5 | B11: Product | C11: TD | D11: ODFD | E11: 27.87 | F11: 24.16 | G11: 8.74 | H11: -3.58 | I11: 4.72 | J11: 0.34 | K11: 6.55 | L11: 2.85 | M11: -0.81 | N11: -1.96 | O11: -5.67 | P11: -0.35 | Q11: =F11/E11 -> 0.86688195 | R11: =G11/E11 -> 0.31359885 | S11: =H11/E11 -> -0.12845353 | T11: =K11/E11 -> 0.23501973 | U11: =N11/E11 -> -0.070326516 | V11: =E11/E$13 -> 0.00024140605 | X11: 31.44 | Y11: =E11-X11 -> -3.57 | Z11: =TEXT(29.83,"#,##0.00")&" / "&TEXT(E11-29.83,"+#,##0.00;-#,##0.00") -> 29.83 / -1.96 | AA11: =H11-Y11 -> -0.01
A12: 6 | B12: Product | C12: TD | D12: Total | E12: 89929.16 | F12: 44878.68 | G12: 29876.3 | H12: 20183.15 | I12: 906.6 | J12: 344.53 | K12: 27865 | L12: 1668.64 | M12: 747.08 | N12: 31895.78 | O12: 4765.89 | P12: 2645.38 | Q12: =F12/E12 -> 0.4990448 | R12: =G12/E12 -> 0.33222038 | S12: =H12/E12 -> 0.22443388 | T12: =K12/E12 -> 0.309855 | U12: =N12/E12 -> 0.35467673 | V12: =E12/E$13 -> 0.77895383 | W12: =E12-E10-E11 -> 9.8943076e-12
A13: 7 | B13: Product | C13: Grand Total | D13: Grand Total | E13: 115448.64 | F13: 64103.64 | G13: 44426.48 | H13: 20567.85 | I13: 982.36 | J13: 417.21 | K13: 28049.87 | L13: 2162.64 | M13: 1102.6 | N13: 32349.73 | O13: 5037.91 | P13: 2921.84 | Q13: =F13/E13 -> 0.55525678 | R13: =G13/E13 -> 0.38481597 | S13: =H13/E13 -> 0.17815584 | T13: =K13/E13 -> 0.24296406 | U13: =N13/E13 -> 0.28020884 | V13: =E13/E$13 -> 1 | W13: =E13-(E9+E12) -> 0 | X13: 94880.79 | Y13: =E13-X13 -> 20567.85 | Z13: =TEXT(83098.91,"#,##0.00")&" / "&TEXT(E13-83098.91,"+#,##0.00;-#,##0.00") -> 83,098.91 / +32,349.73 | AA13: =H13-Y13 -> 0
A14: 8 | B14: Customer Segment | C14: INSIGNIA | D14: CASA | E14: 14924.43 | F14: 10230.92 | G14: 7800.87 | H14: 260.01 | I14: -31.57 | J14: -25.97 | K14: 242.92 | L14: 118.92 | M14: 82.7 | N14: 397.43 | O14: -103.72 | P14: -104.98 | Q14: =F14/E14 -> 0.68551496 | R14: =G14/E14 -> 0.52269132 | S14: =H14/E14 -> 0.017421771 | T14: =K14/E14 -> 0.016276669 | U14: =N14/E14 -> 0.026629493 | V14: =E14/E$13 -> 0.12927333
A15: 9 | B15: Customer Segment | C15: INSIGNIA | D15: TD | E15: 53845.06 | F15: 25144.63 | G15: 17077.59 | H15: 19011.3 | I15: 550.09 | J15: 151.85 | K15: 26910.99 | L15: 807.69 | M15: 284.87 | N15: 28979.06 | O15: 2487.81 | P15: 1303.3 | Q15: =F15/E15 -> 0.46698119 | R15: =G15/E15 -> 0.31716169 | S15: =H15/E15 -> 0.35307417 | T15: =K15/E15 -> 0.49978568 | U15: =N15/E15 -> 0.53819348 | V15: =E15/E$13 -> 0.46639839
A16: 10 | B16: Customer Segment | C16: INSIGNIA | D16: Total | E16: 68769.49 | F16: 35375.55 | G16: 24878.46 | H16: 19271.31 | I16: 518.52 | J16: 125.88 | K16: 27153.91 | L16: 926.61 | M16: 367.57 | N16: 29376.49 | O16: 2384.09 | P16: 1198.32 | Q16: =F16/E16 -> 0.51440762 | R16: =G16/E16 -> 0.36176595 | S16: =H16/E16 -> 0.28023052 | T16: =K16/E16 -> 0.39485403 | U16: =N16/E16 -> 0.4271733 | V16: =E16/E$13 -> 0.59567172 | W16: =E16-E14-E15 -> 0 | X16: 49498.19 | Y16: =E16-X16 -> 19271.3 | Z16: =TEXT(39393,"#,##0.00")&" / "&TEXT(E16-39393,"+#,##0.00;-#,##0.00") -> 39,393.00 / +29,376.49 | AA16: =H16-Y16 -> 0.01
A17: 11 | B17: Customer Segment | C17: SIGNATURE | D17: CASA | E17: 3627.04 | F17: 3225.72 | G17: 2656.42 | H17: 47.05 | I17: -22.4 | J17: -15.5 | K17: 178.49 | L17: 45.02 | M17: 39.92 | N17: 200.77 | O17: 60.34 | P17: 80.32 | Q17: =F17/E17 -> 0.8893533 | R17: =G17/E17 -> 0.73239336 | S17: =H17/E17 -> 0.01297201 | T17: =K17/E17 -> 0.049210927 | U17: =N17/E17 -> 0.055353677 | V17: =E17/E$13 -> 0.031416914
A18: 12 | B18: Customer Segment | C18: SIGNATURE | D18: TD | E18: 7694.87 | F18: 6491.73 | G18: 5165.84 | H18: 719.8 | I18: 72.57 | J18: 47.25 | K18: 1204.28 | L18: 197.65 | M18: 123.58 | N18: 1702.66 | O18: 671.48 | P18: 492.65 | Q18: =F18/E18 -> 0.84364388 | R18: =G18/E18 -> 0.67133558 | S18: =H18/E18 -> 0.093542841 | T18: =K18/E18 -> 0.15650427 | U18: =N18/E18 -> 0.22127209 | V18: =E18/E$13 -> 0.06665189
A19: 13 | B19: Customer Segment | C19: SIGNATURE | D19: Total | E19: 11321.92 | F19: 9717.45 | G19: 7822.27 | H19: 766.84 | I19: 50.17 | J19: 31.75 | K19: 1382.77 | L19: 242.67 | M19: 163.5 | N19: 1903.43 | O19: 731.82 | P19: 572.97 | Q19: =F19/E19 -> 0.8582864 | R19: =G19/E19 -> 0.69089607 | S19: =H19/E19 -> 0.067730562 | T19: =K19/E19 -> 0.12213211 | U19: =N19/E19 -> 0.16811901 | V19: =E19/E$13 -> 0.09806889 | W19: =E19-E17-E18 -> 0.01 | X19: 10555.07 | Y19: =E19-X19 -> 766.85 | Z19: =TEXT(9418.5,"#,##0.00")&" / "&TEXT(E19-9418.5,"+#,##0.00;-#,##0.00") -> 9,418.50 / +1,903.42 | AA19: =H19-Y19 -> -0.01
A20: 14 | B20: Customer Segment | C20: ASPIRE | D20: CASA | E20: 2113.2 | F20: 1945.75 | G20: 1382.61 | H20: 22.2 | I20: 14.7 | J20: 16.35 | K20: -14.19 | L20: 37.2 | M20: 32.12 | N20: 104.41 | O20: 37.91 | P20: 52.1 | Q20: =F20/E20 -> 0.92075998 | R20: =G20/E20 -> 0.65427314 | S20: =H20/E20 -> 0.010505395 | T20: =K20/E20 -> -0.0067149347 | U20: =N20/E20 -> 0.04940848 | V20: =E20/E$13 -> 0.018304243
A21: 15 | B21: Customer Segment | C21: ASPIRE | D21: TD | E21: 6651.08 | F21: 5239.76 | G21: 4199.26 | H21: 599.98 | I21: 15.39 | J21: 2.75 | K21: 793.85 | L21: 102.82 | M21: 59.29 | N21: 1183.57 | O21: 404.1 | P21: 221.83 | Q21: =F21/E21 -> 0.78780589 | R21: =G21/E21 -> 0.63136513 | S21: =H21/E21 -> 0.090207906 | T21: =K21/E21 -> 0.11935656 | U21: =N21/E21 -> 0.17795155 | V21: =E21/E$13 -> 0.057610726
A22: 16 | B22: Customer Segment | C22: ASPIRE | D22: Total | E22: 8764.28 | F22: 7185.51 | G22: 5581.86 | H22: 622.18 | I22: 30.09 | J22: 19.1 | K22: 779.66 | L22: 140.02 | M22: 91.41 | N22: 1287.98 | O22: 442.01 | P22: 273.92 | Q22: =F22/E22 -> 0.81986313 | R22: =G22/E22 -> 0.63688746 | S22: =H22/E22 -> 0.070990429 | T22: =K22/E22 -> 0.088958819 | U22: =N22/E22 -> 0.14695788 | V22: =E22/E$13 -> 0.07591497 | W22: =E22-E20-E21 -> 0 | X22: 8142.09 | Y22: =E22-X22 -> 622.19 | Z22: =TEXT(7476.31,"#,##0.00")&" / "&TEXT(E22-7476.31,"+#,##0.00;-#,##0.00") -> 7,476.31 / +1,287.97 | AA22: =H22-Y22 -> -0.01
A23: 17 | B23: Customer Segment | C23: MASS | D23: CASA | E23: 4854.81 | F23: 3822.58 | G23: 2710.27 | H23: 55.45 | I23: 115.03 | J23: 97.8 | K23: -222.35 | L23: 292.85 | M23: 200.78 | N23: -248.66 | O23: 277.49 | P23: 249.03 | Q23: =F23/E23 -> 0.78737994 | R23: =G23/E23 -> 0.5582649 | S23: =H23/E23 -> 0.011421662 | T23: =K23/E23 -> -0.045799939 | U23: =N23/E23 -> -0.051219306 | V23: =E23/E$13 -> 0.042051686
A24: 18 | B24: Customer Segment | C24: MASS | D24: TD | E24: 21738.15 | F24: 8002.56 | G24: 3433.62 | H24: -147.93 | I24: 268.55 | J24: 142.68 | K24: -1044.12 | L24: 560.49 | M24: 279.35 | N24: 30.49 | O24: 1202.5 | P24: 627.6 | Q24: =F24/E24 -> 0.36813436 | R24: =G24/E24 -> 0.15795364 | S24: =H24/E24 -> -0.0068050869 | T24: =K24/E24 -> -0.048031686 | U24: =N24/E24 -> 0.0014026033 | V24: =E24/E$13 -> 0.18829282
A25: 19 | B25: Customer Segment | C25: MASS | D25: Total | E25: 26592.96 | F25: 11825.14 | G25: 6143.89 | H25: -92.48 | I25: 383.58 | J25: 240.48 | K25: -1266.47 | L25: 853.34 | M25: 480.13 | N25: -218.17 | O25: 1479.99 | P25: 876.63 | Q25: =F25/E25 -> 0.44467182 | R25: =G25/E25 -> 0.23103445 | S25: =H25/E25 -> -0.0034776121 | T25: =K25/E25 -> -0.047624258 | U25: =N25/E25 -> -0.008204051 | V25: =E25/E$13 -> 0.23034451 | W25: =E25-E23-E24 -> 0 | X25: 26685.43 | Y25: =E25-X25 -> -92.47 | Z25: =TEXT(26811.13,"#,##0.00")&" / "&TEXT(E25-26811.13,"+#,##0.00;-#,##0.00") -> 26,811.13 / -218.17 | AA25: =H25-Y25 -> -0.01
A26: 20 | B26: Customer Segment | C26: Grand Total | D26: Grand Total | E26: 115448.64 | F26: 64103.64 | G26: 44426.48 | H26: 20567.85 | I26: 982.36 | J26: 417.21 | K26: 28049.87 | L26: 2162.64 | M26: 1102.6 | N26: 32349.73 | O26: 5037.91 | P26: 2921.84 | Q26: =F26/E26 -> 0.55525678 | R26: =G26/E26 -> 0.38481597 | S26: =H26/E26 -> 0.17815584 | T26: =K26/E26 -> 0.24296406 | U26: =N26/E26 -> 0.28020884 | V26: =E26/E$13 -> 1 | W26: =E26-(E16+E19+E22+E25) -> -0.01 | X26: 94880.79 | Y26: =E26-X26 -> 20567.85 | Z26: =TEXT(83098.91,"#,##0.00")&" / "&TEXT(E26-83098.91,"+#,##0.00;-#,##0.00") -> 83,098.91 / +32,349.73 | AA26: =H26-Y26 -> 0
A27: 21 | B27: RM Segment | C27: INSIGNIA | D27: CASA | E27: 12398.02 | F27: 8840.67 | G27: 6877.22 | H27: 290.92 | I27: -32.94 | J27: -7.75 | K27: 554.59 | L27: 89.68 | M27: 92.14 | N27: 427.87 | O27: -165.33 | P27: -99.4 | Q27: =F27/E27 -> 0.71307112 | R27: =G27/E27 -> 0.55470309 | S27: =H27/E27 -> 0.023465037 | T27: =K27/E27 -> 0.044732143 | U27: =N27/E27 -> 0.034511156 | V27: =E27/E$13 -> 0.10738992
A28: 22 | B28: RM Segment | C28: INSIGNIA | D28: TD | E28: 48539.41 | F28: 22858.81 | G28: 15370.74 | H28: 18065.25 | I28: 427.53 | J28: 98.43 | K28: 24161.85 | L28: 656.43 | M28: 211.38 | N28: 25875.44 | O28: 2062.1 | P28: 1030.75 | Q28: =F28/E28 -> 0.470933 | R28: =G28/E28 -> 0.31666516 | S28: =H28/E28 -> 0.37217696 | T28: =K28/E28 -> 0.49777799 | U28: =N28/E28 -> 0.53308106 | V28: =E28/E$13 -> 0.42044159
A29: 23 | B29: RM Segment | C29: INSIGNIA | D29: Total | E29: 60937.43 | F29: 31699.48 | G29: 22247.97 | H29: 18356.17 | I29: 394.58 | J29: 90.68 | K29: 24716.44 | L29: 746.11 | M29: 303.52 | N29: 26303.3 | O29: 1896.78 | P29: 931.35 | Q29: =F29/E29 -> 0.52019719 | R29: =G29/E29 -> 0.36509531 | S29: =H29/E29 -> 0.3012298 | T29: =K29/E29 -> 0.40560358 | U29: =N29/E29 -> 0.43164439 | V29: =E29/E$13 -> 0.52783151 | W29: =E29-E27-E28 -> 0
A30: 24 | B30: RM Segment | C30: SIGNATURE | D30: CASA | E30: 2835.95 | F30: 2581.52 | G30: 2106.99 | H30: -9.14 | I30: -8.06 | J30: -7.55 | K30: 80.19 | L30: 48.76 | M30: 38.12 | N30: 102.21 | O30: 60.54 | P30: 72.77 | Q30: =F30/E30 -> 0.91028403 | R30: =G30/E30 -> 0.74295739 | S30: =H30/E30 -> -0.0032229059 | T30: =K30/E30 -> 0.028276239 | U30: =N30/E30 -> 0.036040833 | V30: =E30/E$13 -> 0.024564603
A31: 25 | B31: RM Segment | C31: SIGNATURE | D31: TD | E31: 7189.69 | F31: 5695.5 | G31: 4467.6 | H31: 869.7 | I31: 89.92 | J31: 73.53 | K31: 1507.27 | L31: 224.51 | M31: 154.94 | N31: 2038.23 | O31: 722.48 | P31: 539.69 | Q31: =F31/E31 -> 0.79217602 | R31: =G31/E31 -> 0.6213898 | S31: =H31/E31 -> 0.12096488 | T31: =K31/E31 -> 0.20964325 | U31: =N31/E31 -> 0.28349345 | V31: =E31/E$13 -> 0.062276091
A32: 26 | B32: RM Segment | C32: SIGNATURE | D32: Total | E32: 10025.65 | F32: 8277.01 | G32: 6574.58 | H32: 860.55 | I32: 81.86 | J32: 65.98 | K32: 1587.46 | L32: 273.27 | M32: 193.06 | N32: 2140.44 | O32: 783.02 | P32: 612.46 | Q32: =F32/E32 -> 0.82558338 | R32: =G32/E32 -> 0.65577593 | S32: =H32/E32 -> 0.085834834 | T32: =K32/E32 -> 0.15833986 | U32: =N32/E32 -> 0.21349638 | V32: =E32/E$13 -> 0.08684078 | W32: =E32-E30-E31 -> 0.01
A33: 27 | B33: RM Segment | C33: ASPIRE | D33: CASA | E33: 2165.16 | F33: 2039.05 | G33: 1549.33 | H33: 58.38 | I33: 27.42 | J33: 26.65 | K33: 109.27 | L33: 64.7 | M33: 53.7 | N33: 148.76 | O33: 74.85 | P33: 70.17 | Q33: =F33/E33 -> 0.94175488 | R33: =G33/E33 -> 0.71557298 | S33: =H33/E33 -> 0.026963365 | T33: =K33/E33 -> 0.050467402 | U33: =N33/E33 -> 0.068706239 | V33: =E33/E$13 -> 0.018754314
A34: 28 | B34: RM Segment | C34: ASPIRE | D34: TD | E34: 5728.17 | F34: 4960.2 | G34: 4499.35 | H34: 656.55 | I34: 26.15 | J34: 16.13 | K34: 864.45 | L34: 129.06 | M34: 85.15 | N34: 1140.79 | O34: 380.89 | P34: 289.65 | Q34: =F34/E34 -> 0.865931 | R34: =G34/E34 -> 0.78547774 | S34: =H34/E34 -> 0.11461776 | T34: =K34/E34 -> 0.15091207 | U34: =N34/E34 -> 0.19915435 | V34: =E34/E$13 -> 0.049616609
A35: 29 | B35: RM Segment | C35: ASPIRE | D35: Total | E35: 7893.34 | F35: 6999.25 | G35: 6048.68 | H35: 714.93 | I35: 53.57 | J35: 42.78 | K35: 973.72 | L35: 193.76 | M35: 138.85 | N35: 1289.55 | O35: 455.74 | P35: 359.82 | Q35: =F35/E35 -> 0.88672856 | R35: =G35/E35 -> 0.76630172 | S35: =H35/E35 -> 0.090573826 | T35: =K35/E35 -> 0.12335969 | U35: =N35/E35 -> 0.16337191 | V35: =E35/E$13 -> 0.068371009 | W35: =E35-E33-E34 -> 0.01
A36: 30 | B36: RM Segment | C36: MASS | D36: CASA | E36: 8120.34 | F36: 5763.73 | G36: 4016.63 | H36: 44.54 | I36: 89.35 | J36: 61.33 | K36: -559.18 | L36: 290.86 | M36: 171.56 | N36: -224.89 | O36: 301.96 | P36: 232.92 | Q36: =F36/E36 -> 0.70978925 | R36: =G36/E36 -> 0.49463816 | S36: =H36/E36 -> 0.005484992 | T36: =K36/E36 -> -0.068861649 | U36: =N36/E36 -> -0.027694653 | V36: =E36/E$13 -> 0.070337251
A37: 31 | B37: RM Segment | C37: MASS | D37: TD | E37: 28471.88 | F37: 11364.17 | G37: 5538.61 | H37: 591.66 | I37: 363 | J37: 156.44 | K37: 1331.42 | L37: 658.64 | M37: 295.62 | N37: 2841.32 | O37: 1600.42 | P37: 785.29 | Q37: =F37/E37 -> 0.39913662 | R37: =G37/E37 -> 0.19452913 | S37: =H37/E37 -> 0.020780503 | T37: =K37/E37 -> 0.04676263 | U37: =N37/E37 -> 0.099793902 | V37: =E37/E$13 -> 0.24661945
A38: 32 | B38: RM Segment | C38: MASS | D38: Total | E38: 36592.22 | F38: 17127.9 | G38: 9555.25 | H38: 636.2 | I38: 452.35 | J38: 217.77 | K38: 772.24 | L38: 949.5 | M38: 467.18 | N38: 2616.43 | O38: 1902.38 | P38: 1018.21 | Q38: =F38/E38 -> 0.46807491 | R38: =G38/E38 -> 0.26112791 | S38: =H38/E38 -> 0.017386209 | T38: =K38/E38 -> 0.02110394 | U38: =N38/E38 -> 0.071502358 | V38: =E38/E$13 -> 0.3169567 | W38: =E38-E36-E37 -> 0
A39: 33 | B39: RM Segment | C39: Grand Total | D39: Grand Total | E39: 115448.64 | F39: 64103.64 | G39: 44426.48 | H39: 20567.85 | I39: 982.36 | J39: 417.21 | K39: 28049.87 | L39: 2162.64 | M39: 1102.6 | N39: 32349.73 | O39: 5037.91 | P39: 2921.84 | Q39: =F39/E39 -> 0.55525678 | R39: =G39/E39 -> 0.38481597 | S39: =H39/E39 -> 0.17815584 | T39: =K39/E39 -> 0.24296406 | U39: =N39/E39 -> 0.28020884 | V39: =E39/E$13 -> 1 | W39: =E39-(E29+E32+E35+E38) -> 0 | X39: 94880.79 | Y39: =E39-X39 -> 20567.85 | Z39: =TEXT(83098.91,"#,##0.00")&" / "&TEXT(E39-83098.91,"+#,##0.00;-#,##0.00") -> 83,098.91 / +32,349.73 | AA39: =H39-Y39 -> 0
A40: 34 | B40: Derived Segment | C40: INSIGNIA | D40: CASA | E40: 13689.7 | F40: 9714.38 | G40: 7587.18 | H40: 239.76 | I40: -39.07 | J40: -15.41 | K40: 170.87 | L40: 89.06 | M40: 86.82 | N40: 313.24 | O40: -162.13 | P40: -112.92 | Q40: =F40/E40 -> 0.70961234 | R40: =G40/E40 -> 0.55422544 | S40: =H40/E40 -> 0.017513897 | T40: =K40/E40 -> 0.012481647 | U40: =N40/E40 -> 0.022881436 | V40: =E40/E$13 -> 0.11857827
A41: 35 | B41: Derived Segment | C41: INSIGNIA | D41: TD | E41: 53013.16 | F41: 24821.02 | G41: 16939.59 | H41: 18957.52 | I41: 491.71 | J41: 153.74 | K41: 26850.81 | L41: 748.7 | M41: 284.23 | N41: 28741.88 | O41: 2418.83 | P41: 1298.89 | Q41: =F41/E41 -> 0.46820488 | R41: =G41/E41 -> 0.31953556 | S41: =H41/E41 -> 0.35760026 | T41: =K41/E41 -> 0.50649329 | U41: =N41/E41 -> 0.542165 | V41: =E41/E$13 -> 0.45919259
...

Sheet B1_Metrics
A1: MAB tables: notation and metrics
A2: Format: Notation → Exhaustive metrics table | Example column = live Excel formula on the block sheet (green = cross-sheet)
A3: ⚠ DRAFT ONLY — Requires review and approval by a qualified Alvarez and Marsal professional before use.
A5: Notation
B6: Symbol | C6: Meaning
B7: MAB | C7: Monthly average balance, ₹ Cr, for the current month (CM) to the balance date
B8: M(x) | C8: CM MAB of line x (product, segment × CASA/TD, or BAU identifier)
B9: M3(x) / MI(x) | C9: CM MAB of customers below ₹3 Cr / individual customers below ₹3 Cr
B10: D_v(x) | C10: Printed 'CM vs v MAB Diff', v ∈ {LM, M-1, LY}; signed (brackets = negative)
B11: D̂_LM(x) | C11: Recomputed diff = M(x) − LM MAB from the Book Growth page (Product and Customer Segment only) — cross-check of D_LM
B12: GT | C12: Grand Total CM MAB = 115,448.64
B13: sh(x) | C13: M(x) ÷ GT
B14: CASA / TD | C14: CA + SA / Deposits + ODFD
B15: Views | C15: Customer Segment (owned), RM Segment (managed), Derived Segment, BAU identifier
B16: Values are ₹ Cr monthly average balances; growth in %, shares in %; diffs signed as printed (D̂ = recomputed).
A18: Exhaustive metrics table
A19: # | B19: Metric family | C19: Pipeline-ready metric | D19: Definition / formula | E19: Applies to | F19: Example
A20: 1 | B20: Fact lookup | C20: Line MAB | D20: M(x), M3(x), MI(x) | E20: All lines × 3 measures | F20: ="Deposits "&TEXT(B1_MAB_Tables!E10,"#,##0.00;-#,##0.00;0.00")&" / "&TEXT(B1_MAB_Tables!F10,"#,##0.00;-#,##0.00;0.00")&" / "&TEXT(B1_MAB_Tables!G10,"#,##0.00;-#,##0.00;0.00") -> Deposits 89,901.29 / 44,854.51 / 29,867.57
A21: 2 | B21: Fact lookup | C21: Printed diffs | D21: D_LM, D_M-1, D_LY (signed) | E21: All lines × 9 columns | F21: ="GT: LM "&TEXT(B1_MAB_Tables!H13,"#,##0.00;-#,##0.00;0.00")&"; M-1 "&TEXT(B1_MAB_Tables!K13,"#,##0.00;-#,##0.00;0.00")&"; LY "&TEXT(B1_MAB_Tables!N13,"#,##0.00;-#,##0.00;0.00") -> GT: LM 20,567.85; M-1 28,049.87; LY 32,349.73
A22: 3 | B22: Roll-up check | C22: Lines to Total / Grand Total | D22: Total − Σ lines | E22: Every Total row | F22: ="Σ |gaps| "&TEXT(SUMPRODUCT(ABS(B1_MAB_Tables!W7:W86)),"#,##0.00;-#,##0.00;0.00") -> Σ |gaps| 0.12
A23: 4 | B23: Roll-up check | C23: GT consistency across views | D23: GT identical in all five tables | E23: 5 tables | F23: =TEXT(B1_MAB_Tables!E13,"#,##0.00;-#,##0.00;0.00")&" / "&TEXT(B1_MAB_Tables!E26,"#,##0.00;-#,##0.00;0.00")&" / "&TEXT(B1_MAB_Tables!E39,"#,##0.00;-#,##0.00;0.00")&" / "&TEXT(B1_MAB_Tables!E64,"#,##0.00;-#,##0.00;0.00")&" / "&TEXT(B1_MAB_Tables!E86,"#,##0.00;-#,##0.00;0.00") -> 115,448.64 / 115,448.64 / 115,448.64 / 115,448.64 / 115,448.64
A24: 5 | B24: Mix & share | C24: CASA ratio | D24: CASA ÷ GT | E24: Bank + each segment | F24: ="Bank "&TEXT(B1_MAB_Tables!E9/B1_MAB_Tables!E13,"0.0%")&"; INSIGNIA "&TEXT(B1_MAB_Tables!E14/B1_MAB_Tables!E16,"0.0%")&"; MASS "&TEXT(B1_MAB_Tables!E23/B1_MAB_Tables!E25,"0.0%")&"; NR "&TEXT(B1_MAB_Tables!E68/B1_MAB_Tables!E70,"0.0%") -> Bank 22.1%; INSIGNIA 21.7%; MASS 18.3%; NR 9.0%
A25: 6 | B25: Mix & share | C25: Segment share of GT | D25: sh(segment Total) | E25: 4 customer segments | F25: =TEXT(B1_MAB_Tables!V16,"0.0%")&" / "&TEXT(B1_MAB_Tables!V19,"0.0%")&" / "&TEXT(B1_MAB_Tables!V22,"0.0%")&" / "&TEXT(B1_MAB_Tables!V25,"0.0%") -> 59.6% / 9.8% / 7.6% / 23.0%
A26: 7 | B26: Mix & share | C26: Managed vs owned (RM vs Customer segment) | D26: M_RM(s) − M_Cust(s) | E26: 4 segments | F26: =TEXT(B1_MAB_Tables!E29-B1_MAB_Tables!E16,"#,##0.00;-#,##0.00;0.00")&" / "&TEXT(B1_MAB_Tables!E32-B1_MAB_Tables!E19,"#,##0.00;-#,##0.00;0.00")&" / "&TEXT(B1_MAB_Tables!E35-B1_MAB_Tables!E22,"#,##0.00;-#,##0.00;0.00")&" / "&TEXT(B1_MAB_Tables!E38-B1_MAB_Tables!E25,"#,##0.00;-#,##0.00;0.00")&" (INSIGNIA … MASS)" -> -7,832.06 / -1,296.27 / -870.94 / 9,999.26 (INSIGNIA … MASS)
A27: 8 | B27: Mix & share | C27: Derived segment share | D27: sh(derived Total) | E27: 8 derived segments | F27: ="COOP "&TEXT(B1_MAB_Tables!V54,"0.0%")&"; Affluence "&TEXT(B1_MAB_Tables!V51,"0.0%")&"; FIGU "&TEXT(B1_MAB_Tables!V60,"0.0%")&"; Diplomat "&TEXT(B1_MAB_Tables!V57,"0.0%") -> COOP 11.6%; Affluence 2.1%; FIGU 2.3%; Diplomat 1.5%
A28: 9 | B28: Mix & share | C28: BAU identifier share | D28: sh(BAU Total) | E28: 7 identifiers | F28: ="NR "&TEXT(B1_MAB_Tables!V70,"0.0%")&"; TASC "&TEXT(B1_MAB_Tables!V73,"0.0%")&"; SALARY "&TEXT(B1_MAB_Tables!V67,"0.0%")&"; OTHER "&TEXT(B1_MAB_Tables!V85,"0.0%") -> NR 33.1%; TASC 6.9%; SALARY 1.3%; OTHER 45.2%
A29: 10 | B29: Mix & share | C29: < 3 Cr sub-book share | D29: M3 ÷ M | E29: All lines | F29: ="GT "&TEXT(B1_MAB_Tables!Q13,"0.0%")&"; TD "&TEXT(B1_MAB_Tables!Q10,"0.0%")&"; CA "&TEXT(B1_MAB_Tables!Q7,"0.0%")&"; NR TD "&TEXT(B1_MAB_Tables!Q69,"0.0%") -> GT 55.5%; TD 49.9%; CA 63.5%; NR TD 16.3%
A30: 11 | B30: Mix & share | C30: Individual share | D30: MI ÷ M | E30: All lines | F30: ="GT "&TEXT(B1_MAB_Tables!R13,"0.0%")&"; SA "&TEXT(B1_MAB_Tables!R8,"0.0%")&"; TD "&TEXT(B1_MAB_Tables!R10,"0.0%") -> GT 38.5%; SA 73.4%; TD 33.2%
A31: 12 | B31: Mix & share | C31: Institutional TD proxy | D31: (TD − MI(TD)) ÷ TD | E31: Bank | F31: =TEXT(1-B1_MAB_Tables!R10,"0.0%") -> 66.8%
A32: 13 | B32: Growth & momentum | C32: MoM change (recomputed) | D32: D̂_LM = M − LM(Book Growth) | E32: Products, customer segments, GT | F32: ="CA "&TEXT(B1_MAB_Tables!Y7,"#,##0.00;-#,##0.00;0.00")&"; SA "&TEXT(B1_MAB_Tables!Y8,"#,##0.00;-#,##0.00;0.00")&"; Deposits "&TEXT(B1_MAB_Tables!Y10,"#,##0.00;-#,##0.00;0.00")&"; GT "&TEXT(B1_MAB_Tables!Y13,"#,##0.00;-#,##0.00;0.00") -> CA -72.18; SA 456.89; Deposits 20,186.72; GT 20,567.85
A33: 14 | B33: Growth & momentum | C33: MoM growth | D33: M ÷ LM(ref) − 1 | E33: Products, customer segments, GT | F33: ="GT "&TEXT(B1_MAB_Tables!E13/B1_MAB_Tables!X13-1,"+0.0%;-0.0%;0.0%")&"; Deposits "&TEXT(B1_MAB_Tables!E10/B1_MAB_Tables!X10-1,"+0.0%;-0.0%;0.0%")&"; CA "&TEXT(B1_MAB_Tables!E7/B1_MAB_Tables!X7-1,"+0.0%;-0.0%;0.0%") -> GT +21.7%; Deposits +29.0%; CA -1.2%
A34: 15 | B34: Growth & momentum | C34: YoY growth | D34: M ÷ LY(ref) − 1 | E34: Products, customer segments, GT | F34: ="GT "&TEXT(B1_MAB_Tables!E13/83098.91-1,"+0.0%;-0.0%;0.0%")&"; Deposits "&TEXT(B1_MAB_Tables!E10/58003.56-1,"+0.0%;-0.0%;0.0%")&"; INSIGNIA "&TEXT(B1_MAB_Tables!E16/39393-1,"+0.0%;-0.0%;0.0%") -> GT +38.9%; Deposits +55.0%; INSIGNIA +74.6%
A35: 16 | B35: Growth & momentum | C35: Diff as % of CM | D35: D_v ÷ M | E35: All lines × 3 bases | F35: ="GT: LM "&TEXT(B1_MAB_Tables!S13,"0.0%")&"; M-1 "&TEXT(B1_MAB_Tables!T13,"0.0%")&"; LY "&TEXT(B1_MAB_Tables!U13,"0.0%") -> GT: LM 17.8%; M-1 24.3%; LY 28.0%
A36: 17 | B36: Attribution | C36: Share of MoM TD diff from NR | D36: D_LM(NR TD) ÷ D_LM(TD) | E36: BAU | F36: =TEXT(B1_MAB_Tables!H69/B1_MAB_Tables!H10,"0.0%") -> 102.6%
A37: 18 | B37: Attribution | C37: Share of MoM GT diff from INSIGNIA | D37: D_LM(INSIGNIA) ÷ D_LM(GT) | E37: Customer segment | F37: =TEXT(B1_MAB_Tables!H16/B1_MAB_Tables!H13,"0.0%") -> 93.7%
A38: 19 | B38: Attribution | C38: Share of YoY GT diff from INSIGNIA TD | D38: D_LY(INSIGNIA TD) ÷ D_LY(GT) | E38: Customer segment | F38: =TEXT(B1_MAB_Tables!N15/B1_MAB_Tables!N13,"0.0%") -> 89.6%
A39: 20 | B39: Attribution | C39: Non-individual share of MoM TD diff | D39: (D_LM(TD) − D_LM Indi(TD)) ÷ D_LM(TD) | E39: Product | F39: =TEXT(1-B1_MAB_Tables!J10/B1_MAB_Tables!H10,"0.0%") -> 98.3%
A40: 21 | B40: Concentration | C40: Top segment share | D40: max sh(segment) | E40: Customer segment | F40: =TEXT(B1_MAB_Tables!V16,"0.0%")&" INSIGNIA" -> 59.6% INSIGNIA
A41: 22 | B41: Concentration | C41: HHI across customer segments | D41: Σ (100 × sh)² | E41: 4 segments | F41: =TEXT((B1_MAB_Tables!E16^2+B1_MAB_Tables!E19^2+B1_MAB_Tables!E22^2+B1_MAB_Tables!E25^2)/B1_MAB_Tables!E13^2*10000,"#,##0") -> 4,233
A42: 23 | B42: Concentration | C42: COOP bank share of MASS TD | D42: M(COOP TD) ÷ M(MASS TD) | E42: Derived vs customer | F42: =TEXT(B1_MAB_Tables!E53/B1_MAB_Tables!E24,"0.0%") -> 61.4%
...
