Workbook

Sheet README
A1: RBL Bank — Interest Rate Sensitivity: Deposits Maturity — page-wise metric extraction
A2: Source: 03_Interest_Rate_Sensitivity_Deposits_Maturity.pdf (1 page, 1 matrix; data to 15-May-2026) | ₹ Cr and account counts
A3: ⚠ DRAFT ONLY — Requires review and approval by a qualified Alvarez and Marsal professional before use.
A5: Sheet map
A6: B1_Rate_x_Maturity | B6: Rate bucket × maturity bucket matrix (Amount and No. of Accounts) with totals, shares, ATS and rate/maturity-weighted derivations
A7: B1_Metrics | B7: Notation + exhaustive metrics
A9: Colour legend
A10: Blue text | B10: Hard-coded input transcribed from the PDF
A11: Blue italic on grey | B11: Budget / projected value (ᴾ) transcribed from the PDF
A12: Black text | B12: Formula on the same sheet
A13: Green text | B13: Link to another sheet
A14: Yellow fill | B14: Data flag to review
A16: Key assumptions (confirm with client)
A17: 1 | B17: Blank cells placed by column reconciliation to the printed Grand Total (rows with fewer than 12 values); all rows and columns now tie.
A18: 2 | B18: Rate-bucket midpoints used for the weighted-average rate proxy: 3.00 / 3.75 / 4.875 / 5.75 / 6.25 / 6.75 / 8.00 / 9.25 %. The two open-ended buckets ('Upto 3.5%', '>9%') are judgement calls. Buckets 'Upto 3.5%' and '>3.25% to 4.25%' overlap between 3.25% and 3.5% as printed.
A19: 3 | B19: Maturity midpoints in days: 3 / 10.5 / 30 / 68 / 135.5 / 210.5 / 302.5 / 547.5 / 912.5 / 1,460 / 2,190 (> 5 Yrs set to 6 years). Null column carries ₹0 and is ignored.
A20: 4 | B20: The 7%–9% and 6.5%–7% buckets are printed out of ascending order; rows are re-ordered ascending here.
A21: 5 | B21: Data date 15-May-2026 differs from the MAB / Book Growth pages (Aug-2026); totals are not expected to tie across pages.
A22: Confidentiality | B22: Client-confidential RBL Bank data.
A24: ⚠ DRAFT ONLY — Requires review and approval by a qualified Alvarez and Marsal professional before use.

Sheet B1_Rate_x_Maturity
A1: Block 1 — Term deposits by rate bucket × contractual maturity bucket
A2: Source: Interest Rate Sensitivity – Deposits Maturity.pdf | ₹ Cr (Amount) and No. of Accounts | data to 15-May-2026
A3: ⚠ DRAFT ONLY — Requires review and approval by a qualified Alvarez and Marsal professional before use.
A5: A. Amount (₹ Cr) — source values blue; totals, shares and weighted maturity computed
A6: # | B6: Rate bucket | C6: Null | D6: Upto 6 Days | E6: 7 To 14 Days | F6: 15 To 45 Days | G6: 46 To 90 Days | H6: 91 To 180 Days | I6: 181 To 240 Days | J6: 241 To 364 Days | K6: 1 To 2 Yrs | L6: 2 To 3 Yrs | M6: 3 To 5 Yrs | N6: > 5 Yrs | O6: Printed total | P6: Σ maturity | Q6: Gap | R6: Share of book | S6: Rate midpoint % | T6: Σ Amount × days | U6: Wtd avg maturity (days) | V6: < 1 yr share of row
A7: 1 | B7: Upto 3.5% | C7: 0 | D7: 112.25 | E7: 106.74 | F7: 19.53 | G7: 27.56 | H7: 65.9 | I7: 9.9 | J7: 15.79 | K7: 33.8 | L7: 0 | M7: 0.03 | O7: 391.5 | P7: =SUM(C7:N7) -> 391.5 | Q7: =O7-P7 -> 0 | R7: =O7/$O$15 -> 0.0042188036 | S7: 3 | T7: =SUMPRODUCT(C7:N7,$C$17:$N$17) -> 38256.675 | U7: =T7/P7 -> 97.718199 | V7: =SUM(D7:J7)/P7 -> 0.91358876
A8: 2 | B8: >3.25% to 4.25% | D8: 494 | E8: 533.93 | F8: 1339.56 | G8: 426.22 | H8: 75.36 | I8: 234.11 | J8: 154.45 | K8: 20.48 | L8: 0.61 | O8: 3278.73 | P8: =SUM(C8:N8) -> 3278.72 | Q8: =O8-P8 -> 0.01 | R8: =O8/$O$15 -> 0.035331592 | S8: 3.75 | T8: =SUMPRODUCT(C8:N8,$C$17:$N$17) -> 194240.01 | U8: =T8/P8 -> 59.242634 | V8: =SUM(D8:J8)/P8 -> 0.99356761
A9: 3 | B9: >4.25% to 5.5% | D9: 256.29 | E9: 102.9 | F9: 1470.92 | G9: 485.76 | H9: 165.78 | I9: 23.82 | J9: 148.49 | K9: 269.26 | L9: 45.3 | M9: 203.67 | O9: 3172.19 | P9: =SUM(C9:N9) -> 3172.19 | Q9: =O9-P9 -> 0 | R9: =O9/$O$15 -> 0.034183517 | S9: 4.875 | T9: =SUMPRODUCT(C9:N9,$C$17:$N$17) -> 637518.43 | U9: =T9/P9 -> 200.97107 | V9: =SUM(D9:J9)/P9 -> 0.83663337
A10: 4 | B10: 5.5% to 6% | D10: 13.78 | E10: 16.73 | F10: 169.75 | G10: 138.53 | H10: 476.53 | I10: 43.17 | J10: 15.36 | K10: 168.98 | L10: 511.68 | M10: 490.11 | N10: 9.41 | O10: 2054.05 | P10: =SUM(C10:N10) -> 2054.03 | Q10: =O10-P10 -> 0.02 | R10: =O10/$O$15 -> 0.022134441 | S10: 5.75 | T10: =SUMPRODUCT(C10:N10,$C$17:$N$17) -> 1388626.1 | U10: =T10/P10 -> 676.04957 | V10: =SUM(D10:J10)/P10 -> 0.42543196
A11: 5 | B11: 6% to 6.5% | D11: 65.05 | E11: 100.08 | F11: 58.77 | G11: 284.64 | H11: 214.88 | I11: 138.09 | J11: 129.05 | K11: 159.9 | L11: 97.27 | M11: 4.88 | N11: 15.06 | O11: 1267.68 | P11: =SUM(C11:N11) -> 1267.67 | Q11: =O11-P11 -> 0.01 | R11: =O11/$O$15 -> 0.013660519 | S11: 6.25 | T11: =SUMPRODUCT(C11:N11,$C$17:$N$17) -> 335996.74 | U11: =T11/P11 -> 265.05064 | V11: =SUM(D11:J11)/P11 -> 0.7814021
A12: 6 | B12: 6.5% to 7% | D12: 63.53 | E12: 107.7 | F12: 253.39 | G12: 1333.98 | H12: 2221.55 | I12: 663.4 | J12: 454.95 | K12: 229.05 | L12: 57.32 | M12: 46.54 | N12: 80.03 | O12: 5511.44 | P12: =SUM(C12:N12) -> 5511.44 | Q12: =O12-P12 -> 0 | R12: =O12/$O$15 -> 0.059391272 | S12: 6.75 | T12: =SUMPRODUCT(C12:N12,$C$17:$N$17) -> 1098845.4 | U12: =T12/P12 -> 199.37536 | V12: =SUM(D12:J12)/P12 -> 0.92507584
A13: 7 | B13: 7% to 9% | D13: 951.02 | E13: 1570.34 | F13: 7177.88 | G13: 5943.63 | H13: 13584.3 | I13: 8337.26 | J13: 19837.96 | K13: 15859.19 | L13: 3323.2 | M13: 253.77 | N13: 208.67 | O13: 77047.21 | P13: =SUM(C13:N13) -> 77047.22 | Q13: =O13-P13 -> -0.01 | R13: =O13/$O$15 -> 0.83026066 | S13: 8 | T13: =SUMPRODUCT(C13:N13,$C$17:$N$17) -> 22778312 | U13: =T13/P13 -> 295.64093 | V13: =SUM(D13:J13)/P13 -> 0.7450287
A14: 8 | B14: >9% | C14: 0 | D14: 1.4 | E14: 2.8 | F14: 24.16 | G14: 13.29 | H14: 16.12 | I14: 4.11 | J14: 3.66 | K14: 0.83 | L14: 6.29 | M14: 0.34 | N14: 3.02 | O14: 76.02 | P14: =SUM(C14:N14) -> 76.02 | Q14: =O14-P14 -> 0 | R14: =O14/$O$15 -> 0.00081919145 | S14: 9.25 | T14: =SUMPRODUCT(C14:N14,$C$17:$N$17) -> 19122.935 | U14: =T14/P14 -> 251.55137 | V14: =SUM(D14:J14)/P14 -> 0.86214154
B15: Grand Total (printed) | C15: 0 | D15: 1957.33 | E15: 2541.23 | F15: 10513.97 | G15: 8653.6 | H15: 16820.42 | I15: 9453.86 | J15: 20759.71 | K15: 16741.5 | L15: 4041.67 | M15: 999.34 | N15: 316.19 | O15: 92798.82 | P15: =SUM(C15:N15) -> 92798.82 | Q15: =O15-P15 -> 0 | T15: =SUMPRODUCT(C15:N15,C17:N17) -> 26490923 | U15: =T15/P15 -> 285.46616 | V15: =SUM(D15:J15)/P15 -> 0.76186443
B16: Σ rate buckets (computed) / gap vs printed | C16: =C15-SUM(C7:C14) -> 0 | D16: =D15-SUM(D7:D14) -> 0.01 | E16: =E15-SUM(E7:E14) -> 0.01 | F16: =F15-SUM(F7:F14) -> 0.01 | G16: =G15-SUM(G7:G14) -> -0.01 | H16: =H15-SUM(H7:H14) -> 0 | I16: =I15-SUM(I7:I14) -> 0 | J16: =J15-SUM(J7:J14) -> 0 | ... O16: =O15-SUM(O7:O14) -> 0
B17: Maturity midpoint (days) — assumption | C17: 0 | D17: 3 | E17: 10.5 | F17: 30 | G17: 68 | H17: 135.5 | I17: 210.5 | J17: 302.5 | K17: 547.5 | L17: 912.5 | M17: 1460 | N17: 2190
B18: Share of book by maturity | C18: =C15/$O$15 -> 0 | D18: =D15/$O$15 -> 0.021092186 | E18: =E15/$O$15 -> 0.027384292 | F18: =F15/$O$15 -> 0.11329853 | G18: =G15/$O$15 -> 0.093251186 | H18: =H15/$O$15 -> 0.18125683 | I18: =I15/$O$15 -> 0.10187479 | J18: =J15/$O$15 -> 0.22370662 | ... N18: =N15/$O$15 -> 0.0034072632
B19: Cumulative share by maturity | C19: =SUM($C$15:C15)/$O$15 -> 0 | D19: =SUM($C$15:D15)/$O$15 -> 0.021092186 | E19: =SUM($C$15:E15)/$O$15 -> 0.048476478 | F19: =SUM($C$15:F15)/$O$15 -> 0.16177501 | G19: =SUM($C$15:G15)/$O$15 -> 0.2550262 | H19: =SUM($C$15:H15)/$O$15 -> 0.43628303 | I19: =SUM($C$15:I15)/$O$15 -> 0.53815781 | J19: =SUM($C$15:J15)/$O$15 -> 0.76186443 | ... N19: =SUM($C$15:N15)/$O$15 -> 1
B20: Σ Amount × rate midpoint (for weighted rate by maturity) | C20: =SUMPRODUCT(C7:C14,$S$7:$S$14) -> 0 | D20: =SUMPRODUCT(D7:D14,$S$7:$S$14) -> 11974.399 | E20: =SUMPRODUCT(E7:E14,$S$7:$S$14) -> 16861.388 | F20: =SUMPRODUCT(F7:F14,$S$7:$S$14) -> 72952.952 | G20: =SUMPRODUCT(G7:G14,$S$7:$S$14) -> 63300.97 | H20: =SUMPRODUCT(H7:H14,$S$7:$S$14) -> 129190.5 | I20: =SUMPRODUCT(I7:I14,$S$7:$S$14) -> 73349.072 | J20: =SUMPRODUCT(J7:J14,$S$7:$S$14) -> 164053.78 | ... O20: =SUMPRODUCT(O7:O14,$S$7:$S$14) -> 702951.04
B21: Weighted avg rate by maturity bucket (%) | C21: =IF(C15=0,"",C20/C15) | D21: =IF(D15=0,"",D20/D15) -> 6.117721 | E21: =IF(E15=0,"",E20/E15) -> 6.6351285 | F21: =IF(F15=0,"",F20/F15) -> 6.9386685 | G21: =IF(G15=0,"",G20/G15) -> 7.3149868 | H21: =IF(H15=0,"",H20/H15) -> 7.680575 | I21: =IF(I15=0,"",I20/I15) -> 7.7586375 | J21: =IF(J15=0,"",J20/J15) -> 7.9025081 | ... O21: =IF(O15=0,"",O20/O15) -> 7.5749997
B22: Share of column in 7%–9% + >9% buckets | C22: =IF(C15=0,"",(C13+C14)/C15) | D22: =IF(D15=0,"",(D13+D14)/D15) -> 0.48659143 | E22: =IF(E15=0,"",(E13+E14)/E15) -> 0.61904668 | F22: =IF(F15=0,"",(F13+F14)/F15) -> 0.6849972 | G22: =IF(G15=0,"",(G13+G14)/G15) -> 0.68837478 | H22: =IF(H15=0,"",(H13+H14)/H15) -> 0.80856602 | I22: =IF(I15=0,"",(I13+I14)/I15) -> 0.88232426 | J22: =IF(J15=0,"",(J13+J14)/J15) -> 0.95577539 | ... O22: =IF(O15=0,"",(O13+O14)/O15) -> 0.83107986
A24: B. No. of Accounts — source values blue; totals and ATS computed
A25: # | B25: Rate bucket | C25: Null | D25: Upto 6 Days | E25: 7 To 14 Days | F25: 15 To 45 Days | G25: 46 To 90 Days | H25: 91 To 180 Days | I25: 181 To 240 Days | J25: 241 To 364 Days | K25: 1 To 2 Yrs | L25: 2 To 3 Yrs | M25: 3 To 5 Yrs | N25: > 5 Yrs | O25: Printed total | P25: Σ maturity | Q25: Gap | R25: Share of accounts | S25: ATS (₹ lakh) = Amount × 100 ÷ accounts
A26: 1 | B26: Upto 3.5% | C26: 1 | D26: 24 | E26: 28 | F26: 32 | G26: 50 | H26: 71 | I26: 14 | J26: 31 | K26: 69 | L26: 1 | M26: 1 | O26: 322 | P26: =SUM(C26:N26) -> 322 | Q26: =O26-P26 -> 0 | R26: =O26/$O$34 -> 0.00049885975 | S26: =O7*100/O26 -> 121.58385
A27: 2 | B27: >3.25% to 4.25% | D27: 1009 | E27: 1222 | F27: 1457 | G27: 268 | H27: 162 | I27: 64 | J27: 516 | K27: 26 | L27: 4 | O27: 4728 | P27: =SUM(C27:N27) -> 4728 | Q27: =O27-P27 -> 0 | R27: =O27/$O$34 -> 0.0073248723 | S27: =O8*100/O27 -> 69.347081
A28: 3 | B28: >4.25% to 5.5% | D28: 719 | E28: 994 | F28: 3824 | G28: 4545 | H28: 1048 | I28: 68 | J28: 239 | K28: 475 | L28: 83 | M28: 223 | O28: 12218 | P28: =SUM(C28:N28) -> 12218 | Q28: =O28-P28 -> 0 | R28: =O28/$O$34 -> 0.018928784 | S28: =O9*100/O28 -> 25.963251
A29: 4 | B29: 5.5% to 6% | D29: 279 | E29: 505 | F29: 2012 | G29: 3336 | H29: 9702 | I29: 600 | J29: 63 | K29: 325 | L29: 754 | M29: 806 | N29: 311 | O29: 18693 | P29: =SUM(C29:N29) -> 18693 | Q29: =O29-P29 -> 0 | R29: =O29/$O$34 -> 0.028960203 | S29: =O10*100/O29 -> 10.988338
A30: 5 | B30: 6% to 6.5% | D30: 65 | E30: 113 | F30: 432 | G30: 789 | H30: 2823 | I30: 1670 | J30: 2223 | K30: 457 | L30: 232 | M30: 167 | N30: 326 | O30: 9297 | P30: =SUM(C30:N30) -> 9297 | Q30: =O30-P30 -> 0 | R30: =O30/$O$34 -> 0.014403413 | S30: =O11*100/O30 -> 13.635366
A31: 6 | B31: 6.5% to 7% | D31: 114 | E31: 165 | F31: 832 | G31: 1441 | H31: 1365 | I31: 481 | J31: 590 | K31: 1275 | L31: 32 | M31: 1635 | N31: 1119 | O31: 9049 | P31: =SUM(C31:N31) -> 9049 | Q31: =O31-P31 -> 0 | R31: =O31/$O$34 -> 0.014019198 | S31: =O12*100/O31 -> 60.90662
A32: 7 | B32: 7% to 9% | D32: 7172 | E32: 8706 | F32: 35726 | G32: 43933 | H32: 94810 | I32: 47789 | J32: 95708 | K32: 199141 | L32: 45590 | M32: 6163 | N32: 4400 | O32: 589138 | P32: =SUM(C32:N32) -> 589138 | Q32: =O32-P32 -> 0 | R32: =O32/$O$34 -> 0.91272433 | S32: =O13*100/O32 -> 13.077956
A33: 8 | B33: >9% | C33: 1 | D33: 82 | E33: 97 | F33: 544 | G33: 535 | H33: 440 | I33: 93 | J33: 63 | K33: 49 | L33: 7 | M33: 6 | N33: 110 | O33: 2027 | P33: =SUM(C33:N33) -> 2027 | Q33: =O33-P33 -> 0 | R33: =O33/$O$34 -> 0.0031403376 | S33: =O14*100/O33 -> 3.75037
B34: Grand Total (printed) | C34: 2 | D34: 9464 | E34: 11830 | F34: 44859 | G34: 54897 | H34: 110421 | I34: 50779 | J34: 99433 | K34: 201817 | L34: 46703 | M34: 9001 | N34: 6266 | O34: 645472 | P34: =SUM(C34:N34) -> 645472 | Q34: =O34-P34 -> 0 | S34: =O15*100/O34 -> 14.376893
B35: Σ rate buckets gap vs printed | C35: =C34-SUM(C26:C33) -> 0 | D35: =D34-SUM(D26:D33) -> 0 | E35: =E34-SUM(E26:E33) -> 0 | F35: =F34-SUM(F26:F33) -> 0 | G35: =G34-SUM(G26:G33) -> 0 | H35: =H34-SUM(H26:H33) -> 0 | I35: =I34-SUM(I26:I33) -> 0 | J35: =J34-SUM(J26:J33) -> 0 | ... O35: =O34-SUM(O26:O33) -> 0
B36: Share of accounts by maturity | C36: =C34/$O$34 -> 3.0985078e-06 | D36: =D34/$O$34 -> 0.014662139 | E36: =E34/$O$34 -> 0.018327673 | F36: =F34/$O$34 -> 0.06949798 | G36: =G34/$O$34 -> 0.08504939 | H36: =H34/$O$34 -> 0.17107016 | I36: =I34/$O$34 -> 0.078669563 | J36: =J34/$O$34 -> 0.15404696 | ... N36: =N34/$O$34 -> 0.0097076248
B37: ATS by maturity (₹ lakh) | C37: =IF(C34=0,"",C15*100/C34) -> 0 | D37: =IF(D34=0,"",D15*100/D34) -> 20.681847 | E37: =IF(E34=0,"",E15*100/E34) -> 21.481234 | F37: =IF(F34=0,"",F15*100/F34) -> 23.437816 | G37: =IF(G34=0,"",G15*100/G34) -> 15.763339 | H37: =IF(H34=0,"",H15*100/H34) -> 15.23299 | I37: =IF(I34=0,"",I15*100/I34) -> 18.617657 | J37: =IF(J34=0,"",J15*100/J34) -> 20.878089 | ... N37: =IF(N34=0,"",N15*100/N34) -> 5.0461219
A39: C. ATS matrix (₹ lakh) = Amount × 100 ÷ Accounts
A40: # | B40: Rate bucket | C40: Null | D40: Upto 6 Days | E40: 7 To 14 Days | F40: 15 To 45 Days | G40: 46 To 90 Days | H40: 91 To 180 Days | I40: 181 To 240 Days | J40: 241 To 364 Days | K40: 1 To 2 Yrs | L40: 2 To 3 Yrs | M40: 3 To 5 Yrs | N40: > 5 Yrs
A41: 1 | B41: Upto 3.5% | C41: =IF(OR(C26="",C26=0),"",C7*100/C26) -> 0 | D41: =IF(OR(D26="",D26=0),"",D7*100/D26) -> 467.70833 | E41: =IF(OR(E26="",E26=0),"",E7*100/E26) -> 381.21429 | F41: =IF(OR(F26="",F26=0),"",F7*100/F26) -> 61.03125 | G41: =IF(OR(G26="",G26=0),"",G7*100/G26) -> 55.12 | H41: =IF(OR(H26="",H26=0),"",H7*100/H26) -> 92.816901 | I41: =IF(OR(I26="",I26=0),"",I7*100/I26) -> 70.714286 | J41: =IF(OR(J26="",J26=0),"",J7*100/J26) -> 50.935484 | ... N41: =IF(OR(N26="",N26=0),"",N7*100/N26)
A42: 2 | B42: >3.25% to 4.25% | C42: =IF(OR(C27="",C27=0),"",C8*100/C27) | D42: =IF(OR(D27="",D27=0),"",D8*100/D27) -> 48.959366 | E42: =IF(OR(E27="",E27=0),"",E8*100/E27) -> 43.693126 | F42: =IF(OR(F27="",F27=0),"",F8*100/F27) -> 91.939602 | G42: =IF(OR(G27="",G27=0),"",G8*100/G27) -> 159.03731 | H42: =IF(OR(H27="",H27=0),"",H8*100/H27) -> 46.518519 | I42: =IF(OR(I27="",I27=0),"",I8*100/I27) -> 365.79688 | J42: =IF(OR(J27="",J27=0),"",J8*100/J27) -> 29.932171 | ... N42: =IF(OR(N27="",N27=0),"",N8*100/N27)
A43: 3 | B43: >4.25% to 5.5% | C43: =IF(OR(C28="",C28=0),"",C9*100/C28) | D43: =IF(OR(D28="",D28=0),"",D9*100/D28) -> 35.645341 | E43: =IF(OR(E28="",E28=0),"",E9*100/E28) -> 10.352113 | F43: =IF(OR(F28="",F28=0),"",F9*100/F28) -> 38.465481 | G43: =IF(OR(G28="",G28=0),"",G9*100/G28) -> 10.687789 | H43: =IF(OR(H28="",H28=0),"",H9*100/H28) -> 15.818702 | I43: =IF(OR(I28="",I28=0),"",I9*100/I28) -> 35.029412 | J43: =IF(OR(J28="",J28=0),"",J9*100/J28) -> 62.129707 | ... N43: =IF(OR(N28="",N28=0),"",N9*100/N28)
...

Sheet B1_Metrics
A1: Rate × maturity matrix: notation and metrics
A2: Format: Notation → Exhaustive metrics table | Example column = live Excel formula on the block sheet (green = cross-sheet)
A3: ⚠ DRAFT ONLY — Requires review and approval by a qualified Alvarez and Marsal professional before use.
A5: Notation
B6: Symbol | C6: Meaning
B7: A(r,m) | C7: Term-deposit amount (₹ Cr) in rate bucket r and maturity bucket m
B8: N(r,m) | C8: Number of accounts in the same cell
B9: A(r) / A(m) | C9: Row / column totals; A = Grand Total = 92,798.82
B10: sh(r), sh(m) | C10: A(r) ÷ A, A(m) ÷ A
B11: mid_r | C11: Rate-bucket midpoint (%) — analyst assumption
B12: d_m | C12: Maturity-bucket midpoint in days — analyst assumption
B13: WAR | C13: Weighted average rate proxy = Σ A × mid_r ÷ Σ A
B14: WAM | C14: Weighted average maturity = Σ A × d_m ÷ Σ A (days)
B15: ATS | C15: Average ticket size = A × 100 ÷ N, ₹ lakh
B16: ≤ 1 yr | C16: Maturity buckets up to 241–364 days
B17: Values are ₹ Cr (amount) and account counts; shares in %; ATS in ₹ lakh; midpoints are analyst assumptions.
A19: Exhaustive metrics table
A20: # | B20: Metric family | C20: Pipeline-ready metric | D20: Definition / formula | E20: Applies to | F20: Example
A21: 1 | B21: Fact lookup | C21: Cell amount | D21: A(r,m) | E21: 8 × 12 cells | F21: ="7%–9% × 241–364 d "&TEXT(B1_Rate_x_Maturity!J13,"#,##0.00;-#,##0.00;0.00")&"; 7%–9% × 1–2 yr "&TEXT(B1_Rate_x_Maturity!K13,"#,##0.00;-#,##0.00;0.00") -> 7%–9% × 241–364 d 19,837.96; 7%–9% × 1–2 yr 15,859.19
A22: 2 | B22: Fact lookup | C22: Cell accounts | D22: N(r,m) | E22: 8 × 12 cells | F22: ="7%–9% × 1–2 yr "&TEXT(B1_Rate_x_Maturity!K32,"#,##0")&"; 7%–9% × 91–180 d "&TEXT(B1_Rate_x_Maturity!H32,"#,##0") -> 7%–9% × 1–2 yr 199,141; 7%–9% × 91–180 d 94,810
A23: 3 | B23: Fact lookup | C23: Row totals | D23: A(r), N(r) | E23: 8 buckets | F23: =TEXT(B1_Rate_x_Maturity!O7,"#,##0.00;-#,##0.00;0.00")&" / "&TEXT(B1_Rate_x_Maturity!O8,"#,##0.00;-#,##0.00;0.00")&" / "&TEXT(B1_Rate_x_Maturity!O9,"#,##0.00;-#,##0.00;0.00")&" / "&TEXT(B1_Rate_x_Maturity!O10,"#,##0.00;-#,##0.00;0.00")&" / "&TEXT(B1_Rate_x_Maturity!O11,"#,##0.00;-#,##0.00;0.00")&" / "&TEXT(B1_Rate_x_Maturity!O12,"#,##0.00;-#,##0.00;0.00")&" / "&TEXT(B1_Rate_x_Maturity!O13,"#,##0.00;-#,##0.00;0.00")&" / "&TEXT(B1_Rate_x_Maturity!O14,"#,##0.00;-#,##0.00;0.00") -> 391.50 / 3,278.73 / 3,172.19 / 2,054.05 / 1,267.68 / 5,511.44 / 77,047.21 / 76.02
A24: 4 | B24: Fact lookup | C24: Column totals | D24: A(m), N(m) | E24: 12 maturity buckets | F24: =TEXT(B1_Rate_x_Maturity!D15,"#,##0.00;-#,##0.00;0.00")&" / "&TEXT(B1_Rate_x_Maturity!E15,"#,##0.00;-#,##0.00;0.00")&" / "&TEXT(B1_Rate_x_Maturity!F15,"#,##0.00;-#,##0.00;0.00")&" / "&TEXT(B1_Rate_x_Maturity!G15,"#,##0.00;-#,##0.00;0.00")&" / "&TEXT(B1_Rate_x_Maturity!H15,"#,##0.00;-#,##0.00;0.00")&" / "&TEXT(B1_Rate_x_Maturity!I15,"#,##0.00;-#,##0.00;0.00")&" / "&TEXT(B1_Rate_x_Maturity!J15,"#,##0.00;-#,##0.00;0.00")&" / "&TEXT(B1_Rate_x_Maturity!K15,"#,##0.00;-#,##0.00;0.00")&" / "&TEXT(B1_Rate_x_Maturity!L15,"#,##0.00;-#,##0.00;0.00")&" / "&TEXT(B1_Rate_x_Maturity!M15,"#,##0.00;-#,##0.00;0.00")&" / "&TEXT(B1_Rate_x_Maturity!N15,"#,##0.00;-#,##0.00;0.00") -> 1,957.33 / 2,541.23 / 10,513.97 / 8,653.60 / 16,820.42 / 9,453.86 / 20,759.71 / 16,741.50 / 4,041.67 / 999.34 / 316.19
A25: 5 | B25: Roll-up check | C25: Rows to Grand Total | D25: A(r) − Σm A(r,m) | E25: 8 rows | F25: =TEXT(B1_Rate_x_Maturity!Q7,"#,##0.00;-#,##0.00;0.00")&" / "&TEXT(B1_Rate_x_Maturity!Q8,"#,##0.00;-#,##0.00;0.00")&" / "&TEXT(B1_Rate_x_Maturity!Q9,"#,##0.00;-#,##0.00;0.00")&" / "&TEXT(B1_Rate_x_Maturity!Q10,"#,##0.00;-#,##0.00;0.00")&" / "&TEXT(B1_Rate_x_Maturity!Q11,"#,##0.00;-#,##0.00;0.00")&" / "&TEXT(B1_Rate_x_Maturity!Q12,"#,##0.00;-#,##0.00;0.00")&" / "&TEXT(B1_Rate_x_Maturity!Q13,"#,##0.00;-#,##0.00;0.00")&" / "&TEXT(B1_Rate_x_Maturity!Q14,"#,##0.00;-#,##0.00;0.00") -> 0.00 / 0.01 / 0.00 / 0.02 / 0.01 / 0.00 / -0.01 / 0.00
A26: 6 | B26: Roll-up check | C26: Columns to Grand Total | D26: A(m) − Σr A(r,m) | E26: 12 columns | F26: ="max |gap| "&TEXT(MAX(ABS(MIN(B1_Rate_x_Maturity!C16:O16)),MAX(B1_Rate_x_Maturity!C16:O16)),"#,##0.00;-#,##0.00;0.00") -> max |gap| 0.01
A27: 7 | B27: Roll-up check | C27: Accounts roll-up | D27: N(m) − Σr N(r,m) | E27: 12 columns + 8 rows | F27: ="Σ |gaps| "&TEXT(SUMPRODUCT(ABS(B1_Rate_x_Maturity!C35:O35))+SUMPRODUCT(ABS(B1_Rate_x_Maturity!Q26:Q33)),"#,##0") -> Σ |gaps| 0
A28: 8 | B28: Mix & share | C28: Rate-bucket share of book | D28: sh(r) | E28: 8 buckets | F28: =TEXT(B1_Rate_x_Maturity!R7,"0.0%")&" / "&TEXT(B1_Rate_x_Maturity!R8,"0.0%")&" / "&TEXT(B1_Rate_x_Maturity!R9,"0.0%")&" / "&TEXT(B1_Rate_x_Maturity!R10,"0.0%")&" / "&TEXT(B1_Rate_x_Maturity!R11,"0.0%")&" / "&TEXT(B1_Rate_x_Maturity!R12,"0.0%")&" / "&TEXT(B1_Rate_x_Maturity!R13,"0.0%")&" / "&TEXT(B1_Rate_x_Maturity!R14,"0.0%") -> 0.4% / 3.5% / 3.4% / 2.2% / 1.4% / 5.9% / 83.0% / 0.1%
A29: 9 | B29: Mix & share | C29: Maturity-bucket share of book | D29: sh(m) | E29: 11 buckets | F29: =TEXT(B1_Rate_x_Maturity!D18,"0.0%")&" / "&TEXT(B1_Rate_x_Maturity!E18,"0.0%")&" / "&TEXT(B1_Rate_x_Maturity!F18,"0.0%")&" / "&TEXT(B1_Rate_x_Maturity!G18,"0.0%")&" / "&TEXT(B1_Rate_x_Maturity!H18,"0.0%")&" / "&TEXT(B1_Rate_x_Maturity!I18,"0.0%")&" / "&TEXT(B1_Rate_x_Maturity!J18,"0.0%")&" / "&TEXT(B1_Rate_x_Maturity!K18,"0.0%")&" / "&TEXT(B1_Rate_x_Maturity!L18,"0.0%")&" / "&TEXT(B1_Rate_x_Maturity!M18,"0.0%")&" / "&TEXT(B1_Rate_x_Maturity!N18,"0.0%") -> 2.1% / 2.7% / 11.3% / 9.3% / 18.1% / 10.2% / 22.4% / 18.0% / 4.4% / 1.1% / 0.3%
A30: 10 | B30: Mix & share | C30: Cumulative maturity profile | D30: Σ sh(m) up to bucket | E30: 11 buckets | F30: =TEXT(B1_Rate_x_Maturity!D19,"0.0%")&" / "&TEXT(B1_Rate_x_Maturity!E19,"0.0%")&" / "&TEXT(B1_Rate_x_Maturity!F19,"0.0%")&" / "&TEXT(B1_Rate_x_Maturity!G19,"0.0%")&" / "&TEXT(B1_Rate_x_Maturity!H19,"0.0%")&" / "&TEXT(B1_Rate_x_Maturity!I19,"0.0%")&" / "&TEXT(B1_Rate_x_Maturity!J19,"0.0%")&" / "&TEXT(B1_Rate_x_Maturity!K19,"0.0%")&" / "&TEXT(B1_Rate_x_Maturity!L19,"0.0%")&" / "&TEXT(B1_Rate_x_Maturity!M19,"0.0%")&" / "&TEXT(B1_Rate_x_Maturity!N19,"0.0%") -> 2.1% / 4.8% / 16.2% / 25.5% / 43.6% / 53.8% / 76.2% / 94.2% / 98.6% / 99.7% / 100.0%
A31: 11 | B31: Mix & share | C31: ≤ 1 yr share | D31: Σ A(m ≤ 364 d) ÷ A | E31: Book + each rate bucket | F31: ="Book "&TEXT(B1_Rate_x_Maturity!V15,"0.0%")&"; 7%–9% "&TEXT(B1_Rate_x_Maturity!V13,"0.0%")&"; 5.5%–6% "&TEXT(B1_Rate_x_Maturity!V10,"0.0%") -> Book 76.2%; 7%–9% 74.5%; 5.5%–6% 42.5%
A32: 12 | B32: Mix & share | C32: ≤ 90 d share | D32: Σ A(m ≤ 90 d) ÷ A | E32: Book | F32: =TEXT(B1_Rate_x_Maturity!G19,"0.0%") -> 25.5%
A33: 13 | B33: Mix & share | C33: High-rate share by maturity | D33: (A(7–9%) + A(> 9%)) ÷ A(m) | E33: 11 buckets | F33: =TEXT(B1_Rate_x_Maturity!D22,"0.0%")&" / "&TEXT(B1_Rate_x_Maturity!E22,"0.0%")&" / "&TEXT(B1_Rate_x_Maturity!F22,"0.0%")&" / "&TEXT(B1_Rate_x_Maturity!G22,"0.0%")&" / "&TEXT(B1_Rate_x_Maturity!H22,"0.0%")&" / "&TEXT(B1_Rate_x_Maturity!I22,"0.0%")&" / "&TEXT(B1_Rate_x_Maturity!J22,"0.0%")&" / "&TEXT(B1_Rate_x_Maturity!K22,"0.0%")&" / "&TEXT(B1_Rate_x_Maturity!L22,"0.0%")&" / "&TEXT(B1_Rate_x_Maturity!M22,"0.0%")&" / "&TEXT(B1_Rate_x_Maturity!N22,"0.0%") -> 48.7% / 61.9% / 68.5% / 68.8% / 80.9% / 88.2% / 95.6% / 94.7% / 82.4% / 25.4% / 67.0%
A34: 14 | B34: Mix & share | C34: Low-rate share (≤ 5.5%) | D34: Σ sh(r ≤ 5.5%) | E34: Book | F34: =TEXT(B1_Rate_x_Maturity!R7+B1_Rate_x_Maturity!R8+B1_Rate_x_Maturity!R9,"0.0%") -> 7.4%
A35: 15 | B35: Mix & share | C35: Account share by maturity | D35: N(m) ÷ N | E35: 11 buckets | F35: =TEXT(B1_Rate_x_Maturity!D36,"0.0%")&" / "&TEXT(B1_Rate_x_Maturity!E36,"0.0%")&" / "&TEXT(B1_Rate_x_Maturity!F36,"0.0%")&" / "&TEXT(B1_Rate_x_Maturity!G36,"0.0%")&" / "&TEXT(B1_Rate_x_Maturity!H36,"0.0%")&" / "&TEXT(B1_Rate_x_Maturity!I36,"0.0%")&" / "&TEXT(B1_Rate_x_Maturity!J36,"0.0%")&" / "&TEXT(B1_Rate_x_Maturity!K36,"0.0%")&" / "&TEXT(B1_Rate_x_Maturity!L36,"0.0%")&" / "&TEXT(B1_Rate_x_Maturity!M36,"0.0%")&" / "&TEXT(B1_Rate_x_Maturity!N36,"0.0%") -> 1.5% / 1.8% / 6.9% / 8.5% / 17.1% / 7.9% / 15.4% / 31.3% / 7.2% / 1.4% / 1.0%
A36: 16 | B36: Pricing | C36: Weighted average rate proxy | D36: WAR = Σ A × mid_r ÷ A | E36: Book + by maturity | F36: ="Book "&TEXT(B1_Rate_x_Maturity!O21,"0.00")&"%; by maturity "&TEXT(B1_Rate_x_Maturity!D21,"0.00")&" / "&TEXT(B1_Rate_x_Maturity!E21,"0.00")&" / "&TEXT(B1_Rate_x_Maturity!F21,"0.00")&" / "&TEXT(B1_Rate_x_Maturity!G21,"0.00")&" / "&TEXT(B1_Rate_x_Maturity!H21,"0.00")&" / "&TEXT(B1_Rate_x_Maturity!I21,"0.00")&" / "&TEXT(B1_Rate_x_Maturity!J21,"0.00")&" / "&TEXT(B1_Rate_x_Maturity!K21,"0.00")&" / "&TEXT(B1_Rate_x_Maturity!L21,"0.00")&" / "&TEXT(B1_Rate_x_Maturity!M21,"0.00")&" / "&TEXT(B1_Rate_x_Maturity!N21,"0.00") -> Book 7.57%; by maturity 6.12 / 6.64 / 6.94 / 7.31 / 7.68 / 7.76 / 7.90 / 7.88 / 7.62 / 6.19 / 7.55
A37: 17 | B37: Pricing | C37: Rate midpoint | D37: mid_r (assumption) | E37: 8 buckets | F37: =TEXT(B1_Rate_x_Maturity!S7,"0.000")&" / "&TEXT(B1_Rate_x_Maturity!S8,"0.000")&" / "&TEXT(B1_Rate_x_Maturity!S9,"0.000")&" / "&TEXT(B1_Rate_x_Maturity!S10,"0.000")&" / "&TEXT(B1_Rate_x_Maturity!S11,"0.000")&" / "&TEXT(B1_Rate_x_Maturity!S12,"0.000")&" / "&TEXT(B1_Rate_x_Maturity!S13,"0.000")&" / "&TEXT(B1_Rate_x_Maturity!S14,"0.000") -> 3.000 / 3.750 / 4.875 / 5.750 / 6.250 / 6.750 / 8.000 / 9.250
A38: 18 | B38: Pricing | C38: Illustrative 50 bp repricing saving on 7–9% ≤ 1 yr | D38: Σ A(7–9%, ≤ 364 d) × 0.005 | E38: Illustrative | F38: =TEXT(SUM(B1_Rate_x_Maturity!D13:J13)*0.005,"#,##0.00;-#,##0.00;0.00")&" per year" -> 287.01 per year
A39: 19 | B39: Maturity | C39: Weighted average maturity | D39: WAM (days) | E39: Book + each rate bucket | F39: ="Book "&TEXT(B1_Rate_x_Maturity!U15,"#,##0.0")&" days; by bucket "&TEXT(B1_Rate_x_Maturity!U7,"#,##0.0")&" / "&TEXT(B1_Rate_x_Maturity!U8,"#,##0.0")&" / "&TEXT(B1_Rate_x_Maturity!U9,"#,##0.0")&" / "&TEXT(B1_Rate_x_Maturity!U10,"#,##0.0")&" / "&TEXT(B1_Rate_x_Maturity!U11,"#,##0.0")&" / "&TEXT(B1_Rate_x_Maturity!U12,"#,##0.0")&" / "&TEXT(B1_Rate_x_Maturity!U13,"#,##0.0")&" / "&TEXT(B1_Rate_x_Maturity!U14,"#,##0.0") -> Book 285.5 days; by bucket 97.7 / 59.2 / 201.0 / 676.0 / 265.1 / 199.4 / 295.6 / 251.6
A40: 20 | B40: Maturity | C40: Maturity midpoint | D40: d_m (assumption) | E40: 12 buckets | F40: =TEXT(B1_Rate_x_Maturity!D17,"#,##0.0")&" / "&TEXT(B1_Rate_x_Maturity!E17,"#,##0.0")&" / "&TEXT(B1_Rate_x_Maturity!F17,"#,##0.0")&" / "&TEXT(B1_Rate_x_Maturity!G17,"#,##0.0")&" / "&TEXT(B1_Rate_x_Maturity!H17,"#,##0.0")&" / "&TEXT(B1_Rate_x_Maturity!I17,"#,##0.0")&" / "&TEXT(B1_Rate_x_Maturity!J17,"#,##0.0")&" / "&TEXT(B1_Rate_x_Maturity!K17,"#,##0.0")&" / "&TEXT(B1_Rate_x_Maturity!L17,"#,##0.0")&" / "&TEXT(B1_Rate_x_Maturity!M17,"#,##0.0")&" / "&TEXT(B1_Rate_x_Maturity!N17,"#,##0.0") -> 3.0 / 10.5 / 30.0 / 68.0 / 135.5 / 210.5 / 302.5 / 547.5 / 912.5 / 1,460.0 / 2,190.0
A41: 21 | B41: Ticket size | C41: ATS by rate bucket | D41: A(r) × 100 ÷ N(r) | E41: 8 buckets | F41: =TEXT(B1_Rate_x_Maturity!S26,"#,##0.00")&" / "&TEXT(B1_Rate_x_Maturity!S27,"#,##0.00")&" / "&TEXT(B1_Rate_x_Maturity!S28,"#,##0.00")&" / "&TEXT(B1_Rate_x_Maturity!S29,"#,##0.00")&" / "&TEXT(B1_Rate_x_Maturity!S30,"#,##0.00")&" / "&TEXT(B1_Rate_x_Maturity!S31,"#,##0.00")&" / "&TEXT(B1_Rate_x_Maturity!S32,"#,##0.00")&" / "&TEXT(B1_Rate_x_Maturity!S33,"#,##0.00")&" ₹ lakh" -> 121.58 / 69.35 / 25.96 / 10.99 / 13.64 / 60.91 / 13.08 / 3.75 ₹ lakh
A42: 22 | B42: Ticket size | C42: ATS by maturity bucket | D42: A(m) × 100 ÷ N(m) | E42: 11 buckets | F42: =TEXT(B1_Rate_x_Maturity!D37,"#,##0.00")&" / "&TEXT(B1_Rate_x_Maturity!E37,"#,##0.00")&" / "&TEXT(B1_Rate_x_Maturity!F37,"#,##0.00")&" / "&TEXT(B1_Rate_x_Maturity!G37,"#,##0.00")&" / "&TEXT(B1_Rate_x_Maturity!H37,"#,##0.00")&" / "&TEXT(B1_Rate_x_Maturity!I37,"#,##0.00")&" / "&TEXT(B1_Rate_x_Maturity!J37,"#,##0.00")&" / "&TEXT(B1_Rate_x_Maturity!K37,"#,##0.00")&" / "&TEXT(B1_Rate_x_Maturity!L37,"#,##0.00")&" / "&TEXT(B1_Rate_x_Maturity!M37,"#,##0.00")&" / "&TEXT(B1_Rate_x_Maturity!N37,"#,##0.00")&" ₹ lakh" -> 20.68 / 21.48 / 23.44 / 15.76 / 15.23 / 18.62 / 20.88 / 8.30 / 8.65 / 11.10 / 5.05 ₹ lakh
...
