Workbook

Sheet README
A1: RBL Bank — New Originations, Month-wise (SA customers): page-wise metric extraction
A2: Source: 04_New_Originations_Month_Wise.pdf (1 page, 2 tables: # customers × ATS and # customers × Sanction) | Mar-25 to Mar-26
A3: ⚠ DRAFT ONLY — Requires review and approval by a qualified Alvarez and Marsal professional before use.
A5: Sheet map
A6: B1_Originations | B6: Product × footprint × month: # customers, ATS (₹ lakh), Sanction (₹ Cr), with implied-sanction check, roll-ups by product / footprint / month and growth
A7: B1_Metrics | B7: Notation + exhaustive metrics
A9: Colour legend
A10: Blue text | B10: Hard-coded input transcribed from the PDF
A11: Blue italic on grey | B11: Budget / projected value (ᴾ) transcribed from the PDF
A12: Black text | B12: Formula on the same sheet
A13: Green text | B13: Link to another sheet
A14: Yellow fill | B14: Data flag to review
A16: Key assumptions (confirm with client)
A17: 1 | B17: Months are re-ordered chronologically (Mar-25 → Mar-26). Mar-26 is a partial month (customer counts ~5% of a normal month) and is excluded from run-rates unless stated.
A18: 2 | B18: The second table's month headers are mis-labelled on the page (Mar-25, Feb-25, Jan-25, Dec-24 …); customer counts are identical to the first table, so the Sanction columns are mapped to the first table's months.
A19: 3 | B19: Sanction ≈ # × ATS ÷ 100 (ATS in ₹ lakh → ₹ Cr); implied sanction is checked against printed sanction (rounding to whole ₹ Cr).
A20: 4 | B20: 'Customer Footprint # Customers' is taken as the 13-month distinct customer count for the row.
A21: 5 | B21: 'SA' customer type filter — origination counts are SA (savings-account) customers taking the product; OFFUS / ONUS denote the credit-footprint flag.
A22: Confidentiality | B22: Client-confidential RBL Bank data.
A24: ⚠ DRAFT ONLY — Requires review and approval by a qualified Alvarez and Marsal professional before use.

Sheet B1_Originations
A1: Block 1 — New originations by product × footprint × month
A2: Source: New Originations – Month Wise.pdf | # distinct customers, ATS ₹ lakh, Sanction ₹ Cr | Mar-25 … Mar-26 (Mar-26 partial)
A3: ⚠ DRAFT ONLY — Requires review and approval by a qualified Alvarez and Marsal professional before use.
A5: A. # Distinct customers originated per month (blue) — row totals and growth computed
A6: # | B6: Product | C6: Footprint | D6: 13M distinct customers | E6: Mar-25 | F6: Apr-25 | G6: May-25 | H6: Jun-25 | I6: Jul-25 | J6: Aug-25 | K6: Sep-25 | L6: Oct-25 | M6: Nov-25 | N6: Dec-25 | O6: Jan-26 | P6: Feb-26 | Q6: Mar-26 | R6: Σ Apr-25…Feb-26 (11 full months) | S6: Avg / month (11M) | T6: Feb-26 vs Apr-25 | U6: Feb-26 vs Mar-25
A7: 1 | B7: Housing Loan | C7: OFFUS | D7: 35881 | E7: 3528 | F7: 1893 | G7: 2561 | H7: 2665 | I7: 2843 | J7: 2796 | K7: 3071 | L7: 2580 | M7: 2924 | N7: 3203 | O7: 2830 | P7: 3002 | Q7: 133 | R7: =SUM(F7:P7) -> 30368 | S7: =R7/11 -> 2760.7273 | T7: =IF(F7=0,"n/a",P7/F7-1) -> 0.58584258 | U7: =IF(E7=0,"n/a",P7/E7-1) -> -0.14909297
A8: 2 | B8: Housing Loan | C8: ONUS | D8: 4974 | E8: 481 | F8: 309 | G8: 411 | H8: 362 | I8: 398 | J8: 357 | K8: 433 | L8: 398 | M8: 413 | N8: 397 | O8: 428 | P8: 442 | Q8: 0 | R8: =SUM(F8:P8) -> 4348 | S8: =R8/11 -> 395.27273 | T8: =IF(F8=0,"n/a",P8/F8-1) -> 0.43042071 | U8: =IF(E8=0,"n/a",P8/E8-1) -> -0.081081081
A9: 3 | B9: Property Loan | C9: OFFUS | D9: 24378 | E9: 2395 | F9: 1391 | G9: 1694 | H9: 1755 | I9: 1959 | J9: 1819 | K9: 2061 | L9: 1853 | M9: 1934 | N9: 2147 | O9: 1985 | P9: 1995 | Q9: 31 | R9: =SUM(F9:P9) -> 20593 | S9: =R9/11 -> 1872.0909 | T9: =IF(F9=0,"n/a",P9/F9-1) -> 0.43421999 | U9: =IF(E9=0,"n/a",P9/E9-1) -> -0.16701461
A10: 4 | B10: Property Loan | C10: ONUS | D10: 1945 | E10: 144 | F10: 72 | G10: 109 | H10: 158 | I10: 182 | J10: 192 | K10: 216 | L10: 202 | M10: 207 | N10: 203 | O10: 224 | P10: 200 | Q10: 0 | R10: =SUM(F10:P10) -> 1965 | S10: =R10/11 -> 178.63636 | T10: =IF(F10=0,"n/a",P10/F10-1) -> 1.7777778 | U10: =IF(E10=0,"n/a",P10/E10-1) -> 0.38888889
A11: 5 | B11: Gold Loan | C11: OFFUS | D11: 132558 | E11: 5718 | F11: 6331 | G11: 9260 | H11: 9374 | I11: 10635 | J11: 10120 | K11: 13881 | L11: 17869 | M11: 20113 | N11: 23679 | O11: 28506 | P11: 38463 | Q11: 4608 | R11: =SUM(F11:P11) -> 188231 | S11: =R11/11 -> 17111.909 | T11: =IF(F11=0,"n/a",P11/F11-1) -> 5.0753435 | U11: =IF(E11=0,"n/a",P11/E11-1) -> 5.7266527
A12: 6 | B12: Gold Loan | C12: ONUS | D12: 13102 | E12: 303 | F12: 404 | G12: 579 | H12: 627 | I12: 854 | J12: 911 | K12: 1459 | L12: 1782 | M12: 2745 | N12: 3345 | O12: 3801 | P12: 3524 | Q12: 0 | R12: =SUM(F12:P12) -> 20031 | S12: =R12/11 -> 1821 | T12: =IF(F12=0,"n/a",P12/F12-1) -> 7.7227723 | U12: =IF(E12=0,"n/a",P12/E12-1) -> 10.630363
A13: 7 | B13: Two Wheeler Loan | C13: OFFUS | D13: 49237 | E13: 3650 | F13: 3688 | G13: 3628 | H13: 3680 | I13: 3594 | J13: 3712 | K13: 3616 | L13: 7101 | M13: 4185 | N13: 3315 | O13: 3965 | P13: 3425 | Q13: 470 | R13: =SUM(F13:P13) -> 43909 | S13: =R13/11 -> 3991.7273 | T13: =IF(F13=0,"n/a",P13/F13-1) -> -0.071312364 | U13: =IF(E13=0,"n/a",P13/E13-1) -> -0.061643836
A14: 8 | B14: Two Wheeler Loan | C14: ONUS | D14: 434 | E14: 38 | F14: 43 | G14: 54 | H14: 33 | I14: 41 | J14: 25 | K14: 20 | L14: 58 | M14: 29 | N14: 26 | O14: 25 | P14: 13 | Q14: 0 | R14: =SUM(F14:P14) -> 367 | S14: =R14/11 -> 33.363636 | T14: =IF(F14=0,"n/a",P14/F14-1) -> -0.69767442 | U14: =IF(E14=0,"n/a",P14/E14-1) -> -0.65789474
A15: 9 | B15: Auto Loan | C15: OFFUS | D15: 32479 | E15: 2596 | F15: 2052 | G15: 2125 | H15: 2210 | I15: 2473 | J15: 2413 | K15: 2784 | L15: 3387 | M15: 2342 | N15: 3275 | O15: 2356 | P15: 2318 | Q15: 147 | R15: =SUM(F15:P15) -> 27735 | S15: =R15/11 -> 2521.3636 | T15: =IF(F15=0,"n/a",P15/F15-1) -> 0.12962963 | U15: =IF(E15=0,"n/a",P15/E15-1) -> -0.10708783
A16: 10 | B16: Auto Loan | C16: ONUS | D16: 86 | E16: 9 | F16: 11 | G16: 6 | H16: 3 | I16: 5 | J16: 6 | K16: 11 | L16: 12 | M16: 4 | N16: 0 | O16: 9 | P16: 11 | Q16: 0 | R16: =SUM(F16:P16) -> 78 | S16: =R16/11 -> 7.0909091 | T16: =IF(F16=0,"n/a",P16/F16-1) -> 0 | U16: =IF(E16=0,"n/a",P16/E16-1) -> 0.22222222
A17: 11 | B17: Rural Vehicle Finance | C17: OFFUS | D17: 4311 | E17: 332 | F17: 276 | G17: 333 | H17: 365 | I17: 336 | J17: 255 | K17: 289 | L17: 484 | M17: 417 | N17: 318 | O17: 335 | P17: 276 | Q17: 13 | R17: =SUM(F17:P17) -> 3684 | S17: =R17/11 -> 334.90909 | T17: =IF(F17=0,"n/a",P17/F17-1) -> 0 | U17: =IF(E17=0,"n/a",P17/E17-1) -> -0.1686747
A18: 12 | B18: Rural Vehicle Finance | C18: ONUS | D18: 240 | E18: 21 | F18: 10 | G18: 17 | H18: 14 | I18: 14 | J18: 13 | K18: 17 | L18: 23 | M18: 31 | N18: 24 | O18: 86 | P18: 249 | Q18: 0 | R18: =SUM(F18:P18) -> 498 | S18: =R18/11 -> 45.272727 | T18: =IF(F18=0,"n/a",P18/F18-1) -> 23.9 | U18: =IF(E18=0,"n/a",P18/E18-1) -> 10.857143
... A34: 28 | B34: Used Car Loan | C34: ONUS | D34: 67 | E34: 6 | F34: 4 | G34: 3 | H34: 5 | I34: 3 | J34: 12 | K34: 1 | L34: 4 | M34: 6 | N34: 2 | O34: 2 | P34: 4 | Q34: 0 | R34: =SUM(F34:P34) -> 46 | S34: =R34/11 -> 4.1818182 | T34: =IF(F34=0,"n/a",P34/F34-1) -> 0 | U34: =IF(E34=0,"n/a",P34/E34-1) -> -0.33333333
A38: B. ATS (₹ lakh) per month (blue) — 11M weighted average and growth computed
A39: # | B39: Product | C39: Footprint | D39: 13M distinct customers | E39: Mar-25 | F39: Apr-25 | G39: May-25 | H39: Jun-25 | I39: Jul-25 | J39: Aug-25 | K39: Sep-25 | L39: Oct-25 | M39: Nov-25 | N39: Dec-25 | O39: Jan-26 | P39: Feb-26 | Q39: Mar-26 | R39: 11M Σ or wtd avg | S39: Feb-26 vs Apr-25 | T39: Feb-26 vs Mar-25 | U39: Implied check
A40: 1 | B40: Housing Loan | C40: OFFUS | D40: 35881 | E40: 61.17 | F40: 55.3 | G40: 55.16 | H40: 54.57 | I40: 57.33 | J40: 61.59 | K40: 65.23 | L40: 66.53 | M40: 61 | N40: 67.53 | O40: 60.46 | P40: 58.26 | Q40: 62.9 | R40: =IFERROR(SUMPRODUCT(F40:P40,F7:P7)/SUM(F7:P7),"n/a") -> 60.56379 | S40: =IF(F40=0,"n/a",P40/F40-1) -> 0.053526221 | T40: =IF(E40=0,"n/a",P40/E40-1) -> -0.047572339
A41: 2 | B41: Housing Loan | C41: ONUS | D41: 4974 | E41: 28.96 | F41: 30.02 | G41: 28.03 | H41: 34.41 | I41: 26.93 | J41: 29.09 | K41: 60.02 | L41: 39.94 | M41: 36.66 | N41: 32.41 | O41: 33.07 | P41: 31.48 | Q41: 0 | R41: =IFERROR(SUMPRODUCT(F41:P41,F8:P8)/SUM(F8:P8),"n/a") -> 35.031382 | S41: =IF(F41=0,"n/a",P41/F41-1) -> 0.048634244 | T41: =IF(E41=0,"n/a",P41/E41-1) -> 0.087016575
A42: 3 | B42: Property Loan | C42: OFFUS | D42: 24378 | E42: 83.65 | F42: 85.37 | G42: 84.36 | H42: 79.05 | I42: 78.3 | J42: 97.73 | K42: 105.08 | L42: 86.23 | M42: 90.35 | N42: 109.91 | O42: 108.89 | P42: 89 | Q42: 99.06 | R42: =IFERROR(SUMPRODUCT(F42:P42,F9:P9)/SUM(F9:P9),"n/a") -> 92.862537 | S42: =IF(F42=0,"n/a",P42/F42-1) -> 0.042520792 | T42: =IF(E42=0,"n/a",P42/E42-1) -> 0.063956964
A43: 4 | B43: Property Loan | C43: ONUS | D43: 1945 | E43: 160.57 | F43: 248.07 | G43: 62.66 | H43: 89.14 | I43: 74.67 | J43: 83.27 | K43: 79.28 | L43: 88.62 | M43: 88.38 | N43: 114.14 | O43: 93.09 | P43: 74.77 | Q43: 0 | R43: =IFERROR(SUMPRODUCT(F43:P43,F10:P10)/SUM(F10:P10),"n/a") -> 91.933761 | S43: =IF(F43=0,"n/a",P43/F43-1) -> -0.69859314 | T43: =IF(E43=0,"n/a",P43/E43-1) -> -0.53434639
A44: 5 | B44: Gold Loan | C44: OFFUS | D44: 132558 | E44: 2.56 | F44: 2.41 | G44: 2.58 | H44: 2.6 | I44: 2.77 | J44: 2.92 | K44: 3.23 | L44: 3.47 | M44: 3.46 | N44: 3.85 | O44: 4.16 | P44: 4.71 | Q44: 4.68 | R44: =IFERROR(SUMPRODUCT(F44:P44,F11:P11)/SUM(F11:P11),"n/a") -> 3.6650294 | S44: =IF(F44=0,"n/a",P44/F44-1) -> 0.95435685 | T44: =IF(E44=0,"n/a",P44/E44-1) -> 0.83984375
A45: 6 | B45: Gold Loan | C45: ONUS | D45: 13102 | E45: 4.06 | F45: 4 | G45: 3.93 | H45: 4.1 | I45: 3.94 | J45: 4.19 | K45: 4.64 | L45: 4.74 | M45: 5.62 | N45: 6.18 | O45: 6.55 | P45: 7.58 | Q45: 0 | R45: =IFERROR(SUMPRODUCT(F45:P45,F12:P12)/SUM(F12:P12),"n/a") -> 5.8193765 | S45: =IF(F45=0,"n/a",P45/F45-1) -> 0.895 | T45: =IF(E45=0,"n/a",P45/E45-1) -> 0.86699507
A46: 7 | B46: Two Wheeler Loan | C46: OFFUS | D46: 49237 | E46: 1.18 | F46: 1.06 | G46: 1.08 | H46: 1.1 | I46: 1.12 | J46: 1.11 | K46: 1.12 | L46: 1.01 | M46: 1.06 | N46: 1.16 | O46: 1.06 | P46: 1.11 | Q46: 1.08 | R46: =IFERROR(SUMPRODUCT(F46:P46,F13:P13)/SUM(F13:P13),"n/a") -> 1.0824478 | S46: =IF(F46=0,"n/a",P46/F46-1) -> 0.047169811 | T46: =IF(E46=0,"n/a",P46/E46-1) -> -0.059322034
A47: 8 | B47: Two Wheeler Loan | C47: ONUS | D47: 434 | E47: 0.94 | F47: 0.92 | G47: 0.95 | H47: 0.97 | I47: 0.95 | J47: 0.93 | K47: 0.94 | L47: 0.86 | M47: 0.84 | N47: 0.94 | O47: 0.85 | P47: 0.93 | Q47: 0 | R47: =IFERROR(SUMPRODUCT(F47:P47,F14:P14)/SUM(F14:P14),"n/a") -> 0.91523161 | S47: =IF(F47=0,"n/a",P47/F47-1) -> 0.010869565 | T47: =IF(E47=0,"n/a",P47/E47-1) -> -0.010638298
A48: 9 | B48: Auto Loan | C48: OFFUS | D48: 32479 | E48: 13.12 | F48: 13.64 | G48: 13.78 | H48: 12.75 | I48: 12.63 | J48: 13.58 | K48: 13.06 | L48: 11.91 | M48: 12.79 | N48: 12.44 | O48: 13.43 | P48: 12.93 | Q48: 11.05 | R48: =IFERROR(SUMPRODUCT(F48:P48,F15:P15)/SUM(F15:P15),"n/a") -> 12.924392 | S48: =IF(F48=0,"n/a",P48/F48-1) -> -0.052052786 | T48: =IF(E48=0,"n/a",P48/E48-1) -> -0.014481707
A49: 10 | B49: Auto Loan | C49: ONUS | D49: 86 | E49: 9.94 | F49: 10.32 | G49: 17.62 | H49: 8.07 | I49: 7.03 | J49: 13.67 | K49: 20.88 | L49: 12.64 | M49: 6.65 | N49: 0 | O49: 9.11 | P49: 10.66 | Q49: 0 | R49: =IFERROR(SUMPRODUCT(F49:P49,F16:P16)/SUM(F16:P16),"n/a") -> 12.408077 | S49: =IF(F49=0,"n/a",P49/F49-1) -> 0.032945736 | T49: =IF(E49=0,"n/a",P49/E49-1) -> 0.072434608
A50: 11 | B50: Rural Vehicle Finance | C50: OFFUS | D50: 4311 | E50: 5 | F50: 5.08 | G50: 4.93 | H50: 5.11 | I50: 5.01 | J50: 6.02 | K50: 5.23 | L50: 5.49 | M50: 5.04 | N50: 5.13 | O50: 4.98 | P50: 5.2 | Q50: 5.98 | R50: =IFERROR(SUMPRODUCT(F50:P50,F17:P17)/SUM(F17:P17),"n/a") -> 5.1934121 | S50: =IF(F50=0,"n/a",P50/F50-1) -> 0.023622047 | T50: =IF(E50=0,"n/a",P50/E50-1) -> 0.04
A51: 12 | B51: Rural Vehicle Finance | C51: ONUS | D51: 240 | E51: 5.35 | F51: 5.97 | G51: 5.04 | H51: 5.04 | I51: 4.62 | J51: 5.2 | K51: 5.51 | L51: 4.62 | M51: 5.59 | N51: 4.75 | O51: 4.8 | P51: 4.54 | Q51: 0 | R51: =IFERROR(SUMPRODUCT(F51:P51,F18:P18)/SUM(F18:P18),"n/a") -> 4.776506 | S51: =IF(F51=0,"n/a",P51/F51-1) -> -0.23953099 | T51: =IF(E51=0,"n/a",P51/E51-1) -> -0.15140187
... A67: 28 | B67: Used Car Loan | C67: ONUS | D67: 67 | E67: 6.08 | F67: 4.33 | G67: 4.04 | H67: 2.08 | I67: 8.98 | J67: 9.2 | K67: 5.06 | L67: 9.5 | M67: 6.87 | N67: 8.72 | O67: 6 | P67: 8.28 | Q67: 0 | R67: =IFERROR(SUMPRODUCT(F67:P67,F34:P34)/SUM(F34:P34),"n/a") -> 7.043913 | S67: =IF(F67=0,"n/a",P67/F67-1) -> 0.91224018 | T67: =IF(E67=0,"n/a",P67/E67-1) -> 0.36184211
A71: C. Sanction (₹ Cr) per month (blue) — totals, growth and implied-sanction check (|Σ #×ATS÷100 − Σ printed|)
A72: # | B72: Product | C72: Footprint | D72: 13M distinct customers | E72: Mar-25 | F72: Apr-25 | G72: May-25 | H72: Jun-25 | I72: Jul-25 | J72: Aug-25 | K72: Sep-25 | L72: Oct-25 | M72: Nov-25 | N72: Dec-25 | O72: Jan-26 | P72: Feb-26 | Q72: Mar-26 | R72: 11M Σ or wtd avg | S72: Feb-26 vs Apr-25 | T72: Feb-26 vs Mar-25 | U72: Implied check
A73: 1 | B73: Housing Loan | C73: OFFUS | D73: 35881 | E73: 2158 | F73: 1047 | G73: 1413 | H73: 1454 | I73: 1630 | J73: 1722 | K73: 2003 | L73: 1716 | M73: 1784 | N73: 2163 | O73: 1711 | P73: 1749 | Q73: 84 | R73: =SUM(F73:P73) -> 18392 | S73: =IF(F73=0,"n/a",P73/F73-1) -> 0.67048711 | T73: =IF(E73=0,"n/a",P73/E73-1) -> -0.18952734 | U73: =MAX(ABS(SUMPRODUCT(E7:Q7,E40:Q40)/100-SUM(E73:Q73)),0) -> 0.2536
A74: 2 | B74: Housing Loan | C74: ONUS | D74: 4974 | E74: 139 | F74: 93 | G74: 115 | H74: 125 | I74: 107 | J74: 104 | K74: 260 | L74: 159 | M74: 151 | N74: 129 | O74: 142 | P74: 139 | Q74: 0 | R74: =SUM(F74:P74) -> 1524 | S74: =IF(F74=0,"n/a",P74/F74-1) -> 0.49462366 | T74: =IF(E74=0,"n/a",P74/E74-1) -> 0 | U74: =MAX(ABS(SUMPRODUCT(E8:Q8,E41:Q41)/100-SUM(E74:Q74)),0) -> 0.5379
A75: 3 | B75: Property Loan | C75: OFFUS | D75: 24378 | E75: 2003 | F75: 1188 | G75: 1429 | H75: 1387 | I75: 1534 | J75: 1778 | K75: 2166 | L75: 1598 | M75: 1747 | N75: 2360 | O75: 2162 | P75: 1775 | Q75: 31 | R75: =SUM(F75:P75) -> 19124 | S75: =IF(F75=0,"n/a",P75/F75-1) -> 0.49410774 | T75: =IF(E75=0,"n/a",P75/E75-1) -> -0.11382926 | U75: =MAX(ABS(SUMPRODUCT(E9:Q9,E42:Q42)/100-SUM(E75:Q75)),0) -> 0.6917
A76: 4 | B76: Property Loan | C76: ONUS | D76: 1945 | E76: 231 | F76: 179 | G76: 68 | H76: 141 | I76: 136 | J76: 160 | K76: 171 | L76: 179 | M76: 183 | N76: 232 | O76: 209 | P76: 150 | Q76: 0 | R76: =SUM(F76:P76) -> 1808 | S76: =IF(F76=0,"n/a",P76/F76-1) -> -0.16201117 | T76: =IF(E76=0,"n/a",P76/E76-1) -> -0.35064935 | U76: =MAX(ABS(SUMPRODUCT(E10:Q10,E43:Q43)/100-SUM(E76:Q76)),0) -> 1.2808
A77: 5 | B77: Gold Loan | C77: OFFUS | D77: 132558 | E77: 146 | F77: 152 | G77: 239 | H77: 244 | I77: 295 | J77: 295 | K77: 448 | L77: 620 | M77: 696 | N77: 913 | O77: 1185 | P77: 1811 | Q77: 215 | R77: =SUM(F77:P77) -> 6898 | S77: =IF(F77=0,"n/a",P77/F77-1) -> 10.914474 | T77: =IF(E77=0,"n/a",P77/E77-1) -> 11.40411 | U77: =MAX(ABS(SUMPRODUCT(E11:Q11,E44:Q44)/100-SUM(E77:Q77)),0) -> 1.7566
...

Sheet B1_Metrics
A1: New originations: notation and metrics
A2: Format: Notation → Exhaustive metrics table | Example column = live Excel formula on the block sheet (green = cross-sheet)
A3: ⚠ DRAFT ONLY — Requires review and approval by a qualified Alvarez and Marsal professional before use.
A5: Notation
B6: Symbol | C6: Meaning
B7: N(p,f,m) | C7: Distinct SA customers originated in product p, footprint f (OFFUS / ONUS), month m
B8: ATS(p,f,m) | C8: Average ticket size, ₹ lakh
B9: S(p,f,m) | C9: Sanction amount, ₹ Cr; S ≈ N × ATS ÷ 100
B10: m | C10: Mar-25 … Mar-26; Mar-26 partial
B11: 11M | C11: Apr-25 … Feb-26 (full months)
B12: N(m), S(m) | C12: Bank totals across products and footprints
B13: ATS_b(m) | C13: Implied bank ATS = S(m) × 100 ÷ N(m)
B14: g | C14: Feb-26 ÷ Apr-25 − 1 unless stated
B15: sh | C15: Share of 11M total
B16: ONUS% | C16: ONUS ÷ (OFFUS + ONUS)
B17: Counts are distinct SA customers; ATS in ₹ lakh; Sanction in ₹ Cr; growth in %; shares in %.
A19: Exhaustive metrics table
A20: # | B20: Metric family | C20: Pipeline-ready metric | D20: Definition / formula | E20: Applies to | F20: Example
A21: 1 | B21: Fact lookup | C21: Customers originated | D21: N(p,f,m) | E21: 29 rows × 13 months | F21: ="Gold Loan OFFUS Apr-25 → Feb-26 "&TEXT(B1_Originations!F11,"#,##0")&" → "&TEXT(B1_Originations!P11,"#,##0")&"; Personal Loan OFFUS "&TEXT(B1_Originations!F23,"#,##0")&" → "&TEXT(B1_Originations!P23,"#,##0") -> Gold Loan OFFUS Apr-25 → Feb-26 6,331 → 38,463; Personal Loan OFFUS 16,072 → 42,373
A22: 2 | B22: Fact lookup | C22: ATS | D22: ATS(p,f,m) | E22: 29 × 13 | F22: ="Housing Loan OFFUS "&TEXT(B1_Originations!F40,"#,##0.00")&" / "&TEXT(B1_Originations!I40,"#,##0.00")&" / "&TEXT(B1_Originations!L40,"#,##0.00")&" / "&TEXT(B1_Originations!P40,"#,##0.00")&" (Apr / Jul / Oct / Feb)" -> Housing Loan OFFUS 55.30 / 57.33 / 66.53 / 58.26 (Apr / Jul / Oct / Feb)
A23: 3 | B23: Fact lookup | C23: Sanction | D23: S(p,f,m) | E23: 29 × 13 | F23: ="Housing Loan OFFUS "&TEXT(B1_Originations!F73,"#,##0;-#,##0;0")&" / "&TEXT(B1_Originations!I73,"#,##0;-#,##0;0")&" / "&TEXT(B1_Originations!L73,"#,##0;-#,##0;0")&" / "&TEXT(B1_Originations!P73,"#,##0;-#,##0;0") -> Housing Loan OFFUS 1,047 / 1,630 / 1,716 / 1,749
A24: 4 | B24: Fact lookup | C24: 13M distinct customers | D24: Printed footprint count | E24: 29 rows | F24: ="Personal Loan OFFUS "&TEXT(B1_Originations!D23,"#,##0")&"; Credit Card OFFUS "&TEXT(B1_Originations!D25,"#,##0") -> Personal Loan OFFUS 286,830; Credit Card OFFUS 213,489
A25: 5 | B25: Roll-up check | C25: Sanction identity | D25: |Σm N × ATS ÷ 100 − Σm S| | E25: 29 rows | F25: ="max "&TEXT(MAX(B1_Originations!U73:U101),"#,##0;-#,##0;0")&" ₹ Cr (rounding)" -> max 4 ₹ Cr (rounding)
A26: 6 | B26: Roll-up check | C26: 13M distinct vs Σ monthly | D26: Σm N(p,f,m) ÷ printed 13M distinct | E26: 29 rows | F26: ="PL OFFUS "&TEXT(SUM(B1_Originations!E23:Q23)/B1_Originations!D23,"0.00""x""")&"; Gold OFFUS "&TEXT(SUM(B1_Originations!E11:Q11)/B1_Originations!D11,"0.00""x""")&" (>1 = repeat customers within the year)" -> PL OFFUS 1.16x; Gold OFFUS 1.50x (>1 = repeat customers within the year)
A27: 7 | B27: Volume aggregates | C27: Bank customers by month | D27: N(m) | E27: 13 months | F27: =TEXT(B1_Originations!F106,"#,##0")&" / "&TEXT(B1_Originations!G106,"#,##0")&" / "&TEXT(B1_Originations!H106,"#,##0")&" / "&TEXT(B1_Originations!I106,"#,##0")&" / "&TEXT(B1_Originations!J106,"#,##0")&" / "&TEXT(B1_Originations!K106,"#,##0")&" / "&TEXT(B1_Originations!L106,"#,##0")&" / "&TEXT(B1_Originations!M106,"#,##0")&" / "&TEXT(B1_Originations!N106,"#,##0")&" / "&TEXT(B1_Originations!O106,"#,##0")&" / "&TEXT(B1_Originations!P106,"#,##0")&" (Apr-25 … Feb-26)" -> 64,162 / 74,295 / 78,779 / 91,867 / 95,584 / 113,823 / 134,642 / 119,689 / 131,253 / 143,984 / 148,639 (Apr-25 … Feb-26)
A28: 8 | B28: Volume aggregates | C28: Bank sanction by month | D28: S(m) | E28: 13 months | F28: =TEXT(B1_Originations!F107,"#,##0;-#,##0;0")&" / "&TEXT(B1_Originations!G107,"#,##0;-#,##0;0")&" / "&TEXT(B1_Originations!H107,"#,##0;-#,##0;0")&" / "&TEXT(B1_Originations!I107,"#,##0;-#,##0;0")&" / "&TEXT(B1_Originations!J107,"#,##0;-#,##0;0")&" / "&TEXT(B1_Originations!K107,"#,##0;-#,##0;0")&" / "&TEXT(B1_Originations!L107,"#,##0;-#,##0;0")&" / "&TEXT(B1_Originations!M107,"#,##0;-#,##0;0")&" / "&TEXT(B1_Originations!N107,"#,##0;-#,##0;0")&" / "&TEXT(B1_Originations!O107,"#,##0;-#,##0;0")&" / "&TEXT(B1_Originations!P107,"#,##0;-#,##0;0") -> 4,580 / 5,642 / 6,329 / 6,813 / 6,851 / 8,402 / 7,442 / 7,856 / 9,670 / 8,750 / 8,659
A29: 9 | B29: Volume aggregates | C29: 11M totals | D29: Σ N, Σ S | E29: Bank | F29: =TEXT(B1_Originations!R106,"#,##0")&" customers; "&TEXT(B1_Originations!R107,"#,##0;-#,##0;0")&" ₹ Cr" -> 1,196,717 customers; 80,994 ₹ Cr
A30: 10 | B30: Volume aggregates | C30: Average month | D30: Σ ÷ 11 | E30: Bank | F30: =TEXT(B1_Originations!S106,"#,##0")&" customers; "&TEXT(B1_Originations!S107,"#,##0;-#,##0;0")&" ₹ Cr" -> 108,792 customers; 7,363 ₹ Cr
A31: 11 | B31: Volume aggregates | C31: Product 11M totals | D31: Σm N(p), Σm S(p) | E31: 15 products | F31: ="Gold "&TEXT(B1_Originations!C150,"#,##0")&" / "&TEXT(B1_Originations!E150,"#,##0;-#,##0;0")&"; Housing "&TEXT(B1_Originations!C148,"#,##0")&" / "&TEXT(B1_Originations!E148,"#,##0;-#,##0;0") -> Gold 208,262 / 8,064; Housing 34,716 / 19,916
A32: 12 | B32: Ticket size | C32: Bank implied ATS | D32: ATS_b(m) | E32: 13 months | F32: =TEXT(B1_Originations!F108,"#,##0.00")&" / "&TEXT(B1_Originations!I108,"#,##0.00")&" / "&TEXT(B1_Originations!L108,"#,##0.00")&" / "&TEXT(B1_Originations!P108,"#,##0.00")&" (Apr / Jul / Oct / Feb)" -> 7.14 / 7.42 / 5.53 / 5.83 (Apr / Jul / Oct / Feb)
A33: 13 | B33: Ticket size | C33: Product 11M ATS | D33: Σ S(p) × 100 ÷ Σ N(p) | E33: 15 products | F33: ="Housing "&TEXT(B1_Originations!G148,"#,##0.00")&"; Property "&TEXT(B1_Originations!G149,"#,##0.00")&"; Gold "&TEXT(B1_Originations!G150,"#,##0.00")&"; PL "&TEXT(B1_Originations!G156,"#,##0.00")&"; Card "&TEXT(B1_Originations!G157,"#,##0.00") -> Housing 57.37; Property 92.79; Gold 3.87; PL 2.19; Card 0.56
A34: 14 | B34: Ticket size | C34: Weighted ATS by row | D34: Σ N × ATS ÷ Σ N (11M) | E34: 29 rows | F34: ="Business Loan OFFUS "&TEXT(B1_Originations!R54,"#,##0.00")&" vs ONUS "&TEXT(B1_Originations!R55,"#,##0.00") -> Business Loan OFFUS 13.37 vs ONUS 119.69
A35: 15 | B35: Ticket size | C35: ATS change | D35: ATS(Feb-26) ÷ ATS(Apr-25) − 1 | E35: 29 rows | F35: ="Credit Card OFFUS "&TEXT(B1_Originations!S58,"+0.0%;-0.0%;0.0%")&"; Gold OFFUS "&TEXT(B1_Originations!S44,"+0.0%;-0.0%;0.0%")&"; PL OFFUS "&TEXT(B1_Originations!S56,"+0.0%;-0.0%;0.0%") -> Credit Card OFFUS -61.6%; Gold OFFUS +95.4%; PL OFFUS -27.3%
A36: 16 | B36: Ticket size | C36: ONUS ÷ OFFUS ATS ratio | D36: ATS_ONUS ÷ ATS_OFFUS (11M wtd) | E36: 12 products with both | F36: ="Business Loan "&TEXT(B1_Originations!R55/B1_Originations!R54,"0.00""x""")&"; Gold "&TEXT(B1_Originations!R45/B1_Originations!R44,"0.00""x""") -> Business Loan 8.95x; Gold 1.59x
A37: 17 | B37: Growth & momentum | C37: Bank growth | D37: g(N), g(S) | E37: Feb-26 vs Apr-25 and vs Mar-25 | F37: ="N "&TEXT(B1_Originations!T106,"+0.0%;-0.0%;0.0%")&" / "&TEXT(B1_Originations!U106,"+0.0%;-0.0%;0.0%")&"; S "&TEXT(B1_Originations!T107,"+0.0%;-0.0%;0.0%")&" / "&TEXT(B1_Originations!U107,"+0.0%;-0.0%;0.0%") -> N +131.7% / +109.8%; S +89.1% / +12.3%
A38: 18 | B38: Growth & momentum | C38: Product count growth | D38: g(N(p)) | E38: 15 products | F38: ="Gold "&TEXT(B1_Originations!H150,"+0.0%;-0.0%;0.0%")&"; PL "&TEXT(B1_Originations!H156,"+0.0%;-0.0%;0.0%")&"; Consumer "&TEXT(B1_Originations!H159,"+0.0%;-0.0%;0.0%")&"; Housing "&TEXT(B1_Originations!H148,"+0.0%;-0.0%;0.0%")&"; Card "&TEXT(B1_Originations!H157,"+0.0%;-0.0%;0.0%") -> Gold +523.4%; PL +164.1%; Consumer +214.8%; Housing +56.4%; Card -9.0%
A39: 19 | B39: Growth & momentum | C39: Product sanction growth | D39: g(S(p)) | E39: 15 products | F39: ="Gold "&TEXT(B1_Originations!I150,"+0.0%;-0.0%;0.0%")&"; PL "&TEXT(B1_Originations!I156,"+0.0%;-0.0%;0.0%")&"; Housing "&TEXT(B1_Originations!I148,"+0.0%;-0.0%;0.0%")&"; Business "&TEXT(B1_Originations!I155,"+0.0%;-0.0%;0.0%") -> Gold +1136.9%; PL +93.0%; Housing +65.6%; Business +37.9%
A40: 20 | B40: Growth & momentum | C40: MoM growth in bank customers | D40: N(m) ÷ N(m−1) − 1 | E40: 12 pairs | F40: =TEXT(B1_Originations!G106/B1_Originations!F106-1,"+0.0%;-0.0%;0.0%")&" / "&TEXT(B1_Originations!H106/B1_Originations!G106-1,"+0.0%;-0.0%;0.0%")&" / "&TEXT(B1_Originations!I106/B1_Originations!H106-1,"+0.0%;-0.0%;0.0%")&" / "&TEXT(B1_Originations!J106/B1_Originations!I106-1,"+0.0%;-0.0%;0.0%")&" / "&TEXT(B1_Originations!K106/B1_Originations!J106-1,"+0.0%;-0.0%;0.0%")&" / "&TEXT(B1_Originations!L106/B1_Originations!K106-1,"+0.0%;-0.0%;0.0%")&" / "&TEXT(B1_Originations!M106/B1_Originations!L106-1,"+0.0%;-0.0%;0.0%")&" / "&TEXT(B1_Originations!N106/B1_Originations!M106-1,"+0.0%;-0.0%;0.0%")&" / "&TEXT(B1_Originations!O106/B1_Originations!N106-1,"+0.0%;-0.0%;0.0%")&" / "&TEXT(B1_Originations!P106/B1_Originations!O106-1,"+0.0%;-0.0%;0.0%")&" (May-25 … Feb-26)" -> +15.8% / +6.0% / +16.6% / +4.0% / +19.1% / +18.3% / -11.1% / +9.7% / +9.7% / +3.2% (May-25 … Feb-26)
A41: 21 | B41: Growth & momentum | C41: Compounded monthly growth (customers) | D41: (N(Feb-26) ÷ N(Apr-25))^(1/10) − 1 | E41: Bank | F41: =TEXT((B1_Originations!P106/B1_Originations!F106)^(1/10)-1,"+0.0%;-0.0%;0.0%") -> +8.8%
A42: 22 | B42: Growth & momentum | C42: Peak month | D42: MAX N(m) and month | E42: 11 months | F42: =INDEX(B1_Originations!F105:P105,MATCH(MAX(B1_Originations!F106:P106),B1_Originations!F106:P106,0))&" "&TEXT(MAX(B1_Originations!F106:P106),"#,##0") -> Feb-26 148,639
...
