Workbook

Sheet README
A1: RBL Bank — Retail Disbursement MIS: page-wise metric extraction
A2: Source: 05_Disb_MIS.pdf (1 page; main quarterly table + unlabelled FY27 Q2 table; latest date 18-Aug-2026) | ₹ Cr, counts, yield %
A3: ⚠ DRAFT ONLY — Requires review and approval by a qualified Alvarez and Marsal professional before use.
A5: Sheet map
A6: B1_Disbursement_MIS | B6: Quarterly disbursement by sub-product (Disb ₹ Cr, #, Yield %) with ATS, growth, run-rate, mix and yield checks; unlabelled lower table with inferred labels
A7: B1_Metrics | B7: Notation + exhaustive metrics
A9: Colour legend
A10: Blue text | B10: Hard-coded input transcribed from the PDF
A11: Blue italic on grey | B11: Budget / projected value (ᴾ) transcribed from the PDF
A12: Black text | B12: Formula on the same sheet
A13: Green text | B13: Link to another sheet
A14: Yellow fill | B14: Data flag to review
A16: Key assumptions (confirm with client)
A17: 1 | B17: Q2 FY27 is partial (data to 18-Aug-2026 = 49 of 92 days). Run-rate annualisation uses 92 ÷ 49; both parameters are editable inputs.
A18: 2 | B18: The lower 'FY 2027 Q2' table has no row labels; labels are inferred by matching values to the upper table. Three rows (₹56.4 Cr / 2, ₹4.1 Cr / 41, ₹864.8 Cr / 139,608 @ 25%) do not exist in the upper table, so the lower totals exceed the upper ones. The 139,608-account row looks like Micro Banking.
A19: 3 | B19: Printed category and Grand Total yields are SIMPLE (unweighted) averages of sub-product yields, not disbursement-weighted. The true weighted yields are computed alongside (e.g. LAP Q3: printed 10.60% vs weighted 9.22%).
A20: 4 | B20: Note on page: Cards, BBG and Agri TL are not part of the dashboard.
A21: Confidentiality | B21: Client-confidential RBL Bank data.
A23: ⚠ DRAFT ONLY — Requires review and approval by a qualified Alvarez and Marsal professional before use.

Sheet B1_Disbursement_MIS
A1: Block 1 — Retail disbursement MIS by sub-product and quarter
A2: Source: Disb MIS.pdf | Disb ₹ Cr, Disb # (count), Yield % | Q3 FY26 – Q2 FY27 (Q2 to 18-Aug-2026)
A3: ⚠ DRAFT ONLY — Requires review and approval by a qualified Alvarez and Marsal professional before use.
B4: Q2 FY27 days in quarter | C4: 92 | D4: Days elapsed to 18-Aug | E4: 49 | F4: Annualisation factor | G4: =C4/E4 -> 1.877551
A5: A. Source data (blue) with live calculations
A6: # | B6: Category | C6: Sub product | D6: Q3 FY26 Disb ₹ Cr | E6: Q3 FY26 # | F6: Q3 FY26 Yield % | G6: Q4 FY26 Disb ₹ Cr | H6: Q4 FY26 # | I6: Q4 FY26 Yield % | J6: Q1 FY27 Disb ₹ Cr | K6: Q1 FY27 # | L6: Q1 FY27 Yield % | M6: Q2 FY27 (to 18-Aug) Disb ₹ Cr | N6: Q2 FY27 (to 18-Aug) # | O6: Q2 FY27 (to 18-Aug) Yield % | P6: ATS Q3 (₹ lakh) | Q6: ATS Q4 | R6: ATS Q1 | S6: ATS Q2 | T6: QoQ Q4/Q3 | U6: QoQ Q1/Q4 | V6: Q2 run-rate (full quarter) | W6: Q2 run-rate vs Q1 | X6: Share of GT (Q1) | Y6: Yield Δ Q1 − Q3 (bp) | Z6: Σ sub-products check (Totals) | AA6: Printed − simple-avg yield (pp) | AB6: Wtd yield Q3 (true) | AC6: Wtd yield Q1 (true)
A7: 1 | B7: Loan Against Property | C7: LAP | D7: 1030.19 | E7: 516 | F7: 0.0944 | G7: 1305.36 | H7: 584 | I7: 0.0911 | J7: 960.54 | K7: 533 | L7: 0.0896 | M7: 455.23 | N7: 287 | O7: 0.089 | P7: =IF(OR(E7="",E7=0),"",D7*100/E7) -> 199.64922 | Q7: =IF(OR(H7="",H7=0),"",G7*100/H7) -> 223.52055 | R7: =IF(OR(K7="",K7=0),"",J7*100/K7) -> 180.21388 | S7: =IF(OR(N7="",N7=0),"",M7*100/N7) -> 158.61672 | T7: =IF(OR(D7="",G7="",D7=0),"n/a",G7/D7-1) -> 0.26710607 | U7: =IF(OR(G7="",J7="",G7=0),"n/a",J7/G7-1) -> -0.26415701 | V7: =IF(M7="","",M7*$G$4) -> 854.71755 | W7: =IF(OR(J7="",V7=""),"n/a",V7/J7-1) -> -0.11016975 | X7: =IF(J7="","",J7/$J$28) -> 0.37645795 | Y7: =IF(OR(F7="",L7=""),"",(L7-F7)*10000) -> -48
A8: 2 | B8: Loan Against Property | C8: Micro LAP | D8: 88.98 | E8: 447 | F8: 0.1308 | G8: 90.74 | H8: 420 | I8: 0.1299 | J8: 68.18 | K8: 293 | L8: 0.1289 | M8: 34.6 | N8: 164 | O8: 0.1234 | P8: =IF(OR(E8="",E8=0),"",D8*100/E8) -> 19.90604 | Q8: =IF(OR(H8="",H8=0),"",G8*100/H8) -> 21.604762 | R8: =IF(OR(K8="",K8=0),"",J8*100/K8) -> 23.269625 | S8: =IF(OR(N8="",N8=0),"",M8*100/N8) -> 21.097561 | T8: =IF(OR(D8="",G8="",D8=0),"n/a",G8/D8-1) -> 0.019779726 | U8: =IF(OR(G8="",J8="",G8=0),"n/a",J8/G8-1) -> -0.24862244 | V8: =IF(M8="","",M8*$G$4) -> 64.963265 | W8: =IF(OR(J8="",V8=""),"n/a",V8/J8-1) -> -0.047180034 | X8: =IF(J8="","",J8/$J$28) -> 0.026721327 | Y8: =IF(OR(F8="",L8=""),"",(L8-F8)*10000) -> -19
A9: 3 | B9: Loan Against Property | C9: Micro LAP RFL | D9: 13.78 | E9: 86 | F9: 0.1303 | G9: 17.66 | H9: 108 | I9: 0.1299 | J9: 10 | K9: 59 | L9: 0.1275 | M9: 5.29 | N9: 25 | O9: 0.1278 | P9: =IF(OR(E9="",E9=0),"",D9*100/E9) -> 16.023256 | Q9: =IF(OR(H9="",H9=0),"",G9*100/H9) -> 16.351852 | R9: =IF(OR(K9="",K9=0),"",J9*100/K9) -> 16.949153 | S9: =IF(OR(N9="",N9=0),"",M9*100/N9) -> 21.16 | T9: =IF(OR(D9="",G9="",D9=0),"n/a",G9/D9-1) -> 0.28156749 | U9: =IF(OR(G9="",J9="",G9=0),"n/a",J9/G9-1) -> -0.43374858 | V9: =IF(M9="","",M9*$G$4) -> 9.9322449 | W9: =IF(OR(J9="",V9=""),"n/a",V9/J9-1) -> -0.0067755102 | X9: =IF(J9="","",J9/$J$28) -> 0.0039192325 | Y9: =IF(OR(F9="",L9=""),"",(L9-F9)*10000) -> -28
A10: 4 | B10: Loan Against Property | C10: LAP Colending | D10: 96.14 | E10: 9 | F10: 0.094 | G10: 90.23 | H10: 59 | I10: 0.0886 | J10: 33.08 | K10: 62 | L10: 0.0942 | M10: 11.77 | N10: 24 | O10: 0.0941 | P10: =IF(OR(E10="",E10=0),"",D10*100/E10) -> 1068.2222 | Q10: =IF(OR(H10="",H10=0),"",G10*100/H10) -> 152.9322 | R10: =IF(OR(K10="",K10=0),"",J10*100/K10) -> 53.354839 | S10: =IF(OR(N10="",N10=0),"",M10*100/N10) -> 49.041667 | T10: =IF(OR(D10="",G10="",D10=0),"n/a",G10/D10-1) -> -0.061472852 | U10: =IF(OR(G10="",J10="",G10=0),"n/a",J10/G10-1) -> -0.63338136 | V10: =IF(M10="","",M10*$G$4) -> 22.098776 | W10: =IF(OR(J10="",V10=""),"n/a",V10/J10-1) -> -0.33195963 | X10: =IF(J10="","",J10/$J$28) -> 0.012964821 | Y10: =IF(OR(F10="",L10=""),"",(L10-F10)*10000) -> 2
A11: 5 | B11: Loan Against Property | C11: DA Portfolio LAP | D11: 545.18 | E11: 3 | F11: 0.0806 | G11: 8.85 | H11: 2 | I11: 0.0984 | J11: 42.15 | K11: 1 | L11: 0.087 | M11: 29.72 | N11: 3 | O11: 0.0876 | P11: =IF(OR(E11="",E11=0),"",D11*100/E11) -> 18172.667 | Q11: =IF(OR(H11="",H11=0),"",G11*100/H11) -> 442.5 | R11: =IF(OR(K11="",K11=0),"",J11*100/K11) -> 4215 | S11: =IF(OR(N11="",N11=0),"",M11*100/N11) -> 990.66667 | T11: =IF(OR(D11="",G11="",D11=0),"n/a",G11/D11-1) -> -0.98376683 | U11: =IF(OR(G11="",J11="",G11=0),"n/a",J11/G11-1) -> 3.7627119 | V11: =IF(M11="","",M11*$G$4) -> 55.800816 | W11: =IF(OR(J11="",V11=""),"n/a",V11/J11-1) -> 0.32386278 | X11: =IF(J11="","",J11/$J$28) -> 0.016519565 | Y11: =IF(OR(F11="",L11=""),"",(L11-F11)*10000) -> 64
A12: 6 | B12: Loan Against Property | C12: Total | D12: 1774.27 | E12: 1061 | F12: 0.106 | G12: 1512.84 | H12: 1173 | I12: 0.1076 | J12: 1113.94 | K12: 948 | L12: 0.1054 | M12: 536.61 | N12: 503 | O12: 0.1044 | P12: =IF(OR(E12="",E12=0),"",D12*100/E12) -> 167.2262 | Q12: =IF(OR(H12="",H12=0),"",G12*100/H12) -> 128.97187 | R12: =IF(OR(K12="",K12=0),"",J12*100/K12) -> 117.50422 | S12: =IF(OR(N12="",N12=0),"",M12*100/N12) -> 106.68191 | T12: =IF(OR(D12="",G12="",D12=0),"n/a",G12/D12-1) -> -0.14734511 | U12: =IF(OR(G12="",J12="",G12=0),"n/a",J12/G12-1) -> -0.26367626 | V12: =IF(M12="","",M12*$G$4) -> 1007.5127 | W12: =IF(OR(J12="",V12=""),"n/a",V12/J12-1) -> -0.095541364 | X12: =IF(J12="","",J12/$J$28) -> 0.43657898 | Y12: =IF(OR(F12="",L12=""),"",(L12-F12)*10000) -> -6 | Z12: =D12-SUM(D7:D11) -> 0 | AA12: =(F12-AVERAGE(F7:F11))*100 -> -0.002 | AB12: =SUMPRODUCT(D7:D11,F7:F11)/SUM(D7:D11) -> 0.092242287 | AC12: =SUMPRODUCT(J7:J11,L7:L11)/SUM(J7:J11) -> 0.092383834
A13: 7 | B13: Home Loan | C13: PHL | D13: 192.15 | E13: 495 | F13: 0.086 | G13: 180.13 | H13: 434 | I13: 0.0838 | J13: 215.02 | K13: 420 | L13: 0.0844 | M13: 88.52 | N13: 224 | O13: 0.0836 | P13: =IF(OR(E13="",E13=0),"",D13*100/E13) -> 38.818182 | Q13: =IF(OR(H13="",H13=0),"",G13*100/H13) -> 41.504608 | R13: =IF(OR(K13="",K13=0),"",J13*100/K13) -> 51.195238 | S13: =IF(OR(N13="",N13=0),"",M13*100/N13) -> 39.517857 | T13: =IF(OR(D13="",G13="",D13=0),"n/a",G13/D13-1) -> -0.062555295 | U13: =IF(OR(G13="",J13="",G13=0),"n/a",J13/G13-1) -> 0.19369344 | V13: =IF(M13="","",M13*$G$4) -> 166.20082 | W13: =IF(OR(J13="",V13=""),"n/a",V13/J13-1) -> -0.22704485 | X13: =IF(J13="","",J13/$J$28) -> 0.084271336 | Y13: =IF(OR(F13="",L13=""),"",(L13-F13)*10000) -> -16
A14: 8 | B14: Home Loan | C14: AHL | D14: 264.71 | E14: 1835 | F14: 0.1087 | G14: 361.18 | H14: 2390 | I14: 0.1069 | J14: 275.19 | K14: 2165 | L14: 0.1069 | M14: 123.3 | N14: 1059 | O14: 0.1069 | P14: =IF(OR(E14="",E14=0),"",D14*100/E14) -> 14.425613 | Q14: =IF(OR(H14="",H14=0),"",G14*100/H14) -> 15.112134 | R14: =IF(OR(K14="",K14=0),"",J14*100/K14) -> 12.710855 | S14: =IF(OR(N14="",N14=0),"",M14*100/N14) -> 11.643059 | T14: =IF(OR(D14="",G14="",D14=0),"n/a",G14/D14-1) -> 0.36443655 | U14: =IF(OR(G14="",J14="",G14=0),"n/a",J14/G14-1) -> -0.23808074 | V14: =IF(M14="","",M14*$G$4) -> 231.50204 | W14: =IF(OR(J14="",V14=""),"n/a",V14/J14-1) -> -0.15875562 | X14: =IF(J14="","",J14/$J$28) -> 0.10785336 | Y14: =IF(OR(F14="",L14=""),"",(L14-F14)*10000) -> -18
A15: 9 | B15: Home Loan | C15: AHL RFL | D15: 25.96 | E15: 248 | F15: 0.1139 | G15: 35.64 | H15: 340 | I15: 0.1148 | J15: 32.39 | K15: 294 | L15: 0.1134 | M15: 13.61 | N15: 148 | O15: 0.113 | P15: =IF(OR(E15="",E15=0),"",D15*100/E15) -> 10.467742 | Q15: =IF(OR(H15="",H15=0),"",G15*100/H15) -> 10.482353 | R15: =IF(OR(K15="",K15=0),"",J15*100/K15) -> 11.017007 | S15: =IF(OR(N15="",N15=0),"",M15*100/N15) -> 9.1959459 | T15: =IF(OR(D15="",G15="",D15=0),"n/a",G15/D15-1) -> 0.37288136 | U15: =IF(OR(G15="",J15="",G15=0),"n/a",J15/G15-1) -> -0.091189675 | V15: =IF(M15="","",M15*$G$4) -> 25.553469 | W15: =IF(OR(J15="",V15=""),"n/a",V15/J15-1) -> -0.21106918 | X15: =IF(J15="","",J15/$J$28) -> 0.012694394 | Y15: =IF(OR(F15="",L15=""),"",(L15-F15)*10000) -> -5
A16: 10 | B16: Home Loan | C16: AHL Colending | D16: 2.98 | E16: 3 | F16: 0.1005 | P16: =IF(OR(E16="",E16=0),"",D16*100/E16) -> 99.333333 | Q16: =IF(OR(H16="",H16=0),"",G16*100/H16) | R16: =IF(OR(K16="",K16=0),"",J16*100/K16) | S16: =IF(OR(N16="",N16=0),"",M16*100/N16) | T16: =IF(OR(D16="",G16="",D16=0),"n/a",G16/D16-1) -> n/a | U16: =IF(OR(G16="",J16="",G16=0),"n/a",J16/G16-1) -> n/a | V16: =IF(M16="","",M16*$G$4) | W16: =IF(OR(J16="",V16=""),"n/a",V16/J16-1) -> n/a | X16: =IF(J16="","",J16/$J$28) | Y16: =IF(OR(F16="",L16=""),"",(L16-F16)*10000)
A17: 11 | B17: Home Loan | C17: PHL Colending | D17: 123.28 | E17: 3 | F17: 0.09 | P17: =IF(OR(E17="",E17=0),"",D17*100/E17) -> 4109.3333 | Q17: =IF(OR(H17="",H17=0),"",G17*100/H17) | R17: =IF(OR(K17="",K17=0),"",J17*100/K17) | S17: =IF(OR(N17="",N17=0),"",M17*100/N17) | T17: =IF(OR(D17="",G17="",D17=0),"n/a",G17/D17-1) -> n/a | U17: =IF(OR(G17="",J17="",G17=0),"n/a",J17/G17-1) -> n/a | V17: =IF(M17="","",M17*$G$4) | W17: =IF(OR(J17="",V17=""),"n/a",V17/J17-1) -> n/a | X17: =IF(J17="","",J17/$J$28) | Y17: =IF(OR(F17="",L17=""),"",(L17-F17)*10000)
A18: 12 | B18: Home Loan | C18: Total | D18: 609.08 | E18: 2584 | F18: 0.0998 | G18: 576.95 | H18: 3164 | I18: 0.1019 | J18: 522.61 | K18: 2879 | L18: 0.1016 | M18: 225.43 | N18: 1431 | O18: 0.1011 | P18: =IF(OR(E18="",E18=0),"",D18*100/E18) -> 23.571207 | Q18: =IF(OR(H18="",H18=0),"",G18*100/H18) -> 18.234829 | R18: =IF(OR(K18="",K18=0),"",J18*100/K18) -> 18.152484 | S18: =IF(OR(N18="",N18=0),"",M18*100/N18) -> 15.753319 | T18: =IF(OR(D18="",G18="",D18=0),"n/a",G18/D18-1) -> -0.052751691 | U18: =IF(OR(G18="",J18="",G18=0),"n/a",J18/G18-1) -> -0.094184938 | V18: =IF(M18="","",M18*$G$4) -> 423.25633 | W18: =IF(OR(J18="",V18=""),"n/a",V18/J18-1) -> -0.19011055 | X18: =IF(J18="","",J18/$J$28) -> 0.20482301 | Y18: =IF(OR(F18="",L18=""),"",(L18-F18)*10000) -> 18 | Z18: =D18-SUM(D13:D17) -> 0 | AA18: =(F18-AVERAGE(F13:F17))*100 -> -0.002 | AB18: =SUMPRODUCT(D13:D17,F13:F17)/SUM(D13:D17) -> 0.097935265 | AC18: =SUMPRODUCT(J13:J17,L13:L17)/SUM(J13:J17) -> 0.098045398
A19: 13 | B19: Wheels | C19: New Car Loan | D19: 5.57 | E19: 39 | F19: 0.089 | G19: 5.4 | H19: 47 | I19: 0.0928 | J19: 2.41 | K19: 22 | L19: 0.0926 | M19: 1.34 | N19: 11 | O19: 0.0939 | P19: =IF(OR(E19="",E19=0),"",D19*100/E19) -> 14.282051 | Q19: =IF(OR(H19="",H19=0),"",G19*100/H19) -> 11.489362 | R19: =IF(OR(K19="",K19=0),"",J19*100/K19) -> 10.954545 | S19: =IF(OR(N19="",N19=0),"",M19*100/N19) -> 12.181818 | T19: =IF(OR(D19="",G19="",D19=0),"n/a",G19/D19-1) -> -0.030520646 | U19: =IF(OR(G19="",J19="",G19=0),"n/a",J19/G19-1) -> -0.5537037 | V19: =IF(M19="","",M19*$G$4) -> 2.5159184 | W19: =IF(OR(J19="",V19=""),"n/a",V19/J19-1) -> 0.04394953 | X19: =IF(J19="","",J19/$J$28) -> 0.00094453502 | Y19: =IF(OR(F19="",L19=""),"",(L19-F19)*10000) -> 36
A20: 14 | B20: Wheels | C20: Two Wheeler | D20: 112.68 | E20: 13330 | F20: 0.2081 | G20: 68.4 | H20: 7980 | I20: 0.2085 | J20: 60.78 | K20: 7011 | L20: 0.2083 | M20: 31.65 | N20: 3622 | O20: 0.2085 | P20: =IF(OR(E20="",E20=0),"",D20*100/E20) -> 0.84531133 | Q20: =IF(OR(H20="",H20=0),"",G20*100/H20) -> 0.85714286 | R20: =IF(OR(K20="",K20=0),"",J20*100/K20) -> 0.86692341 | S20: =IF(OR(N20="",N20=0),"",M20*100/N20) -> 0.87382662 | T20: =IF(OR(D20="",G20="",D20=0),"n/a",G20/D20-1) -> -0.39297125 | U20: =IF(OR(G20="",J20="",G20=0),"n/a",J20/G20-1) -> -0.11140351 | V20: =IF(M20="","",M20*$G$4) -> 59.42449 | W20: =IF(OR(J20="",V20=""),"n/a",V20/J20-1) -> -0.022301912 | X20: =IF(J20="","",J20/$J$28) -> 0.023821095 | Y20: =IF(OR(F20="",L20=""),"",(L20-F20)*10000) -> 2
A21: 15 | B21: Wheels | C21: Used Car Loan | D21: 6.1 | E21: 109 | F21: 0.1417 | G21: 4.93 | H21: 81 | I21: 0.1403 | J21: 2.88 | K21: 53 | L21: 0.1369 | M21: 0.61 | N21: 15 | O21: 0.1387 | P21: =IF(OR(E21="",E21=0),"",D21*100/E21) -> 5.5963303 | Q21: =IF(OR(H21="",H21=0),"",G21*100/H21) -> 6.0864198 | R21: =IF(OR(K21="",K21=0),"",J21*100/K21) -> 5.4339623 | S21: =IF(OR(N21="",N21=0),"",M21*100/N21) -> 4.0666667 | T21: =IF(OR(D21="",G21="",D21=0),"n/a",G21/D21-1) -> -0.19180328 | U21: =IF(OR(G21="",J21="",G21=0),"n/a",J21/G21-1) -> -0.4158215 | V21: =IF(M21="","",M21*$G$4) -> 1.1453061 | W21: =IF(OR(J21="",V21=""),"n/a",V21/J21-1) -> -0.60232426 | X21: =IF(J21="","",J21/$J$28) -> 0.0011287389 | Y21: =IF(OR(F21="",L21=""),"",(L21-F21)*10000) -> -48
A22: 16 | B22: Wheels | C22: RVF | D22: 563.72 | E22: 11936 | F22: 0.157 | G22: 401.71 | H22: 9029 | I22: 0.1608 | J22: 447.82 | K22: 9826 | L22: 0.1593 | M22: 158.88 | N22: 3584 | O22: 0.1636 | P22: =IF(OR(E22="",E22=0),"",D22*100/E22) -> 4.7228552 | Q22: =IF(OR(H22="",H22=0),"",G22*100/H22) -> 4.4491084 | R22: =IF(OR(K22="",K22=0),"",J22*100/K22) -> 4.5575005 | S22: =IF(OR(N22="",N22=0),"",M22*100/N22) -> 4.4330357 | T22: =IF(OR(D22="",G22="",D22=0),"n/a",G22/D22-1) -> -0.28739445 | U22: =IF(OR(G22="",J22="",G22=0),"n/a",J22/G22-1) -> 0.1147843 | V22: =IF(M22="","",M22*$G$4) -> 298.30531 | W22: =IF(OR(J22="",V22=""),"n/a",V22/J22-1) -> -0.3338723 | X22: =IF(J22="","",J22/$J$28) -> 0.17551107 | Y22: =IF(OR(F22="",L22=""),"",(L22-F22)*10000) -> 23
A23: 17 | B23: Wheels | C23: Total | D23: 688.08 | E23: 25414 | F23: 0.1489 | G23: 480.44 | H23: 17137 | I23: 0.1506 | J23: 513.89 | K23: 16912 | L23: 0.1493 | M23: 192.47 | N23: 7232 | O23: 0.1512 | P23: =IF(OR(E23="",E23=0),"",D23*100/E23) -> 2.7074841 | Q23: =IF(OR(H23="",H23=0),"",G23*100/H23) -> 2.8035245 | R23: =IF(OR(K23="",K23=0),"",J23*100/K23) -> 3.0386116 | S23: =IF(OR(N23="",N23=0),"",M23*100/N23) -> 2.6613662 | T23: =IF(OR(D23="",G23="",D23=0),"n/a",G23/D23-1) -> -0.30176724 | U23: =IF(OR(G23="",J23="",G23=0),"n/a",J23/G23-1) -> 0.069623678 | V23: =IF(M23="","",M23*$G$4) -> 361.37224 | W23: =IF(OR(J23="",V23=""),"n/a",V23/J23-1) -> -0.29679067 | X23: =IF(J23="","",J23/$J$28) -> 0.20140544 | Y23: =IF(OR(F23="",L23=""),"",(L23-F23)*10000) -> 4 | Z23: =D23-SUM(D19:D22) -> 0.01 | AA23: =(F23-AVERAGE(F19:F22))*100 -> -0.005 | AB23: =SUMPRODUCT(D19:D22,F19:F22)/SUM(D19:D22) -> 0.16468215 | AC23: =SUMPRODUCT(J19:J22,L19:L22)/SUM(J19:J22) -> 0.1646571
A24: 18 | B24: Retail Others | C24: BIL | D24: 7.86 | E24: 29 | F24: 0.1649 | G24: 5.5 | H24: 20 | I24: 0.1577 | J24: 1.11 | K24: 5 | L24: 0.1562 | M24: 1.25 | N24: 6 | O24: 0.1565 | P24: =IF(OR(E24="",E24=0),"",D24*100/E24) -> 27.103448 | Q24: =IF(OR(H24="",H24=0),"",G24*100/H24) -> 27.5 | R24: =IF(OR(K24="",K24=0),"",J24*100/K24) -> 22.2 | S24: =IF(OR(N24="",N24=0),"",M24*100/N24) -> 20.833333 | T24: =IF(OR(D24="",G24="",D24=0),"n/a",G24/D24-1) -> -0.30025445 | U24: =IF(OR(G24="",J24="",G24=0),"n/a",J24/G24-1) -> -0.79818182 | V24: =IF(M24="","",M24*$G$4) -> 2.3469388 | W24: =IF(OR(J24="",V24=""),"n/a",V24/J24-1) -> 1.1143593 | X24: =IF(J24="","",J24/$J$28) -> 0.0004350348 | Y24: =IF(OR(F24="",L24=""),"",(L24-F24)*10000) -> -87
A25: 19 | B25: Retail Others | C25: Education Loan | D25: 3.67 | E25: 29 | F25: 0.0943 | G25: 3.82 | H25: 29 | I25: 0.0931 | J25: 3.85 | K25: 22 | L25: 0.0931 | M25: 3.53 | N25: 19 | O25: 0.0925 | P25: =IF(OR(E25="",E25=0),"",D25*100/E25) -> 12.655172 | Q25: =IF(OR(H25="",H25=0),"",G25*100/H25) -> 13.172414 | R25: =IF(OR(K25="",K25=0),"",J25*100/K25) -> 17.5 | S25: =IF(OR(N25="",N25=0),"",M25*100/N25) -> 18.578947 | T25: =IF(OR(D25="",G25="",D25=0),"n/a",G25/D25-1) -> 0.040871935 | U25: =IF(OR(G25="",J25="",G25=0),"n/a",J25/G25-1) -> 0.0078534031 | V25: =IF(M25="","",M25*$G$4) -> 6.6277551 | W25: =IF(OR(J25="",V25=""),"n/a",V25/J25-1) -> 0.72149483 | X25: =IF(J25="","",J25/$J$28) -> 0.0015089045 | Y25: =IF(OR(F25="",L25=""),"",(L25-F25)*10000) -> -12
A26: 20 | B26: Retail Others | C26: Gold Loan-BBB | D26: 655.21 | E26: 11843 | F26: 0.1156 | G26: 756.67 | H26: 11394 | I26: 0.1142 | J26: 396.14 | K26: 7395 | L26: 0.1159 | M26: 150.89 | N26: 3523 | O26: 0.1182 | P26: =IF(OR(E26="",E26=0),"",D26*100/E26) -> 5.5324664 | Q26: =IF(OR(H26="",H26=0),"",G26*100/H26) -> 6.6409514 | R26: =IF(OR(K26="",K26=0),"",J26*100/K26) -> 5.3568627 | S26: =IF(OR(N26="",N26=0),"",M26*100/N26) -> 4.2829974 | T26: =IF(OR(D26="",G26="",D26=0),"n/a",G26/D26-1) -> 0.15485112 | U26: =IF(OR(G26="",J26="",G26=0),"n/a",J26/G26-1) -> -0.47646927 | V26: =IF(M26="","",M26*$G$4) -> 283.30367 | W26: =IF(OR(J26="",V26=""),"n/a",V26/J26-1) -> -0.28483952 | X26: =IF(J26="","",J26/$J$28) -> 0.15525647 | Y26: =IF(OR(F26="",L26=""),"",(L26-F26)*10000) -> 3
A27: 21 | B27: Retail Others | C27: Total | D27: 666.74 | E27: 11901 | F27: 0.125 | G27: 765.99 | H27: 11443 | I27: 0.1217 | J27: 401.09 | K27: 7422 | L27: 0.1217 | M27: 155.68 | N27: 3548 | O27: 0.1224 | P27: =IF(OR(E27="",E27=0),"",D27*100/E27) -> 5.6023864 | Q27: =IF(OR(H27="",H27=0),"",G27*100/H27) -> 6.6939614 | R27: =IF(OR(K27="",K27=0),"",J27*100/K27) -> 5.404069 | S27: =IF(OR(N27="",N27=0),"",M27*100/N27) -> 4.3878241 | T27: =IF(OR(D27="",G27="",D27=0),"n/a",G27/D27-1) -> 0.14885863 | U27: =IF(OR(G27="",J27="",G27=0),"n/a",J27/G27-1) -> -0.47637698 | V27: =IF(M27="","",M27*$G$4) -> 292.29714 | W27: =IF(OR(J27="",V27=""),"n/a",V27/J27-1) -> -0.27124301 | X27: =IF(J27="","",J27/$J$28) -> 0.15719649 | Y27: =IF(OR(F27="",L27=""),"",(L27-F27)*10000) -> -33 | Z27: =D27-SUM(D24:D26) -> 0 | AA27: =(F27-AVERAGE(F24:F26))*100 -> 0.0066666667 | AB27: =SUMPRODUCT(D24:D26,F24:F26)/SUM(D24:D26) -> 0.11606394 | AC27: =SUMPRODUCT(J24:J26,L24:L26)/SUM(J24:J26) -> 0.11579268
A28: 22 | B28: Grand Total | C28: Grand Total | D28: 3738.17 | E28: 40960 | F28: 0.1176 | G28: 3336.22 | H28: 32917 | I28: 0.1207 | J28: 2551.52 | K28: 28161 | L28: 0.1196 | M28: 1110.2 | N28: 12714 | O28: 0.1198 | P28: =IF(OR(E28="",E28=0),"",D28*100/E28) -> 9.1263916 | Q28: =IF(OR(H28="",H28=0),"",G28*100/H28) -> 10.135249 | R28: =IF(OR(K28="",K28=0),"",J28*100/K28) -> 9.0604737 | S28: =IF(OR(N28="",N28=0),"",M28*100/N28) -> 8.7321063 | T28: =IF(OR(D28="",G28="",D28=0),"n/a",G28/D28-1) -> -0.10752587 | U28: =IF(OR(G28="",J28="",G28=0),"n/a",J28/G28-1) -> -0.23520631 | V28: =IF(M28="","",M28*$G$4) -> 2084.4571 | W28: =IF(OR(J28="",V28=""),"n/a",V28/J28-1) -> -0.18305279 | X28: =IF(J28="","",J28/$J$28) -> 1 | Y28: =IF(OR(F28="",L28=""),"",(L28-F28)*10000) -> 20 | Z28: =D28-(D12+D18+D23+D27) -> 0 | AA28: =(F28-AVERAGEIF(C7:C27,"<>Total",F7:F27))*100 -> -0.0035294118 | AB28: =SUMPRODUCT((C7:C27<>"Total")*D7:D27,F7:F27)/SUMPRODUCT((C7:C27<>"Total")*D7:D27) -> 0.11075247 | AC28: =SUMPRODUCT((C7:C27<>"Total")*J7:J27,L7:L27)/SUMPRODUCT((C7:C27<>"Total")*J7:J27) -> 0.11177939
A31: B. Lower 'FY 2027 Q2' table — unlabelled in the original; labels inferred (blue values as printed)
A32: # | B32: Inferred label | D32: Disb ₹ Cr | E32: # | F32: Yield % | G32: Match to upper Q2 (Disb) | H32: Match to upper Q2 (#)
A33: 1 | B33: Micro LAP RFL (inferred) | D33: 5.3 | E33: 25 | F33: 0.128 | G33: =D33-M9 -> 0.01 | H33: =E33-N9 -> 0
A34: 2 | B34: Micro LAP (inferred) | D34: 34.6 | E34: 164 | F34: 0.123 | G34: =D34-M8 -> 0 | H34: =E34-N8 -> 0
A35: 3 | B35: LAP Colending (inferred) | D35: 11.8 | E35: 24 | F35: 0.094 | G35: =D35-M10 -> 0.03 | H35: =E35-N10 -> 0
A36: 4 | B36: LAP (inferred) | D36: 455.2 | E36: 287 | F36: 0.089 | G36: =D36-M7 -> -0.03 | H36: =E36-N7 -> 0
A37: 5 | B37: DA Portfolio LAP (inferred) | D37: 29.7 | E37: 3 | F37: 0.088 | G37: =D37-M11 -> -0.02 | H37: =E37-N11 -> 0
A38: 6 | B38: LAP Total (inferred) | D38: 536.6 | E38: 503 | F38: 0.104 | G38: =D38-M12 -> -0.01 | H38: =E38-N12 -> 0
A39: 7 | B39: PHL (inferred) | D39: 88.5 | E39: 224 | F39: 0.084 | G39: =D39-M13 -> -0.02 | H39: =E39-N13 -> 0
A40: 8 | B40: Unlabelled — not in upper table (PHL Colending / DA?) | D40: 56.4 | E40: 2 | F40: 0.088
A41: 9 | B41: AHL RFL (inferred) | D41: 13.6 | E41: 148 | F41: 0.113 | G41: =D41-M15 -> -0.01 | H41: =E41-N15 -> 0
A42: 10 | B42: Unlabelled — not in upper table (AHL Colending?) | D42: 4.1 | E42: 41 | F42: 0.123
...

Sheet B1_Metrics
A1: Retail disbursement MIS: notation and metrics
A2: Format: Notation → Exhaustive metrics table | Example column = live Excel formula on the block sheet (green = cross-sheet)
A3: ⚠ DRAFT ONLY — Requires review and approval by a qualified Alvarez and Marsal professional before use.
A5: Notation
B6: Symbol | C6: Meaning
B7: D(s,q) | C7: Disbursement ₹ Cr for sub-product s in quarter q
B8: N(s,q) | C8: Number of disbursements
B9: Y(s,q) | C9: Yield % on disbursement as printed
B10: q | C10: Q3 FY26, Q4 FY26, Q1 FY27, Q2 FY27 (partial to 18-Aug-2026)
B11: C | C11: Category total (LAP, Home Loan, Wheels, Retail Others); GT = Grand Total
B12: ATS | C12: D × 100 ÷ N, ₹ lakh
B13: RR(Q2) | C13: Run-rate = D(Q2) × days-in-quarter ÷ days-elapsed (92 ÷ 49)
B14: g | C14: D(q) ÷ D(q−1) − 1
B15: Ȳ(C) | C15: True disbursement-weighted yield = Σ D × Y ÷ Σ D
B16: Ȳs(C) | C16: Simple average of sub-product yields — what the page prints as the category yield
B17: bp / pp | C17: Basis points / percentage points
B18: L | C18: Lower unlabelled FY27 Q2 table
B19: Disbursement in ₹ Cr, counts, yield in %; ATS in ₹ lakh; Q2 FY27 partial (to 18-Aug-2026); printed yields are simple averages.
A21: Exhaustive metrics table
A22: # | B22: Metric family | C22: Pipeline-ready metric | D22: Definition / formula | E22: Applies to | F22: Example
A23: 1 | B23: Fact lookup | C23: Disbursement | D23: D(s,q) | E23: 16 sub-products × 4 quarters | F23: ="LAP "&TEXT(B1_Disbursement_MIS!D7,"#,##0.00;-#,##0.00;0.00")&" / "&TEXT(B1_Disbursement_MIS!G7,"#,##0.00;-#,##0.00;0.00")&" / "&TEXT(B1_Disbursement_MIS!J7,"#,##0.00;-#,##0.00;0.00")&" / "&TEXT(B1_Disbursement_MIS!M7,"#,##0.00;-#,##0.00;0.00") -> LAP 1,030.19 / 1,305.36 / 960.54 / 455.23
A24: 2 | B24: Fact lookup | C24: Count | D24: N(s,q) | E24: 16 × 4 | F24: ="Two Wheeler "&TEXT(B1_Disbursement_MIS!E20,"#,##0")&" / "&TEXT(B1_Disbursement_MIS!H20,"#,##0")&" / "&TEXT(B1_Disbursement_MIS!K20,"#,##0")&" / "&TEXT(B1_Disbursement_MIS!N20,"#,##0") -> Two Wheeler 13,330 / 7,980 / 7,011 / 3,622
A25: 3 | B25: Fact lookup | C25: Yield | D25: Y(s,q) | E25: 16 × 4 | F25: ="Two Wheeler "&TEXT(B1_Disbursement_MIS!F20,"0.00%")&" / "&TEXT(B1_Disbursement_MIS!I20,"0.00%")&" / "&TEXT(B1_Disbursement_MIS!L20,"0.00%")&" / "&TEXT(B1_Disbursement_MIS!O20,"0.00%")&"; LAP "&TEXT(B1_Disbursement_MIS!F7,"0.00%")&" / "&TEXT(B1_Disbursement_MIS!I7,"0.00%")&" / "&TEXT(B1_Disbursement_MIS!L7,"0.00%")&" / "&TEXT(B1_Disbursement_MIS!O7,"0.00%") -> Two Wheeler 20.81% / 20.85% / 20.83% / 20.85%; LAP 9.44% / 9.11% / 8.96% / 8.90%
A26: 4 | B26: Fact lookup | C26: Category and Grand totals | D26: D(C,q), N(C,q), Y(C,q) | E26: 5 × 4 | F26: ="GT D "&TEXT(B1_Disbursement_MIS!D28,"#,##0.00;-#,##0.00;0.00")&" / "&TEXT(B1_Disbursement_MIS!G28,"#,##0.00;-#,##0.00;0.00")&" / "&TEXT(B1_Disbursement_MIS!J28,"#,##0.00;-#,##0.00;0.00")&" / "&TEXT(B1_Disbursement_MIS!M28,"#,##0.00;-#,##0.00;0.00")&"; N "&TEXT(B1_Disbursement_MIS!E28,"#,##0")&" / "&TEXT(B1_Disbursement_MIS!H28,"#,##0")&" / "&TEXT(B1_Disbursement_MIS!K28,"#,##0")&" / "&TEXT(B1_Disbursement_MIS!N28,"#,##0") -> GT D 3,738.17 / 3,336.22 / 2,551.52 / 1,110.20; N 40,960 / 32,917 / 28,161 / 12,714
A27: 5 | B27: Roll-up check | C27: Sub-products to category | D27: D(C) − Σ D(s) | E27: 4 categories + GT (Q3) | F27: =TEXT(B1_Disbursement_MIS!Z12,"#,##0.00;-#,##0.00;0.00")&" / "&TEXT(B1_Disbursement_MIS!Z18,"#,##0.00;-#,##0.00;0.00")&" / "&TEXT(B1_Disbursement_MIS!Z23,"#,##0.00;-#,##0.00;0.00")&" / "&TEXT(B1_Disbursement_MIS!Z27,"#,##0.00;-#,##0.00;0.00")&" / "&TEXT(B1_Disbursement_MIS!Z28,"#,##0.00;-#,##0.00;0.00") -> 0.00 / 0.00 / 0.01 / 0.00 / 0.00
A28: 6 | B28: Roll-up check | C28: Yield construction | D28: Y(C) − Ȳs(C), pp (≈0 → printed yields are simple averages) | E28: 4 categories + GT (Q3) | F28: =TEXT(B1_Disbursement_MIS!AA12,"+0.0"" pp"";-0.0"" pp"";0.0"" pp""")&" / "&TEXT(B1_Disbursement_MIS!AA18,"+0.0"" pp"";-0.0"" pp"";0.0"" pp""")&" / "&TEXT(B1_Disbursement_MIS!AA23,"+0.0"" pp"";-0.0"" pp"";0.0"" pp""")&" / "&TEXT(B1_Disbursement_MIS!AA27,"+0.0"" pp"";-0.0"" pp"";0.0"" pp""")&" / "&TEXT(B1_Disbursement_MIS!AA28,"+0.0"" pp"";-0.0"" pp"";0.0"" pp""") -> -0.0 pp / -0.0 pp / -0.0 pp / +0.0 pp / -0.0 pp
A29: 7 | B29: Pricing | C29: True weighted yield | D29: Ȳ(C) = Σ D × Y ÷ Σ D | E29: 4 categories + GT; Q3 and Q1 | F29: ="Q3 "&TEXT(B1_Disbursement_MIS!AB12,"0.00%")&" / "&TEXT(B1_Disbursement_MIS!AB18,"0.00%")&" / "&TEXT(B1_Disbursement_MIS!AB23,"0.00%")&" / "&TEXT(B1_Disbursement_MIS!AB27,"0.00%")&" / "&TEXT(B1_Disbursement_MIS!AB28,"0.00%")&"; Q1 "&TEXT(B1_Disbursement_MIS!AC12,"0.00%")&" / "&TEXT(B1_Disbursement_MIS!AC18,"0.00%")&" / "&TEXT(B1_Disbursement_MIS!AC23,"0.00%")&" / "&TEXT(B1_Disbursement_MIS!AC27,"0.00%")&" / "&TEXT(B1_Disbursement_MIS!AC28,"0.00%") -> Q3 9.22% / 9.79% / 16.47% / 11.61% / 11.08%; Q1 9.24% / 9.80% / 16.47% / 11.58% / 11.18%
A30: 8 | B30: Pricing | C30: Printed − weighted yield | D30: (Y(C) − Ȳ(C)) × 100, pp | E30: 4 categories + GT (Q3) | F30: =TEXT((B1_Disbursement_MIS!F12-B1_Disbursement_MIS!AB12)*100,"+0.0"" pp"";-0.0"" pp"";0.0"" pp""")&" / "&TEXT((B1_Disbursement_MIS!F18-B1_Disbursement_MIS!AB18)*100,"+0.0"" pp"";-0.0"" pp"";0.0"" pp""")&" / "&TEXT((B1_Disbursement_MIS!F23-B1_Disbursement_MIS!AB23)*100,"+0.0"" pp"";-0.0"" pp"";0.0"" pp""")&" / "&TEXT((B1_Disbursement_MIS!F27-B1_Disbursement_MIS!AB27)*100,"+0.0"" pp"";-0.0"" pp"";0.0"" pp""")&" / "&TEXT((B1_Disbursement_MIS!F28-B1_Disbursement_MIS!AB28)*100,"+0.0"" pp"";-0.0"" pp"";0.0"" pp""") -> +1.4 pp / +0.2 pp / -1.6 pp / +0.9 pp / +0.7 pp
A31: 9 | B31: Pricing | C31: Blended yield trend (printed) | D31: Y(GT,q) | E31: 4 quarters | F31: =TEXT(B1_Disbursement_MIS!F28,"0.00%")&" / "&TEXT(B1_Disbursement_MIS!I28,"0.00%")&" / "&TEXT(B1_Disbursement_MIS!L28,"0.00%")&" / "&TEXT(B1_Disbursement_MIS!O28,"0.00%") -> 11.76% / 12.07% / 11.96% / 11.98%
A32: 10 | B32: Pricing | C32: Yield change Q1 − Q3 | D32: (Y(Q1) − Y(Q3)) × 10,000 bp | E32: All rows | F32: ="GT "&TEXT(B1_Disbursement_MIS!Y28,"0")&" bp; LAP "&TEXT(B1_Disbursement_MIS!Y7,"0")&"; AHL "&TEXT(B1_Disbursement_MIS!Y14,"0")&"; RVF "&TEXT(B1_Disbursement_MIS!Y22,"0") -> GT 20 bp; LAP -48; AHL -18; RVF 23
A33: 11 | B33: Pricing | C33: Yield spread to GT | D33: Y(s,Q1) − Y(GT,Q1), pp | E33: 16 sub-products | F33: ="Two Wheeler "&TEXT((B1_Disbursement_MIS!L20-B1_Disbursement_MIS!L28)*100,"+0.0"" pp"";-0.0"" pp"";0.0"" pp""")&"; LAP "&TEXT((B1_Disbursement_MIS!L7-B1_Disbursement_MIS!L28)*100,"+0.0"" pp"";-0.0"" pp"";0.0"" pp""") -> Two Wheeler +8.9 pp; LAP -3.0 pp
A34: 12 | B34: Pricing | C34: Yield-weighted disbursement (income proxy) | D34: Σ D × Y over sub-products | E34: GT by quarter | F34: =TEXT(B1_Disbursement_MIS!D28*B1_Disbursement_MIS!AB28,"#,##0.00;-#,##0.00;0.00")&" / "&TEXT(B1_Disbursement_MIS!J28*B1_Disbursement_MIS!AC28,"#,##0.00;-#,##0.00;0.00")&" (Q3 / Q1, ₹ Cr-yield)" -> 414.01 / 285.21 (Q3 / Q1, ₹ Cr-yield)
A35: 13 | B35: Ticket size | C35: ATS by sub-product | D35: ATS(s,q) | E35: 16 × 4 | F35: ="LAP "&TEXT(B1_Disbursement_MIS!P7,"#,##0.00")&" / "&TEXT(B1_Disbursement_MIS!Q7,"#,##0.00")&" / "&TEXT(B1_Disbursement_MIS!R7,"#,##0.00")&" / "&TEXT(B1_Disbursement_MIS!S7,"#,##0.00")&"; AHL "&TEXT(B1_Disbursement_MIS!P14,"#,##0.00")&" / "&TEXT(B1_Disbursement_MIS!Q14,"#,##0.00")&" / "&TEXT(B1_Disbursement_MIS!R14,"#,##0.00")&" / "&TEXT(B1_Disbursement_MIS!S14,"#,##0.00")&"; Gold "&TEXT(B1_Disbursement_MIS!P26,"#,##0.00")&" / "&TEXT(B1_Disbursement_MIS!Q26,"#,##0.00")&" / "&TEXT(B1_Disbursement_MIS!R26,"#,##0.00")&" / "&TEXT(B1_Disbursement_MIS!S26,"#,##0.00") -> LAP 199.65 / 223.52 / 180.21 / 158.62; AHL 14.43 / 15.11 / 12.71 / 11.64; Gold 5.53 / 6.64 / 5.36 / 4.28
A36: 14 | B36: Ticket size | C36: ATS by category / GT | D36: ATS(C,q) | E36: 5 × 4 | F36: ="GT "&TEXT(B1_Disbursement_MIS!P28,"#,##0.00")&" / "&TEXT(B1_Disbursement_MIS!Q28,"#,##0.00")&" / "&TEXT(B1_Disbursement_MIS!R28,"#,##0.00")&" / "&TEXT(B1_Disbursement_MIS!S28,"#,##0.00")&"; Wheels "&TEXT(B1_Disbursement_MIS!P23,"#,##0.00")&" / "&TEXT(B1_Disbursement_MIS!Q23,"#,##0.00")&" / "&TEXT(B1_Disbursement_MIS!R23,"#,##0.00")&" / "&TEXT(B1_Disbursement_MIS!S23,"#,##0.00") -> GT 9.13 / 10.14 / 9.06 / 8.73; Wheels 2.71 / 2.80 / 3.04 / 2.66
A37: 15 | B37: Ticket size | C37: ATS change | D37: ATS(Q1) ÷ ATS(Q3) − 1 | E37: All rows | F37: ="GT "&TEXT(B1_Disbursement_MIS!R28/B1_Disbursement_MIS!P28-1,"+0.0%;-0.0%;0.0%")&"; LAP "&TEXT(B1_Disbursement_MIS!R7/B1_Disbursement_MIS!P7-1,"+0.0%;-0.0%;0.0%") -> GT -0.7%; LAP -9.7%
A38: 16 | B38: Growth & momentum | C38: QoQ growth | D38: g(Q4/Q3), g(Q1/Q4) | E38: All rows | F38: ="GT "&TEXT(B1_Disbursement_MIS!T28,"+0.0%;-0.0%;0.0%")&" / "&TEXT(B1_Disbursement_MIS!U28,"+0.0%;-0.0%;0.0%")&"; LAP cat "&TEXT(B1_Disbursement_MIS!T12,"+0.0%;-0.0%;0.0%")&" / "&TEXT(B1_Disbursement_MIS!U12,"+0.0%;-0.0%;0.0%")&"; Gold "&TEXT(B1_Disbursement_MIS!T26,"+0.0%;-0.0%;0.0%")&" / "&TEXT(B1_Disbursement_MIS!U26,"+0.0%;-0.0%;0.0%") -> GT -10.8% / -23.5%; LAP cat -14.7% / -26.4%; Gold +15.5% / -47.6%
A39: 17 | B39: Growth & momentum | C39: Two-quarter change | D39: D(Q1) ÷ D(Q3) − 1; N(Q1) ÷ N(Q3) − 1 | E39: All rows | F39: ="GT value "&TEXT(B1_Disbursement_MIS!J28/B1_Disbursement_MIS!D28-1,"+0.0%;-0.0%;0.0%")&"; count "&TEXT(B1_Disbursement_MIS!K28/B1_Disbursement_MIS!E28-1,"+0.0%;-0.0%;0.0%") -> GT value -31.7%; count -31.2%
A40: 18 | B40: Growth & momentum | C40: LAP growth ex DA Portfolio | D40: (D(LAP) − D(DA))(q) ÷ same (q−1) − 1 | E40: Q4, Q1 | F40: =TEXT((B1_Disbursement_MIS!G12-B1_Disbursement_MIS!G11)/(B1_Disbursement_MIS!D12-B1_Disbursement_MIS!D11)-1,"+0.0%;-0.0%;0.0%")&" / "&TEXT((B1_Disbursement_MIS!J12-B1_Disbursement_MIS!J11)/(B1_Disbursement_MIS!G12-B1_Disbursement_MIS!G11)-1,"+0.0%;-0.0%;0.0%") -> +22.4% / -28.7%
A41: 19 | B41: Run-rate & pacing | C41: Q2 annualised run-rate | D41: RR(Q2) | E41: All rows | F41: ="GT "&TEXT(B1_Disbursement_MIS!V28,"#,##0.00;-#,##0.00;0.00")&"; LAP "&TEXT(B1_Disbursement_MIS!V12,"#,##0.00;-#,##0.00;0.00")&"; Home "&TEXT(B1_Disbursement_MIS!V18,"#,##0.00;-#,##0.00;0.00")&"; Wheels "&TEXT(B1_Disbursement_MIS!V23,"#,##0.00;-#,##0.00;0.00")&"; Others "&TEXT(B1_Disbursement_MIS!V27,"#,##0.00;-#,##0.00;0.00") -> GT 2,084.46; LAP 1,007.51; Home 423.26; Wheels 361.37; Others 292.30
A42: 20 | B42: Run-rate & pacing | C42: Q2 run-rate vs Q1 | D42: RR(Q2) ÷ D(Q1) − 1 | E42: All rows | F42: ="GT "&TEXT(B1_Disbursement_MIS!W28,"+0.0%;-0.0%;0.0%")&"; LAP "&TEXT(B1_Disbursement_MIS!W12,"+0.0%;-0.0%;0.0%")&"; Home "&TEXT(B1_Disbursement_MIS!W18,"+0.0%;-0.0%;0.0%")&"; Wheels "&TEXT(B1_Disbursement_MIS!W23,"+0.0%;-0.0%;0.0%")&"; Others "&TEXT(B1_Disbursement_MIS!W27,"+0.0%;-0.0%;0.0%") -> GT -18.3%; LAP -9.6%; Home -19.0%; Wheels -29.7%; Others -27.1%
...
