Workbook

Sheet README
A1: RBL Bank — Wholesale Banking Balance Sheet (Oneview): page-wise metric extraction
A2: Source: 06_WB_Balance_Sheet.pdf (1 page, 10 segment blocks) | ₹ Cr | FY26 A, Q1 FY26 A, Q1 FY27 A actuals; Jul'26 P projection; Q2 FY27 B and FY27 B budgets
A3: ⚠ DRAFT ONLY — Requires review and approval by a qualified Alvarez and Marsal professional before use.
A5: Sheet map
A6: B1_WB_Balance_Sheet | B6: Segment × line × column grid with derived ratios (CASA, EOP/AVG, LDR), growth / budget pacing columns, and segment roll-up to Wholesale Banking
A7: B1_Metrics | B7: Notation + exhaustive metrics
A9: Colour legend
A10: Blue text | B10: Hard-coded input transcribed from the PDF
A11: Blue italic on grey | B11: Budget / projected value (ᴾ) transcribed from the PDF
A12: Black text | B12: Formula on the same sheet
A13: Green text | B13: Link to another sheet
A14: Yellow fill | B14: Data flag to review
A16: Key assumptions (confirm with client)
A17: 1 | B17: Columns marked P (Jul'26 projection) and B (Q2 FY27 / FY27 budget) are forward-looking (ᴾ); every metric that uses them is labelled 'incl. projection / budget'.
A18: 2 | B18: MNC and Commercial Banking show deposit figures identical to Corporate Banking in the original — a copy error on the page. Deposit roll-ups are shown with and without these two segments; advances roll up exactly to Wholesale Banking.
A19: 3 | B19: Two blocks are both titled 'Liabilities & New Economy'. The second block's advances (3,540 → 4,008) equal the IFI line on the Net Advances page; it is labelled 'L&NE (2) — advances match IFI'.
A20: 4 | B20: Glossary on page: for MNC and L&NE, CA EOP / CA AVG include Nodal Balance; excluded for other segments.
A21: 5 | B21: Cross-page: Wholesale ADV EOP Q1 FY27 (51,323) vs Net Advances Jun-26 wholesale (51,044) differ by ~₹279 Cr (gross vs net funded basis).
A22: Confidentiality | B22: Client-confidential RBL Bank data.
A24: ⚠ DRAFT ONLY — Requires review and approval by a qualified Alvarez and Marsal professional before use.

Sheet B1_WB_Balance_Sheet
A1: Block 1 — Wholesale Banking balance sheet by segment (Oneview)
A2: Source: WB – Balance Sheet.pdf | ₹ Cr | A = actual, P = projection, B = budget (grey)
A3: ⚠ DRAFT ONLY — Requires review and approval by a qualified Alvarez and Marsal professional before use.
A5: A. Source data (blue; grey = P/B) with growth, pacing and ratio calculations
A6: # | B6: Segment | C6: Line | D6: FY26 A | E6: Q1 FY26 A | F6: Q1 FY27 A | G6: Jul'26 P | H6: Q2 FY27 B | I6: FY27 B | J6: Q1 YoY (Q1 FY27 ÷ Q1 FY26 − 1) | K6: Q1 FY27 vs FY26 A | L6: Jul'26 P vs Q1 FY27 A ᴾ | M6: Q2 FY27 B vs Q1 FY27 A ᴾ | N6: FY27 B vs FY26 A ᴾ | O6: Q1 A as % of Q2 B ᴾ | P6: FY27 B − FY26 A ᴾ | Q6: Share of Wholesale (Q1 FY27 A)
A7: 1 | B7: Wholesale Banking (total) | C7: ADV EOP | D7: 47432 | E7: 38256 | F7: 51323 | G7: 52289 | H7: 53098 | I7: 59961 | J7: =IF(E7=0,"n/a",F7/E7-1) -> 0.34156734 | K7: =IF(D7=0,"n/a",F7/D7-1) -> 0.082033227 | L7: =IF(F7=0,"n/a",G7/F7-1) -> 0.018821971 | M7: =IF(F7=0,"n/a",H7/F7-1) -> 0.034584884 | N7: =IF(D7=0,"n/a",I7/D7-1) -> 0.26414657 | O7: =IF(H7=0,"n/a",F7/H7) -> 0.96657125 | P7: =I7-D7 -> 12529 | Q7: =F7/F$7 -> 1
A8: 2 | B8: Wholesale Banking (total) | C8: ADV AVG | D8: 38331 | E8: 34795 | F8: 45724 | G8: 49538 | H8: 47771 | I8: 49765 | J8: =IF(E8=0,"n/a",F8/E8-1) -> 0.31409685 | K8: =IF(D8=0,"n/a",F8/D8-1) -> 0.19287261 | L8: =IF(F8=0,"n/a",G8/F8-1) -> 0.083413525 | M8: =IF(F8=0,"n/a",H8/F8-1) -> 0.044768612 | N8: =IF(D8=0,"n/a",I8/D8-1) -> 0.29829642 | O8: =IF(H8=0,"n/a",F8/H8) -> 0.95714974 | P8: =I8-D8 -> 11434 | Q8: =F8/F$8 -> 1
A9: 3 | B9: Wholesale Banking (total) | C9: CA EOP | D9: 17886 | E9: 11680 | F9: 9341 | G9: 5649 | H9: 9607 | I9: 14432 | J9: =IF(E9=0,"n/a",F9/E9-1) -> -0.20025685 | K9: =IF(D9=0,"n/a",F9/D9-1) -> -0.47774796 | L9: =IF(F9=0,"n/a",G9/F9-1) -> -0.39524676 | M9: =IF(F9=0,"n/a",H9/F9-1) -> 0.028476609 | N9: =IF(D9=0,"n/a",I9/D9-1) -> -0.19311193 | O9: =IF(H9=0,"n/a",F9/H9) -> 0.97231186 | P9: =I9-D9 -> -3454 | Q9: =F9/F$9 -> 1
A10: 4 | B10: Wholesale Banking (total) | C10: SA EOP | D10: 1783 | E10: 882 | F10: 1773 | G10: 1594 | H10: 1491 | I10: 2896 | J10: =IF(E10=0,"n/a",F10/E10-1) -> 1.0102041 | K10: =IF(D10=0,"n/a",F10/D10-1) -> -0.005608525 | L10: =IF(F10=0,"n/a",G10/F10-1) -> -0.10095883 | M10: =IF(F10=0,"n/a",H10/F10-1) -> -0.15905245 | N10: =IF(D10=0,"n/a",I10/D10-1) -> 0.62422883 | O10: =IF(H10=0,"n/a",F10/H10) -> 1.1891348 | P10: =I10-D10 -> 1113 | Q10: =F10/F$10 -> 1
A11: 5 | B11: Wholesale Banking (total) | C11: TD EOP | D11: 33402 | E11: 29600 | F11: 32624 | G11: 30725 | H11: 35730 | I11: 40000 | J11: =IF(E11=0,"n/a",F11/E11-1) -> 0.10216216 | K11: =IF(D11=0,"n/a",F11/D11-1) -> -0.023292018 | L11: =IF(F11=0,"n/a",G11/F11-1) -> -0.058208681 | M11: =IF(F11=0,"n/a",H11/F11-1) -> 0.095205983 | N11: =IF(D11=0,"n/a",I11/D11-1) -> 0.19753308 | O11: =IF(H11=0,"n/a",F11/H11) -> 0.91307025 | P11: =I11-D11 -> 6598 | Q11: =F11/F$11 -> 1
A12: 6 | B12: Wholesale Banking (total) | C12: Deposits EOP | D12: 53070 | E12: 42162 | F12: 43738 | G12: 37968 | H12: 46828 | I12: 57328 | J12: =IF(E12=0,"n/a",F12/E12-1) -> 0.037379631 | K12: =IF(D12=0,"n/a",F12/D12-1) -> -0.17584323 | L12: =IF(F12=0,"n/a",G12/F12-1) -> -0.1319219 | M12: =IF(F12=0,"n/a",H12/F12-1) -> 0.070647949 | N12: =IF(D12=0,"n/a",I12/D12-1) -> 0.080233654 | O12: =IF(H12=0,"n/a",F12/H12) -> 0.93401384 | P12: =I12-D12 -> 4258 | Q12: =F12/F$12 -> 1
A13: 7 | B13: Wholesale Banking (total) | C13: CA AVG | D13: 7267 | E13: 5688 | F13: 6544 | G13: 6069 | H13: 8165 | I13: 8633 | J13: =IF(E13=0,"n/a",F13/E13-1) -> 0.15049226 | K13: =IF(D13=0,"n/a",F13/D13-1) -> -0.099490849 | L13: =IF(F13=0,"n/a",G13/F13-1) -> -0.072585575 | M13: =IF(F13=0,"n/a",H13/F13-1) -> 0.24770782 | N13: =IF(D13=0,"n/a",I13/D13-1) -> 0.18797303 | O13: =IF(H13=0,"n/a",F13/H13) -> 0.80146969 | P13: =I13-D13 -> 1366 | Q13: =F13/F$13 -> 1
A14: 8 | B14: Wholesale Banking (total) | C14: SA AVG | D14: 967 | E14: 908 | F14: 1580 | G14: 1123 | H14: 1225 | I14: 1336 | J14: =IF(E14=0,"n/a",F14/E14-1) -> 0.74008811 | K14: =IF(D14=0,"n/a",F14/D14-1) -> 0.63391934 | L14: =IF(F14=0,"n/a",G14/F14-1) -> -0.28924051 | M14: =IF(F14=0,"n/a",H14/F14-1) -> -0.22468354 | N14: =IF(D14=0,"n/a",I14/D14-1) -> 0.38159255 | O14: =IF(H14=0,"n/a",F14/H14) -> 1.2897959 | P14: =I14-D14 -> 369 | Q14: =F14/F$14 -> 1
A15: 9 | B15: Wholesale Banking (total) | C15: TD AVG | D15: 30114 | E15: 26619 | F15: 36465 | G15: 32077 | H15: 35886 | I15: 37072 | J15: =IF(E15=0,"n/a",F15/E15-1) -> 0.36988617 | K15: =IF(D15=0,"n/a",F15/D15-1) -> 0.21089859 | L15: =IF(F15=0,"n/a",G15/F15-1) -> -0.12033457 | M15: =IF(F15=0,"n/a",H15/F15-1) -> -0.015878239 | N15: =IF(D15=0,"n/a",I15/D15-1) -> 0.23105532 | O15: =IF(H15=0,"n/a",F15/H15) -> 1.0161344 | P15: =I15-D15 -> 6958 | Q15: =F15/F$15 -> 1
A16: 10 | B16: Wholesale Banking (total) | C16: Deposits Avg | D16: 38348 | E16: 33215 | F16: 44589 | G16: 39268 | H16: 45276 | I16: 47041 | J16: =IF(E16=0,"n/a",F16/E16-1) -> 0.34243565 | K16: =IF(D16=0,"n/a",F16/D16-1) -> 0.16274643 | L16: =IF(F16=0,"n/a",G16/F16-1) -> -0.11933436 | M16: =IF(F16=0,"n/a",H16/F16-1) -> 0.015407387 | N16: =IF(D16=0,"n/a",I16/D16-1) -> 0.22668718 | O16: =IF(H16=0,"n/a",F16/H16) -> 0.9848264 | P16: =I16-D16 -> 8693 | Q16: =F16/F$16 -> 1
A17: 11 | B17: Wholesale Banking (total) | C17: CASA ratio EOP | D17: =(D9+D10)/D12 -> 0.3706237 | E17: =(E9+E10)/E12 -> 0.29794602 | F17: =(F9+F10)/F12 -> 0.25410398 | G17: =(G9+G10)/G12 -> 0.19076591 | H17: =(H9+H10)/H12 -> 0.23699496 | I17: =(I9+I10)/I12 -> 0.30226068
A18: 12 | B18: Wholesale Banking (total) | C18: CASA ratio AVG | D18: =(D13+D14)/D16 -> 0.21471785 | E18: =(E13+E14)/E16 -> 0.19858498 | F18: =(F13+F14)/F16 -> 0.1821974 | G18: =(G13+G14)/G16 -> 0.18315168 | H18: =(H13+H14)/H16 -> 0.20739465 | I18: =(I13+I14)/I16 -> 0.21192152
A19: 13 | B19: Wholesale Banking (total) | C19: ADV EOP ÷ ADV AVG | D19: =D7/D8 -> 1.2374318 | E19: =E7/E8 -> 1.0994683 | F19: =F7/F8 -> 1.1224521 | G19: =G7/G8 -> 1.0555331 | H19: =H7/H8 -> 1.1115112 | I19: =I7/I8 -> 1.2048829
A20: 14 | B20: Wholesale Banking (total) | C20: Deposits EOP ÷ AVG | D20: =D12/D16 -> 1.3839053 | E20: =E12/E16 -> 1.2693663 | F20: =F12/F16 -> 0.98091458 | G20: =G12/G16 -> 0.96689416 | H20: =H12/H16 -> 1.0342786 | I20: =I12/I16 -> 1.2186816
A21: 15 | B21: Wholesale Banking (total) | C21: Advances ÷ Deposits (EOP) | D21: =D7/D12 -> 0.89376295 | E21: =E7/E12 -> 0.90735734 | F21: =F7/F12 -> 1.173419 | G21: =G7/G12 -> 1.3771861 | H21: =H7/H12 -> 1.1338943 | I21: =I7/I12 -> 1.0459287
A22: 16 | B22: Wholesale Banking (total) | C22: Check: CA+SA+TD − Deposits EOP | D22: =D9+D10+D11-D12 -> 1 | E22: =E9+E10+E11-E12 -> 0 | F22: =F9+F10+F11-F12 -> 0 | G22: =G9+G10+G11-G12 -> 0 | H22: =H9+H10+H11-H12 -> 0 | I22: =I9+I10+I11-I12 -> 0
A24: 18 | B24: Corporate Banking | C24: ADV EOP | D24: 19187 | E24: 16505 | F24: 21087 | G24: 21204 | H24: 21800 | I24: 24158 | J24: =IF(E24=0,"n/a",F24/E24-1) -> 0.27761284 | K24: =IF(D24=0,"n/a",F24/D24-1) -> 0.099025382 | L24: =IF(F24=0,"n/a",G24/F24-1) -> 0.0055484422 | M24: =IF(F24=0,"n/a",H24/F24-1) -> 0.033812301 | N24: =IF(D24=0,"n/a",I24/D24-1) -> 0.25908167 | O24: =IF(H24=0,"n/a",F24/H24) -> 0.96729358 | P24: =I24-D24 -> 4971 | Q24: =F24/F$7 -> 0.41086842
A25: 19 | B25: Corporate Banking | C25: ADV AVG | D25: 16617 | E25: 15344 | F25: 19045 | G25: 20430 | H25: 20581 | I25: 20878 | J25: =IF(E25=0,"n/a",F25/E25-1) -> 0.24120177 | K25: =IF(D25=0,"n/a",F25/D25-1) -> 0.14611542 | L25: =IF(F25=0,"n/a",G25/F25-1) -> 0.072722499 | M25: =IF(F25=0,"n/a",H25/F25-1) -> 0.08065109 | N25: =IF(D25=0,"n/a",I25/D25-1) -> 0.25642414 | O25: =IF(H25=0,"n/a",F25/H25) -> 0.92536806 | P25: =I25-D25 -> 4261 | Q25: =F25/F$8 -> 0.41652086
A26: 20 | B26: Corporate Banking | C26: CA EOP | D26: 2969 | E26: 2293 | F26: 1945 | G26: 1164 | H26: 2400 | I26: 3750 | J26: =IF(E26=0,"n/a",F26/E26-1) -> -0.15176625 | K26: =IF(D26=0,"n/a",F26/D26-1) -> -0.34489727 | L26: =IF(F26=0,"n/a",G26/F26-1) -> -0.40154242 | M26: =IF(F26=0,"n/a",H26/F26-1) -> 0.23393316 | N26: =IF(D26=0,"n/a",I26/D26-1) -> 0.26305153 | O26: =IF(H26=0,"n/a",F26/H26) -> 0.81041667 | P26: =I26-D26 -> 781 | Q26: =F26/F$9 -> 0.20822182
A27: 21 | B27: Corporate Banking | C27: SA EOP | D27: 96 | E27: 34 | F27: 42 | G27: 63 | H27: 250 | I27: 250 | J27: =IF(E27=0,"n/a",F27/E27-1) -> 0.23529412 | K27: =IF(D27=0,"n/a",F27/D27-1) -> -0.5625 | L27: =IF(F27=0,"n/a",G27/F27-1) -> 0.5 | M27: =IF(F27=0,"n/a",H27/F27-1) -> 4.952381 | N27: =IF(D27=0,"n/a",I27/D27-1) -> 1.6041667 | O27: =IF(H27=0,"n/a",F27/H27) -> 0.168 | P27: =I27-D27 -> 154 | Q27: =F27/F$10 -> 0.023688663
A28: 22 | B28: Corporate Banking | C28: TD EOP | D28: 10242 | E28: 8988 | F28: 10045 | G28: 9583 | H28: 10650 | I28: 12646 | J28: =IF(E28=0,"n/a",F28/E28-1) -> 0.11760125 | K28: =IF(D28=0,"n/a",F28/D28-1) -> -0.019234525 | L28: =IF(F28=0,"n/a",G28/F28-1) -> -0.045993031 | M28: =IF(F28=0,"n/a",H28/F28-1) -> 0.06022897 | N28: =IF(D28=0,"n/a",I28/D28-1) -> 0.23471978 | O28: =IF(H28=0,"n/a",F28/H28) -> 0.94319249 | P28: =I28-D28 -> 2404 | Q28: =F28/F$11 -> 0.30790216
A29: 23 | B29: Corporate Banking | C29: Deposits EOP | D29: 13307 | E29: 11314 | F29: 12031 | G29: 10810 | H29: 13300 | I29: 16646 | J29: =IF(E29=0,"n/a",F29/E29-1) -> 0.063372812 | K29: =IF(D29=0,"n/a",F29/D29-1) -> -0.095889382 | L29: =IF(F29=0,"n/a",G29/F29-1) -> -0.10148782 | M29: =IF(F29=0,"n/a",H29/F29-1) -> 0.10547752 | N29: =IF(D29=0,"n/a",I29/D29-1) -> 0.25092057 | O29: =IF(H29=0,"n/a",F29/H29) -> 0.90458647 | P29: =I29-D29 -> 3339 | Q29: =F29/F$12 -> 0.27506973
A30: 24 | B30: Corporate Banking | C30: CA AVG | D30: 1279 | E30: 1098 | F30: 1298 | G30: 1175 | H30: 1562 | I30: 1610 | J30: =IF(E30=0,"n/a",F30/E30-1) -> 0.18214936 | K30: =IF(D30=0,"n/a",F30/D30-1) -> 0.014855356 | L30: =IF(F30=0,"n/a",G30/F30-1) -> -0.094761171 | M30: =IF(F30=0,"n/a",H30/F30-1) -> 0.20338983 | N30: =IF(D30=0,"n/a",I30/D30-1) -> 0.25879593 | O30: =IF(H30=0,"n/a",F30/H30) -> 0.83098592 | P30: =I30-D30 -> 331 | Q30: =F30/F$13 -> 0.19834963
A31: 25 | B31: Corporate Banking | C31: SA AVG | D31: 101 | E31: 46 | F31: 49 | G31: 57 | H31: 150 | I31: 150 | J31: =IF(E31=0,"n/a",F31/E31-1) -> 0.065217391 | K31: =IF(D31=0,"n/a",F31/D31-1) -> -0.51485149 | L31: =IF(F31=0,"n/a",G31/F31-1) -> 0.16326531 | M31: =IF(F31=0,"n/a",H31/F31-1) -> 2.0612245 | N31: =IF(D31=0,"n/a",I31/D31-1) -> 0.48514851 | O31: =IF(H31=0,"n/a",F31/H31) -> 0.32666667 | P31: =I31-D31 -> 49 | Q31: =F31/F$14 -> 0.031012658
A32: 26 | B32: Corporate Banking | C32: TD AVG | D32: 9138 | E32: 8375 | F32: 10633 | G32: 9708 | H32: 10790 | I32: 10944 | J32: =IF(E32=0,"n/a",F32/E32-1) -> 0.26961194 | K32: =IF(D32=0,"n/a",F32/D32-1) -> 0.16360254 | L32: =IF(F32=0,"n/a",G32/F32-1) -> -0.086993323 | M32: =IF(F32=0,"n/a",H32/F32-1) -> 0.014765353 | N32: =IF(D32=0,"n/a",I32/D32-1) -> 0.19763624 | O32: =IF(H32=0,"n/a",F32/H32) -> 0.98544949 | P32: =I32-D32 -> 1806 | Q32: =F32/F$15 -> 0.29159468
A33: 27 | B33: Corporate Banking | C33: Deposits Avg | D33: 10518 | E33: 9519 | F33: 11980 | G33: 10940 | H33: 12502 | I33: 12704 | J33: =IF(E33=0,"n/a",F33/E33-1) -> 0.25853556 | K33: =IF(D33=0,"n/a",F33/D33-1) -> 0.13899981 | L33: =IF(F33=0,"n/a",G33/F33-1) -> -0.086811352 | M33: =IF(F33=0,"n/a",H33/F33-1) -> 0.043572621 | N33: =IF(D33=0,"n/a",I33/D33-1) -> 0.20783419 | O33: =IF(H33=0,"n/a",F33/H33) -> 0.95824668 | P33: =I33-D33 -> 2186 | Q33: =F33/F$16 -> 0.26867613
A34: 28 | B34: Corporate Banking | C34: CASA ratio EOP | D34: =(D26+D27)/D29 -> 0.2303299 | E34: =(E26+E27)/E29 -> 0.20567439 | F34: =(F26+F27)/F29 -> 0.16515668 | G34: =(G26+G27)/G29 -> 0.11350601 | H34: =(H26+H27)/H29 -> 0.19924812 | I34: =(I26+I27)/I29 -> 0.24029797
A35: 29 | B35: Corporate Banking | C35: CASA ratio AVG | D35: =(D30+D31)/D33 -> 0.13120365 | E35: =(E30+E31)/E33 -> 0.12018069 | F35: =(F30+F31)/F33 -> 0.1124374 | G35: =(G30+G31)/G33 -> 0.11261426 | H35: =(H30+H31)/H33 -> 0.13693809 | I35: =(I30+I31)/I33 -> 0.13853904
A36: 30 | B36: Corporate Banking | C36: ADV EOP ÷ ADV AVG | D36: =D24/D25 -> 1.1546609 | E36: =E24/E25 -> 1.0756648 | F36: =F24/F25 -> 1.1072197 | G36: =G24/G25 -> 1.0378855 | H36: =H24/H25 -> 1.0592294 | I36: =I24/I25 -> 1.1571032
A37: 31 | B37: Corporate Banking | C37: Deposits EOP ÷ AVG | D37: =D29/D33 -> 1.2651645 | E37: =E29/E33 -> 1.1885702 | F37: =F29/F33 -> 1.0042571 | G37: =G29/G33 -> 0.988117 | H37: =H29/H33 -> 1.0638298 | I37: =I29/I33 -> 1.310296
A38: 32 | B38: Corporate Banking | C38: Advances ÷ Deposits (EOP) | D38: =D24/D29 -> 1.4418727 | E38: =E24/E29 -> 1.4588121 | F38: =F24/F29 -> 1.7527221 | G38: =G24/G29 -> 1.9615171 | H38: =H24/H29 -> 1.6390977 | I38: =I24/I29 -> 1.4512796
A39: 33 | B39: Corporate Banking | C39: Check: CA+SA+TD − Deposits EOP | D39: =D26+D27+D28-D29 -> 0 | E39: =E26+E27+E28-E29 -> 1 | F39: =F26+F27+F28-F29 -> 1 | G39: =G26+G27+G28-G29 -> 0 | H39: =H26+H27+H28-H29 -> 0 | I39: =I26+I27+I28-I29 -> 0
A41: 35 | B41: MNC | C41: ADV EOP | D41: 322.2 | E41: 352.4 | F41: 145.1 | G41: 189.6 | H41: 405 | I41: 467 | J41: =IF(E41=0,"n/a",F41/E41-1) -> -0.58825199 | K41: =IF(D41=0,"n/a",F41/D41-1) -> -0.5496586 | L41: =IF(F41=0,"n/a",G41/F41-1) -> 0.30668504 | M41: =IF(F41=0,"n/a",H41/F41-1) -> 1.7911785 | N41: =IF(D41=0,"n/a",I41/D41-1) -> 0.4494103 | O41: =IF(H41=0,"n/a",F41/H41) -> 0.3582716 | P41: =I41-D41 -> 144.8 | Q41: =F41/F$7 -> 0.0028271925
A42: 36 | B42: MNC | C42: ADV AVG | D42: 197.2 | E42: 143.5 | F42: 188.3 | G42: 150.4 | H42: 350 | I42: 388 | J42: =IF(E42=0,"n/a",F42/E42-1) -> 0.31219512 | K42: =IF(D42=0,"n/a",F42/D42-1) -> -0.045131846 | L42: =IF(F42=0,"n/a",G42/F42-1) -> -0.20127456 | M42: =IF(F42=0,"n/a",H42/F42-1) -> 0.85873606 | N42: =IF(D42=0,"n/a",I42/D42-1) -> 0.96754564 | O42: =IF(H42=0,"n/a",F42/H42) -> 0.538 | P42: =I42-D42 -> 190.8 | Q42: =F42/F$8 -> 0.0041181874
A43: 37 | B43: MNC | C43: CA EOP | D43: 2969 | E43: 2293 | F43: 1945 | G43: 1164 | H43: 2400 | I43: 3750 | J43: =IF(E43=0,"n/a",F43/E43-1) -> -0.15176625 | K43: =IF(D43=0,"n/a",F43/D43-1) -> -0.34489727 | L43: =IF(F43=0,"n/a",G43/F43-1) -> -0.40154242 | M43: =IF(F43=0,"n/a",H43/F43-1) -> 0.23393316 | N43: =IF(D43=0,"n/a",I43/D43-1) -> 0.26305153 | O43: =IF(H43=0,"n/a",F43/H43) -> 0.81041667 | P43: =I43-D43 -> 781 | Q43: =F43/F$9 -> 0.20822182
...

Sheet B1_Metrics
A1: Wholesale Banking balance sheet: notation and metrics
A2: Format: Notation → Exhaustive metrics table | Example column = live Excel formula on the block sheet (green = cross-sheet)
A3: ⚠ DRAFT ONLY — Requires review and approval by a qualified Alvarez and Marsal professional before use.
A5: Notation
B6: Symbol | C6: Meaning
B7: X(s,c) | C7: Value of line X for segment s in column c, ₹ Cr
B8: c | C8: FY26 A (Mar-26 EOP / FY avg), Q1 FY26 A, Q1 FY27 A (actuals); Jul'26 P (projection); Q2 FY27 B, FY27 B (budgets) — P/B marked ᴾ
B9: ADV EOP / AVG | C9: Advances end-of-period / average
B10: CA, SA, TD, Dep | C10: Current, savings, term and total deposits (EOP and AVG)
B11: W | C11: Wholesale Banking total block
B12: Σs | C12: Sum over the 9 segment blocks (ex-dup = excluding MNC and Commercial Banking deposit duplicates)
B13: CASA | C13: (CA + SA) ÷ Deposits
B14: LDR | C14: ADV EOP ÷ Deposits EOP
B15: g_YoY | C15: Q1 FY27 A ÷ Q1 FY26 A − 1
B16: pace | C16: Q1 FY27 A ÷ Q2 FY27 B ᴾ
B17: g_B | C17: FY27 B ÷ FY26 A − 1 (budgeted growth) ᴾ
B18: Values are ₹ Cr; A = actual, P = projection, B = budget (ᴾ); growth in %, ratios in x.
A20: Exhaustive metrics table
A21: # | B21: Metric family | C21: Pipeline-ready metric | D21: Definition / formula | E21: Applies to | F21: Example
A22: 1 | B22: Fact lookup | C22: Line values | D22: X(s,c) | E22: 10 blocks × 10 lines × 6 columns (600 cells) | F22: ="W ADV EOP "&TEXT(B1_WB_Balance_Sheet!D7,"#,##0;-#,##0;0")&" / "&TEXT(B1_WB_Balance_Sheet!E7,"#,##0;-#,##0;0")&" / "&TEXT(B1_WB_Balance_Sheet!F7,"#,##0;-#,##0;0")&" / "&TEXT(B1_WB_Balance_Sheet!G7,"#,##0;-#,##0;0")&" / "&TEXT(B1_WB_Balance_Sheet!H7,"#,##0;-#,##0;0")&" / "&TEXT(B1_WB_Balance_Sheet!I7,"#,##0;-#,##0;0") -> W ADV EOP 47,432 / 38,256 / 51,323 / 52,289 / 53,098 / 59,961
A23: 2 | B23: Fact lookup | C23: Wholesale deposits | D23: Dep EOP(W,c) | E23: 6 columns | F23: =TEXT(B1_WB_Balance_Sheet!D12,"#,##0;-#,##0;0")&" / "&TEXT(B1_WB_Balance_Sheet!E12,"#,##0;-#,##0;0")&" / "&TEXT(B1_WB_Balance_Sheet!F12,"#,##0;-#,##0;0")&" / "&TEXT(B1_WB_Balance_Sheet!G12,"#,##0;-#,##0;0")&" / "&TEXT(B1_WB_Balance_Sheet!H12,"#,##0;-#,##0;0")&" / "&TEXT(B1_WB_Balance_Sheet!I12,"#,##0;-#,##0;0") -> 53,070 / 42,162 / 43,738 / 37,968 / 46,828 / 57,328
A24: 3 | B24: Roll-up check | C24: Advances | D24: Σs ADV EOP − ADV EOP(W) | E24: 6 columns | F24: =TEXT(B1_WB_Balance_Sheet!D179,"#,##0;-#,##0;0")&" / "&TEXT(B1_WB_Balance_Sheet!E179,"#,##0;-#,##0;0")&" / "&TEXT(B1_WB_Balance_Sheet!F179,"#,##0;-#,##0;0")&" / "&TEXT(B1_WB_Balance_Sheet!G179,"#,##0;-#,##0;0")&" / "&TEXT(B1_WB_Balance_Sheet!H179,"#,##0;-#,##0;0")&" / "&TEXT(B1_WB_Balance_Sheet!I179,"#,##0;-#,##0;0") -> 0 / -19 / 0 / 1 / -442 / 185
A25: 4 | B25: Roll-up check | C25: Deposits as printed | D25: Σs Dep EOP − Dep EOP(W) | E25: 6 columns | F25: =TEXT(B1_WB_Balance_Sheet!D181,"#,##0;-#,##0;0")&" / "&TEXT(B1_WB_Balance_Sheet!E181,"#,##0;-#,##0;0")&" / "&TEXT(B1_WB_Balance_Sheet!F181,"#,##0;-#,##0;0")&" / "&TEXT(B1_WB_Balance_Sheet!G181,"#,##0;-#,##0;0")&" / "&TEXT(B1_WB_Balance_Sheet!H181,"#,##0;-#,##0;0")&" / "&TEXT(B1_WB_Balance_Sheet!I181,"#,##0;-#,##0;0") -> 17,031 / 14,258 / 15,141 / 13,311 / 17,484 / 23,532
A26: 5 | B26: Roll-up check | C26: Deposits ex-duplicates | D26: Σs(ex-dup) Dep EOP − Dep EOP(W) | E26: 6 columns | F26: =TEXT(B1_WB_Balance_Sheet!D182,"#,##0;-#,##0;0")&" / "&TEXT(B1_WB_Balance_Sheet!E182,"#,##0;-#,##0;0")&" / "&TEXT(B1_WB_Balance_Sheet!F182,"#,##0;-#,##0;0")&" / "&TEXT(B1_WB_Balance_Sheet!G182,"#,##0;-#,##0;0")&" / "&TEXT(B1_WB_Balance_Sheet!H182,"#,##0;-#,##0;0")&" / "&TEXT(B1_WB_Balance_Sheet!I182,"#,##0;-#,##0;0") -> -9,583 / -8,370 / -8,921 / -8,309 / -9,116 / -9,760
A27: 6 | B27: Roll-up check | C27: Deposit components | D27: CA + SA + TD − Deposits EOP | E27: 10 blocks × 6 | F27: ="W "&TEXT(B1_WB_Balance_Sheet!D22,"#,##0;-#,##0;0")&" / "&TEXT(B1_WB_Balance_Sheet!E22,"#,##0;-#,##0;0")&" / "&TEXT(B1_WB_Balance_Sheet!F22,"#,##0;-#,##0;0")&" / "&TEXT(B1_WB_Balance_Sheet!G22,"#,##0;-#,##0;0")&" / "&TEXT(B1_WB_Balance_Sheet!H22,"#,##0;-#,##0;0")&" / "&TEXT(B1_WB_Balance_Sheet!I22,"#,##0;-#,##0;0") -> W 1 / 0 / 0 / 0 / 0 / 0
A28: 7 | B28: Growth & momentum | C28: YoY growth (Q1) | D28: g_YoY by line | E28: 10 blocks × 10 lines | F28: ="W ADV EOP "&TEXT(B1_WB_Balance_Sheet!J7,"+0.0%;-0.0%;0.0%")&"; ADV AVG "&TEXT(B1_WB_Balance_Sheet!J8,"+0.0%;-0.0%;0.0%")&"; Dep EOP "&TEXT(B1_WB_Balance_Sheet!J12,"+0.0%;-0.0%;0.0%")&"; Dep AVG "&TEXT(B1_WB_Balance_Sheet!J16,"+0.0%;-0.0%;0.0%") -> W ADV EOP +34.2%; ADV AVG +31.4%; Dep EOP +3.7%; Dep AVG +34.2%
A29: 8 | B29: Growth & momentum | C29: Segment ADV YoY | D29: g_YoY(ADV EOP) | E29: 9 segments | F29: =TEXT(B1_WB_Balance_Sheet!J24,"+0.0%;-0.0%;0.0%")&" / "&TEXT(B1_WB_Balance_Sheet!J41,"+0.0%;-0.0%;0.0%")&" / "&TEXT(B1_WB_Balance_Sheet!J58,"+0.0%;-0.0%;0.0%")&" / "&TEXT(B1_WB_Balance_Sheet!J75,"+0.0%;-0.0%;0.0%")&" / "&TEXT(B1_WB_Balance_Sheet!J92,"+0.0%;-0.0%;0.0%")&" / "&TEXT(B1_WB_Balance_Sheet!J109,"+0.0%;-0.0%;0.0%")&" / "&TEXT(B1_WB_Balance_Sheet!J126,"+0.0%;-0.0%;0.0%")&" / "&TEXT(B1_WB_Balance_Sheet!J143,"+0.0%;-0.0%;0.0%")&" / "&TEXT(B1_WB_Balance_Sheet!J160,"+0.0%;-0.0%;0.0%") -> +27.8% / -58.8% / +36.6% / +21.0% / +41.5% / +33.1% / +58.6% / -98.5% / +99.5%
A30: 9 | B30: Growth & momentum | C30: Q1 FY27 vs Mar-26 | D30: X(Q1 FY27 A) ÷ X(FY26 A) − 1 | E30: EOP lines | F30: ="W ADV "&TEXT(B1_WB_Balance_Sheet!K7,"+0.0%;-0.0%;0.0%")&"; W Dep "&TEXT(B1_WB_Balance_Sheet!K12,"+0.0%;-0.0%;0.0%")&"; W CA "&TEXT(B1_WB_Balance_Sheet!K9,"+0.0%;-0.0%;0.0%")&"; FIG Dep "&TEXT(B1_WB_Balance_Sheet!K97,"+0.0%;-0.0%;0.0%") -> W ADV +8.2%; W Dep -17.6%; W CA -47.8%; FIG Dep -49.2%
A31: 10 | B31: Growth & momentum | C31: July projection vs Q1 ᴾ | D31: X(Jul P) ÷ X(Q1 FY27 A) − 1 | E31: All lines | F31: ="W ADV EOP "&TEXT(B1_WB_Balance_Sheet!L7,"+0.0%;-0.0%;0.0%")&"; W Dep EOP "&TEXT(B1_WB_Balance_Sheet!L12,"+0.0%;-0.0%;0.0%")&"; FIG Dep "&TEXT(B1_WB_Balance_Sheet!L97,"+0.0%;-0.0%;0.0%") -> W ADV EOP +1.9%; W Dep EOP -13.2%; FIG Dep -35.5%
A32: 11 | B32: Budget | C32: Budgeted growth ᴾ | D32: g_B = FY27 B ÷ FY26 A − 1 | E32: All lines | F32: ="W ADV EOP "&TEXT(B1_WB_Balance_Sheet!N7,"+0.0%;-0.0%;0.0%")&"; W Dep EOP "&TEXT(B1_WB_Balance_Sheet!N12,"+0.0%;-0.0%;0.0%")&"; W CA EOP "&TEXT(B1_WB_Balance_Sheet!N9,"+0.0%;-0.0%;0.0%")&"; CB ADV "&TEXT(B1_WB_Balance_Sheet!N24,"+0.0%;-0.0%;0.0%") -> W ADV EOP +26.4%; W Dep EOP +8.0%; W CA EOP -19.3%; CB ADV +25.9%
A33: 12 | B33: Budget | C33: Budgeted increment ᴾ | D33: FY27 B − FY26 A | E33: All lines | F33: ="W ADV EOP "&TEXT(B1_WB_Balance_Sheet!P7,"#,##0;-#,##0;0")&"; W Dep EOP "&TEXT(B1_WB_Balance_Sheet!P12,"#,##0;-#,##0;0") -> W ADV EOP 12,529; W Dep EOP 4,258
A34: 13 | B34: Budget | C34: Segment share of budgeted ADV increment ᴾ | D34: (FY27 B − FY26 A)(s) ÷ same (W) | E34: 9 segments | F34: =TEXT(B1_WB_Balance_Sheet!P24/B1_WB_Balance_Sheet!P7,"0.0%")&" / "&TEXT(B1_WB_Balance_Sheet!P41/B1_WB_Balance_Sheet!P7,"0.0%")&" / "&TEXT(B1_WB_Balance_Sheet!P58/B1_WB_Balance_Sheet!P7,"0.0%")&" / "&TEXT(B1_WB_Balance_Sheet!P75/B1_WB_Balance_Sheet!P7,"0.0%")&" / "&TEXT(B1_WB_Balance_Sheet!P92/B1_WB_Balance_Sheet!P7,"0.0%")&" / "&TEXT(B1_WB_Balance_Sheet!P109/B1_WB_Balance_Sheet!P7,"0.0%")&" / "&TEXT(B1_WB_Balance_Sheet!P126/B1_WB_Balance_Sheet!P7,"0.0%")&" / "&TEXT(B1_WB_Balance_Sheet!P143/B1_WB_Balance_Sheet!P7,"0.0%")&" / "&TEXT(B1_WB_Balance_Sheet!P160/B1_WB_Balance_Sheet!P7,"0.0%") -> 39.7% / 1.2% / 30.4% / 4.2% / 14.4% / 2.0% / 5.3% / 3.7% / 0.7%
A35: 14 | B35: Budget | C35: Q2 pacing ᴾ | D35: pace = Q1 FY27 A ÷ Q2 FY27 B | E35: All lines | F35: ="W ADV EOP "&TEXT(B1_WB_Balance_Sheet!O7,"0.0%")&"; W Dep EOP "&TEXT(B1_WB_Balance_Sheet!O12,"0.0%")&"; W CA EOP "&TEXT(B1_WB_Balance_Sheet!O9,"0.0%") -> W ADV EOP 96.7%; W Dep EOP 93.4%; W CA EOP 97.2%
A36: 15 | B36: Budget | C36: Q2 budget vs Q1 actual ᴾ | D36: Q2 FY27 B ÷ Q1 FY27 A − 1 | E36: All lines | F36: ="W ADV EOP "&TEXT(B1_WB_Balance_Sheet!M7,"+0.0%;-0.0%;0.0%")&"; W Dep EOP "&TEXT(B1_WB_Balance_Sheet!M12,"+0.0%;-0.0%;0.0%")&"; W ADV AVG "&TEXT(B1_WB_Balance_Sheet!M8,"+0.0%;-0.0%;0.0%") -> W ADV EOP +3.5%; W Dep EOP +7.1%; W ADV AVG +4.5%
A37: 16 | B37: Budget | C37: July projection vs Q2 budget ᴾ | D37: X(Jul P) − X(Q2 B) | E37: All lines | F37: ="W ADV AVG "&TEXT(B1_WB_Balance_Sheet!G8-B1_WB_Balance_Sheet!H8,"#,##0;-#,##0;0")&"; W Dep EOP "&TEXT(B1_WB_Balance_Sheet!G12-B1_WB_Balance_Sheet!H12,"#,##0;-#,##0;0") -> W ADV AVG 1,767; W Dep EOP -8,860
A38: 17 | B38: Budget | C38: FY27 B remaining after Q1 ᴾ | D38: FY27 B − Q1 FY27 A (EOP lines) | E38: All EOP lines | F38: ="W ADV EOP "&TEXT(B1_WB_Balance_Sheet!I7-B1_WB_Balance_Sheet!F7,"#,##0;-#,##0;0")&" to add in 3 quarters" -> W ADV EOP 8,638 to add in 3 quarters
A39: 18 | B39: Mix & share | C39: Segment share of Wholesale | D39: X(s) ÷ X(W), Q1 FY27 A | E39: 9 segments × lines | F39: ="ADV EOP "&TEXT(B1_WB_Balance_Sheet!Q24,"0.0%")&" / "&TEXT(B1_WB_Balance_Sheet!Q41,"0.0%")&" / "&TEXT(B1_WB_Balance_Sheet!Q58,"0.0%")&" / "&TEXT(B1_WB_Balance_Sheet!Q75,"0.0%")&" / "&TEXT(B1_WB_Balance_Sheet!Q92,"0.0%")&" / "&TEXT(B1_WB_Balance_Sheet!Q109,"0.0%")&" / "&TEXT(B1_WB_Balance_Sheet!Q126,"0.0%")&" / "&TEXT(B1_WB_Balance_Sheet!Q143,"0.0%")&" / "&TEXT(B1_WB_Balance_Sheet!Q160,"0.0%") -> ADV EOP 41.1% / 0.3% / 27.9% / 3.2% / 16.0% / 1.8% / 7.8% / 0.0% / 1.9%
A40: 19 | B40: Mix & share | C40: CASA ratio EOP | D40: (CA + SA) ÷ Dep EOP | E40: 10 blocks × 6 | F40: ="W "&TEXT(B1_WB_Balance_Sheet!D17,"0.0%")&" / "&TEXT(B1_WB_Balance_Sheet!E17,"0.0%")&" / "&TEXT(B1_WB_Balance_Sheet!F17,"0.0%")&" / "&TEXT(B1_WB_Balance_Sheet!G17,"0.0%")&" / "&TEXT(B1_WB_Balance_Sheet!H17,"0.0%")&" / "&TEXT(B1_WB_Balance_Sheet!I17,"0.0%") -> W 37.1% / 29.8% / 25.4% / 19.1% / 23.7% / 30.2%
A41: 20 | B41: Mix & share | C41: CASA ratio AVG | D41: (CA + SA) ÷ Dep AVG | E41: 10 blocks × 6 | F41: ="W "&TEXT(B1_WB_Balance_Sheet!D18,"0.0%")&" / "&TEXT(B1_WB_Balance_Sheet!E18,"0.0%")&" / "&TEXT(B1_WB_Balance_Sheet!F18,"0.0%")&" / "&TEXT(B1_WB_Balance_Sheet!G18,"0.0%")&" / "&TEXT(B1_WB_Balance_Sheet!H18,"0.0%")&" / "&TEXT(B1_WB_Balance_Sheet!I18,"0.0%") -> W 21.5% / 19.9% / 18.2% / 18.3% / 20.7% / 21.2%
A42: 21 | B42: Mix & share | C42: Segment CASA (EOP, Q1 FY27) | D42: CASA by segment | E42: 9 segments | F42: =TEXT(B1_WB_Balance_Sheet!F34,"0.0%")&" / "&TEXT(B1_WB_Balance_Sheet!F51,"0.0%")&" / "&TEXT(B1_WB_Balance_Sheet!F68,"0.0%")&" / "&TEXT(B1_WB_Balance_Sheet!F85,"0.0%")&" / "&TEXT(B1_WB_Balance_Sheet!F102,"0.0%")&" / "&TEXT(B1_WB_Balance_Sheet!F119,"0.0%")&" / "&TEXT(B1_WB_Balance_Sheet!F136,"0.0%")&" / "&TEXT(B1_WB_Balance_Sheet!F153,"0.0%")&" / "&TEXT(B1_WB_Balance_Sheet!F170,"0.0%") -> 16.5% / 16.5% / 16.5% / 8.7% / 49.1% / 38.5% / 66.5% / 9.0% / 46.7%
...
