Workbook

Sheet README
A1: RBL Bank — Portfolio Monitoring: Product-wise SMA / NPA weekly data — page-wise metric extraction
A2: Source: 07_Product_Wise.pdf (1 page, Product Summary table; data to 29-Aug-2026) | accounts and advances ₹ Cr at 5 dates
A3: ⚠ DRAFT ONLY — Requires review and approval by a qualified Alvarez and Marsal professional before use.
A5: Sheet map
A6: B1_Product_Wise | B6: Leaf rows (product × type × sub-group × norm) with accounts and advances at five dates (re-ordered chronologically), ATS, movements, shares; group roll-ups vs printed totals; comparable total excluding anomalous rows
A7: B1_Metrics | B7: Notation + exhaustive metrics
A9: Colour legend
A10: Blue text | B10: Hard-coded input transcribed from the PDF
A11: Blue italic on grey | B11: Budget / projected value (ᴾ) transcribed from the PDF
A12: Black text | B12: Formula on the same sheet
A13: Green text | B13: Link to another sheet
A14: Yellow fill | B14: Data flag to review
A16: Key assumptions (confirm with client)
A17: 1 | B17: Dates re-ordered chronologically: 29-Jun (CM2), 29-Jul (CM1), 31-Jul (last month last day), 04-Aug (first week), 29-Aug (current).
A18: 2 | B18: Partially filled rows placed by column reconciliation to Grand Total: Credit Card ₹21,373.54 Cr / 612 accounts sits in the 29-Jul column (its total is ~₹21k Cr above the others); Null ₹985.72 Cr in 29-Jul (ties to the Credit Portfolio Overview Jul-26 Null row); Null ₹0.12 Cr assumed in 29-Aug; HL Co-Lending ₹0.11 Cr only on 29-Aug.
A19: 3 | B19: 'Norms' 90 / 365 are the NPA recognition norms (365 for agri-linked); 'Ganaseva' is the micro-banking product (~4M accounts).
A20: 4 | B20: A 'comparable total' is computed excluding Credit Card, Null and Gift City Loans, which make the printed Grand Total jump between dates.
A21: 5 | B21: Cross-page: this page's Grand Total (~₹99k Cr) is below the Net Advances page (~₹117k Cr) mainly because Credit Cards are missing on most dates; Gift City is included here.
A22: Confidentiality | B22: Client-confidential RBL Bank data.
A24: ⚠ DRAFT ONLY — Requires review and approval by a qualified Alvarez and Marsal professional before use.

Sheet B1_Product_Wise
A1: Block 1 — Product-wise accounts and advances at five dates
A2: Source: Product Wise.pdf | Accounts (count) and Advances ₹ Cr | columns re-ordered chronologically
A3: ⚠ DRAFT ONLY — Requires review and approval by a qualified Alvarez and Marsal professional before use.
A5: A. Leaf rows (blue) with live calculations
A6: # | B6: Group | C6: Product type | D6: Sub group / Norm | E6: 29 Jun 2026 (CM2) Accounts | F6: 29 Jun 2026 (CM2) Advances ₹ Cr | G6: 29 Jul 2026 (CM1) Accounts | H6: 29 Jul 2026 (CM1) Advances ₹ Cr | I6: 31 Jul 2026 (LM last day) Accounts | J6: 31 Jul 2026 (LM last day) Advances ₹ Cr | K6: 04 Aug 2026 (first week) Accounts | L6: 04 Aug 2026 (first week) Advances ₹ Cr | M6: 29 Aug 2026 (current) Accounts | N6: 29 Aug 2026 (current) Advances ₹ Cr | O6: ATS 29-Aug (₹ lakh) | P6: Δ Adv 29-Aug vs 29-Jul (₹ Cr) | Q6: MoM % (29-Aug vs 29-Jul) | R6: 2M % (29-Aug vs 29-Jun) | S6: WoW-type % (29-Aug vs 04-Aug) | T6: Month-end effect % (31-Jul vs 29-Jul) | U6: Share of GT 29-Aug | V6: Δ accounts 29-Aug vs 29-Jul | W6: Auto-flag | X6: Excluded from comparable total
A7: 1 | B7: Agri | C7: Agri | D7: New Book / 90 | E7: 3442 | F7: 350.06 | G7: 3348 | H7: 351.97 | I7: 3376 | J7: 357.77 | K7: 3361 | L7: 355.63 | M7: 3333 | N7: 357.89 | O7: =IF(OR(M7="",M7=0),"",N7*100/M7) -> 10.737774 | P7: =IF(OR(N7="",H7=""),"",N7-H7) -> 5.92 | Q7: =IF(OR(N7="",H7="",H7=0),"n/a",N7/H7-1) -> 0.016819615 | R7: =IF(OR(N7="",F7="",F7=0),"n/a",N7/F7-1) -> 0.022367594 | S7: =IF(OR(N7="",L7="",L7=0),"n/a",N7/L7-1) -> 0.0063549194 | T7: =IF(OR(J7="",H7="",H7=0),"n/a",J7/H7-1) -> 0.016478677 | U7: =IF(N7="","",N7/$N$94) -> 0.0032940615 | V7: =IF(OR(M7="",G7=""),"",M7-G7) -> -15 | W7: =IF(COUNT(F7,H7,J7,L7,N7)<5,"Partial-period row",IF(ISNUMBER(Q7),IF(ABS(Q7)>0.1,"MoM move > ±10%",""),""))
A8: 2 | B8: Agri | C8: Agri | D8: New Book / 365 | E8: 19364 | F8: 1111.7 | G8: 19524 | H8: 1109.42 | I8: 19562 | J8: 1113.55 | K8: 19548 | L8: 1112.21 | M8: 19589 | N8: 1114.22 | O8: =IF(OR(M8="",M8=0),"",N8*100/M8) -> 5.6879882 | P8: =IF(OR(N8="",H8=""),"",N8-H8) -> 4.8 | Q8: =IF(OR(N8="",H8="",H8=0),"n/a",N8/H8-1) -> 0.0043265851 | R8: =IF(OR(N8="",F8="",F8=0),"n/a",N8/F8-1) -> 0.0022667986 | S8: =IF(OR(N8="",L8="",L8=0),"n/a",N8/L8-1) -> 0.0018072127 | T8: =IF(OR(J8="",H8="",H8=0),"n/a",J8/H8-1) -> 0.0037226659 | U8: =IF(N8="","",N8/$N$94) -> 0.010255411 | V8: =IF(OR(M8="",G8=""),"",M8-G8) -> 65 | W8: =IF(COUNT(F8,H8,J8,L8,N8)<5,"Partial-period row",IF(ISNUMBER(Q8),IF(ABS(Q8)>0.1,"MoM move > ±10%",""),""))
A9: 3 | B9: Agri | C9: Agri | D9: Old Book / 90 | E9: 559 | F9: 6.54 | G9: 554 | H9: 6.53 | I9: 554 | J9: 6.21 | K9: 553 | L9: 5.17 | M9: 552 | N9: 5.3 | O9: =IF(OR(M9="",M9=0),"",N9*100/M9) -> 0.96014493 | P9: =IF(OR(N9="",H9=""),"",N9-H9) -> -1.23 | Q9: =IF(OR(N9="",H9="",H9=0),"n/a",N9/H9-1) -> -0.18836141 | R9: =IF(OR(N9="",F9="",F9=0),"n/a",N9/F9-1) -> -0.18960245 | S9: =IF(OR(N9="",L9="",L9=0),"n/a",N9/L9-1) -> 0.025145068 | T9: =IF(OR(J9="",H9="",H9=0),"n/a",J9/H9-1) -> -0.049004594 | U9: =IF(N9="","",N9/$N$94) -> 4.8781821e-05 | V9: =IF(OR(M9="",G9=""),"",M9-G9) -> -2 | W9: =IF(COUNT(F9,H9,J9,L9,N9)<5,"Partial-period row",IF(ISNUMBER(Q9),IF(ABS(Q9)>0.1,"MoM move > ±10%",""),"")) -> MoM move > ±10%
A10: 4 | B10: Agri | C10: Agri | D10: Old Book / 365 | E10: 11336 | F10: 241.9 | G10: 11280 | H10: 240.31 | I10: 11284 | J10: 240.32 | K10: 11268 | L10: 240.06 | M10: 11148 | N10: 237.53 | O10: =IF(OR(M10="",M10=0),"",N10*100/M10) -> 2.1306961 | P10: =IF(OR(N10="",H10=""),"",N10-H10) -> -2.78 | Q10: =IF(OR(N10="",H10="",H10=0),"n/a",N10/H10-1) -> -0.011568391 | R10: =IF(OR(N10="",F10="",F10=0),"n/a",N10/F10-1) -> -0.018065316 | S10: =IF(OR(N10="",L10="",L10=0),"n/a",N10/L10-1) -> -0.010539032 | T10: =IF(OR(J10="",H10="",H10=0),"n/a",J10/H10-1) -> 4.1612917e-05 | U10: =IF(N10="","",N10/$N$94) -> 0.002186254 | V10: =IF(OR(M10="",G10=""),"",M10-G10) -> -132 | W10: =IF(COUNT(F10,H10,J10,L10,N10)<5,"Partial-period row",IF(ISNUMBER(Q10),IF(ABS(Q10)>0.1,"MoM move > ±10%",""),""))
A11: 5 | B11: BBG | C11: BBG | D11: New Book / 90 | E11: 1449 | F11: 2750.96 | G11: 1654 | H11: 2865.3 | I11: 1693 | J11: 2953.38 | K11: 1699 | L11: 2940.12 | M11: 1754 | N11: 3016.48 | O11: =IF(OR(M11="",M11=0),"",N11*100/M11) -> 171.97719 | P11: =IF(OR(N11="",H11=""),"",N11-H11) -> 151.18 | Q11: =IF(OR(N11="",H11="",H11=0),"n/a",N11/H11-1) -> 0.052762363 | R11: =IF(OR(N11="",F11="",F11=0),"n/a",N11/F11-1) -> 0.096519033 | S11: =IF(OR(N11="",L11="",L11=0),"n/a",N11/L11-1) -> 0.025971729 | T11: =IF(OR(J11="",H11="",H11=0),"n/a",J11/H11-1) -> 0.030740237 | U11: =IF(N11="","",N11/$N$94) -> 0.027764036 | V11: =IF(OR(M11="",G11=""),"",M11-G11) -> 100 | W11: =IF(COUNT(F11,H11,J11,L11,N11)<5,"Partial-period row",IF(ISNUMBER(Q11),IF(ABS(Q11)>0.1,"MoM move > ±10%",""),""))
A12: 6 | B12: BBG | C12: BBG | D12: Old Book / 90 | E12: 274 | F12: 241.23 | G12: 268 | H12: 238.83 | I12: 265 | J12: 239.91 | K12: 267 | L12: 237.01 | M12: 272 | N12: 244.46 | O12: =IF(OR(M12="",M12=0),"",N12*100/M12) -> 89.875 | P12: =IF(OR(N12="",H12=""),"",N12-H12) -> 5.63 | Q12: =IF(OR(N12="",H12="",H12=0),"n/a",N12/H12-1) -> 0.023573253 | R12: =IF(OR(N12="",F12="",F12=0),"n/a",N12/F12-1) -> 0.013389711 | S12: =IF(OR(N12="",L12="",L12=0),"n/a",N12/L12-1) -> 0.031433273 | T12: =IF(OR(J12="",H12="",H12=0),"n/a",J12/H12-1) -> 0.004522045 | U12: =IF(N12="","",N12/$N$94) -> 0.0022500385 | V12: =IF(OR(M12="",G12=""),"",M12-G12) -> 4 | W12: =IF(COUNT(F12,H12,J12,L12,N12)<5,"Partial-period row",IF(ISNUMBER(Q12),IF(ABS(Q12)>0.1,"MoM move > ±10%",""),""))
A13: 7 | B13: BBG | C13: BBG | D13: Old Book / 365 | E13: 1 | F13: 0 | G13: 1 | H13: 0 | I13: 1 | J13: 0 | K13: 1 | L13: 0 | M13: 1 | N13: 0 | O13: =IF(OR(M13="",M13=0),"",N13*100/M13) -> 0 | P13: =IF(OR(N13="",H13=""),"",N13-H13) -> 0 | Q13: =IF(OR(N13="",H13="",H13=0),"n/a",N13/H13-1) -> n/a | R13: =IF(OR(N13="",F13="",F13=0),"n/a",N13/F13-1) -> n/a | S13: =IF(OR(N13="",L13="",L13=0),"n/a",N13/L13-1) -> n/a | T13: =IF(OR(J13="",H13="",H13=0),"n/a",J13/H13-1) -> n/a | U13: =IF(N13="","",N13/$N$94) -> 0 | V13: =IF(OR(M13="",G13=""),"",M13-G13) -> 0 | W13: =IF(COUNT(F13,H13,J13,L13,N13)<5,"Partial-period row",IF(ISNUMBER(Q13),IF(ABS(Q13)>0.1,"MoM move > ±10%",""),""))
A14: 8 | B14: HL | C14: AHL | D14: AHL / 90 | E14: 9 | F14: 0.02 | G14: 8 | H14: 0.02 | I14: 8 | J14: 0.02 | K14: 8 | L14: 0.02 | M14: 8 | N14: 0.02 | O14: =IF(OR(M14="",M14=0),"",N14*100/M14) -> 0.25 | P14: =IF(OR(N14="",H14=""),"",N14-H14) -> 0 | Q14: =IF(OR(N14="",H14="",H14=0),"n/a",N14/H14-1) -> 0 | R14: =IF(OR(N14="",F14="",F14=0),"n/a",N14/F14-1) -> 0 | S14: =IF(OR(N14="",L14="",L14=0),"n/a",N14/L14-1) -> 0 | T14: =IF(OR(J14="",H14="",H14=0),"n/a",J14/H14-1) -> 0 | U14: =IF(N14="","",N14/$N$94) -> 1.8408234e-07 | V14: =IF(OR(M14="",G14=""),"",M14-G14) -> 0 | W14: =IF(COUNT(F14,H14,J14,L14,N14)<5,"Partial-period row",IF(ISNUMBER(Q14),IF(ABS(Q14)>0.1,"MoM move > ±10%",""),""))
A15: 9 | B15: HL | C15: AHL | D15: AHL (High Yield) / 90 | E15: 16704 | F15: 2506.17 | G15: 17223 | H15: 2571.04 | I15: 17360 | J15: 2603.03 | K15: 17395 | L15: 2607.11 | M15: 17704 | N15: 2633.22 | O15: =IF(OR(M15="",M15=0),"",N15*100/M15) -> 14.873588 | P15: =IF(OR(N15="",H15=""),"",N15-H15) -> 62.18 | Q15: =IF(OR(N15="",H15="",H15=0),"n/a",N15/H15-1) -> 0.024184766 | R15: =IF(OR(N15="",F15="",F15=0),"n/a",N15/F15-1) -> 0.050694885 | S15: =IF(OR(N15="",L15="",L15=0),"n/a",N15/L15-1) -> 0.010014921 | T15: =IF(OR(J15="",H15="",H15=0),"n/a",J15/H15-1) -> 0.012442436 | U15: =IF(N15="","",N15/$N$94) -> 0.024236466 | V15: =IF(OR(M15="",G15=""),"",M15-G15) -> 481 | W15: =IF(COUNT(F15,H15,J15,L15,N15)<5,"Partial-period row",IF(ISNUMBER(Q15),IF(ABS(Q15)>0.1,"MoM move > ±10%",""),""))
A16: 10 | B16: HL | C16: HL CL | D16: HL CL / 90 | E16: 3978 | F16: 1216.48 | G16: 4025 | H16: 1218.53 | I16: 4060 | J16: 1232.04 | K16: 4066 | L16: 1234.15 | M16: 4078 | N16: 1234.75 | O16: =IF(OR(M16="",M16=0),"",N16*100/M16) -> 30.278323 | P16: =IF(OR(N16="",H16=""),"",N16-H16) -> 16.22 | Q16: =IF(OR(N16="",H16="",H16=0),"n/a",N16/H16-1) -> 0.013311121 | R16: =IF(OR(N16="",F16="",F16=0),"n/a",N16/F16-1) -> 0.015018743 | S16: =IF(OR(N16="",L16="",L16=0),"n/a",N16/L16-1) -> 0.00048616457 | T16: =IF(OR(J16="",H16="",H16=0),"n/a",J16/H16-1) -> 0.01108713 | U16: =IF(N16="","",N16/$N$94) -> 0.011364784 | V16: =IF(OR(M16="",G16=""),"",M16-G16) -> 53 | W16: =IF(COUNT(F16,H16,J16,L16,N16)<5,"Partial-period row",IF(ISNUMBER(Q16),IF(ABS(Q16)>0.1,"MoM move > ±10%",""),""))
A17: 11 | B17: HL | C17: HL Co-Lending | D17: HL Co-Lending / 90 | M17: 1 | N17: 0.11 | O17: =IF(OR(M17="",M17=0),"",N17*100/M17) -> 11 | P17: =IF(OR(N17="",H17=""),"",N17-H17) | Q17: =IF(OR(N17="",H17="",H17=0),"n/a",N17/H17-1) -> n/a | R17: =IF(OR(N17="",F17="",F17=0),"n/a",N17/F17-1) -> n/a | S17: =IF(OR(N17="",L17="",L17=0),"n/a",N17/L17-1) -> n/a | T17: =IF(OR(J17="",H17="",H17=0),"n/a",J17/H17-1) -> n/a | U17: =IF(N17="","",N17/$N$94) -> 1.0124529e-06 | V17: =IF(OR(M17="",G17=""),"",M17-G17) | W17: =IF(COUNT(F17,H17,J17,L17,N17)<5,"Partial-period row",IF(ISNUMBER(Q17),IF(ABS(Q17)>0.1,"MoM move > ±10%",""),"")) -> Partial-period row
A18: 12 | B18: HL | C18: HL DA | D18: HL DA / 90 | E18: 6879 | F18: 913.5 | G18: 6815 | H18: 898.3 | I18: 6798 | J18: 954.73 | K18: 6797 | L18: 954.73 | M18: 6920 | N18: 938.53 | O18: =IF(OR(M18="",M18=0),"",N18*100/M18) -> 13.562572 | P18: =IF(OR(N18="",H18=""),"",N18-H18) -> 40.23 | Q18: =IF(OR(N18="",H18="",H18=0),"n/a",N18/H18-1) -> 0.044784593 | R18: =IF(OR(N18="",F18="",F18=0),"n/a",N18/F18-1) -> 0.027400109 | S18: =IF(OR(N18="",L18="",L18=0),"n/a",N18/L18-1) -> -0.016968148 | T18: =IF(OR(J18="",H18="",H18=0),"n/a",J18/H18-1) -> 0.062818657 | U18: =IF(N18="","",N18/$N$94) -> 0.0086383401 | V18: =IF(OR(M18="",G18=""),"",M18-G18) -> 105 | W18: =IF(COUNT(F18,H18,J18,L18,N18)<5,"Partial-period row",IF(ISNUMBER(Q18),IF(ABS(Q18)>0.1,"MoM move > ±10%",""),""))
A19: 13 | B19: HL | C19: Housing Loan | D19: Housing Loan / 90 | E19: 5 | F19: 1.11 | G19: 5 | H19: 1.11 | I19: 5 | J19: 1.11 | K19: 5 | L19: 1.11 | M19: 4 | N19: 1.1 | O19: =IF(OR(M19="",M19=0),"",N19*100/M19) -> 27.5 | P19: =IF(OR(N19="",H19=""),"",N19-H19) -> -0.01 | Q19: =IF(OR(N19="",H19="",H19=0),"n/a",N19/H19-1) -> -0.009009009 | R19: =IF(OR(N19="",F19="",F19=0),"n/a",N19/F19-1) -> -0.009009009 | S19: =IF(OR(N19="",L19="",L19=0),"n/a",N19/L19-1) -> -0.009009009 | T19: =IF(OR(J19="",H19="",H19=0),"n/a",J19/H19-1) -> 0 | U19: =IF(N19="","",N19/$N$94) -> 1.0124529e-05 | V19: =IF(OR(M19="",G19=""),"",M19-G19) -> -1 | W19: =IF(COUNT(F19,H19,J19,L19,N19)<5,"Partial-period row",IF(ISNUMBER(Q19),IF(ABS(Q19)>0.1,"MoM move > ±10%",""),""))
A20: 14 | B20: HL | C20: Housing Loan | D20: AHL (High Yield) / 90 | E20: 25 | F20: 1.4 | G20: 25 | H20: 1.4 | I20: 25 | J20: 1.4 | K20: 25 | L20: 1.4 | M20: 25 | N20: 1.34 | O20: =IF(OR(M20="",M20=0),"",N20*100/M20) -> 5.36 | P20: =IF(OR(N20="",H20=""),"",N20-H20) -> -0.06 | Q20: =IF(OR(N20="",H20="",H20=0),"n/a",N20/H20-1) -> -0.042857143 | R20: =IF(OR(N20="",F20="",F20=0),"n/a",N20/F20-1) -> -0.042857143 | S20: =IF(OR(N20="",L20="",L20=0),"n/a",N20/L20-1) -> -0.042857143 | T20: =IF(OR(J20="",H20="",H20=0),"n/a",J20/H20-1) -> 0 | U20: =IF(N20="","",N20/$N$94) -> 1.2333517e-05 | V20: =IF(OR(M20="",G20=""),"",M20-G20) -> 0 | W20: =IF(COUNT(F20,H20,J20,L20,N20)<5,"Partial-period row",IF(ISNUMBER(Q20),IF(ABS(Q20)>0.1,"MoM move > ±10%",""),""))
A21: 15 | B21: HL | C21: PHL | D21: PHL (Low Yield) / 90 | E21: 7887 | F21: 4303 | G21: 7877 | H21: 4273.33 | I21: 7883 | J21: 4293.31 | K21: 7884 | L21: 4289.46 | M21: 7892 | N21: 4268.24 | O21: =IF(OR(M21="",M21=0),"",N21*100/M21) -> 54.083122 | P21: =IF(OR(N21="",H21=""),"",N21-H21) -> -5.09 | Q21: =IF(OR(N21="",H21="",H21=0),"n/a",N21/H21-1) -> -0.0011911086 | R21: =IF(OR(N21="",F21="",F21=0),"n/a",N21/F21-1) -> -0.0080780851 | S21: =IF(OR(N21="",L21="",L21=0),"n/a",N21/L21-1) -> -0.0049470096 | T21: =IF(OR(J21="",H21="",H21=0),"n/a",J21/H21-1) -> 0.0046755107 | U21: =IF(N21="","",N21/$N$94) -> 0.039285381 | V21: =IF(OR(M21="",G21=""),"",M21-G21) -> 15 | W21: =IF(COUNT(F21,H21,J21,L21,N21)<5,"Partial-period row",IF(ISNUMBER(Q21),IF(ABS(Q21)>0.1,"MoM move > ±10%",""),""))
A22: 16 | B22: LAP | C22: HL - LAP Team | D22: New Book / 90 | E22: 203 | F22: 152.99 | G22: 201 | H22: 151.99 | I22: 202 | J22: 152.46 | K22: 202 | L22: 150.97 | M22: 199 | N22: 154.2 | O22: =IF(OR(M22="",M22=0),"",N22*100/M22) -> 77.487437 | P22: =IF(OR(N22="",H22=""),"",N22-H22) -> 2.21 | Q22: =IF(OR(N22="",H22="",H22=0),"n/a",N22/H22-1) -> 0.01454043 | R22: =IF(OR(N22="",F22="",F22=0),"n/a",N22/F22-1) -> 0.0079090137 | S22: =IF(OR(N22="",L22="",L22=0),"n/a",N22/L22-1) -> 0.021394979 | T22: =IF(OR(J22="",H22="",H22=0),"n/a",J22/H22-1) -> 0.0030923087 | U22: =IF(N22="","",N22/$N$94) -> 0.0014192749 | V22: =IF(OR(M22="",G22=""),"",M22-G22) -> -2 | W22: =IF(COUNT(F22,H22,J22,L22,N22)<5,"Partial-period row",IF(ISNUMBER(Q22),IF(ABS(Q22)>0.1,"MoM move > ±10%",""),""))
A23: 17 | B23: LAP | C23: HL - LAP Team | D23: Old Book / 90 | E23: 112 | F23: 16.13 | G23: 111 | H23: 15.98 | I23: 111 | J23: 15.98 | K23: 111 | L23: 15.96 | M23: 110 | N23: 15.88 | O23: =IF(OR(M23="",M23=0),"",N23*100/M23) -> 14.436364 | P23: =IF(OR(N23="",H23=""),"",N23-H23) -> -0.1 | Q23: =IF(OR(N23="",H23="",H23=0),"n/a",N23/H23-1) -> -0.0062578223 | R23: =IF(OR(N23="",F23="",F23=0),"n/a",N23/F23-1) -> -0.01549907 | S23: =IF(OR(N23="",L23="",L23=0),"n/a",N23/L23-1) -> -0.0050125313 | T23: =IF(OR(J23="",H23="",H23=0),"n/a",J23/H23-1) -> 0 | U23: =IF(N23="","",N23/$N$94) -> 0.00014616138 | V23: =IF(OR(M23="",G23=""),"",M23-G23) -> -1 | W23: =IF(COUNT(F23,H23,J23,L23,N23)<5,"Partial-period row",IF(ISNUMBER(Q23),IF(ABS(Q23)>0.1,"MoM move > ±10%",""),""))
A24: 18 | B24: LAP | C24: HL - LAP Team RSTR | D24: Old Book / 90 | E24: 5 | F24: 2.79 | G24: 5 | H24: 2.78 | I24: 5 | J24: 2.78 | K24: 5 | L24: 2.78 | M24: 5 | N24: 2.77 | O24: =IF(OR(M24="",M24=0),"",N24*100/M24) -> 55.4 | P24: =IF(OR(N24="",H24=""),"",N24-H24) -> -0.01 | Q24: =IF(OR(N24="",H24="",H24=0),"n/a",N24/H24-1) -> -0.0035971223 | R24: =IF(OR(N24="",F24="",F24=0),"n/a",N24/F24-1) -> -0.0071684588 | S24: =IF(OR(N24="",L24="",L24=0),"n/a",N24/L24-1) -> -0.0035971223 | T24: =IF(OR(J24="",H24="",H24=0),"n/a",J24/H24-1) -> 0 | U24: =IF(N24="","",N24/$N$94) -> 2.5495405e-05 | V24: =IF(OR(M24="",G24=""),"",M24-G24) -> 0 | W24: =IF(COUNT(F24,H24,J24,L24,N24)<5,"Partial-period row",IF(ISNUMBER(Q24),IF(ABS(Q24)>0.1,"MoM move > ±10%",""),""))
A25: 19 | B25: LAP | C25: LAP | D25: New Book / 90 | E25: 4922 | F25: 8758.33 | G25: 5015 | H25: 8930.04 | I25: 5109 | J25: 9173.53 | K25: 5106 | L25: 9159.17 | M25: 5154 | N25: 9205.58 | O25: =IF(OR(M25="",M25=0),"",N25*100/M25) -> 178.6104 | P25: =IF(OR(N25="",H25=""),"",N25-H25) -> 275.54 | Q25: =IF(OR(N25="",H25="",H25=0),"n/a",N25/H25-1) -> 0.030855405 | R25: =IF(OR(N25="",F25="",F25=0),"n/a",N25/F25-1) -> 0.051065671 | S25: =IF(OR(N25="",L25="",L25=0),"n/a",N25/L25-1) -> 0.005067053 | T25: =IF(OR(J25="",H25="",H25=0),"n/a",J25/H25-1) -> 0.027266395 | U25: =IF(N25="","",N25/$N$94) -> 0.084729237 | V25: =IF(OR(M25="",G25=""),"",M25-G25) -> 139 | W25: =IF(COUNT(F25,H25,J25,L25,N25)<5,"Partial-period row",IF(ISNUMBER(Q25),IF(ABS(Q25)>0.1,"MoM move > ±10%",""),""))
A26: 20 | B26: LAP | C26: LAP | D26: Old Book / 90 | E26: 1710 | F26: 922.84 | G26: 1683 | H26: 899.27 | I26: 1680 | J26: 895.83 | K26: 1672 | L26: 892 | M26: 1645 | N26: 865.13 | O26: =IF(OR(M26="",M26=0),"",N26*100/M26) -> 52.591489 | P26: =IF(OR(N26="",H26=""),"",N26-H26) -> -34.14 | Q26: =IF(OR(N26="",H26="",H26=0),"n/a",N26/H26-1) -> -0.037964126 | R26: =IF(OR(N26="",F26="",F26=0),"n/a",N26/F26-1) -> -0.062535217 | S26: =IF(OR(N26="",L26="",L26=0),"n/a",N26/L26-1) -> -0.030123318 | T26: =IF(OR(J26="",H26="",H26=0),"n/a",J26/H26-1) -> -0.003825325 | U26: =IF(N26="","",N26/$N$94) -> 0.0079627579 | V26: =IF(OR(M26="",G26=""),"",M26-G26) -> -38 | W26: =IF(COUNT(F26,H26,J26,L26,N26)<5,"Partial-period row",IF(ISNUMBER(Q26),IF(ABS(Q26)>0.1,"MoM move > ±10%",""),""))
A27: 21 | B27: LAP | C27: LAP Co-Lending | D27: New Book / 90 | E27: 1225 | F27: 458.47 | G27: 1213 | H27: 453.84 | I27: 1217 | J27: 454.62 | K27: 1217 | L27: 454.62 | M27: 1207 | N27: 451.35 | O27: =IF(OR(M27="",M27=0),"",N27*100/M27) -> 37.394366 | P27: =IF(OR(N27="",H27=""),"",N27-H27) -> -2.49 | Q27: =IF(OR(N27="",H27="",H27=0),"n/a",N27/H27-1) -> -0.0054865151 | R27: =IF(OR(N27="",F27="",F27=0),"n/a",N27/F27-1) -> -0.015529915 | S27: =IF(OR(N27="",L27="",L27=0),"n/a",N27/L27-1) -> -0.0071928204 | T27: =IF(OR(J27="",H27="",H27=0),"n/a",J27/H27-1) -> 0.0017186674 | U27: =IF(N27="","",N27/$N$94) -> 0.0041542783 | V27: =IF(OR(M27="",G27=""),"",M27-G27) -> -6 | W27: =IF(COUNT(F27,H27,J27,L27,N27)<5,"Partial-period row",IF(ISNUMBER(Q27),IF(ABS(Q27)>0.1,"MoM move > ±10%",""),""))
A28: 22 | B28: LAP | C28: LAP Co-Lending | D28: Old Book / 90 | E28: 52 | F28: 16.83 | G28: 51 | H28: 16.74 | I28: 50 | J28: 15.55 | K28: 50 | L28: 15.55 | M28: 50 | N28: 16.03 | O28: =IF(OR(M28="",M28=0),"",N28*100/M28) -> 32.06 | P28: =IF(OR(N28="",H28=""),"",N28-H28) -> -0.71 | Q28: =IF(OR(N28="",H28="",H28=0),"n/a",N28/H28-1) -> -0.042413381 | R28: =IF(OR(N28="",F28="",F28=0),"n/a",N28/F28-1) -> -0.047534165 | S28: =IF(OR(N28="",L28="",L28=0),"n/a",N28/L28-1) -> 0.030868167 | T28: =IF(OR(J28="",H28="",H28=0),"n/a",J28/H28-1) -> -0.071087216 | U28: =IF(N28="","",N28/$N$94) -> 0.000147542 | V28: =IF(OR(M28="",G28=""),"",M28-G28) -> -1 | W28: =IF(COUNT(F28,H28,J28,L28,N28)<5,"Partial-period row",IF(ISNUMBER(Q28),IF(ABS(Q28)>0.1,"MoM move > ±10%",""),""))
A29: 23 | B29: LAP | C29: LAP Direct Assignment | D29: New Book / 90 | E29: 5142 | F29: 1868.57 | G29: 5101 | H29: 1848.01 | I29: 5070 | J29: 1877.73 | K29: 5070 | L29: 1877.65 | M29: 5084 | N29: 1835.36 | O29: =IF(OR(M29="",M29=0),"",N29*100/M29) -> 36.100708 | P29: =IF(OR(N29="",H29=""),"",N29-H29) -> -12.65 | Q29: =IF(OR(N29="",H29="",H29=0),"n/a",N29/H29-1) -> -0.0068452011 | R29: =IF(OR(N29="",F29="",F29=0),"n/a",N29/F29-1) -> -0.017772949 | S29: =IF(OR(N29="",L29="",L29=0),"n/a",N29/L29-1) -> -0.022522834 | T29: =IF(OR(J29="",H29="",H29=0),"n/a",J29/H29-1) -> 0.016082164 | U29: =IF(N29="","",N29/$N$94) -> 0.016892869 | V29: =IF(OR(M29="",G29=""),"",M29-G29) -> -17 | W29: =IF(COUNT(F29,H29,J29,L29,N29)<5,"Partial-period row",IF(ISNUMBER(Q29),IF(ABS(Q29)>0.1,"MoM move > ±10%",""),""))
... A40: 34 | B40: Two Wheeler Loan | C40: Two Wheeler Loan - TA | D40: Two Wheeler Loan - TA / 90 | E40: 61 | F40: 1.48 | G40: 64 | H40: 1.23 | I40: 65 | J40: 1.16 | K40: 52 | L40: 1.44 | M40: 69 | N40: 1.22 | O40: =IF(OR(M40="",M40=0),"",N40*100/M40) -> 1.7681159 | P40: =IF(OR(N40="",H40=""),"",N40-H40) -> -0.01 | Q40: =IF(OR(N40="",H40="",H40=0),"n/a",N40/H40-1) -> -0.0081300813 | R40: =IF(OR(N40="",F40="",F40=0),"n/a",N40/F40-1) -> -0.17567568 | S40: =IF(OR(N40="",L40="",L40=0),"n/a",N40/L40-1) -> -0.15277778 | T40: =IF(OR(J40="",H40="",H40=0),"n/a",J40/H40-1) -> -0.056910569 | U40: =IF(N40="","",N40/$N$94) -> 1.1229023e-05 | V40: =IF(OR(M40="",G40=""),"",M40-G40) -> 5 | W40: =IF(COUNT(F40,H40,J40,L40,N40)<5,"Partial-period row",IF(ISNUMBER(Q40),IF(ABS(Q40)>0.1,"MoM move > ±10%",""),""))
A41: 35 | B41: OTHERS | C41: Null | D41: Null / 90 | G41: 1 | H41: 985.72 | M41: 1 | N41: 0.12 | O41: =IF(OR(M41="",M41=0),"",N41*100/M41) -> 12 | P41: =IF(OR(N41="",H41=""),"",N41-H41) -> -985.6 | Q41: =IF(OR(N41="",H41="",H41=0),"n/a",N41/H41-1) -> -0.99987826 | R41: =IF(OR(N41="",F41="",F41=0),"n/a",N41/F41-1) -> n/a | S41: =IF(OR(N41="",L41="",L41=0),"n/a",N41/L41-1) -> n/a | T41: =IF(OR(J41="",H41="",H41=0),"n/a",J41/H41-1) -> n/a | U41: =IF(N41="","",N41/$N$94) -> 1.1044941e-06 | V41: =IF(OR(M41="",G41=""),"",M41-G41) -> 0 | W41: =IF(COUNT(F41,H41,J41,L41,N41)<5,"Partial-period row",IF(ISNUMBER(Q41),IF(ABS(Q41)>0.1,"MoM move > ±10%",""),"")) -> Partial-period row | X41: Yes
A42: 36 | B42: OTHERS | C42: Agri | D42: Agri / 90 | E42: 1001 | F42: 45.87 | G42: 1004 | H42: 40.07 | I42: 1072 | J42: 48.9 | K42: 901 | L42: 48.2 | M42: 976 | N42: 44.06 | O42: =IF(OR(M42="",M42=0),"",N42*100/M42) -> 4.5143443 | P42: =IF(OR(N42="",H42=""),"",N42-H42) -> 3.99 | Q42: =IF(OR(N42="",H42="",H42=0),"n/a",N42/H42-1) -> 0.099575742 | R42: =IF(OR(N42="",F42="",F42=0),"n/a",N42/F42-1) -> -0.039459342 | S42: =IF(OR(N42="",L42="",L42=0),"n/a",N42/L42-1) -> -0.085892116 | T42: =IF(OR(J42="",H42="",H42=0),"n/a",J42/H42-1) -> 0.22036436 | U42: =IF(N42="","",N42/$N$94) -> 0.0004055334 | V42: =IF(OR(M42="",G42=""),"",M42-G42) -> -28 | W42: =IF(COUNT(F42,H42,J42,L42,N42)<5,"Partial-period row",IF(ISNUMBER(Q42),IF(ABS(Q42)>0.1,"MoM move > ±10%",""),""))
A43: 37 | B43: OTHERS | C43: Agri | D43: Agri / 365 | E43: 14 | F43: 0.12 | G43: 10 | H43: 0.12 | I43: 10 | J43: 0.12 | K43: 10 | L43: 0.12 | M43: 10 | N43: 0.12 | O43: =IF(OR(M43="",M43=0),"",N43*100/M43) -> 1.2 | P43: =IF(OR(N43="",H43=""),"",N43-H43) -> 0 | Q43: =IF(OR(N43="",H43="",H43=0),"n/a",N43/H43-1) -> 0 | R43: =IF(OR(N43="",F43="",F43=0),"n/a",N43/F43-1) -> 0 | S43: =IF(OR(N43="",L43="",L43=0),"n/a",N43/L43-1) -> 0 | T43: =IF(OR(J43="",H43="",H43=0),"n/a",J43/H43-1) -> 0 | U43: =IF(N43="","",N43/$N$94) -> 1.1044941e-06 | V43: =IF(OR(M43="",G43=""),"",M43-G43) -> 0 | W43: =IF(COUNT(F43,H43,J43,L43,N43)<5,"Partial-period row",IF(ISNUMBER(Q43),IF(ABS(Q43)>0.1,"MoM move > ±10%",""),""))
A44: 38 | B44: OTHERS | C44: Bills | D44: Bills / 90 | E44: 377 | F44: 1786.96 | G44: 377 | H44: 1590.9 | I44: 377 | J44: 1577.49 | K44: 376 | L44: 1619.39 | M44: 367 | N44: 1712.4 | O44: =IF(OR(M44="",M44=0),"",N44*100/M44) -> 466.59401 | P44: =IF(OR(N44="",H44=""),"",N44-H44) -> 121.5 | Q44: =IF(OR(N44="",H44="",H44=0),"n/a",N44/H44-1) -> 0.076371865 | R44: =IF(OR(N44="",F44="",F44=0),"n/a",N44/F44-1) -> -0.041724493 | S44: =IF(OR(N44="",L44="",L44=0),"n/a",N44/L44-1) -> 0.057435207 | T44: =IF(OR(J44="",H44="",H44=0),"n/a",J44/H44-1) -> -0.008429191 | U44: =IF(N44="","",N44/$N$94) -> 0.01576113 | V44: =IF(OR(M44="",G44=""),"",M44-G44) -> -10 | W44: =IF(COUNT(F44,H44,J44,L44,N44)<5,"Partial-period row",IF(ISNUMBER(Q44),IF(ABS(Q44)>0.1,"MoM move > ±10%",""),""))
A45: 39 | B45: OTHERS | C45: Bullion | D45: Bullion / 90 | E45: 71 | F45: 345.33 | G45: 79 | H45: 440.71 | I45: 79 | J45: 439.15 | K45: 80 | L45: 447.1 | M45: 83 | N45: 472.7 | O45: =IF(OR(M45="",M45=0),"",N45*100/M45) -> 569.51807 | P45: =IF(OR(N45="",H45=""),"",N45-H45) -> 31.99 | Q45: =IF(OR(N45="",H45="",H45=0),"n/a",N45/H45-1) -> 0.072587416 | R45: =IF(OR(N45="",F45="",F45=0),"n/a",N45/F45-1) -> 0.36883561 | S45: =IF(OR(N45="",L45="",L45=0),"n/a",N45/L45-1) -> 0.057257884 | T45: =IF(OR(J45="",H45="",H45=0),"n/a",J45/H45-1) -> -0.0035397427 | U45: =IF(N45="","",N45/$N$94) -> 0.0043507862 | V45: =IF(OR(M45="",G45=""),"",M45-G45) -> 4 | W45: =IF(COUNT(F45,H45,J45,L45,N45)<5,"Partial-period row",IF(ISNUMBER(Q45),IF(ABS(Q45)>0.1,"MoM move > ±10%",""),""))
A46: 40 | B46: OTHERS | C46: Business Loans | D46: Business Loans / 90 | E46: 412 | F46: 38.93 | G46: 411 | H46: 37.62 | I46: 411 | J46: 38.01 | K46: 410 | L46: 38 | M46: 409 | N46: 37.4 | O46: =IF(OR(M46="",M46=0),"",N46*100/M46) -> 9.1442543 | P46: =IF(OR(N46="",H46=""),"",N46-H46) -> -0.22 | Q46: =IF(OR(N46="",H46="",H46=0),"n/a",N46/H46-1) -> -0.0058479532 | R46: =IF(OR(N46="",F46="",F46=0),"n/a",N46/F46-1) -> -0.03930131 | S46: =IF(OR(N46="",L46="",L46=0),"n/a",N46/L46-1) -> -0.015789474 | T46: =IF(OR(J46="",H46="",H46=0),"n/a",J46/H46-1) -> 0.010366826 | U46: =IF(N46="","",N46/$N$94) -> 0.00034423398 | V46: =IF(OR(M46="",G46=""),"",M46-G46) -> -2 | W46: =IF(COUNT(F46,H46,J46,L46,N46)<5,"Partial-period row",IF(ISNUMBER(Q46),IF(ABS(Q46)>0.1,"MoM move > ±10%",""),""))
A47: 41 | B47: OTHERS | C47: Business Loans | D47: Business Loans / 365 | E47: 71 | F47: 0 | G47: 71 | H47: 0 | I47: 76 | J47: 0 | K47: 73 | L47: 0 | M47: 72 | N47: 0 | O47: =IF(OR(M47="",M47=0),"",N47*100/M47) -> 0 | P47: =IF(OR(N47="",H47=""),"",N47-H47) -> 0 | Q47: =IF(OR(N47="",H47="",H47=0),"n/a",N47/H47-1) -> n/a | R47: =IF(OR(N47="",F47="",F47=0),"n/a",N47/F47-1) -> n/a | S47: =IF(OR(N47="",L47="",L47=0),"n/a",N47/L47-1) -> n/a | T47: =IF(OR(J47="",H47="",H47=0),"n/a",J47/H47-1) -> n/a | U47: =IF(N47="","",N47/$N$94) -> 0 | V47: =IF(OR(M47="",G47=""),"",M47-G47) -> 1 | W47: =IF(COUNT(F47,H47,J47,L47,N47)<5,"Partial-period row",IF(ISNUMBER(Q47),IF(ABS(Q47)>0.1,"MoM move > ±10%",""),""))
A48: 42 | B48: OTHERS | C48: Cash Credit | D48: Cash Credit / 90 | E48: 778 | F48: 3412.48 | G48: 766 | H48: 3399.69 | I48: 776 | J48: 3397.82 | K48: 777 | L48: 3557.34 | M48: 775 | N48: 3599.74 | O48: =IF(OR(M48="",M48=0),"",N48*100/M48) -> 464.48258 | P48: =IF(OR(N48="",H48=""),"",N48-H48) -> 200.05 | Q48: =IF(OR(N48="",H48="",H48=0),"n/a",N48/H48-1) -> 0.0588436 | R48: =IF(OR(N48="",F48="",F48=0),"n/a",N48/F48-1) -> 0.054875047 | S48: =IF(OR(N48="",L48="",L48=0),"n/a",N48/L48-1) -> 0.011919018 | T48: =IF(OR(J48="",H48="",H48=0),"n/a",J48/H48-1) -> -0.00055005015 | U48: =IF(N48="","",N48/$N$94) -> 0.033132429 | V48: =IF(OR(M48="",G48=""),"",M48-G48) -> 9 | W48: =IF(COUNT(F48,H48,J48,L48,N48)<5,"Partial-period row",IF(ISNUMBER(Q48),IF(ABS(Q48)>0.1,"MoM move > ±10%",""),""))
A49: 43 | B49: OTHERS | C49: Consumer Durable | D49: Consumer Durable / 90 | E49: 36 | F49: 0 | G49: 36 | H49: 0 | I49: 36 | J49: 0 | K49: 36 | L49: 0 | M49: 36 | N49: 0 | O49: =IF(OR(M49="",M49=0),"",N49*100/M49) -> 0 | P49: =IF(OR(N49="",H49=""),"",N49-H49) -> 0 | Q49: =IF(OR(N49="",H49="",H49=0),"n/a",N49/H49-1) -> n/a | R49: =IF(OR(N49="",F49="",F49=0),"n/a",N49/F49-1) -> n/a | S49: =IF(OR(N49="",L49="",L49=0),"n/a",N49/L49-1) -> n/a | T49: =IF(OR(J49="",H49="",H49=0),"n/a",J49/H49-1) -> n/a | U49: =IF(N49="","",N49/$N$94) -> 0 | V49: =IF(OR(M49="",G49=""),"",M49-G49) -> 0 | W49: =IF(COUNT(F49,H49,J49,L49,N49)<5,"Partial-period row",IF(ISNUMBER(Q49),IF(ABS(Q49)>0.1,"MoM move > ±10%",""),""))
A50: 44 | B50: OTHERS | C50: Credit Card | D50: Credit Card / 90 | G50: 612 | H50: 21373.54 | O50: =IF(OR(M50="",M50=0),"",N50*100/M50) | P50: =IF(OR(N50="",H50=""),"",N50-H50) | Q50: =IF(OR(N50="",H50="",H50=0),"n/a",N50/H50-1) -> n/a | R50: =IF(OR(N50="",F50="",F50=0),"n/a",N50/F50-1) -> n/a | S50: =IF(OR(N50="",L50="",L50=0),"n/a",N50/L50-1) -> n/a | T50: =IF(OR(J50="",H50="",H50=0),"n/a",J50/H50-1) -> n/a | U50: =IF(N50="","",N50/$N$94) | V50: =IF(OR(M50="",G50=""),"",M50-G50) | W50: =IF(COUNT(F50,H50,J50,L50,N50)<5,"Partial-period row",IF(ISNUMBER(Q50),IF(ABS(Q50)>0.1,"MoM move > ±10%",""),"")) -> Partial-period row | X50: Yes
A51: 45 | B51: OTHERS | C51: Education Loan | D51: Education Loan / 90 | E51: 82 | F51: 33.24 | G51: 86 | H51: 34.98 | I51: 88 | J51: 35.34 | K51: 88 | L51: 35.99 | M51: 87 | N51: 36.45 | O51: =IF(OR(M51="",M51=0),"",N51*100/M51) -> 41.896552 | P51: =IF(OR(N51="",H51=""),"",N51-H51) -> 1.47 | Q51: =IF(OR(N51="",H51="",H51=0),"n/a",N51/H51-1) -> 0.042024014 | R51: =IF(OR(N51="",F51="",F51=0),"n/a",N51/F51-1) -> 0.096570397 | S51: =IF(OR(N51="",L51="",L51=0),"n/a",N51/L51-1) -> 0.012781328 | T51: =IF(OR(J51="",H51="",H51=0),"n/a",J51/H51-1) -> 0.010291595 | U51: =IF(N51="","",N51/$N$94) -> 0.00033549007 | V51: =IF(OR(M51="",G51=""),"",M51-G51) -> 1 | W51: =IF(COUNT(F51,H51,J51,L51,N51)<5,"Partial-period row",IF(ISNUMBER(Q51),IF(ABS(Q51)>0.1,"MoM move > ±10%",""),""))
...

Sheet B1_Metrics
A1: Product-wise weekly portfolio table: notation and metrics
A2: Format: Notation → Exhaustive metrics table | Example column = live Excel formula on the block sheet (green = cross-sheet)
A3: ⚠ DRAFT ONLY — Requires review and approval by a qualified Alvarez and Marsal professional before use.
A5: Notation
B6: Symbol | C6: Meaning
B7: N(x,d) / A(x,d) | C7: Accounts and advances (₹ Cr) of leaf row x at date d
B8: d | C8: 29-Jun (CM2), 29-Jul (CM1), 31-Jul (LM last day), 04-Aug (first week), 29-Aug (current)
B9: G(d) | C9: Group total = Σ leaf rows in group; GT = Grand Total
B10: GT*(d) | C10: Comparable total = GT excluding Credit Card, Null and Gift City Loans
B11: ATS | C11: A × 100 ÷ N, ₹ lakh
B12: MoM | C12: 29-Aug ÷ 29-Jul − 1
B13: 2M | C13: 29-Aug ÷ 29-Jun − 1
B14: WoW* | C14: 29-Aug ÷ 04-Aug − 1 (3.5 weeks)
B15: ME | C15: Month-end effect = 31-Jul ÷ 29-Jul − 1
B16: sh | C16: A(x, 29-Aug) ÷ GT(29-Aug)
B17: Norm | C17: NPA norm days (90 / 365)
B18: Accounts are counts; advances in ₹ Cr; ATS in ₹ lakh; growth in %; dates re-ordered chronologically.
A20: Exhaustive metrics table
A21: # | B21: Metric family | C21: Pipeline-ready metric | D21: Definition / formula | E21: Applies to | F21: Example
A22: 1 | B22: Fact lookup | C22: Leaf advances | D22: A(x,d) | E22: 67 rows × 5 dates | F22: ="Term Loan "&TEXT(B1_Product_Wise!F69,"#,##0.00;-#,##0.00;0.00")&" / "&TEXT(B1_Product_Wise!H69,"#,##0.00;-#,##0.00;0.00")&" / "&TEXT(B1_Product_Wise!J69,"#,##0.00;-#,##0.00;0.00")&" / "&TEXT(B1_Product_Wise!L69,"#,##0.00;-#,##0.00;0.00")&" / "&TEXT(B1_Product_Wise!N69,"#,##0.00;-#,##0.00;0.00") -> Term Loan 13,711.79 / 13,871.69 / 13,998.95 / 14,014.31 / 14,798.70
A23: 2 | B23: Fact lookup | C23: Leaf accounts | D23: N(x,d) | E23: 67 × 5 | F23: ="Ganaseva "&TEXT(B1_Product_Wise!E53,"#,##0")&" / "&TEXT(B1_Product_Wise!G53,"#,##0")&" / "&TEXT(B1_Product_Wise!I53,"#,##0")&" / "&TEXT(B1_Product_Wise!K53,"#,##0")&" / "&TEXT(B1_Product_Wise!M53,"#,##0") -> Ganaseva 3,977,189 / 3,993,388 / 3,998,208 / 3,993,850 / 4,007,293
A24: 3 | B24: Fact lookup | C24: Printed group totals | D24: G(d) as printed | E24: 7 groups + GT × 5 | F24: ="GT "&TEXT(B1_Product_Wise!F94,"#,##0.00;-#,##0.00;0.00")&" / "&TEXT(B1_Product_Wise!H94,"#,##0.00;-#,##0.00;0.00")&" / "&TEXT(B1_Product_Wise!J94,"#,##0.00;-#,##0.00;0.00")&" / "&TEXT(B1_Product_Wise!L94,"#,##0.00;-#,##0.00;0.00")&" / "&TEXT(B1_Product_Wise!N94,"#,##0.00;-#,##0.00;0.00") -> GT 94,523.88 / 118,641.47 / 99,094.13 / 97,997.96 / 108,647.03
A25: 4 | B25: Roll-up check | C25: Leaf rows to group totals | D25: G(d) printed − Σ leaf | E25: 7 groups × 5 | F25: ="max |gap| "&TEXT(MAX(ABS(MIN(B1_Product_Wise!P87:T93)),MAX(B1_Product_Wise!P87:T93)),"#,##0.00;-#,##0.00;0.00") -> max |gap| 0.02
A26: 5 | B26: Roll-up check | C26: Groups to Grand Total | D26: GT printed − Σ groups | E26: 5 dates | F26: =TEXT(B1_Product_Wise!P94,"#,##0.00;-#,##0.00;0.00")&" / "&TEXT(B1_Product_Wise!Q94,"#,##0.00;-#,##0.00;0.00")&" / "&TEXT(B1_Product_Wise!R94,"#,##0.00;-#,##0.00;0.00")&" / "&TEXT(B1_Product_Wise!S94,"#,##0.00;-#,##0.00;0.00")&" / "&TEXT(B1_Product_Wise!T94,"#,##0.00;-#,##0.00;0.00") -> -0.01 / -0.01 / 0.00 / 0.01 / 0.00
A27: 6 | B27: Volume aggregates | C27: Comparable total | D27: GT*(d) | E27: 5 dates | F27: =TEXT(B1_Product_Wise!F98,"#,##0.00;-#,##0.00;0.00")&" / "&TEXT(B1_Product_Wise!H98,"#,##0.00;-#,##0.00;0.00")&" / "&TEXT(B1_Product_Wise!J98,"#,##0.00;-#,##0.00;0.00")&" / "&TEXT(B1_Product_Wise!L98,"#,##0.00;-#,##0.00;0.00")&" / "&TEXT(B1_Product_Wise!N98,"#,##0.00;-#,##0.00;0.00") -> 86,157.00 / 86,390.40 / 88,915.51 / 87,548.14 / 88,864.04
A28: 7 | B28: Volume aggregates | C28: Excluded rows | D28: GT − GT* | E28: 5 dates | F28: =TEXT(B1_Product_Wise!F99,"#,##0.00;-#,##0.00;0.00")&" / "&TEXT(B1_Product_Wise!H99,"#,##0.00;-#,##0.00;0.00")&" / "&TEXT(B1_Product_Wise!J99,"#,##0.00;-#,##0.00;0.00")&" / "&TEXT(B1_Product_Wise!L99,"#,##0.00;-#,##0.00;0.00")&" / "&TEXT(B1_Product_Wise!N99,"#,##0.00;-#,##0.00;0.00") -> 8,366.89 / 32,251.08 / 10,178.62 / 10,449.81 / 19,782.99
A29: 8 | B29: Volume aggregates | C29: Group advances | D29: G(d) | E29: 7 groups | F29: ="29-Aug: "&TEXT(B1_Product_Wise!N77,"#,##0.00;-#,##0.00;0.00")&" / "&TEXT(B1_Product_Wise!N78,"#,##0.00;-#,##0.00;0.00")&" / "&TEXT(B1_Product_Wise!N79,"#,##0.00;-#,##0.00;0.00")&" / "&TEXT(B1_Product_Wise!N80,"#,##0.00;-#,##0.00;0.00")&" / "&TEXT(B1_Product_Wise!N81,"#,##0.00;-#,##0.00;0.00")&" / "&TEXT(B1_Product_Wise!N82,"#,##0.00;-#,##0.00;0.00")&" / "&TEXT(B1_Product_Wise!N83,"#,##0.00;-#,##0.00;0.00")&" (Agri / BBG / HL / LAP / TW / OTHERS / RVF)" -> 29-Aug: 1,714.94 / 3,260.94 / 9,077.31 / 13,978.71 / 387.08 / 76,841.23 / 3,386.82 (Agri / BBG / HL / LAP / TW / OTHERS / RVF)
A30: 9 | B30: Volume aggregates | C30: Group accounts | D30: Σ N | E30: 7 groups | F30: ="29-Aug: "&TEXT(B1_Product_Wise!M77,"#,##0")&" / "&TEXT(B1_Product_Wise!M78,"#,##0")&" / "&TEXT(B1_Product_Wise!M79,"#,##0")&" / "&TEXT(B1_Product_Wise!M80,"#,##0")&" / "&TEXT(B1_Product_Wise!M81,"#,##0")&" / "&TEXT(B1_Product_Wise!M82,"#,##0")&" / "&TEXT(B1_Product_Wise!M83,"#,##0") -> 29-Aug: 34,622 / 2,027 / 36,632 / 18,719 / 73,557 / 4,151,721 / 109,316
A31: 10 | B31: Growth & momentum | C31: MoM growth (29-Aug vs 29-Jul) | D31: MoM by group | E31: 7 groups + GT + GT* | F31: =TEXT(B1_Product_Wise!Q77,"+0.0%;-0.0%;0.0%")&" / "&TEXT(B1_Product_Wise!Q78,"+0.0%;-0.0%;0.0%")&" / "&TEXT(B1_Product_Wise!Q79,"+0.0%;-0.0%;0.0%")&" / "&TEXT(B1_Product_Wise!Q80,"+0.0%;-0.0%;0.0%")&" / "&TEXT(B1_Product_Wise!Q81,"+0.0%;-0.0%;0.0%")&" / "&TEXT(B1_Product_Wise!Q82,"+0.0%;-0.0%;0.0%")&" / "&TEXT(B1_Product_Wise!Q83,"+0.0%;-0.0%;0.0%")&"; GT "&TEXT(B1_Product_Wise!N94/B1_Product_Wise!H94-1,"+0.0%;-0.0%;0.0%")&"; GT* "&TEXT(B1_Product_Wise!Q98,"+0.0%;-0.0%;0.0%") -> +0.4% / +5.1% / +1.3% / +1.8% / -0.0% / -12.0% / -0.6%; GT -8.4%; GT* +2.9%
A32: 11 | B32: Growth & momentum | C32: Two-month growth (29-Aug vs 29-Jun) | D32: 2M by group | E32: 7 groups + GT* | F32: =TEXT(B1_Product_Wise!R77,"+0.0%;-0.0%;0.0%")&" / "&TEXT(B1_Product_Wise!R78,"+0.0%;-0.0%;0.0%")&" / "&TEXT(B1_Product_Wise!R79,"+0.0%;-0.0%;0.0%")&" / "&TEXT(B1_Product_Wise!R80,"+0.0%;-0.0%;0.0%")&" / "&TEXT(B1_Product_Wise!R81,"+0.0%;-0.0%;0.0%")&" / "&TEXT(B1_Product_Wise!R82,"+0.0%;-0.0%;0.0%")&" / "&TEXT(B1_Product_Wise!R83,"+0.0%;-0.0%;0.0%")&"; GT* "&TEXT(B1_Product_Wise!R98,"+0.0%;-0.0%;0.0%") -> +0.3% / +9.0% / +1.5% / +2.8% / -0.5% / +21.0% / +0.1%; GT* +3.1%
A33: 12 | B33: Growth & momentum | C33: Leaf MoM growth | D33: MoM by leaf row | E33: 67 rows | F33: ="LAP New Book "&TEXT(B1_Product_Wise!Q25,"+0.0%;-0.0%;0.0%")&"; Gift City "&TEXT(B1_Product_Wise!Q54,"+0.0%;-0.0%;0.0%")&"; Bills "&TEXT(B1_Product_Wise!Q44,"+0.0%;-0.0%;0.0%")&"; Overdraft "&TEXT(B1_Product_Wise!Q63,"+0.0%;-0.0%;0.0%") -> LAP New Book +3.1%; Gift City +100.0%; Bills +7.6%; Overdraft +0.8%
A34: 13 | B34: Growth & momentum | C34: Absolute MoM change | D34: A(29-Aug) − A(29-Jul) | E34: 67 rows + groups | F34: ="Gift City "&TEXT(B1_Product_Wise!P54,"#,##0.00;-#,##0.00;0.00")&"; Term Loan "&TEXT(B1_Product_Wise!P69,"#,##0.00;-#,##0.00;0.00")&"; WCL "&TEXT(B1_Product_Wise!P72,"#,##0.00;-#,##0.00;0.00")&"; GT* "&TEXT(B1_Product_Wise!P98,"#,##0.00;-#,##0.00;0.00") -> Gift City 9,891.05; Term Loan 927.01; WCL 433.83; GT* 2,473.64
A35: 14 | B35: Growth & momentum | C35: Comparable growth ex micro banking | D35: (GT* − Ganaseva) MoM / 2M | E35: Window | F35: =TEXT(B1_Product_Wise!Q100,"+0.0%;-0.0%;0.0%")&" / "&TEXT(B1_Product_Wise!R100,"+0.0%;-0.0%;0.0%") -> +3.1% / +3.4%
A36: 15 | B36: Growth & momentum | C36: Rows growing / declining MoM | D36: COUNT Δ > 0 / < 0 | E36: 67 rows | F36: =TEXT(COUNTIF(B1_Product_Wise!P7:P73,">0"),"#,##0")&" up / "&TEXT(COUNTIF(B1_Product_Wise!P7:P73,"<0"),"#,##0")&" down" -> 26 up / 29 down
A37: 16 | B37: Growth & momentum | C37: Account growth MoM | D37: N(29-Aug) − N(29-Jul) | E37: 67 rows + groups | F37: ="Ganaseva "&TEXT(B1_Product_Wise!V53,"#,##0")&"; GoldLoans "&TEXT(B1_Product_Wise!V56,"#,##0")&"; Two Wheeler "&TEXT(B1_Product_Wise!V39,"#,##0") -> Ganaseva 13,905; GoldLoans -4,113; Two Wheeler 1,135
A38: 17 | B38: Intra-month | C38: Month-end effect | D38: ME = 31-Jul ÷ 29-Jul − 1 | E38: 67 rows + GT* | F38: ="GT* "&TEXT(B1_Product_Wise!T98,"+0.0%;-0.0%;0.0%")&"; WCL "&TEXT(B1_Product_Wise!T72,"+0.0%;-0.0%;0.0%")&"; Cash Credit "&TEXT(B1_Product_Wise!T48,"+0.0%;-0.0%;0.0%")&"; Term Loan "&TEXT(B1_Product_Wise!T69,"+0.0%;-0.0%;0.0%") -> GT* +2.9%; WCL +11.2%; Cash Credit -0.1%; Term Loan +0.9%
A39: 18 | B39: Intra-month | C39: First-week to month-end move | D39: 29-Aug ÷ 04-Aug − 1 | E39: 67 rows + GT* | F39: ="GT* "&TEXT(B1_Product_Wise!S98,"+0.0%;-0.0%;0.0%")&"; LAP New "&TEXT(B1_Product_Wise!S25,"+0.0%;-0.0%;0.0%")&"; Gift City "&TEXT(B1_Product_Wise!S54,"+0.0%;-0.0%;0.0%") -> GT* +1.5%; LAP New +0.5%; Gift City +89.3%
A40: 19 | B40: Ticket size | C40: ATS by leaf row (29-Aug) | D40: ATS(x) | E40: 67 rows | F40: ="Term Loan "&TEXT(B1_Product_Wise!O69,"#,##0.00")&"; LAP New "&TEXT(B1_Product_Wise!O25,"#,##0.00")&"; Ganaseva "&TEXT(B1_Product_Wise!O53,"#,##0.00")&"; Gift City "&TEXT(B1_Product_Wise!O54,"#,##0.00")&" ₹ lakh" -> Term Loan 541.09; LAP New 178.61; Ganaseva 0.21; Gift City 3,110.51 ₹ lakh
A41: 20 | B41: Ticket size | C41: ATS by group (29-Aug) | D41: G adv × 100 ÷ G accounts | E41: 7 groups | F41: =TEXT(B1_Product_Wise!N77*100/B1_Product_Wise!M77,"#,##0.00")&" / "&TEXT(B1_Product_Wise!N78*100/B1_Product_Wise!M78,"#,##0.00")&" / "&TEXT(B1_Product_Wise!N79*100/B1_Product_Wise!M79,"#,##0.00")&" / "&TEXT(B1_Product_Wise!N80*100/B1_Product_Wise!M80,"#,##0.00")&" / "&TEXT(B1_Product_Wise!N81*100/B1_Product_Wise!M81,"#,##0.00")&" / "&TEXT(B1_Product_Wise!N82*100/B1_Product_Wise!M82,"#,##0.00")&" / "&TEXT(B1_Product_Wise!N83*100/B1_Product_Wise!M83,"#,##0.00") -> 4.95 / 160.88 / 24.78 / 74.68 / 0.53 / 1.85 / 3.10
A42: 21 | B42: Mix & share | C42: Group share of GT (29-Aug) | D42: sh(G) | E42: 7 groups | F42: =TEXT(B1_Product_Wise!U77,"0.0%")&" / "&TEXT(B1_Product_Wise!U78,"0.0%")&" / "&TEXT(B1_Product_Wise!U79,"0.0%")&" / "&TEXT(B1_Product_Wise!U80,"0.0%")&" / "&TEXT(B1_Product_Wise!U81,"0.0%")&" / "&TEXT(B1_Product_Wise!U82,"0.0%")&" / "&TEXT(B1_Product_Wise!U83,"0.0%") -> 1.6% / 3.0% / 8.4% / 12.9% / 0.4% / 70.7% / 3.1%
...
