Workbook

Sheet README
A1: RBL Bank — MFI SMA and Collection Efficiency (daily bucket resolution report): page-wise metric extraction
A2: Source: 08_SMA_and_Collection_Efficiency.pdf (1 page, 8 tables; MTD to 26-Aug-2026 with 26-Jul-2026 comparatives) | ₹ Cr, accounts, %
A3: ⚠ DRAFT ONLY — Requires review and approval by a qualified Alvarez and Marsal professional before use.
A5: Sheet map
A6: B1_SMA_Pool | B6: Block 1 — SMA pool performance (bucket resolution MTD vs STLM), same-day resolution trend (8 months), BC-wise resolution vs target
A7: B1_Metrics | B7: Notation + metrics for Block 1
A8: B2_Collections_Recovery | B8: Block 2 — Bucket-wise collection efficiency, BC and vintage recovery on NPA / written-off pools, SMA forward-flow position (total and BC-wise)
A9: B2_Metrics | B9: Notation + metrics for Block 2
A11: Colour legend
A12: Blue text | B12: Hard-coded input transcribed from the PDF
A13: Blue italic on grey | B13: Budget / projected value (ᴾ) transcribed from the PDF
A14: Black text | B14: Formula on the same sheet
A15: Green text | B15: Link to another sheet
A16: Yellow fill | B16: Data flag to review
A18: Key assumptions (confirm with client)
A19: 1 | B19: DPD buckets as printed: '1)0 - dpd', '2)1-30', '3)31-60', '4)61-90', '5)91-180' → Current (0), SMA0 (1–30), SMA1 (31–60), SMA2 (61–90), NPA (91–180). The forward-flow table confirms 1–30 = ₹55.96 Cr, 31–60 = ₹29.07 Cr, 61–90 = ₹24.41 Cr.
A20: 2 | B20: Resolution rate (RR) = Stabilized + Roll backward + Normalized = 1 − Flow Forward. Verified against the trend table and the forward-flow table: SMA0 29.34% + 0.00% + 7.99% = 37.33%; SMA1 6.53% + 1.01% + 1.22% = 8.76%; SMA2 2.92% + 0.34% + 0.52% = 3.78%.
A21: 3 | B21: 'Δ' columns in the BC table are printed signed (RR − Target, negative = shortfall) and are recomputed live here; recomputed values match the printed Δ. SMA2 actuals exceed the 3.50% target for NOCPL and PAHAL.
A22: 4 | B22: MTD = month-to-date to 26-Aug-2026; STLM = same-time-last-month (26-Jul-2026). PAHAL 'Total' in the 25-Aug status table is obscured in the source and left blank.
A23: 5 | B23: Collection-efficiency demand for Aug (₹1,400 Cr) is ~2x July (₹697 Cr) at the same day of month — July comparatives likely cover a shorter demand window; compare % not ₹.
A24: Confidentiality | B24: Client-confidential RBL Bank data (MFI / micro-banking book).
A26: ⚠ DRAFT ONLY — Requires review and approval by a qualified Alvarez and Marsal professional before use.

Sheet B1_SMA_Pool
A1: Block 1 — SMA pool performance, resolution trend and BC-wise resolution
A2: Source: SMA and Collection Efficiency.pdf | MTD as on 26-Aug-2026 vs STLM 26-Jul-2026 | ₹ Cr, accounts, %
A3: ⚠ DRAFT ONLY — Requires review and approval by a qualified Alvarez and Marsal professional before use.
A5: A. Bucket resolution — MTD (26-Aug-2026) and STLM (26-Jul-2026); blue = printed
A6: # | B6: Starting DPD bucket | C6: Accounts (MTD) | D6: Balance ₹ Cr (MTD) | E6: Stabilized | F6: Flow forward | G6: Roll backward | H6: Normalized | I6: Σ states | J6: RR = Stab + RB + Norm (= 1 − FF) | K6: ATS ₹ lakh | L6: Accounts (STLM) | M6: Balance ₹ Cr (STLM) | N6: Stabilized | O6: Flow forward | P6: Roll backward | Q6: Normalized | R6: Σ states | S6: RR (STLM) | T6: RR Δ MoM (pp) | U6: FF Δ MoM (pp) | V6: Balance Δ MoM | W6: Share of pool (MTD)
A7: 1 | B7: Current (0 dpd) | C7: 1923659 | D7: 7603.87 | E7: 0.9838 | F7: 0.0162 | G7: 0 | H7: 0 | I7: =SUM(E7:H7) -> 1 | J7: =E7+G7+H7 -> 0.9838 | K7: =D7*100/C7 -> 0.3952816 | L7: 1915951 | M7: 7506.11 | N7: 0.9826 | O7: 0.0174 | P7: 0 | Q7: 0 | R7: =SUM(N7:Q7) -> 1 | S7: =N7+P7+Q7 -> 0.9826 | T7: =(J7-S7)*100 -> 0.12 | U7: =(F7-O7)*100 -> -0.12 | V7: =D7-M7 -> 97.76 | W7: =D7/$D$12 -> 0.97687024
A8: 2 | B8: 1–30 dpd (SMA0) | C8: 19548 | D8: 55.96 | E8: 0.2934 | F8: 0.6267 | G8: 0 | H8: 0.0799 | I8: =SUM(E8:H8) -> 1 | J8: =E8+G8+H8 -> 0.3733 | K8: =D8*100/C8 -> 0.2862697 | L8: 18325 | M8: 50.67 | N8: 0.3254 | O8: 0.5975 | P8: 0 | Q8: 0.0772 | R8: =SUM(N8:Q8) -> 1.0001 | S8: =N8+P8+Q8 -> 0.4026 | T8: =(J8-S8)*100 -> -2.93 | U8: =(F8-O8)*100 -> 2.92 | V8: =D8-M8 -> 5.29 | W8: =D8/$D$12 -> 0.007189189
A9: 3 | B9: 31–60 dpd (SMA1) | C9: 9781 | D9: 29.07 | E9: 0.0653 | F9: 0.9124 | G9: 0.0101 | H9: 0.0122 | I9: =SUM(E9:H9) -> 1 | J9: =E9+G9+H9 -> 0.0876 | K9: =D9*100/C9 -> 0.29720887 | L9: 9565 | M9: 26.35 | N9: 0.073 | O9: 0.9055 | P9: 0.0091 | Q9: 0.0124 | R9: =SUM(N9:Q9) -> 1 | S9: =N9+P9+Q9 -> 0.0945 | T9: =(J9-S9)*100 -> -0.69 | U9: =(F9-O9)*100 -> 0.69 | V9: =D9-M9 -> 2.72 | W9: =D9/$D$12 -> 0.0037346269
A10: 4 | B10: 61–90 dpd (SMA2) | C10: 8676 | D10: 24.41 | E10: 0.0292 | F10: 0.9622 | G10: 0.0034 | H10: 0.0052 | I10: =SUM(E10:H10) -> 1 | J10: =E10+G10+H10 -> 0.0378 | K10: =D10*100/C10 -> 0.28135085 | L10: 10129 | M10: 24.38 | N10: 0.0368 | O10: 0.9516 | P10: 0.0037 | Q10: 0.008 | R10: =SUM(N10:Q10) -> 1.0001 | S10: =N10+P10+Q10 -> 0.0485 | T10: =(J10-S10)*100 -> -1.07 | U10: =(F10-O10)*100 -> 1.06 | V10: =D10-M10 -> 0.03 | W10: =D10/$D$12 -> 0.0031359561
A11: 5 | B11: 91–180 dpd (NPA) | C11: 43131 | D11: 70.61 | E11: 0.7142 | F11: 0.2783 | G11: 0.0002 | H11: 0.0073 | I11: =SUM(E11:H11) -> 1 | J11: =E11+G11+H11 -> 0.7217 | K11: =D11*100/C11 -> 0.16371056 | L11: 45974 | M11: 69.31 | N11: 0.6867 | O11: 0.3045 | P11: 0.0005 | Q11: 0.0084 | R11: =SUM(N11:Q11) -> 1.0001 | S11: =N11+P11+Q11 -> 0.6956 | T11: =(J11-S11)*100 -> 2.61 | U11: =(F11-O11)*100 -> -2.62 | V11: =D11-M11 -> 1.3 | W11: =D11/$D$12 -> 0.0090712765
A12: 6 | B12: Grand Total | C12: 2004795 | D12: 7783.91 | E12: 0.9699 | F12: 0.0293 | G12: 0.0001 | H12: 0.0007 | I12: =SUM(E12:H12) -> 1 | J12: =E12+G12+H12 -> 0.9707 | K12: =D12*100/C12 -> 0.38826464 | L12: 1999944 | M12: 7676.82 | N12: 0.9694 | O12: 0.0299 | P12: 0 | Q12: 0.0007 | R12: =SUM(N12:Q12) -> 1 | S12: =N12+P12+Q12 -> 0.9701 | T12: =(J12-S12)*100 -> 0.06 | U12: =(F12-O12)*100 -> -0.06 | V12: =D12-M12 -> 107.09 | W12: =D12/$D$12 -> 1
B13: Σ buckets (computed) / gap vs Grand Total | C13: =C12-SUM(C7:C11) -> 0 | D13: =D12-SUM(D7:D11) -> -0.01 | L13: =L12-SUM(L7:L11) -> 0 | M13: =M12-SUM(M7:M11) -> 0
B14: Weighted RR from buckets (balance-weighted) vs printed GT RR (pp) | J14: =(J12-SUMPRODUCT(D7:D11,J7:J11)/D12)*100 -> -0.0021095311 | S14: =(S12-SUMPRODUCT(M7:M11,S7:S11)/M12)*100 -> -0.0065767727
B15: Overdue pool (SMA0–NPA) ₹ Cr / share of total pool | D15: =SUM(D8:D11) -> 180.05 | M15: =SUM(M8:M11) -> 170.71 | W15: =D15/D12 -> 0.023131049
B16: SMA pool (1–90 dpd) ₹ Cr / share | D16: =SUM(D8:D10) -> 109.44 | M16: =SUM(M8:M10) -> 101.4 | W16: =D16/D12 -> 0.014059772
B17: Expected flow-forward amount ₹ Cr (balance × FF%) | D17: =SUMPRODUCT(D8:D10,F8:F10) -> 85.080902 | M17: =SUMPRODUCT(M8:M10,O8:O10) -> 77.335258
A19: B. Previous months same-day resolution rate (printed, %)
A20: # | B20: DPD bucket | C20: 26-Aug-26 | D20: 26-Jul-26 | E20: 26-Jun-26 | F20: 26-May-26 | G20: 26-Apr-26 | H20: 26-Mar-26 | I20: 26-Feb-26 | J20: 26-Jan-26 | K20: Δ Aug vs Jul (pp) | L20: Δ Aug vs Jan (pp) | M20: 8M average | N20: 8M min | O20: 8M max | P20: Months below Aug (of 7)
A21: 1 | B21: Current | C21: 0.9838 | D21: 0.9826 | E21: 0.9868 | F21: 0.9872 | G21: 0.9872 | H21: 0.988 | I21: 0.9903 | J21: 0.9821 | K21: =(C21-D21)*100 -> 0.12 | L21: =(C21-J21)*100 -> 0.17 | M21: =AVERAGE(C21:J21) -> 0.986 | N21: =MIN(C21:J21) -> 0.9821 | O21: =MAX(C21:J21) -> 0.9903 | P21: =COUNTIF(D21:J21,"<"&C21) -> 2
A22: 2 | B22: SMA0 | C22: 0.3733 | D22: 0.4025 | E22: 0.421 | F22: 0.4237 | G22: 0.4509 | H22: 0.495 | I22: 0.5061 | J22: 0.4452 | K22: =(C22-D22)*100 -> -2.92 | L22: =(C22-J22)*100 -> -7.19 | M22: =AVERAGE(C22:J22) -> 0.4397125 | N22: =MIN(C22:J22) -> 0.3733 | O22: =MAX(C22:J22) -> 0.5061 | P22: =COUNTIF(D22:J22,"<"&C22) -> 0
A23: 3 | B23: SMA1 | C23: 0.0876 | D23: 0.0945 | E23: 0.1053 | F23: 0.1264 | G23: 0.1433 | H23: 0.1539 | I23: 0.1568 | J23: 0.1518 | K23: =(C23-D23)*100 -> -0.69 | L23: =(C23-J23)*100 -> -6.42 | M23: =AVERAGE(C23:J23) -> 0.12745 | N23: =MIN(C23:J23) -> 0.0876 | O23: =MAX(C23:J23) -> 0.1568 | P23: =COUNTIF(D23:J23,"<"&C23) -> 0
A24: 4 | B24: SMA2 | C24: 0.0378 | D24: 0.0484 | E24: 0.0227 | F24: 0.0747 | G24: 0.0389 | H24: 0.0343 | I24: 0.0616 | J24: 0.0489 | K24: =(C24-D24)*100 -> -1.06 | L24: =(C24-J24)*100 -> -1.11 | M24: =AVERAGE(C24:J24) -> 0.0459125 | N24: =MIN(C24:J24) -> 0.0227 | O24: =MAX(C24:J24) -> 0.0747 | P24: =COUNTIF(D24:J24,"<"&C24) -> 2
B25: Check: Aug trend values vs MTD table RR (pp) | C25: =(C21-J7)*100 -> 0 | D25: =(C22-J8)*100 -> 0 | E25: =(C23-J9)*100 -> 0 | F25: =(C24-J10)*100 -> 0
A27: C. BC-wise resolution rate vs target — MTD (26-Aug) and STLM (26-Jul); Δ recomputed as RR − Target
A28: # | B28: BC | C28: Current RR | D28: Target | E28: Δ (pp) | F28: SMA0 RR | G28: Target | H28: Δ (pp) | I28: SMA1 RR | J28: Target | K28: Δ (pp) | L28: SMA2 RR | M28: Target | N28: Δ (pp) | O28: STLM Current RR | P28: STLM SMA0 RR | Q28: STLM SMA1 RR | R28: STLM SMA2 RR | S28: SMA0 Δ MoM (pp) | T28: SMA1 Δ MoM (pp) | U28: Targets met (of 4)
A29: 1 | B29: RBLFINSERVE | C29: 0.9841 | D29: 0.993 | E29: =(C29-D29)*100 -> -0.89 | F29: 0.3759 | G29: 0.5 | H29: =(F29-G29)*100 -> -12.41 | I29: 0.0833 | J29: 0.2 | K29: =(I29-J29)*100 -> -11.67 | L29: 0.035 | M29: 0.035 | N29: =(L29-M29)*100 -> 0 | O29: 0.9827 | P29: 0.4021 | Q29: 0.0909 | R29: 0.045 | S29: =(F29-P29)*100 -> -2.62 | T29: =(I29-Q29)*100 -> -0.76 | U29: =(C29>=D29)+(F29>=G29)+(I29>=J29)+(L29>=M29) -> 1
A30: 2 | B30: NOCPL | C30: 0.984 | D30: 0.993 | E30: =(C30-D30)*100 -> -0.9 | F30: 0.3785 | G30: 0.5 | H30: =(F30-G30)*100 -> -12.15 | I30: 0.1595 | J30: 0.25 | K30: =(I30-J30)*100 -> -9.05 | L30: 0.1234 | M30: 0.035 | N30: =(L30-M30)*100 -> 8.84 | O30: 0.9881 | P30: 0.3979 | Q30: 0.1482 | R30: 0.1618 | S30: =(F30-P30)*100 -> -1.94 | T30: =(I30-Q30)*100 -> 1.13 | U30: =(C30>=D30)+(F30>=G30)+(I30>=J30)+(L30>=M30) -> 1
A31: 3 | B31: PAHAL | C31: 0.9793 | D31: 0.993 | E31: =(C31-D31)*100 -> -1.37 | F31: 0.3234 | G31: 0.5 | H31: =(F31-G31)*100 -> -17.66 | I31: 0.1348 | J31: 0.25 | K31: =(I31-J31)*100 -> -11.52 | L31: 0.046 | M31: 0.035 | N31: =(L31-M31)*100 -> 1.1 | O31: 0.9778 | P31: 0.4121 | Q31: 0.127 | R31: 0.0576 | S31: =(F31-P31)*100 -> -8.87 | T31: =(I31-Q31)*100 -> 0.78 | U31: =(C31>=D31)+(F31>=G31)+(I31>=J31)+(L31>=M31) -> 1
A34: Data points to flag before metrics (live checks)
A35: # | B35: Flag | C35: Check value (live) | D35: Unit | E35: Implication / action
A36: 1 | B36: SMA0 same-day resolution has fallen in each of the six months since its February peak, from 50.6% to 37.3% (Aug); SMA1 from 15.7% to 8.8%. SMA0 change Feb → Aug (pp): | C36: =(C22-I22)*100 -> -13.28 | D36: pp | E36: Early-bucket cure is deteriorating → more flow into SMA1/SMA2 and NPA; the single most important trend on the page.
A37: 2 | B37: Flow-forward from SMA1 and SMA2 exceeds 91% and 96%: once past 30 dpd almost nothing cures. SMA1 flow-forward: | C37: =F9 -> 0.9124 | D37: % | E37: Collections capacity should be concentrated in 1–30 dpd.
A38: 3 | B38: No BC meets the SMA0 (50%) or SMA1 (20–25%) target; shortfall for RBLFINSERVE on SMA0: | C38: =H29 -> -12.41 | D38: pp | E38: Targets are missed by 12–18 pp across all three BCs.
A39: 4 | B39: Overdue pool (SMA0–NPA) is only 2.3% of the book by balance; the SMA pool (1–90) is ₹109 Cr. | C39: =W15 -> 0.023131049 | D39: % | E39: Stock is small; the issue is the deteriorating cure rate, not the stock.
A40: 5 | B40: Bucket states sum to 100% in every row (max deviation, pp): | C40: =MAX(ABS(I7-1),ABS(I8-1),ABS(I9-1),ABS(I10-1),ABS(I11-1),ABS(I12-1))*100 -> 0 | D40: pp | E40: Table is internally consistent.
A41: 6 | B41: Trend-table Aug values equal MTD-table RR (Stab + RB + Norm) for all four buckets — max gap (pp): | C41: =MAX(ABS(C25),ABS(D25),ABS(E25),ABS(F25)) -> 0 | D41: pp | E41: Confirms RR definition.
A43: Notation and exhaustive metrics table for this block: see sheet B1_Metrics
A45: 10-question test set (3 Low / 4 Medium / 3 High) — expected answers are live formulas
A46: # | B46: Level | C46: Question | D46: Calculation | E46: Expected answer (live) | F46: Unit | G46: So what
A47: 1 | B47: Low | C47: What is the balance in the 1–30 dpd (SMA0) pool at Aug month-start? | D47: Lookup | E47: =D8 -> 55.96 | F47: ₹ Cr
...

Sheet B1_Metrics
A1: SMA pool performance: notation and metrics
A2: Format: Notation → Exhaustive metrics table | Example column = live Excel formula on the block sheet (green = cross-sheet)
A3: ⚠ DRAFT ONLY — Requires review and approval by a qualified Alvarez and Marsal professional before use.
A5: Notation
B6: Symbol | C6: Meaning
B7: B(k) | C7: Opening (prior month-end) balance ₹ Cr of DPD bucket k; N(k) accounts
B8: k | C8: Current (0 dpd), SMA0 (1–30), SMA1 (31–60), SMA2 (61–90), NPA (91–180); GT = Grand Total
B9: Stab / FF / RB / Norm | C9: Share of bucket that stabilised, flowed forward, rolled backward, normalised (MTD, %)
B10: RR(k) | C10: Resolution rate = Stab + RB + Norm = 1 − FF
B11: MTD / STLM | C11: Month-to-date to 26-Aug-2026 / same time last month (26-Jul-2026)
B12: RR(k,t) | C12: Same-day resolution rate on 26th of month t, Jan-26 … Aug-26
B13: RR_bc(k), T_bc(k) | C13: BC-wise resolution rate and target; Δ = RR − T (pp)
B14: ATS | C14: B × 100 ÷ N, ₹ lakh
B15: Pool | C15: SMA pool = Σ B(SMA0..SMA2); overdue pool = Σ B(SMA0..NPA)
B16: Balances ₹ Cr, accounts as counts, rates in %, changes in pp; MTD to 26-Aug-2026.
A18: Exhaustive metrics table
A19: # | B19: Metric family | C19: Pipeline-ready metric | D19: Definition / formula | E19: Applies to | F19: Example
A20: 1 | B20: Fact lookup | C20: Bucket balance and accounts | D20: B(k), N(k) | E20: 6 buckets × 2 periods | F20: ="MTD "&TEXT(B1_SMA_Pool!D7,"#,##0.00;-#,##0.00;0.00")&" / "&TEXT(B1_SMA_Pool!D8,"#,##0.00;-#,##0.00;0.00")&" / "&TEXT(B1_SMA_Pool!D9,"#,##0.00;-#,##0.00;0.00")&" / "&TEXT(B1_SMA_Pool!D10,"#,##0.00;-#,##0.00;0.00")&" / "&TEXT(B1_SMA_Pool!D11,"#,##0.00;-#,##0.00;0.00")&" / "&TEXT(B1_SMA_Pool!D12,"#,##0.00;-#,##0.00;0.00") -> MTD 7,603.87 / 55.96 / 29.07 / 24.41 / 70.61 / 7,783.91
A21: 2 | B21: Fact lookup | C21: Bucket state shares | D21: Stab / FF / RB / Norm | E21: 6 × 4 × 2 | F21: ="SMA0 MTD "&TEXT(B1_SMA_Pool!E8,"0.00%")&" / "&TEXT(B1_SMA_Pool!F8,"0.00%")&" / "&TEXT(B1_SMA_Pool!G8,"0.00%")&" / "&TEXT(B1_SMA_Pool!H8,"0.00%") -> SMA0 MTD 29.34% / 62.67% / 0.00% / 7.99%
A22: 3 | B22: Fact lookup | C22: Same-day RR trend | D22: RR(k,t) | E22: 4 buckets × 8 months | F22: ="SMA0 Jan → Aug "&TEXT(B1_SMA_Pool!J22,"0.00%")&" / "&TEXT(B1_SMA_Pool!I22,"0.00%")&" / "&TEXT(B1_SMA_Pool!H22,"0.00%")&" / "&TEXT(B1_SMA_Pool!G22,"0.00%")&" / "&TEXT(B1_SMA_Pool!F22,"0.00%")&" / "&TEXT(B1_SMA_Pool!E22,"0.00%")&" / "&TEXT(B1_SMA_Pool!D22,"0.00%")&" / "&TEXT(B1_SMA_Pool!C22,"0.00%") -> SMA0 Jan → Aug 44.52% / 50.61% / 49.50% / 45.09% / 42.37% / 42.10% / 40.25% / 37.33%
A23: 4 | B23: Fact lookup | C23: BC resolution vs target | D23: RR_bc(k), T_bc(k) | E23: 3 BCs × 4 buckets × 2 | F23: ="SMA0 MTD "&TEXT(B1_SMA_Pool!F29,"0.00%")&" / "&TEXT(B1_SMA_Pool!F30,"0.00%")&" / "&TEXT(B1_SMA_Pool!F31,"0.00%")&" vs target "&TEXT(B1_SMA_Pool!G29,"0.00%") -> SMA0 MTD 37.59% / 37.85% / 32.34% vs target 50.00%
A24: 5 | B24: Roll-up check | C24: States sum to 100% | D24: Stab + FF + RB + Norm | E24: 12 rows | F24: ="max dev "&TEXT(MAX(ABS(B1_SMA_Pool!I7-1),ABS(B1_SMA_Pool!I8-1),ABS(B1_SMA_Pool!I9-1),ABS(B1_SMA_Pool!I10-1),ABS(B1_SMA_Pool!I11-1),ABS(B1_SMA_Pool!I12-1))*100,"+0.0"" pp"";-0.0"" pp"";0.0"" pp""") -> max dev 0.0 pp
A25: 6 | B25: Roll-up check | C25: Buckets to Grand Total | D25: GT − Σ buckets (accounts / balance) | E25: 2 periods | F25: ="MTD "&TEXT(B1_SMA_Pool!C13,"#,##0")&" / "&TEXT(B1_SMA_Pool!D13,"#,##0.00;-#,##0.00;0.00")&"; STLM "&TEXT(B1_SMA_Pool!L13,"#,##0")&" / "&TEXT(B1_SMA_Pool!M13,"#,##0.00;-#,##0.00;0.00") -> MTD 0 / -0.01; STLM 0 / 0.00
A26: 7 | B26: Roll-up check | C26: GT RR is balance-weighted | D26: RR(GT) − Σ B × RR ÷ Σ B | E26: 2 periods | F26: =TEXT(B1_SMA_Pool!J14,"+0.0"" pp"";-0.0"" pp"";0.0"" pp""")&" / "&TEXT(B1_SMA_Pool!S14,"+0.0"" pp"";-0.0"" pp"";0.0"" pp""") -> -0.0 pp / -0.0 pp
A27: 8 | B27: Roll-up check | C27: Trend vs MTD table | D27: RR(k, Aug) − RR(k) MTD | E27: 4 buckets | F27: =TEXT(B1_SMA_Pool!C25,"+0.0"" pp"";-0.0"" pp"";0.0"" pp""")&" / "&TEXT(B1_SMA_Pool!D25,"+0.0"" pp"";-0.0"" pp"";0.0"" pp""")&" / "&TEXT(B1_SMA_Pool!E25,"+0.0"" pp"";-0.0"" pp"";0.0"" pp""")&" / "&TEXT(B1_SMA_Pool!F25,"+0.0"" pp"";-0.0"" pp"";0.0"" pp""") -> 0.0 pp / 0.0 pp / 0.0 pp / 0.0 pp
A28: 9 | B28: Resolution | C28: Resolution rate by bucket | D28: RR(k) = Stab + RB + Norm | E28: 6 × 2 | F28: ="MTD "&TEXT(B1_SMA_Pool!J7,"0.00%")&" / "&TEXT(B1_SMA_Pool!J8,"0.00%")&" / "&TEXT(B1_SMA_Pool!J9,"0.00%")&" / "&TEXT(B1_SMA_Pool!J10,"0.00%")&" / "&TEXT(B1_SMA_Pool!J11,"0.00%")&" / "&TEXT(B1_SMA_Pool!J12,"0.00%") -> MTD 98.38% / 37.33% / 8.76% / 3.78% / 72.17% / 97.07%
A29: 10 | B29: Resolution | C29: Flow-forward rate | D29: FF(k) | E29: 6 × 2 | F29: ="MTD "&TEXT(B1_SMA_Pool!F7,"0.00%")&" / "&TEXT(B1_SMA_Pool!F8,"0.00%")&" / "&TEXT(B1_SMA_Pool!F9,"0.00%")&" / "&TEXT(B1_SMA_Pool!F10,"0.00%")&" / "&TEXT(B1_SMA_Pool!F11,"0.00%")&" / "&TEXT(B1_SMA_Pool!F12,"0.00%") -> MTD 1.62% / 62.67% / 91.24% / 96.22% / 27.83% / 2.93%
A30: 11 | B30: Resolution | C30: Roll-backward rate | D30: RB(k) | E30: 6 × 2 | F30: ="MTD "&TEXT(B1_SMA_Pool!G8,"0.00%")&" / "&TEXT(B1_SMA_Pool!G9,"0.00%")&" / "&TEXT(B1_SMA_Pool!G10,"0.00%")&" / "&TEXT(B1_SMA_Pool!G11,"0.00%") -> MTD 0.00% / 1.01% / 0.34% / 0.02%
A31: 12 | B31: Resolution | C31: RR change MoM | D31: RR(k) MTD − RR(k) STLM | E31: 6 buckets | F31: =TEXT(B1_SMA_Pool!T7,"+0.0"" pp"";-0.0"" pp"";0.0"" pp""")&" / "&TEXT(B1_SMA_Pool!T8,"+0.0"" pp"";-0.0"" pp"";0.0"" pp""")&" / "&TEXT(B1_SMA_Pool!T9,"+0.0"" pp"";-0.0"" pp"";0.0"" pp""")&" / "&TEXT(B1_SMA_Pool!T10,"+0.0"" pp"";-0.0"" pp"";0.0"" pp""")&" / "&TEXT(B1_SMA_Pool!T11,"+0.0"" pp"";-0.0"" pp"";0.0"" pp""")&" / "&TEXT(B1_SMA_Pool!T12,"+0.0"" pp"";-0.0"" pp"";0.0"" pp""") -> +0.1 pp / -2.9 pp / -0.7 pp / -1.1 pp / +2.6 pp / +0.1 pp
A32: 13 | B32: Resolution | C32: FF change MoM | D32: FF(k) MTD − FF(k) STLM | E32: 6 buckets | F32: =TEXT(B1_SMA_Pool!U7,"+0.0"" pp"";-0.0"" pp"";0.0"" pp""")&" / "&TEXT(B1_SMA_Pool!U8,"+0.0"" pp"";-0.0"" pp"";0.0"" pp""")&" / "&TEXT(B1_SMA_Pool!U9,"+0.0"" pp"";-0.0"" pp"";0.0"" pp""")&" / "&TEXT(B1_SMA_Pool!U10,"+0.0"" pp"";-0.0"" pp"";0.0"" pp""")&" / "&TEXT(B1_SMA_Pool!U11,"+0.0"" pp"";-0.0"" pp"";0.0"" pp""")&" / "&TEXT(B1_SMA_Pool!U12,"+0.0"" pp"";-0.0"" pp"";0.0"" pp""") -> -0.1 pp / +2.9 pp / +0.7 pp / +1.1 pp / -2.6 pp / -0.1 pp
A33: 14 | B33: Resolution | C33: Composition of RR | D33: Stab ÷ RR; RB ÷ RR; Norm ÷ RR | E33: SMA0, SMA1 | F33: ="SMA0 "&TEXT(B1_SMA_Pool!E8/B1_SMA_Pool!J8,"0.0%")&" / "&TEXT(B1_SMA_Pool!G8/B1_SMA_Pool!J8,"0.0%")&" / "&TEXT(B1_SMA_Pool!H8/B1_SMA_Pool!J8,"0.0%")&"; SMA1 "&TEXT(B1_SMA_Pool!E9/B1_SMA_Pool!J9,"0.0%")&" / "&TEXT(B1_SMA_Pool!G9/B1_SMA_Pool!J9,"0.0%")&" / "&TEXT(B1_SMA_Pool!H9/B1_SMA_Pool!J9,"0.0%") -> SMA0 78.6% / 0.0% / 21.4%; SMA1 74.5% / 11.5% / 13.9%
A34: 15 | B34: Resolution | C34: Balance-weighted RR, overdue pool | D34: Σ B × RR ÷ Σ B over SMA0–NPA | E34: 2 periods | F34: ="MTD "&TEXT(SUMPRODUCT(B1_SMA_Pool!D8:D11,B1_SMA_Pool!J8:J11)/B1_SMA_Pool!D15,"0.00%")&"; STLM "&TEXT(SUMPRODUCT(B1_SMA_Pool!M8:M11,B1_SMA_Pool!S8:S11)/B1_SMA_Pool!M15,"0.00%") -> MTD 41.83%; STLM 42.34%
A35: 16 | B35: Resolution | C35: Expected forward-flow amount (SMA pool) | D35: Σ B(k) × FF(k), k ∈ SMA0..SMA2 | E35: 2 periods | F35: ="MTD "&TEXT(B1_SMA_Pool!D17,"#,##0.00;-#,##0.00;0.00")&"; STLM "&TEXT(B1_SMA_Pool!M17,"#,##0.00;-#,##0.00;0.00") -> MTD 85.08; STLM 77.34
A36: 17 | B36: Trend | C36: RR change since Jan-26 | D36: RR(k, Aug) − RR(k, Jan) | E36: 4 buckets | F36: =TEXT(B1_SMA_Pool!L21,"+0.0"" pp"";-0.0"" pp"";0.0"" pp""")&" / "&TEXT(B1_SMA_Pool!L22,"+0.0"" pp"";-0.0"" pp"";0.0"" pp""")&" / "&TEXT(B1_SMA_Pool!L23,"+0.0"" pp"";-0.0"" pp"";0.0"" pp""")&" / "&TEXT(B1_SMA_Pool!L24,"+0.0"" pp"";-0.0"" pp"";0.0"" pp""")&" (Current / SMA0 / SMA1 / SMA2)" -> +0.2 pp / -7.2 pp / -6.4 pp / -1.1 pp (Current / SMA0 / SMA1 / SMA2)
A37: 18 | B37: Trend | C37: RR change MoM (trend table) | D37: RR(k, Aug) − RR(k, Jul) | E37: 4 buckets | F37: =TEXT(B1_SMA_Pool!K21,"+0.0"" pp"";-0.0"" pp"";0.0"" pp""")&" / "&TEXT(B1_SMA_Pool!K22,"+0.0"" pp"";-0.0"" pp"";0.0"" pp""")&" / "&TEXT(B1_SMA_Pool!K23,"+0.0"" pp"";-0.0"" pp"";0.0"" pp""")&" / "&TEXT(B1_SMA_Pool!K24,"+0.0"" pp"";-0.0"" pp"";0.0"" pp""") -> +0.1 pp / -2.9 pp / -0.7 pp / -1.1 pp
A38: 19 | B38: Trend | C38: 8-month average / min / max | D38: AVERAGE, MIN, MAX of RR(k,t) | E38: 4 buckets | F38: ="SMA0 "&TEXT(B1_SMA_Pool!M22,"0.00%")&" / "&TEXT(B1_SMA_Pool!N22,"0.00%")&" / "&TEXT(B1_SMA_Pool!O22,"0.00%") -> SMA0 43.97% / 37.33% / 50.61%
A39: 20 | B39: Trend | C39: Months of consecutive SMA0 decline | D39: COUNT RR(t) < RR(t−1) from Feb peak | E39: SMA0 | F39: =TEXT(SUMPRODUCT(--(B1_SMA_Pool!C22:H22<B1_SMA_Pool!D22:I22)),"#,##0")&" of 6 months since Feb-26 peak" -> 6 of 6 months since Feb-26 peak
A40: 21 | B40: Trend | C40: Position of Aug in 8-month range | D40: Months below Aug (of 7) | E40: 4 buckets | F40: =TEXT(B1_SMA_Pool!P21,"#,##0")&" / "&TEXT(B1_SMA_Pool!P22,"#,##0")&" / "&TEXT(B1_SMA_Pool!P23,"#,##0")&" / "&TEXT(B1_SMA_Pool!P24,"#,##0") -> 2 / 0 / 0 / 2
A41: 22 | B41: Trend | C41: Illustrative extra forward flow from cure deterioration | D41: B(SMA0) × (RR(Jan) − RR(Aug)) | E41: SMA0 | F41: =TEXT(B1_SMA_Pool!D8*(B1_SMA_Pool!J22-B1_SMA_Pool!C22),"#,##0.00;-#,##0.00;0.00")&" ₹ Cr per month" -> 4.02 ₹ Cr per month
A42: 23 | B42: BC performance | C42: Shortfall vs target | D42: Δ = RR_bc − T_bc (pp) | E42: 3 BCs × 4 buckets | F42: ="SMA0 "&TEXT(B1_SMA_Pool!H29,"+0.0"" pp"";-0.0"" pp"";0.0"" pp""")&" / "&TEXT(B1_SMA_Pool!H30,"+0.0"" pp"";-0.0"" pp"";0.0"" pp""")&" / "&TEXT(B1_SMA_Pool!H31,"+0.0"" pp"";-0.0"" pp"";0.0"" pp""")&"; SMA1 "&TEXT(B1_SMA_Pool!K29,"+0.0"" pp"";-0.0"" pp"";0.0"" pp""")&" / "&TEXT(B1_SMA_Pool!K30,"+0.0"" pp"";-0.0"" pp"";0.0"" pp""")&" / "&TEXT(B1_SMA_Pool!K31,"+0.0"" pp"";-0.0"" pp"";0.0"" pp""") -> SMA0 -12.4 pp / -12.2 pp / -17.7 pp; SMA1 -11.7 pp / -9.1 pp / -11.5 pp
...

Sheet B2_Collections_Recovery
A1: Block 2 — Collection efficiency, recovery on NPA / written-off pools, SMA forward flow
A2: Source: SMA and Collection Efficiency.pdf | MTD 26-Aug-2026 vs STLM 26-Jul-2026 | ₹ Cr, %
A3: ⚠ DRAFT ONLY — Requires review and approval by a qualified Alvarez and Marsal professional before use.
A5: A. Bucket-wise collection efficiency — MTD (26-Aug) and STLM (26-Jul)
A6: # | B6: DPD bucket | C6: Demand ₹ Cr (Aug) | D6: Collection ₹ Cr (Aug) | E6: CE % printed | F6: CE % computed | G6: Shortfall ₹ Cr | H6: Share of demand | I6: Share of shortfall | J6: Demand ₹ Cr (Jul) | K6: Collection ₹ Cr (Jul) | L6: CE % printed (Jul) | M6: CE % computed (Jul) | N6: CE Δ MoM (pp) | O6: Demand Aug ÷ Jul
A7: 1 | B7: CURRENT | C7: 1184.23 | D7: 1163.74 | E7: 0.9827 | F7: =D7/C7 -> 0.98269762 | G7: =C7-D7 -> 20.49 | H7: =C7/$C$15 -> 0.84573963 | I7: =G7/$G$15 -> 0.097659787 | J7: 583.51 | K7: 572.18 | L7: 0.9806 | M7: =K7/J7 -> 0.98058302 | N7: =(F7-M7)*100 -> 0.21145944 | O7: =C7/J7 -> 2.0294939
A8: 2 | B8: 1–30 DPD | C8: 10.16 | D8: 4.85 | E8: 0.4776 | F8: =D8/C8 -> 0.4773622 | G8: =C8-D8 -> 5.31 | H8: =C8/$C$15 -> 0.0072559508 | I8: =G8/$G$15 -> 0.025308613 | J8: 4.74 | K8: 2.45 | L8: 0.5166 | M8: =K8/J8 -> 0.51687764 | N8: =(F8-M8)*100 -> -3.9515432 | O8: =C8/J8 -> 2.1434599
A9: 3 | B9: 31–60 DPD | C9: 5 | D9: 0.81 | E9: 0.1618 | F9: =D9/C9 -> 0.162 | G9: =C9-D9 -> 4.19 | H9: =C9/$C$15 -> 0.0035708419 | I9: =G9/$G$15 -> 0.019970449 | J9: 2.4 | K9: 0.42 | L9: 0.1737 | M9: =K9/J9 -> 0.175 | N9: =(F9-M9)*100 -> -1.3 | O9: =C9/J9 -> 2.0833333
A10: 4 | B10: 61–90 DPD | C10: 4.18 | D10: 0.48 | E10: 0.1145 | F10: =D10/C10 -> 0.11483254 | G10: =C10-D10 -> 3.7 | H10: =C10/$C$15 -> 0.0029852239 | I10: =G10/$G$15 -> 0.017635003 | J10: 2.21 | K10: 0.32 | L10: 0.1467 | M10: =K10/J10 -> 0.14479638 | N10: =(F10-M10)*100 -> -2.9963844 | O10: =C10/J10 -> 1.8914027
A11: 5 | B11: Total (≤ 90) | C11: 1203.56 | D11: 1169.88 | E11: 0.972 | F11: =D11/C11 -> 0.97201635 | G11: =C11-D11 -> 33.68 | H11: =C11/$C$15 -> 0.8595445 | I11: =G11/$G$15 -> 0.16052619 | J11: 592.86 | K11: 575.37 | L11: 0.9705 | M11: =K11/J11 -> 0.97049894 | N11: =(F11-M11)*100 -> 0.15174141 | O11: =C11/J11 -> 2.0300914
A12: 6 | B12: 91–180 DPD | C12: 10.86 | D12: 2.37 | E12: 0.2185 | F12: =D12/C12 -> 0.21823204 | G12: =C12-D12 -> 8.49 | H12: =C12/$C$15 -> 0.0077558687 | I12: =G12/$G$15 -> 0.040465183 | J12: 5.57 | K12: 1.51 | L12: 0.2702 | M12: =K12/J12 -> 0.27109515 | N12: =(F12-M12)*100 -> -5.2863108 | O12: =C12/J12 -> 1.9497307
A13: 7 | B13: > 180 DPD | C13: 185.81 | D13: 18.17 | E13: 0.0978 | F13: =D13/C13 -> 0.097788063 | G13: =C13-D13 -> 167.64 | H13: =C13/$C$15 -> 0.13269963 | I13: =G13/$G$15 -> 0.79900863 | J13: 98.13 | K13: 9.27 | L13: 0.0945 | M13: =K13/J13 -> 0.094466524 | N13: =(F13-M13)*100 -> 0.33215391 | O13: =C13/J13 -> 1.8935086
A14: 8 | B14: Total (> 90) | C14: 196.67 | D14: 20.54 | E14: 0.1044 | F14: =D14/C14 -> 0.10443891 | G14: =C14-D14 -> 176.13 | H14: =C14/$C$15 -> 0.1404555 | I14: =G14/$G$15 -> 0.83947381 | J14: 103.7 | K14: 10.78 | L14: 0.1039 | M14: =K14/J14 -> 0.10395371 | N14: =(F14-M14)*100 -> 0.048519518 | O14: =C14/J14 -> 1.8965284
A15: 9 | B15: Grand Total | C15: 1400.23 | D15: 1190.42 | E15: 0.8502 | F15: =D15/C15 -> 0.85016033 | G15: =C15-D15 -> 209.81 | H15: =C15/$C$15 -> 1 | I15: =G15/$G$15 -> 1 | J15: 696.57 | K15: 586.15 | L15: 0.8415 | M15: =K15/J15 -> 0.8414804 | N15: =(F15-M15)*100 -> 0.8679934 | O15: =C15/J15 -> 2.0101784
B16: Check: Σ (≤90 buckets) − Total (≤90); Σ (>90) − Total (>90); Totals − Grand Total | C16: =SUM(C7:C10)-C11 -> 0.01 | D16: =SUM(C12:C13)-C14 -> 0 | E16: =C11+C14-C15 -> 0
B17: CE on overdue buckets only (1–90): collection ÷ demand | F17: =SUM(D8:D10)/SUM(C8:C10) -> 0.31747673 | M17: =SUM(K8:K10)/SUM(J8:J10) -> 0.34117647
A19: B. BC-wise recovery on NPA and written-off (WOFF) pools — MTD (26-Aug) and STLM (26-Jul)
A20: # | B20: BC | C20: NPA POS | D20: NPA recovery | E20: NPA rate printed | F20: NPA rate computed | G20: WOFF POS | H20: WOFF recovery | I20: WOFF rate printed | J20: WOFF rate computed | K20: Total POS | L20: Total recovery | M20: Total rate computed | N20: Share of total POS | O20: Share of total recovery | P20: STLM NPA POS | Q20: STLM NPA recovery | R20: STLM WOFF POS | S20: STLM WOFF recovery | T20: Total rate STLM | U20: Rate Δ MoM (pp) | V20: POS Δ MoM
A21: 1 | B21: RFL | C21: 520.73 | D21: 4.25 | E21: 0.0082 | F21: =IF(C21=0,"",D21/C21) -> 0.0081616193 | G21: 2513.29 | H21: 3.81 | I21: 0.0015 | J21: =H21/G21 -> 0.0015159413 | K21: =C21+G21 -> 3034.02 | L21: =D21+H21 -> 8.06 | M21: =L21/K21 -> 0.0026565415 | N21: =K21/$K$25 -> 0.86273161 | O21: =L21/$L$25 -> 0.92114286 | P21: 503.92 | Q21: 4.56 | R21: 2517.42 | S21: 3.72 | T21: =(Q21+S21)/(P21+R21) -> 0.0027405059 | U21: =(M21-T21)*100 -> -0.0083964382 | V21: =K21-(P21+R21) -> 12.68
A22: 2 | B22: NOCPL | C22: 27.82 | D22: 0.13 | E22: 0.0048 | F22: =IF(C22=0,"",D22/C22) -> 0.0046728972 | G22: 144.64 | H22: 0.19 | I22: 0.0013 | J22: =H22/G22 -> 0.0013136062 | K22: =C22+G22 -> 172.46 | L22: =D22+H22 -> 0.32 | M22: =L22/K22 -> 0.0018555027 | N22: =K22/$K$25 -> 0.049039457 | O22: =L22/$L$25 -> 0.036571429 | P22: 27.53 | Q22: 0.21 | R22: 144.88 | S22: 0.28 | T22: =(Q22+S22)/(P22+R22) -> 0.0028420625 | U22: =(M22-T22)*100 -> -0.09865598 | V22: =K22-(P22+R22) -> 0.05
A23: 3 | B23: PAHAL | C23: 28.58 | D23: 0.11 | E23: 0.004 | F23: =IF(C23=0,"",D23/C23) -> 0.0038488453 | G23: 255.83 | H23: 0.23 | I23: 0.0009 | J23: =H23/G23 -> 0.00089903452 | K23: =C23+G23 -> 284.41 | L23: =D23+H23 -> 0.34 | M23: =L23/K23 -> 0.0011954573 | N23: =K23/$K$25 -> 0.080872735 | O23: =L23/$L$25 -> 0.038857143 | P23: 27.58 | Q23: 0.13 | R23: 256.07 | S23: 0.25 | T23: =(Q23+S23)/(P23+R23) -> 0.0013396792 | U23: =(M23-T23)*100 -> -0.014422192 | V23: =K23-(P23+R23) -> 0.76
A24: 4 | B24: STSPL | C24: 0 | D24: 0 | E24: 0 | F24: =IF(C24=0,"",D24/C24) | G24: 25.85 | H24: 0.02 | I24: 0.0007 | J24: =H24/G24 -> 0.00077369439 | K24: =C24+G24 -> 25.85 | L24: =D24+H24 -> 0.02 | M24: =L24/K24 -> 0.00077369439 | N24: =K24/$K$25 -> 0.0073505158 | O24: =L24/$L$25 -> 0.0022857143 | P24: 0 | Q24: 0 | R24: 25.88 | S24: 0.01 | T24: =(Q24+S24)/(P24+R24) -> 0.00038639876 | U24: =(M24-T24)*100 -> 0.038729563 | V24: =K24-(P24+R24) -> -0.03
A25: 5 | B25: Grand Total | C25: 577.14 | D25: 4.5 | E25: 0.0078 | F25: =IF(C25=0,"",D25/C25) -> 0.0077970683 | G25: 2939.62 | H25: 4.25 | I25: 0.0014 | J25: =H25/G25 -> 0.0014457651 | K25: =C25+G25 -> 3516.76 | L25: =D25+H25 -> 8.75 | M25: =L25/K25 -> 0.0024880856 | N25: =K25/$K$25 -> 1 | O25: =L25/$L$25 -> 1 | P25: 559.03 | Q25: 4.9 | R25: 2944.25 | S25: 4.26 | T25: =(Q25+S25)/(P25+R25) -> 0.0026146925 | U25: =(M25-T25)*100 -> -0.012660689 | V25: =K25-(P25+R25) -> 13.48
B26: Check: Σ BCs − Grand Total (NPA POS / WOFF POS / total recovery) | C26: =SUM(C21:C24)-C25 -> -0.01 | G26: =SUM(G21:G24)-G25 -> -0.01 | L26: =SUM(L21:L24)-L25 -> -0.01
A28: C. Vintage-wise recovery — MTD (26-Aug) and STLM (26-Jul)
A29: # | B29: Status / DPD / Vintage | C29: POS (Aug) | D29: Recovery (Aug) | E29: Rate printed | F29: Rate computed | G29: Share of POS | H29: Share of recovery | I29: POS (Jul) | J29: Recovery (Jul) | K29: Rate (Jul) computed | L29: Rate Δ MoM (pp) | M29: POS Δ MoM | N29: Annualised rate ×12 (Aug)
A30: 1 | B30: NPA 91–180 / V0 | C30: 58.6 | D30: 0.56 | E30: 0.0096 | F30: =D30/C30 -> 0.009556314 | G30: =C30/$C$37 -> 0.016663065 | H30: =D30/$D$37 -> 0.064 | I30: 54.51 | J30: 0.61 | K30: =J30/I30 -> 0.011190607 | L30: =(F30-K30)*100 -> -0.16342932 | M30: =C30-I30 -> 4.09 | N30: =F30*12 -> 0.11467577
A31: 2 | B31: NPA 181–365 / V1 | C31: 518.54 | D31: 3.94 | E31: 0.0076 | F31: =D31/C31 -> 0.0075982566 | G31: =C31/$C$37 -> 0.14744822 | H31: =D31/$D$37 -> 0.45028571 | I31: 504.53 | J31: 4.29 | K31: =J31/I31 -> 0.0085029632 | L31: =(F31-K31)*100 -> -0.090470651 | M31: =C31-I31 -> 14.01 | N31: =F31*12 -> 0.09117908
A32: 3 | B32: WOFF < 456 / V2 | C32: 99.35 | D32: 0.29 | E32: 0.003 | F32: =D32/C32 -> 0.0029189733 | G32: =C32/$C$37 -> 0.028250435 | H32: =D32/$D$37 -> 0.033142857 | I32: 173.78 | J32: 0.49 | K32: =J32/I32 -> 0.002819657 | L32: =(F32-K32)*100 -> 0.0099316289 | M32: =C32-I32 -> -74.43 | N32: =F32*12 -> 0.03502768
A33: 4 | B33: WOFF 457–637 / V3 | C33: 563.87 | D33: 1.71 | E33: 0.003 | F33: =D33/C33 -> 0.0030326139 | G33: =C33/$C$37 -> 0.16033792 | H33: =D33/$D$37 -> 0.19542857 | I33: 639.92 | J33: 1.68 | K33: =J33/I33 -> 0.0026253282 | L33: =(F33-K33)*100 -> 0.040728573 | M33: =C33-I33 -> -76.05 | N33: =F33*12 -> 0.036391367
A34: 5 | B34: WOFF 638–818 / V4 | C34: 610.61 | D34: 0.94 | E34: 0.0015 | F34: =D34/C34 -> 0.0015394442 | G34: =C34/$C$37 -> 0.17362857 | H34: =D34/$D$37 -> 0.10742857 | I34: 522.61 | J34: 0.74 | K34: =J34/I34 -> 0.0014159698 | L34: =(F34-K34)*100 -> 0.012347432 | M34: =C34-I34 -> 88 | N34: =F34*12 -> 0.01847333
A35: 6 | B35: WOFF 819–999 / V5 | C35: 282.69 | D35: 0.24 | E35: 0.0008 | F35: =D35/C35 -> 0.00084898652 | G35: =C35/$C$37 -> 0.080383649 | H35: =D35/$D$37 -> 0.027428571 | I35: 268.95 | J35: 0.21 | K35: =J35/I35 -> 0.00078081428 | L35: =(F35-K35)*100 -> 0.0068172245 | M35: =C35-I35 -> 13.74 | N35: =F35*12 -> 0.010187838
A36: 7 | B36: WOFF > 1000 / V5+ | C36: 1383.1 | D36: 1.08 | E36: 0.0008 | F36: =D36/C36 -> 0.0007808546 | G36: =C36/$C$37 -> 0.39328814 | H36: =D36/$D$37 -> 0.12342857 | I36: 1339 | J36: 1.13 | K36: =J36/I36 -> 0.00084391337 | L36: =(F36-K36)*100 -> -0.0063058766 | M36: =C36-I36 -> 44.1 | N36: =F36*12 -> 0.0093702552
A37: 8 | B37: Grand Total | C37: 3516.76 | D37: 8.75 | E37: 0.0025 | F37: =D37/C37 -> 0.0024880856 | G37: =C37/$C$37 -> 1 | H37: =D37/$D$37 -> 1 | I37: 3503.29 | J37: 9.16 | K37: =J37/I37 -> 0.0026146851 | L37: =(F37-K37)*100 -> -0.012659943 | M37: =C37-I37 -> 13.47 | N37: =F37*12 -> 0.029857027
B38: Check: Σ vintages − Grand Total (POS / recovery); vintage GT vs BC GT | C38: =SUM(C30:C36)-C37 -> 0 | D38: =SUM(D30:D36)-D37 -> 0.01 | I38: =C37-K25 -> 0
B39: NPA pool (V0+V1) POS / rate; WOFF pool (V2–V5) POS / rate | C39: =C30+C31 -> 577.14 | F39: =(D30+D31)/C39 -> 0.0077970683 | I39: =SUM(C32:C36) -> 2939.62 | K39: =SUM(D32:D36)/I39 -> 0.0014491669
A41: D. SMA forward-flow position — opening pool and status (26-Aug), 25-Aug status, MTD pool & FF; BC-wise
A42: # | B42: BC | C42: DPD bucket | D42: Opening accounts | E42: Opening amount ₹ Cr | F42: Resolution ₹ Cr | G42: RR % printed | H42: RR % computed | I42: FF ₹ Cr | J42: FF % printed | K42: RR + FF | L42: Resolution 25-Aug | M42: RR 25-Aug | N42: 1-day Δ resolution | O42: MTD pool accounts | P42: MTD pool amount | Q42: MTD FF accounts | R42: MTD FF amount | S42: MTD FF % printed | T42: MTD FF % computed (amount) | U42: FF % by accounts
A43: 1 | B43: Total | C43: 1–30 DPD | D43: 19543 | E43: 55.96 | F43: 20.89 | G43: 0.3733 | H43: =F43/E43 -> 0.37330236 | I43: 35.07 | J43: 0.6267 | K43: =H43+I43/E43 -> 1 | L43: 20.53 | M43: 0.3669 | N43: =IF(L43="","obscured",F43-L43) -> 0.36 | O43: 19543 | P43: 55.96 | Q43: 11717 | R43: 35.07 | S43: 0.6267 | T43: =R43/P43 -> 0.62669764 | U43: =Q43/O43 -> 0.59954971
A44: 2 | B44: Total | C44: 31–60 DPD | D44: 9781 | E44: 29.07 | F44: 2.55 | G44: 0.0876 | H44: =F44/E44 -> 0.087719298 | I44: 26.52 | J44: 0.9124 | K44: =H44+I44/E44 -> 1 | L44: 2.52 | M44: 0.0866 | N44: =IF(L44="","obscured",F44-L44) -> 0.03 | O44: 9685 | P44: 28.82 | Q44: 8714 | R44: 26.52 | S44: 0.92 | T44: =R44/P44 -> 0.92019431 | U44: =Q44/O44 -> 0.89974187
...

Sheet B2_Metrics
A1: Collection efficiency, recovery and forward flow: notation and metrics
A2: Format: Notation → Exhaustive metrics table | Example column = live Excel formula on the block sheet (green = cross-sheet)
A3: ⚠ DRAFT ONLY — Requires review and approval by a qualified Alvarez and Marsal professional before use.
A5: Notation
B6: Symbol | C6: Meaning
B7: Dm(b), Col(b) | C7: Demand and collection ₹ Cr for DPD bucket b (MTD)
B8: CE(b) | C8: Collection efficiency = Col ÷ Dm
B9: b | C9: Current, 1–30, 31–60, 61–90, Total(≤90), 91–180, >180, Total(>90), Grand Total
B10: POS_N / POS_W | C10: Principal outstanding on NPA / written-off (WOFF) pools, by BC or vintage
B11: Rec | C11: MTD recovery ₹ Cr; rate = Rec ÷ POS
B12: V0–V5+ | C12: Vintage buckets by DPD (NPA: 91–180, 181–365; WOFF: < 456 … > 1000)
B13: OP(k), Res(k), FF(k) | C13: SMA forward flow: opening pool, resolution and flow-forward amounts for bucket k (1–30, 31–60, 61–90)
B14: RR%, FF% | C14: Res ÷ OP, FF ÷ OP; RR + FF = 100%
B15: MTD pool | C15: Second pool definition on the page (accounts/amount differ slightly from opening pool)
B16: STLM | C16: Same time last month (26-Jul-2026)
B17: Amounts ₹ Cr, rates in %, changes in pp; MTD to 26-Aug-2026 with 26-Jul-2026 comparatives.
A19: Exhaustive metrics table
A20: # | B20: Metric family | C20: Pipeline-ready metric | D20: Definition / formula | E20: Applies to | F20: Example
A21: 1 | B21: Fact lookup | C21: Demand / collection by bucket | D21: Dm(b), Col(b) | E21: 9 rows × 2 periods | F21: ="Aug "&TEXT(B2_Collections_Recovery!C7,"#,##0.00;-#,##0.00;0.00")&" / "&TEXT(B2_Collections_Recovery!C8,"#,##0.00;-#,##0.00;0.00")&" / "&TEXT(B2_Collections_Recovery!C9,"#,##0.00;-#,##0.00;0.00")&" / "&TEXT(B2_Collections_Recovery!C10,"#,##0.00;-#,##0.00;0.00")&" demand (Current … 61–90)" -> Aug 1,184.23 / 10.16 / 5.00 / 4.18 demand (Current … 61–90)
A22: 2 | B22: Fact lookup | C22: Recovery pools | D22: POS_N, POS_W, Rec by BC | E22: 5 rows × 2 periods | F22: ="GT NPA "&TEXT(B2_Collections_Recovery!C25,"#,##0.00;-#,##0.00;0.00")&" / WOFF "&TEXT(B2_Collections_Recovery!G25,"#,##0.00;-#,##0.00;0.00")&"; recovery "&TEXT(B2_Collections_Recovery!L25,"#,##0.00;-#,##0.00;0.00") -> GT NPA 577.14 / WOFF 2,939.62; recovery 8.75
A23: 3 | B23: Fact lookup | C23: Forward-flow pool | D23: OP, Res, FF by bucket and BC | E23: 16 rows | F23: ="GT "&TEXT(B2_Collections_Recovery!E46,"#,##0.00;-#,##0.00;0.00")&" / "&TEXT(B2_Collections_Recovery!F46,"#,##0.00;-#,##0.00;0.00")&" / "&TEXT(B2_Collections_Recovery!I46,"#,##0.00;-#,##0.00;0.00") -> GT 109.44 / 24.36 / 85.08
A24: 4 | B24: Roll-up check | C24: CE buckets to totals | D24: Σ ≤90 − Total; Σ >90 − Total; Totals − GT | E24: Aug | F24: =TEXT(B2_Collections_Recovery!C16,"#,##0.00;-#,##0.00;0.00")&" / "&TEXT(B2_Collections_Recovery!D16,"#,##0.00;-#,##0.00;0.00")&" / "&TEXT(B2_Collections_Recovery!E16,"#,##0.00;-#,##0.00;0.00") -> 0.01 / 0.00 / 0.00
A25: 5 | B25: Roll-up check | C25: Printed vs computed rates | D25: Max |printed − computed| (pp) | E25: CE, recovery, RR tables | F25: =TEXT(MAX(ABS(B2_Collections_Recovery!E15-B2_Collections_Recovery!F15),ABS(B2_Collections_Recovery!E25-B2_Collections_Recovery!F25),ABS(B2_Collections_Recovery!I25-B2_Collections_Recovery!J25),ABS(B2_Collections_Recovery!G46-B2_Collections_Recovery!H46))*100,"+0.0"" pp"";-0.0"" pp"";0.0"" pp""") -> +0.0 pp
A26: 6 | B26: Roll-up check | C26: BC recovery to Grand Total | D26: Σ BCs − GT (NPA POS / WOFF POS / recovery) | E26: 3 checks | F26: =TEXT(B2_Collections_Recovery!C26,"#,##0.00;-#,##0.00;0.00")&" / "&TEXT(B2_Collections_Recovery!G26,"#,##0.00;-#,##0.00;0.00")&" / "&TEXT(B2_Collections_Recovery!L26,"#,##0.00;-#,##0.00;0.00") -> -0.01 / -0.01 / -0.01
A27: 7 | B27: Roll-up check | C27: Vintage to Grand Total and to BC GT | D27: Σ vintages − GT; vintage GT − BC GT | E27: 3 checks | F27: =TEXT(B2_Collections_Recovery!C38,"#,##0.00;-#,##0.00;0.00")&" / "&TEXT(B2_Collections_Recovery!D38,"#,##0.00;-#,##0.00;0.00")&" / "&TEXT(B2_Collections_Recovery!I38,"#,##0.00;-#,##0.00;0.00") -> 0.00 / 0.01 / 0.00
A28: 8 | B28: Roll-up check | C28: Forward-flow BCs to GT and to Block-1 pool | D28: Σ BC totals − GT; OP − B(k) Block 1 | E28: 6 checks | F28: =TEXT(B2_Collections_Recovery!E60,"#,##0.00;-#,##0.00;0.00")&" / "&TEXT(B2_Collections_Recovery!F60,"#,##0.00;-#,##0.00;0.00")&" / "&TEXT(B2_Collections_Recovery!I60,"#,##0.00;-#,##0.00;0.00")&"; "&TEXT(B2_Collections_Recovery!E61,"#,##0.00;-#,##0.00;0.00")&" / "&TEXT(B2_Collections_Recovery!F61,"#,##0.00;-#,##0.00;0.00")&" / "&TEXT(B2_Collections_Recovery!G61,"#,##0.00;-#,##0.00;0.00") -> 0.00 / 0.00 / 0.00; 0.00 / 0.00 / 0.00
A29: 9 | B29: Collection efficiency | C29: CE by bucket | D29: CE(b) computed | E29: 9 × 2 | F29: ="Aug "&TEXT(B2_Collections_Recovery!F7,"0.00%")&" / "&TEXT(B2_Collections_Recovery!F8,"0.00%")&" / "&TEXT(B2_Collections_Recovery!F9,"0.00%")&" / "&TEXT(B2_Collections_Recovery!F10,"0.00%")&" / "&TEXT(B2_Collections_Recovery!F11,"0.00%")&" / "&TEXT(B2_Collections_Recovery!F12,"0.00%")&" / "&TEXT(B2_Collections_Recovery!F13,"0.00%")&" / "&TEXT(B2_Collections_Recovery!F14,"0.00%")&" / "&TEXT(B2_Collections_Recovery!F15,"0.00%") -> Aug 98.27% / 47.74% / 16.20% / 11.48% / 97.20% / 21.82% / 9.78% / 10.44% / 85.02%
A30: 10 | B30: Collection efficiency | C30: CE change MoM | D30: CE(b) Aug − Jul (pp) | E30: 9 buckets | F30: =TEXT(B2_Collections_Recovery!N7,"+0.0"" pp"";-0.0"" pp"";0.0"" pp""")&" / "&TEXT(B2_Collections_Recovery!N8,"+0.0"" pp"";-0.0"" pp"";0.0"" pp""")&" / "&TEXT(B2_Collections_Recovery!N9,"+0.0"" pp"";-0.0"" pp"";0.0"" pp""")&" / "&TEXT(B2_Collections_Recovery!N10,"+0.0"" pp"";-0.0"" pp"";0.0"" pp""")&" / "&TEXT(B2_Collections_Recovery!N11,"+0.0"" pp"";-0.0"" pp"";0.0"" pp""")&" / "&TEXT(B2_Collections_Recovery!N12,"+0.0"" pp"";-0.0"" pp"";0.0"" pp""")&" / "&TEXT(B2_Collections_Recovery!N13,"+0.0"" pp"";-0.0"" pp"";0.0"" pp""")&" / "&TEXT(B2_Collections_Recovery!N14,"+0.0"" pp"";-0.0"" pp"";0.0"" pp""")&" / "&TEXT(B2_Collections_Recovery!N15,"+0.0"" pp"";-0.0"" pp"";0.0"" pp""") -> +0.2 pp / -4.0 pp / -1.3 pp / -3.0 pp / +0.2 pp / -5.3 pp / +0.3 pp / +0.0 pp / +0.9 pp
A31: 11 | B31: Collection efficiency | C31: CE ex > 180 dpd | D31: (Col − Col(>180)) ÷ (Dm − Dm(>180)) | E31: Aug / Jul | F31: =TEXT((B2_Collections_Recovery!D15-B2_Collections_Recovery!D13)/(B2_Collections_Recovery!C15-B2_Collections_Recovery!C13),"0.00%")&" / "&TEXT((B2_Collections_Recovery!K15-B2_Collections_Recovery!K13)/(B2_Collections_Recovery!J15-B2_Collections_Recovery!J13),"0.00%") -> 96.53% / 96.40%
A32: 12 | B32: Collection efficiency | C32: CE on overdue 1–90 only | D32: Σ Col(1–90) ÷ Σ Dm(1–90) | E32: Aug / Jul | F32: =TEXT(B2_Collections_Recovery!F17,"0.00%")&" / "&TEXT(B2_Collections_Recovery!M17,"0.00%") -> 31.75% / 34.12%
A33: 13 | B33: Collection efficiency | C33: Shortfall by bucket | D33: Dm − Col | E33: 9 buckets | F33: =TEXT(B2_Collections_Recovery!G7,"#,##0.00;-#,##0.00;0.00")&" / "&TEXT(B2_Collections_Recovery!G8,"#,##0.00;-#,##0.00;0.00")&" / "&TEXT(B2_Collections_Recovery!G9,"#,##0.00;-#,##0.00;0.00")&" / "&TEXT(B2_Collections_Recovery!G10,"#,##0.00;-#,##0.00;0.00")&" / "&TEXT(B2_Collections_Recovery!G12,"#,##0.00;-#,##0.00;0.00")&" / "&TEXT(B2_Collections_Recovery!G13,"#,##0.00;-#,##0.00;0.00")&"; GT "&TEXT(B2_Collections_Recovery!G15,"#,##0.00;-#,##0.00;0.00") -> 20.49 / 5.31 / 4.19 / 3.70 / 8.49 / 167.64; GT 209.81
A34: 14 | B34: Collection efficiency | C34: Share of shortfall | D34: Shortfall(b) ÷ total shortfall | E34: 7 buckets | F34: ="Current "&TEXT(B2_Collections_Recovery!I7,"0.0%")&"; 1–30 "&TEXT(B2_Collections_Recovery!I8,"0.0%")&"; 91–180 "&TEXT(B2_Collections_Recovery!I12,"0.0%")&"; >180 "&TEXT(B2_Collections_Recovery!I13,"0.0%") -> Current 9.8%; 1–30 2.5%; 91–180 4.0%; >180 79.9%
A35: 15 | B35: Collection efficiency | C35: Demand mix | D35: Dm(b) ÷ Dm(GT) | E35: 7 buckets | F35: ="Current "&TEXT(B2_Collections_Recovery!H7,"0.0%")&"; 1–90 "&TEXT(SUM(B2_Collections_Recovery!C8:C10)/B2_Collections_Recovery!C15,"0.0%")&"; >180 "&TEXT(B2_Collections_Recovery!H13,"0.0%") -> Current 84.6%; 1–90 1.4%; >180 13.3%
A36: 16 | B36: Collection efficiency | C36: Demand Aug ÷ Jul (same-day) | D36: Dm Aug ÷ Dm Jul | E36: 9 buckets | F36: =TEXT(B2_Collections_Recovery!O7,"0.00""x""")&" / "&TEXT(B2_Collections_Recovery!O11,"0.00""x""")&" / "&TEXT(B2_Collections_Recovery!O13,"0.00""x""")&" / "&TEXT(B2_Collections_Recovery!O15,"0.00""x""")&" (window effect)" -> 2.03x / 2.03x / 1.89x / 2.01x (window effect)
A37: 17 | B37: Recovery | C37: Recovery rate by BC | D37: Rec ÷ POS — NPA, WOFF, total | E37: 4 BCs + GT | F37: ="GT NPA "&TEXT(B2_Collections_Recovery!F25,"0.00%")&"; WOFF "&TEXT(B2_Collections_Recovery!J25,"0.00%")&"; total "&TEXT(B2_Collections_Recovery!M25,"0.00%")&"; RFL total "&TEXT(B2_Collections_Recovery!M21,"0.00%")&"; NOCPL "&TEXT(B2_Collections_Recovery!M22,"0.00%") -> GT NPA 0.78%; WOFF 0.14%; total 0.25%; RFL total 0.27%; NOCPL 0.19%
A38: 18 | B38: Recovery | C38: Annualised recovery rate | D38: MTD rate × 12 | E38: GT NPA / WOFF | F38: ="NPA "&TEXT(B2_Collections_Recovery!F25*12,"0.00%")&"; WOFF "&TEXT(B2_Collections_Recovery!J25*12,"0.00%") -> NPA 9.36%; WOFF 1.73%
A39: 19 | B39: Recovery | C39: Recovery rate change MoM | D39: Rate Aug − Jul (pp) | E39: 4 BCs + GT | F39: =TEXT(B2_Collections_Recovery!U21,"+0.0"" pp"";-0.0"" pp"";0.0"" pp""")&" / "&TEXT(B2_Collections_Recovery!U22,"+0.0"" pp"";-0.0"" pp"";0.0"" pp""")&" / "&TEXT(B2_Collections_Recovery!U23,"+0.0"" pp"";-0.0"" pp"";0.0"" pp""")&" / "&TEXT(B2_Collections_Recovery!U24,"+0.0"" pp"";-0.0"" pp"";0.0"" pp""")&" / "&TEXT(B2_Collections_Recovery!U25,"+0.0"" pp"";-0.0"" pp"";0.0"" pp""") -> -0.0 pp / -0.1 pp / -0.0 pp / +0.0 pp / -0.0 pp
A40: 20 | B40: Recovery | C40: POS change MoM | D40: POS Aug − Jul | E40: 4 BCs + GT | F40: =TEXT(B2_Collections_Recovery!V21,"#,##0.00;-#,##0.00;0.00")&" / "&TEXT(B2_Collections_Recovery!V22,"#,##0.00;-#,##0.00;0.00")&" / "&TEXT(B2_Collections_Recovery!V23,"#,##0.00;-#,##0.00;0.00")&" / "&TEXT(B2_Collections_Recovery!V24,"#,##0.00;-#,##0.00;0.00")&" / "&TEXT(B2_Collections_Recovery!V25,"#,##0.00;-#,##0.00;0.00") -> 12.68 / 0.05 / 0.76 / -0.03 / 13.48
A41: 21 | B41: Recovery | C41: BC share of POS vs recovery | D41: POS share; recovery share | E41: 4 BCs | F41: ="RFL "&TEXT(B2_Collections_Recovery!N21,"0.0%")&" / "&TEXT(B2_Collections_Recovery!O21,"0.0%")&"; NOCPL "&TEXT(B2_Collections_Recovery!N22,"0.0%")&" / "&TEXT(B2_Collections_Recovery!O22,"0.0%")&"; PAHAL "&TEXT(B2_Collections_Recovery!N23,"0.0%")&" / "&TEXT(B2_Collections_Recovery!O23,"0.0%") -> RFL 86.3% / 92.1%; NOCPL 4.9% / 3.7%; PAHAL 8.1% / 3.9%
A42: 22 | B42: Recovery | C42: WOFF ÷ NPA pool ratio | D42: POS_W ÷ POS_N | E42: GT | F42: =TEXT(B2_Collections_Recovery!G25/B2_Collections_Recovery!C25,"0.00""x""") -> 5.09x
...
