Workbook

Sheet README
A1: RBL Bank — Credit Portfolio Overview (Jul-26): page-wise metric extraction
A2: Source: 10_Credit_Portfolio_Overview.pdf (1 page: summary + wholesale and retail sub-category tables) | accounts and ₹ Cr for Total Outstanding, SMA and NPA | Month Jul-26
A3: ⚠ DRAFT ONLY — Requires review and approval by a qualified Alvarez and Marsal professional before use.
A5: Sheet map
A6: B1_Credit_Portfolio | B6: Sub-category rows with outstanding / SMA / NPA (accounts and amount), ratios, ATS, shares and incidence; roll-ups vs the summary table; cross-page ties
A7: B1_Metrics | B7: Notation + exhaustive metrics
A9: Colour legend
A10: Blue text | B10: Hard-coded input transcribed from the PDF
A11: Blue italic on grey | B11: Budget / projected value (ᴾ) transcribed from the PDF
A12: Black text | B12: Formula on the same sheet
A13: Green text | B13: Link to another sheet
A14: Yellow fill | B14: Data flag to review
A16: Key assumptions (confirm with client)
A17: 1 | B17: Retail Grand Total 'Outstanding amount' and 'SMA accounts' are obscured in the source; they are computed from the sub-category rows and compared with the summary table (67,042.37 and 239,858).
A18: 2 | B18: Blank SMA / NPA cells are read as zero (no stress reported); blank outstanding amount for C&IB Agri (1 account) treated as zero.
A19: 3 | B19: SMA % and NPA % are amount-based unless labelled 'by accounts'. 'Stress' = SMA + NPA.
A20: 4 | B20: Cross-page: Jul-26 outstanding here (wholesale 52,231 / retail 67,042) is gross; the Net Advances page shows Jul-26 net funded 51,950 / 65,077. The Null row (₹985.72 Cr) equals the Null bucket on the Net Advances and Product-wise pages.
A21: Confidentiality | B21: Client-confidential RBL Bank data.
A23: ⚠ DRAFT ONLY — Requires review and approval by a qualified Alvarez and Marsal professional before use.

Sheet B1_Credit_Portfolio
A1: Block 1 — Credit portfolio: outstanding, SMA and NPA by sub-category (Jul-26)
A2: Source: Credit Portfolio Overview.pdf | accounts (count) and amount ₹ Cr | blanks = no stress reported
A3: ⚠ DRAFT ONLY — Requires review and approval by a qualified Alvarez and Marsal professional before use.
A5: A. Sub-category rows (blue) with live ratios
A6: # | B6: Segment | C6: Sub-category | D6: OS accounts | E6: OS ₹ Cr | F6: SMA accounts | G6: SMA ₹ Cr | H6: NPA accounts | I6: NPA ₹ Cr | J6: SMA % (amt) | K6: NPA % (amt) | L6: Stress % (amt) | M6: SMA % (accts) | N6: NPA % (accts) | O6: ATS ₹ lakh | P6: NPA ATS ₹ lakh | Q6: Share of bank OS | R6: Share of bank NPA ₹ | S6: Share of bank SMA ₹ | T6: NPA ₹ share ÷ OS share (index) | U6: Auto-flag
A7: 1 | B7: Wholesale | C7: C&IB Agri | D7: 1 | J7: =IF(N(E7)=0,"",N(G7)/E7) | K7: =IF(N(E7)=0,"",N(I7)/E7) | L7: =IF(N(E7)=0,"",(N(G7)+N(I7))/E7) | M7: =IF(N(D7)=0,"",N(F7)/D7) -> 0 | N7: =IF(N(D7)=0,"",N(H7)/D7) -> 0 | O7: =IF(N(D7)=0,"",N(E7)*100/D7) -> 0 | P7: =IF(N(H7)=0,"",I7*100/H7) | Q7: =N(E7)/$E$49 -> 0 | R7: =N(I7)/$I$49 -> 0 | S7: =N(G7)/$G$49 -> 0 | T7: =IF(Q7=0,"",R7/Q7) | U7: =IF(N(E7)=0,"No amount",IF(ISNUMBER(K7),IF(K7>0.05,"NPA > 5%",IF(ISNUMBER(N7),IF(N7>0.1,"NPA incidence by accounts > 10%",""),"")),"")) -> No amount
A8: 2 | B8: Wholesale | C8: CB (incl Agri & NE) | D8: 8693 | E8: 14955.87 | F8: 64 | G8: 86.09 | H8: 12 | I8: 20.54 | J8: =IF(N(E8)=0,"",N(G8)/E8) -> 0.0057562683 | K8: =IF(N(E8)=0,"",N(I8)/E8) -> 0.0013733738 | L8: =IF(N(E8)=0,"",(N(G8)+N(I8))/E8) -> 0.0071296421 | M8: =IF(N(D8)=0,"",N(F8)/D8) -> 0.0073622455 | N8: =IF(N(D8)=0,"",N(H8)/D8) -> 0.001380421 | O8: =IF(N(D8)=0,"",N(E8)*100/D8) -> 172.04498 | P8: =IF(N(H8)=0,"",I8*100/H8) -> 171.16667 | Q8: =N(E8)/$E$49 -> 0.12539158 | R8: =N(I8)/$I$49 -> 0.011915259 | S8: =N(G8)/$G$49 -> 0.037085539 | T8: =IF(Q8=0,"",R8/Q8) -> 0.095024395 | U8: =IF(N(E8)=0,"No amount",IF(ISNUMBER(K8),IF(K8>0.05,"NPA > 5%",IF(ISNUMBER(N8),IF(N8>0.1,"NPA incidence by accounts > 10%",""),"")),""))
A9: 3 | B9: Wholesale | C9: CB- BBG | D9: 164 | E9: 137.84 | F9: 5 | G9: 60.48 | J9: =IF(N(E9)=0,"",N(G9)/E9) -> 0.43876959 | K9: =IF(N(E9)=0,"",N(I9)/E9) -> 0 | L9: =IF(N(E9)=0,"",(N(G9)+N(I9))/E9) -> 0.43876959 | M9: =IF(N(D9)=0,"",N(F9)/D9) -> 0.030487805 | N9: =IF(N(D9)=0,"",N(H9)/D9) -> 0 | O9: =IF(N(D9)=0,"",N(E9)*100/D9) -> 84.04878 | P9: =IF(N(H9)=0,"",I9*100/H9) | Q9: =N(E9)/$E$49 -> 0.001155665 | R9: =N(I9)/$I$49 -> 0 | S9: =N(G9)/$G$49 -> 0.026053356 | T9: =IF(Q9=0,"",R9/Q9) -> 0 | U9: =IF(N(E9)=0,"No amount",IF(ISNUMBER(K9),IF(K9>0.05,"NPA > 5%",IF(ISNUMBER(N9),IF(N9>0.1,"NPA incidence by accounts > 10%",""),"")),""))
A10: 4 | B10: Wholesale | C10: Corporate Banking (incl G&J) | D10: 4157 | E10: 22103.54 | F10: 10 | G10: 3.73 | H10: 9 | I10: 256.41 | J10: =IF(N(E10)=0,"",N(G10)/E10) -> 0.00016875125 | K10: =IF(N(E10)=0,"",N(I10)/E10) -> 0.011600404 | L10: =IF(N(E10)=0,"",(N(G10)+N(I10))/E10) -> 0.011769156 | M10: =IF(N(D10)=0,"",N(F10)/D10) -> 0.0024055809 | N10: =IF(N(D10)=0,"",N(H10)/D10) -> 0.0021650229 | O10: =IF(N(D10)=0,"",N(E10)*100/D10) -> 531.71855 | P10: =IF(N(H10)=0,"",I10*100/H10) -> 2849 | Q10: =N(E10)/$E$49 -> 0.18531839 | R10: =N(I10)/$I$49 -> 0.1487435 | S10: =N(G10)/$G$49 -> 0.0016067959 | T10: =IF(Q10=0,"",R10/Q10) -> 0.80263756 | U10: =IF(N(E10)=0,"No amount",IF(ISNUMBER(K10),IF(K10>0.05,"NPA > 5%",IF(ISNUMBER(N10),IF(N10>0.1,"NPA incidence by accounts > 10%",""),"")),""))
A11: 5 | B11: Wholesale | C11: FI | D11: 481 | E11: 8755.24 | J11: =IF(N(E11)=0,"",N(G11)/E11) -> 0 | K11: =IF(N(E11)=0,"",N(I11)/E11) -> 0 | L11: =IF(N(E11)=0,"",(N(G11)+N(I11))/E11) -> 0 | M11: =IF(N(D11)=0,"",N(F11)/D11) -> 0 | N11: =IF(N(D11)=0,"",N(H11)/D11) -> 0 | O11: =IF(N(D11)=0,"",N(E11)*100/D11) -> 1820.2162 | P11: =IF(N(H11)=0,"",I11*100/H11) | Q11: =N(E11)/$E$49 -> 0.073404849 | R11: =N(I11)/$I$49 -> 0 | S11: =N(G11)/$G$49 -> 0 | T11: =IF(Q11=0,"",R11/Q11) -> 0 | U11: =IF(N(E11)=0,"No amount",IF(ISNUMBER(K11),IF(K11>0.05,"NPA > 5%",IF(ISNUMBER(N11),IF(N11>0.1,"NPA incidence by accounts > 10%",""),"")),""))
A12: 6 | B12: Wholesale | C12: FIGU- BBB | D12: 2 | E12: 3 | J12: =IF(N(E12)=0,"",N(G12)/E12) -> 0 | K12: =IF(N(E12)=0,"",N(I12)/E12) -> 0 | L12: =IF(N(E12)=0,"",(N(G12)+N(I12))/E12) -> 0 | M12: =IF(N(D12)=0,"",N(F12)/D12) -> 0 | N12: =IF(N(D12)=0,"",N(H12)/D12) -> 0 | O12: =IF(N(D12)=0,"",N(E12)*100/D12) -> 150 | P12: =IF(N(H12)=0,"",I12*100/H12) | Q12: =N(E12)/$E$49 -> 2.5152314e-05 | R12: =N(I12)/$I$49 -> 0 | S12: =N(G12)/$G$49 -> 0 | T12: =IF(Q12=0,"",R12/Q12) -> 0 | U12: =IF(N(E12)=0,"No amount",IF(ISNUMBER(K12),IF(K12>0.05,"NPA > 5%",IF(ISNUMBER(N12),IF(N12>0.1,"NPA incidence by accounts > 10%",""),"")),""))
A13: 7 | B13: Wholesale | C13: Govt. Banking | D13: 15 | E13: 369 | J13: =IF(N(E13)=0,"",N(G13)/E13) -> 0 | K13: =IF(N(E13)=0,"",N(I13)/E13) -> 0 | L13: =IF(N(E13)=0,"",(N(G13)+N(I13))/E13) -> 0 | M13: =IF(N(D13)=0,"",N(F13)/D13) -> 0 | N13: =IF(N(D13)=0,"",N(H13)/D13) -> 0 | O13: =IF(N(D13)=0,"",N(E13)*100/D13) -> 2460 | P13: =IF(N(H13)=0,"",I13*100/H13) | Q13: =N(E13)/$E$49 -> 0.0030937346 | R13: =N(I13)/$I$49 -> 0 | S13: =N(G13)/$G$49 -> 0 | T13: =IF(Q13=0,"",R13/Q13) -> 0 | U13: =IF(N(E13)=0,"No amount",IF(ISNUMBER(K13),IF(K13>0.05,"NPA > 5%",IF(ISNUMBER(N13),IF(N13>0.1,"NPA incidence by accounts > 10%",""),"")),""))
A14: 8 | B14: Wholesale | C14: IFI | D14: 178 | E14: 4010.12 | J14: =IF(N(E14)=0,"",N(G14)/E14) -> 0 | K14: =IF(N(E14)=0,"",N(I14)/E14) -> 0 | L14: =IF(N(E14)=0,"",(N(G14)+N(I14))/E14) -> 0 | M14: =IF(N(D14)=0,"",N(F14)/D14) -> 0 | N14: =IF(N(D14)=0,"",N(H14)/D14) -> 0 | O14: =IF(N(D14)=0,"",N(E14)*100/D14) -> 2252.8764 | P14: =IF(N(H14)=0,"",I14*100/H14) | Q14: =N(E14)/$E$49 -> 0.033621266 | R14: =N(I14)/$I$49 -> 0 | S14: =N(G14)/$G$49 -> 0 | T14: =IF(Q14=0,"",R14/Q14) -> 0 | U14: =IF(N(E14)=0,"No amount",IF(ISNUMBER(K14),IF(K14>0.05,"NPA > 5%",IF(ISNUMBER(N14),IF(N14>0.1,"NPA incidence by accounts > 10%",""),"")),""))
A15: 9 | B15: Wholesale | C15: MNC | D15: 24 | E15: 189.6 | J15: =IF(N(E15)=0,"",N(G15)/E15) -> 0 | K15: =IF(N(E15)=0,"",N(I15)/E15) -> 0 | L15: =IF(N(E15)=0,"",(N(G15)+N(I15))/E15) -> 0 | M15: =IF(N(D15)=0,"",N(F15)/D15) -> 0 | N15: =IF(N(D15)=0,"",N(H15)/D15) -> 0 | O15: =IF(N(D15)=0,"",N(E15)*100/D15) -> 790 | P15: =IF(N(H15)=0,"",I15*100/H15) | Q15: =N(E15)/$E$49 -> 0.0015896262 | R15: =N(I15)/$I$49 -> 0 | S15: =N(G15)/$G$49 -> 0 | T15: =IF(Q15=0,"",R15/Q15) -> 0 | U15: =IF(N(E15)=0,"No amount",IF(ISNUMBER(K15),IF(K15>0.05,"NPA > 5%",IF(ISNUMBER(N15),IF(N15>0.1,"NPA incidence by accounts > 10%",""),"")),""))
A16: 10 | B16: Wholesale | C16: Supply Chain | D16: 560 | E16: 1706.73 | F16: 44 | G16: 157.2 | H16: 9 | I16: 9.66 | J16: =IF(N(E16)=0,"",N(G16)/E16) -> 0.092105957 | K16: =IF(N(E16)=0,"",N(I16)/E16) -> 0.0056599462 | L16: =IF(N(E16)=0,"",(N(G16)+N(I16))/E16) -> 0.097765903 | M16: =IF(N(D16)=0,"",N(F16)/D16) -> 0.078571429 | N16: =IF(N(D16)=0,"",N(H16)/D16) -> 0.016071429 | O16: =IF(N(D16)=0,"",N(E16)*100/D16) -> 304.77321 | P16: =IF(N(H16)=0,"",I16*100/H16) -> 107.33333 | Q16: =N(E16)/$E$49 -> 0.014309403 | R16: =N(I16)/$I$49 -> 0.0056037683 | S16: =N(G16)/$G$49 -> 0.067718048 | T16: =IF(Q16=0,"",R16/Q16) -> 0.3916144 | U16: =IF(N(E16)=0,"No amount",IF(ISNUMBER(K16),IF(K16>0.05,"NPA > 5%",IF(ISNUMBER(N16),IF(N16>0.1,"NPA incidence by accounts > 10%",""),"")),""))
A17: 11 | B17: Wholesale | C17: Retail - Others | D17: 5 | E17: 0 | J17: =IF(N(E17)=0,"",N(G17)/E17) | K17: =IF(N(E17)=0,"",N(I17)/E17) | L17: =IF(N(E17)=0,"",(N(G17)+N(I17))/E17) | M17: =IF(N(D17)=0,"",N(F17)/D17) -> 0 | N17: =IF(N(D17)=0,"",N(H17)/D17) -> 0 | O17: =IF(N(D17)=0,"",N(E17)*100/D17) -> 0 | P17: =IF(N(H17)=0,"",I17*100/H17) | Q17: =N(E17)/$E$49 -> 0 | R17: =N(I17)/$I$49 -> 0 | S17: =N(G17)/$G$49 -> 0 | T17: =IF(Q17=0,"",R17/Q17) | U17: =IF(N(E17)=0,"No amount",IF(ISNUMBER(K17),IF(K17>0.05,"NPA > 5%",IF(ISNUMBER(N17),IF(N17>0.1,"NPA incidence by accounts > 10%",""),"")),"")) -> No amount
A18: 12 | B18: Retail | C18: Affordable Housing | D18: 17882 | E18: 2585.66 | F18: 596 | G18: 100.53 | H18: 167 | I18: 28.83 | J18: =IF(N(E18)=0,"",N(G18)/E18) -> 0.038879822 | K18: =IF(N(E18)=0,"",N(I18)/E18) -> 0.011149958 | L18: =IF(N(E18)=0,"",(N(G18)+N(I18))/E18) -> 0.05002978 | M18: =IF(N(D18)=0,"",N(F18)/D18) -> 0.033329605 | N18: =IF(N(D18)=0,"",N(H18)/D18) -> 0.0093390001 | O18: =IF(N(D18)=0,"",N(E18)*100/D18) -> 14.459568 | P18: =IF(N(H18)=0,"",I18*100/H18) -> 17.263473 | Q18: =N(E18)/$E$49 -> 0.021678444 | R18: =N(I18)/$I$49 -> 0.01672429 | S18: =N(G18)/$G$49 -> 0.04330595 | T18: =IF(Q18=0,"",R18/Q18) -> 0.77147095 | U18: =IF(N(E18)=0,"No amount",IF(ISNUMBER(K18),IF(K18>0.05,"NPA > 5%",IF(ISNUMBER(N18),IF(N18>0.1,"NPA incidence by accounts > 10%",""),"")),""))
A19: 13 | B19: Retail | C19: Prime Housing | D19: 8292 | E19: 4300.78 | F19: 132 | G19: 60.57 | H19: 33 | I19: 24.46 | J19: =IF(N(E19)=0,"",N(G19)/E19) -> 0.014083492 | K19: =IF(N(E19)=0,"",N(I19)/E19) -> 0.0056873404 | L19: =IF(N(E19)=0,"",(N(G19)+N(I19))/E19) -> 0.019770832 | M19: =IF(N(D19)=0,"",N(F19)/D19) -> 0.015918958 | N19: =IF(N(D19)=0,"",N(H19)/D19) -> 0.0039797395 | O19: =IF(N(D19)=0,"",N(E19)*100/D19) -> 51.866618 | P19: =IF(N(H19)=0,"",I19*100/H19) -> 74.121212 | Q19: =N(E19)/$E$49 -> 0.03605819 | R19: =N(I19)/$I$49 -> 0.014189252 | S19: =N(G19)/$G$49 -> 0.026092126 | T19: =IF(Q19=0,"",R19/Q19) -> 0.39350982 | U19: =IF(N(E19)=0,"No amount",IF(ISNUMBER(K19),IF(K19>0.05,"NPA > 5%",IF(ISNUMBER(N19),IF(N19>0.1,"NPA incidence by accounts > 10%",""),"")),""))
A20: 14 | B20: Retail | C20: Housing Loan CL | D20: 4353 | E20: 1232.04 | F20: 207 | G20: 61.88 | H20: 67 | I20: 15.94 | J20: =IF(N(E20)=0,"",N(G20)/E20) -> 0.050225642 | K20: =IF(N(E20)=0,"",N(I20)/E20) -> 0.012937892 | L20: =IF(N(E20)=0,"",(N(G20)+N(I20))/E20) -> 0.063163534 | M20: =IF(N(D20)=0,"",N(F20)/D20) -> 0.047553411 | N20: =IF(N(D20)=0,"",N(H20)/D20) -> 0.015391684 | O20: =IF(N(D20)=0,"",N(E20)*100/D20) -> 28.303239 | P20: =IF(N(H20)=0,"",I20*100/H20) -> 23.791045 | Q20: =N(E20)/$E$49 -> 0.010329552 | R20: =N(I20)/$I$49 -> 0.0092467978 | S20: =N(G20)/$G$49 -> 0.026656443 | T20: =IF(Q20=0,"",R20/Q20) -> 0.89517895 | U20: =IF(N(E20)=0,"No amount",IF(ISNUMBER(K20),IF(K20>0.05,"NPA > 5%",IF(ISNUMBER(N20),IF(N20>0.1,"NPA incidence by accounts > 10%",""),"")),""))
A21: 15 | B21: Retail | C21: Housing Loan DA | D21: 7217 | E21: 954.73 | F21: 197 | G21: 25.96 | H21: 331 | I21: 39.92 | J21: =IF(N(E21)=0,"",N(G21)/E21) -> 0.027190934 | K21: =IF(N(E21)=0,"",N(I21)/E21) -> 0.041812869 | L21: =IF(N(E21)=0,"",(N(G21)+N(I21))/E21) -> 0.069003802 | M21: =IF(N(D21)=0,"",N(F21)/D21) -> 0.027296661 | N21: =IF(N(D21)=0,"",N(H21)/D21) -> 0.045863932 | O21: =IF(N(D21)=0,"",N(E21)*100/D21) -> 13.228904 | P21: =IF(N(H21)=0,"",I21*100/H21) -> 12.060423 | Q21: =N(E21)/$E$49 -> 0.0080045563 | R21: =N(I21)/$I$49 -> 0.023157602 | S21: =N(G21)/$G$49 -> 0.011182955 | T21: =IF(Q21=0,"",R21/Q21) -> 2.8930525 | U21: =IF(N(E21)=0,"No amount",IF(ISNUMBER(K21),IF(K21>0.05,"NPA > 5%",IF(ISNUMBER(N21),IF(N21>0.1,"NPA incidence by accounts > 10%",""),"")),""))
A22: 16 | B22: Retail | C22: Small LAP | D22: 4708 | E22: 1023.28 | F22: 137 | G22: 25.95 | H22: 21 | I22: 4.51 | J22: =IF(N(E22)=0,"",N(G22)/E22) -> 0.025359628 | K22: =IF(N(E22)=0,"",N(I22)/E22) -> 0.0044073958 | L22: =IF(N(E22)=0,"",(N(G22)+N(I22))/E22) -> 0.029767024 | M22: =IF(N(D22)=0,"",N(F22)/D22) -> 0.029099405 | N22: =IF(N(D22)=0,"",N(H22)/D22) -> 0.0044604928 | O22: =IF(N(D22)=0,"",N(E22)*100/D22) -> 21.734919 | P22: =IF(N(H22)=0,"",I22*100/H22) -> 21.47619 | Q22: =N(E22)/$E$49 -> 0.0085792866 | R22: =N(I22)/$I$49 -> 0.0026162521 | S22: =N(G22)/$G$49 -> 0.011178647 | T22: =IF(Q22=0,"",R22/Q22) -> 0.30494984 | U22: =IF(N(E22)=0,"No amount",IF(ISNUMBER(K22),IF(K22>0.05,"NPA > 5%",IF(ISNUMBER(N22),IF(N22>0.1,"NPA incidence by accounts > 10%",""),"")),""))
A23: 17 | B23: Retail | C23: Prime LAP | D23: 7757 | E23: 10517.4 | F23: 318 | G23: 251.67 | H23: 136 | I23: 92.21 | J23: =IF(N(E23)=0,"",N(G23)/E23) -> 0.023928918 | K23: =IF(N(E23)=0,"",N(I23)/E23) -> 0.008767376 | L23: =IF(N(E23)=0,"",(N(G23)+N(I23))/E23) -> 0.032696294 | M23: =IF(N(D23)=0,"",N(F23)/D23) -> 0.04099523 | N23: =IF(N(D23)=0,"",N(H23)/D23) -> 0.017532551 | O23: =IF(N(D23)=0,"",N(E23)*100/D23) -> 135.58592 | P23: =IF(N(H23)=0,"",I23*100/H23) -> 67.801471 | Q23: =N(E23)/$E$49 -> 0.088178983 | R23: =N(I23)/$I$49 -> 0.053491043 | S23: =N(G23)/$G$49 -> 0.10841349 | T23: =IF(Q23=0,"",R23/Q23) -> 0.60661897 | U23: =IF(N(E23)=0,"No amount",IF(ISNUMBER(K23),IF(K23>0.05,"NPA > 5%",IF(ISNUMBER(N23),IF(N23>0.1,"NPA incidence by accounts > 10%",""),"")),""))
A24: 18 | B24: Retail | C24: LAP - CL | D24: 1338 | E24: 470.17 | F24: 72 | G24: 24.27 | H24: 12 | I24: 4.58 | J24: =IF(N(E24)=0,"",N(G24)/E24) -> 0.051619627 | K24: =IF(N(E24)=0,"",N(I24)/E24) -> 0.0097411575 | L24: =IF(N(E24)=0,"",(N(G24)+N(I24))/E24) -> 0.061360784 | M24: =IF(N(D24)=0,"",N(F24)/D24) -> 0.053811659 | N24: =IF(N(D24)=0,"",N(H24)/D24) -> 0.0089686099 | O24: =IF(N(D24)=0,"",N(E24)*100/D24) -> 35.139761 | P24: =IF(N(H24)=0,"",I24*100/H24) -> 38.166667 | Q24: =N(E24)/$E$49 -> 0.0039419545 | R24: =N(I24)/$I$49 -> 0.0026568591 | S24: =N(G24)/$G$49 -> 0.010454943 | T24: =IF(Q24=0,"",R24/Q24) -> 0.67399538 | U24: =IF(N(E24)=0,"No amount",IF(ISNUMBER(K24),IF(K24>0.05,"NPA > 5%",IF(ISNUMBER(N24),IF(N24>0.1,"NPA incidence by accounts > 10%",""),"")),""))
A25: 19 | B25: Retail | C25: LAP - DA | D25: 5040 | E25: 1981.52 | F25: 209 | G25: 63.29 | H25: 171 | I25: 51.07 | J25: =IF(N(E25)=0,"",N(G25)/E25) -> 0.031940127 | K25: =IF(N(E25)=0,"",N(I25)/E25) -> 0.025773144 | L25: =IF(N(E25)=0,"",(N(G25)+N(I25))/E25) -> 0.057713271 | M25: =IF(N(D25)=0,"",N(F25)/D25) -> 0.041468254 | N25: =IF(N(D25)=0,"",N(H25)/D25) -> 0.033928571 | O25: =IF(N(D25)=0,"",N(E25)*100/D25) -> 39.315873 | P25: =IF(N(H25)=0,"",I25*100/H25) -> 29.865497 | Q25: =N(E25)/$E$49 -> 0.016613271 | R25: =N(I25)/$I$49 -> 0.029625719 | S25: =N(G25)/$G$49 -> 0.027263838 | T25: =IF(Q25=0,"",R25/Q25) -> 1.7832562 | U25: =IF(N(E25)=0,"No amount",IF(ISNUMBER(K25),IF(K25>0.05,"NPA > 5%",IF(ISNUMBER(N25),IF(N25>0.1,"NPA incidence by accounts > 10%",""),"")),""))
A26: 20 | B26: Retail | C26: BIL/SBL | D26: 437 | E26: 38.47 | F26: 20 | G26: 0.93 | H26: 85 | I26: 1.1 | J26: =IF(N(E26)=0,"",N(G26)/E26) -> 0.024174682 | K26: =IF(N(E26)=0,"",N(I26)/E26) -> 0.028593709 | L26: =IF(N(E26)=0,"",(N(G26)+N(I26))/E26) -> 0.052768391 | M26: =IF(N(D26)=0,"",N(F26)/D26) -> 0.04576659 | N26: =IF(N(D26)=0,"",N(H26)/D26) -> 0.19450801 | O26: =IF(N(D26)=0,"",N(E26)*100/D26) -> 8.8032037 | P26: =IF(N(H26)=0,"",I26*100/H26) -> 1.2941176 | Q26: =N(E26)/$E$49 -> 0.00032253651 | R26: =N(I26)/$I$49 -> 0.00063811027 | S26: =N(G26)/$G$49 -> 0.00040062204 | T26: =IF(Q26=0,"",R26/Q26) -> 1.9784125 | U26: =IF(N(E26)=0,"No amount",IF(ISNUMBER(K26),IF(K26>0.05,"NPA > 5%",IF(ISNUMBER(N26),IF(N26>0.1,"NPA incidence by accounts > 10%",""),"")),"")) -> NPA incidence by accounts > 10%
A27: 21 | B27: Retail | C27: Gold Loan - BBB | D27: 30995 | E27: 1429.34 | F27: 3926 | G27: 155.71 | H27: 348 | I27: 10.02 | J27: =IF(N(E27)=0,"",N(G27)/E27) -> 0.10893839 | K27: =IF(N(E27)=0,"",N(I27)/E27) -> 0.0070102285 | L27: =IF(N(E27)=0,"",(N(G27)+N(I27))/E27) -> 0.11594862 | M27: =IF(N(D27)=0,"",N(F27)/D27) -> 0.12666559 | N27: =IF(N(D27)=0,"",N(H27)/D27) -> 0.011227617 | O27: =IF(N(D27)=0,"",N(E27)*100/D27) -> 4.611518 | P27: =IF(N(H27)=0,"",I27*100/H27) -> 2.8793103 | Q27: =N(E27)/$E$49 -> 0.011983736 | R27: =N(I27)/$I$49 -> 0.0058126044 | S27: =N(G27)/$G$49 -> 0.067076191 | T27: =IF(Q27=0,"",R27/Q27) -> 0.48504109 | U27: =IF(N(E27)=0,"No amount",IF(ISNUMBER(K27),IF(K27>0.05,"NPA > 5%",IF(ISNUMBER(N27),IF(N27>0.1,"NPA incidence by accounts > 10%",""),"")),""))
A28: 22 | B28: Retail | C28: Gold Loan DA/CL | D28: 129665 | E28: 2819.96 | F28: 5937 | G28: 111.73 | H28: 763 | I28: 12.01 | J28: =IF(N(E28)=0,"",N(G28)/E28) -> 0.039621129 | K28: =IF(N(E28)=0,"",N(I28)/E28) -> 0.0042589257 | L28: =IF(N(E28)=0,"",(N(G28)+N(I28))/E28) -> 0.043880055 | M28: =IF(N(D28)=0,"",N(F28)/D28) -> 0.045787221 | N28: =IF(N(D28)=0,"",N(H28)/D28) -> 0.0058843944 | O28: =IF(N(D28)=0,"",N(E28)*100/D28) -> 2.1748043 | P28: =IF(N(H28)=0,"",I28*100/H28) -> 1.5740498 | Q28: =N(E28)/$E$49 -> 0.02364284 | R28: =N(I28)/$I$49 -> 0.0069670039 | S28: =N(G28)/$G$49 -> 0.048130646 | T28: =IF(Q28=0,"",R28/Q28) -> 0.29467712 | U28: =IF(N(E28)=0,"No amount",IF(ISNUMBER(K28),IF(K28>0.05,"NPA > 5%",IF(ISNUMBER(N28),IF(N28>0.1,"NPA incidence by accounts > 10%",""),"")),""))
A29: 23 | B29: Retail | C29: Education Loan | D29: 83 | E29: 34.99 | J29: =IF(N(E29)=0,"",N(G29)/E29) -> 0 | K29: =IF(N(E29)=0,"",N(I29)/E29) -> 0 | L29: =IF(N(E29)=0,"",(N(G29)+N(I29))/E29) -> 0 | M29: =IF(N(D29)=0,"",N(F29)/D29) -> 0 | N29: =IF(N(D29)=0,"",N(H29)/D29) -> 0 | O29: =IF(N(D29)=0,"",N(E29)*100/D29) -> 42.156627 | P29: =IF(N(H29)=0,"",I29*100/H29) | Q29: =N(E29)/$E$49 -> 0.00029335982 | R29: =N(I29)/$I$49 -> 0 | S29: =N(G29)/$G$49 -> 0 | T29: =IF(Q29=0,"",R29/Q29) -> 0 | U29: =IF(N(E29)=0,"No amount",IF(ISNUMBER(K29),IF(K29>0.05,"NPA > 5%",IF(ISNUMBER(N29),IF(N29>0.1,"NPA incidence by accounts > 10%",""),"")),""))
A30: 24 | B30: Retail | C30: Two Wheeler | D30: 76304 | E30: 388.49 | F30: 6426 | G30: 29 | H30: 5441 | I30: 28.6 | J30: =IF(N(E30)=0,"",N(G30)/E30) -> 0.074647996 | K30: =IF(N(E30)=0,"",N(I30)/E30) -> 0.073618369 | L30: =IF(N(E30)=0,"",(N(G30)+N(I30))/E30) -> 0.14826636 | M30: =IF(N(D30)=0,"",N(F30)/D30) -> 0.084215769 | N30: =IF(N(D30)=0,"",N(H30)/D30) -> 0.071306878 | O30: =IF(N(D30)=0,"",N(E30)*100/D30) -> 0.50913451 | P30: =IF(N(H30)=0,"",I30*100/H30) -> 0.52563867 | Q30: =N(E30)/$E$49 -> 0.0032571408 | R30: =N(I30)/$I$49 -> 0.016590867 | S30: =N(G30)/$G$49 -> 0.012492515 | T30: =IF(Q30=0,"",R30/Q30) -> 5.0936904 | U30: =IF(N(E30)=0,"No amount",IF(ISNUMBER(K30),IF(K30>0.05,"NPA > 5%",IF(ISNUMBER(N30),IF(N30>0.1,"NPA incidence by accounts > 10%",""),"")),"")) -> NPA > 5%
A31: 25 | B31: Retail | C31: Used Car Loans | D31: 1939 | E31: 103.17 | F31: 100 | G31: 4.47 | H31: 93 | I31: 5.34 | J31: =IF(N(E31)=0,"",N(G31)/E31) -> 0.043326548 | K31: =IF(N(E31)=0,"",N(I31)/E31) -> 0.051759232 | L31: =IF(N(E31)=0,"",(N(G31)+N(I31))/E31) -> 0.095085781 | M31: =IF(N(D31)=0,"",N(F31)/D31) -> 0.051572976 | N31: =IF(N(D31)=0,"",N(H31)/D31) -> 0.047962867 | O31: =IF(N(D31)=0,"",N(E31)*100/D31) -> 5.3207839 | P31: =IF(N(H31)=0,"",I31*100/H31) -> 5.7419355 | Q31: =N(E31)/$E$49 -> 0.00086498808 | R31: =N(I31)/$I$49 -> 0.0030977353 | S31: =N(G31)/$G$49 -> 0.0019255705 | T31: =IF(Q31=0,"",R31/Q31) -> 3.5812462 | U31: =IF(N(E31)=0,"No amount",IF(ISNUMBER(K31),IF(K31>0.05,"NPA > 5%",IF(ISNUMBER(N31),IF(N31>0.1,"NPA incidence by accounts > 10%",""),"")),"")) -> NPA > 5%
A32: 26 | B32: Retail | C32: LAS | D32: 8 | E32: 0.26 | J32: =IF(N(E32)=0,"",N(G32)/E32) -> 0 | K32: =IF(N(E32)=0,"",N(I32)/E32) -> 0 | L32: =IF(N(E32)=0,"",(N(G32)+N(I32))/E32) -> 0 | M32: =IF(N(D32)=0,"",N(F32)/D32) -> 0 | N32: =IF(N(D32)=0,"",N(H32)/D32) -> 0 | O32: =IF(N(D32)=0,"",N(E32)*100/D32) -> 3.25 | P32: =IF(N(H32)=0,"",I32*100/H32) | Q32: =N(E32)/$E$49 -> 2.1798672e-06 | R32: =N(I32)/$I$49 -> 0 | S32: =N(G32)/$G$49 -> 0 | T32: =IF(Q32=0,"",R32/Q32) -> 0 | U32: =IF(N(E32)=0,"No amount",IF(ISNUMBER(K32),IF(K32>0.05,"NPA > 5%",IF(ISNUMBER(N32),IF(N32>0.1,"NPA incidence by accounts > 10%",""),"")),""))
A33: 27 | B33: Retail | C33: Retail - Others | D33: 5444 | E33: 1488.86 | F33: 104 | G33: 4.28 | H33: 19 | I33: 0.65 | J33: =IF(N(E33)=0,"",N(G33)/E33) -> 0.0028746826 | K33: =IF(N(E33)=0,"",N(I33)/E33) -> 0.00043657564 | L33: =IF(N(E33)=0,"",(N(G33)+N(I33))/E33) -> 0.0033112583 | M33: =IF(N(D33)=0,"",N(F33)/D33) -> 0.0191036 | N33: =IF(N(D33)=0,"",N(H33)/D33) -> 0.0034900808 | O33: =IF(N(D33)=0,"",N(E33)*100/D33) -> 27.348641 | P33: =IF(N(H33)=0,"",I33*100/H33) -> 3.4210526 | Q33: =N(E33)/$E$49 -> 0.012482758 | R33: =N(I33)/$I$49 -> 0.00037706516 | S33: =N(G33)/$G$49 -> 0.0018437229 | T33: =IF(Q33=0,"",R33/Q33) -> 0.030206878 | U33: =IF(N(E33)=0,"No amount",IF(ISNUMBER(K33),IF(K33>0.05,"NPA > 5%",IF(ISNUMBER(N33),IF(N33>0.1,"NPA incidence by accounts > 10%",""),"")),""))
A34: 28 | B34: Retail | C34: Credit Card | D34: 4304393 | E34: 19324.58 | F34: 171499 | G34: 833.42 | H34: 175978 | I34: 526.32 | J34: =IF(N(E34)=0,"",N(G34)/E34) -> 0.043127457 | K34: =IF(N(E34)=0,"",N(I34)/E34) -> 0.02723578 | L34: =IF(N(E34)=0,"",(N(G34)+N(I34))/E34) -> 0.070363237 | M34: =IF(N(D34)=0,"",N(F34)/D34) -> 0.039842784 | N34: =IF(N(D34)=0,"",N(H34)/D34) -> 0.040883349 | O34: =IF(N(D34)=0,"",N(E34)*100/D34) -> 0.44895018 | P34: =IF(N(H34)=0,"",I34*100/H34) -> 0.29908284 | Q34: =N(E34)/$E$49 -> 0.1620193 | R34: =N(I34)/$I$49 -> 0.30531836 | S34: =N(G34)/$G$49 -> 0.35901766 | T34: =IF(Q34=0,"",R34/Q34) -> 1.8844567 | U34: =IF(N(E34)=0,"No amount",IF(ISNUMBER(K34),IF(K34>0.05,"NPA > 5%",IF(ISNUMBER(N34),IF(N34>0.1,"NPA incidence by accounts > 10%",""),"")),""))
A35: 29 | B35: Retail | C35: Micro Banking | D35: 2693180 | E35: 8516.74 | F35: 46962 | G35: 113.25 | H35: 307339 | I35: 271.88 | J35: =IF(N(E35)=0,"",N(G35)/E35) -> 0.013297341 | K35: =IF(N(E35)=0,"",N(I35)/E35) -> 0.031923013 | L35: =IF(N(E35)=0,"",(N(G35)+N(I35))/E35) -> 0.045220354 | M35: =IF(N(D35)=0,"",N(F35)/D35) -> 0.017437379 | N35: =IF(N(D35)=0,"",N(H35)/D35) -> 0.11411751 | O35: =IF(N(D35)=0,"",N(E35)*100/D35) -> 0.3162336 | P35: =IF(N(H35)=0,"",I35*100/H35) -> 0.088462577 | Q35: =N(E35)/$E$49 -> 0.07140524 | R35: =N(I35)/$I$49 -> 0.15771765 | S35: =N(G35)/$G$49 -> 0.048785426 | T35: =IF(Q35=0,"",R35/Q35) -> 2.2087686 | U35: =IF(N(E35)=0,"No amount",IF(ISNUMBER(K35),IF(K35>0.05,"NPA > 5%",IF(ISNUMBER(N35),IF(N35>0.1,"NPA incidence by accounts > 10%",""),"")),"")) -> NPA incidence by accounts > 10%
A36: 30 | B36: Retail | C36: MSME | D36: 3050 | E36: 48.62 | F36: 156 | G36: 6.34 | H36: 2420 | I36: 25.19 | J36: =IF(N(E36)=0,"",N(G36)/E36) -> 0.13039901 | K36: =IF(N(E36)=0,"",N(I36)/E36) -> 0.51809955 | L36: =IF(N(E36)=0,"",(N(G36)+N(I36))/E36) -> 0.64849856 | M36: =IF(N(D36)=0,"",N(F36)/D36) -> 0.051147541 | N36: =IF(N(D36)=0,"",N(H36)/D36) -> 0.79344262 | O36: =IF(N(D36)=0,"",N(E36)*100/D36) -> 1.5940984 | P36: =IF(N(H36)=0,"",I36*100/H36) -> 1.0409091 | Q36: =N(E36)/$E$49 -> 0.00040763517 | R36: =N(I36)/$I$49 -> 0.014612725 | S36: =N(G36)/$G$49 -> 0.0027311223 | T36: =IF(Q36=0,"",R36/Q36) -> 35.847557 | U36: =IF(N(E36)=0,"No amount",IF(ISNUMBER(K36),IF(K36>0.05,"NPA > 5%",IF(ISNUMBER(N36),IF(N36>0.1,"NPA incidence by accounts > 10%",""),"")),"")) -> NPA > 5%
A37: 31 | B37: Retail | C37: Retail Agri | D37: 35707 | E37: 1763.42 | F37: 369 | G37: 11.24 | H37: 5515 | I37: 165.1 | J37: =IF(N(E37)=0,"",N(G37)/E37) -> 0.0063739778 | K37: =IF(N(E37)=0,"",N(I37)/E37) -> 0.093624888 | L37: =IF(N(E37)=0,"",(N(G37)+N(I37))/E37) -> 0.099998866 | M37: =IF(N(D37)=0,"",N(F37)/D37) -> 0.010334108 | N37: =IF(N(D37)=0,"",N(H37)/D37) -> 0.15445151 | O37: =IF(N(D37)=0,"",N(E37)*100/D37) -> 4.9385835 | P37: =IF(N(H37)=0,"",I37*100/H37) -> 2.9936537 | Q37: =N(E37)/$E$49 -> 0.014784698 | R37: =N(I37)/$I$49 -> 0.09577455 | S37: =N(G37)/$G$49 -> 0.0048419266 | T37: =IF(Q37=0,"",R37/Q37) -> 6.4779511 | U37: =IF(N(E37)=0,"No amount",IF(ISNUMBER(K37),IF(K37>0.05,"NPA > 5%",IF(ISNUMBER(N37),IF(N37>0.1,"NPA incidence by accounts > 10%",""),"")),"")) -> NPA > 5%
A38: 32 | B38: Retail | C38: RVF | D38: 115277 | E38: 3464.44 | F38: 2358 | G38: 52.31 | H38: 2071 | I38: 59.33 | J38: =IF(N(E38)=0,"",N(G38)/E38) -> 0.015099121 | K38: =IF(N(E38)=0,"",N(I38)/E38) -> 0.017125423 | L38: =IF(N(E38)=0,"",(N(G38)+N(I38))/E38) -> 0.032224544 | M38: =IF(N(D38)=0,"",N(F38)/D38) -> 0.020455078 | N38: =IF(N(D38)=0,"",N(H38)/D38) -> 0.017965422 | O38: =IF(N(D38)=0,"",N(E38)*100/D38) -> 3.0053176 | P38: =IF(N(H38)=0,"",I38*100/H38) -> 2.8647996 | Q38: =N(E38)/$E$49 -> 0.029046228 | R38: =N(I38)/$I$49 -> 0.034417347 | S38: =N(G38)/$G$49 -> 0.022533913 | T38: =IF(Q38=0,"",R38/Q38) -> 1.1849163 | U38: =IF(N(E38)=0,"No amount",IF(ISNUMBER(K38),IF(K38>0.05,"NPA > 5%",IF(ISNUMBER(N38),IF(N38>0.1,"NPA incidence by accounts > 10%",""),"")),""))
A39: 33 | B39: Retail | C39: WCF/BBG | D39: 2761 | E39: 3055.28 | F39: 65 | G39: 75.95 | H39: 23 | I39: 69.75 | J39: =IF(N(E39)=0,"",N(G39)/E39) -> 0.024858605 | K39: =IF(N(E39)=0,"",N(I39)/E39) -> 0.022829332 | L39: =IF(N(E39)=0,"",(N(G39)+N(I39))/E39) -> 0.047687937 | M39: =IF(N(D39)=0,"",N(F39)/D39) -> 0.023542195 | N39: =IF(N(D39)=0,"",N(H39)/D39) -> 0.0083303151 | O39: =IF(N(D39)=0,"",N(E39)*100/D39) -> 110.65846 | P39: =IF(N(H39)=0,"",I39*100/H39) -> 303.26087 | Q39: =N(E39)/$E$49 -> 0.025615787 | R39: =N(I39)/$I$49 -> 0.040461992 | S39: =N(G39)/$G$49 -> 0.032717467 | T39: =IF(Q39=0,"",R39/Q39) -> 1.5795724 | U39: =IF(N(E39)=0,"No amount",IF(ISNUMBER(K39),IF(K39>0.05,"NPA > 5%",IF(ISNUMBER(N39),IF(N39>0.1,"NPA incidence by accounts > 10%",""),"")),""))
A40: 34 | B40: Retail | C40: Null | D40: 14 | E40: 985.72 | J40: =IF(N(E40)=0,"",N(G40)/E40) -> 0 | K40: =IF(N(E40)=0,"",N(I40)/E40) -> 0 | L40: =IF(N(E40)=0,"",(N(G40)+N(I40))/E40) -> 0 | M40: =IF(N(D40)=0,"",N(F40)/D40) -> 0 | N40: =IF(N(D40)=0,"",N(H40)/D40) -> 0 | O40: =IF(N(D40)=0,"",N(E40)*100/D40) -> 7040.8571 | P40: =IF(N(H40)=0,"",I40*100/H40) | Q40: =N(E40)/$E$49 -> 0.0082643797 | R40: =N(I40)/$I$49 -> 0 | S40: =N(G40)/$G$49 -> 0 | T40: =IF(Q40=0,"",R40/Q40) -> 0 | U40: =IF(N(E40)=0,"No amount",IF(ISNUMBER(K40),IF(K40>0.05,"NPA > 5%",IF(ISNUMBER(N40),IF(N40>0.1,"NPA incidence by accounts > 10%",""),"")),""))
A41: 35 | B41: Retail | C41: Agri-BBB | D41: 9 | E41: 4.69 | J41: =IF(N(E41)=0,"",N(G41)/E41) -> 0 | K41: =IF(N(E41)=0,"",N(I41)/E41) -> 0 | L41: =IF(N(E41)=0,"",(N(G41)+N(I41))/E41) -> 0 | M41: =IF(N(D41)=0,"",N(F41)/D41) -> 0 | N41: =IF(N(D41)=0,"",N(H41)/D41) -> 0 | O41: =IF(N(D41)=0,"",N(E41)*100/D41) -> 52.111111 | P41: =IF(N(H41)=0,"",I41*100/H41) | Q41: =N(E41)/$E$49 -> 3.9321451e-05 | R41: =N(I41)/$I$49 -> 0 | S41: =N(G41)/$G$49 -> 0 | T41: =IF(Q41=0,"",R41/Q41) -> 0 | U41: =IF(N(E41)=0,"No amount",IF(ISNUMBER(K41),IF(K41>0.05,"NPA > 5%",IF(ISNUMBER(N41),IF(N41>0.1,"NPA incidence by accounts > 10%",""),"")),""))
...

Sheet B1_Metrics
A1: Credit portfolio overview: notation and metrics
A2: Format: Notation → Exhaustive metrics table | Example column = live Excel formula on the block sheet (green = cross-sheet)
A3: ⚠ DRAFT ONLY — Requires review and approval by a qualified Alvarez and Marsal professional before use.
A5: Notation
B6: Symbol | C6: Meaning
B7: OS(x), SMA(x), NPA(x) | C7: Outstanding, SMA and NPA amounts ₹ Cr for sub-category x at Jul-26
B8: n_OS, n_SMA, n_NPA | C8: Corresponding account counts
B9: W / R / B | C9: Wholesale / Retail / Bank totals
B10: SMA%, NPA% | C10: SMA ÷ OS, NPA ÷ OS (amount)
B11: Stress% | C11: (SMA + NPA) ÷ OS
B12: inc_NPA | C12: NPA incidence by accounts = n_NPA ÷ n_OS
B13: ATS | C13: OS × 100 ÷ n_OS, ₹ lakh; NPA ATS = NPA × 100 ÷ n_NPA
B14: sh_OS, sh_NPA | C14: Share of bank OS / NPA ₹
B15: idx | C15: NPA share ÷ OS share (>1 = over-represented in NPA)
B16: UNS / SEC / PART | C16: Analyst groupings: unsecured retail, secured retail, partnership (CL + DA) book
B17: NET | C17: Jul-26 net funded advances from the Net Advances page
B18: Amounts ₹ Cr, accounts as counts, ratios in %, ATS in ₹ lakh; single month (Jul-26); blanks read as zero.
A20: Exhaustive metrics table
A21: # | B21: Metric family | C21: Pipeline-ready metric | D21: Definition / formula | E21: Applies to | F21: Example
A22: 1 | B22: Fact lookup | C22: Sub-category OS / SMA / NPA | D22: OS, SMA, NPA and accounts | E22: 36 rows × 6 fields | F22: ="Credit Card "&TEXT(B1_Credit_Portfolio!E34,"#,##0.00;-#,##0.00;0.00")&" / "&TEXT(B1_Credit_Portfolio!G34,"#,##0.00;-#,##0.00;0.00")&" / "&TEXT(B1_Credit_Portfolio!I34,"#,##0.00;-#,##0.00;0.00")&" ₹ Cr; accounts "&TEXT(B1_Credit_Portfolio!D34,"#,##0")&" / "&TEXT(B1_Credit_Portfolio!F34,"#,##0")&" / "&TEXT(B1_Credit_Portfolio!H34,"#,##0") -> Credit Card 19,324.58 / 833.42 / 526.32 ₹ Cr; accounts 4,304,393 / 171,499 / 175,978
A23: 2 | B23: Fact lookup | C23: Summary totals | D23: W, R, B as printed | E23: 3 × 6 | F23: ="B OS "&TEXT(B1_Credit_Portfolio!E49,"#,##0.00;-#,##0.00;0.00")&"; SMA "&TEXT(B1_Credit_Portfolio!G49,"#,##0.00;-#,##0.00;0.00")&"; NPA "&TEXT(B1_Credit_Portfolio!I49,"#,##0.00;-#,##0.00;0.00") -> B OS 119,273.32; SMA 2,321.39; NPA 1,723.84
A24: 3 | B24: Roll-up check | C24: Rows to summary | D24: Σ rows − summary | E24: W, R × 6 | F24: ="W "&TEXT(B1_Credit_Portfolio!D52,"#,##0.00;-#,##0.00;0.00")&" / "&TEXT(B1_Credit_Portfolio!E52,"#,##0.00;-#,##0.00;0.00")&" / "&TEXT(B1_Credit_Portfolio!F52,"#,##0.00;-#,##0.00;0.00")&" / "&TEXT(B1_Credit_Portfolio!G52,"#,##0.00;-#,##0.00;0.00")&" / "&TEXT(B1_Credit_Portfolio!H52,"#,##0.00;-#,##0.00;0.00")&" / "&TEXT(B1_Credit_Portfolio!I52,"#,##0.00;-#,##0.00;0.00")&"; R "&TEXT(B1_Credit_Portfolio!D53,"#,##0.00;-#,##0.00;0.00")&" / "&TEXT(B1_Credit_Portfolio!E53,"#,##0.00;-#,##0.00;0.00")&" / "&TEXT(B1_Credit_Portfolio!F53,"#,##0.00;-#,##0.00;0.00")&" / "&TEXT(B1_Credit_Portfolio!G53,"#,##0.00;-#,##0.00;0.00")&" / "&TEXT(B1_Credit_Portfolio!H53,"#,##0.00;-#,##0.00;0.00")&" / "&TEXT(B1_Credit_Portfolio!I53,"#,##0.00;-#,##0.00;0.00") -> W 0.00 / 0.00 / 0.00 / 0.00 / 0.00 / 0.00; R 0.00 / -0.02 / 0.00 / -0.02 / 0.00 / 0.01
A25: 4 | B25: Roll-up check | C25: Summary to Grand Total | D25: W + R − B | E25: 6 fields | F25: =TEXT(B1_Credit_Portfolio!D54,"#,##0.00;-#,##0.00;0.00")&" / "&TEXT(B1_Credit_Portfolio!E54,"#,##0.00;-#,##0.00;0.00")&" / "&TEXT(B1_Credit_Portfolio!F54,"#,##0.00;-#,##0.00;0.00")&" / "&TEXT(B1_Credit_Portfolio!G54,"#,##0.00;-#,##0.00;0.00")&" / "&TEXT(B1_Credit_Portfolio!H54,"#,##0.00;-#,##0.00;0.00")&" / "&TEXT(B1_Credit_Portfolio!I54,"#,##0.00;-#,##0.00;0.00") -> 0.00 / -0.01 / 0.00 / 0.01 / 0.00 / 0.01
A26: 5 | B26: Asset quality | C26: Gross NPA ratio | D26: NPA% = NPA ÷ OS | E26: B, W, R + 36 rows | F26: ="B "&TEXT(B1_Credit_Portfolio!K49,"0.00%")&"; W "&TEXT(B1_Credit_Portfolio!K50,"0.00%")&"; R "&TEXT(B1_Credit_Portfolio!K51,"0.00%") -> B 1.45%; W 0.55%; R 2.14%
A27: 6 | B27: Asset quality | C27: SMA ratio | D27: SMA ÷ OS | E27: B, W, R + rows | F27: ="B "&TEXT(B1_Credit_Portfolio!J49,"0.00%")&"; W "&TEXT(B1_Credit_Portfolio!J50,"0.00%")&"; R "&TEXT(B1_Credit_Portfolio!J51,"0.00%") -> B 1.95%; W 0.59%; R 3.00%
A28: 7 | B28: Asset quality | C28: Stress ratio | D28: (SMA + NPA) ÷ OS | E28: B, W, R + rows | F28: ="B "&TEXT(B1_Credit_Portfolio!L49,"0.00%")&"; W "&TEXT(B1_Credit_Portfolio!L50,"0.00%")&"; R "&TEXT(B1_Credit_Portfolio!L51,"0.00%") -> B 3.39%; W 1.14%; R 5.15%
A29: 8 | B29: Asset quality | C29: Sub-category NPA % | D29: NPA%(x) | E29: 36 rows | F29: ="Cards "&TEXT(B1_Credit_Portfolio!K34,"0.00%")&"; Micro "&TEXT(B1_Credit_Portfolio!K35,"0.00%")&"; Two Wheeler "&TEXT(B1_Credit_Portfolio!K30,"0.00%")&"; Retail Agri "&TEXT(B1_Credit_Portfolio!K37,"0.00%")&"; Prime LAP "&TEXT(B1_Credit_Portfolio!K23,"0.00%")&"; HL DA "&TEXT(B1_Credit_Portfolio!K21,"0.00%") -> Cards 2.72%; Micro 3.19%; Two Wheeler 7.36%; Retail Agri 9.36%; Prime LAP 0.88%; HL DA 4.18%
A30: 9 | B30: Asset quality | C30: Sub-category SMA % | D30: SMA%(x) | E30: 36 rows | F30: ="Gold BBB "&TEXT(B1_Credit_Portfolio!J27,"0.00%")&"; Cards "&TEXT(B1_Credit_Portfolio!J34,"0.00%")&"; Two Wheeler "&TEXT(B1_Credit_Portfolio!J30,"0.00%")&"; Supply Chain "&TEXT(B1_Credit_Portfolio!J16,"0.00%") -> Gold BBB 10.89%; Cards 4.31%; Two Wheeler 7.46%; Supply Chain 9.21%
A31: 10 | B31: Asset quality | C31: NPA incidence by accounts | D31: inc_NPA = n_NPA ÷ n_OS | E31: 36 rows | F31: ="Micro "&TEXT(B1_Credit_Portfolio!N35,"0.00%")&"; Cards "&TEXT(B1_Credit_Portfolio!N34,"0.00%")&"; MSME "&TEXT(B1_Credit_Portfolio!N36,"0.00%")&"; Retail Agri "&TEXT(B1_Credit_Portfolio!N37,"0.00%")&"; Two Wheeler "&TEXT(B1_Credit_Portfolio!N30,"0.00%") -> Micro 11.41%; Cards 4.09%; MSME 79.34%; Retail Agri 15.45%; Two Wheeler 7.13%
A32: 11 | B32: Asset quality | C32: Incidence gap (accounts − amount) | D32: (inc_NPA − NPA%) × 100 | E32: 36 rows | F32: ="Micro "&TEXT((B1_Credit_Portfolio!N35-B1_Credit_Portfolio!K35)*100,"+0.0"" pp"";-0.0"" pp"";0.0"" pp""")&"; Cards "&TEXT((B1_Credit_Portfolio!N34-B1_Credit_Portfolio!K34)*100,"+0.0"" pp"";-0.0"" pp"";0.0"" pp""")&"; Retail Agri "&TEXT((B1_Credit_Portfolio!N37-B1_Credit_Portfolio!K37)*100,"+0.0"" pp"";-0.0"" pp"";0.0"" pp""") -> Micro +8.2 pp; Cards +1.4 pp; Retail Agri +6.1 pp
A33: 12 | B33: Asset quality | C33: SMA incidence by accounts | D33: n_SMA ÷ n_OS | E33: 36 rows | F33: ="Gold BBB "&TEXT(B1_Credit_Portfolio!M27,"0.00%")&"; Two Wheeler "&TEXT(B1_Credit_Portfolio!M30,"0.00%")&"; Cards "&TEXT(B1_Credit_Portfolio!M34,"0.00%") -> Gold BBB 12.67%; Two Wheeler 8.42%; Cards 3.98%
A34: 13 | B34: Asset quality | C34: SMA-to-NPA pipeline ratio | D34: SMA ÷ NPA (amount) | E34: B, W, R | F34: ="B "&TEXT(B1_Credit_Portfolio!G49/B1_Credit_Portfolio!I49,"0.00""x""")&"; W "&TEXT(B1_Credit_Portfolio!G50/B1_Credit_Portfolio!I50,"0.00""x""")&"; R "&TEXT(B1_Credit_Portfolio!G51/B1_Credit_Portfolio!I51,"0.00""x""") -> B 1.35x; W 1.07x; R 1.40x
A35: 14 | B35: Asset quality | C35: Group NPA / stress ratios | D35: NPA%, Stress% for analyst groups | E35: 7 groups | F35: ="UNS "&TEXT(B1_Credit_Portfolio!G58,"0.00%")&" / "&TEXT(B1_Credit_Portfolio!H58,"0.00%")&"; SEC "&TEXT(B1_Credit_Portfolio!G59,"0.00%")&" / "&TEXT(B1_Credit_Portfolio!H59,"0.00%")&"; PART "&TEXT(B1_Credit_Portfolio!G60,"0.00%")&" / "&TEXT(B1_Credit_Portfolio!H60,"0.00%") -> UNS 2.95% / 6.37%; SEC 1.19% / 4.23%; PART 1.66% / 5.51%
A36: 15 | B36: Asset quality | C36: Housing / LAP / Gold NPA % | D36: Group NPA% | E36: 3 groups | F36: =TEXT(B1_Credit_Portfolio!G61,"0.00%")&" / "&TEXT(B1_Credit_Portfolio!G62,"0.00%")&" / "&TEXT(B1_Credit_Portfolio!G63,"0.00%") -> 1.20% / 1.09% / 0.52%
A37: 16 | B37: Concentration of stress | C37: Share of bank NPA ₹ | D37: sh_NPA(x) | E37: 36 rows | F37: ="Cards "&TEXT(B1_Credit_Portfolio!R34,"0.0%")&"; Micro "&TEXT(B1_Credit_Portfolio!R35,"0.0%")&"; Corp Banking "&TEXT(B1_Credit_Portfolio!R10,"0.0%")&"; Retail Agri "&TEXT(B1_Credit_Portfolio!R37,"0.0%")&"; Prime LAP "&TEXT(B1_Credit_Portfolio!R23,"0.0%") -> Cards 30.5%; Micro 15.8%; Corp Banking 14.9%; Retail Agri 9.6%; Prime LAP 5.3%
A38: 17 | B38: Concentration of stress | C38: Share of bank SMA ₹ | D38: sh_SMA(x) | E38: 36 rows | F38: ="Cards "&TEXT(B1_Credit_Portfolio!S34,"0.0%")&"; Prime LAP "&TEXT(B1_Credit_Portfolio!S23,"0.0%")&"; Gold BBB "&TEXT(B1_Credit_Portfolio!S27,"0.0%")&"; Supply Chain "&TEXT(B1_Credit_Portfolio!S16,"0.0%") -> Cards 35.9%; Prime LAP 10.8%; Gold BBB 6.7%; Supply Chain 6.8%
A39: 18 | B39: Concentration of stress | C39: Over-representation index | D39: idx = sh_NPA ÷ sh_OS | E39: 36 rows | F39: ="Cards "&TEXT(B1_Credit_Portfolio!T34,"0.00""x""")&"; Micro "&TEXT(B1_Credit_Portfolio!T35,"0.00""x""")&"; Retail Agri "&TEXT(B1_Credit_Portfolio!T37,"0.00""x""")&"; Corp Banking "&TEXT(B1_Credit_Portfolio!T10,"0.00""x""")&"; CB "&TEXT(B1_Credit_Portfolio!T8,"0.00""x""") -> Cards 1.88x; Micro 2.21x; Retail Agri 6.48x; Corp Banking 0.80x; CB 0.10x
A40: 19 | B40: Concentration of stress | C40: Group share of bank NPA | D40: sh_NPA(group) | E40: 7 groups | F40: ="UNS "&TEXT(B1_Credit_Portfolio!J58,"0.0%")&"; SEC "&TEXT(B1_Credit_Portfolio!J59,"0.0%")&"; PART "&TEXT(B1_Credit_Portfolio!J60,"0.0%") -> UNS 47.8%; SEC 21.9%; PART 7.2%
A41: 20 | B41: Concentration of stress | C41: Top-3 NPA contributors share | D41: Σ LARGE(NPA, 3) ÷ NPA(B) | E41: 36 rows | F41: =TEXT(SUMPRODUCT(LARGE(B1_Credit_Portfolio!I7:I42,{1,2,3}))/B1_Credit_Portfolio!I49,"0.0%") -> 61.2%
A42: 21 | B42: Concentration of stress | C42: Wholesale NPA concentration | D42: NPA(Corp) ÷ NPA(W); accounts | E42: W | F42: =TEXT(B1_Credit_Portfolio!I10/B1_Credit_Portfolio!I50,"0.0%")&" on "&TEXT(B1_Credit_Portfolio!H10,"#,##0")&" accounts" -> 89.5% on 9 accounts
...
