Workbook

Sheet README
A1: RBL Bank — Overview of Advances: Overall (gross) Advances and Liability MEB — page-wise metric extraction
A2: Source: 11_Overall_Advances.pdf (1 page, 2 clipped tables; balance dates 26-Aug-26, 31-Jul-26, 30-Jun-26, 31-May-26) | ₹ Cr, accounts, customers
A3: ⚠ DRAFT ONLY — Requires review and approval by a qualified Alvarez and Marsal professional before use.
A5: Sheet map
A6: B1_Gross_Advances | B6: Block 1 — Gross advances by category / sub-category at four balance dates with accounts and customers (May accounts clipped), ATS, accounts-per-customer, growth, mix and roll-up checks
A7: B1_Metrics | B7: Notation + metrics for Block 1
A8: B2_Liability_MEB | B8: Block 2 — Liability MEB by product at three dates with accounts and customers (Jun customers clipped)
A9: B2_Metrics | B9: Notation + metrics for Block 2
A11: Colour legend
A12: Blue text | B12: Hard-coded input transcribed from the PDF
A13: Blue italic on grey | B13: Budget / projected value (ᴾ) transcribed from the PDF
A14: Black text | B14: Formula on the same sheet
A15: Green text | B15: Link to another sheet
A16: Yellow fill | B16: Data flag to review
A18: Key assumptions (confirm with client)
A19: 1 | B19: Both tables were exported clipped. Gross Advances: 31-May-26 shows only the Gross Advances column; the Retail Lending rows shown do not add to the Retail Sub Total (more rows below the visible area) — the unseen remainder is computed. Liability MEB: 30-Jun-26 shows MEB and accounts only.
A20: 2 | B20: Wholesale rows add exactly to the Wholesale Sub Total at every date (C&IB Agri and 'Retail - Others' are blank). Overall − Wholesale − Retail Lending = the un-shown retail products (cards, micro banking, wheels, agri, etc.).
A21: 3 | B21: ATS = Gross ÷ accounts (₹ lakh); accounts per customer = accounts ÷ customers.
A22: 4 | B22: Cross-page: 31-Jul-26 Overall (119,273.32) and Wholesale (52,230.94) equal the Credit Portfolio Overview Jul-26 totals; these are gross figures — the Net Advances page shows Jul-26 net funded 117,027. Liability MEB total (106,752) is the end-of-day balance on 26-Aug-26, while the MAB page reports 115,449 monthly-average.
A23: Confidentiality | B23: Client-confidential RBL Bank data.
A25: ⚠ DRAFT ONLY — Requires review and approval by a qualified Alvarez and Marsal professional before use.

Sheet B1_Gross_Advances
A1: Block 1 — Gross advances by sub-category at four balance dates
A2: Source: Overall Advances.pdf | Gross ₹ Cr, # accounts, # customers | 31-May-26 gross only (clipped)
A3: ⚠ DRAFT ONLY — Requires review and approval by a qualified Alvarez and Marsal professional before use.
A5: A. Source data (blue) with live calculations
A6: # | B6: Category | C6: Sub category | D6: Gross 26-Aug | E6: # Acc 26-Aug | F6: # Cust 26-Aug | G6: Gross 31-Jul | H6: # Acc 31-Jul | I6: # Cust 31-Jul | J6: Gross 30-Jun | K6: # Acc 30-Jun | L6: # Cust 30-Jun | M6: Gross 31-May | N6: MoM Aug vs Jul | O6: MoM Jul vs Jun | P6: MoM Jun vs May | Q6: 3M Aug vs May | R6: ATS Aug (₹ lakh) | S6: ATS Jul (₹ lakh) | T6: Acc per customer Aug | U6: Δ accounts Aug − Jul | V6: Δ customers Aug − Jul | W6: Share of Overall Aug | X6: Share of sub-total Aug | Y6: Share of Overall May | Z6: Share shift (pp) May → Aug | AA6: Contribution to 3M Overall growth
A7: 1 | B7: Overall | C7: Overall Advances | D7: 126108.71 | E7: 6003330 | F7: 5757648 | G7: 119273.32 | H7: 5904324 | I7: 5676691 | J7: 117318.52 | K7: 5926228 | L7: 5700683 | M7: 114456.96 | N7: =IF(OR(D7="",G7="",G7=0),"n/a",D7/G7-1) -> 0.057308625 | O7: =IF(OR(G7="",J7="",J7=0),"n/a",G7/J7-1) -> 0.016662331 | P7: =IF(OR(J7="",M7="",M7=0),"n/a",J7/M7-1) -> 0.025001188 | Q7: =IF(OR(D7="",M7="",M7=0),"n/a",D7/M7-1) -> 0.10180027 | R7: =IF(OR(E7="",E7=0),"",D7*100/E7) -> 2.100646 | S7: =IF(OR(H7="",H7=0),"",G7*100/H7) -> 2.0201012 | T7: =IF(OR(F7="",F7=0),"",E7/F7) -> 1.0426705 | U7: =IF(OR(E7="",H7=""),"",E7-H7) -> 99006 | V7: =IF(OR(F7="",I7=""),"",F7-I7) -> 80957 | W7: =IF(D7="","",D7/$D$7) -> 1 | Y7: =IF(M7="","",M7/$M$7) -> 1 | Z7: =IF(OR(D7="",M7=""),"",(W7-Y7)*100) -> 0 | AA7: =IF(OR(D7="",M7=""),"",(D7-M7)/($D$7-$M$7)) -> 1
A8: 2 | B8: Wholesale | C8: Sub Total | D8: 53873.7 | E8: 3135 | F8: 1219 | G8: 52230.94 | H8: 3110 | I8: 1204 | J8: 51322.63 | K8: 3024 | L8: 1206 | M8: 46483.02 | N8: =IF(OR(D8="",G8="",G8=0),"n/a",D8/G8-1) -> 0.031451856 | O8: =IF(OR(G8="",J8="",J8=0),"n/a",G8/J8-1) -> 0.017698041 | P8: =IF(OR(J8="",M8="",M8=0),"n/a",J8/M8-1) -> 0.10411565 | Q8: =IF(OR(D8="",M8="",M8=0),"n/a",D8/M8-1) -> 0.15899741 | R8: =IF(OR(E8="",E8=0),"",D8*100/E8) -> 1718.4593 | S8: =IF(OR(H8="",H8=0),"",G8*100/H8) -> 1679.4514 | T8: =IF(OR(F8="",F8=0),"",E8/F8) -> 2.5717801 | U8: =IF(OR(E8="",H8=""),"",E8-H8) -> 25 | V8: =IF(OR(F8="",I8=""),"",F8-I8) -> 15 | W8: =IF(D8="","",D8/$D$7) -> 0.42720047 | X8: =IF(D8="","",D8/$D$8) -> 1 | Y8: =IF(M8="","",M8/$M$7) -> 0.4061179 | Z8: =IF(OR(D8="",M8=""),"",(W8-Y8)*100) -> 2.1082571 | AA8: =IF(OR(D8="",M8=""),"",(D8-M8)/($D$7-$M$7)) -> 0.63429785
A9: 3 | B9: Wholesale | C9: C&IB Agri | N9: =IF(OR(D9="",G9="",G9=0),"n/a",D9/G9-1) -> n/a | O9: =IF(OR(G9="",J9="",J9=0),"n/a",G9/J9-1) -> n/a | P9: =IF(OR(J9="",M9="",M9=0),"n/a",J9/M9-1) -> n/a | Q9: =IF(OR(D9="",M9="",M9=0),"n/a",D9/M9-1) -> n/a | R9: =IF(OR(E9="",E9=0),"",D9*100/E9) | S9: =IF(OR(H9="",H9=0),"",G9*100/H9) | T9: =IF(OR(F9="",F9=0),"",E9/F9) | U9: =IF(OR(E9="",H9=""),"",E9-H9) | V9: =IF(OR(F9="",I9=""),"",F9-I9) | W9: =IF(D9="","",D9/$D$7) | X9: =IF(D9="","",D9/$D$8) | Y9: =IF(M9="","",M9/$M$7) | Z9: =IF(OR(D9="",M9=""),"",(W9-Y9)*100) | AA9: =IF(OR(D9="",M9=""),"",(D9-M9)/($D$7-$M$7))
A10: 4 | B10: Wholesale | C10: CB (incl Agri & NE) | D10: 15715.13 | E10: 1507 | F10: 469 | G10: 14955.87 | H10: 1515 | I10: 472 | J10: 15090.59 | K10: 1497 | L10: 480 | M10: 13723.25 | N10: =IF(OR(D10="",G10="",G10=0),"n/a",D10/G10-1) -> 0.050766689 | O10: =IF(OR(G10="",J10="",J10=0),"n/a",G10/J10-1) -> -0.0089274177 | P10: =IF(OR(J10="",M10="",M10=0),"n/a",J10/M10-1) -> 0.099636748 | Q10: =IF(OR(D10="",M10="",M10=0),"n/a",D10/M10-1) -> 0.14514638 | R10: =IF(OR(E10="",E10=0),"",D10*100/E10) -> 1042.8089 | S10: =IF(OR(H10="",H10=0),"",G10*100/H10) -> 987.18614 | T10: =IF(OR(F10="",F10=0),"",E10/F10) -> 3.2132196 | U10: =IF(OR(E10="",H10=""),"",E10-H10) -> -8 | V10: =IF(OR(F10="",I10=""),"",F10-I10) -> -3 | W10: =IF(D10="","",D10/$D$7) -> 0.12461574 | X10: =IF(D10="","",D10/$D$8) -> 0.29170319 | Y10: =IF(M10="","",M10/$M$7) -> 0.11989878 | Z10: =IF(OR(D10="",M10=""),"",(W10-Y10)*100) -> 0.47169571 | AA10: =IF(OR(D10="",M10=""),"",(D10-M10)/($D$7-$M$7)) -> 0.17095114
A11: 5 | B11: Wholesale | C11: CB- BBG | D11: 147.84 | E11: 36 | F11: 6 | G11: 137.84 | H11: 25 | I11: 4 | J11: 149.81 | K11: 24 | L11: 4 | M11: 140.64 | N11: =IF(OR(D11="",G11="",G11=0),"n/a",D11/G11-1) -> 0.072547882 | O11: =IF(OR(G11="",J11="",J11=0),"n/a",G11/J11-1) -> -0.079901208 | P11: =IF(OR(J11="",M11="",M11=0),"n/a",J11/M11-1) -> 0.065201934 | Q11: =IF(OR(D11="",M11="",M11=0),"n/a",D11/M11-1) -> 0.051194539 | R11: =IF(OR(E11="",E11=0),"",D11*100/E11) -> 410.66667 | S11: =IF(OR(H11="",H11=0),"",G11*100/H11) -> 551.36 | T11: =IF(OR(F11="",F11=0),"",E11/F11) -> 6 | U11: =IF(OR(E11="",H11=""),"",E11-H11) -> 11 | V11: =IF(OR(F11="",I11=""),"",F11-I11) -> 2 | W11: =IF(D11="","",D11/$D$7) -> 0.0011723219 | X11: =IF(D11="","",D11/$D$8) -> 0.0027441961 | Y11: =IF(M11="","",M11/$M$7) -> 0.0012287588 | Z11: =IF(OR(D11="",M11=""),"",(W11-Y11)*100) -> -0.0056436948 | AA11: =IF(OR(D11="",M11=""),"",(D11-M11)/($D$7-$M$7)) -> 0.00061793293
A12: 6 | B12: Wholesale | C12: Corporate Banking (incl G&J) | D12: 23736.16 | E12: 853 | F12: 303 | G12: 22103.54 | H12: 867 | I12: 294 | J12: 22066.31 | K12: 841 | L12: 296 | M12: 20247.46 | N12: =IF(OR(D12="",G12="",G12=0),"n/a",D12/G12-1) -> 0.073862377 | O12: =IF(OR(G12="",J12="",J12=0),"n/a",G12/J12-1) -> 0.0016871874 | P12: =IF(OR(J12="",M12="",M12=0),"n/a",J12/M12-1) -> 0.089831021 | Q12: =IF(OR(D12="",M12="",M12=0),"n/a",D12/M12-1) -> 0.17230309 | R12: =IF(OR(E12="",E12=0),"",D12*100/E12) -> 2782.6682 | S12: =IF(OR(H12="",H12=0),"",G12*100/H12) -> 2549.4279 | T12: =IF(OR(F12="",F12=0),"",E12/F12) -> 2.8151815 | U12: =IF(OR(E12="",H12=""),"",E12-H12) -> -14 | V12: =IF(OR(F12="",I12=""),"",F12-I12) -> 9 | W12: =IF(D12="","",D12/$D$7) -> 0.18821983 | X12: =IF(D12="","",D12/$D$8) -> 0.44058901 | Y12: =IF(M12="","",M12/$M$7) -> 0.17690021 | Z12: =IF(OR(D12="",M12=""),"",(W12-Y12)*100) -> 1.1319623 | AA12: =IF(OR(D12="",M12=""),"",(D12-M12)/($D$7-$M$7)) -> 0.29941425
A13: 7 | B13: Wholesale | C13: FI | D13: 8259.59 | E13: 132 | F13: 49 | G13: 8755.24 | H13: 127 | I13: 48 | J13: 8204.68 | K13: 117 | L13: 43 | M13: 7053.03 | N13: =IF(OR(D13="",G13="",G13=0),"n/a",D13/G13-1) -> -0.056611812 | O13: =IF(OR(G13="",J13="",J13=0),"n/a",G13/J13-1) -> 0.067103166 | P13: =IF(OR(J13="",M13="",M13=0),"n/a",J13/M13-1) -> 0.16328443 | Q13: =IF(OR(D13="",M13="",M13=0),"n/a",D13/M13-1) -> 0.17106974 | R13: =IF(OR(E13="",E13=0),"",D13*100/E13) -> 6257.2652 | S13: =IF(OR(H13="",H13=0),"",G13*100/H13) -> 6893.8898 | T13: =IF(OR(F13="",F13=0),"",E13/F13) -> 2.6938776 | U13: =IF(OR(E13="",H13=""),"",E13-H13) -> 5 | V13: =IF(OR(F13="",I13=""),"",F13-I13) -> 1 | W13: =IF(D13="","",D13/$D$7) -> 0.065495793 | X13: =IF(D13="","",D13/$D$8) -> 0.15331395 | Y13: =IF(M13="","",M13/$M$7) -> 0.061621679 | Z13: =IF(OR(D13="",M13=""),"",(W13-Y13)*100) -> 0.38741147 | AA13: =IF(OR(D13="",M13=""),"",(D13-M13)/($D$7-$M$7)) -> 0.10355183
A14: 8 | B14: Wholesale | C14: FIGU- BBB | D14: 2.18 | E14: 1 | F14: 1 | G14: 3 | H14: 1 | I14: 1 | J14: 0.3 | K14: 1 | L14: 1 | M14: 5.61 | N14: =IF(OR(D14="",G14="",G14=0),"n/a",D14/G14-1) -> -0.27333333 | O14: =IF(OR(G14="",J14="",J14=0),"n/a",G14/J14-1) -> 9 | P14: =IF(OR(J14="",M14="",M14=0),"n/a",J14/M14-1) -> -0.94652406 | Q14: =IF(OR(D14="",M14="",M14=0),"n/a",D14/M14-1) -> -0.6114082 | R14: =IF(OR(E14="",E14=0),"",D14*100/E14) -> 218 | S14: =IF(OR(H14="",H14=0),"",G14*100/H14) -> 300 | T14: =IF(OR(F14="",F14=0),"",E14/F14) -> 1 | U14: =IF(OR(E14="",H14=""),"",E14-H14) -> 0 | V14: =IF(OR(F14="",I14=""),"",F14-I14) -> 0 | W14: =IF(D14="","",D14/$D$7) -> 1.7286673e-05 | X14: =IF(D14="","",D14/$D$8) -> 4.0465014e-05 | Y14: =IF(M14="","",M14/$M$7) -> 4.9014057e-05 | Z14: =IF(OR(D14="",M14=""),"",(W14-Y14)*100) -> -0.0031727385 | AA14: =IF(OR(D14="",M14=""),"",(D14-M14)/($D$7-$M$7)) -> -0.00029437638
A15: 9 | B15: Wholesale | C15: Govt. Banking | D15: 190.06 | E15: 7 | F15: 2 | G15: 369 | H15: 1 | I15: 1 | N15: =IF(OR(D15="",G15="",G15=0),"n/a",D15/G15-1) -> -0.48493225 | O15: =IF(OR(G15="",J15="",J15=0),"n/a",G15/J15-1) -> n/a | P15: =IF(OR(J15="",M15="",M15=0),"n/a",J15/M15-1) -> n/a | Q15: =IF(OR(D15="",M15="",M15=0),"n/a",D15/M15-1) -> n/a | R15: =IF(OR(E15="",E15=0),"",D15*100/E15) -> 2715.1429 | S15: =IF(OR(H15="",H15=0),"",G15*100/H15) -> 36900 | T15: =IF(OR(F15="",F15=0),"",E15/F15) -> 3.5 | U15: =IF(OR(E15="",H15=""),"",E15-H15) -> 6 | V15: =IF(OR(F15="",I15=""),"",F15-I15) -> 1 | W15: =IF(D15="","",D15/$D$7) -> 0.0015071124 | X15: =IF(D15="","",D15/$D$8) -> 0.003527881 | Y15: =IF(M15="","",M15/$M$7) | Z15: =IF(OR(D15="",M15=""),"",(W15-Y15)*100) | AA15: =IF(OR(D15="",M15=""),"",(D15-M15)/($D$7-$M$7))
A16: 10 | B16: Wholesale | C16: IFI | D16: 3876.27 | E16: 118 | F16: 35 | G16: 4010.12 | H16: 119 | I16: 35 | J16: 4007.99 | K16: 112 | L16: 35 | M16: 3540.73 | N16: =IF(OR(D16="",G16="",G16=0),"n/a",D16/G16-1) -> -0.033378054 | O16: =IF(OR(G16="",J16="",J16=0),"n/a",G16/J16-1) -> 0.00053143845 | P16: =IF(OR(J16="",M16="",M16=0),"n/a",J16/M16-1) -> 0.13196714 | Q16: =IF(OR(D16="",M16="",M16=0),"n/a",D16/M16-1) -> 0.094765769 | R16: =IF(OR(E16="",E16=0),"",D16*100/E16) -> 3284.9746 | S16: =IF(OR(H16="",H16=0),"",G16*100/H16) -> 3369.8487 | T16: =IF(OR(F16="",F16=0),"",E16/F16) -> 3.3714286 | U16: =IF(OR(E16="",H16=""),"",E16-H16) -> -1 | V16: =IF(OR(F16="",I16=""),"",F16-I16) -> 0 | W16: =IF(D16="","",D16/$D$7) -> 0.030737528 | X16: =IF(D16="","",D16/$D$8) -> 0.071951063 | Y16: =IF(M16="","",M16/$M$7) -> 0.030935034 | Z16: =IF(OR(D16="",M16=""),"",(W16-Y16)*100) -> -0.019750648 | AA16: =IF(OR(D16="",M16=""),"",(D16-M16)/($D$7-$M$7)) -> 0.028797391
A17: 11 | B17: Wholesale | C17: MNC | D17: 172.31 | E17: 11 | F17: 8 | G17: 189.6 | H17: 10 | I17: 7 | J17: 145.08 | K17: 11 | L17: 9 | M17: 99.24 | N17: =IF(OR(D17="",G17="",G17=0),"n/a",D17/G17-1) -> -0.091191983 | O17: =IF(OR(G17="",J17="",J17=0),"n/a",G17/J17-1) -> 0.30686518 | P17: =IF(OR(J17="",M17="",M17=0),"n/a",J17/M17-1) -> 0.46191052 | Q17: =IF(OR(D17="",M17="",M17=0),"n/a",D17/M17-1) -> 0.73629585 | R17: =IF(OR(E17="",E17=0),"",D17*100/E17) -> 1566.4545 | S17: =IF(OR(H17="",H17=0),"",G17*100/H17) -> 1896 | T17: =IF(OR(F17="",F17=0),"",E17/F17) -> 1.375 | U17: =IF(OR(E17="",H17=""),"",E17-H17) -> 1 | V17: =IF(OR(F17="",I17=""),"",F17-I17) -> 1 | W17: =IF(D17="","",D17/$D$7) -> 0.0013663608 | X17: =IF(D17="","",D17/$D$8) -> 0.0031984066 | Y17: =IF(M17="","",M17/$M$7) -> 0.00086705081 | Z17: =IF(OR(D17="",M17=""),"",(W17-Y17)*100) -> 0.049931001 | AA17: =IF(OR(D17="",M17=""),"",(D17-M17)/($D$7-$M$7)) -> 0.006271161
A18: 12 | B18: Wholesale | C18: Supply Chain | D18: 1774.16 | E18: 470 | F18: 346 | G18: 1706.73 | H18: 445 | I18: 342 | J18: 1657.86 | K18: 421 | L18: 338 | M18: 1673.06 | N18: =IF(OR(D18="",G18="",G18=0),"n/a",D18/G18-1) -> 0.039508299 | O18: =IF(OR(G18="",J18="",J18=0),"n/a",G18/J18-1) -> 0.02947776 | P18: =IF(OR(J18="",M18="",M18=0),"n/a",J18/M18-1) -> -0.0090851494 | Q18: =IF(OR(D18="",M18="",M18=0),"n/a",D18/M18-1) -> 0.060428197 | R18: =IF(OR(E18="",E18=0),"",D18*100/E18) -> 377.48085 | S18: =IF(OR(H18="",H18=0),"",G18*100/H18) -> 383.53483 | T18: =IF(OR(F18="",F18=0),"",E18/F18) -> 1.3583815 | U18: =IF(OR(E18="",H18=""),"",E18-H18) -> 25 | V18: =IF(OR(F18="",I18=""),"",F18-I18) -> 4 | W18: =IF(D18="","",D18/$D$7) -> 0.014068497 | X18: =IF(D18="","",D18/$D$8) -> 0.032931839 | Y18: =IF(M18="","",M18/$M$7) -> 0.014617372 | Z18: =IF(OR(D18="",M18=""),"",(W18-Y18)*100) -> -0.05488754 | AA18: =IF(OR(D18="",M18=""),"",(D18-M18)/($D$7-$M$7)) -> 0.0086768082
A19: 13 | B19: Wholesale | C19: Retail - Others | N19: =IF(OR(D19="",G19="",G19=0),"n/a",D19/G19-1) -> n/a | O19: =IF(OR(G19="",J19="",J19=0),"n/a",G19/J19-1) -> n/a | P19: =IF(OR(J19="",M19="",M19=0),"n/a",J19/M19-1) -> n/a | Q19: =IF(OR(D19="",M19="",M19=0),"n/a",D19/M19-1) -> n/a | R19: =IF(OR(E19="",E19=0),"",D19*100/E19) | S19: =IF(OR(H19="",H19=0),"",G19*100/H19) | T19: =IF(OR(F19="",F19=0),"",E19/F19) | U19: =IF(OR(E19="",H19=""),"",E19-H19) | V19: =IF(OR(F19="",I19=""),"",F19-I19) | W19: =IF(D19="","",D19/$D$7) | X19: =IF(D19="","",D19/$D$8) | Y19: =IF(M19="","",M19/$M$7) | Z19: =IF(OR(D19="",M19=""),"",(W19-Y19)*100) | AA19: =IF(OR(D19="",M19=""),"",(D19-M19)/($D$7-$M$7))
A20: 14 | B20: Retail Lending | C20: Sub Total | D20: 27619.34 | E20: 245245 | F20: 222235 | G20: 27885.39 | H20: 245901 | I20: 222807 | J20: 27831.05 | K20: 243630 | L20: 220817 | M20: 27521.35 | N20: =IF(OR(D20="",G20="",G20=0),"n/a",D20/G20-1) -> -0.0095408384 | O20: =IF(OR(G20="",J20="",J20=0),"n/a",G20/J20-1) -> 0.0019524955 | P20: =IF(OR(J20="",M20="",M20=0),"n/a",J20/M20-1) -> 0.011253082 | Q20: =IF(OR(D20="",M20="",M20=0),"n/a",D20/M20-1) -> 0.0035605085 | R20: =IF(OR(E20="",E20=0),"",D20*100/E20) -> 11.261938 | S20: =IF(OR(H20="",H20=0),"",G20*100/H20) -> 11.340088 | T20: =IF(OR(F20="",F20=0),"",E20/F20) -> 1.103539 | U20: =IF(OR(E20="",H20=""),"",E20-H20) -> -656 | V20: =IF(OR(F20="",I20=""),"",F20-I20) -> -572 | W20: =IF(D20="","",D20/$D$7) -> 0.21901215 | X20: =IF(D20="","",D20/$D$20) -> 1 | Y20: =IF(M20="","",M20/$M$7) -> 0.24045152 | Z20: =IF(OR(D20="",M20=""),"",(W20-Y20)*100) -> -2.1439368 | AA20: =IF(OR(D20="",M20=""),"",(D20-M20)/($D$7-$M$7)) -> 0.0084098955
A21: 15 | B21: Retail Lending | C21: Affordable Housing | D21: 2606.15 | E21: 17561 | F21: 10130 | G21: 2585.66 | H21: 17290 | I21: 10095 | J21: 2509.03 | K21: 16721 | L21: 9887 | M21: 2434.39 | N21: =IF(OR(D21="",G21="",G21=0),"n/a",D21/G21-1) -> 0.0079244758 | O21: =IF(OR(G21="",J21="",J21=0),"n/a",G21/J21-1) -> 0.030541683 | P21: =IF(OR(J21="",M21="",M21=0),"n/a",J21/M21-1) -> 0.030660658 | Q21: =IF(OR(D21="",M21="",M21=0),"n/a",D21/M21-1) -> 0.070555663 | R21: =IF(OR(E21="",E21=0),"",D21*100/E21) -> 14.840556 | S21: =IF(OR(H21="",H21=0),"",G21*100/H21) -> 14.954656 | T21: =IF(OR(F21="",F21=0),"",E21/F21) -> 1.7335637 | U21: =IF(OR(E21="",H21=""),"",E21-H21) -> 271 | V21: =IF(OR(F21="",I21=""),"",F21-I21) -> 35 | W21: =IF(D21="","",D21/$D$7) -> 0.0206659 | X21: =IF(D21="","",D21/$D$20) -> 0.094359605 | Y21: =IF(M21="","",M21/$M$7) -> 0.021269043 | Z21: =IF(OR(D21="",M21=""),"",(W21-Y21)*100) -> -0.060314289 | AA21: =IF(OR(D21="",M21=""),"",(D21-M21)/($D$7-$M$7)) -> 0.014741133
A22: 16 | B22: Retail Lending | C22: Prime Housing | D22: 4271.99 | E22: 7912 | F22: 5816 | G22: 4300.78 | H22: 7907 | I22: 5829 | J22: 4324.98 | K22: 7926 | L22: 5859 | M22: 4339.7 | N22: =IF(OR(D22="",G22="",G22=0),"n/a",D22/G22-1) -> -0.0066941346 | O22: =IF(OR(G22="",J22="",J22=0),"n/a",G22/J22-1) -> -0.0055954016 | P22: =IF(OR(J22="",M22="",M22=0),"n/a",J22/M22-1) -> -0.0033919395 | Q22: =IF(OR(D22="",M22="",M22=0),"n/a",D22/M22-1) -> -0.015602461 | R22: =IF(OR(E22="",E22=0),"",D22*100/E22) -> 53.993807 | S22: =IF(OR(H22="",H22=0),"",G22*100/H22) -> 54.392058 | T22: =IF(OR(F22="",F22=0),"",E22/F22) -> 1.3603851 | U22: =IF(OR(E22="",H22=""),"",E22-H22) -> 5 | V22: =IF(OR(F22="",I22=""),"",F22-I22) -> -13 | W22: =IF(D22="","",D22/$D$7) -> 0.033875456 | X22: =IF(D22="","",D22/$D$20) -> 0.15467386 | Y22: =IF(M22="","",M22/$M$7) -> 0.037915562 | Z22: =IF(OR(D22="",M22=""),"",(W22-Y22)*100) -> -0.40401068 | AA22: =IF(OR(D22="",M22=""),"",(D22-M22)/($D$7-$M$7)) -> -0.0058111442
A23: 17 | B23: Retail Lending | C23: Housing Loan CL | D23: 1232.25 | E23: 4074 | F23: 4042 | G23: 1232.04 | H23: 4059 | I23: 4024 | J23: 1222.04 | K23: 3994 | L23: 3959 | M23: 1223.45 | N23: =IF(OR(D23="",G23="",G23=0),"n/a",D23/G23-1) -> 0.00017044901 | O23: =IF(OR(G23="",J23="",J23=0),"n/a",G23/J23-1) -> 0.0081830382 | P23: =IF(OR(J23="",M23="",M23=0),"n/a",J23/M23-1) -> -0.0011524786 | Q23: =IF(OR(D23="",M23="",M23=0),"n/a",D23/M23-1) -> 0.0071927745 | R23: =IF(OR(E23="",E23=0),"",D23*100/E23) -> 30.246686 | S23: =IF(OR(H23="",H23=0),"",G23*100/H23) -> 30.353289 | T23: =IF(OR(F23="",F23=0),"",E23/F23) -> 1.0079169 | U23: =IF(OR(E23="",H23=""),"",E23-H23) -> 15 | V23: =IF(OR(F23="",I23=""),"",F23-I23) -> 18 | W23: =IF(D23="","",D23/$D$7) -> 0.0097713314 | X23: =IF(D23="","",D23/$D$20) -> 0.044615476 | Y23: =IF(M23="","",M23/$M$7) -> 0.010689171 | Z23: =IF(OR(D23="",M23=""),"",(W23-Y23)*100) -> -0.091783943 | AA23: =IF(OR(D23="",M23=""),"",(D23-M23)/($D$7-$M$7)) -> 0.00075525136
A24: 18 | B24: Retail Lending | C24: Housing Loan DA | D24: 938.53 | E24: 6920 | F24: 5849 | G24: 954.73 | H24: 6796 | I24: 5718 | J24: 913.49 | K24: 6876 | L24: 5788 | M24: 929.54 | N24: =IF(OR(D24="",G24="",G24=0),"n/a",D24/G24-1) -> -0.016968148 | O24: =IF(OR(G24="",J24="",J24=0),"n/a",G24/J24-1) -> 0.045145541 | P24: =IF(OR(J24="",M24="",M24=0),"n/a",J24/M24-1) -> -0.017266605 | Q24: =IF(OR(D24="",M24="",M24=0),"n/a",D24/M24-1) -> 0.0096714504 | R24: =IF(OR(E24="",E24=0),"",D24*100/E24) -> 13.562572 | S24: =IF(OR(H24="",H24=0),"",G24*100/H24) -> 14.048411 | T24: =IF(OR(F24="",F24=0),"",E24/F24) -> 1.1831082 | U24: =IF(OR(E24="",H24=""),"",E24-H24) -> 124 | V24: =IF(OR(F24="",I24=""),"",F24-I24) -> 131 | W24: =IF(D24="","",D24/$D$7) -> 0.0074422298 | X24: =IF(D24="","",D24/$D$20) -> 0.033980899 | Y24: =IF(M24="","",M24/$M$7) -> 0.008121306 | Z24: =IF(OR(D24="",M24=""),"",(W24-Y24)*100) -> -0.067907623 | AA24: =IF(OR(D24="",M24=""),"",(D24-M24)/($D$7-$M$7)) -> 0.00077155792
A25: 19 | B25: Retail Lending | C25: Small LAP | D25: 1027.29 | E25: 4551 | F25: 4379 | G25: 1023.28 | H25: 4531 | I25: 4361 | J25: 999.47 | K25: 4413 | L25: 4257 | M25: 970.12 | N25: =IF(OR(D25="",G25="",G25=0),"n/a",D25/G25-1) -> 0.003918771 | O25: =IF(OR(G25="",J25="",J25=0),"n/a",G25/J25-1) -> 0.023822626 | P25: =IF(OR(J25="",M25="",M25=0),"n/a",J25/M25-1) -> 0.030253989 | Q25: =IF(OR(D25="",M25="",M25=0),"n/a",D25/M25-1) -> 0.058930854 | R25: =IF(OR(E25="",E25=0),"",D25*100/E25) -> 22.572841 | S25: =IF(OR(H25="",H25=0),"",G25*100/H25) -> 22.583977 | T25: =IF(OR(F25="",F25=0),"",E25/F25) -> 1.0392784 | U25: =IF(OR(E25="",H25=""),"",E25-H25) -> 20 | V25: =IF(OR(F25="",I25=""),"",F25-I25) -> 18 | W25: =IF(D25="","",D25/$D$7) -> 0.008146067 | X25: =IF(D25="","",D25/$D$20) -> 0.037194589 | Y25: =IF(M25="","",M25/$M$7) -> 0.0084758498 | Z25: =IF(OR(D25="",M25=""),"",(W25-Y25)*100) -> -0.032978279 | AA25: =IF(OR(D25="",M25=""),"",(D25-M25)/($D$7-$M$7)) -> 0.0049065591
A26: 20 | B26: Retail Lending | C26: Prime LAP | D26: 10457.71 | E26: 7237 | F26: 5799 | G26: 10517.4 | H26: 7256 | I26: 5825 | J26: 10382.9 | K26: 7181 | L26: 5774 | M26: 10045.12 | N26: =IF(OR(D26="",G26="",G26=0),"n/a",D26/G26-1) -> -0.005675357 | O26: =IF(OR(G26="",J26="",J26=0),"n/a",G26/J26-1) -> 0.012953992 | P26: =IF(OR(J26="",M26="",M26=0),"n/a",J26/M26-1) -> 0.033626278 | Q26: =IF(OR(D26="",M26="",M26=0),"n/a",D26/M26-1) -> 0.041073676 | R26: =IF(OR(E26="",E26=0),"",D26*100/E26) -> 144.50339 | S26: =IF(OR(H26="",H26=0),"",G26*100/H26) -> 144.94763 | T26: =IF(OR(F26="",F26=0),"",E26/F26) -> 1.2479738 | U26: =IF(OR(E26="",H26=""),"",E26-H26) -> -19 | V26: =IF(OR(F26="",I26=""),"",F26-I26) -> -26 | W26: =IF(D26="","",D26/$D$7) -> 0.082926152 | X26: =IF(D26="","",D26/$D$20) -> 0.37863722 | Y26: =IF(M26="","",M26/$M$7) -> 0.087763295 | Z26: =IF(OR(D26="",M26=""),"",(W26-Y26)*100) -> -0.48371439 | AA26: =IF(OR(D26="",M26=""),"",(D26-M26)/($D$7-$M$7)) -> 0.035410132
A27: 21 | B27: Retail Lending | C27: LAP - CL | D27: 467.39 | E27: 1257 | F27: 1226 | G27: 470.17 | H27: 1267 | I27: 1235 | J27: 477.59 | K27: 1276 | L27: 1244 | M27: 481.56 | N27: =IF(OR(D27="",G27="",G27=0),"n/a",D27/G27-1) -> -0.005912755 | O27: =IF(OR(G27="",J27="",J27=0),"n/a",G27/J27-1) -> -0.015536339 | P27: =IF(OR(J27="",M27="",M27=0),"n/a",J27/M27-1) -> -0.0082440402 | Q27: =IF(OR(D27="",M27="",M27=0),"n/a",D27/M27-1) -> -0.029425201 | R27: =IF(OR(E27="",E27=0),"",D27*100/E27) -> 37.182975 | S27: =IF(OR(H27="",H27=0),"",G27*100/H27) -> 37.108919 | T27: =IF(OR(F27="",F27=0),"",E27/F27) -> 1.0252855 | U27: =IF(OR(E27="",H27=""),"",E27-H27) -> -10 | V27: =IF(OR(F27="",I27=""),"",F27-I27) -> -9 | W27: =IF(D27="","",D27/$D$7) -> 0.0037062468 | X27: =IF(D27="","",D27/$D$20) -> 0.016922562 | Y27: =IF(M27="","",M27/$M$7) -> 0.0042073457 | Z27: =IF(OR(D27="",M27=""),"",(W27-Y27)*100) -> -0.050109894 | AA27: =IF(OR(D27="",M27=""),"",(D27-M27)/($D$7-$M$7)) -> -0.0012161263
A28: 22 | B28: Retail Lending | C28: LAP - DA | D28: 1936.94 | E28: 4748 | F28: 4513 | G28: 1981.52 | H28: 4731 | I28: 4493 | J28: 2017.01 | K28: 4781 | L28: 4546 | M28: 2023.02 | N28: =IF(OR(D28="",G28="",G28=0),"n/a",D28/G28-1) -> -0.02249788 | O28: =IF(OR(G28="",J28="",J28=0),"n/a",G28/J28-1) -> -0.017595352 | P28: =IF(OR(J28="",M28="",M28=0),"n/a",J28/M28-1) -> -0.002970806 | Q28: =IF(OR(D28="",M28="",M28=0),"n/a",D28/M28-1) -> -0.042550247 | R28: =IF(OR(E28="",E28=0),"",D28*100/E28) -> 40.794861 | S28: =IF(OR(H28="",H28=0),"",G28*100/H28) -> 41.883746 | T28: =IF(OR(F28="",F28=0),"",E28/F28) -> 1.0520718 | U28: =IF(OR(E28="",H28=""),"",E28-H28) -> 17 | V28: =IF(OR(F28="",I28=""),"",F28-I28) -> 20 | W28: =IF(D28="","",D28/$D$7) -> 0.015359288 | X28: =IF(D28="","",D28/$D$20) -> 0.070129844 | Y28: =IF(M28="","",M28/$M$7) -> 0.017674941 | Z28: =IF(OR(D28="",M28=""),"",(W28-Y28)*100) -> -0.23156528 | AA28: =IF(OR(D28="",M28=""),"",(D28-M28)/($D$7-$M$7)) -> -0.0073877315
A29: 23 | B29: Retail Lending | C29: BIL/SBL | D29: 37.18 | E29: 312 | F29: 308 | G29: 38.47 | H29: 318 | I29: 314 | J29: 39.29 | K29: 380 | L29: 378 | M29: 40.56 | N29: =IF(OR(D29="",G29="",G29=0),"n/a",D29/G29-1) -> -0.033532623 | O29: =IF(OR(G29="",J29="",J29=0),"n/a",G29/J29-1) -> -0.02087045 | P29: =IF(OR(J29="",M29="",M29=0),"n/a",J29/M29-1) -> -0.031311637 | Q29: =IF(OR(D29="",M29="",M29=0),"n/a",D29/M29-1) -> -0.083333333 | R29: =IF(OR(E29="",E29=0),"",D29*100/E29) -> 11.916667 | S29: =IF(OR(H29="",H29=0),"",G29*100/H29) -> 12.097484 | T29: =IF(OR(F29="",F29=0),"",E29/F29) -> 1.012987 | U29: =IF(OR(E29="",H29=""),"",E29-H29) -> -6 | V29: =IF(OR(F29="",I29=""),"",F29-I29) -> -6 | W29: =IF(D29="","",D29/$D$7) -> 0.000294825 | X29: =IF(D29="","",D29/$D$20) -> 0.0013461582 | Y29: =IF(M29="","",M29/$M$7) -> 0.00035436901 | Z29: =IF(OR(D29="",M29=""),"",(W29-Y29)*100) -> -0.0059544017 | AA29: =IF(OR(D29="",M29=""),"",(D29-M29)/($D$7-$M$7)) -> -0.00029008518
A30: 24 | B30: Retail Lending | C30: Gold Loan - BBB | D30: 1384.46 | E30: 24068 | F30: 19671 | G30: 1429.34 | H30: 24323 | I30: 19937 | J30: 1444.03 | K30: 24250 | L30: 19990 | M30: 1433.15 | N30: =IF(OR(D30="",G30="",G30=0),"n/a",D30/G30-1) -> -0.031399107 | O30: =IF(OR(G30="",J30="",J30=0),"n/a",G30/J30-1) -> -0.010172919 | P30: =IF(OR(J30="",M30="",M30=0),"n/a",J30/M30-1) -> 0.0075916687 | Q30: =IF(OR(D30="",M30="",M30=0),"n/a",D30/M30-1) -> -0.033974113 | R30: =IF(OR(E30="",E30=0),"",D30*100/E30) -> 5.7522852 | S30: =IF(OR(H30="",H30=0),"",G30*100/H30) -> 5.8764955 | T30: =IF(OR(F30="",F30=0),"",E30/F30) -> 1.223527 | U30: =IF(OR(E30="",H30=""),"",E30-H30) -> -255 | V30: =IF(OR(F30="",I30=""),"",F30-I30) -> -266 | W30: =IF(D30="","",D30/$D$7) -> 0.010978306 | X30: =IF(D30="","",D30/$D$20) -> 0.050126469 | Y30: =IF(M30="","",M30/$M$7) -> 0.012521301 | Z30: =IF(OR(D30="",M30=""),"",(W30-Y30)*100) -> -0.15429946 | AA30: =IF(OR(D30="",M30=""),"",(D30-M30)/($D$7-$M$7)) -> -0.0041787714
A31: 25 | B31: Retail Lending | C31: Gold Loan DA/CL | D31: 2724.28 | E31: 93084 | F31: 87000 | G31: 2819.96 | H31: 94484 | I31: 88089 | J31: 2968.42 | K31: 93898 | L31: 87257 | M31: 3066.17 | N31: =IF(OR(D31="",G31="",G31=0),"n/a",D31/G31-1) -> -0.033929559 | O31: =IF(OR(G31="",J31="",J31=0),"n/a",G31/J31-1) -> -0.050013138 | P31: =IF(OR(J31="",M31="",M31=0),"n/a",J31/M31-1) -> -0.031880163 | Q31: =IF(OR(D31="",M31="",M31=0),"n/a",D31/M31-1) -> -0.11150393 | R31: =IF(OR(E31="",E31=0),"",D31*100/E31) -> 2.9266899 | S31: =IF(OR(H31="",H31=0),"",G31*100/H31) -> 2.98459 | T31: =IF(OR(F31="",F31=0),"",E31/F31) -> 1.069931 | U31: =IF(OR(E31="",H31=""),"",E31-H31) -> -1400 | V31: =IF(OR(F31="",I31=""),"",F31-I31) -> -1089 | W31: =IF(D31="","",D31/$D$7) -> 0.021602632 | X31: =IF(D31="","",D31/$D$20) -> 0.09863668 | Y31: =IF(M31="","",M31/$M$7) -> 0.026788847 | Z31: =IF(OR(D31="",M31=""),"",(W31-Y31)*100) -> -0.51862155 | AA31: =IF(OR(D31="",M31=""),"",(D31-M31)/($D$7-$M$7)) -> -0.029342373
A33: B. Roll-up checks and the unseen remainder
A34: # | B34: Check | D34: 26-Aug | G34: 31-Jul | J34: 30-Jun | M34: 31-May
A35: 1 | B35: Σ Wholesale rows − Wholesale Sub Total (gross) | D35: =SUMIFS(D8:D31,$B$8:$B$31,"Wholesale",$C$8:$C$31,"<>Sub Total")-D8 -> 0 | G35: =SUMIFS(G8:G31,$B$8:$B$31,"Wholesale",$C$8:$C$31,"<>Sub Total")-G8 -> 0 | J35: =SUMIFS(J8:J31,$B$8:$B$31,"Wholesale",$C$8:$C$31,"<>Sub Total")-J8 -> -0.01 | M35: =SUMIFS(M8:M31,$B$8:$B$31,"Wholesale",$C$8:$C$31,"<>Sub Total")-M8 -> 0
A36: 2 | B36: Σ Wholesale rows − Sub Total (accounts) | E36: =SUMIFS(E8:E31,$B$8:$B$31,"Wholesale",$C$8:$C$31,"<>Sub Total")-E8 -> 0 | H36: =SUMIFS(H8:H31,$B$8:$B$31,"Wholesale",$C$8:$C$31,"<>Sub Total")-H8 -> 0 | K36: =SUMIFS(K8:K31,$B$8:$B$31,"Wholesale",$C$8:$C$31,"<>Sub Total")-K8 -> 0
A37: 3 | B37: Σ visible Retail Lending rows (gross) | D37: =SUMIFS(D8:D31,$B$8:$B$31,"Retail Lending",$C$8:$C$31,"<>Sub Total") -> 27084.17 | G37: =SUMIFS(G8:G31,$B$8:$B$31,"Retail Lending",$C$8:$C$31,"<>Sub Total") -> 27353.35 | J37: =SUMIFS(J8:J31,$B$8:$B$31,"Retail Lending",$C$8:$C$31,"<>Sub Total") -> 27298.25 | M37: =SUMIFS(M8:M31,$B$8:$B$31,"Retail Lending",$C$8:$C$31,"<>Sub Total") -> 26986.78
A38: 4 | B38: Retail Lending Sub Total − Σ visible rows (clipped rows, gross) | D38: =D20-SUMIFS(D8:D31,$B$8:$B$31,"Retail Lending",$C$8:$C$31,"<>Sub Total") -> 535.17 | G38: =G20-SUMIFS(G8:G31,$B$8:$B$31,"Retail Lending",$C$8:$C$31,"<>Sub Total") -> 532.04 | J38: =J20-SUMIFS(J8:J31,$B$8:$B$31,"Retail Lending",$C$8:$C$31,"<>Sub Total") -> 532.8 | M38: =M20-SUMIFS(M8:M31,$B$8:$B$31,"Retail Lending",$C$8:$C$31,"<>Sub Total") -> 534.57
A39: 5 | B39: Overall − Wholesale − Retail Lending = other retail (cards, micro, wheels, agri …) | D39: =D7-D8-D20 -> 44615.67 | G39: =G7-G8-G20 -> 39156.99 | J39: =J7-J8-J20 -> 38164.84 | M39: =M7-M8-M20 -> 40452.59
A40: 6 | B40: Other retail share of Overall | D40: =(D7-D8-D20)/D7 -> 0.35378738 | G40: =(G7-G8-G20)/G7 -> 0.3282963 | J40: =(J7-J8-J20)/J7 -> 0.32530959 | M40: =(M7-M8-M20)/M7 -> 0.35343058
A41: 7 | B41: Overall − Wholesale − Retail Lending (accounts) | E41: =E7-E8-E20 -> 5754950 | H41: =H7-H8-H20 -> 5655313 | K41: =K7-K8-K20 -> 5679574
A42: 8 | B42: Wholesale share of Overall (gross) | D42: =D8/D7 -> 0.42720047 | G42: =G8/G7 -> 0.43790967 | J42: =J8/J7 -> 0.43746401 | M42: =M8/M7 -> 0.4061179
...

Sheet B1_Metrics
A1: Gross advances by sub-category: notation and metrics
A2: Format: Notation → Exhaustive metrics table | Example column = live Excel formula on the block sheet (green = cross-sheet)
A3: ⚠ DRAFT ONLY — Requires review and approval by a qualified Alvarez and Marsal professional before use.
A5: Notation
B6: Symbol | C6: Meaning
B7: G(x,d) | C7: Gross advances ₹ Cr of row x at balance date d
B8: N(x,d) / C(x,d) | C8: Accounts / customers
B9: d | C9: 26-Aug-26, 31-Jul-26, 30-Jun-26, 31-May-26 (May: gross only)
B10: OV / W / RL | C10: Overall Advances / Wholesale Sub Total / Retail Lending Sub Total
B11: OR | C11: Other retail = OV − W − RL (rows not shown on the page)
B12: ATS | C12: G × 100 ÷ N, ₹ lakh
B13: APC | C13: Accounts per customer = N ÷ C
B14: g | C14: G(d) ÷ G(d−1) − 1; 3M = Aug ÷ May − 1
B15: sh | C15: G(x) ÷ OV
B16: Δ3M | C16: G(Aug) − G(May)
B17: Gross advances ₹ Cr; accounts and customers as counts; ATS ₹ lakh; growth in %.
A19: Exhaustive metrics table
A20: # | B20: Metric family | C20: Pipeline-ready metric | D20: Definition / formula | E20: Applies to | F20: Example
A21: 1 | B21: Fact lookup | C21: Row gross advances | D21: G(x,d) | E21: 25 rows × 4 dates | F21: ="Corporate Banking "&TEXT(B1_Gross_Advances!D12,"#,##0.00;-#,##0.00;0.00")&" / "&TEXT(B1_Gross_Advances!G12,"#,##0.00;-#,##0.00;0.00")&" / "&TEXT(B1_Gross_Advances!J12,"#,##0.00;-#,##0.00;0.00")&" / "&TEXT(B1_Gross_Advances!M12,"#,##0.00;-#,##0.00;0.00")&" (Aug / Jul / Jun / May)" -> Corporate Banking 23,736.16 / 22,103.54 / 22,066.31 / 20,247.46 (Aug / Jul / Jun / May)
A22: 2 | B22: Fact lookup | C22: Accounts and customers | D22: N(x,d), C(x,d) | E22: 25 × 3 | F22: ="Overall "&TEXT(B1_Gross_Advances!E7,"#,##0")&" / "&TEXT(B1_Gross_Advances!F7,"#,##0")&"; Wholesale "&TEXT(B1_Gross_Advances!E8,"#,##0")&" / "&TEXT(B1_Gross_Advances!F8,"#,##0") -> Overall 6,003,330 / 5,757,648; Wholesale 3,135 / 1,219
A23: 3 | B23: Roll-up check | C23: Wholesale rows to Sub Total | D23: Σ rows − W | E23: 4 dates (gross), 3 (accounts) | F23: =TEXT(B1_Gross_Advances!D35,"#,##0.00;-#,##0.00;0.00")&" / "&TEXT(B1_Gross_Advances!G35,"#,##0.00;-#,##0.00;0.00")&" / "&TEXT(B1_Gross_Advances!J35,"#,##0.00;-#,##0.00;0.00")&" / "&TEXT(B1_Gross_Advances!M35,"#,##0.00;-#,##0.00;0.00")&"; accounts "&TEXT(B1_Gross_Advances!E36,"#,##0")&" / "&TEXT(B1_Gross_Advances!H36,"#,##0")&" / "&TEXT(B1_Gross_Advances!K36,"#,##0") -> 0.00 / 0.00 / -0.01 / 0.00; accounts 0 / 0 / 0
A24: 4 | B24: Roll-up check | C24: Retail Lending visible rows | D24: Σ visible; RL − Σ visible (clipped) | E24: 4 dates | F24: ="visible "&TEXT(B1_Gross_Advances!D37,"#,##0.00;-#,##0.00;0.00")&" / "&TEXT(B1_Gross_Advances!G37,"#,##0.00;-#,##0.00;0.00")&" / "&TEXT(B1_Gross_Advances!J37,"#,##0.00;-#,##0.00;0.00")&" / "&TEXT(B1_Gross_Advances!M37,"#,##0.00;-#,##0.00;0.00")&"; clipped "&TEXT(B1_Gross_Advances!D38,"#,##0.00;-#,##0.00;0.00")&" / "&TEXT(B1_Gross_Advances!G38,"#,##0.00;-#,##0.00;0.00")&" / "&TEXT(B1_Gross_Advances!J38,"#,##0.00;-#,##0.00;0.00")&" / "&TEXT(B1_Gross_Advances!M38,"#,##0.00;-#,##0.00;0.00") -> visible 27,084.17 / 27,353.35 / 27,298.25 / 26,986.78; clipped 535.17 / 532.04 / 532.80 / 534.57
A25: 5 | B25: Volume aggregates | C25: Other retail (not shown) | D25: OR = OV − W − RL | E25: 4 dates | F25: =TEXT(B1_Gross_Advances!D39,"#,##0.00;-#,##0.00;0.00")&" / "&TEXT(B1_Gross_Advances!G39,"#,##0.00;-#,##0.00;0.00")&" / "&TEXT(B1_Gross_Advances!J39,"#,##0.00;-#,##0.00;0.00")&" / "&TEXT(B1_Gross_Advances!M39,"#,##0.00;-#,##0.00;0.00") -> 44,615.67 / 39,156.99 / 38,164.84 / 40,452.59
A26: 6 | B26: Volume aggregates | C26: Overall / W / RL by date | D26: G(OV), G(W), G(RL) | E26: 4 dates | F26: ="OV "&TEXT(B1_Gross_Advances!D7,"#,##0.00;-#,##0.00;0.00")&" / "&TEXT(B1_Gross_Advances!G7,"#,##0.00;-#,##0.00;0.00")&" / "&TEXT(B1_Gross_Advances!J7,"#,##0.00;-#,##0.00;0.00")&" / "&TEXT(B1_Gross_Advances!M7,"#,##0.00;-#,##0.00;0.00") -> OV 126,108.71 / 119,273.32 / 117,318.52 / 114,456.96
A27: 7 | B27: Growth & momentum | C27: MoM growth | D27: g by row | E27: 25 rows × 3 | F27: ="OV "&TEXT(B1_Gross_Advances!N7,"+0.0%;-0.0%;0.0%")&" / "&TEXT(B1_Gross_Advances!O7,"+0.0%;-0.0%;0.0%")&" / "&TEXT(B1_Gross_Advances!P7,"+0.0%;-0.0%;0.0%")&"; W "&TEXT(B1_Gross_Advances!N8,"+0.0%;-0.0%;0.0%")&" / "&TEXT(B1_Gross_Advances!O8,"+0.0%;-0.0%;0.0%")&" / "&TEXT(B1_Gross_Advances!P8,"+0.0%;-0.0%;0.0%")&"; RL "&TEXT(B1_Gross_Advances!N20,"+0.0%;-0.0%;0.0%")&" / "&TEXT(B1_Gross_Advances!O20,"+0.0%;-0.0%;0.0%")&" / "&TEXT(B1_Gross_Advances!P20,"+0.0%;-0.0%;0.0%")&" (Aug/Jul, Jul/Jun, Jun/May)" -> OV +5.7% / +1.7% / +2.5%; W +3.1% / +1.8% / +10.4%; RL -1.0% / +0.2% / +1.1% (Aug/Jul, Jul/Jun, Jun/May)
A28: 8 | B28: Growth & momentum | C28: 3-month growth | D28: Aug ÷ May − 1 | E28: 23 rows | F28: ="OV "&TEXT(B1_Gross_Advances!Q7,"+0.0%;-0.0%;0.0%")&"; W "&TEXT(B1_Gross_Advances!Q8,"+0.0%;-0.0%;0.0%")&"; RL "&TEXT(B1_Gross_Advances!Q20,"+0.0%;-0.0%;0.0%")&"; Corp "&TEXT(B1_Gross_Advances!Q12,"+0.0%;-0.0%;0.0%")&"; CB "&TEXT(B1_Gross_Advances!Q10,"+0.0%;-0.0%;0.0%")&"; FI "&TEXT(B1_Gross_Advances!Q13,"+0.0%;-0.0%;0.0%") -> OV +10.2%; W +15.9%; RL +0.4%; Corp +17.2%; CB +14.5%; FI +17.1%
A29: 9 | B29: Growth & momentum | C29: 3-month absolute change | D29: Δ3M | E29: 23 rows | F29: ="OV "&TEXT(B1_Gross_Advances!D7-B1_Gross_Advances!M7,"#,##0.00;-#,##0.00;0.00")&"; W "&TEXT(B1_Gross_Advances!D8-B1_Gross_Advances!M8,"#,##0.00;-#,##0.00;0.00")&"; OR "&TEXT(B1_Gross_Advances!D39-B1_Gross_Advances!M39,"#,##0.00;-#,##0.00;0.00") -> OV 11,651.75; W 7,390.68; OR 4,163.08
A30: 10 | B30: Growth & momentum | C30: Sub-category 3M growth (retail) | D30: Aug ÷ May − 1 | E30: 11 retail rows | F30: ="Affordable Housing "&TEXT(B1_Gross_Advances!Q21,"+0.0%;-0.0%;0.0%")&"; Prime LAP "&TEXT(B1_Gross_Advances!Q26,"+0.0%;-0.0%;0.0%")&"; Gold DA/CL "&TEXT(B1_Gross_Advances!Q31,"+0.0%;-0.0%;0.0%")&"; LAP DA "&TEXT(B1_Gross_Advances!Q28,"+0.0%;-0.0%;0.0%") -> Affordable Housing +7.1%; Prime LAP +4.1%; Gold DA/CL -11.2%; LAP DA -4.3%
A31: 11 | B31: Growth & momentum | C31: Account growth MoM | D31: N(Aug) − N(Jul) | E31: 25 rows | F31: ="OV "&TEXT(B1_Gross_Advances!U7,"#,##0")&"; Gold DA/CL "&TEXT(B1_Gross_Advances!U31,"#,##0")&"; Affordable Housing "&TEXT(B1_Gross_Advances!U21,"#,##0") -> OV 99,006; Gold DA/CL -1,400; Affordable Housing 271
A32: 12 | B32: Attribution | C32: Contribution to 3M Overall growth | D32: Δ3M(x) ÷ Δ3M(OV) | E32: 23 rows + OR | F32: ="W "&TEXT(B1_Gross_Advances!AA8,"0.0%")&"; RL "&TEXT(B1_Gross_Advances!AA20,"0.0%")&"; OR "&TEXT((B1_Gross_Advances!D39-B1_Gross_Advances!M39)/(B1_Gross_Advances!D7-B1_Gross_Advances!M7),"0.0%")&"; Corp "&TEXT(B1_Gross_Advances!AA12,"0.0%") -> W 63.4%; RL 0.8%; OR 35.7%; Corp 29.9%
A33: 13 | B33: Mix & share | C33: Share of Overall | D33: sh(x, Aug) | E33: 25 rows | F33: ="W "&TEXT(B1_Gross_Advances!W8,"0.0%")&"; RL "&TEXT(B1_Gross_Advances!W20,"0.0%")&"; OR "&TEXT(B1_Gross_Advances!D40,"0.0%")&"; Corp "&TEXT(B1_Gross_Advances!W12,"0.0%")&"; Prime LAP "&TEXT(B1_Gross_Advances!W26,"0.0%") -> W 42.7%; RL 21.9%; OR 35.4%; Corp 18.8%; Prime LAP 8.3%
A34: 14 | B34: Mix & share | C34: Share of sub-total | D34: G(x) ÷ G(W or RL) | E34: 20 rows | F34: ="Corp in W "&TEXT(B1_Gross_Advances!X12,"0.0%")&"; CB in W "&TEXT(B1_Gross_Advances!X10,"0.0%")&"; Prime LAP in RL "&TEXT(B1_Gross_Advances!X26,"0.0%") -> Corp in W 44.1%; CB in W 29.2%; Prime LAP in RL 37.9%
A35: 15 | B35: Mix & share | C35: Share shift May → Aug | D35: (sh Aug − sh May) × 100 | E35: 23 rows | F35: ="W "&TEXT(B1_Gross_Advances!Z8,"+0.0"" pp"";-0.0"" pp"";0.0"" pp""")&"; RL "&TEXT(B1_Gross_Advances!Z20,"+0.0"" pp"";-0.0"" pp"";0.0"" pp""")&"; Corp "&TEXT(B1_Gross_Advances!Z12,"+0.0"" pp"";-0.0"" pp"";0.0"" pp""") -> W +2.1 pp; RL -2.1 pp; Corp +1.1 pp
A36: 16 | B36: Ticket size | C36: ATS by row | D36: ATS(x, Aug) | E36: 25 rows | F36: ="Corp "&TEXT(B1_Gross_Advances!R12,"#,##0.00")&"; CB "&TEXT(B1_Gross_Advances!R10,"#,##0.00")&"; Prime LAP "&TEXT(B1_Gross_Advances!R26,"#,##0.00")&"; Gold DA/CL "&TEXT(B1_Gross_Advances!R31,"#,##0.00")&" ₹ lakh" -> Corp 2,782.67; CB 1,042.81; Prime LAP 144.50; Gold DA/CL 2.93 ₹ lakh
A37: 17 | B37: Ticket size | C37: ATS by block | D37: OV / W / RL | E37: 3 dates | F37: ="OV "&TEXT(B1_Gross_Advances!D43,"#,##0.00")&" / "&TEXT(B1_Gross_Advances!G43,"#,##0.00")&" / "&TEXT(B1_Gross_Advances!J43,"#,##0.00")&"; W "&TEXT(B1_Gross_Advances!D44,"#,##0.00")&" / "&TEXT(B1_Gross_Advances!G44,"#,##0.00")&" / "&TEXT(B1_Gross_Advances!J44,"#,##0.00")&"; RL "&TEXT(B1_Gross_Advances!D45,"#,##0.00")&" / "&TEXT(B1_Gross_Advances!G45,"#,##0.00")&" / "&TEXT(B1_Gross_Advances!J45,"#,##0.00") -> OV 2.10 / 2.02 / 1.98; W 1,718.46 / 1,679.45 / 1,697.18; RL 11.26 / 11.34 / 11.42
A38: 18 | B38: Ticket size | C38: Accounts per customer | D38: APC(x, Aug) | E38: 25 rows | F38: ="OV "&TEXT(B1_Gross_Advances!T7,"0.00""x""")&"; W "&TEXT(B1_Gross_Advances!T8,"0.00""x""")&"; Gold DA/CL "&TEXT(B1_Gross_Advances!T31,"0.00""x""")&"; Affordable Housing "&TEXT(B1_Gross_Advances!T21,"0.00""x""") -> OV 1.04x; W 2.57x; Gold DA/CL 1.07x; Affordable Housing 1.73x
A39: 19 | B39: Concentration | C39: Top-2 wholesale rows share of W | D39: (Corp + CB) ÷ W | E39: Aug | F39: =TEXT((B1_Gross_Advances!D12+B1_Gross_Advances!D10)/B1_Gross_Advances!D8,"0.0%") -> 73.2%
A40: 20 | B40: Concentration | C40: Wholesale customers | D40: C(W) | E40: 3 dates | F40: =TEXT(B1_Gross_Advances!F8,"#,##0")&" / "&TEXT(B1_Gross_Advances!I8,"#,##0")&" / "&TEXT(B1_Gross_Advances!L8,"#,##0")&" customers hold "&TEXT(B1_Gross_Advances!W8,"0.0%")&" of gross" -> 1,219 / 1,204 / 1,206 customers hold 42.7% of gross
A41: 21 | B41: Cross-page | C41: Credit Portfolio Overview tie (Jul-26) | D41: CPO total − OV(31-Jul) | E41: 1 date | F41: =TEXT(B1_Gross_Advances!G46,"#,##0.00;-#,##0.00;0.00") -> 0.00
A42: 22 | B42: Cross-page | C42: Gross vs net (Jul-26) | D42: OV(31-Jul) − net funded 117,027 | E42: 1 date | F42: =TEXT(B1_Gross_Advances!G47,"#,##0.00;-#,##0.00;0.00") -> 2,246.32
...

Sheet B2_Liability_MEB
A1: Block 2 — Liability MEB by product at three dates
A2: Source: Overall Advances.pdf, 'Liability MEB' table | MEB ₹ Cr, # accounts, # customers | 30-Jun-26 customers clipped
A3: ⚠ DRAFT ONLY — Requires review and approval by a qualified Alvarez and Marsal professional before use.
A5: A. Source data (blue) with live calculations
A6: # | B6: Product | C6: MEB 26-Aug | D6: # Acc 26-Aug | E6: # Cust 26-Aug | F6: MEB 31-Jul | G6: # Acc 31-Jul | H6: # Cust 31-Jul | I6: MEB 30-Jun | J6: # Acc 30-Jun | K6: MoM Aug vs Jul | L6: MoM Jul vs Jun | M6: 2M Aug vs Jun | N6: Avg balance per account Aug (₹ lakh) | O6: Avg balance per account Jun (₹ lakh) | P6: Acc per customer Aug | Q6: Share of MEB Aug | R6: Share of MEB Jun | S6: Share shift (pp) Jun → Aug | T6: Contribution to 2M growth | U6: Δ accounts Aug − Jul
A7: 1 | B7: CA | C7: 6079.1 | D7: 158382 | E7: 149222 | F7: 6395.63 | G7: 157791 | H7: 148704 | I7: 6947.86 | J7: 162931 | K7: =C7/F7-1 -> -0.049491606 | L7: =F7/I7-1 -> -0.079482028 | M7: =C7/I7-1 -> -0.12503994 | N7: =C7*100/D7 -> 3.8382518 | O7: =I7*100/J7 -> 4.2642959 | P7: =D7/E7 -> 1.0613851 | Q7: =C7/$C$13 -> 0.05694599 | R7: =I7/$I$13 -> 0.083064476 | S7: =(Q7-R7)*100 -> -2.6118487 | T7: =(C7-I7)/($C$13-$I$13) -> -0.037595882 | U7: =D7-G7 -> 591
A8: 2 | B8: DEPOSITS | C8: 81230.06 | D8: 661190 | E8: 215707 | F8: 65244.74 | G8: 655678 | H8: 213983 | I8: 57566.67 | J8: 649558 | K8: =C8/F8-1 -> 0.2450055 | L8: =F8/I8-1 -> 0.133377 | M8: =C8/I8-1 -> 0.4110606 | N8: =C8*100/D8 -> 12.285434 | O8: =I8*100/J8 -> 8.8624372 | P8: =D8/E8 -> 3.0652227 | Q8: =C8/$C$13 -> 0.76092286 | R8: =I8/$I$13 -> 0.68823282 | S8: =(Q8-R8)*100 -> 7.2690039 | T8: =(C8-I8)/($C$13-$I$13) -> 1.0240412 | U8: =D8-G8 -> 5512
A9: 3 | B9: NR | C9: 3355.7 | D9: 92185 | E9: 57393 | F9: 3174.16 | G9: 91016 | H9: 56929 | I9: 2729.86 | J9: 90604 | K9: =C9/F9-1 -> 0.057193084 | L9: =F9/I9-1 -> 0.1627556 | M9: =C9/I9-1 -> 0.22925718 | N9: =C9*100/D9 -> 3.6401801 | O9: =I9*100/J9 -> 3.0129575 | P9: =D9/E9 -> 1.6062063 | Q9: =C9/$C$13 -> 0.031434531 | R9: =I9/$I$13 -> 0.03263658 | S9: =(Q9-R9)*100 -> -0.12020493 | T9: =(C9-I9)/($C$13-$I$13) -> 0.027083437 | U9: =D9-G9 -> 1169
A10: 4 | B10: SA | C10: 15061.87 | D10: 1508338 | E10: 1492921 | F10: 14951.75 | G10: 1500369 | H10: 1484987 | I10: 15288.43 | J10: 1549583 | K10: =C10/F10-1 -> 0.0073650242 | L10: =F10/I10-1 -> -0.022021882 | M10: =C10/I10-1 -> -0.014819049 | N10: =C10*100/D10 -> 0.99857393 | O10: =I10*100/J10 -> 0.98661575 | P10: =D10/E10 -> 1.0103267 | Q10: =C10/$C$13 -> 0.14109212 | R10: =I10/$I$13 -> 0.18277936 | S10: =(Q10-R10)*100 -> -4.1687246 | T10: =(C10-I10)/($C$13-$I$13) -> -0.0098044604 | U10: =D10-G10 -> 7969
A11: 5 | B11: SA DIGITAL | C11: 171.3 | D11: 331727 | E11: 331715 | F11: 171.5 | G11: 324967 | H11: 324956 | I11: 179.12 | J11: 331067 | K11: =C11/F11-1 -> -0.0011661808 | L11: =F11/I11-1 -> -0.042541313 | M11: =C11/I11-1 -> -0.043657883 | N11: =C11*100/D11 -> 0.051638848 | O11: =I11*100/J11 -> 0.054103852 | P11: =D11/E11 -> 1.0000362 | Q11: =C11/$C$13 -> 0.0016046533 | R11: =I11/$I$13 -> 0.002141452 | S11: =(Q11-R11)*100 -> -0.053679872 | T11: =(C11-I11)/($C$13-$I$13) -> -0.00033841314 | U11: =D11-G11 -> 6760
A12: 6 | B12: SALARY | C12: 853.99 | D12: 378402 | E12: 378379 | F12: 973.44 | G12: 374637 | H12: 374614 | I12: 932.22 | J12: 369767 | K12: =C12/F12-1 -> -0.12270916 | L12: =F12/I12-1 -> 0.04421703 | M12: =C12/I12-1 -> -0.083917959 | N12: =C12*100/D12 -> 0.22568327 | O12: =I12*100/J12 -> 0.25211011 | P12: =D12/E12 -> 1.0000608 | Q12: =C12/$C$13 -> 0.0079997542 | R12: =I12/$I$13 -> 0.011145067 | S12: =(Q12-R12)*100 -> -0.31453129 | T12: =(C12-I12)/($C$13-$I$13) -> -0.0033854296 | U12: =D12-G12 -> 3765
A13: 7 | B13: Grand Total | C13: 106752.03 | D13: 3130224 | E13: 2625337 | F13: 90911.22 | G13: 3104458 | H13: 2604173 | I13: 83644.18 | J13: 3153510 | K13: =C13/F13-1 -> 0.17424483 | L13: =F13/I13-1 -> 0.086880402 | M13: =C13/I13-1 -> 0.27626369 | N13: =C13*100/D13 -> 3.4103639 | O13: =I13*100/J13 -> 2.6524152 | P13: =D13/E13 -> 1.1923132 | Q13: =C13/$C$13 -> 1 | R13: =I13/$I$13 -> 1 | S13: =(Q13-R13)*100 -> 0 | T13: =(C13-I13)/($C$13-$I$13) -> 1 | U13: =D13-G13 -> 25766
B15: Σ products − Grand Total (MEB / accounts Aug / Jul / Jun) | C15: =SUM(C7:C12)-C13 -> -0.01 | D15: =SUM(D7:D12)-D13 -> 0 | E15: =SUM(E7:E12)-E13 -> 0 | F15: =SUM(F7:F12)-F13 -> 0 | G15: =SUM(G7:G12)-G13 -> 0 | H15: =SUM(H7:H12)-H13 -> 0 | I15: =SUM(I7:I12)-I13 -> -0.02 | J15: =SUM(J7:J12)-J13 -> 0
B16: CASA (CA + SA + SA Digital + Salary) MEB | C16: =C7+C10+C11+C12 -> 22166.26 | F16: =F7+F10+F11+F12 -> 22492.32 | I16: =I7+I10+I11+I12 -> 23347.63
B17: CASA ratio = CASA ÷ Grand Total | C17: =C16/C13 -> 0.20764252 | F17: =F16/F13 -> 0.24740973 | I17: =I16/I13 -> 0.27913036
B18: TD (Deposits + NR) MEB | C18: =C8+C9 -> 84585.76 | F18: =F8+F9 -> 68418.9 | I18: =I8+I9 -> 60296.53
B19: Cross-page: MAB page CM MAB grand total (115,448.64) − MEB 26-Aug | C19: =115448.64-C13 -> 8696.61
B20: Cross-page: Book Growth CM MEB grand total (113,109.81) − MEB 26-Aug | C20: =113109.81-C13 -> 6357.78
A23: Data points to flag before metrics (live checks)
A24: # | B24: Flag | C24: Check value (live) | D24: Unit | E24: Implication / action
A25: 1 | B25: Deposits (TD) MEB rose ₹16.0k Cr (+24.5%) in August on top of +₹7.7k Cr in July — the same NR / bulk inflow seen on the MAB page; the CASA ratio fell from 28% to 21% in two months. | C25: =K8 -> 0.2450055 | D25: % | E25: Funding mix is shifting sharply to term deposits.
A26: 2 | B26: CA MEB fell 12.5% over two months while CA accounts were flat — balance per CA account dropping. | C26: =M7 -> -0.12503994 | D26: % | E26: Check large-CA attrition (nodal / corporate).
A27: 3 | B27: Deposits accounts per customer is 3.1x (661k accounts, 216k customers): multiple TDs per depositor. | C27: =P8 -> 3.0652227 | D27: x | E27: Customer-level concentration is higher than account counts suggest.
A28: 4 | B28: Products add to the Grand Total at every date (max |gap|): | C28: =MAX(ABS(C15),ABS(F15),ABS(I15)) -> 0.02 | D28: ₹ Cr | E28: Table is complete.
A29: 5 | B29: 26-Aug MEB (106,752) sits below the MAB page's CM MAB (115,449) and the Book Growth CM MEB (113,110): different dates (26-Aug vs 29-Aug) and definitions. | C29: =C19 -> 8696.61 | D29: ₹ Cr | E29: State basis and date on every liability total.
A31: Notation and exhaustive metrics table for this block: see sheet B2_Metrics
A33: 10-question test set (3 Low / 4 Medium / 3 High) — expected answers are live formulas
A34: # | B34: Level | C34: Question | D34: Calculation | E34: Expected answer (live) | F34: Unit | G34: So what
A35: 1 | B35: Low | C35: What is total liability MEB at 26-Aug-26? | D35: Lookup | E35: =C13 -> 106752.03 | F35: ₹ Cr
A36: 2 | B36: Low | C36: How many SA accounts are there at 26-Aug? | D36: Lookup | E36: =D10 -> 1508338 | F36: count
A37: 3 | B37: Low | C37: What was NR MEB at 30-Jun? | D37: Lookup | E37: =I9 -> 2729.86 | F37: ₹ Cr
A38: 4 | B38: Medium | C38: What is the CASA ratio at 26-Aug vs 30-Jun? | D38: (CA + SA + SA Digital + Salary) ÷ GT | E38: =C17 -> 0.20764252 | F38: %
A39: 5 | B39: Medium | C39: What is the average balance per SA account (₹ lakh)? | D39: MEB × 100 ÷ accounts | E39: =N10 -> 0.99857393 | F39: ₹ lakh
A40: 6 | B40: Medium | C40: What is the 2-month growth of Deposits MEB? | D40: Aug ÷ Jun − 1 | E40: =M8 -> 0.4110606 | F40: %
A41: 7 | B41: Medium | C41: How did the Deposits share of MEB move Jun → Aug (pp)? | D41: Share Aug − share Jun | E41: =S8 -> 7.2690039 | F41: pp
A42: 8 | B42: High | C42: What share of the 2-month growth in total MEB came from Deposits? | D42: ΔDeposits ÷ ΔGT | E42: =T8 -> 1.0240412 | F42: % | G42: Over 100% — every other product net declined.
A43: 9 | B43: High | C43: Salary accounts grew (+3.8k) while Salary MEB fell 12% MoM — what is the change in balance per account? | D43: Aug ÷ Jul balance per account − 1 | E43: =(C12*100/D12)/(F12*100/G12)-1 -> -0.13143797 | F43: % | G43: Salary balances are being swept out faster than accounts are added.
A44: 10 | B44: High | C44: Is the 26-Aug MEB consistent with the MAB page (115,449 CM MAB)? | D44: MAB − MEB | E44: =C19 -> 8696.61 | F44: ₹ Cr | G44: ₹8.7k Cr gap is date (26 vs 29 Aug) and average-vs-end-of-day; the NR TD inflow landed late in the month.
A46: What this page cannot support (feeds the data request)
A47: Not derivable: 30-Jun customers (clipped), cost of deposits, tenor of the TD inflow, segment (INSIGNIA / MASS …) split, daily balances, and the mapping of NR to the NR BAU identifier on the MAB page.
...

Sheet B2_Metrics
A1: Liability MEB: notation and metrics
A2: Format: Notation → Exhaustive metrics table | Example column = live Excel formula on the block sheet (green = cross-sheet)
A3: ⚠ DRAFT ONLY — Requires review and approval by a qualified Alvarez and Marsal professional before use.
A5: Notation
B6: Symbol | C6: Meaning
B7: M(p,d) | C7: Liability MEB ₹ Cr of product p at date d (26-Aug, 31-Jul, 30-Jun)
B8: N(p,d) / C(p,d) | C8: Accounts / customers (Jun customers clipped)
B9: GT | C9: Grand Total MEB
B10: CASA | C10: CA + SA + SA Digital + Salary
B11: TD | C11: Deposits + NR
B12: BPA | C12: Balance per account = M × 100 ÷ N, ₹ lakh
B13: APC | C13: N ÷ C
B14: g | C14: M(d) ÷ M(d−1) − 1; 2M = Aug ÷ Jun − 1
B15: sh | C15: M(p) ÷ GT
B16: MEB ₹ Cr; accounts and customers as counts; balance per account ₹ lakh; growth in %.
A18: Exhaustive metrics table
A19: # | B19: Metric family | C19: Pipeline-ready metric | D19: Definition / formula | E19: Applies to | F19: Example
A20: 1 | B20: Fact lookup | C20: Product MEB | D20: M(p,d) | E20: 6 products × 3 dates | F20: ="Deposits "&TEXT(B2_Liability_MEB!C8,"#,##0.00;-#,##0.00;0.00")&" / "&TEXT(B2_Liability_MEB!F8,"#,##0.00;-#,##0.00;0.00")&" / "&TEXT(B2_Liability_MEB!I8,"#,##0.00;-#,##0.00;0.00")&"; SA "&TEXT(B2_Liability_MEB!C10,"#,##0.00;-#,##0.00;0.00")&" / "&TEXT(B2_Liability_MEB!F10,"#,##0.00;-#,##0.00;0.00")&" / "&TEXT(B2_Liability_MEB!I10,"#,##0.00;-#,##0.00;0.00") -> Deposits 81,230.06 / 65,244.74 / 57,566.67; SA 15,061.87 / 14,951.75 / 15,288.43
A21: 2 | B21: Fact lookup | C21: Accounts / customers | D21: N, C | E21: 6 × 3 / 6 × 2 | F21: ="SA accounts "&TEXT(B2_Liability_MEB!D10,"#,##0")&" / "&TEXT(B2_Liability_MEB!G10,"#,##0")&" / "&TEXT(B2_Liability_MEB!J10,"#,##0")&"; Deposits customers "&TEXT(B2_Liability_MEB!E8,"#,##0")&" / "&TEXT(B2_Liability_MEB!H8,"#,##0") -> SA accounts 1,508,338 / 1,500,369 / 1,549,583; Deposits customers 215,707 / 213,983
A22: 3 | B22: Roll-up check | C22: Products to Grand Total | D22: GT − Σ M(p) | E22: 3 dates | F22: =TEXT(B2_Liability_MEB!C15,"#,##0.00;-#,##0.00;0.00")&" / "&TEXT(B2_Liability_MEB!F15,"#,##0.00;-#,##0.00;0.00")&" / "&TEXT(B2_Liability_MEB!I15,"#,##0.00;-#,##0.00;0.00") -> -0.01 / 0.00 / -0.02
A23: 4 | B23: Mix & share | C23: CASA and TD | D23: CASA, TD, CASA ratio | E23: 3 dates | F23: ="CASA "&TEXT(B2_Liability_MEB!C16,"#,##0.00;-#,##0.00;0.00")&" / "&TEXT(B2_Liability_MEB!F16,"#,##0.00;-#,##0.00;0.00")&" / "&TEXT(B2_Liability_MEB!I16,"#,##0.00;-#,##0.00;0.00")&"; ratio "&TEXT(B2_Liability_MEB!C17,"0.0%")&" / "&TEXT(B2_Liability_MEB!F17,"0.0%")&" / "&TEXT(B2_Liability_MEB!I17,"0.0%") -> CASA 22,166.26 / 22,492.32 / 23,347.63; ratio 20.8% / 24.7% / 27.9%
A24: 5 | B24: Mix & share | C24: Product share of MEB | D24: sh(p, Aug) / sh(p, Jun) | E24: 6 products | F24: ="Deposits "&TEXT(B2_Liability_MEB!Q8,"0.0%")&" / "&TEXT(B2_Liability_MEB!R8,"0.0%")&"; SA "&TEXT(B2_Liability_MEB!Q10,"0.0%")&" / "&TEXT(B2_Liability_MEB!R10,"0.0%")&"; CA "&TEXT(B2_Liability_MEB!Q7,"0.0%")&" / "&TEXT(B2_Liability_MEB!R7,"0.0%") -> Deposits 76.1% / 68.8%; SA 14.1% / 18.3%; CA 5.7% / 8.3%
A25: 6 | B25: Mix & share | C25: Share shift Jun → Aug | D25: (sh Aug − sh Jun) × 100 | E25: 6 products | F25: =TEXT(B2_Liability_MEB!S7,"+0.0"" pp"";-0.0"" pp"";0.0"" pp""")&" / "&TEXT(B2_Liability_MEB!S8,"+0.0"" pp"";-0.0"" pp"";0.0"" pp""")&" / "&TEXT(B2_Liability_MEB!S9,"+0.0"" pp"";-0.0"" pp"";0.0"" pp""")&" / "&TEXT(B2_Liability_MEB!S10,"+0.0"" pp"";-0.0"" pp"";0.0"" pp""")&" / "&TEXT(B2_Liability_MEB!S11,"+0.0"" pp"";-0.0"" pp"";0.0"" pp""")&" / "&TEXT(B2_Liability_MEB!S12,"+0.0"" pp"";-0.0"" pp"";0.0"" pp""")&" (CA / Dep / NR / SA / SA Dig / Salary)" -> -2.6 pp / +7.3 pp / -0.1 pp / -4.2 pp / -0.1 pp / -0.3 pp (CA / Dep / NR / SA / SA Dig / Salary)
A26: 7 | B26: Growth & momentum | C26: MoM growth | D26: g(Aug/Jul), g(Jul/Jun) | E26: 7 rows | F26: ="GT "&TEXT(B2_Liability_MEB!K13,"+0.0%;-0.0%;0.0%")&" / "&TEXT(B2_Liability_MEB!L13,"+0.0%;-0.0%;0.0%")&"; Deposits "&TEXT(B2_Liability_MEB!K8,"+0.0%;-0.0%;0.0%")&" / "&TEXT(B2_Liability_MEB!L8,"+0.0%;-0.0%;0.0%")&"; CA "&TEXT(B2_Liability_MEB!K7,"+0.0%;-0.0%;0.0%")&" / "&TEXT(B2_Liability_MEB!L7,"+0.0%;-0.0%;0.0%") -> GT +17.4% / +8.7%; Deposits +24.5% / +13.3%; CA -4.9% / -7.9%
A27: 8 | B27: Growth & momentum | C27: Two-month growth | D27: Aug ÷ Jun − 1 | E27: 7 rows | F27: =TEXT(B2_Liability_MEB!M7,"+0.0%;-0.0%;0.0%")&" / "&TEXT(B2_Liability_MEB!M8,"+0.0%;-0.0%;0.0%")&" / "&TEXT(B2_Liability_MEB!M9,"+0.0%;-0.0%;0.0%")&" / "&TEXT(B2_Liability_MEB!M10,"+0.0%;-0.0%;0.0%")&" / "&TEXT(B2_Liability_MEB!M11,"+0.0%;-0.0%;0.0%")&" / "&TEXT(B2_Liability_MEB!M12,"+0.0%;-0.0%;0.0%")&" / "&TEXT(B2_Liability_MEB!M13,"+0.0%;-0.0%;0.0%") -> -12.5% / +41.1% / +22.9% / -1.5% / -4.4% / -8.4% / +27.6%
A28: 9 | B28: Growth & momentum | C28: Account growth | D28: N(Aug) − N(Jul) | E28: 7 rows | F28: ="GT "&TEXT(B2_Liability_MEB!U13,"#,##0")&"; SA "&TEXT(B2_Liability_MEB!U10,"#,##0")&"; Salary "&TEXT(B2_Liability_MEB!U12,"#,##0")&"; SA Digital "&TEXT(B2_Liability_MEB!U11,"#,##0") -> GT 25,766; SA 7,969; Salary 3,765; SA Digital 6,760
A29: 10 | B29: Attribution | C29: Contribution to 2M MEB growth | D29: ΔM(p) ÷ ΔGT | E29: 6 products | F29: =TEXT(B2_Liability_MEB!T7,"0.0%")&" / "&TEXT(B2_Liability_MEB!T8,"0.0%")&" / "&TEXT(B2_Liability_MEB!T9,"0.0%")&" / "&TEXT(B2_Liability_MEB!T10,"0.0%")&" / "&TEXT(B2_Liability_MEB!T11,"0.0%")&" / "&TEXT(B2_Liability_MEB!T12,"0.0%") -> -3.8% / 102.4% / 2.7% / -1.0% / 0.0% / -0.3%
A30: 11 | B30: Ticket size | C30: Balance per account | D30: BPA(p, Aug) / BPA(p, Jun) | E30: 7 rows | F30: ="CA "&TEXT(B2_Liability_MEB!N7,"#,##0.00")&" / "&TEXT(B2_Liability_MEB!O7,"#,##0.00")&"; Deposits "&TEXT(B2_Liability_MEB!N8,"#,##0.00")&" / "&TEXT(B2_Liability_MEB!O8,"#,##0.00")&"; SA "&TEXT(B2_Liability_MEB!N10,"#,##0.00")&" / "&TEXT(B2_Liability_MEB!O10,"#,##0.00")&" ₹ lakh" -> CA 3.84 / 4.26; Deposits 12.29 / 8.86; SA 1.00 / 0.99 ₹ lakh
A31: 12 | B31: Ticket size | C31: Accounts per customer | D31: APC(p, Aug) | E31: 7 rows | F31: ="Deposits "&TEXT(B2_Liability_MEB!P8,"0.00""x""")&"; NR "&TEXT(B2_Liability_MEB!P9,"0.00""x""")&"; SA "&TEXT(B2_Liability_MEB!P10,"0.00""x""")&"; GT "&TEXT(B2_Liability_MEB!P13,"0.00""x""") -> Deposits 3.07x; NR 1.61x; SA 1.01x; GT 1.19x
A32: 13 | B32: Ticket size | C32: Balance per customer (Deposits) | D32: M × 100 ÷ C | E32: Aug / Jul | F32: =TEXT(B2_Liability_MEB!C8*100/B2_Liability_MEB!E8,"#,##0.00")&" / "&TEXT(B2_Liability_MEB!F8*100/B2_Liability_MEB!H8,"#,##0.00")&" ₹ lakh" -> 37.66 / 30.49 ₹ lakh
A33: 14 | B33: Cross-page | C33: MAB page vs MEB | D33: CM MAB 115,448.64 − MEB(26-Aug) | E33: Page | F33: =TEXT(B2_Liability_MEB!C19,"#,##0.00;-#,##0.00;0.00") -> 8,696.61
A34: 15 | B34: Cross-page | C34: Book Growth MEB vs this MEB | D34: 113,109.81 − MEB(26-Aug) | E34: Page | F34: =TEXT(B2_Liability_MEB!C20,"#,##0.00;-#,##0.00;0.00") -> 6,357.78
A35: 16 | B35: Data integrity | C35: Clipped column | D35: 30-Jun customers | E35: Page | F35: Not visible; APC computed for Aug and Jul only
A36: 17 | B36: Data integrity | C36: SA Digital balance | D36: BPA(SA Digital) | E36: 1 row | F36: =TEXT(B2_Liability_MEB!N11,"#,##0.00")&" ₹ lakh per account — near-dormant digital accounts" -> 0.05 ₹ lakh per account — near-dormant digital accounts
A38: ⚠ DRAFT ONLY — Requires review and approval by a qualified Alvarez and Marsal professional before use.
