Workbook

Sheet README
A1: RBL Bank — Liability Summary (Oneview): page-wise metric extraction
A2: Source: 12_Liability_Summary.pdf (1 page; segment table as at 15-May-26, month-end trend Dec-25 … Apr-26, donut) | ₹ Cr and account counts
A3: ⚠ DRAFT ONLY — Requires review and approval by a qualified Alvarez and Marsal professional before use.
A5: Sheet map
A6: B1_Liability_Summary | B6: Block A — business-segment accounts and current balance by product (CA / Deposits / SA) at 15-May-26; Block B — month-end trend (accounts and balance) Apr-26 → Jan-26 with Dec-25 accounts; donut inputs
A7: B1_Metrics | B7: Notation + exhaustive metrics
A9: Colour legend
A10: Blue text | B10: Hard-coded input transcribed from the PDF
A11: Blue italic on grey | B11: Budget / projected value (ᴾ) transcribed from the PDF
A12: Black text | B12: Formula on the same sheet
A13: Green text | B13: Link to another sheet
A14: Yellow fill | B14: Data flag to review
A16: Key assumptions (confirm with client)
A17: 1 | B17: The trend table is exported clipped: December-2025 Current Balance is cut off (accounts are visible) and earlier months are not shown. Months are re-ordered chronologically.
A18: 2 | B18: Current balances are as at 15-May-26 (intra-month); trend values are month-ends, so the 15-May vs Apr-26 comparison is a half-month move.
A19: 3 | B19: The 'No of Accounts By View' donut prints SA 89.91%, Deposits 7.87%, CA 2.2?% (last digit illegible). These do not match the segment table (SA 73.8%, Deposits 20.5%, CA 5.8%) — the donut is evidently on a different base; flagged, not used.
A20: 4 | B20: Segments here (AFFLUENT, PREMIUM, MASSMKT …) are the Oneview liability segments and differ from the BBRL customer segments (INSIGNIA / SIGNATURE / ASPIRE / MASS) on the Book Growth and MAB pages; INSIGNIA and SIGNATURE appear on both.
A21: 5 | B21: CASA = CA + SA. ATS / balance per account = balance × 100 ÷ accounts (₹ lakh).
A22: Confidentiality | B22: Client-confidential RBL Bank data.
A24: ⚠ DRAFT ONLY — Requires review and approval by a qualified Alvarez and Marsal professional before use.

Sheet B1_Liability_Summary
A1: Block 1 — Liability book by business segment and product; month-end trend
A2: Source: Liability Summary.pdf | ₹ Cr, accounts | current = 15-May-26; trend = month-ends
A3: ⚠ DRAFT ONLY — Requires review and approval by a qualified Alvarez and Marsal professional before use.
A5: A. Business-segment accounts and current balance at 15-May-26 (blue) with live calculations
A6: # | B6: Segment | C6: CA accounts | D6: CA ₹ Cr | E6: Deposits accounts | F6: Deposits ₹ Cr | G6: SA accounts | H6: SA ₹ Cr | I6: GT accounts (printed) | J6: GT ₹ Cr (printed) | K6: Σ products − GT (accounts) | L6: Σ products − GT (₹) | M6: CASA ₹ Cr | N6: CASA ratio | O6: TD share of balance | P6: Share of bank balance | Q6: Share of bank accounts | R6: Balance per account (₹ lakh) | S6: CA bal/acct (₹ lakh) | T6: Dep bal/acct (₹ lakh) | U6: SA bal/acct (₹ lakh) | V6: Balance share ÷ account share
A7: 1 | B7: AFFLUENT | C7: 33121 | D7: 1897.16 | E7: 49885 | F7: 6941.63 | G7: 237389 | H7: 1278.31 | I7: 320395 | J7: 10117.09 | K7: =N(C7)+N(E7)+N(G7)-I7 -> 0 | L7: =N(D7)+N(F7)+N(H7)-J7 -> 0.01 | M7: =N(D7)+N(H7) -> 3175.47 | N7: =M7/J7 -> 0.31387187 | O7: =N(F7)/J7 -> 0.68612911 | P7: =J7/$J$15 -> 0.081863275 | Q7: =I7/$I$15 -> 0.10163765 | R7: =J7*100/I7 -> 3.1576928 | S7: =IF(N(C7)=0,"",D7*100/C7) -> 5.7279672 | T7: =IF(N(E7)=0,"",F7*100/E7) -> 13.915265 | U7: =IF(N(G7)=0,"",H7*100/G7) -> 0.53848746 | V7: =P7/Q7 -> 0.80544244
A8: 2 | B8: ASPIRE | C8: 23755 | D8: 538.5 | E8: 164029 | F8: 6658.91 | G8: 115385 | H8: 2138.85 | I8: 303169 | J8: 9336.27 | K8: =N(C8)+N(E8)+N(G8)-I8 -> 0 | L8: =N(D8)+N(F8)+N(H8)-J8 -> -0.01 | M8: =N(D8)+N(H8) -> 2677.35 | N8: =M8/J8 -> 0.2867687 | O8: =N(F8)/J8 -> 0.71323023 | P8: =J8/$J$15 -> 0.075545205 | Q8: =I8/$I$15 -> 0.096173112 | R8: =J8*100/I8 -> 3.0795596 | S8: =IF(N(C8)=0,"",D8*100/C8) -> 2.2668912 | T8: =IF(N(E8)=0,"",F8*100/E8) -> 4.0595931 | U8: =IF(N(G8)=0,"",H8*100/G8) -> 1.8536638 | V8: =P8/Q8 -> 0.78551274
A9: 3 | B9: INSIGNIA | C9: 20478 | D9: 3450.76 | E9: 117652 | F9: 21935.17 | G9: 72285 | H9: 10128.26 | I9: 210415 | J9: 35514.2 | K9: =N(C9)+N(E9)+N(G9)-I9 -> 0 | L9: =N(D9)+N(F9)+N(H9)-J9 -> -0.01 | M9: =N(D9)+N(H9) -> 13579.02 | N9: =M9/J9 -> 0.38235466 | O9: =N(F9)/J9 -> 0.61764505 | P9: =J9/$J$15 -> 0.2873661 | Q9: =I9/$I$15 -> 0.066749124 | R9: =J9*100/I9 -> 16.878169 | S9: =IF(N(C9)=0,"",D9*100/C9) -> 16.85106 | T9: =IF(N(E9)=0,"",F9*100/E9) -> 18.644111 | U9: =IF(N(G9)=0,"",H9*100/G9) -> 14.011565 | V9: =P9/Q9 -> 4.3051666
A10: 4 | B10: MASSMKT | C10: 86511 | D10: 2175.58 | E10: 171035 | F10: 17718.49 | G10: 1802921 | H10: 2685.8 | I10: 2060467 | J10: 22579.86 | K10: =N(C10)+N(E10)+N(G10)-I10 -> 0 | L10: =N(D10)+N(F10)+N(H10)-J10 -> 0.01 | M10: =N(D10)+N(H10) -> 4861.38 | N10: =M10/J10 -> 0.21529717 | O10: =N(F10)/J10 -> 0.78470327 | P10: =J10/$J$15 -> 0.18270681 | Q10: =I10/$I$15 -> 0.65363386 | R10: =J10*100/I10 -> 1.0958613 | S10: =IF(N(C10)=0,"",D10*100/C10) -> 2.5148016 | T10: =IF(N(E10)=0,"",F10*100/E10) -> 10.35957 | U10: =IF(N(G10)=0,"",H10*100/G10) -> 0.14896937 | V10: =P10/Q10 -> 0.27952471
A11: 5 | B11: PREMIUM | C11: 6818 | D11: 3349.61 | E11: 8246 | F11: 29998.73 | G11: 6681 | H11: 672.68 | I11: 21745 | J11: 34021.03 | K11: =N(C11)+N(E11)+N(G11)-I11 -> 0 | L11: =N(D11)+N(F11)+N(H11)-J11 -> -0.01 | M11: =N(D11)+N(H11) -> 4022.29 | N11: =M11/J11 -> 0.11822952 | O11: =N(F11)/J11 -> 0.88177019 | P11: =J11/$J$15 -> 0.27528399 | Q11: =I11/$I$15 -> 0.006898081 | R11: =J11*100/I11 -> 156.4545 | S11: =IF(N(C11)=0,"",D11*100/C11) -> 49.128923 | T11: =IF(N(E11)=0,"",F11*100/E11) -> 363.79736 | U11: =IF(N(G11)=0,"",H11*100/G11) -> 10.068553 | V11: =P11/Q11 -> 39.90733
A12: 6 | B12: RBS | C12: 573 | D12: 12.22 | E12: 106 | F12: 3.41 | G12: 61 | H12: 0.22 | I12: 740 | J12: 15.85 | K12: =N(C12)+N(E12)+N(G12)-I12 -> 0 | L12: =N(D12)+N(F12)+N(H12)-J12 -> 0 | M12: =N(D12)+N(H12) -> 12.44 | N12: =M12/J12 -> 0.78485804 | O12: =N(F12)/J12 -> 0.21514196 | P12: =J12/$J$15 -> 0.00012825159 | Q12: =I12/$I$15 -> 0.00023474729 | R12: =J12*100/I12 -> 2.1418919 | S12: =IF(N(C12)=0,"",D12*100/C12) -> 2.1326353 | T12: =IF(N(E12)=0,"",F12*100/E12) -> 3.2169811 | U12: =IF(N(G12)=0,"",H12*100/G12) -> 0.36065574 | V12: =P12/Q12 -> 0.54633896
A13: 7 | B13: SIGNATURE | C13: 10581 | D13: 494.66 | E13: 134158 | F13: 8156.33 | G13: 90523 | H13: 3326.76 | I13: 235262 | J13: 11977.75 | K13: =N(C13)+N(E13)+N(G13)-I13 -> 0 | L13: =N(D13)+N(F13)+N(H13)-J13 -> 0 | M13: =N(D13)+N(H13) -> 3821.42 | N13: =M13/J13 -> 0.31904323 | O13: =N(F13)/J13 -> 0.68095677 | P13: =J13/$J$15 -> 0.09691896 | Q13: =I13/$I$15 -> 0.074631241 | R13: =J13*100/I13 -> 5.0912387 | S13: =IF(N(C13)=0,"",D13*100/C13) -> 4.6749835 | T13: =IF(N(E13)=0,"",F13*100/E13) -> 6.0796449 | U13: =IF(N(G13)=0,"",H13*100/G13) -> 3.6750439 | V13: =P13/Q13 -> 1.2986379
A14: 8 | B14: WEALTH | C14: 81 | D14: 16.7 | G14: 52 | H14: 6.46 | I14: 133 | J14: 23.15 | K14: =N(C14)+N(E14)+N(G14)-I14 -> 0 | L14: =N(D14)+N(F14)+N(H14)-J14 -> 0.01 | M14: =N(D14)+N(H14) -> 23.16 | N14: =M14/J14 -> 1.000432 | O14: =N(F14)/J14 -> 0 | P14: =J14/$J$15 -> 0.00018732015 | Q14: =I14/$I$15 -> 4.2191068e-05 | R14: =J14*100/I14 -> 17.406015 | S14: =IF(N(C14)=0,"",D14*100/C14) -> 20.617284 | T14: =IF(N(E14)=0,"",F14*100/E14) | U14: =IF(N(G14)=0,"",H14*100/G14) -> 12.423077 | V14: =P14/Q14 -> 4.4398058
A15: 9 | B15: Grand Total | C15: 181918 | D15: 11935.19 | E15: 645111 | F15: 91412.67 | G15: 2325297 | H15: 20237.35 | I15: 3152326 | J15: 123585.21 | K15: =N(C15)+N(E15)+N(G15)-I15 -> 0 | L15: =N(D15)+N(F15)+N(H15)-J15 -> 0 | M15: =N(D15)+N(H15) -> 32172.54 | N15: =M15/J15 -> 0.26032678 | O15: =N(F15)/J15 -> 0.73967322 | P15: =J15/$J$15 -> 1 | Q15: =I15/$I$15 -> 1 | R15: =J15*100/I15 -> 3.9204451 | S15: =IF(N(C15)=0,"",D15*100/C15) -> 6.5607526 | T15: =IF(N(E15)=0,"",F15*100/E15) -> 14.170068 | U15: =IF(N(G15)=0,"",H15*100/G15) -> 0.87031248 | V15: =P15/Q15 -> 1
B16: Σ segments − Grand Total (accounts / ₹ by product) | C16: =SUM(C7:C14)-C15 -> 0 | D16: =SUM(D7:D14)-D15 -> 0 | E16: =SUM(E7:E14)-E15 -> 0 | F16: =SUM(F7:F14)-F15 -> 0 | G16: =SUM(G7:G14)-G15 -> 0 | H16: =SUM(H7:H14)-H15 -> -0.01 | I16: =SUM(I7:I14)-I15 -> 0 | J16: =SUM(J7:J14)-J15 -> -0.01
B17: Product share of bank balance (CA / Dep / SA) | D17: =D15/J15 -> 0.096574582 | F17: =F15/J15 -> 0.73967322 | H17: =H15/J15 -> 0.1637522
B18: Product share of bank accounts (CA / Dep / SA) — compare donut | C18: =C15/I15 -> 0.057709133 | E18: =E15/I15 -> 0.20464603 | G18: =G15/I15 -> 0.73764484
B19: Donut as printed (CA / Deposits / SA) — CA last digit illegible | C19: 0.022 | E19: 0.0787 | G19: 0.8991
B20: Donut − table (pp) | C20: =(C19-C18)*100 -> -3.5709133 | E20: =(E19-E18)*100 -> -12.594603 | G20: =(G19-G18)*100 -> 16.145516
A22: B. Month-end trend (blue), re-ordered chronologically; Dec-25 balance clipped
A23: # | B23: Segment | C23: Dec-25 accounts | D23: Jan-26 accounts | E23: Jan-26 ₹ Cr | F23: Feb-26 accounts | G23: Feb-26 ₹ Cr | H23: Mar-26 accounts | I23: Mar-26 ₹ Cr | J23: Apr-26 accounts | K23: Apr-26 ₹ Cr | L23: 15-May-26 accounts (Block A) | M23: 15-May-26 ₹ Cr (Block A) | N23: Bal MoM Feb/Jan | O23: Bal MoM Mar/Feb | P23: Bal MoM Apr/Mar | Q23: Bal Apr vs Jan | R23: Bal 15-May vs Apr | S23: Accounts Apr vs Dec | T23: Accounts Dec → 15-May | U23: Bal/acct Jan (₹ lakh) | V23: Bal/acct Apr (₹ lakh) | W23: Share of bank bal Apr | X23: Share shift Jan → Apr (pp)
A24: 1 | B24: AFFLUENT | C24: 286894 | D24: 293084 | E24: 9152.02 | F24: 301483 | G24: 9630.03 | H24: 305766 | I24: 11299.44 | J24: 312403 | K24: 10501.83 | L24: =I7 -> 320395 | M24: =J7 -> 10117.09 | N24: =G24/E24-1 -> 0.052229999 | O24: =I24/G24-1 -> 0.1733546 | P24: =K24/I24-1 -> -0.070588454 | Q24: =K24/E24-1 -> 0.14748766 | R24: =M24/K24-1 -> -0.03663552 | S24: =J24/C24-1 -> 0.088914373 | T24: =L24-C24 -> 33501 | U24: =E24*100/D24 -> 3.1226611 | V24: =K24*100/J24 -> 3.361629 | W24: =K24/$K$32 -> 0.084368068 | X24: =(K24/$K$32-E24/$E$32)*100 -> 0.20089376
A25: 2 | B25: ASPIRE | C25: 296688 | D25: 295752 | E25: 8525.99 | F25: 296092 | G25: 8593.69 | H25: 295208 | I25: 8954.36 | J25: 294469 | K25: 8896.32 | L25: =I8 -> 303169 | M25: =J8 -> 9336.27 | N25: =G25/E25-1 -> 0.0079404269 | O25: =I25/G25-1 -> 0.041969166 | P25: =K25/I25-1 -> -0.0064817586 | Q25: =K25/E25-1 -> 0.043435425 | R25: =M25/K25-1 -> 0.049453032 | S25: =J25/C25-1 -> -0.0074792374 | T25: =L25-C25 -> 6481 | U25: =E25*100/D25 -> 2.8828174 | V25: =K25*100/J25 -> 3.0211397 | W25: =K25/$K$32 -> 0.071469956 | X25: =(K25/$K$32-E25/$E$32)*100 -> -0.52555232
A26: 3 | B26: INSIGNIA | C26: 199971 | D26: 201924 | E26: 32600.81 | F26: 204716 | G26: 33896.21 | H26: 206705 | I26: 36014.76 | J26: 208501 | K26: 35537.37 | L26: =I9 -> 210415 | M26: =J9 -> 35514.2 | N26: =G26/E26-1 -> 0.039735209 | O26: =I26/G26-1 -> 0.062501088 | P26: =K26/I26-1 -> -0.013255399 | Q26: =K26/E26-1 -> 0.09007629 | R26: =M26/K26-1 -> -0.00065198972 | S26: =J26/C26-1 -> 0.042656185 | T26: =L26-C26 -> 10444 | U26: =E26*100/D26 -> 16.145089 | V26: =K26*100/J26 -> 17.04422 | W26: =K26/$K$32 -> 0.28549493 | X26: =(K26/$K$32-E26/$E$32)*100 -> -0.78801214
A27: 4 | B27: MASSMKT | C27: 1969151 | D27: 1977375 | E27: 21631.95 | F27: 1988751 | G27: 25073.22 | H27: 1996911 | I27: 23983.4 | J27: 2002892 | K27: 22056.87 | L27: =I10 -> 2060467 | M27: =J10 -> 22579.86 | N27: =G27/E27-1 -> 0.15908275 | O27: =I27/G27-1 -> -0.043465498 | P27: =K27/I27-1 -> -0.080327643 | Q27: =K27/E27-1 -> 0.019643167 | R27: =M27/K27-1 -> 0.02371098 | S27: =J27/C27-1 -> 0.017134796 | T27: =L27-C27 -> 91316 | U27: =E27*100/D27 -> 1.0939731 | V27: =K27*100/J27 -> 1.1012511 | W27: =K27/$K$32 -> 0.17719726 | X27: =(K27/$K$32-E27/$E$32)*100 -> -1.7468899
A28: 5 | B28: PREMIUM | C28: 18371 | D28: 19252 | E28: 27489.43 | F28: 20061 | G28: 30692.25 | H28: 20591 | I28: 35619.69 | J28: 21236 | K28: 35474.81 | L28: =I11 -> 21745 | M28: =J11 -> 34021.03 | N28: =G28/E28-1 -> 0.11651096 | O28: =I28/G28-1 -> 0.16054346 | P28: =K28/I28-1 -> -0.0040674133 | Q28: =K28/E28-1 -> 0.29048911 | R28: =M28/K28-1 -> -0.040980628 | S28: =J28/C28-1 -> 0.15595232 | T28: =L28-C28 -> 3374 | U28: =E28*100/D28 -> 142.7874 | V28: =K28*100/J28 -> 167.05034 | W28: =K28/$K$32 -> 0.28499235 | X28: =(K28/$K$32-E28/$E$32)*100 -> 3.7614659
A29: 6 | B29: RBS | C29: 742 | D29: 741 | E29: 15.3 | F29: 741 | G29: 14.34 | H29: 738 | I29: 15.56 | J29: 738 | K29: 15.91 | L29: =I12 -> 740 | M29: =J12 -> 15.85 | N29: =G29/E29-1 -> -0.062745098 | O29: =I29/G29-1 -> 0.085076709 | P29: =K29/I29-1 -> 0.022493573 | Q29: =K29/E29-1 -> 0.039869281 | R29: =M29/K29-1 -> -0.0037712131 | S29: =J29/C29-1 -> -0.0053908356 | T29: =L29-C29 -> -2 | U29: =E29*100/D29 -> 2.0647773 | V29: =K29*100/J29 -> 2.1558266 | W29: =K29/$K$32 -> 0.00012781543 | X29: =(K29/$K$32-E29/$E$32)*100 -> -0.0009869437
A30: 7 | B30: SIGNATURE | C30: 233185 | D30: 232575 | E30: 11700.91 | F30: 233760 | G30: 11771.78 | H30: 232843 | I30: 12076.34 | J30: 233223 | K30: 11984.8 | L30: =I13 -> 235262 | M30: =J13 -> 11977.75 | N30: =G30/E30-1 -> 0.0060567939 | O30: =I30/G30-1 -> 0.025872043 | P30: =K30/I30-1 -> -0.0075801112 | Q30: =K30/E30-1 -> 0.024262216 | R30: =M30/K30-1 -> -0.00058824511 | S30: =J30/C30-1 -> 0.00016296074 | T30: =L30-C30 -> 2077 | U30: =E30*100/D30 -> 5.0310266 | V30: =K30*100/J30 -> 5.1387728 | W30: =K30/$K$32 -> 0.096281736 | X30: =(K30/$K$32-E30/$E$32)*100 -> -0.90148843
A31: 8 | B31: WEALTH | C31: 137 | D31: 137 | E31: 6.91 | F31: 138 | G31: 6.5 | H31: 136 | I31: 12.53 | J31: 136 | K31: 8.45 | L31: =I14 -> 133 | M31: =J14 -> 23.15 | N31: =G31/E31-1 -> -0.059334298 | O31: =I31/G31-1 -> 0.92769231 | P31: =K31/I31-1 -> -0.32561852 | Q31: =K31/E31-1 -> 0.22286541 | R31: =M31/K31-1 -> 1.739645 | S31: =J31/C31-1 -> -0.0072992701 | T31: =L31-C31 -> -4 | U31: =E31*100/D31 -> 5.0437956 | V31: =K31*100/J31 -> 6.2132353 | W31: =K31/$K$32 -> 6.7884376e-05 | X31: =(K31/$K$32-E31/$E$32)*100 -> 0.00057012085
A32: 9 | B32: Grand Total | C32: 3005139 | D32: 3020840 | E32: 111123.32 | F32: 3045742 | G32: 119678.01 | H32: 3058898 | I32: 127976.09 | J32: 3073598 | K32: 124476.36 | L32: =I15 -> 3152326 | M32: =J15 -> 123585.21 | N32: =G32/E32-1 -> 0.076983751 | O32: =I32/G32-1 -> 0.069336714 | P32: =K32/I32-1 -> -0.027346749 | Q32: =K32/E32-1 -> 0.12016416 | R32: =M32/K32-1 -> -0.0071591907 | S32: =J32/C32-1 -> 0.022780643 | T32: =L32-C32 -> 147187 | U32: =E32*100/D32 -> 3.678557 | V32: =K32*100/J32 -> 4.0498582 | W32: =K32/$K$32 -> 1 | X32: =(K32/$K$32-E32/$E$32)*100 -> 0
B33: Σ segments − Grand Total (max |gap| across accounts / balances) | C33: =SUM(C24:C31)-C32 -> 0 | D33: =SUM(D24:D31)-D32 -> 0 | E33: =SUM(E24:E31)-E32 -> 0 | F33: =SUM(F24:F31)-F32 -> 0 | G33: =SUM(G24:G31)-G32 -> 0.01 | H33: =SUM(H24:H31)-H32 -> 0 | I33: =SUM(I24:I31)-I32 -> -0.01 | J33: =SUM(J24:J31)-J32 -> 0 | K33: =SUM(K24:K31)-K32 -> 0
A36: Data points to flag before metrics (live checks)
A37: # | B37: Flag | C37: Check value (live) | D37: Unit | E37: Implication / action
A38: 1 | B38: The donut ('No of Accounts By View': SA 89.91%, Deposits 7.87%) does not match the segment table (SA share of accounts is 73.8%). | C38: =G20 -> 16.145516 | D38: pp | E38: Donut is on a different base — do not use it; the table is internally consistent.
A39: 2 | B39: Segments add to the Grand Total in every column (max |gap|): | C39: =MAX(ABS(MIN(C16:J16)),MAX(C16:J16),ABS(MIN(C33:K33)),MAX(C33:K33)) -> 0.01 | D39: ₹ Cr | E39: Both tables roll up.
A40: 3 | B40: MASSMKT holds 65% of accounts but 18% of balance; PREMIUM holds 0.7% of accounts and 28% of balance (₹156 lakh per account). | C40: =R11 -> 156.4545 | D40: ₹ lakh | E40: Balance is concentrated in ~22k PREMIUM and ~210k INSIGNIA accounts.
A41: 4 | B41: Total balance fell ₹3.5k Cr (−2.7%) in April after +₹8.3k Cr in March and a further −₹0.9k Cr by 15-May; MASSMKT balance is down ₹3.0k Cr since Feb. | C41: =P32 -> -0.027346749 | D41: % | E41: Quarter-end (March) balances are inflated; April is the clean-out.
A42: 5 | B42: Accounts grew steadily (+68k Dec → Apr; +147k Dec → 15-May) while the balance is volatile. | C42: =T32 -> 147187 | D42: count | E42: Volume growth is real; balance moves are driven by a few large segments.
A43: 6 | B43: CASA ratio is 26% at bank level; INSIGNIA 38%, PREMIUM 12%, MASSMKT 22%. | C43: =N15 -> 0.26032678 | D43: % | E43: Deposits (TD) are 74% of the book.
A45: Notation and exhaustive metrics table for this block: see sheet B1_Metrics
...

Sheet B1_Metrics
A1: Liability summary: notation and metrics
A2: Format: Notation → Exhaustive metrics table | Example column = live Excel formula on the block sheet (green = cross-sheet)
A3: ⚠ DRAFT ONLY — Requires review and approval by a qualified Alvarez and Marsal professional before use.
A5: Notation
B6: Symbol | C6: Meaning
B7: B(s,p), N(s,p) | C7: Current balance ₹ Cr and accounts of segment s, product p (CA, Deposits, SA) at 15-May-26
B8: GT | C8: Grand Total across segments / products
B9: CASA(s) | C9: B(s,CA) + B(s,SA)
B10: CASA% | C10: CASA ÷ B(s)
B11: BPA | C11: Balance per account = B × 100 ÷ N, ₹ lakh
B12: sh_B / sh_N | C12: Share of bank balance / accounts
B13: B(s,m), N(s,m) | C13: Month-end balance / accounts for m = Jan-26 … Apr-26 (Dec-25 accounts only)
B14: g | C14: B(m) ÷ B(m−1) − 1
B15: Δsh | C15: Share shift in pp
B16: Balances ₹ Cr; accounts as counts; balance per account ₹ lakh; growth in %; shares in %.
A18: Exhaustive metrics table
A19: # | B19: Metric family | C19: Pipeline-ready metric | D19: Definition / formula | E19: Applies to | F19: Example
A20: 1 | B20: Fact lookup | C20: Segment × product balance and accounts | D20: B(s,p), N(s,p) | E20: 8 segments × 3 products | F20: ="INSIGNIA CA / Dep / SA "&TEXT(B1_Liability_Summary!D9,"#,##0.00;-#,##0.00;0.00")&" / "&TEXT(B1_Liability_Summary!F9,"#,##0.00;-#,##0.00;0.00")&" / "&TEXT(B1_Liability_Summary!H9,"#,##0.00;-#,##0.00;0.00")&"; accounts "&TEXT(B1_Liability_Summary!C9,"#,##0")&" / "&TEXT(B1_Liability_Summary!E9,"#,##0")&" / "&TEXT(B1_Liability_Summary!G9,"#,##0") -> INSIGNIA CA / Dep / SA 3,450.76 / 21,935.17 / 10,128.26; accounts 20,478 / 117,652 / 72,285
A21: 2 | B21: Fact lookup | C21: Segment totals | D21: B(s), N(s) | E21: 8 + GT | F21: =TEXT(B1_Liability_Summary!J7,"#,##0.00;-#,##0.00;0.00")&" / "&TEXT(B1_Liability_Summary!J8,"#,##0.00;-#,##0.00;0.00")&" / "&TEXT(B1_Liability_Summary!J9,"#,##0.00;-#,##0.00;0.00")&" / "&TEXT(B1_Liability_Summary!J10,"#,##0.00;-#,##0.00;0.00")&" / "&TEXT(B1_Liability_Summary!J11,"#,##0.00;-#,##0.00;0.00")&" / "&TEXT(B1_Liability_Summary!J12,"#,##0.00;-#,##0.00;0.00")&" / "&TEXT(B1_Liability_Summary!J13,"#,##0.00;-#,##0.00;0.00")&" / "&TEXT(B1_Liability_Summary!J14,"#,##0.00;-#,##0.00;0.00")&" / "&TEXT(B1_Liability_Summary!J15,"#,##0.00;-#,##0.00;0.00") -> 10,117.09 / 9,336.27 / 35,514.20 / 22,579.86 / 34,021.03 / 15.85 / 11,977.75 / 23.15 / 123,585.21
A22: 3 | B22: Fact lookup | C22: Month-end balance | D22: B(s,m) | E22: 9 rows × 4 months | F22: ="GT Jan → Apr "&TEXT(B1_Liability_Summary!E32,"#,##0.00;-#,##0.00;0.00")&" / "&TEXT(B1_Liability_Summary!G32,"#,##0.00;-#,##0.00;0.00")&" / "&TEXT(B1_Liability_Summary!I32,"#,##0.00;-#,##0.00;0.00")&" / "&TEXT(B1_Liability_Summary!K32,"#,##0.00;-#,##0.00;0.00") -> GT Jan → Apr 111,123.32 / 119,678.01 / 127,976.09 / 124,476.36
A23: 4 | B23: Roll-up check | C23: Products to segment total | D23: Σp B(s,p) − B(s); Σp N(s,p) − N(s) | E23: 9 rows | F23: ="max |gap| "&TEXT(MAX(ABS(MIN(B1_Liability_Summary!L7:L15)),MAX(B1_Liability_Summary!L7:L15)),"#,##0.00;-#,##0.00;0.00")&" ₹ Cr; accounts "&TEXT(MAX(ABS(MIN(B1_Liability_Summary!K7:K15)),MAX(B1_Liability_Summary!K7:K15)),"#,##0") -> max |gap| 0.01 ₹ Cr; accounts 0
A24: 5 | B24: Roll-up check | C24: Segments to Grand Total | D24: Σs − GT | E24: both tables | F24: =TEXT(B1_Liability_Summary!C16,"#,##0.00;-#,##0.00;0.00")&" / "&TEXT(B1_Liability_Summary!D16,"#,##0.00;-#,##0.00;0.00")&" / "&TEXT(B1_Liability_Summary!E16,"#,##0.00;-#,##0.00;0.00")&" / "&TEXT(B1_Liability_Summary!F16,"#,##0.00;-#,##0.00;0.00")&" / "&TEXT(B1_Liability_Summary!G16,"#,##0.00;-#,##0.00;0.00")&" / "&TEXT(B1_Liability_Summary!H16,"#,##0.00;-#,##0.00;0.00")&" / "&TEXT(B1_Liability_Summary!I16,"#,##0.00;-#,##0.00;0.00")&" / "&TEXT(B1_Liability_Summary!J16,"#,##0.00;-#,##0.00;0.00")&"; trend "&TEXT(B1_Liability_Summary!E33,"#,##0.00;-#,##0.00;0.00")&" / "&TEXT(B1_Liability_Summary!G33,"#,##0.00;-#,##0.00;0.00")&" / "&TEXT(B1_Liability_Summary!I33,"#,##0.00;-#,##0.00;0.00")&" / "&TEXT(B1_Liability_Summary!K33,"#,##0.00;-#,##0.00;0.00") -> 0.00 / 0.00 / 0.00 / 0.00 / 0.00 / -0.01 / 0.00 / -0.01; trend 0.00 / 0.01 / -0.01 / 0.00
A25: 6 | B25: Mix & share | C25: CASA ratio | D25: CASA% | E25: 8 + GT | F25: =TEXT(B1_Liability_Summary!N7,"0.0%")&" / "&TEXT(B1_Liability_Summary!N8,"0.0%")&" / "&TEXT(B1_Liability_Summary!N9,"0.0%")&" / "&TEXT(B1_Liability_Summary!N10,"0.0%")&" / "&TEXT(B1_Liability_Summary!N11,"0.0%")&" / "&TEXT(B1_Liability_Summary!N12,"0.0%")&" / "&TEXT(B1_Liability_Summary!N13,"0.0%")&" / "&TEXT(B1_Liability_Summary!N14,"0.0%")&" / "&TEXT(B1_Liability_Summary!N15,"0.0%") -> 31.4% / 28.7% / 38.2% / 21.5% / 11.8% / 78.5% / 31.9% / 100.0% / 26.0%
A26: 7 | B26: Mix & share | C26: TD share of balance | D26: B(s,Dep) ÷ B(s) | E26: 8 + GT | F26: =TEXT(B1_Liability_Summary!O7,"0.0%")&" / "&TEXT(B1_Liability_Summary!O8,"0.0%")&" / "&TEXT(B1_Liability_Summary!O9,"0.0%")&" / "&TEXT(B1_Liability_Summary!O10,"0.0%")&" / "&TEXT(B1_Liability_Summary!O11,"0.0%")&" / "&TEXT(B1_Liability_Summary!O12,"0.0%")&" / "&TEXT(B1_Liability_Summary!O13,"0.0%")&" / "&TEXT(B1_Liability_Summary!O14,"0.0%")&" / "&TEXT(B1_Liability_Summary!O15,"0.0%") -> 68.6% / 71.3% / 61.8% / 78.5% / 88.2% / 21.5% / 68.1% / 0.0% / 74.0%
A27: 8 | B27: Mix & share | C27: Product share of bank | D27: B(p) ÷ GT; N(p) ÷ GT | E27: 3 products | F27: ="balance CA / Dep / SA "&TEXT(B1_Liability_Summary!D17,"0.0%")&" / "&TEXT(B1_Liability_Summary!F17,"0.0%")&" / "&TEXT(B1_Liability_Summary!H17,"0.0%")&"; accounts "&TEXT(B1_Liability_Summary!C18,"0.0%")&" / "&TEXT(B1_Liability_Summary!E18,"0.0%")&" / "&TEXT(B1_Liability_Summary!G18,"0.0%") -> balance CA / Dep / SA 9.7% / 74.0% / 16.4%; accounts 5.8% / 20.5% / 73.8%
A28: 9 | B28: Mix & share | C28: Segment share of balance and accounts | D28: sh_B(s), sh_N(s) | E28: 8 segments | F28: ="balance "&TEXT(B1_Liability_Summary!P7,"0.0%")&" / "&TEXT(B1_Liability_Summary!P8,"0.0%")&" / "&TEXT(B1_Liability_Summary!P9,"0.0%")&" / "&TEXT(B1_Liability_Summary!P10,"0.0%")&" / "&TEXT(B1_Liability_Summary!P11,"0.0%")&" / "&TEXT(B1_Liability_Summary!P12,"0.0%")&" / "&TEXT(B1_Liability_Summary!P13,"0.0%")&" / "&TEXT(B1_Liability_Summary!P14,"0.0%") -> balance 8.2% / 7.6% / 28.7% / 18.3% / 27.5% / 0.0% / 9.7% / 0.0%
A29: 10 | B29: Mix & share | C29: Balance share ÷ account share | D29: sh_B ÷ sh_N | E29: 8 segments | F29: =TEXT(B1_Liability_Summary!V7,"0.00""x""")&" / "&TEXT(B1_Liability_Summary!V8,"0.00""x""")&" / "&TEXT(B1_Liability_Summary!V9,"0.00""x""")&" / "&TEXT(B1_Liability_Summary!V10,"0.00""x""")&" / "&TEXT(B1_Liability_Summary!V11,"0.00""x""")&" / "&TEXT(B1_Liability_Summary!V12,"0.00""x""")&" / "&TEXT(B1_Liability_Summary!V13,"0.00""x""")&" / "&TEXT(B1_Liability_Summary!V14,"0.00""x""") -> 0.81x / 0.79x / 4.31x / 0.28x / 39.91x / 0.55x / 1.30x / 4.44x
A30: 11 | B30: Mix & share | C30: Share shift Jan → Apr | D30: Δsh in pp | E30: 8 segments | F30: =TEXT(B1_Liability_Summary!X24,"+0.0"" pp"";-0.0"" pp"";0.0"" pp""")&" / "&TEXT(B1_Liability_Summary!X25,"+0.0"" pp"";-0.0"" pp"";0.0"" pp""")&" / "&TEXT(B1_Liability_Summary!X26,"+0.0"" pp"";-0.0"" pp"";0.0"" pp""")&" / "&TEXT(B1_Liability_Summary!X27,"+0.0"" pp"";-0.0"" pp"";0.0"" pp""")&" / "&TEXT(B1_Liability_Summary!X28,"+0.0"" pp"";-0.0"" pp"";0.0"" pp""")&" / "&TEXT(B1_Liability_Summary!X29,"+0.0"" pp"";-0.0"" pp"";0.0"" pp""")&" / "&TEXT(B1_Liability_Summary!X30,"+0.0"" pp"";-0.0"" pp"";0.0"" pp""")&" / "&TEXT(B1_Liability_Summary!X31,"+0.0"" pp"";-0.0"" pp"";0.0"" pp""") -> +0.2 pp / -0.5 pp / -0.8 pp / -1.7 pp / +3.8 pp / -0.0 pp / -0.9 pp / +0.0 pp
A31: 12 | B31: Ticket size | C31: Balance per account | D31: BPA(s) | E31: 8 + GT | F31: =TEXT(B1_Liability_Summary!R7,"#,##0.00")&" / "&TEXT(B1_Liability_Summary!R8,"#,##0.00")&" / "&TEXT(B1_Liability_Summary!R9,"#,##0.00")&" / "&TEXT(B1_Liability_Summary!R10,"#,##0.00")&" / "&TEXT(B1_Liability_Summary!R11,"#,##0.00")&" / "&TEXT(B1_Liability_Summary!R12,"#,##0.00")&" / "&TEXT(B1_Liability_Summary!R13,"#,##0.00")&" / "&TEXT(B1_Liability_Summary!R14,"#,##0.00")&" / "&TEXT(B1_Liability_Summary!R15,"#,##0.00")&" ₹ lakh" -> 3.16 / 3.08 / 16.88 / 1.10 / 156.45 / 2.14 / 5.09 / 17.41 / 3.92 ₹ lakh
A32: 13 | B32: Ticket size | C32: Balance per account by product | D32: BPA(s,p) | E32: 8 × 3 | F32: ="GT CA / Dep / SA "&TEXT(B1_Liability_Summary!S15,"#,##0.00")&" / "&TEXT(B1_Liability_Summary!T15,"#,##0.00")&" / "&TEXT(B1_Liability_Summary!U15,"#,##0.00")&"; INSIGNIA "&TEXT(B1_Liability_Summary!S9,"#,##0.00")&" / "&TEXT(B1_Liability_Summary!T9,"#,##0.00")&" / "&TEXT(B1_Liability_Summary!U9,"#,##0.00") -> GT CA / Dep / SA 6.56 / 14.17 / 0.87; INSIGNIA 16.85 / 18.64 / 14.01
A33: 14 | B33: Ticket size | C33: BPA trend | D33: BPA Jan vs Apr | E33: 9 rows | F33: ="GT "&TEXT(B1_Liability_Summary!U32,"#,##0.00")&" → "&TEXT(B1_Liability_Summary!V32,"#,##0.00")&"; PREMIUM "&TEXT(B1_Liability_Summary!U28,"#,##0.00")&" → "&TEXT(B1_Liability_Summary!V28,"#,##0.00") -> GT 3.68 → 4.05; PREMIUM 142.79 → 167.05
A34: 15 | B34: Growth & momentum | C34: MoM balance growth | D34: g(m) | E34: 9 rows × 3 | F34: ="GT "&TEXT(B1_Liability_Summary!N32,"+0.0%;-0.0%;0.0%")&" / "&TEXT(B1_Liability_Summary!O32,"+0.0%;-0.0%;0.0%")&" / "&TEXT(B1_Liability_Summary!P32,"+0.0%;-0.0%;0.0%")&" (Feb / Mar / Apr); MASSMKT "&TEXT(B1_Liability_Summary!N27,"+0.0%;-0.0%;0.0%")&" / "&TEXT(B1_Liability_Summary!O27,"+0.0%;-0.0%;0.0%")&" / "&TEXT(B1_Liability_Summary!P27,"+0.0%;-0.0%;0.0%") -> GT +7.7% / +6.9% / -2.7% (Feb / Mar / Apr); MASSMKT +15.9% / -4.3% / -8.0%
A35: 16 | B35: Growth & momentum | C35: Jan → Apr balance growth | D35: B(Apr) ÷ B(Jan) − 1 | E35: 9 rows | F35: =TEXT(B1_Liability_Summary!Q24,"+0.0%;-0.0%;0.0%")&" / "&TEXT(B1_Liability_Summary!Q25,"+0.0%;-0.0%;0.0%")&" / "&TEXT(B1_Liability_Summary!Q26,"+0.0%;-0.0%;0.0%")&" / "&TEXT(B1_Liability_Summary!Q27,"+0.0%;-0.0%;0.0%")&" / "&TEXT(B1_Liability_Summary!Q28,"+0.0%;-0.0%;0.0%")&" / "&TEXT(B1_Liability_Summary!Q29,"+0.0%;-0.0%;0.0%")&" / "&TEXT(B1_Liability_Summary!Q30,"+0.0%;-0.0%;0.0%")&" / "&TEXT(B1_Liability_Summary!Q31,"+0.0%;-0.0%;0.0%")&" / "&TEXT(B1_Liability_Summary!Q32,"+0.0%;-0.0%;0.0%") -> +14.7% / +4.3% / +9.0% / +2.0% / +29.0% / +4.0% / +2.4% / +22.3% / +12.0%
A36: 17 | B36: Growth & momentum | C36: 15-May vs Apr | D36: B(15-May) ÷ B(Apr) − 1 (half-month) | E36: 9 rows | F36: =TEXT(B1_Liability_Summary!R24,"+0.0%;-0.0%;0.0%")&" / "&TEXT(B1_Liability_Summary!R25,"+0.0%;-0.0%;0.0%")&" / "&TEXT(B1_Liability_Summary!R26,"+0.0%;-0.0%;0.0%")&" / "&TEXT(B1_Liability_Summary!R27,"+0.0%;-0.0%;0.0%")&" / "&TEXT(B1_Liability_Summary!R28,"+0.0%;-0.0%;0.0%")&" / "&TEXT(B1_Liability_Summary!R29,"+0.0%;-0.0%;0.0%")&" / "&TEXT(B1_Liability_Summary!R30,"+0.0%;-0.0%;0.0%")&" / "&TEXT(B1_Liability_Summary!R31,"+0.0%;-0.0%;0.0%")&" / "&TEXT(B1_Liability_Summary!R32,"+0.0%;-0.0%;0.0%") -> -3.7% / +4.9% / -0.1% / +2.4% / -4.1% / -0.4% / -0.1% / +174.0% / -0.7%
A37: 18 | B37: Growth & momentum | C37: Account growth | D37: N(Apr) ÷ N(Dec) − 1; N(15-May) − N(Dec) | E37: 9 rows | F37: ="GT "&TEXT(B1_Liability_Summary!S32,"+0.0%;-0.0%;0.0%")&" / "&TEXT(B1_Liability_Summary!T32,"#,##0")&"; AFFLUENT "&TEXT(B1_Liability_Summary!S24,"+0.0%;-0.0%;0.0%")&"; PREMIUM "&TEXT(B1_Liability_Summary!S28,"+0.0%;-0.0%;0.0%") -> GT +2.3% / 147,187; AFFLUENT +8.9%; PREMIUM +15.6%
A38: 19 | B38: Growth & momentum | C38: Quarter-end effect | D38: B(Mar) ÷ AVERAGE(B(Feb), B(Apr)) − 1 | E38: 9 rows | F38: ="GT "&TEXT(B1_Liability_Summary!I32/AVERAGE(B1_Liability_Summary!G32,B1_Liability_Summary!K32)-1,"+0.0%;-0.0%;0.0%")&"; MASSMKT "&TEXT(B1_Liability_Summary!I27/AVERAGE(B1_Liability_Summary!G27,B1_Liability_Summary!K27)-1,"+0.0%;-0.0%;0.0%") -> GT +4.8%; MASSMKT +1.8%
A39: 20 | B39: Attribution | C39: Contribution to April balance fall | D39: ΔB(s) ÷ ΔGT (Apr − Mar) | E39: 8 segments | F39: =TEXT((B1_Liability_Summary!K24-B1_Liability_Summary!I24)/(B1_Liability_Summary!K32-B1_Liability_Summary!I32),"0.0%")&" / "&TEXT((B1_Liability_Summary!K25-B1_Liability_Summary!I25)/(B1_Liability_Summary!K32-B1_Liability_Summary!I32),"0.0%")&" / "&TEXT((B1_Liability_Summary!K26-B1_Liability_Summary!I26)/(B1_Liability_Summary!K32-B1_Liability_Summary!I32),"0.0%")&" / "&TEXT((B1_Liability_Summary!K27-B1_Liability_Summary!I27)/(B1_Liability_Summary!K32-B1_Liability_Summary!I32),"0.0%")&" / "&TEXT((B1_Liability_Summary!K28-B1_Liability_Summary!I28)/(B1_Liability_Summary!K32-B1_Liability_Summary!I32),"0.0%")&" / "&TEXT((B1_Liability_Summary!K29-B1_Liability_Summary!I29)/(B1_Liability_Summary!K32-B1_Liability_Summary!I32),"0.0%")&" / "&TEXT((B1_Liability_Summary!K30-B1_Liability_Summary!I30)/(B1_Liability_Summary!K32-B1_Liability_Summary!I32),"0.0%")&" / "&TEXT((B1_Liability_Summary!K31-B1_Liability_Summary!I31)/(B1_Liability_Summary!K32-B1_Liability_Summary!I32),"0.0%") -> 22.8% / 1.7% / 13.6% / 55.0% / 4.1% / 0.0% / 2.6% / 0.1%
A40: 21 | B40: Attribution | C40: Contribution to Jan → Apr growth | D40: ΔB(s) ÷ ΔGT | E40: 8 segments | F40: =TEXT((B1_Liability_Summary!K24-B1_Liability_Summary!E24)/(B1_Liability_Summary!K32-B1_Liability_Summary!E32),"0.0%")&" / "&TEXT((B1_Liability_Summary!K25-B1_Liability_Summary!E25)/(B1_Liability_Summary!K32-B1_Liability_Summary!E32),"0.0%")&" / "&TEXT((B1_Liability_Summary!K26-B1_Liability_Summary!E26)/(B1_Liability_Summary!K32-B1_Liability_Summary!E32),"0.0%")&" / "&TEXT((B1_Liability_Summary!K27-B1_Liability_Summary!E27)/(B1_Liability_Summary!K32-B1_Liability_Summary!E32),"0.0%")&" / "&TEXT((B1_Liability_Summary!K28-B1_Liability_Summary!E28)/(B1_Liability_Summary!K32-B1_Liability_Summary!E32),"0.0%")&" / "&TEXT((B1_Liability_Summary!K29-B1_Liability_Summary!E29)/(B1_Liability_Summary!K32-B1_Liability_Summary!E32),"0.0%")&" / "&TEXT((B1_Liability_Summary!K30-B1_Liability_Summary!E30)/(B1_Liability_Summary!K32-B1_Liability_Summary!E32),"0.0%")&" / "&TEXT((B1_Liability_Summary!K31-B1_Liability_Summary!E31)/(B1_Liability_Summary!K32-B1_Liability_Summary!E32),"0.0%") -> 10.1% / 2.8% / 22.0% / 3.2% / 59.8% / 0.0% / 2.1% / 0.0%
A41: 22 | B41: Concentration | C41: Top-2 segments share of balance | D41: (PREMIUM + INSIGNIA) ÷ GT; their account share | E41: 15-May | F41: =TEXT((B1_Liability_Summary!J11+B1_Liability_Summary!J9)/B1_Liability_Summary!J15,"0.0%")&" of balance in "&TEXT((B1_Liability_Summary!I11+B1_Liability_Summary!I9)/B1_Liability_Summary!I15,"0.0%")&" of accounts" -> 56.3% of balance in 7.4% of accounts
A42: 23 | B42: Concentration | C42: HHI across segments (balance) | D42: Σ (100 × sh_B)² | E42: 15-May | F42: =TEXT(SUMPRODUCT((B1_Liability_Summary!J7:J14/B1_Liability_Summary!J15)^2)*10000,"#,##0") -> 2,135
...
