Workbook

Sheet README
A1: RBL Bank — Credit Card Daily Collections (BAU + Supercards): page-wise metric extraction
A2: Source: 13_Collection_Daily_Refresh.pdf (1 page; data to 27-08-2026, cycles closed to 26 EOD) | ₹ Cr, % | Jul'26 vs Aug'26 closing cycles
A3: ⚠ DRAFT ONLY — Requires review and approval by a qualified Alvarez and Marsal professional before use.
A5: Sheet map
A6: B1_PreNPA_Resolution | B6: Block 1 — Pre-NPA (B1–B3) bucket-wise resolution, normalisation, roll-back and stabilisation by balance band (Jul vs Aug), with weighted-average checks and headline-claim checks
A7: B1_Metrics | B7: Notation + metrics for Block 1
A8: B2_NPA_TWO_Recovery | B8: Block 2 — NPA (90–120 DPD) and TWO (120+ DPD, tech write-off) allocated balance and money collected by balance band, MTD Jul vs Aug
A9: B2_Metrics | B9: Notation + metrics for Block 2
A11: Colour legend
A12: Blue text | B12: Hard-coded input transcribed from the PDF
A13: Blue italic on grey | B13: Budget / projected value (ᴾ) transcribed from the PDF
A14: Black text | B14: Formula on the same sheet
A15: Green text | B15: Link to another sheet
A16: Yellow fill | B16: Data flag to review
A18: Key assumptions (confirm with client)
A19: 1 | B19: B1 / B2 / B3 are the 1–30 / 31–60 / 61–90 DPD card buckets ('Pre-NPA'); Resolution % ≈ Normalisation + Roll-back + Stabilisation (ties within 0.1 pp, rounding of one-decimal prints).
A20: 2 | B20: Band totals are balance-weighted averages of the bands (verified live); 'Var' = Aug − Jul in pp, signed as printed (red down-arrows are negatives).
A21: 3 | B21: Aug'26 is an in-progress month (cycles to 26 EOD) compared with Jul'26 full closing cycles — part of the 'dip' may be timing. NPA and TWO figures are MTD money collected vs allocated balance; the page notes NPA / TWO numbers refresh after the 10th.
A22: 4 | B22: Headline claims on the page are re-tested live: B1/B2/B3 resolution dips of 5.00 / 2.67 / 2.02 pp, NPA collection dip ₹1.805 Cr (printed −1.81), W-off recovery up ₹0.67 Cr (67.16 lakh).
A23: Confidentiality | B23: Client-confidential RBL Bank data (credit-card collections).
A25: ⚠ DRAFT ONLY — Requires review and approval by a qualified Alvarez and Marsal professional before use.

Sheet B1_PreNPA_Resolution
A1: Block 1 — Pre-NPA card buckets B1–B3: resolution by balance band
A2: Source: Collection Daily Refresh.pdf | Currbal ₹ Cr; rates in %; Var in pp (signed as printed) | Jul'26 vs Aug'26 closing cycles
A3: ⚠ DRAFT ONLY — Requires review and approval by a qualified Alvarez and Marsal professional before use.
A5: A. Source data (blue) with live checks
A6: # | B6: Bucket | C6: Balance band | D6: Currbal Jul | E6: Currbal Aug | F6: Res % Jul | G6: Res % Aug | H6: Res Var (pp) | I6: Norm % Jul | J6: Norm % Aug | K6: Norm Var | L6: RB % Jul | M6: RB % Aug | N6: RB Var | O6: Stab % Jul | P6: Stab % Aug | Q6: Stab Var | R6: Res Var computed | S6: Var check (pp) | T6: Norm+RB+Stab − Res (Aug, pp) | U6: Resolved ₹ Cr Jul | V6: Resolved ₹ Cr Aug | W6: Δ resolved ₹ Cr | X6: Band share of bucket Aug | Y6: Currbal MoM | Z6: Wtd-avg check (Totals, pp)
A7: 1 | B7: B1 | C7: < 1L | D7: 298 | E7: 318.9 | F7: 0.261 | G7: 0.217 | H7: -4.36 | I7: 0.127 | J7: 0.104 | K7: -2.29 | L7: 0 | M7: 0 | N7: 0 | O7: 0.134 | P7: 0.113 | Q7: -2.07 | R7: =(G7-F7)*100 -> -4.4 | S7: =R7-H7 -> -0.04 | T7: =(J7+M7+P7-G7)*100 -> 0 | U7: =D7*F7 -> 77.778 | V7: =E7*G7 -> 69.2013 | W7: =V7-U7 -> -8.5767 | X7: =E7/E$11 -> 0.4554413 | Y7: =E7/D7-1 -> 0.070134228
A8: 2 | B8: B1 | C8: 1L -2L | D8: 150.7 | E8: 159.3 | F8: 0.215 | G8: 0.159 | H8: -5.6 | I8: 0.094 | J8: 0.067 | K8: -2.68 | L8: 0 | M8: 0 | N8: 0 | O8: 0.121 | P8: 0.092 | Q8: -2.93 | R8: =(G8-F8)*100 -> -5.6 | S8: =R8-H8 -> 0 | T8: =(J8+M8+P8-G8)*100 -> 0 | U8: =D8*F8 -> 32.4005 | V8: =E8*G8 -> 25.3287 | W8: =V8-U8 -> -7.0718 | X8: =E8/E$11 -> 0.22750643 | Y8: =E8/D8-1 -> 0.057067021
A9: 3 | B9: B1 | C9: 2L -5L | D9: 189.3 | E9: 185.7 | F9: 0.207 | G9: 0.152 | H9: -5.52 | I9: 0.093 | J9: 0.065 | K9: -2.78 | L9: 0 | M9: 0 | N9: 0 | O9: 0.114 | P9: 0.086 | Q9: -2.75 | R9: =(G9-F9)*100 -> -5.5 | S9: =R9-H9 -> 0.02 | T9: =(J9+M9+P9-G9)*100 -> -0.1 | U9: =D9*F9 -> 39.1851 | V9: =E9*G9 -> 28.2264 | W9: =V9-U9 -> -10.9587 | X9: =E9/E$11 -> 0.26520994 | Y9: =E9/D9-1 -> -0.019017433
A10: 4 | B10: B1 | C10: >5L | D10: 39.4 | E10: 36.3 | F10: 0.227 | G10: 0.16 | H10: -6.72 | I10: 0.151 | J10: 0.094 | K10: -5.65 | L10: 0 | M10: 0 | N10: 0 | O10: 0.077 | P10: 0.066 | Q10: -1.07 | R10: =(G10-F10)*100 -> -6.7 | S10: =R10-H10 -> 0.02 | T10: =(J10+M10+P10-G10)*100 -> 0 | U10: =D10*F10 -> 8.9438 | V10: =E10*G10 -> 5.808 | W10: =V10-U10 -> -3.1358 | X10: =E10/E$11 -> 0.051842331 | Y10: =E10/D10-1 -> -0.078680203
A11: 5 | B11: B1 | C11: Total | D11: 677.4 | E11: 700.2 | F11: 0.234 | G11: 0.184 | H11: -5 | I11: 0.111 | J11: 0.085 | K11: -2.66 | L11: 0 | M11: 0 | N11: 0 | O11: 0.122 | P11: 0.099 | Q11: -2.33 | R11: =(G11-F11)*100 -> -5 | S11: =R11-H11 -> 0 | T11: =(J11+M11+P11-G11)*100 -> 0 | U11: =D11*F11 -> 158.5116 | V11: =E11*G11 -> 128.8368 | W11: =V11-U11 -> -29.6748 | X11: =SUM(E7:E10)/E11 -> 1 | Y11: =E11/D11-1 -> 0.033658105 | Z11: =(G11-SUMPRODUCT(E7:E10,G7:G10)/SUM(E7:E10))*100 -> 0.038903171
A12: 6 | B12: B2 | C12: < 1L | D12: 112.7 | E12: 112 | F12: 0.115 | G12: 0.086 | H12: -2.94 | I12: 0.033 | J12: 0.023 | K12: -0.96 | L12: 0.008 | M12: 0.005 | N12: -0.26 | O12: 0.075 | P12: 0.058 | Q12: -1.72 | R12: =(G12-F12)*100 -> -2.9 | S12: =R12-H12 -> 0.04 | T12: =(J12+M12+P12-G12)*100 -> 0 | U12: =D12*F12 -> 12.9605 | V12: =E12*G12 -> 9.632 | W12: =V12-U12 -> -3.3285 | X12: =E12/E$16 -> 0.43990573 | Y12: =E12/D12-1 -> -0.0062111801
A13: 7 | B13: B2 | C13: 1L -2L | D13: 57.9 | E13: 56.2 | F13: 0.078 | G13: 0.049 | H13: -2.91 | I13: 0.033 | J13: 0.016 | K13: -1.68 | L13: 0.009 | M13: 0.006 | N13: -0.34 | O13: 0.036 | P13: 0.027 | Q13: -0.89 | R13: =(G13-F13)*100 -> -2.9 | S13: =R13-H13 -> 0.01 | T13: =(J13+M13+P13-G13)*100 -> 0 | U13: =D13*F13 -> 4.5162 | V13: =E13*G13 -> 2.7538 | W13: =V13-U13 -> -1.7624 | X13: =E13/E$16 -> 0.22073841 | Y13: =E13/D13-1 -> -0.029360967
A14: 8 | B14: B2 | C14: 2L -5L | D14: 69.3 | E14: 70.5 | F14: 0.06 | G14: 0.044 | H14: -1.62 | I14: 0.026 | J14: 0.017 | K14: -0.98 | L14: 0.005 | M14: 0.007 | N14: 0.15 | O14: 0.028 | P14: 0.021 | Q14: -0.78 | R14: =(G14-F14)*100 -> -1.6 | S14: =R14-H14 -> 0.02 | T14: =(J14+M14+P14-G14)*100 -> 0.1 | U14: =D14*F14 -> 4.158 | V14: =E14*G14 -> 3.102 | W14: =V14-U14 -> -1.056 | X14: =E14/E$16 -> 0.27690495 | Y14: =E14/D14-1 -> 0.017316017
A15: 9 | B15: B2 | C15: >5L | D15: 18.6 | E15: 15.9 | F15: 0.092 | G15: 0.05 | H15: -4.28 | I15: 0.047 | J15: 0.028 | K15: -1.88 | L15: 0.005 | M15: 0.01 | N15: 0.44 | O15: 0.04 | P15: 0.011 | Q15: -2.84 | R15: =(G15-F15)*100 -> -4.2 | S15: =R15-H15 -> 0.08 | T15: =(J15+M15+P15-G15)*100 -> -0.1 | U15: =D15*F15 -> 1.7112 | V15: =E15*G15 -> 0.795 | W15: =V15-U15 -> -0.9162 | X15: =E15/E$16 -> 0.062450903 | Y15: =E15/D15-1 -> -0.14516129
A16: 10 | B16: B2 | C16: Total | D16: 258.5 | E16: 254.6 | F16: 0.091 | G16: 0.064 | H16: -2.67 | I16: 0.032 | J16: 0.02 | K16: -1.2 | L16: 0.007 | M16: 0.006 | N16: -0.12 | O16: 0.051 | P16: 0.038 | Q16: -1.34 | R16: =(G16-F16)*100 -> -2.7 | S16: =R16-H16 -> -0.03 | T16: =(J16+M16+P16-G16)*100 -> 0 | U16: =D16*F16 -> 23.5235 | V16: =E16*G16 -> 16.2944 | W16: =V16-U16 -> -7.2291 | X16: =SUM(E12:E15)/E16 -> 1 | Y16: =E16/D16-1 -> -0.015087041 | Z16: =(G16-SUMPRODUCT(E12:E15,G12:G15)/SUM(E12:E15))*100 -> 0.0045561665
A17: 11 | B17: B3 | C17: < 1L | D17: 89.9 | E17: 137 | F17: 0.066 | G17: 0.036 | H17: -3 | I17: 0.013 | J17: 0.008 | K17: -0.51 | L17: 0.004 | M17: 0.002 | N17: -0.23 | O17: 0.048 | P17: 0.026 | Q17: -2.25 | R17: =(G17-F17)*100 -> -3 | S17: =R17-H17 -> 0 | T17: =(J17+M17+P17-G17)*100 -> 0 | U17: =D17*F17 -> 5.9334 | V17: =E17*G17 -> 4.932 | W17: =V17-U17 -> -1.0014 | X17: =E17/E$21 -> 0.2557879 | Y17: =E17/D17-1 -> 0.52391546
A18: 12 | B18: B3 | C18: 1L -2L | D18: 67.4 | E18: 137.8 | F18: 0.021 | G18: 0.01 | H18: -1.11 | I18: 0.004 | J18: 0.002 | K18: -0.16 | L18: 0.001 | M18: 0.001 | N18: -0.03 | O18: 0.016 | P18: 0.007 | Q18: -0.92 | R18: =(G18-F18)*100 -> -1.1 | S18: =R18-H18 -> 0.01 | T18: =(J18+M18+P18-G18)*100 -> 0 | U18: =D18*F18 -> 1.4154 | V18: =E18*G18 -> 1.378 | W18: =V18-U18 -> -0.0374 | X18: =E18/E$21 -> 0.25728155 | Y18: =E18/D18-1 -> 1.0445104
A19: 13 | B19: B3 | C19: 2L -5L | D19: 89.7 | E19: 220 | F19: 0.017 | G19: 0.005 | H19: -1.18 | I19: 0.003 | J19: 0.002 | K19: -0.09 | L19: 0.001 | M19: 0 | N19: -0.13 | O19: 0.013 | P19: 0.003 | Q19: -0.96 | R19: =(G19-F19)*100 -> -1.2 | S19: =R19-H19 -> -0.02 | T19: =(J19+M19+P19-G19)*100 -> 0 | U19: =D19*F19 -> 1.5249 | V19: =E19*G19 -> 1.1 | W19: =V19-U19 -> -0.4249 | X19: =E19/E$21 -> 0.41075429 | Y19: =E19/D19-1 -> 1.4526198
A20: 14 | B20: B3 | C20: >5L | D20: 20.5 | E20: 40.8 | F20: 0.021 | G20: 0.008 | H20: -1.3 | I20: 0 | J20: 0.006 | K20: 0.56 | L20: 0.005 | M20: 0 | N20: -0.51 | O20: 0.015 | P20: 0.002 | Q20: -1.35 | R20: =(G20-F20)*100 -> -1.3 | S20: =R20-H20 -> 0 | T20: =(J20+M20+P20-G20)*100 -> 0 | U20: =D20*F20 -> 0.4305 | V20: =E20*G20 -> 0.3264 | W20: =V20-U20 -> -0.1041 | X20: =E20/E$21 -> 0.076176251 | Y20: =E20/D20-1 -> 0.9902439
A21: 15 | B21: B3 | C21: Total | D21: 267.4 | E21: 535.6 | F21: 0.035 | G21: 0.014 | H21: -2.02 | I21: 0.006 | J21: 0.004 | K21: -0.25 | L21: 0.003 | M21: 0.001 | N21: -0.18 | O21: 0.026 | P21: 0.01 | Q21: -1.59 | R21: =(G21-F21)*100 -> -2.1 | S21: =R21-H21 -> -0.08 | T21: =(J21+M21+P21-G21)*100 -> 0.1 | U21: =D21*F21 -> 9.359 | V21: =E21*G21 -> 7.4984 | W21: =V21-U21 -> -1.8606 | X21: =SUM(E17:E20)/E21 -> 1 | Y21: =E21/D21-1 -> 1.0029918 | Z21: =(G21-SUMPRODUCT(E17:E20,G17:G20)/SUM(E17:E20))*100 -> -0.044436146
A23: B. Bucket roll-up (Totals) and page headline checks
A24: # | B24: Item | D24: Jul | E24: Aug | F24: Δ / check
A25: 1 | B25: Pre-NPA currbal B1 + B2 + B3 (₹ Cr) | D25: =D11+D16+D21 -> 1203.3 | E25: =E11+E16+E21 -> 1490.4 | F25: =E25-D25 -> 287.1
A26: 2 | B26: Σ band currbal − Total (max |gap|, all buckets) | D26: =MAX(ABS(SUM(D7:D10)-D11),ABS(SUM(D12:D15)-D16),ABS(SUM(D17:D20)-D21)) -> 0.1 | E26: =MAX(ABS(SUM(E7:E10)-E11),ABS(SUM(E12:E15)-E16),ABS(SUM(E17:E20)-E21)) -> 0
A27: 3 | B27: Resolved ₹ Cr across B1–B3 | D27: =U11+U16+U21 -> 191.3941 | E27: =V11+V16+V21 -> 152.6296 | F27: =E27-D27 -> -38.7645
A28: 4 | B28: Blended pre-NPA resolution % (balance-weighted) | D28: =D27/D25 -> 0.15905767 | E28: =E27/E25 -> 0.10240848 | F28: =(E28-D28)*100 -> -5.6649194
A29: 5 | B29: B3 share of pre-NPA currbal | D29: =D21/D25 -> 0.22222222 | E29: =E21/E25 -> 0.35936661 | F29: =(E29-D29)*100 -> 13.714439
A30: 6 | B30: Headline check: B1 resolution dip printed 5.00 pp vs computed | F30: =H11-R11 -> 0
A31: 7 | B31: Headline check: B2 resolution dip printed 2.67 pp vs computed | F31: =H16-R16 -> 0.03
A32: 8 | B32: Headline check: B3 resolution dip printed 2.02 pp vs computed | F32: =H21-R21 -> 0.08
A33: 9 | B33: Max |printed Var − computed Var| across all 15 rows (pp) | F33: =MAX(ABS(MIN(S7:S21)),MAX(S7:S21)) -> 0.08
A34: 10 | B34: Max |Norm + RB + Stab − Res| (Aug, pp) | F34: =MAX(ABS(MIN(T7:T21)),MAX(T7:T21)) -> 0.1
A35: 11 | B35: Max |Total − balance-weighted bands| (Aug, pp) | F35: =MAX(ABS(Z11),ABS(Z16),ABS(Z21)) -> 0.044436146
A38: Data points to flag before metrics (live checks)
A39: # | B39: Flag | C39: Check value (live) | D39: Unit | E39: Implication / action
A40: 1 | B40: B3 current balance doubled in a month (₹267 Cr → ₹536 Cr) while its resolution fell to 1.4% — the roll from B2 into B3 is accelerating and almost nothing cures once in B3. | C40: =Y21 -> 1.0029918 | D40: % | E40: This is the lead indicator for card NPA formation next month.
A41: 2 | B41: Resolution fell in every band of every bucket (all 15 rows, 12 bands + 3 totals, negative); B1 bands dipped 4.4–6.7 pp. | C41: =COUNTIF(H7:H21,"<0") -> 15 | D41: count | E41: Broad-based deterioration, not a single-band effect.
A42: 3 | B42: B1 is the only bucket where stabilisation (9.9%) still exceeds normalisation (8.5%); in B3 roll-back and normalisation are near zero. | C42: =P11 -> 0.099 | D42: % | E42: Collections capacity should sit in B1 — the only bucket with meaningful cure.
A43: 4 | B43: Pre-NPA currbal grew ₹287 Cr (+24%) MoM; blended resolution fell from 15.9% to 10.2%. | C43: =F28 -> -5.6649194 | D43: pp | E43: Both stock and cure moved the wrong way.
A44: 5 | B44: Printed Var ties to Aug − Jul within rounding (max gap, pp); Norm + RB + Stab ties to Res within 0.1 pp; Totals are balance-weighted. | C44: =F33 -> 0.08 | D44: pp | E44: Table is internally consistent; 'Var' is signed (negative = dip).
...

Sheet B1_Metrics
A1: Pre-NPA card resolution by band: notation and metrics
A2: Format: Notation → Exhaustive metrics table | Example column = live Excel formula on the block sheet (green = cross-sheet)
A3: ⚠ DRAFT ONLY — Requires review and approval by a qualified Alvarez and Marsal professional before use.
A5: Notation
B6: Symbol | C6: Meaning
B7: CB(b,k,m) | C7: Current balance ₹ Cr of bucket b (B1–B3) and band k (< 1L, 1L–2L, 2L–5L, > 5L) for month m (Jul'26 / Aug'26 closing cycles)
B8: Res, Norm, RB, Stab | C8: Resolution, normalisation, roll-back, stabilisation rates (%); Res ≈ Norm + RB + Stab
B9: Var | C9: Aug − Jul in pp, signed as printed
B10: Res₹ | C10: Resolved rupees = CB × Res
B11: Tot(b) | C11: Bucket total = balance-weighted average of bands
B12: Blended | C12: Σ Res₹ ÷ Σ CB across B1–B3
B13: sh(k|b) | C13: CB(b,k) ÷ CB(b)
B14: Balances ₹ Cr; rates in %; Var in pp (signed as printed).
A16: Exhaustive metrics table
A17: # | B17: Metric family | C17: Pipeline-ready metric | D17: Definition / formula | E17: Applies to | F17: Example
A18: 1 | B18: Fact lookup | C18: Current balance | D18: CB(b,k,m) | E18: 15 rows × 2 months | F18: ="B1 / B2 / B3 totals Jul → Aug "&TEXT(B1_PreNPA_Resolution!D11,"#,##0.0")&" / "&TEXT(B1_PreNPA_Resolution!E11,"#,##0.0")&"; "&TEXT(B1_PreNPA_Resolution!D16,"#,##0.0")&" / "&TEXT(B1_PreNPA_Resolution!E16,"#,##0.0")&"; "&TEXT(B1_PreNPA_Resolution!D21,"#,##0.0")&" / "&TEXT(B1_PreNPA_Resolution!E21,"#,##0.0") -> B1 / B2 / B3 totals Jul → Aug 677.4 / 700.2; 258.5 / 254.6; 267.4 / 535.6
A19: 2 | B19: Fact lookup | C19: Rates | D19: Res, Norm, RB, Stab (Jul, Aug) | E19: 15 rows × 4 × 2 | F19: ="B1 Aug "&TEXT(B1_PreNPA_Resolution!G11,"0.00%")&" / "&TEXT(B1_PreNPA_Resolution!J11,"0.00%")&" / "&TEXT(B1_PreNPA_Resolution!M11,"0.00%")&" / "&TEXT(B1_PreNPA_Resolution!P11,"0.00%")&" (Res / Norm / RB / Stab)" -> B1 Aug 18.40% / 8.50% / 0.00% / 9.90% (Res / Norm / RB / Stab)
A20: 3 | B20: Fact lookup | C20: Printed Var | D20: Var (pp) | E20: 15 × 4 | F20: ="B1 "&TEXT(B1_PreNPA_Resolution!H11,"+0.0"" pp"";-0.0"" pp"";0.0"" pp""")&" / "&TEXT(B1_PreNPA_Resolution!K11,"+0.0"" pp"";-0.0"" pp"";0.0"" pp""")&" / "&TEXT(B1_PreNPA_Resolution!N11,"+0.0"" pp"";-0.0"" pp"";0.0"" pp""")&" / "&TEXT(B1_PreNPA_Resolution!Q11,"+0.0"" pp"";-0.0"" pp"";0.0"" pp""") -> B1 -5.0 pp / -2.7 pp / 0.0 pp / -2.3 pp
A21: 4 | B21: Roll-up check | C21: Printed vs computed Var | D21: Var − (Aug − Jul) | E21: 15 rows | F21: ="max |gap| "&TEXT(B1_PreNPA_Resolution!F33,"+0.0"" pp"";-0.0"" pp"";0.0"" pp""") -> max |gap| +0.1 pp
A22: 5 | B22: Roll-up check | C22: Component identity | D22: Norm + RB + Stab − Res (Aug) | E22: 15 rows | F22: ="max |gap| "&TEXT(B1_PreNPA_Resolution!F34,"+0.0"" pp"";-0.0"" pp"";0.0"" pp""") -> max |gap| +0.1 pp
A23: 6 | B23: Roll-up check | C23: Weighted totals | D23: Tot(b) − Σ CB × Res ÷ Σ CB | E23: 3 buckets | F23: =TEXT(B1_PreNPA_Resolution!Z11,"+0.0"" pp"";-0.0"" pp"";0.0"" pp""")&" / "&TEXT(B1_PreNPA_Resolution!Z16,"+0.0"" pp"";-0.0"" pp"";0.0"" pp""")&" / "&TEXT(B1_PreNPA_Resolution!Z21,"+0.0"" pp"";-0.0"" pp"";0.0"" pp""") -> +0.0 pp / +0.0 pp / -0.0 pp
A24: 7 | B24: Roll-up check | C24: Bands to bucket total (currbal) | D24: Σ bands − Total | E24: 3 × 2 | F24: ="Jul "&TEXT(B1_PreNPA_Resolution!D26,"#,##0.00;-#,##0.00;0.00")&"; Aug "&TEXT(B1_PreNPA_Resolution!E26,"#,##0.00;-#,##0.00;0.00") -> Jul 0.10; Aug 0.00
A25: 8 | B25: Resolution | C25: Bucket resolution % | D25: Res(b) | E25: 3 buckets × 2 | F25: ="Jul "&TEXT(B1_PreNPA_Resolution!F11,"0.00%")&" / "&TEXT(B1_PreNPA_Resolution!F16,"0.00%")&" / "&TEXT(B1_PreNPA_Resolution!F21,"0.00%")&"; Aug "&TEXT(B1_PreNPA_Resolution!G11,"0.00%")&" / "&TEXT(B1_PreNPA_Resolution!G16,"0.00%")&" / "&TEXT(B1_PreNPA_Resolution!G21,"0.00%") -> Jul 23.40% / 9.10% / 3.50%; Aug 18.40% / 6.40% / 1.40%
A26: 9 | B26: Resolution | C26: Resolution dip | D26: Var(Res) | E26: 3 buckets + 12 bands | F26: ="B1 / B2 / B3 "&TEXT(B1_PreNPA_Resolution!H11,"+0.0"" pp"";-0.0"" pp"";0.0"" pp""")&" / "&TEXT(B1_PreNPA_Resolution!H16,"+0.0"" pp"";-0.0"" pp"";0.0"" pp""")&" / "&TEXT(B1_PreNPA_Resolution!H21,"+0.0"" pp"";-0.0"" pp"";0.0"" pp""")&"; B1 bands "&TEXT(B1_PreNPA_Resolution!H7,"+0.0"" pp"";-0.0"" pp"";0.0"" pp""")&" / "&TEXT(B1_PreNPA_Resolution!H8,"+0.0"" pp"";-0.0"" pp"";0.0"" pp""")&" / "&TEXT(B1_PreNPA_Resolution!H9,"+0.0"" pp"";-0.0"" pp"";0.0"" pp""")&" / "&TEXT(B1_PreNPA_Resolution!H10,"+0.0"" pp"";-0.0"" pp"";0.0"" pp""") -> B1 / B2 / B3 -5.0 pp / -2.7 pp / -2.0 pp; B1 bands -4.4 pp / -5.6 pp / -5.5 pp / -6.7 pp
A27: 10 | B27: Resolution | C27: Component split of dip | D27: Var(Norm), Var(RB), Var(Stab) | E27: 3 buckets | F27: ="B1 "&TEXT(B1_PreNPA_Resolution!K11,"+0.0"" pp"";-0.0"" pp"";0.0"" pp""")&" / "&TEXT(B1_PreNPA_Resolution!N11,"+0.0"" pp"";-0.0"" pp"";0.0"" pp""")&" / "&TEXT(B1_PreNPA_Resolution!Q11,"+0.0"" pp"";-0.0"" pp"";0.0"" pp""")&"; B2 "&TEXT(B1_PreNPA_Resolution!K16,"+0.0"" pp"";-0.0"" pp"";0.0"" pp""")&" / "&TEXT(B1_PreNPA_Resolution!N16,"+0.0"" pp"";-0.0"" pp"";0.0"" pp""")&" / "&TEXT(B1_PreNPA_Resolution!Q16,"+0.0"" pp"";-0.0"" pp"";0.0"" pp""")&"; B3 "&TEXT(B1_PreNPA_Resolution!K21,"+0.0"" pp"";-0.0"" pp"";0.0"" pp""")&" / "&TEXT(B1_PreNPA_Resolution!N21,"+0.0"" pp"";-0.0"" pp"";0.0"" pp""")&" / "&TEXT(B1_PreNPA_Resolution!Q21,"+0.0"" pp"";-0.0"" pp"";0.0"" pp""") -> B1 -2.7 pp / 0.0 pp / -2.3 pp; B2 -1.2 pp / -0.1 pp / -1.3 pp; B3 -0.3 pp / -0.2 pp / -1.6 pp
A28: 11 | B28: Resolution | C28: Component mix of resolution (Aug) | D28: Norm ÷ Res, Stab ÷ Res | E28: 3 buckets | F28: ="B1 "&TEXT(B1_PreNPA_Resolution!J11/B1_PreNPA_Resolution!G11,"0.0%")&" / "&TEXT(B1_PreNPA_Resolution!P11/B1_PreNPA_Resolution!G11,"0.0%")&"; B2 "&TEXT(B1_PreNPA_Resolution!J16/B1_PreNPA_Resolution!G16,"0.0%")&" / "&TEXT(B1_PreNPA_Resolution!P16/B1_PreNPA_Resolution!G16,"0.0%") -> B1 46.2% / 53.8%; B2 31.3% / 59.4%
A29: 12 | B29: Resolution | C29: Band resolution (Aug) | D29: Res(b,k) | E29: 12 bands | F29: ="B1 "&TEXT(B1_PreNPA_Resolution!G7,"0.00%")&" / "&TEXT(B1_PreNPA_Resolution!G8,"0.00%")&" / "&TEXT(B1_PreNPA_Resolution!G9,"0.00%")&" / "&TEXT(B1_PreNPA_Resolution!G10,"0.00%")&"; B3 "&TEXT(B1_PreNPA_Resolution!G17,"0.00%")&" / "&TEXT(B1_PreNPA_Resolution!G18,"0.00%")&" / "&TEXT(B1_PreNPA_Resolution!G19,"0.00%")&" / "&TEXT(B1_PreNPA_Resolution!G20,"0.00%") -> B1 21.70% / 15.90% / 15.20% / 16.00%; B3 3.60% / 1.00% / 0.50% / 0.80%
A30: 13 | B30: Resolution | C30: Blended pre-NPA resolution | D30: Σ Res₹ ÷ Σ CB | E30: 2 months | F30: =TEXT(B1_PreNPA_Resolution!D28,"0.00%")&" → "&TEXT(B1_PreNPA_Resolution!E28,"0.00%")&"; Δ "&TEXT(B1_PreNPA_Resolution!F28,"+0.0"" pp"";-0.0"" pp"";0.0"" pp""") -> 15.91% → 10.24%; Δ -5.7 pp
A31: 14 | B31: Resolution | C31: Resolved rupees | D31: Res₹(b) | E31: 3 buckets × 2 | F31: ="Jul "&TEXT(B1_PreNPA_Resolution!U11,"#,##0.00;-#,##0.00;0.00")&" / "&TEXT(B1_PreNPA_Resolution!U16,"#,##0.00;-#,##0.00;0.00")&" / "&TEXT(B1_PreNPA_Resolution!U21,"#,##0.00;-#,##0.00;0.00")&"; Aug "&TEXT(B1_PreNPA_Resolution!V11,"#,##0.00;-#,##0.00;0.00")&" / "&TEXT(B1_PreNPA_Resolution!V16,"#,##0.00;-#,##0.00;0.00")&" / "&TEXT(B1_PreNPA_Resolution!V21,"#,##0.00;-#,##0.00;0.00") -> Jul 158.51 / 23.52 / 9.36; Aug 128.84 / 16.29 / 7.50
A32: 15 | B32: Resolution | C32: Change in resolved rupees | D32: Res₹(Aug) − Res₹(Jul) | E32: 3 buckets | F32: =TEXT(B1_PreNPA_Resolution!W11,"#,##0.00;-#,##0.00;0.00")&" / "&TEXT(B1_PreNPA_Resolution!W16,"#,##0.00;-#,##0.00;0.00")&" / "&TEXT(B1_PreNPA_Resolution!W21,"#,##0.00;-#,##0.00;0.00")&"; all "&TEXT(B1_PreNPA_Resolution!E27,"#,##0.00;-#,##0.00;0.00")&" vs "&TEXT(B1_PreNPA_Resolution!D27,"#,##0.00;-#,##0.00;0.00") -> -29.67 / -7.23 / -1.86; all 152.63 vs 191.39
A33: 16 | B33: Stock | C33: Pre-NPA stock and MoM | D33: Σ CB; Aug ÷ Jul − 1 | E33: 2 months | F33: =TEXT(B1_PreNPA_Resolution!D25,"#,##0.00;-#,##0.00;0.00")&" → "&TEXT(B1_PreNPA_Resolution!E25,"#,##0.00;-#,##0.00;0.00")&"; MoM "&TEXT(B1_PreNPA_Resolution!E25/B1_PreNPA_Resolution!D25-1,"+0.0%;-0.0%;0.0%") -> 1,203.30 → 1,490.40; MoM +23.9%
A34: 17 | B34: Stock | C34: Bucket MoM | D34: CB(b, Aug) ÷ CB(b, Jul) − 1 | E34: 3 buckets | F34: =TEXT(B1_PreNPA_Resolution!Y11,"+0.0%;-0.0%;0.0%")&" / "&TEXT(B1_PreNPA_Resolution!Y16,"+0.0%;-0.0%;0.0%")&" / "&TEXT(B1_PreNPA_Resolution!Y21,"+0.0%;-0.0%;0.0%") -> +3.4% / -1.5% / +100.3%
A35: 18 | B35: Stock | C35: B3 share of pre-NPA stock | D35: CB(B3) ÷ Σ CB | E35: 2 months | F35: =TEXT(B1_PreNPA_Resolution!D29,"0.0%")&" → "&TEXT(B1_PreNPA_Resolution!E29,"0.0%") -> 22.2% → 35.9%
A36: 19 | B36: Stock | C36: Band mix within bucket (Aug) | D36: sh(k|b) | E36: 12 bands | F36: ="B1 "&TEXT(B1_PreNPA_Resolution!X7,"0.0%")&" / "&TEXT(B1_PreNPA_Resolution!X8,"0.0%")&" / "&TEXT(B1_PreNPA_Resolution!X9,"0.0%")&" / "&TEXT(B1_PreNPA_Resolution!X10,"0.0%")&"; B3 "&TEXT(B1_PreNPA_Resolution!X17,"0.0%")&" / "&TEXT(B1_PreNPA_Resolution!X18,"0.0%")&" / "&TEXT(B1_PreNPA_Resolution!X19,"0.0%")&" / "&TEXT(B1_PreNPA_Resolution!X20,"0.0%") -> B1 45.5% / 22.8% / 26.5% / 5.2%; B3 25.6% / 25.7% / 41.1% / 7.6%
A37: 20 | B37: Stock | C37: Band MoM (B3) | D37: CB(B3,k) Aug ÷ Jul − 1 | E37: 4 bands | F37: =TEXT(B1_PreNPA_Resolution!Y17,"+0.0%;-0.0%;0.0%")&" / "&TEXT(B1_PreNPA_Resolution!Y18,"+0.0%;-0.0%;0.0%")&" / "&TEXT(B1_PreNPA_Resolution!Y19,"+0.0%;-0.0%;0.0%")&" / "&TEXT(B1_PreNPA_Resolution!Y20,"+0.0%;-0.0%;0.0%") -> +52.4% / +104.5% / +145.3% / +99.0%
A38: 21 | B38: Headline checks | C38: Page claims vs computed | D38: Printed dip − computed | E38: B1, B2, B3 | F38: =TEXT(B1_PreNPA_Resolution!F30,"+0.0"" pp"";-0.0"" pp"";0.0"" pp""")&" / "&TEXT(B1_PreNPA_Resolution!F31,"+0.0"" pp"";-0.0"" pp"";0.0"" pp""")&" / "&TEXT(B1_PreNPA_Resolution!F32,"+0.0"" pp"";-0.0"" pp"";0.0"" pp""") -> 0.0 pp / +0.0 pp / +0.1 pp
A39: 22 | B39: Data integrity | C39: Negative-rate rows | D39: COUNT Var(Res) < 0 | E39: 15 rows | F39: =TEXT(COUNTIF(B1_PreNPA_Resolution!H7:H21,"<0"),"#,##0")&" of 15 rows deteriorated" -> 15 of 15 rows deteriorated
A40: 23 | B40: Data integrity | C40: Timing | D40: Aug cycles to 26 EOD vs full Jul | E40: Page | F40: Dip partly timing; re-run after month-end
A42: ⚠ DRAFT ONLY — Requires review and approval by a qualified Alvarez and Marsal professional before use.

Sheet B2_NPA_TWO_Recovery
A1: Block 2 — NPA (90–120 DPD) and TWO (120+ DPD) collections by balance band
A2: Source: Collection Daily Refresh.pdf | Allocated balance and money collected ₹ Cr, MTD | Jul'26 vs Aug'26
A3: ⚠ DRAFT ONLY — Requires review and approval by a qualified Alvarez and Marsal professional before use.
A5: A. NPA portfolio (90–120 DPD)
A6: # | B6: Balance band | C6: Allocated Jul | D6: Allocated Aug | E6: Collected Jul | F6: Collected Aug | G6: Var ₹ Cr (printed) | H6: Var computed | I6: Var check | J6: Collection rate Jul | K6: Collection rate Aug | L6: Rate Δ (pp) | M6: Allocated MoM | N6: Band share of allocated Aug | O6: Band share of collected Aug | P6: Rate Aug × allocated Jul (volume-neutral collection)
A7: 1 | B7: < 1L | C7: 134.5 | D7: 99.3 | E7: 4.5 | F7: 3.9 | G7: -0.63 | H7: =F7-E7 -> -0.6 | I7: =H7-G7 -> 0.03 | J7: =E7/C7 -> 0.033457249 | K7: =F7/D7 -> 0.039274924 | L7: =(K7-J7)*100 -> 0.58176754 | M7: =D7/C7-1 -> -0.26171004 | N7: =D7/D$13 -> 0.323137 | O7: =F7/F$13 -> 0.46428571 | P7: =K7*C7 -> 5.2824773
A8: 2 | B8: 1L -2L | C8: 121.5 | D8: 77.7 | E8: 2.4 | F8: 2.1 | G8: -0.27 | H8: =F8-E8 -> -0.3 | I8: =H8-G8 -> -0.03 | J8: =E8/C8 -> 0.019753086 | K8: =F8/D8 -> 0.027027027 | L8: =(K8-J8)*100 -> 0.72739406 | M8: =D8/C8-1 -> -0.36049383 | N8: =D8/D$13 -> 0.25284738 | O8: =F8/F$13 -> 0.25 | P8: =K8*C8 -> 3.2837838
A9: 3 | B9: 2L -3L | C9: 92.8 | D9: 59 | E9: 1.6 | F9: 1.2 | G9: -0.44 | H9: =F9-E9 -> -0.4 | I9: =H9-G9 -> 0.04 | J9: =E9/C9 -> 0.017241379 | K9: =F9/D9 -> 0.020338983 | L9: =(K9-J9)*100 -> 0.30976037 | M9: =D9/C9-1 -> -0.36422414 | N9: =D9/D$13 -> 0.19199479 | O9: =F9/F$13 -> 0.14285714 | P9: =K9*C9 -> 1.8874576
A10: 4 | B10: 3L -4L | C10: 55.7 | D10: 31.2 | E10: 0.7 | F10: 0.6 | G10: -0.14 | H10: =F10-E10 -> -0.1 | I10: =H10-G10 -> 0.04 | J10: =E10/C10 -> 0.012567325 | K10: =F10/D10 -> 0.019230769 | L10: =(K10-J10)*100 -> 0.66634443 | M10: =D10/C10-1 -> -0.43985637 | N10: =D10/D$13 -> 0.10152945 | O10: =F10/F$13 -> 0.071428571 | P10: =K10*C10 -> 1.0711538
A11: 5 | B11: 4L -5L | C11: 30.4 | D11: 17.9 | E11: 0.5 | F11: 0.3 | G11: -0.2 | H11: =F11-E11 -> -0.2 | I11: =H11-G11 -> 0 | J11: =E11/C11 -> 0.016447368 | K11: =F11/D11 -> 0.016759777 | L11: =(K11-J11)*100 -> 0.031240812 | M11: =D11/C11-1 -> -0.41118421 | N11: =D11/D$13 -> 0.058249268 | O11: =F11/F$13 -> 0.035714286 | P11: =K11*C11 -> 0.50949721
A12: 6 | B12: >5L | C12: 32.3 | D12: 22.1 | E12: 0.5 | F12: 0.3 | G12: -0.13 | H12: =F12-E12 -> -0.2 | I12: =H12-G12 -> -0.07 | J12: =E12/C12 -> 0.015479876 | K12: =F12/D12 -> 0.013574661 | L12: =(K12-J12)*100 -> -0.19052155 | M12: =D12/C12-1 -> -0.31578947 | N12: =D12/D$13 -> 0.071916694 | O12: =F12/F$13 -> 0.035714286 | P12: =K12*C12 -> 0.43846154
A13: 7 | B13: NPA Total | C13: 467.2 | D13: 307.3 | E13: 10.2 | F13: 8.4 | G13: -1.81 | H13: =F13-E13 -> -1.8 | I13: =H13-G13 -> 0.01 | J13: =E13/C13 -> 0.021832192 | K13: =F13/D13 -> 0.027334852 | L13: =(K13-J13)*100 -> 0.55026602 | M13: =D13/C13-1 -> -0.34225171 | N13: =D13/D$13 -> 1 | O13: =F13/F$13 -> 1 | P13: =K13*C13 -> 12.770843
B14: Σ bands − Total (allocated Jul / Aug; collected Jul / Aug) | C14: =SUM(C7:C12)-C13 -> 0 | D14: =SUM(D7:D12)-D13 -> -0.1 | E14: =SUM(E7:E12)-E13 -> 0 | F14: =SUM(F7:F12)-F13 -> 0
B15: Weighted-rate check: Total rate − Σ collected ÷ Σ allocated (pp) | K15: =(K13-SUM(F7:F12)/SUM(D7:D12))*100 -> -0.00088980638
A17: B. TWO portfolio (120+ DPD, tech write-off)
A18: # | B18: Balance band | C18: Allocated Jul | D18: Allocated Aug | E18: Collected Jul | F18: Collected Aug | G18: Var ₹ Cr (printed) | H18: Var computed | I18: Var check | J18: Collection rate Jul | K18: Collection rate Aug | L18: Rate Δ (pp) | M18: Allocated MoM | N18: Band share of allocated Aug | O18: Band share of collected Aug | P18: Rate Aug × allocated Jul (volume-neutral collection)
A19: 1 | B19: < 1L | C19: 1638.3 | D19: 1251.5 | E19: 14.6 | F19: 14.3 | G19: -0.29 | H19: =F19-E19 -> -0.3 | I19: =H19-G19 -> -0.01 | J19: =E19/C19 -> 0.0089116767 | K19: =F19/D19 -> 0.011426288 | L19: =(K19-J19)*100 -> 0.25146117 | M19: =D19/C19-1 -> -0.23609839 | N19: =D19/D$25 -> 0.43654946 | O19: =F19/F$25 -> 0.64705882 | P19: =K19*C19 -> 18.719688
A20: 2 | B20: 1L -2L | C20: 807.6 | D20: 719.4 | E20: 3.7 | F20: 3.9 | G20: 0.26 | H20: =F20-E20 -> 0.2 | I20: =H20-G20 -> -0.06 | J20: =E20/C20 -> 0.004581476 | K20: =F20/D20 -> 0.0054211843 | L20: =(K20-J20)*100 -> 0.083970834 | M20: =D20/C20-1 -> -0.10921248 | N20: =D20/D$25 -> 0.25094182 | O20: =F20/F$25 -> 0.17647059 | P20: =K20*C20 -> 4.3781485
A21: 3 | B21: 2L -3L | C21: 465.6 | D21: 446.4 | E21: 1.7 | F21: 1.9 | G21: 0.22 | H21: =F21-E21 -> 0.2 | I21: =H21-G21 -> -0.02 | J21: =E21/C21 -> 0.0036512027 | K21: =F21/D21 -> 0.0042562724 | L21: =(K21-J21)*100 -> 0.060506965 | M21: =D21/C21-1 -> -0.041237113 | N21: =D21/D$25 -> 0.15571369 | O21: =F21/F$25 -> 0.085972851 | P21: =K21*C21 -> 1.9817204
A22: 4 | B22: 3L -4L | C22: 247.9 | D22: 245.7 | E22: 0.6 | F22: 1 | G22: 0.33 | H22: =F22-E22 -> 0.4 | I22: =H22-G22 -> 0.07 | J22: =E22/C22 -> 0.0024203308 | K22: =F22/D22 -> 0.0040700041 | L22: =(K22-J22)*100 -> 0.16496733 | M22: =D22/C22-1 -> -0.0088745462 | N22: =D22/D$25 -> 0.085705316 | O22: =F22/F$25 -> 0.045248869 | P22: =K22*C22 -> 1.008954
A23: 5 | B23: 4L -5L | C23: 130.1 | D23: 133.2 | E23: 0.6 | F23: 0.5 | G23: -0.04 | H23: =F23-E23 -> -0.1 | I23: =H23-G23 -> -0.06 | J23: =E23/C23 -> 0.004611837 | K23: =F23/D23 -> 0.0037537538 | L23: =(K23-J23)*100 -> -0.085808329 | M23: =D23/C23-1 -> 0.023827825 | N23: =D23/D$25 -> 0.046462955 | O23: =F23/F$25 -> 0.022624434 | P23: =K23*C23 -> 0.48836336
A24: 6 | B24: >5L | C24: 70.5 | D24: 70.6 | E24: 0.2 | F24: 0.4 | G24: 0.19 | H24: =F24-E24 -> 0.2 | I24: =H24-G24 -> 0.01 | J24: =E24/C24 -> 0.0028368794 | K24: =F24/D24 -> 0.0056657224 | L24: =(K24-J24)*100 -> 0.28288429 | M24: =D24/C24-1 -> 0.0014184397 | N24: =D24/D$25 -> 0.024626762 | O24: =F24/F$25 -> 0.018099548 | P24: =K24*C24 -> 0.39943343
A25: 7 | B25: W-off Recovery Total | C25: 3360 | D25: 2866.8 | E25: 21.4 | F25: 22.1 | G25: 0.67 | H25: =F25-E25 -> 0.7 | I25: =H25-G25 -> 0.03 | J25: =E25/C25 -> 0.0063690476 | K25: =F25/D25 -> 0.0077089438 | L25: =(K25-J25)*100 -> 0.13398962 | M25: =D25/C25-1 -> -0.14678571 | N25: =D25/D$25 -> 1 | O25: =F25/F$25 -> 1 | P25: =K25*C25 -> 25.902051
B26: Σ bands − Total (allocated Jul / Aug; collected Jul / Aug) | C26: =SUM(C19:C24)-C25 -> 0 | D26: =SUM(D19:D24)-D25 -> 0 | E26: =SUM(E19:E24)-E25 -> 0 | F26: =SUM(F19:F24)-F25 -> -0.1
B27: Weighted-rate check: Total rate − Σ collected ÷ Σ allocated (pp) | K27: =(K25-SUM(F19:F24)/SUM(D19:D24))*100 -> 0.0034882099
A30: Data points to flag before metrics (live checks)
A31: # | B31: Flag | C31: Check value (live) | D31: Unit | E31: Implication / action
A32: 1 | B32: NPA allocated balance fell 34% MoM (₹467 Cr → ₹307 Cr) but money collected fell only 18%: the collection rate improved from 2.18% to 2.73%. | C32: =L13 -> 0.55026602 | D32: pp | E32: The 'dip of ₹1.8 Cr' is a smaller pool, not worse collection — report the rate.
A33: 2 | B33: W-off recovery rate rose from 0.64% to 0.77% on a 15% smaller pool; absolute recovery up ₹0.67 Cr as printed. | C33: =L25 -> 0.13398962 | D33: pp | E33: Recovery is improving modestly; still < 1% of pool per month.
A34: 3 | B34: Printed Var equals Aug − Jul collected (max |gap|): | C34: =MAX(ABS(MIN(I7:I13)),MAX(I7:I13),ABS(MIN(I19:I25)),MAX(I19:I25)) -> 0.07 | D34: ₹ Cr | E34: Signed as printed; red arrows = negative.
A35: 4 | B35: Bands add to totals (max |gap|): | C35: =MAX(ABS(MIN(C14:F14)),MAX(C14:F14),ABS(MIN(C26:F26)),MAX(C26:F26)) -> 0.1 | D35: ₹ Cr | E35: Tables roll up.
A36: 5 | B36: Small-ticket (< 1L) dominates: 44% of TWO pool but 65% of TWO recovery; in NPA the < 1L band collects at 3.9% vs 1.4% for > 5L. | C36: =K7 -> 0.039274924 | D36: % | E36: Recovery effort is most productive on small tickets.
A37: 6 | B37: Headline 'NPA money collection dip by 1.805 Cr' vs printed Var −1.81 and computed: | C37: =H13 -> -1.8 | D37: ₹ Cr | E37: Consistent (rounding).
A39: Notation and exhaustive metrics table for this block: see sheet B2_Metrics
A41: 10-question test set (3 Low / 4 Medium / 3 High) — expected answers are live formulas
A42: # | B42: Level | C42: Question | D42: Calculation | E42: Expected answer (live) | F42: Unit | G42: So what
A43: 1 | B43: Low | C43: What is the NPA allocated balance in Aug'26 MTD? | D43: Lookup | E43: =D13 -> 307.3
A44: 2 | B44: Low | C44: How much was recovered from the TWO pool in Aug MTD? | D44: Lookup | E44: =F25 -> 22.1
A45: 3 | B45: Low | C45: What is the TWO < 1L allocated balance in Jul? | D45: Lookup | E45: =C19 -> 1638.3
A46: 4 | B46: Medium | C46: What is the NPA collection rate in Aug vs Jul? | D46: Collected ÷ allocated | E46: =K13 -> 0.027334852 | F46: %
...

Sheet B2_Metrics
A1: NPA and TWO card collections by band: notation and metrics
A2: Format: Notation → Exhaustive metrics table | Example column = live Excel formula on the block sheet (green = cross-sheet)
A3: ⚠ DRAFT ONLY — Requires review and approval by a qualified Alvarez and Marsal professional before use.
A5: Notation
B6: Symbol | C6: Meaning
B7: AB(k,m) | C7: Allocated balance ₹ Cr in band k for month m (Jul / Aug MTD)
B8: MC(k,m) | C8: Money collected ₹ Cr MTD
B9: Var | C9: MC(Aug) − MC(Jul), signed as printed
B10: CR | C10: Collection / recovery rate = MC ÷ AB
B11: NPA / TWO | C11: 90–120 DPD pool / 120+ DPD tech write-off pool
B12: VN | C12: Volume-neutral collection = CR(Aug) × AB(Jul)
B13: sh | C13: Band share of pool total
B14: Amounts ₹ Cr MTD; rates in %; Var in ₹ Cr (signed as printed).
A16: Exhaustive metrics table
A17: # | B17: Metric family | C17: Pipeline-ready metric | D17: Definition / formula | E17: Applies to | F17: Example
A18: 1 | B18: Fact lookup | C18: Allocated balance and collected | D18: AB, MC | E18: 2 pools × 6 bands × 2 months | F18: ="NPA total "&TEXT(B2_NPA_TWO_Recovery!C13,"#,##0.0")&" / "&TEXT(B2_NPA_TWO_Recovery!D13,"#,##0.0")&" / "&TEXT(B2_NPA_TWO_Recovery!E13,"#,##0.0")&" / "&TEXT(B2_NPA_TWO_Recovery!F13,"#,##0.0")&"; TWO total "&TEXT(B2_NPA_TWO_Recovery!C25,"#,##0.0")&" / "&TEXT(B2_NPA_TWO_Recovery!D25,"#,##0.0")&" / "&TEXT(B2_NPA_TWO_Recovery!E25,"#,##0.0")&" / "&TEXT(B2_NPA_TWO_Recovery!F25,"#,##0.0") -> NPA total 467.2 / 307.3 / 10.2 / 8.4; TWO total 3,360.0 / 2,866.8 / 21.4 / 22.1
A19: 2 | B19: Roll-up check | C19: Printed Var vs computed | D19: Var − (MC Aug − MC Jul) | E19: 14 rows | F19: ="NPA "&TEXT(B2_NPA_TWO_Recovery!I7,"#,##0.00;-#,##0.00;0.00")&" / "&TEXT(B2_NPA_TWO_Recovery!I8,"#,##0.00;-#,##0.00;0.00")&" / "&TEXT(B2_NPA_TWO_Recovery!I9,"#,##0.00;-#,##0.00;0.00")&" / "&TEXT(B2_NPA_TWO_Recovery!I10,"#,##0.00;-#,##0.00;0.00")&" / "&TEXT(B2_NPA_TWO_Recovery!I11,"#,##0.00;-#,##0.00;0.00")&" / "&TEXT(B2_NPA_TWO_Recovery!I12,"#,##0.00;-#,##0.00;0.00")&" / "&TEXT(B2_NPA_TWO_Recovery!I13,"#,##0.00;-#,##0.00;0.00")&"; TWO max "&TEXT(MAX(ABS(MIN(B2_NPA_TWO_Recovery!I19:I25)),MAX(B2_NPA_TWO_Recovery!I19:I25)),"#,##0.00;-#,##0.00;0.00") -> NPA 0.03 / -0.03 / 0.04 / 0.04 / 0.00 / -0.07 / 0.01; TWO max 0.07
A20: 3 | B20: Roll-up check | C20: Bands to total | D20: Σ bands − Total | E20: 2 pools × 4 columns | F20: ="NPA "&TEXT(B2_NPA_TWO_Recovery!C14,"#,##0.00;-#,##0.00;0.00")&" / "&TEXT(B2_NPA_TWO_Recovery!D14,"#,##0.00;-#,##0.00;0.00")&" / "&TEXT(B2_NPA_TWO_Recovery!E14,"#,##0.00;-#,##0.00;0.00")&" / "&TEXT(B2_NPA_TWO_Recovery!F14,"#,##0.00;-#,##0.00;0.00")&"; TWO "&TEXT(B2_NPA_TWO_Recovery!C26,"#,##0.00;-#,##0.00;0.00")&" / "&TEXT(B2_NPA_TWO_Recovery!D26,"#,##0.00;-#,##0.00;0.00")&" / "&TEXT(B2_NPA_TWO_Recovery!E26,"#,##0.00;-#,##0.00;0.00")&" / "&TEXT(B2_NPA_TWO_Recovery!F26,"#,##0.00;-#,##0.00;0.00") -> NPA 0.00 / -0.10 / 0.00 / 0.00; TWO 0.00 / 0.00 / 0.00 / -0.10
A21: 4 | B21: Roll-up check | C21: Total rate is weighted | D21: CR(Total) − Σ MC ÷ Σ AB | E21: 2 pools | F21: ="NPA "&TEXT(B2_NPA_TWO_Recovery!K15,"+0.0"" pp"";-0.0"" pp"";0.0"" pp""")&"; TWO "&TEXT(B2_NPA_TWO_Recovery!K27,"+0.0"" pp"";-0.0"" pp"";0.0"" pp""") -> NPA -0.0 pp; TWO +0.0 pp
A22: 5 | B22: Recovery | C22: Collection rate | D22: CR(Total), Jul / Aug | E22: 2 pools | F22: ="NPA "&TEXT(B2_NPA_TWO_Recovery!J13,"0.00%")&" → "&TEXT(B2_NPA_TWO_Recovery!K13,"0.00%")&"; TWO "&TEXT(B2_NPA_TWO_Recovery!J25,"0.00%")&" → "&TEXT(B2_NPA_TWO_Recovery!K25,"0.00%") -> NPA 2.18% → 2.73%; TWO 0.64% → 0.77%
A23: 6 | B23: Recovery | C23: Rate change | D23: CR(Aug) − CR(Jul) | E23: 2 pools + 12 bands | F23: ="NPA "&TEXT(B2_NPA_TWO_Recovery!L13,"+0.0"" pp"";-0.0"" pp"";0.0"" pp""")&"; TWO "&TEXT(B2_NPA_TWO_Recovery!L25,"+0.0"" pp"";-0.0"" pp"";0.0"" pp""")&"; NPA < 1L "&TEXT(B2_NPA_TWO_Recovery!L7,"+0.0"" pp"";-0.0"" pp"";0.0"" pp""")&"; TWO 3L–4L "&TEXT(B2_NPA_TWO_Recovery!L22,"+0.0"" pp"";-0.0"" pp"";0.0"" pp""") -> NPA +0.6 pp; TWO +0.1 pp; NPA < 1L +0.6 pp; TWO 3L–4L +0.2 pp
A24: 7 | B24: Recovery | C24: Band collection rate (Aug) | D24: CR(k) | E24: 12 bands | F24: ="NPA "&TEXT(B2_NPA_TWO_Recovery!K7,"0.00%")&" / "&TEXT(B2_NPA_TWO_Recovery!K8,"0.00%")&" / "&TEXT(B2_NPA_TWO_Recovery!K9,"0.00%")&" / "&TEXT(B2_NPA_TWO_Recovery!K10,"0.00%")&" / "&TEXT(B2_NPA_TWO_Recovery!K11,"0.00%")&" / "&TEXT(B2_NPA_TWO_Recovery!K12,"0.00%")&"; TWO "&TEXT(B2_NPA_TWO_Recovery!K19,"0.00%")&" / "&TEXT(B2_NPA_TWO_Recovery!K20,"0.00%")&" / "&TEXT(B2_NPA_TWO_Recovery!K21,"0.00%")&" / "&TEXT(B2_NPA_TWO_Recovery!K22,"0.00%")&" / "&TEXT(B2_NPA_TWO_Recovery!K23,"0.00%")&" / "&TEXT(B2_NPA_TWO_Recovery!K24,"0.00%") -> NPA 3.93% / 2.70% / 2.03% / 1.92% / 1.68% / 1.36%; TWO 1.14% / 0.54% / 0.43% / 0.41% / 0.38% / 0.57%
A25: 8 | B25: Recovery | C25: Annualised recovery rate | D25: CR × 12 | E25: 2 pools | F25: ="NPA "&TEXT(B2_NPA_TWO_Recovery!K13*12,"0.0%")&"; TWO "&TEXT(B2_NPA_TWO_Recovery!K25*12,"0.0%") -> NPA 32.8%; TWO 9.3%
A26: 9 | B26: Recovery | C26: Volume-neutral collection | D26: VN = CR(Aug) × AB(Jul) | E26: 2 pools | F26: ="NPA "&TEXT(B2_NPA_TWO_Recovery!P13,"#,##0.00;-#,##0.00;0.00")&" vs actual Jul "&TEXT(B2_NPA_TWO_Recovery!E13,"#,##0.00;-#,##0.00;0.00")&"; TWO "&TEXT(B2_NPA_TWO_Recovery!P25,"#,##0.00;-#,##0.00;0.00")&" vs "&TEXT(B2_NPA_TWO_Recovery!E25,"#,##0.00;-#,##0.00;0.00") -> NPA 12.77 vs actual Jul 10.20; TWO 25.90 vs 21.40
A27: 10 | B27: Recovery | C27: Pool vs rate decomposition of Var | D27: Pool effect = (AB Aug − AB Jul) × CR Jul; rate effect = Var − pool effect | E27: 2 pools | F27: ="NPA pool "&TEXT((B2_NPA_TWO_Recovery!D13-B2_NPA_TWO_Recovery!C13)*B2_NPA_TWO_Recovery!J13,"#,##0.00;-#,##0.00;0.00")&" / rate "&TEXT(B2_NPA_TWO_Recovery!H13-(B2_NPA_TWO_Recovery!D13-B2_NPA_TWO_Recovery!C13)*B2_NPA_TWO_Recovery!J13,"#,##0.00;-#,##0.00;0.00")&"; TWO pool "&TEXT((B2_NPA_TWO_Recovery!D25-B2_NPA_TWO_Recovery!C25)*B2_NPA_TWO_Recovery!J25,"#,##0.00;-#,##0.00;0.00")&" / rate "&TEXT(B2_NPA_TWO_Recovery!H25-(B2_NPA_TWO_Recovery!D25-B2_NPA_TWO_Recovery!C25)*B2_NPA_TWO_Recovery!J25,"#,##0.00;-#,##0.00;0.00") -> NPA pool -3.49 / rate 1.69; TWO pool -3.14 / rate 3.84
A28: 11 | B28: Stock | C28: Pool MoM | D28: AB(Aug) ÷ AB(Jul) − 1 | E28: 2 pools + bands | F28: ="NPA "&TEXT(B2_NPA_TWO_Recovery!M13,"+0.0%;-0.0%;0.0%")&"; TWO "&TEXT(B2_NPA_TWO_Recovery!M25,"+0.0%;-0.0%;0.0%")&"; NPA < 1L "&TEXT(B2_NPA_TWO_Recovery!M7,"+0.0%;-0.0%;0.0%")&"; NPA 3L–4L "&TEXT(B2_NPA_TWO_Recovery!M10,"+0.0%;-0.0%;0.0%") -> NPA -34.2%; TWO -14.7%; NPA < 1L -26.2%; NPA 3L–4L -44.0%
A29: 12 | B29: Stock | C29: Band mix (Aug) | D29: sh(k) of allocated; of collected | E29: 12 bands | F29: ="NPA < 1L "&TEXT(B2_NPA_TWO_Recovery!N7,"0.0%")&" / "&TEXT(B2_NPA_TWO_Recovery!O7,"0.0%")&"; TWO < 1L "&TEXT(B2_NPA_TWO_Recovery!N19,"0.0%")&" / "&TEXT(B2_NPA_TWO_Recovery!O19,"0.0%") -> NPA < 1L 32.3% / 46.4%; TWO < 1L 43.7% / 64.7%
A30: 13 | B30: Stock | C30: TWO ÷ NPA pool ratio | D30: AB(TWO) ÷ AB(NPA) | E30: 2 months | F30: =TEXT(B2_NPA_TWO_Recovery!C25/B2_NPA_TWO_Recovery!C13,"0.00""x""")&" → "&TEXT(B2_NPA_TWO_Recovery!D25/B2_NPA_TWO_Recovery!D13,"0.00""x""") -> 7.19x → 9.33x
A31: 14 | B31: Concentration | C31: Small-ticket share of recovery | D31: MC(< 1L) ÷ MC(Total) | E31: 2 pools | F31: ="NPA "&TEXT(B2_NPA_TWO_Recovery!O7,"0.0%")&"; TWO "&TEXT(B2_NPA_TWO_Recovery!O19,"0.0%") -> NPA 46.4%; TWO 64.7%
A32: 15 | B32: Headline checks | C32: Page claims | D32: NPA dip 1.805; W-off up 67.16 lakh | E32: 2 claims | F32: ="NPA "&TEXT(B2_NPA_TWO_Recovery!H13,"#,##0.00;-#,##0.00;0.00")&"; TWO "&TEXT(B2_NPA_TWO_Recovery!H25,"#,##0.00;-#,##0.00;0.00") -> NPA -1.80; TWO 0.70
A33: 16 | B33: Data integrity | C33: Pool drop | D33: NPA AB −34% MoM | E33: Page | F33: =TEXT(B2_NPA_TWO_Recovery!M13,"+0.0%;-0.0%;0.0%")&" — reason (write-off / upgrade / sale) not on page; refresh after the 10th per note" -> -34.2% — reason (write-off / upgrade / sale) not on page; refresh after the 10th per note
A35: ⚠ DRAFT ONLY — Requires review and approval by a qualified Alvarez and Marsal professional before use.
