Workbook

Sheet README
A1: RBL Bank — Retail Assets Collections Efficiency (daily snapshot, 23-Aug-2026): page-wise metric extraction
A2: Source: 14_Retail_Assets_Collections_Efficiency.pdf (1 page, 6 tables) | counts, ₹ Cr, % | data as on 23-08-2026, base data Aug-2026
A3: ⚠ DRAFT ONLY — Requires review and approval by a qualified Alvarez and Marsal professional before use.
A5: Sheet map
A6: B1_Bounce_Allocation | B6: Block 1 — bounce KPI strip, allocation-team resolution (same-day vs previous months and EOM, with target), 6-month resolution trend
A7: B1_Metrics | B7: Notation + metrics for Block 1
A8: B2_NPA_Vintage | B8: Block 2 — NPA recovery / upgrade by DPD bucket and Tech-off, vintage view, 6-month NPA ROR% trend
A9: B2_Metrics | B9: Notation + metrics for Block 2
A11: Colour legend
A12: Blue text | B12: Hard-coded input transcribed from the PDF
A13: Blue italic on grey | B13: Budget / projected value (ᴾ) transcribed from the PDF
A14: Black text | B14: Formula on the same sheet
A15: Green text | B15: Link to another sheet
A16: Yellow fill | B16: Data flag to review
A18: Key assumptions (confirm with client)
A19: 1 | B19: 'Same Day Previous Months' = resolution achieved by the 23rd of Mar / Jun / Jul; 'EOM' = full-month resolution. The current-month % RES (to 23-Aug) is therefore compared with the same-day columns, not with EOM.
A20: 2 | B20: % RES = RES POS ÷ POS; STAB% + RB% + NORM% = % RES; NR+RB% = NORM% + RB%. Verified live for all rows.
A21: 3 | B21: In the NPA table, ROR% = (Reco + Upg ₹) ÷ POS ₹; Reco + Upg = Reco + Upg in both # and ₹. The 6-month 'NPA ROR%' trend uses a different base from the EOM % in the NPA table (e.g. DPD <=90 Jul: 8.21% vs 8.86%) — flagged.
A22: 4 | B22: Vintage-table same-day % totals (0.92 / 1.20 / 1.10) differ from the NPA-table same-day % totals (1.31 / 1.95 / 1.68) although EOM totals agree — two bases on one page; flagged.
A23: 5 | B23: Percentages in brackets on the page (e.g. '(2.61%)') are formatting, not negatives; values are read as positive rates.
A24: Confidentiality | B24: Client-confidential RBL Bank data (retail-assets collections).
A26: ⚠ DRAFT ONLY — Requires review and approval by a qualified Alvarez and Marsal professional before use.

Sheet B1_Bounce_Allocation
A1: Block 1 — Bounce KPIs, allocation-team resolution and 6-month resolution trend
A2: Source: Retail Assets – Collections Efficiency.pdf | counts, ₹ Cr, % | as on 23-08-2026
A3: ⚠ DRAFT ONLY — Requires review and approval by a qualified Alvarez and Marsal professional before use.
A5: A. Bounce KPI strip (blue) with derived ratios
A6: # | B6: KPI | C6: Value | D6: Unit | E6: Derived | F6: Value
A7: 1 | B7: Total Book # | C7: 161579 | D7: count | E7: Current book share of total (#) | F7: =C9/C7 -> 0.59452652
A8: 2 | B8: Total Book ₹ Cr | C8: 48768.14 | D8: ₹ Cr | E8: Current book share of total (₹) | F8: =C10/C8 -> 0.66363245
A9: 3 | B9: Current Book # | C9: 96063 | D9: count | E9: Book ATS total (₹ lakh) | F9: =C8*100/C7 -> 30.182227
A10: 4 | B10: Current Book ₹ Cr | C10: 32364.12 | D10: ₹ Cr | E10: Book ATS current (₹ lakh) | F10: =C10*100/C9 -> 33.690516
A11: 5 | B11: Bounce # (%) | C11: 0.1573 | D11: % | E11: Bounced ₹ Cr implied = Current book ₹ × Bounce ₹ % | F11: =C10*C12 -> 2246.0699
A12: 6 | B12: Bounce ₹ (%) | C12: 0.0694 | D12: % | E12: Bounced # implied = Current book # × Bounce # % | F12: =C9*C11 -> 15110.71
A13: 7 | B13: Not-to-be-Present ratio | C13: 0.0396 | D13: % | E13: Implied bounced ATS (₹ lakh) | F13: =F11*100/F12 -> 14.864093
A14: 8 | B14: EOM bounce rate Mar-26 | C14: 0.0725 | D14: % | E14: Bounce ₹ % vs EOM Jul (pp) | F14: =(C12-C16)*100 -> -0.7
A15: 9 | B15: EOM bounce rate Jun-26 | C15: 0.0732 | D15: % | E15: EOM bounce drift Mar → Jul (pp) | F15: =(C16-C14)*100 -> 0.39
A16: 10 | B16: EOM bounce rate Jul-26 | C16: 0.0764 | D16: %
A17: 11 | B17: Best month (label) | C17: Sept-25 | D17: text
A19: B. Allocation-team resolution (blue) with live checks — current = to 23-Aug-26
A20: # | B20: Allocation team | C20: # accounts | D20: POS ₹ Cr | E20: RES # | F20: RES POS ₹ Cr | G20: STAB % | H20: RB % | I20: NORM % | J20: NR+RB % | K20: % RES | L20: Target % | M20: Same-day Mar | N20: Same-day Jun | O20: Same-day Jul | P20: EOM Mar | Q20: EOM Jun | R20: EOM Jul | S20: % RES computed | T20: Check RES (pp) | U20: Check STAB+RB+NORM (pp) | V20: Check NR+RB (pp) | W20: Current vs same-day Jul (pp) | X20: Current vs same-day avg (pp) | Y20: Gap to target (pp) | Z20: Jul same-day → EOM uplift (pp) | AA20: Implied EOM at Jul uplift | AB20: Resolution by # (RES # ÷ #) | AC20: ATS ₹ lakh | AD20: Unresolved POS ₹ Cr
A21: 1 | B21: Digital Collection (incl. Field Referred) | C21: 2267 | D21: 279.79 | E21: 924 | F21: 129.95 | G21: 0 | H21: 0 | I21: 0.4645 | J21: 0.4645 | K21: 0.4645 | L21: 0.6714 | M21: 0.5591 | N21: 0.4789 | O21: 0.5513 | P21: 0.5591 | Q21: 0.4788 | R21: 0.5521 | S21: =F21/D21 -> 0.46445548 | T21: =(S21-K21)*100 -> -0.004451553 | U21: =(G21+H21+I21-K21)*100 -> 0 | V21: =(I21+H21-J21)*100 -> 0 | W21: =(K21-O21)*100 -> -8.68 | X21: =(K21-AVERAGE(M21:O21))*100 -> -6.5266667 | Y21: =(K21-L21)*100 -> -20.69 | Z21: =(R21-O21)*100 -> 0.08 | AA21: =K21+(R21-O21) -> 0.4653 | AB21: =E21/C21 -> 0.40758712 | AC21: =D21*100/C21 -> 12.341861 | AD21: =D21-F21 -> 149.84
A22: 2 | B22: Telecalling (incl. Field Referred) | C22: 3643 | D22: 457.12 | E22: 1730 | F22: 338.93 | G22: 0 | H22: 0 | I22: 0.7414 | J22: 0.7414 | K22: 0.7414 | L22: 0.7429 | M22: 0.6746 | N22: 0.8141 | O22: 0.7862 | P22: 0.7554 | Q22: 0.8655 | R22: 0.8897 | S22: =F22/D22 -> 0.74144645 | T22: =(S22-K22)*100 -> 0.0046447322 | U22: =(G22+H22+I22-K22)*100 -> 0 | V22: =(I22+H22-J22)*100 -> 0 | W22: =(K22-O22)*100 -> -4.48 | X22: =(K22-AVERAGE(M22:O22))*100 -> -1.69 | Y22: =(K22-L22)*100 -> -0.15 | Z22: =(R22-O22)*100 -> 10.35 | AA22: =K22+(R22-O22) -> 0.8449 | AB22: =E22/C22 -> 0.47488334 | AC22: =D22*100/C22 -> 12.5479 | AD22: =D22-F22 -> 118.19
A23: 3 | B23: Telecalling (excl. Field Referred) | C23: 2501 | D23: 501.72 | E23: 2122 | F23: 417.98 | G23: 0 | H23: 0 | I23: 0.8331 | J23: 0.8331 | K23: 0.8331 | L23: 1 | M23: 0.8826 | N23: 0.9132 | O23: 0.8762 | P23: 0.9916 | Q23: 0.995 | R23: 0.9994 | S23: =F23/D23 -> 0.83309416 | T23: =(S23-K23)*100 -> -0.0005843897 | U23: =(G23+H23+I23-K23)*100 -> 0 | V23: =(I23+H23-J23)*100 -> 0 | W23: =(K23-O23)*100 -> -4.31 | X23: =(K23-AVERAGE(M23:O23))*100 -> -5.7566667 | Y23: =(K23-L23)*100 -> -16.69 | Z23: =(R23-O23)*100 -> 12.32 | AA23: =K23+(R23-O23) -> 0.9563 | AB23: =E23/C23 -> 0.84846062 | AC23: =D23*100/C23 -> 20.060776 | AD23: =D23-F23 -> 83.74
A24: 4 | B24: Sales | C24: 3989 | D24: 84.61 | E24: 2253 | F24: 49.69 | G24: 0 | H24: 0 | I24: 0.5873 | J24: 0.5873 | K24: 0.5873 | L24: 1 | M24: 0.7536 | N24: 0.6973 | O24: 0.7129 | P24: 0.9693 | Q24: 0.9491 | R24: 0.9657 | S24: =F24/D24 -> 0.58728283 | T24: =(S24-K24)*100 -> -0.0017172911 | U24: =(G24+H24+I24-K24)*100 -> 0 | V24: =(I24+H24-J24)*100 -> 0 | W24: =(K24-O24)*100 -> -12.56 | X24: =(K24-AVERAGE(M24:O24))*100 -> -13.396667 | Y24: =(K24-L24)*100 -> -41.27 | Z24: =(R24-O24)*100 -> 25.28 | AA24: =K24+(R24-O24) -> 0.8401 | AB24: =E24/C24 -> 0.56480321 | AC24: =D24*100/C24 -> 2.121083 | AD24: =D24-F24 -> 34.92
A25: 5 | B25: Field Tele Employee (FTE) | C25: 9284 | D25: 526.98 | E25: 2666 | F25: 155.26 | G25: 0 | H25: 0 | I25: 0.2946 | J25: 0.2946 | K25: 0.2946 | L25: 0.9676 | M25: 0.2635 | N25: 0.3843 | O25: 0.3833 | P25: 0.9502 | Q25: 0.957 | R25: 0.9644 | S25: =F25/D25 -> 0.29462219 | T25: =(S25-K25)*100 -> 0.00221868 | U25: =(G25+H25+I25-K25)*100 -> 0 | V25: =(I25+H25-J25)*100 -> 0 | W25: =(K25-O25)*100 -> -8.87 | X25: =(K25-AVERAGE(M25:O25))*100 -> -4.91 | Y25: =(K25-L25)*100 -> -67.3 | Z25: =(R25-O25)*100 -> 58.11 | AA25: =K25+(R25-O25) -> 0.8757 | AB25: =E25/C25 -> 0.28716071 | AC25: =D25*100/C25 -> 5.6762171 | AD25: =D25-F25 -> 371.72
A26: 6 | B26: Field (Day1) | C26: 6491 | D26: 450.61 | E26: 1338 | F26: 125.03 | G26: 0 | H26: 0 | I26: 0.2775 | J26: 0.2775 | K26: 0.2775 | L26: 0.9677 | M26: 0.1682 | N26: 0.357 | O26: 0.3638 | P26: 0.9532 | Q26: 0.9628 | R26: 0.9647 | S26: =F26/D26 -> 0.27746832 | T26: =(S26-K26)*100 -> -0.0031679279 | U26: =(G26+H26+I26-K26)*100 -> 0 | V26: =(I26+H26-J26)*100 -> 0 | W26: =(K26-O26)*100 -> -8.63 | X26: =(K26-AVERAGE(M26:O26))*100 -> -1.8833333 | Y26: =(K26-L26)*100 -> -69.02 | Z26: =(R26-O26)*100 -> 60.09 | AA26: =K26+(R26-O26) -> 0.8784 | AB26: =E26/C26 -> 0.20613157 | AC26: =D26*100/C26 -> 6.9420736 | AD26: =D26-F26 -> 325.58
A27: 7 | B27: Field (TC Ref) | C27: 2793 | D27: 69.87 | E27: 921 | F27: 28.19 | G27: 0 | H27: 0 | I27: 0.4034 | J27: 0.4034 | K27: 0.4034 | L27: 0.9677 | M27: 0.4429 | N27: 0.5466 | O27: 0.5024 | P27: 0.9447 | Q27: 0.9278 | R27: 0.9675 | S27: =F27/D27 -> 0.40346358 | T27: =(S27-K27)*100 -> 0.0063575211 | U27: =(G27+H27+I27-K27)*100 -> 0 | V27: =(I27+H27-J27)*100 -> 0 | W27: =(K27-O27)*100 -> -9.9 | X27: =(K27-AVERAGE(M27:O27))*100 -> -9.39 | Y27: =(K27-L27)*100 -> -56.43 | Z27: =(R27-O27)*100 -> 46.51 | AA27: =K27+(R27-O27) -> 0.8685 | AB27: =E27/C27 -> 0.32975295 | AC27: =D27*100/C27 -> 2.5016112 | AD27: =D27-F27 -> 41.68
A28: 8 | B28: B1 | C28: 14575 | D28: 1232.22 | E28: 7277 | F28: 749.35 | G28: 0 | H28: 0 | I28: 0.6081 | J28: 0.6081 | K28: 0.6081 | L28: 0.9779 | M28: 0.6397 | N28: 0.6852 | O28: 0.6883 | P28: 0.9742 | Q28: 0.9766 | R28: 0.9837 | S28: =F28/D28 -> 0.60813004 | T28: =(S28-K28)*100 -> 0.0030041713 | U28: =(G28+H28+I28-K28)*100 -> 0 | V28: =(I28+H28-J28)*100 -> 0 | W28: =(K28-O28)*100 -> -8.02 | X28: =(K28-AVERAGE(M28:O28))*100 -> -6.2966667 | Y28: =(K28-L28)*100 -> -36.98 | Z28: =(R28-O28)*100 -> 29.54 | AA28: =K28+(R28-O28) -> 0.9035 | AB28: =E28/C28 -> 0.49927959 | AC28: =D28*100/C28 -> 8.4543396 | AD28: =D28-F28 -> 482.87
A29: 9 | B29: B2 | C29: 2200 | D29: 147.1 | E29: 606 | F29: 16.92 | G29: 0.0972 | H29: 0 | I29: 0.0178 | J29: 0.0178 | K29: 0.115 | L29: 0.8886 | M29: 0.2215 | N29: 0.1449 | O29: 0.2154 | P29: 0.848 | Q29: 0.7803 | R29: 0.8474 | S29: =F29/D29 -> 0.11502379 | T29: =(S29-K29)*100 -> 0.0023793338 | U29: =(G29+H29+I29-K29)*100 -> 0 | V29: =(I29+H29-J29)*100 -> 0 | W29: =(K29-O29)*100 -> -10.04 | X29: =(K29-AVERAGE(M29:O29))*100 -> -7.8933333 | Y29: =(K29-L29)*100 -> -77.36 | Z29: =(R29-O29)*100 -> 63.2 | AA29: =K29+(R29-O29) -> 0.747 | AB29: =E29/C29 -> 0.27545455 | AC29: =D29*100/C29 -> 6.6863636 | AD29: =D29-F29 -> 130.18
A30: 10 | B30: B3 | C30: 1468 | D30: 103.04 | E30: 308 | F30: 10.96 | G30: 0.0945 | H30: 0.0025 | I30: 0.0094 | J30: 0.0119 | K30: 0.1064 | L30: 0.8686 | M30: 0.1657 | N30: 0.1954 | O30: 0.1874 | P30: 0.9496 | Q30: 0.9071 | R30: 0.8381 | S30: =F30/D30 -> 0.10636646 | T30: =(S30-K30)*100 -> -0.0033540373 | U30: =(G30+H30+I30-K30)*100 -> 0 | V30: =(I30+H30-J30)*100 -> 0 | W30: =(K30-O30)*100 -> -8.1 | X30: =(K30-AVERAGE(M30:O30))*100 -> -7.6433333 | Y30: =(K30-L30)*100 -> -76.22 | Z30: =(R30-O30)*100 -> 65.07 | AA30: =K30+(R30-O30) -> 0.7571 | AB30: =E30/C30 -> 0.20980926 | AC30: =D30*100/C30 -> 7.0190736 | AD30: =D30-F30 -> 92.08
B31: B1 + B2 + B3: POS / RES POS / blended % RES / unresolved | D31: =D28+D29+D30 -> 1482.36 | F31: =F28+F29+F30 -> 777.23 | K31: =F31/D31 -> 0.52431933 | AD31: =D31-F31 -> 705.13
B32: Σ channel rows (Digital … Field TC Ref) POS vs B1 POS — channels are a different cut | D32: =SUM(D21:D27) -> 2370.7 | F32: =D32-D28 -> 1138.48
A34: C. Resolution — last 6 months (blue, EOM %)
A35: # | B35: Team | C35: Feb-26 | D35: Mar-26 | E35: Apr-26 | F35: May-26 | G35: Jun-26 | H35: Jul-26 | I35: Jul vs Jun (pp) | J35: Jul vs Feb (pp) | K35: 6M avg | L35: 6M min | M35: 6M max | N35: Jul rank in 6M (1 = best) | O35: Check vs EOM Jul in table B (pp)
A36: 1 | B36: A. Digital Collection (incl. Field Referred) | C36: 0.4906 | D36: 0.5591 | E36: 0.6233 | F36: 0.5335 | G36: 0.4788 | H36: 0.5521 | I36: =(H36-G36)*100 -> 7.33 | J36: =(H36-C36)*100 -> 6.15 | K36: =AVERAGE(C36:H36) -> 0.53956667 | L36: =MIN(C36:H36) -> 0.4788 | M36: =MAX(C36:H36) -> 0.6233 | N36: =RANK(H36,C36:H36) -> 3 | O36: =(H36-R21)*100 -> 0
A37: 2 | B37: B. Telecalling (incl. Field Referred) | C37: 0.8628 | D37: 0.7554 | E37: 0.8185 | F37: 0.7785 | G37: 0.8655 | H37: 0.8897 | I37: =(H37-G37)*100 -> 2.42 | J37: =(H37-C37)*100 -> 2.69 | K37: =AVERAGE(C37:H37) -> 0.8284 | L37: =MIN(C37:H37) -> 0.7554 | M37: =MAX(C37:H37) -> 0.8897 | N37: =RANK(H37,C37:H37) -> 1 | O37: =(H37-R22)*100 -> 0
A38: 3 | B38: C. Telecalling (excl. Field Referred) | C38: 0.9953 | D38: 0.9916 | E38: 0.9887 | F38: 0.9978 | G38: 0.995 | H38: 0.9994 | I38: =(H38-G38)*100 -> 0.44 | J38: =(H38-C38)*100 -> 0.41 | K38: =AVERAGE(C38:H38) -> 0.99463333 | L38: =MIN(C38:H38) -> 0.9887 | M38: =MAX(C38:H38) -> 0.9994 | N38: =RANK(H38,C38:H38) -> 1 | O38: =(H38-R23)*100 -> 0
A39: 4 | B39: D. Sales | C39: 0.9589 | D39: 0.9693 | E39: 0.9994 | F39: 0.965 | G39: 0.9491 | H39: 0.9657 | I39: =(H39-G39)*100 -> 1.66 | J39: =(H39-C39)*100 -> 0.68 | K39: =AVERAGE(C39:H39) -> 0.9679 | L39: =MIN(C39:H39) -> 0.9491 | M39: =MAX(C39:H39) -> 0.9994 | N39: =RANK(H39,C39:H39) -> 3 | O39: =(H39-R24)*100 -> 0
A40: 5 | B40: E. Field Total (F+G) | C40: 0.9554 | D40: 0.9502 | E40: 0.9521 | F40: 0.9306 | G40: 0.957 | H40: 0.9644 | I40: =(H40-G40)*100 -> 0.74 | J40: =(H40-C40)*100 -> 0.9 | K40: =AVERAGE(C40:H40) -> 0.95161667 | L40: =MIN(C40:H40) -> 0.9306 | M40: =MAX(C40:H40) -> 0.9644 | N40: =RANK(H40,C40:H40) -> 1 | O40: =(H40-R25)*100 -> 0
A41: 6 | B41: F. Field (Day1) | C41: 0.9584 | D41: 0.9532 | E41: 0.9646 | F41: 0.9389 | G41: 0.9628 | H41: 0.9647 | I41: =(H41-G41)*100 -> 0.19 | J41: =(H41-C41)*100 -> 0.63 | K41: =AVERAGE(C41:H41) -> 0.9571 | L41: =MIN(C41:H41) -> 0.9389 | M41: =MAX(C41:H41) -> 0.9647 | N41: =RANK(H41,C41:H41) -> 1 | O41: =(H41-R26)*100 -> 0
A42: 7 | B42: G. Field (TC Ref) | C42: 0.943 | D42: 0.9447 | E42: 0.879 | F42: 0.8931 | G42: 0.9278 | H42: 0.9675 | I42: =(H42-G42)*100 -> 3.97 | J42: =(H42-C42)*100 -> 2.45 | K42: =AVERAGE(C42:H42) -> 0.92585 | L42: =MIN(C42:H42) -> 0.879 | M42: =MAX(C42:H42) -> 0.9675 | N42: =RANK(H42,C42:H42) -> 1 | O42: =(H42-R27)*100 -> 0
A43: 8 | B43: H. B1 | C43: 0.977 | D43: 0.9742 | E43: 0.9713 | F43: 0.9612 | G43: 0.9766 | H43: 0.9837 | I43: =(H43-G43)*100 -> 0.71 | J43: =(H43-C43)*100 -> 0.67 | K43: =AVERAGE(C43:H43) -> 0.974 | L43: =MIN(C43:H43) -> 0.9612 | M43: =MAX(C43:H43) -> 0.9837 | N43: =RANK(H43,C43:H43) -> 1 | O43: =(H43-R28)*100 -> 0
...

Sheet B1_Metrics
A1: Bounce and allocation-team resolution: notation and metrics
A2: Format: Notation → Exhaustive metrics table | Example column = live Excel formula on the block sheet (green = cross-sheet)
A3: ⚠ DRAFT ONLY — Requires review and approval by a qualified Alvarez and Marsal professional before use.
A5: Notation
B6: Symbol | C6: Meaning
B7: N(t), POS(t) | C7: Accounts and principal outstanding ₹ Cr allocated to team / bucket t
B8: RESN, RESPOS | C8: Resolved accounts and resolved POS to date (23-Aug)
B9: RES% | C9: RESPOS ÷ POS = STAB + RB + NORM
B10: STAB / RB / NORM | C10: Stabilised (minimum due) / rolled back / normalised shares of POS
B11: T | C11: Target RES%
B12: SD(m) | C12: Resolution at the same day (23rd) of month m, m ∈ {Mar, Jun, Jul}
B13: EOM(m) | C13: Full-month resolution of month m
B14: U | C14: Uplift = EOM(Jul) − SD(Jul); implied EOM = RES% + U
B15: Bounce | C15: Bounce # % and ₹ % on the current book; NTP = not-to-be-present ratio
B16: R6(t,m) | C16: 6-month EOM resolution trend Feb–Jul
B17: POS ₹ Cr; accounts as counts; rates in %; pacing in pp; current month to 23-Aug-26.
A19: Exhaustive metrics table
A20: # | B20: Metric family | C20: Pipeline-ready metric | D20: Definition / formula | E20: Applies to | F20: Example
A21: 1 | B21: Fact lookup | C21: Book and bounce KPIs | D21: Total / current book, bounce %, NTP, EOM bounce | E21: 11 KPIs | F21: ="Total "&TEXT(B1_Bounce_Allocation!C7,"#,##0")&" / "&TEXT(B1_Bounce_Allocation!C8,"#,##0.00;-#,##0.00;0.00")&"; current "&TEXT(B1_Bounce_Allocation!C9,"#,##0")&" / "&TEXT(B1_Bounce_Allocation!C10,"#,##0.00;-#,##0.00;0.00")&"; bounce # "&TEXT(B1_Bounce_Allocation!C11,"0.00%")&" ₹ "&TEXT(B1_Bounce_Allocation!C12,"0.00%") -> Total 161,579 / 48,768.14; current 96,063 / 32,364.12; bounce # 15.73% ₹ 6.94%
A22: 2 | B22: Fact lookup | C22: Team POS and resolution | D22: POS(t), RESPOS(t), RES%(t) | E22: 10 rows | F22: ="B1 "&TEXT(B1_Bounce_Allocation!D28,"#,##0.00;-#,##0.00;0.00")&" / "&TEXT(B1_Bounce_Allocation!F28,"#,##0.00;-#,##0.00;0.00")&" / "&TEXT(B1_Bounce_Allocation!K28,"0.00%")&"; B2 "&TEXT(B1_Bounce_Allocation!D29,"#,##0.00;-#,##0.00;0.00")&" / "&TEXT(B1_Bounce_Allocation!F29,"#,##0.00;-#,##0.00;0.00")&" / "&TEXT(B1_Bounce_Allocation!K29,"0.00%") -> B1 1,232.22 / 749.35 / 60.81%; B2 147.10 / 16.92 / 11.50%
A23: 3 | B23: Roll-up check | C23: RES% identity | D23: RESPOS ÷ POS − RES% | E23: 10 rows | F23: ="max |gap| "&TEXT(MAX(ABS(MIN(B1_Bounce_Allocation!T21:T30)),MAX(B1_Bounce_Allocation!T21:T30)),"+0.0"" pp"";-0.0"" pp"";0.0"" pp""") -> max |gap| +0.0 pp
A24: 4 | B24: Roll-up check | C24: Component identity | D24: STAB + RB + NORM − RES%; NORM + RB − NR+RB | E24: 10 rows × 2 | F24: ="max |gap| "&TEXT(MAX(ABS(MIN(B1_Bounce_Allocation!U21:V30)),MAX(B1_Bounce_Allocation!U21:V30)),"+0.0"" pp"";-0.0"" pp"";0.0"" pp""") -> max |gap| 0.0 pp
A25: 5 | B25: Roll-up check | C25: Trend vs table EOM Jul | D25: R6(t, Jul) − EOM(Jul) | E25: 10 teams | F25: ="max |gap| "&TEXT(MAX(ABS(MIN(B1_Bounce_Allocation!O36:O45)),MAX(B1_Bounce_Allocation!O36:O45)),"+0.0"" pp"";-0.0"" pp"";0.0"" pp""") -> max |gap| 0.0 pp
A26: 6 | B26: Bounce | C26: Derived bounce quantities | D26: Bounced ₹ = current ₹ × bounce ₹ %; bounced # ; bounced ATS | E26: Page | F26: =TEXT(B1_Bounce_Allocation!F11,"#,##0.00;-#,##0.00;0.00")&" ₹ Cr / "&TEXT(B1_Bounce_Allocation!F12,"#,##0")&" accounts / ATS "&TEXT(B1_Bounce_Allocation!F13,"#,##0.00")&" ₹ lakh" -> 2,246.07 ₹ Cr / 15,111 accounts / ATS 14.86 ₹ lakh
A27: 7 | B27: Bounce | C27: Book ATS | D27: ₹ × 100 ÷ # | E27: total / current | F27: =TEXT(B1_Bounce_Allocation!F9,"#,##0.00")&" / "&TEXT(B1_Bounce_Allocation!F10,"#,##0.00")&" ₹ lakh" -> 30.18 / 33.69 ₹ lakh
A28: 8 | B28: Bounce | C28: Bounce trend | D28: EOM bounce Mar / Jun / Jul; drift (pp); current ₹ bounce vs Jul | E28: 4 points | F28: =TEXT(B1_Bounce_Allocation!C14,"0.00%")&" / "&TEXT(B1_Bounce_Allocation!C15,"0.00%")&" / "&TEXT(B1_Bounce_Allocation!C16,"0.00%")&"; drift "&TEXT(B1_Bounce_Allocation!F15,"+0.0"" pp"";-0.0"" pp"";0.0"" pp""")&"; current vs Jul "&TEXT(B1_Bounce_Allocation!F14,"+0.0"" pp"";-0.0"" pp"";0.0"" pp""") -> 7.25% / 7.32% / 7.64%; drift +0.4 pp; current vs Jul -0.7 pp
A29: 9 | B29: Bounce | C29: Current book share | D29: current ÷ total (#, ₹) | E29: Page | F29: =TEXT(B1_Bounce_Allocation!F7,"0.0%")&" / "&TEXT(B1_Bounce_Allocation!F8,"0.0%") -> 59.5% / 66.4%
A30: 10 | B30: Resolution | C30: RES% by team / bucket | D30: RES%(t) | E30: 10 rows | F30: =TEXT(B1_Bounce_Allocation!K21,"0.00%")&" / "&TEXT(B1_Bounce_Allocation!K22,"0.00%")&" / "&TEXT(B1_Bounce_Allocation!K23,"0.00%")&" / "&TEXT(B1_Bounce_Allocation!K24,"0.00%")&" / "&TEXT(B1_Bounce_Allocation!K25,"0.00%")&" / "&TEXT(B1_Bounce_Allocation!K26,"0.00%")&" / "&TEXT(B1_Bounce_Allocation!K27,"0.00%")&" / "&TEXT(B1_Bounce_Allocation!K28,"0.00%")&" / "&TEXT(B1_Bounce_Allocation!K29,"0.00%")&" / "&TEXT(B1_Bounce_Allocation!K30,"0.00%") -> 46.45% / 74.14% / 83.31% / 58.73% / 29.46% / 27.75% / 40.34% / 60.81% / 11.50% / 10.64%
A31: 11 | B31: Resolution | C31: Resolution by accounts | D31: RESN ÷ N | E31: 10 rows | F31: ="B1 "&TEXT(B1_Bounce_Allocation!AB28,"0.0%")&"; B2 "&TEXT(B1_Bounce_Allocation!AB29,"0.0%")&"; B3 "&TEXT(B1_Bounce_Allocation!AB30,"0.0%")&"; Digital "&TEXT(B1_Bounce_Allocation!AB21,"0.0%") -> B1 49.9%; B2 27.5%; B3 21.0%; Digital 40.8%
A32: 12 | B32: Resolution | C32: Component mix | D32: STAB, RB, NORM | E32: B2, B3 | F32: ="B2 "&TEXT(B1_Bounce_Allocation!G29,"0.00%")&" / "&TEXT(B1_Bounce_Allocation!H29,"0.00%")&" / "&TEXT(B1_Bounce_Allocation!I29,"0.00%")&"; B3 "&TEXT(B1_Bounce_Allocation!G30,"0.00%")&" / "&TEXT(B1_Bounce_Allocation!H30,"0.00%")&" / "&TEXT(B1_Bounce_Allocation!I30,"0.00%") -> B2 9.72% / 0.00% / 1.78%; B3 9.45% / 0.25% / 0.94%
A33: 13 | B33: Resolution | C33: Blended B1–B3 | D33: Σ RESPOS ÷ Σ POS | E33: Page | F33: =TEXT(B1_Bounce_Allocation!K31,"0.00%")&"; unresolved "&TEXT(B1_Bounce_Allocation!AD31,"#,##0.00;-#,##0.00;0.00")&" ₹ Cr" -> 52.43%; unresolved 705.13 ₹ Cr
A34: 14 | B34: Resolution | C34: Unresolved POS | D34: POS − RESPOS | E34: 10 rows | F34: ="B1 "&TEXT(B1_Bounce_Allocation!AD28,"#,##0.00;-#,##0.00;0.00")&"; B2 "&TEXT(B1_Bounce_Allocation!AD29,"#,##0.00;-#,##0.00;0.00")&"; B3 "&TEXT(B1_Bounce_Allocation!AD30,"#,##0.00;-#,##0.00;0.00") -> B1 482.87; B2 130.18; B3 92.08
A35: 15 | B35: Pacing | C35: Current vs same-day Jul | D35: RES% − SD(Jul) | E35: 10 rows | F35: =TEXT(B1_Bounce_Allocation!W21,"+0.0"" pp"";-0.0"" pp"";0.0"" pp""")&" / "&TEXT(B1_Bounce_Allocation!W22,"+0.0"" pp"";-0.0"" pp"";0.0"" pp""")&" / "&TEXT(B1_Bounce_Allocation!W23,"+0.0"" pp"";-0.0"" pp"";0.0"" pp""")&" / "&TEXT(B1_Bounce_Allocation!W24,"+0.0"" pp"";-0.0"" pp"";0.0"" pp""")&" / "&TEXT(B1_Bounce_Allocation!W25,"+0.0"" pp"";-0.0"" pp"";0.0"" pp""")&" / "&TEXT(B1_Bounce_Allocation!W26,"+0.0"" pp"";-0.0"" pp"";0.0"" pp""")&" / "&TEXT(B1_Bounce_Allocation!W27,"+0.0"" pp"";-0.0"" pp"";0.0"" pp""")&" / "&TEXT(B1_Bounce_Allocation!W28,"+0.0"" pp"";-0.0"" pp"";0.0"" pp""")&" / "&TEXT(B1_Bounce_Allocation!W29,"+0.0"" pp"";-0.0"" pp"";0.0"" pp""")&" / "&TEXT(B1_Bounce_Allocation!W30,"+0.0"" pp"";-0.0"" pp"";0.0"" pp""") -> -8.7 pp / -4.5 pp / -4.3 pp / -12.6 pp / -8.9 pp / -8.6 pp / -9.9 pp / -8.0 pp / -10.0 pp / -8.1 pp
A36: 16 | B36: Pacing | C36: Current vs same-day 3-month average | D36: RES% − AVERAGE(SD Mar, Jun, Jul) | E36: 10 rows | F36: ="B1 "&TEXT(B1_Bounce_Allocation!X28,"+0.0"" pp"";-0.0"" pp"";0.0"" pp""")&"; B2 "&TEXT(B1_Bounce_Allocation!X29,"+0.0"" pp"";-0.0"" pp"";0.0"" pp""")&"; B3 "&TEXT(B1_Bounce_Allocation!X30,"+0.0"" pp"";-0.0"" pp"";0.0"" pp""")&"; Telecalling incl "&TEXT(B1_Bounce_Allocation!X22,"+0.0"" pp"";-0.0"" pp"";0.0"" pp""") -> B1 -6.3 pp; B2 -7.9 pp; B3 -7.6 pp; Telecalling incl -1.7 pp
A37: 17 | B37: Pacing | C37: Same-day → EOM uplift (Jul) | D37: U = EOM(Jul) − SD(Jul) | E37: 10 rows | F37: ="B1 "&TEXT(B1_Bounce_Allocation!Z28,"+0.0"" pp"";-0.0"" pp"";0.0"" pp""")&"; B2 "&TEXT(B1_Bounce_Allocation!Z29,"+0.0"" pp"";-0.0"" pp"";0.0"" pp""")&"; B3 "&TEXT(B1_Bounce_Allocation!Z30,"+0.0"" pp"";-0.0"" pp"";0.0"" pp""")&"; Field FTE "&TEXT(B1_Bounce_Allocation!Z25,"+0.0"" pp"";-0.0"" pp"";0.0"" pp""") -> B1 +29.5 pp; B2 +63.2 pp; B3 +65.1 pp; Field FTE +58.1 pp
A38: 18 | B38: Pacing | C38: Implied EOM at Jul uplift | D38: RES% + U | E38: 10 rows | F38: ="B1 "&TEXT(B1_Bounce_Allocation!AA28,"0.00%")&"; B2 "&TEXT(B1_Bounce_Allocation!AA29,"0.00%")&"; B3 "&TEXT(B1_Bounce_Allocation!AA30,"0.00%") -> B1 90.35%; B2 74.70%; B3 75.71%
A39: 19 | B39: Pacing | C39: Gap to target | D39: RES% − T (same-day basis); implied EOM − T | E39: 10 rows | F39: ="B1 "&TEXT(B1_Bounce_Allocation!Y28,"+0.0"" pp"";-0.0"" pp"";0.0"" pp""")&" / "&TEXT((B1_Bounce_Allocation!AA28-B1_Bounce_Allocation!L28)*100,"+0.0"" pp"";-0.0"" pp"";0.0"" pp""")&"; B2 "&TEXT(B1_Bounce_Allocation!Y29,"+0.0"" pp"";-0.0"" pp"";0.0"" pp""")&" / "&TEXT((B1_Bounce_Allocation!AA29-B1_Bounce_Allocation!L29)*100,"+0.0"" pp"";-0.0"" pp"";0.0"" pp""")&"; B3 "&TEXT(B1_Bounce_Allocation!Y30,"+0.0"" pp"";-0.0"" pp"";0.0"" pp""")&" / "&TEXT((B1_Bounce_Allocation!AA30-B1_Bounce_Allocation!L30)*100,"+0.0"" pp"";-0.0"" pp"";0.0"" pp""") -> B1 -37.0 pp / -7.4 pp; B2 -77.4 pp / -14.2 pp; B3 -76.2 pp / -11.2 pp
A40: 20 | B40: Trend | C40: EOM resolution trend | D40: R6(t, m) | E40: 10 teams × 6 months | F40: ="B1 Feb → Jul "&TEXT(B1_Bounce_Allocation!C43,"0.00%")&" / "&TEXT(B1_Bounce_Allocation!D43,"0.00%")&" / "&TEXT(B1_Bounce_Allocation!E43,"0.00%")&" / "&TEXT(B1_Bounce_Allocation!F43,"0.00%")&" / "&TEXT(B1_Bounce_Allocation!G43,"0.00%")&" / "&TEXT(B1_Bounce_Allocation!H43,"0.00%") -> B1 Feb → Jul 97.70% / 97.42% / 97.13% / 96.12% / 97.66% / 98.37%
A41: 21 | B41: Trend | C41: MoM and 6M change | D41: Jul − Jun; Jul − Feb (pp) | E41: 10 teams | F41: ="B2 "&TEXT(B1_Bounce_Allocation!I44,"+0.0"" pp"";-0.0"" pp"";0.0"" pp""")&" / "&TEXT(B1_Bounce_Allocation!J44,"+0.0"" pp"";-0.0"" pp"";0.0"" pp""")&"; B3 "&TEXT(B1_Bounce_Allocation!I45,"+0.0"" pp"";-0.0"" pp"";0.0"" pp""")&" / "&TEXT(B1_Bounce_Allocation!J45,"+0.0"" pp"";-0.0"" pp"";0.0"" pp""")&"; Digital "&TEXT(B1_Bounce_Allocation!I36,"+0.0"" pp"";-0.0"" pp"";0.0"" pp""") -> B2 +6.7 pp / -5.0 pp; B3 -6.9 pp / -3.6 pp; Digital +7.3 pp
A42: 22 | B42: Trend | C42: 6M average / min / max | D42: AVERAGE, MIN, MAX | E42: 10 teams | F42: ="B2 "&TEXT(B1_Bounce_Allocation!K44,"0.00%")&" / "&TEXT(B1_Bounce_Allocation!L44,"0.00%")&" / "&TEXT(B1_Bounce_Allocation!M44,"0.00%")&"; Digital "&TEXT(B1_Bounce_Allocation!K36,"0.00%")&" / "&TEXT(B1_Bounce_Allocation!L36,"0.00%")&" / "&TEXT(B1_Bounce_Allocation!M36,"0.00%") -> B2 84.64% / 78.03% / 89.78%; Digital 53.96% / 47.88% / 62.33%
...

Sheet B2_NPA_Vintage
A1: Block 2 — NPA recovery and upgrade by DPD bucket, Tech-off and vintage; 6-month ROR trend
A2: Source: Retail Assets – Collections Efficiency.pdf | counts, ₹ Cr, % | as on 23-08-2026; NPA team target ₹2.58 Cr
A3: ⚠ DRAFT ONLY — Requires review and approval by a qualified Alvarez and Marsal professional before use.
A5: A. NPA / Tech-off recovery (blue) with live checks — current = to 23-Aug-26
A6: # | B6: Bucket | C6: # accounts | D6: POS ₹ Cr | E6: Reco+Upg # | F6: Reco+Upg ₹ Cr | G6: ROR % | H6: Upg # | I6: Upg ₹ Cr | J6: Reco # | K6: Reco ₹ Cr | L6: SD ₹ Mar | M6: SD ₹ Jun | N6: SD ₹ Jul | O6: SD % Mar | P6: SD % Jun | Q6: SD % Jul | R6: EOM ₹ Mar | S6: EOM ₹ Jun | T6: EOM ₹ Jul | U6: EOM % Mar | V6: EOM % Jun | W6: EOM % Jul | X6: ROR computed | Y6: Check ROR (pp) | Z6: Check Reco+Upg ₹ | AA6: Check Reco+Upg # | AB6: Upg share of R+U ₹ | AC6: Current vs SD Jul (pp) | AD6: Jul SD → EOM uplift (x) | AE6: Implied EOM ₹ at Jul uplift | AF6: ATS ₹ lakh | AG6: Share of NPA POS | AH6: Share of NPA R+U ₹
A7: 1 | B7: DPD <=90 | C7: 132 | D7: 48.42 | E7: 62 | F7: 2.03 | G7: 0.0419 | H7: 5 | I7: 0.33 | J7: 57 | K7: 1.7 | L7: 1 | M7: 1.69 | N7: 1.02 | O7: 0.0261 | P7: 0.0703 | Q7: 0.0392 | R7: 4.1 | S7: 5.15 | T7: 2.31 | U7: 0.1067 | V7: 0.2139 | W7: 0.0886 | X7: =F7/D7 -> 0.041924824 | Y7: =(X7-G7)*100 -> 0.0024824453 | Z7: =I7+K7-F7 -> 0 | AA7: =H7+J7-E7 -> 0 | AB7: =IF(F7=0,"",I7/F7) -> 0.16256158 | AC7: =(G7-Q7)*100 -> 0.27 | AD7: =IF(N7=0,"",T7/N7) -> 2.2647059 | AE7: =IF(N7=0,"",F7*T7/N7) -> 4.5973529 | AF7: =D7*100/C7 -> 36.681818 | AG7: =D7/$D$12 -> 0.1383231 | AH7: =F7/$F$12 -> 0.27321669
A8: 2 | B8: DPD 91-120 | C8: 428 | D8: 39.8 | E8: 76 | F8: 0.18 | G8: 0.0046 | H8: 3 | I8: 0.04 | J8: 73 | K8: 0.15 | L8: 0.22 | M8: 0.67 | N8: 0.15 | O8: 0.019 | P8: 0.0682 | Q8: 0.0105 | R8: 2.32 | S8: 1.17 | T8: 0.29 | U8: 0.2016 | V8: 0.1194 | W8: 0.0206 | X8: =F8/D8 -> 0.0045226131 | Y8: =(X8-G8)*100 -> -0.0077386935 | Z8: =I8+K8-F8 -> 0.01 | AA8: =H8+J8-E8 -> 0 | AB8: =IF(F8=0,"",I8/F8) -> 0.22222222 | AC8: =(G8-Q8)*100 -> -0.59 | AD8: =IF(N8=0,"",T8/N8) -> 1.9333333 | AE8: =IF(N8=0,"",F8*T8/N8) -> 0.348 | AF8: =D8*100/C8 -> 9.2990654 | AG8: =D8/$D$12 -> 0.11369804 | AH8: =F8/$F$12 -> 0.02422611
A9: 3 | B9: DPD 121-150 | C9: 356 | D9: 30.37 | E9: 50 | F9: 3.96 | G9: 0.1304 | H9: 6 | I9: 3.67 | J9: 44 | K9: 0.29 | L9: 0.24 | M9: 0.17 | N9: 0.38 | O9: 0.0122 | P9: 0.0127 | Q9: 0.0527 | R9: 8.56 | S9: 0.38 | T9: 0.44 | U9: 0.4398 | V9: 0.0285 | W9: 0.0613 | X9: =F9/D9 -> 0.13039183 | Y9: =(X9-G9)*100 -> -0.00081659532 | Z9: =I9+K9-F9 -> 0 | AA9: =H9+J9-E9 -> 0 | AB9: =IF(F9=0,"",I9/F9) -> 0.92676768 | AC9: =(G9-Q9)*100 -> 7.77 | AD9: =IF(N9=0,"",T9/N9) -> 1.1578947 | AE9: =IF(N9=0,"",F9*T9/N9) -> 4.5852632 | AF9: =D9*100/C9 -> 8.5308989 | AG9: =D9/$D$12 -> 0.086759034 | AH9: =F9/$F$12 -> 0.53297443
A10: 4 | B10: DPD 151-180 | C10: 300 | D10: 10.59 | E10: 20 | F10: 0.05 | G10: 0.0051 | H10: 0 | I10: 0 | J10: 20 | K10: 0.05 | L10: 0.04 | M10: 0.03 | N10: 0.56 | O10: 0.0087 | P10: 0.0068 | Q10: 0.0519 | R10: 0.06 | S10: 0.05 | T10: 1.27 | U10: 0.0123 | V10: 0.0119 | W10: 0.1181 | X10: =F10/D10 -> 0.0047214353 | Y10: =(X10-G10)*100 -> -0.037856468 | Z10: =I10+K10-F10 -> 0 | AA10: =H10+J10-E10 -> 0 | AB10: =IF(F10=0,"",I10/F10) -> 0 | AC10: =(G10-Q10)*100 -> -4.68 | AD10: =IF(N10=0,"",T10/N10) -> 2.2678571 | AE10: =IF(N10=0,"",F10*T10/N10) -> 0.11339286 | AF10: =D10*100/C10 -> 3.53 | AG10: =D10/$D$12 -> 0.030252821 | AH10: =F10/$F$12 -> 0.0067294751
A11: 5 | B11: DPD >180 | C11: 4124 | D11: 220.87 | E11: 96 | F11: 1.21 | G11: 0.0055 | H11: 5 | I11: 0.1 | J11: 91 | K11: 1.11 | L11: 1.35 | M11: 0.4 | N11: 0.65 | O11: 0.0094 | P11: 0.004 | Q11: 0.0062 | R11: 4.87 | S11: 0.72 | T11: 2.16 | U11: 0.0339 | V11: 0.0072 | W11: 0.0203 | X11: =F11/D11 -> 0.0054783357 | Y11: =(X11-G11)*100 -> -0.0021664327 | Z11: =I11+K11-F11 -> 0 | AA11: =H11+J11-E11 -> 0 | AB11: =IF(F11=0,"",I11/F11) -> 0.082644628 | AC11: =(G11-Q11)*100 -> -0.07 | AD11: =IF(N11=0,"",T11/N11) -> 3.3230769 | AE11: =IF(N11=0,"",F11*T11/N11) -> 4.0209231 | AF11: =D11*100/C11 -> 5.3557226 | AG11: =D11/$D$12 -> 0.630967 | AH11: =F11/$F$12 -> 0.1628533
A12: 6 | B12: Total NPA | C12: 5340 | D12: 350.05 | E12: 304 | F12: 7.43 | G12: 0.0212 | H12: 19 | I12: 4.14 | J12: 285 | K12: 3.29 | L12: 2.85 | M12: 2.96 | N12: 2.77 | O12: 0.0131 | P12: 0.0195 | Q12: 0.0168 | R12: 19.9 | S12: 7.47 | T12: 6.47 | U12: 0.0915 | V12: 0.0493 | W12: 0.0394 | X12: =F12/D12 -> 0.021225539 | Y12: =(X12-G12)*100 -> 0.0025539209 | Z12: =I12+K12-F12 -> 0 | AA12: =H12+J12-E12 -> 0 | AB12: =IF(F12=0,"",I12/F12) -> 0.55720054 | AC12: =(G12-Q12)*100 -> 0.44 | AD12: =IF(N12=0,"",T12/N12) -> 2.3357401 | AE12: =IF(N12=0,"",F12*T12/N12) -> 17.354549 | AF12: =D12*100/C12 -> 6.5552434 | AG12: =D12/$D$12 -> 1 | AH12: =F12/$F$12 -> 1
A13: 7 | B13: Tech Off | C13: 5986 | D13: 194.11 | E13: 44 | F13: 0.48 | G13: 0.0025 | H13: 0 | I13: 0 | J13: 16 | K13: 0.48 | L13: 0.37 | M13: 0.29 | N13: 0.45 | O13: 0.0038 | P13: 0.0029 | Q13: 0.0046 | R13: 1.15 | S13: 1.29 | T13: 2.1 | U13: 0.0118 | V13: 0.0131 | W13: 0.0214 | X13: =F13/D13 -> 0.0024728247 | Y13: =(X13-G13)*100 -> -0.0027175313 | Z13: =I13+K13-F13 -> 0 | AA13: =H13+J13-E13 -> -28 | AB13: =IF(F13=0,"",I13/F13) -> 0 | AC13: =(G13-Q13)*100 -> -0.21 | AD13: =IF(N13=0,"",T13/N13) -> 4.6666667 | AE13: =IF(N13=0,"",F13*T13/N13) -> 2.24 | AF13: =D13*100/C13 -> 3.242733 | AG13: =D13/$D$12 -> 0.55452078 | AH13: =F13/$F$12 -> 0.064602961
B14: Σ DPD buckets − Total NPA (# / POS / R+U ₹ / Upg ₹ / Reco ₹) | C14: =SUM(C7:C11)-C12 -> 0 | D14: =SUM(D7:D11)-D12 -> 0 | F14: =SUM(F7:F11)-F12 -> 0 | I14: =SUM(I7:I11)-I12 -> 0 | K14: =SUM(K7:K11)-K12 -> 0.01
B15: NPA team target ₹ Cr (printed) / achieved to date / achievement % | D15: 2.58 | F15: =F12 -> 7.43 | G15: =F15/D15 -> 2.879845
B16: Implied Total EOM ₹ at Jul uplift / vs target | F16: =AE12 -> 17.354549 | G16: =F16/D15 -> 6.7265693
B17: NPA + Tech-off pool ₹ Cr / blended ROR to date | D17: =D12+D13 -> 544.16 | F17: =F12+F13 -> 7.91 | G17: =F17/D17 -> 0.014536166
A19: B. Vintage view (blue) with checks
A20: # | B20: Vintage | C20: # accounts | D20: POS ₹ Cr | E20: Reco+Upg # | F20: Reco+Upg ₹ Cr | G20: ROR % | H20: Upg # | I20: Upg ₹ Cr | J20: Reco # | K20: Reco ₹ Cr | L20: SD % Mar | M20: SD % Jun | N20: SD % Jul | O20: EOM % Mar | P20: EOM % Jun | Q20: EOM % Jul | R20: ROR computed | S20: Check ROR (pp) | T20: Current vs SD Jul (pp) | U20: ATS ₹ lakh | V20: Share of POS | W20: Share of R+U ₹ | X20: Upg share of R+U ₹
A21: 1 | B21: V1 | C21: 2349 | D21: 158.07 | E21: 196 | F21: 5.03 | G21: 0.0318 | H21: 18 | I21: 4.14 | J21: 178 | K21: 0.89 | L21: 0.0135 | M21: 0.0332 | N21: 0.0245 | O21: 0.2019 | P21: 0.0767 | Q21: 0.0572 | R21: =F21/D21 -> 0.031821345 | S21: =(R21-G21)*100 -> 0.0021344974 | T21: =(G21-N21)*100 -> 0.73 | U21: =D21*100/C21 -> 6.7292465 | V21: =D21/$D$26 -> 0.45156406 | W21: =F21/$F$26 -> 0.6769852 | X21: =IF(F21=0,"",I21/F21) -> 0.82306163
A22: 2 | B22: V2 | C22: 1295 | D22: 60.37 | E22: 51 | F22: 0.37 | G22: 0.0062 | H22: 0 | I22: 0 | J22: 51 | K22: 0.37 | L22: 0.0103 | M22: 0.0186 | N22: 0.0019 | O22: 0.0364 | P22: 0.0264 | Q22: 0.0101 | R22: =F22/D22 -> 0.006128872 | S22: =(R22-G22)*100 -> -0.0071128044 | T22: =(G22-N22)*100 -> 0.43 | U22: =D22*100/C22 -> 4.6617761 | V22: =D22/$D$26 -> 0.17246108 | W22: =F22/$F$26 -> 0.049798116 | X22: =IF(F22=0,"",I22/F22) -> 0
A23: 3 | B23: V3 | C23: 886 | D23: 46.81 | E23: 27 | F23: 0.48 | G23: 0.0104 | H23: 1 | I23: 0 | J23: 26 | K23: 0.48 | L23: 0.0095 | M23: 0.0075 | N23: 0.0253 | O23: 0.0386 | P23: 0.0271 | Q23: 0.0386 | R23: =F23/D23 -> 0.010254219 | S23: =(R23-G23)*100 -> -0.014578082 | T23: =(G23-N23)*100 -> -1.49 | U23: =D23*100/C23 -> 5.2832957 | V23: =D23/$D$26 -> 0.13372375 | W23: =F23/$F$26 -> 0.064602961 | X23: =IF(F23=0,"",I23/F23) -> 0
A24: 4 | B24: V4 | C24: 444 | D24: 71.33 | E24: 21 | F24: 1.3 | G24: 0.0182 | H24: 0 | I24: 0 | J24: 21 | K24: 1.3 | L24: 0.0017 | M24: 0.0015 | N24: 0.0154 | O24: 0.0322 | P24: 0.0208 | Q24: 0.0388 | R24: =F24/D24 -> 0.018225151 | S24: =(R24-G24)*100 -> 0.0025150708 | T24: =(G24-N24)*100 -> 0.28 | U24: =D24*100/C24 -> 16.065315 | V24: =D24/$D$26 -> 0.20377089 | W24: =F24/$F$26 -> 0.17496635 | X24: =IF(F24=0,"",I24/F24) -> 0
A25: 5 | B25: V5+ | C25: 366 | D25: 13.48 | E25: 9 | F25: 0.25 | G25: 0.0183 | H25: 0 | I25: 0 | J25: 9 | K25: 0.25 | L25: 0.0081 | M25: 0.002 | N25: 0.0017 | O25: 0.0785 | P25: 0.0742 | Q25: 0.0047 | R25: =F25/D25 -> 0.018545994 | S25: =(R25-G25)*100 -> 0.024599407 | T25: =(G25-N25)*100 -> 1.66 | U25: =D25*100/C25 -> 3.6830601 | V25: =D25/$D$26 -> 0.038508784 | W25: =F25/$F$26 -> 0.033647376 | X25: =IF(F25=0,"",I25/F25) -> 0
A26: 6 | B26: Total | C26: 5340 | D26: 350.05 | E26: 304 | F26: 7.43 | G26: 0.0212 | H26: 19 | I26: 4.14 | J26: 285 | K26: 3.29 | L26: 0.0092 | M26: 0.012 | N26: 0.011 | O26: 0.0915 | P26: 0.0493 | Q26: 0.0394 | R26: =F26/D26 -> 0.021225539 | S26: =(R26-G26)*100 -> 0.0025539209 | T26: =(G26-N26)*100 -> 1.02 | U26: =D26*100/C26 -> 6.5552434 | V26: =D26/$D$26 -> 1 | W26: =F26/$F$26 -> 1 | X26: =IF(F26=0,"",I26/F26) -> 0.55720054
B27: Σ vintages − Total (# / POS / R+U ₹) | C27: =SUM(C21:C25)-C26 -> 0 | D27: =SUM(D21:D25)-D26 -> 0.01 | F27: =SUM(F21:F25)-F26 -> 0
B28: Vintage Total vs NPA Total (POS / R+U ₹) | D28: =D26-D12 -> 0 | F28: =F26-F12 -> 0
B29: Same-day % totals: vintage table vs NPA table (pp) Mar / Jun / Jul | L29: =(L26-O12)*100 -> -0.39 | M29: =(M26-P12)*100 -> -0.75 | N29: =(N26-Q12)*100 -> -0.58
B30: EOM % totals: vintage table vs NPA table (pp) | O30: =(O26-U12)*100 -> 0 | P30: =(P26-V12)*100 -> 0 | Q30: =(Q26-W12)*100 -> 0
A32: C. NPA ROR % — last 6 months (blue)
A33: # | B33: Bucket | C33: Feb-26 | D33: Mar-26 | E33: Apr-26 | F33: May-26 | G33: Jun-26 | H33: Jul-26 | I33: Jul vs Jun (pp) | J33: 6M avg | K33: 6M max | L33: Check vs EOM Jul in table A (pp)
A34: 1 | B34: DPD <=90 | C34: 0.1504 | D34: 0.1233 | E34: 0.2915 | F34: 0.2261 | G34: 0.2012 | H34: 0.0821 | I34: =(H34-G34)*100 -> -11.91 | J34: =AVERAGE(C34:H34) -> 0.1791 | K34: =MAX(C34:H34) -> 0.2915 | L34: =(H34-W7)*100 -> -0.65
A35: 2 | B35: DPD 91-120 | C35: 0.0129 | D35: 0.4365 | E35: 0.0772 | F35: 0.0569 | G35: 0.1094 | H35: 0.0263 | I35: =(H35-G35)*100 -> -8.31 | J35: =AVERAGE(C35:H35) -> 0.11986667 | K35: =MAX(C35:H35) -> 0.4365 | L35: =(H35-W8)*100 -> 0.57
A36: 3 | B36: DPD 121-150 | C36: 0.093 | D36: 0.4302 | E36: 0.0248 | F36: 0.0127 | G36: 0.029 | H36: 0.058 | I36: =(H36-G36)*100 -> 2.9 | J36: =AVERAGE(C36:H36) -> 0.10795 | K36: =MAX(C36:H36) -> 0.4302 | L36: =(H36-W9)*100 -> -0.33
A37: 4 | B37: DPD 151-180 | C37: 0.0268 | D37: 0.0094 | E37: 0.005 | F37: 0.0097 | G37: 0.0147 | H37: 0.1096 | I37: =(H37-G37)*100 -> 9.49 | J37: =AVERAGE(C37:H37) -> 0.0292 | K37: =MAX(C37:H37) -> 0.1096 | L37: =(H37-W10)*100 -> -0.85
A38: 5 | B38: DPD >180 | C38: 0.0215 | D38: 0.027 | E38: 0.0091 | F38: 0.011 | G38: 0.0039 | H38: 0.0115 | I38: =(H38-G38)*100 -> 0.76 | J38: =AVERAGE(C38:H38) -> 0.014 | K38: =MAX(C38:H38) -> 0.027 | L38: =(H38-W11)*100 -> -0.88
A39: 6 | B39: Tech Off | C39: 0.0036 | D39: 0.0084 | E39: 0.0369 | F39: 0.0037 | G39: 0.0094 | H39: 0.0152 | I39: =(H39-G39)*100 -> 0.58 | J39: =AVERAGE(C39:H39) -> 0.012866667 | K39: =MAX(C39:H39) -> 0.0369 | L39: =(H39-W13)*100 -> -0.62
A42: Data points to flag before metrics (live checks)
A43: # | B43: Flag | C43: Check value (live) | D43: Unit | E43: Implication / action
A44: 1 | B44: NPA recovery + upgrade to 23-Aug is ₹7.43 Cr (ROR 2.12%) vs a ₹2.58 Cr team target — already 2.9x the target, but 49% of it is a single ₹3.67 Cr upgrade in DPD 121–150 (upgrades are 56% of the total). | C44: =G15 -> 2.879845 | D44: % | E44: Strip the one large upgrade before judging run-rate performance.
A45: 2 | B45: Same-day % totals in the vintage table (0.92 / 1.20 / 1.10) differ from the NPA table (1.31 / 1.95 / 1.68) although EOM totals agree — two bases on one page. | C45: =L29 -> -0.39 | D45: pp | E45: Confirm which same-day base is correct before trending.
...

Sheet B2_Metrics
A1: NPA recovery by bucket and vintage: notation and metrics
A2: Format: Notation → Exhaustive metrics table | Example column = live Excel formula on the block sheet (green = cross-sheet)
A3: ⚠ DRAFT ONLY — Requires review and approval by a qualified Alvarez and Marsal professional before use.
A5: Notation
B6: Symbol | C6: Meaning
B7: N(b), POS(b) | C7: NPA accounts and POS ₹ Cr in DPD bucket b (<=90, 91–120, 121–150, 151–180, >180), Tech-off, or vintage v (V1 … V5+)
B8: RU, Upg, Reco | C8: Recovery + upgrade, upgrade, cash recovery (# and ₹) to 23-Aug
B9: ROR | C9: RU ₹ ÷ POS
B10: SD(m), EOM(m) | C10: Same-day / end-of-month recovery ₹ and % for Mar, Jun, Jul
B11: Tgt | C11: NPA team target ₹2.58 Cr
B12: U | C12: Uplift multiple = EOM ₹(Jul) ÷ SD ₹(Jul)
B13: R6(b,m) | C13: 6-month NPA ROR% trend, Feb–Jul (different base from EOM %)
B14: ATS | C14: POS × 100 ÷ N, ₹ lakh
B15: POS and recovery ₹ Cr; counts; rates in %; current month to 23-Aug-26.
A17: Exhaustive metrics table
A18: # | B18: Metric family | C18: Pipeline-ready metric | D18: Definition / formula | E18: Applies to | F18: Example
A19: 1 | B19: Fact lookup | C19: Bucket POS and recovery | D19: N, POS, RU, Upg, Reco | E19: 7 rows | F19: ="Total NPA "&TEXT(B2_NPA_Vintage!C12,"#,##0")&" / "&TEXT(B2_NPA_Vintage!D12,"#,##0.00;-#,##0.00;0.00")&" / RU "&TEXT(B2_NPA_Vintage!F12,"#,##0.00;-#,##0.00;0.00")&" / Upg "&TEXT(B2_NPA_Vintage!I12,"#,##0.00;-#,##0.00;0.00")&" / Reco "&TEXT(B2_NPA_Vintage!K12,"#,##0.00;-#,##0.00;0.00") -> Total NPA 5,340 / 350.05 / RU 7.43 / Upg 4.14 / Reco 3.29
A20: 2 | B20: Fact lookup | C20: Same-day and EOM history | D20: SD ₹/% and EOM ₹/% (Mar, Jun, Jul) | E20: 7 rows × 12 | F20: ="Total EOM ₹ "&TEXT(B2_NPA_Vintage!R12,"#,##0.00;-#,##0.00;0.00")&" / "&TEXT(B2_NPA_Vintage!S12,"#,##0.00;-#,##0.00;0.00")&" / "&TEXT(B2_NPA_Vintage!T12,"#,##0.00;-#,##0.00;0.00")&"; EOM % "&TEXT(B2_NPA_Vintage!U12,"0.00%")&" / "&TEXT(B2_NPA_Vintage!V12,"0.00%")&" / "&TEXT(B2_NPA_Vintage!W12,"0.00%") -> Total EOM ₹ 19.90 / 7.47 / 6.47; EOM % 9.15% / 4.93% / 3.94%
A21: 3 | B21: Roll-up check | C21: ROR identity | D21: RU ÷ POS − ROR | E21: 7 + 6 rows | F21: ="max |gap| "&TEXT(MAX(ABS(MIN(B2_NPA_Vintage!Y7:Y13)),MAX(B2_NPA_Vintage!Y7:Y13),ABS(MIN(B2_NPA_Vintage!S21:S26)),MAX(B2_NPA_Vintage!S21:S26)),"+0.0"" pp"";-0.0"" pp"";0.0"" pp""") -> max |gap| +0.0 pp
A22: 4 | B22: Roll-up check | C22: RU = Upg + Reco | D22: ₹ and # | E22: 7 rows | F22: ="max |gap ₹| "&TEXT(MAX(ABS(MIN(B2_NPA_Vintage!Z7:Z13)),MAX(B2_NPA_Vintage!Z7:Z13)),"#,##0.00;-#,##0.00;0.00")&"; # "&TEXT(MAX(ABS(MIN(B2_NPA_Vintage!AA7:AA13)),MAX(B2_NPA_Vintage!AA7:AA13)),"#,##0") -> max |gap ₹| 0.01; # 28
A23: 5 | B23: Roll-up check | C23: Buckets / vintages to totals | D23: Σ − Total | E23: 2 tables | F23: ="NPA "&TEXT(B2_NPA_Vintage!C14,"#,##0.00;-#,##0.00;0.00")&" / "&TEXT(B2_NPA_Vintage!D14,"#,##0.00;-#,##0.00;0.00")&" / "&TEXT(B2_NPA_Vintage!F14,"#,##0.00;-#,##0.00;0.00")&"; vintage "&TEXT(B2_NPA_Vintage!C27,"#,##0.00;-#,##0.00;0.00")&" / "&TEXT(B2_NPA_Vintage!D27,"#,##0.00;-#,##0.00;0.00")&" / "&TEXT(B2_NPA_Vintage!F27,"#,##0.00;-#,##0.00;0.00")&"; vintage vs NPA total "&TEXT(B2_NPA_Vintage!D28,"#,##0.00;-#,##0.00;0.00") -> NPA 0.00 / 0.00 / 0.00; vintage 0.00 / 0.01 / 0.00; vintage vs NPA total 0.00
A24: 6 | B24: Roll-up check | C24: Same-day / EOM base consistency | D24: Vintage total % − NPA total % (pp) | E24: Mar / Jun / Jul | F24: ="SD "&TEXT(B2_NPA_Vintage!L29,"+0.0"" pp"";-0.0"" pp"";0.0"" pp""")&" / "&TEXT(B2_NPA_Vintage!M29,"+0.0"" pp"";-0.0"" pp"";0.0"" pp""")&" / "&TEXT(B2_NPA_Vintage!N29,"+0.0"" pp"";-0.0"" pp"";0.0"" pp""")&"; EOM "&TEXT(B2_NPA_Vintage!O30,"+0.0"" pp"";-0.0"" pp"";0.0"" pp""")&" / "&TEXT(B2_NPA_Vintage!P30,"+0.0"" pp"";-0.0"" pp"";0.0"" pp""")&" / "&TEXT(B2_NPA_Vintage!Q30,"+0.0"" pp"";-0.0"" pp"";0.0"" pp""") -> SD -0.4 pp / -0.8 pp / -0.6 pp; EOM 0.0 pp / 0.0 pp / 0.0 pp
A25: 7 | B25: Roll-up check | C25: 6M trend vs EOM Jul | D25: R6(b, Jul) − EOM %(Jul) | E25: 6 buckets | F25: =TEXT(B2_NPA_Vintage!L34,"+0.0"" pp"";-0.0"" pp"";0.0"" pp""")&" / "&TEXT(B2_NPA_Vintage!L35,"+0.0"" pp"";-0.0"" pp"";0.0"" pp""")&" / "&TEXT(B2_NPA_Vintage!L36,"+0.0"" pp"";-0.0"" pp"";0.0"" pp""")&" / "&TEXT(B2_NPA_Vintage!L37,"+0.0"" pp"";-0.0"" pp"";0.0"" pp""")&" / "&TEXT(B2_NPA_Vintage!L38,"+0.0"" pp"";-0.0"" pp"";0.0"" pp""")&" / "&TEXT(B2_NPA_Vintage!L39,"+0.0"" pp"";-0.0"" pp"";0.0"" pp""") -> -0.6 pp / +0.6 pp / -0.3 pp / -0.9 pp / -0.9 pp / -0.6 pp
A26: 8 | B26: Recovery | C26: ROR by bucket | D26: ROR(b) | E26: 7 rows | F26: =TEXT(B2_NPA_Vintage!G7,"0.00%")&" / "&TEXT(B2_NPA_Vintage!G8,"0.00%")&" / "&TEXT(B2_NPA_Vintage!G9,"0.00%")&" / "&TEXT(B2_NPA_Vintage!G10,"0.00%")&" / "&TEXT(B2_NPA_Vintage!G11,"0.00%")&" / "&TEXT(B2_NPA_Vintage!G12,"0.00%")&" / "&TEXT(B2_NPA_Vintage!G13,"0.00%") -> 4.19% / 0.46% / 13.04% / 0.51% / 0.55% / 2.12% / 0.25%
A27: 9 | B27: Recovery | C27: ROR by vintage | D27: ROR(v) | E27: 6 rows | F27: =TEXT(B2_NPA_Vintage!G21,"0.00%")&" / "&TEXT(B2_NPA_Vintage!G22,"0.00%")&" / "&TEXT(B2_NPA_Vintage!G23,"0.00%")&" / "&TEXT(B2_NPA_Vintage!G24,"0.00%")&" / "&TEXT(B2_NPA_Vintage!G25,"0.00%")&" / "&TEXT(B2_NPA_Vintage!G26,"0.00%") -> 3.18% / 0.62% / 1.04% / 1.82% / 1.83% / 2.12%
A28: 10 | B28: Recovery | C28: Upgrade share of RU ₹ | D28: Upg ÷ RU | E28: 7 + 6 rows | F28: ="Total "&TEXT(B2_NPA_Vintage!AB12,"0.0%")&"; DPD 121–150 "&TEXT(B2_NPA_Vintage!AB9,"0.0%")&"; V1 "&TEXT(B2_NPA_Vintage!X21,"0.0%") -> Total 55.7%; DPD 121–150 92.7%; V1 82.3%
A29: 11 | B29: Recovery | C29: ROR ex one-off upgrade | D29: (RU − Upg(121–150)) ÷ POS | E29: Total | F29: =TEXT((B2_NPA_Vintage!F12-B2_NPA_Vintage!I9)/B2_NPA_Vintage!D12,"0.00%") -> 1.07%
A30: 12 | B30: Recovery | C30: Target achievement | D30: RU ÷ Tgt; implied EOM ÷ Tgt | E30: Total | F30: =TEXT(B2_NPA_Vintage!G15,"0.0%")&" / "&TEXT(B2_NPA_Vintage!G16,"0.0%") -> 288.0% / 672.7%
A31: 13 | B31: Recovery | C31: Blended NPA + Tech-off ROR | D31: Σ RU ÷ Σ POS | E31: Page | F31: =TEXT(B2_NPA_Vintage!G17,"0.00%")&" on "&TEXT(B2_NPA_Vintage!D17,"#,##0.00;-#,##0.00;0.00")&" ₹ Cr" -> 1.45% on 544.16 ₹ Cr
A32: 14 | B32: Recovery | C32: Annualised ROR | D32: ROR × 12 (to-date basis) | E32: Total / Tech-off | F32: =TEXT(B2_NPA_Vintage!G12*12,"0.0%")&" / "&TEXT(B2_NPA_Vintage!G13*12,"0.0%") -> 25.4% / 3.0%
A33: 15 | B33: Pacing | C33: Current vs same-day Jul | D33: ROR − SD %(Jul) | E33: 7 + 6 rows | F33: ="Total "&TEXT(B2_NPA_Vintage!AC12,"+0.0"" pp"";-0.0"" pp"";0.0"" pp""")&"; <=90 "&TEXT(B2_NPA_Vintage!AC7,"+0.0"" pp"";-0.0"" pp"";0.0"" pp""")&"; V1 "&TEXT(B2_NPA_Vintage!T21,"+0.0"" pp"";-0.0"" pp"";0.0"" pp""") -> Total +0.4 pp; <=90 +0.3 pp; V1 +0.7 pp
A34: 16 | B34: Pacing | C34: Same-day → EOM multiple (Jul) | D34: U = EOM ₹ ÷ SD ₹ | E34: 7 rows | F34: ="Total "&TEXT(B2_NPA_Vintage!AD12,"0.00""x""")&"; <=90 "&TEXT(B2_NPA_Vintage!AD7,"0.00""x""")&"; >180 "&TEXT(B2_NPA_Vintage!AD11,"0.00""x""") -> Total 2.34x; <=90 2.26x; >180 3.32x
A35: 17 | B35: Pacing | C35: Implied EOM ₹ at Jul multiple | D35: RU × U | E35: 7 rows | F35: ="Total "&TEXT(B2_NPA_Vintage!AE12,"#,##0.00;-#,##0.00;0.00")&"; <=90 "&TEXT(B2_NPA_Vintage!AE7,"#,##0.00;-#,##0.00;0.00") -> Total 17.35; <=90 4.60
A36: 18 | B36: Mix & share | C36: Bucket share of NPA POS and RU | D36: POS(b) ÷ POS; RU(b) ÷ RU | E36: 5 buckets | F36: ="<=90 "&TEXT(B2_NPA_Vintage!AG7,"0.0%")&" / "&TEXT(B2_NPA_Vintage!AH7,"0.0%")&"; >180 "&TEXT(B2_NPA_Vintage!AG11,"0.0%")&" / "&TEXT(B2_NPA_Vintage!AH11,"0.0%") -> <=90 13.8% / 27.3%; >180 63.1% / 16.3%
A37: 19 | B37: Mix & share | C37: Vintage share of POS and RU | D37: POS(v) ÷ POS; RU(v) ÷ RU | E37: 5 vintages | F37: ="V1 "&TEXT(B2_NPA_Vintage!V21,"0.0%")&" / "&TEXT(B2_NPA_Vintage!W21,"0.0%")&"; V4 "&TEXT(B2_NPA_Vintage!V24,"0.0%")&" / "&TEXT(B2_NPA_Vintage!W24,"0.0%") -> V1 45.2% / 67.7%; V4 20.4% / 17.5%
A38: 20 | B38: Ticket size | C38: ATS by bucket / vintage | D38: POS × 100 ÷ N | E38: 13 rows | F38: ="Total "&TEXT(B2_NPA_Vintage!AF12,"#,##0.00")&"; <=90 "&TEXT(B2_NPA_Vintage!AF7,"#,##0.00")&"; >180 "&TEXT(B2_NPA_Vintage!AF11,"#,##0.00")&"; V4 "&TEXT(B2_NPA_Vintage!U24,"#,##0.00")&" ₹ lakh" -> Total 6.56; <=90 36.68; >180 5.36; V4 16.07 ₹ lakh
A39: 21 | B39: Trend | C39: 6M NPA ROR | D39: R6(b, m) | E39: 6 buckets × 6 | F39: ="<=90 Feb → Jul "&TEXT(B2_NPA_Vintage!C34,"0.00%")&" / "&TEXT(B2_NPA_Vintage!D34,"0.00%")&" / "&TEXT(B2_NPA_Vintage!E34,"0.00%")&" / "&TEXT(B2_NPA_Vintage!F34,"0.00%")&" / "&TEXT(B2_NPA_Vintage!G34,"0.00%")&" / "&TEXT(B2_NPA_Vintage!H34,"0.00%") -> <=90 Feb → Jul 15.04% / 12.33% / 29.15% / 22.61% / 20.12% / 8.21%
A40: 22 | B40: Trend | C40: Jul vs Jun; 6M average / max | D40: pp; AVERAGE; MAX | E40: 6 buckets | F40: ="<=90 "&TEXT(B2_NPA_Vintage!I34,"+0.0"" pp"";-0.0"" pp"";0.0"" pp""")&" / "&TEXT(B2_NPA_Vintage!J34,"0.00%")&" / "&TEXT(B2_NPA_Vintage!K34,"0.00%")&"; 151–180 "&TEXT(B2_NPA_Vintage!I37,"+0.0"" pp"";-0.0"" pp"";0.0"" pp""") -> <=90 -11.9 pp / 17.91% / 29.15%; 151–180 +9.5 pp
A41: 23 | B41: Data integrity | C41: Two same-day bases | D41: Implied Jul pool = SD ₹ ÷ SD % | E41: NPA table | F41: =TEXT(B2_NPA_Vintage!N12/B2_NPA_Vintage!Q12,"#,##0.00;-#,##0.00;0.00")&" ₹ Cr implied vs POS "&TEXT(B2_NPA_Vintage!D12,"#,##0.00;-#,##0.00;0.00") -> 164.88 ₹ Cr implied vs POS 350.05
A42: 24 | B42: Data integrity | C42: Duplicate Total rows | D42: Tech-off and its Total identical | E42: Page | F42: Reproduced once here
...
