Workbook

Sheet README
A1: RBL Bank — Net Advances Insights: page-wise metric extraction
A2: Prepared with the metric-extraction method | Source: 09_Net_Advances_Insights.pdf (1 page, 4 data blocks) | ₹ Cr
A3: ⚠ DRAFT ONLY — Requires review and approval by a qualified Alvarez and Marsal professional before use.
A5: Sheet map (one sheet per block on the page)
A6: P1_NetFunded_Qtr | B6: Block 1 — Net Funded Advances quarterly chart (Wholesale / Retail, 4 quarter-ends)
A7: P2_Detailed_Table | B7: Block 2 — Net Funded Advances Detailed table (35 products + Null, 4 quarter-ends)
A8: P3_Retail_Monthly | B8: Block 3 — Retail Net Advances monthly chart (Aug-25 to Aug-26)
A9: P4_Wholesale_Monthly | B9: Block 4 — Wholesale Net Advances monthly chart (Aug-25 to Aug-26)
A10: X_Cross_Recon | B10: Cross-block reconciliation matrix
A12: Each block has two sheets | B12: Pn_<block>: source data · derived series grid · flags · what it cannot support · 10-question test set. Pn_Metrics: Notation table + exhaustive metrics table (# | Metric family | Pipeline-ready metric | Definition / formula | Applies to | Example), examples are live formulas
A14: Colour legend
A15: Blue text | B15: Hard-coded input transcribed from the PDF
A16: Black text | B16: Formula on the same sheet
A17: Green text | B17: Link to another sheet
A18: Yellow fill | B18: Data flag to review
A20: Notation
A21: W / R / T | B21: Wholesale / Retail / Total net funded advances (₹ Cr)
A22: QoQ / MoM / YoY | B22: Quarter-on-quarter / month-on-month / year-on-year growth
A23: 9M | B23: Sep-25 → Jun-26 (three quarters)
A24: pp | B24: Percentage points (share differences × 100)
A25: CQGR / CMGR | B25: Compounded quarterly / monthly growth rate
A26: HHI | B26: Σ(share %)²; effective number = 10,000 / HHI
A28: Key assumptions (confirm with client)
A29: 1 | B29: Block-2 rows with <4 values placed by roll-up: Govt. Banking = Sep-25; C&IB Agri = Dec-25 & Mar-26; FIGU-BBB = Dec-25, Mar-26, Jun-26 (0); LAS = Jun-26 (0); Null = Dec-25, Mar-26, Jun-26. Blanks treated as zero.
A30: 2 | B30: Block 3 olive segment = Credit Cards (excl STPL + STPL); green segment = LAP. Ties to Block 2 within ±1 Cr.
A31: 3 | B31: Block 4 larger segment = Corporate Banking; smaller = Commercial Banking. Ties within single-digit ₹ Cr.
A32: 4 | B32: Unsecured retail = CC + STPL + Micro Banking + BIL/SBL; partnership book = DA + CL lines. Analyst mappings.
A33: 5 | B33: 'Retail - Others' Sep-25 (₹4,391 Cr) treated as containing ~₹4,000 Cr later reclassified (likely into the Null bucket).
A34: 6 | B34: 'Illustrative' run-rate projections are arithmetic extrapolations, not forecasts.
A36: Confidentiality | B36: Client-confidential RBL Bank data. Do not combine with other clients' data.
A38: ⚠ DRAFT ONLY — Requires review and approval by a qualified Alvarez and Marsal professional before use.

Sheet P1_NetFunded_Qtr
A1: Block 1 — Net Funded Advances (quarterly stacked chart)
A2: Source: Net Advances Insights.pdf, 'Net Funded Advances' chart | ₹ Cr | Sep-25, Dec-25, Mar-26, Jun-26 quarter-ends | all actuals
A3: ⚠ DRAFT ONLY — Requires review and approval by a qualified Alvarez and Marsal professional before use.
A5: A. Source data as printed (blue)
A6: # | B6: Series | C6: Sep-25 | D6: Dec-25 | E6: Mar-26 | F6: Jun-26 | G6: Note
A7: 1 | B7: Wholesale | C7: 40396 | D7: 42475 | E7: 47112 | F7: 51044 | G7: Teal (bottom) — ties to Block 4
A8: 2 | B8: Retail | C8: 60131 | D8: 59611 | E8: 63419 | F8: 64195 | G8: Navy (top) — ties to Block 3
A9: 3 | B9: Total (printed) | C9: 100527 | D9: 102086 | E9: 110532 | F9: 115240 | G9: Differs from Block 2 Grand Total in Dec/Mar/Jun
A11: B. Derived series (live formulas)
A12: # | B12: Derived series | C12: Sep-25 | D12: Dec-25 | E12: Mar-26 | F12: Jun-26
A13: 1 | B13: Computed total W + R | C13: =C7+C8 -> 100527 | D13: =D7+D8 -> 102086 | E13: =E7+E8 -> 110531 | F13: =F7+F8 -> 115239
A14: 2 | B14: Rounding gap printed − computed | C14: =C9-C13 -> 0 | D14: =D9-D13 -> 0 | E14: =E9-E13 -> 1 | F14: =F9-F13 -> 1
A15: 3 | B15: Wholesale share | C15: =C7/C9 -> 0.40184229 | D15: =D7/D9 -> 0.41607076 | E15: =E7/E9 -> 0.42622951 | F15: =F7/F9 -> 0.44293648
A16: 4 | B16: Retail share | C16: =C8/C9 -> 0.59815771 | D16: =D8/D9 -> 0.58392924 | E16: =E8/E9 -> 0.57376144 | F16: =F8/F9 -> 0.55705484
A17: 5 | B17: Wholesale : Retail ratio | C17: =C7/C8 -> 0.6717999 | D17: =D7/D8 -> 0.71253628 | E17: =E7/E8 -> 0.74286886 | F17: =F7/F8 -> 0.79513981
A18: 6 | B18: QoQ Δ Wholesale | C18: – | D18: =D7-C7 -> 2079 | E18: =E7-D7 -> 4637 | F18: =F7-E7 -> 3932
A19: 7 | B19: QoQ Δ Retail | C19: – | D19: =D8-C8 -> -520 | E19: =E8-D8 -> 3808 | F19: =F8-E8 -> 776
A20: 8 | B20: QoQ Δ Total | C20: – | D20: =D9-C9 -> 1559 | E20: =E9-D9 -> 8446 | F20: =F9-E9 -> 4708
A21: 9 | B21: QoQ growth Wholesale | C21: – | D21: =D7/C7-1 -> 0.051465492 | E21: =E7/D7-1 -> 0.1091701 | F21: =F7/E7-1 -> 0.083460689
A22: 10 | B22: QoQ growth Retail | C22: – | D22: =D8/C8-1 -> -0.0086477857 | E22: =E8/D8-1 -> 0.063880827 | F22: =F8/E8-1 -> 0.012236081
A23: 11 | B23: QoQ growth Total | C23: – | D23: =D9/C9-1 -> 0.015508271 | E23: =E9/D9-1 -> 0.082734165 | F23: =F9/E9-1 -> 0.042594
A24: 12 | B24: Wholesale contribution to QoQ Δ | C24: – | D24: =D18/D20 -> 1.3335471 | E24: =E18/E20 -> 0.54901729 | F24: =F18/F20 -> 0.83517417
A25: 13 | B25: Retail contribution to QoQ Δ | C25: – | D25: =D19/D20 -> -0.33354715 | E25: =E19/E20 -> 0.45086431 | F25: =F19/F20 -> 0.16482583
A26: 14 | B26: Growth differential W − R | C26: – | D26: =(D21-D22)*100 -> 6.0113277 | E26: =(E21-E22)*100 -> 4.5289273 | F26: =(F21-F22)*100 -> 7.1224609
A27: 15 | B27: Cumulative growth vs Sep-25 — Wholesale | C27: =C7/$C$7-1 -> 0 | D27: =D7/$C$7-1 -> 0.051465492 | E27: =E7/$C$7-1 -> 0.16625408 | F27: =F7/$C$7-1 -> 0.26359045
A28: 16 | B28: Cumulative growth vs Sep-25 — Retail | C28: =C8/$C$8-1 -> 0 | D28: =D8/$C$8-1 -> -0.0086477857 | E28: =E8/$C$8-1 -> 0.054680614 | F28: =F8/$C$8-1 -> 0.067585771
A29: 17 | B29: Cumulative growth vs Sep-25 — Total | C29: =C9/$C$9-1 -> 0 | D29: =D9/$C$9-1 -> 0.015508271 | E29: =E9/$C$9-1 -> 0.099525501 | F29: =F9/$C$9-1 -> 0.14635869
A30: 18 | B30: Index Wholesale (Sep-25 = 100) | C30: =100*C7/$C$7 -> 100 | D30: =100*D7/$C$7 -> 105.14655 | E30: =100*E7/$C$7 -> 116.62541 | F30: =100*F7/$C$7 -> 126.35905
A31: 19 | B31: Index Retail (Sep-25 = 100) | C31: =100*C8/$C$8 -> 100 | D31: =100*D8/$C$8 -> 99.135221 | E31: =100*E8/$C$8 -> 105.46806 | F31: =100*F8/$C$8 -> 106.75858
A32: 20 | B32: Wholesale share change QoQ | C32: – | D32: =(D15-C15)*100 -> 1.4228473 | E32: =(E15-D15)*100 -> 1.0158744 | F32: =(F15-E15)*100 -> 1.6706972
A33: 21 | B33: Avg of opening & closing total (avg book proxy) | C33: – | D33: =AVERAGE(C9,D9) -> 101306.5 | E33: =AVERAGE(D9,E9) -> 106309 | F33: =AVERAGE(E9,F9) -> 112886
A36: Data points to flag before metrics (live checks)
A37: # | B37: Flag | C37: Check value (live) | D37: Unit | E37: Implication / action
A38: 1 | B38: Chart totals differ from the Block-2 Grand Total in Dec-25, Mar-26, Jun-26 — by exactly the Null bucket. | C38: =SUMPRODUCT(ABS(P2_Detailed_Table!E68:H68)) -> 5686 | D38: ₹ Cr | E38: Chart = excl-Null basis. State the basis on every bank-level number.
A39: 2 | B39: Rounding: W + R ≠ printed total by ₹1 Cr in Mar-26 and Jun-26. | C39: =SUMPRODUCT(ABS(C14:F14)) -> 2 | D39: ₹ Cr | E39: Immaterial.
A40: 3 | B40: Retail declined in Dec-25 (−₹520 Cr QoQ) while wholesale grew — partly the 'Retail - Others' reclass into the Null bucket (Block 2). | C40: =D19 -> -520 | D40: ₹ Cr | E40: Read retail QoQ alongside Block 2 like-for-like.
A41: 4 | B41: Only 4 quarter-ends; no prior-year comparatives on this chart → no YoY. | C41: ="n/a" -> n/a | D41: text | E41: Use Blocks 3/4 for the one YoY pair available (Aug).
A43: Notation and exhaustive metrics table for this block: see sheet P1_Metrics
A45: 10-question test set (3 Low / 4 Medium / 3 High) — expected answers are live formulas
A46: # | B46: Level | C46: Question | D46: Calculation | E46: Expected answer (live) | F46: Unit | G46: So what
...

Sheet P1_Metrics
A1: Block 1 — Net Funded Advances (quarterly): notation and metrics
A2: Format: Notation → Exhaustive metrics table | Example column = live Excel formula on the block sheet (green = cross-sheet)
A3: ⚠ DRAFT ONLY — Requires review and approval by a qualified Alvarez and Marsal professional before use.
A5: Notation
B6: Symbol | C6: Meaning
B7: W | C7: Wholesale net funded advances (chart teal segment)
B8: R | C8: Retail net funded advances (chart navy segment)
B9: T | C9: Total net funded advances as printed on the chart
B10: X | C10: Any of W, R, T
B11: q | C11: Quarter-end: Sep-25, Dec-25, Mar-26, Jun-26
B12: ΔX | C12: X(q) − X(q−1)
B13: gX | C13: X(q) ÷ X(q−1) − 1
B14: 9M | C14: Sep-25 → Jun-26 (three quarters)
B15: CQGR | C15: Compounded quarterly growth rate
B16: GT | C16: Grand Total as printed on the Block-2 detailed table
B17: NULL | C17: Block-2 'Null' bucket row
B18: WM / RM | C18: Block-4 monthly wholesale / Block-3 monthly retail at the same month-end
B19: Values are ₹ Cr as printed; all periods are actuals; growth in %, share shifts in pp.
A21: Exhaustive metrics table
A22: # | B22: Metric family | C22: Pipeline-ready metric | D22: Definition / formula | E22: Applies to | F22: Example
A23: 1 | B23: Fact lookup | C23: Quarter-end balances | D23: W, R, T as printed | E23: 3 series × 4 quarter-ends | F23: ="W "&TEXT(P1_NetFunded_Qtr!C7,"#,##0;-#,##0;0")&" / "&TEXT(P1_NetFunded_Qtr!D7,"#,##0;-#,##0;0")&" / "&TEXT(P1_NetFunded_Qtr!E7,"#,##0;-#,##0;0")&" / "&TEXT(P1_NetFunded_Qtr!F7,"#,##0;-#,##0;0")&"; R "&TEXT(P1_NetFunded_Qtr!C8,"#,##0;-#,##0;0")&" / "&TEXT(P1_NetFunded_Qtr!D8,"#,##0;-#,##0;0")&" / "&TEXT(P1_NetFunded_Qtr!E8,"#,##0;-#,##0;0")&" / "&TEXT(P1_NetFunded_Qtr!F8,"#,##0;-#,##0;0")&"; T "&TEXT(P1_NetFunded_Qtr!C9,"#,##0;-#,##0;0")&" / "&TEXT(P1_NetFunded_Qtr!D9,"#,##0;-#,##0;0")&" / "&TEXT(P1_NetFunded_Qtr!E9,"#,##0;-#,##0;0")&" / "&TEXT(P1_NetFunded_Qtr!F9,"#,##0;-#,##0;0") -> W 40,396 / 42,475 / 47,112 / 51,044; R 60,131 / 59,611 / 63,419 / 64,195; T 100,527 / 102,086 / 110,532 / 115,240
A24: 2 | B24: Roll-up check | C24: Total | D24: W + R vs T | E24: 4 quarter-ends | F24: ="W + R "&TEXT(P1_NetFunded_Qtr!C13,"#,##0;-#,##0;0")&" / "&TEXT(P1_NetFunded_Qtr!D13,"#,##0;-#,##0;0")&" / "&TEXT(P1_NetFunded_Qtr!E13,"#,##0;-#,##0;0")&" / "&TEXT(P1_NetFunded_Qtr!F13,"#,##0;-#,##0;0")&"; T − (W + R) "&TEXT(P1_NetFunded_Qtr!C14,"#,##0;-#,##0;0")&" / "&TEXT(P1_NetFunded_Qtr!D14,"#,##0;-#,##0;0")&" / "&TEXT(P1_NetFunded_Qtr!E14,"#,##0;-#,##0;0")&" / "&TEXT(P1_NetFunded_Qtr!F14,"#,##0;-#,##0;0") -> W + R 100,527 / 102,086 / 110,531 / 115,239; T − (W + R) 0 / 0 / 1 / 1
A25: 3 | B25: Mix & share | C25: Wholesale share | D25: W ÷ T | E25: 4 quarter-ends | F25: =TEXT(P1_NetFunded_Qtr!C15,"0.0%")&" / "&TEXT(P1_NetFunded_Qtr!D15,"0.0%")&" / "&TEXT(P1_NetFunded_Qtr!E15,"0.0%")&" / "&TEXT(P1_NetFunded_Qtr!F15,"0.0%") -> 40.2% / 41.6% / 42.6% / 44.3%
A26: 4 | B26: Mix & share | C26: Retail share | D26: R ÷ T | E26: 4 quarter-ends | F26: =TEXT(P1_NetFunded_Qtr!C16,"0.0%")&" / "&TEXT(P1_NetFunded_Qtr!D16,"0.0%")&" / "&TEXT(P1_NetFunded_Qtr!E16,"0.0%")&" / "&TEXT(P1_NetFunded_Qtr!F16,"0.0%") -> 59.8% / 58.4% / 57.4% / 55.7%
A27: 5 | B27: Mix & share | C27: Wholesale-to-retail ratio | D27: W ÷ R | E27: 4 quarter-ends | F27: =TEXT(P1_NetFunded_Qtr!C17,"0.00""x""")&" / "&TEXT(P1_NetFunded_Qtr!D17,"0.00""x""")&" / "&TEXT(P1_NetFunded_Qtr!E17,"0.00""x""")&" / "&TEXT(P1_NetFunded_Qtr!F17,"0.00""x""") -> 0.67x / 0.71x / 0.74x / 0.80x
A28: 6 | B28: Mix & share | C28: Wholesale share shift | D28: (W ÷ T)(q) − (W ÷ T)(q−1), in pp | E28: 3 quarters + 9M | F28: =TEXT(P1_NetFunded_Qtr!D32,"+0.0"" pp"";-0.0"" pp"";0.0"" pp""")&" / "&TEXT(P1_NetFunded_Qtr!E32,"+0.0"" pp"";-0.0"" pp"";0.0"" pp""")&" / "&TEXT(P1_NetFunded_Qtr!F32,"+0.0"" pp"";-0.0"" pp"";0.0"" pp""")&"; 9M "&TEXT((P1_NetFunded_Qtr!F15-P1_NetFunded_Qtr!C15)*100,"+0.0"" pp"";-0.0"" pp"";0.0"" pp""") -> +1.4 pp / +1.0 pp / +1.7 pp; 9M +4.1 pp
A29: 7 | B29: Growth & momentum | C29: QoQ change | D29: X(q) − X(q−1) | E29: 3 series × 3 quarters | F29: ="W "&TEXT(P1_NetFunded_Qtr!D18,"#,##0;-#,##0;0")&" / "&TEXT(P1_NetFunded_Qtr!E18,"#,##0;-#,##0;0")&" / "&TEXT(P1_NetFunded_Qtr!F18,"#,##0;-#,##0;0")&"; R "&TEXT(P1_NetFunded_Qtr!D19,"#,##0;-#,##0;0")&" / "&TEXT(P1_NetFunded_Qtr!E19,"#,##0;-#,##0;0")&" / "&TEXT(P1_NetFunded_Qtr!F19,"#,##0;-#,##0;0")&"; T "&TEXT(P1_NetFunded_Qtr!D20,"#,##0;-#,##0;0")&" / "&TEXT(P1_NetFunded_Qtr!E20,"#,##0;-#,##0;0")&" / "&TEXT(P1_NetFunded_Qtr!F20,"#,##0;-#,##0;0") -> W 2,079 / 4,637 / 3,932; R -520 / 3,808 / 776; T 1,559 / 8,446 / 4,708
A30: 8 | B30: Growth & momentum | C30: QoQ growth | D30: X(q) ÷ X(q−1) − 1 | E30: 3 series × 3 quarters | F30: ="W "&TEXT(P1_NetFunded_Qtr!D21,"+0.0%;-0.0%;0.0%")&" / "&TEXT(P1_NetFunded_Qtr!E21,"+0.0%;-0.0%;0.0%")&" / "&TEXT(P1_NetFunded_Qtr!F21,"+0.0%;-0.0%;0.0%")&"; R "&TEXT(P1_NetFunded_Qtr!D22,"+0.0%;-0.0%;0.0%")&" / "&TEXT(P1_NetFunded_Qtr!E22,"+0.0%;-0.0%;0.0%")&" / "&TEXT(P1_NetFunded_Qtr!F22,"+0.0%;-0.0%;0.0%")&"; T "&TEXT(P1_NetFunded_Qtr!D23,"+0.0%;-0.0%;0.0%")&" / "&TEXT(P1_NetFunded_Qtr!E23,"+0.0%;-0.0%;0.0%")&" / "&TEXT(P1_NetFunded_Qtr!F23,"+0.0%;-0.0%;0.0%") -> W +5.1% / +10.9% / +8.3%; R -0.9% / +6.4% / +1.2%; T +1.6% / +8.3% / +4.3%
A31: 9 | B31: Growth & momentum | C31: 9M growth | D31: X(Jun-26) ÷ X(Sep-25) − 1; ΔX(9M) | E31: 3 series | F31: ="W "&TEXT(P1_NetFunded_Qtr!F7/P1_NetFunded_Qtr!C7-1,"+0.0%;-0.0%;0.0%")&" ("&TEXT(P1_NetFunded_Qtr!F7-P1_NetFunded_Qtr!C7,"#,##0;-#,##0;0")&"); R "&TEXT(P1_NetFunded_Qtr!F8/P1_NetFunded_Qtr!C8-1,"+0.0%;-0.0%;0.0%")&" ("&TEXT(P1_NetFunded_Qtr!F8-P1_NetFunded_Qtr!C8,"#,##0;-#,##0;0")&"); T "&TEXT(P1_NetFunded_Qtr!F9/P1_NetFunded_Qtr!C9-1,"+0.0%;-0.0%;0.0%")&" ("&TEXT(P1_NetFunded_Qtr!F9-P1_NetFunded_Qtr!C9,"#,##0;-#,##0;0")&")" -> W +26.4% (10,648); R +6.8% (4,064); T +14.6% (14,713)
A32: 10 | B32: Growth & momentum | C32: Compounded quarterly growth | D32: (X(Jun-26) ÷ X(Sep-25))^(1/3) − 1 | E32: 3 series | F32: ="W "&TEXT((P1_NetFunded_Qtr!F7/P1_NetFunded_Qtr!C7)^(1/3)-1,"+0.0%;-0.0%;0.0%")&"; R "&TEXT((P1_NetFunded_Qtr!F8/P1_NetFunded_Qtr!C8)^(1/3)-1,"+0.0%;-0.0%;0.0%")&"; T "&TEXT((P1_NetFunded_Qtr!F9/P1_NetFunded_Qtr!C9)^(1/3)-1,"+0.0%;-0.0%;0.0%") -> W +8.1%; R +2.2%; T +4.7%
A33: 11 | B33: Growth & momentum | C33: Annualised growth | D33: (X(Jun-26) ÷ X(Sep-25))^(4/3) − 1 | E33: 3 series | F33: ="W "&TEXT((P1_NetFunded_Qtr!F7/P1_NetFunded_Qtr!C7)^(4/3)-1,"+0.0%;-0.0%;0.0%")&"; R "&TEXT((P1_NetFunded_Qtr!F8/P1_NetFunded_Qtr!C8)^(4/3)-1,"+0.0%;-0.0%;0.0%")&"; T "&TEXT((P1_NetFunded_Qtr!F9/P1_NetFunded_Qtr!C9)^(4/3)-1,"+0.0%;-0.0%;0.0%") -> W +36.6%; R +9.1%; T +20.0%
A34: 12 | B34: Growth & momentum | C34: Cumulative growth vs Sep-25 | D34: X(q) ÷ X(Sep-25) − 1 | E34: 3 series × 3 quarters | F34: ="W "&TEXT(P1_NetFunded_Qtr!D27,"+0.0%;-0.0%;0.0%")&" / "&TEXT(P1_NetFunded_Qtr!E27,"+0.0%;-0.0%;0.0%")&" / "&TEXT(P1_NetFunded_Qtr!F27,"+0.0%;-0.0%;0.0%")&"; R "&TEXT(P1_NetFunded_Qtr!D28,"+0.0%;-0.0%;0.0%")&" / "&TEXT(P1_NetFunded_Qtr!E28,"+0.0%;-0.0%;0.0%")&" / "&TEXT(P1_NetFunded_Qtr!F28,"+0.0%;-0.0%;0.0%")&"; T "&TEXT(P1_NetFunded_Qtr!D29,"+0.0%;-0.0%;0.0%")&" / "&TEXT(P1_NetFunded_Qtr!E29,"+0.0%;-0.0%;0.0%")&" / "&TEXT(P1_NetFunded_Qtr!F29,"+0.0%;-0.0%;0.0%") -> W +5.1% / +16.6% / +26.4%; R -0.9% / +5.5% / +6.8%; T +1.6% / +10.0% / +14.6%
A35: 13 | B35: Growth & momentum | C35: Growth index | D35: 100 × X(q) ÷ X(Sep-25) | E35: W, R × 4 quarter-ends | F35: ="W "&TEXT(P1_NetFunded_Qtr!C30,"0.0")&" / "&TEXT(P1_NetFunded_Qtr!D30,"0.0")&" / "&TEXT(P1_NetFunded_Qtr!E30,"0.0")&" / "&TEXT(P1_NetFunded_Qtr!F30,"0.0")&"; R "&TEXT(P1_NetFunded_Qtr!C31,"0.0")&" / "&TEXT(P1_NetFunded_Qtr!D31,"0.0")&" / "&TEXT(P1_NetFunded_Qtr!E31,"0.0")&" / "&TEXT(P1_NetFunded_Qtr!F31,"0.0") -> W 100.0 / 105.1 / 116.6 / 126.4; R 100.0 / 99.1 / 105.5 / 106.8
A36: 14 | B36: Growth & momentum | C36: Growth differential | D36: gW(q) − gR(q), in pp | E36: 3 quarters + 9M | F36: =TEXT(P1_NetFunded_Qtr!D26,"+0.0"" pp"";-0.0"" pp"";0.0"" pp""")&" / "&TEXT(P1_NetFunded_Qtr!E26,"+0.0"" pp"";-0.0"" pp"";0.0"" pp""")&" / "&TEXT(P1_NetFunded_Qtr!F26,"+0.0"" pp"";-0.0"" pp"";0.0"" pp""")&"; 9M "&TEXT((P1_NetFunded_Qtr!F27-P1_NetFunded_Qtr!F28)*100,"+0.0"" pp"";-0.0"" pp"";0.0"" pp""") -> +6.0 pp / +4.5 pp / +7.1 pp; 9M +19.6 pp
A37: 15 | B37: Growth & momentum | C37: Acceleration | D37: gT(q) − gT(q−1), in pp | E37: Mar-26, Jun-26 | F37: ="Mar-26 "&TEXT((P1_NetFunded_Qtr!E23-P1_NetFunded_Qtr!D23)*100,"+0.0"" pp"";-0.0"" pp"";0.0"" pp""")&"; Jun-26 "&TEXT((P1_NetFunded_Qtr!F23-P1_NetFunded_Qtr!E23)*100,"+0.0"" pp"";-0.0"" pp"";0.0"" pp""") -> Mar-26 +6.7 pp; Jun-26 -4.0 pp
A38: 16 | B38: Growth & momentum | C38: Momentum ratio | D38: AVERAGE(ΔT Mar-26, ΔT Jun-26) ÷ ΔT Dec-25 | E38: Window | F38: =TEXT(AVERAGE(P1_NetFunded_Qtr!E20:F20)/P1_NetFunded_Qtr!D20,"0.00""x""") -> 4.22x
A39: 17 | B39: Growth & momentum | C39: Retail decline quarters | D39: COUNT(ΔR < 0) | E39: 3 quarters | F39: =TEXT(COUNTIF(P1_NetFunded_Qtr!D19:F19,"<0"),"0")&" (Dec-25 ΔR "&TEXT(P1_NetFunded_Qtr!D19,"#,##0;-#,##0;0")&")" -> 1 (Dec-25 ΔR -520)
A40: 18 | B40: Attribution | C40: Contribution to QoQ change | D40: ΔW ÷ ΔT; ΔR ÷ ΔT | E40: 3 quarters | F40: ="W "&TEXT(P1_NetFunded_Qtr!D24,"0.0%")&" / "&TEXT(P1_NetFunded_Qtr!E24,"0.0%")&" / "&TEXT(P1_NetFunded_Qtr!F24,"0.0%")&"; R "&TEXT(P1_NetFunded_Qtr!D25,"0.0%")&" / "&TEXT(P1_NetFunded_Qtr!E25,"0.0%")&" / "&TEXT(P1_NetFunded_Qtr!F25,"0.0%") -> W 133.4% / 54.9% / 83.5%; R -33.4% / 45.1% / 16.5%
A41: 19 | B41: Attribution | C41: Incremental mix | D41: ΔW(9M) ÷ ΔT(9M); ΔR(9M) ÷ ΔT(9M) | E41: Window | F41: ="W "&TEXT((P1_NetFunded_Qtr!F7-P1_NetFunded_Qtr!C7)/(P1_NetFunded_Qtr!F9-P1_NetFunded_Qtr!C9),"0.0%")&"; R "&TEXT((P1_NetFunded_Qtr!F8-P1_NetFunded_Qtr!C8)/(P1_NetFunded_Qtr!F9-P1_NetFunded_Qtr!C9),"0.0%") -> W 72.4%; R 27.6%
A42: 20 | B42: Attribution | C42: Marginal vs average mix gap | D42: (ΔW(9M) ÷ ΔT(9M) − W(Sep-25) ÷ T(Sep-25)) × 100 | E42: Window | F42: =TEXT(((P1_NetFunded_Qtr!F7-P1_NetFunded_Qtr!C7)/(P1_NetFunded_Qtr!F9-P1_NetFunded_Qtr!C9)-P1_NetFunded_Qtr!C15)*100,"+0.0"" pp"";-0.0"" pp"";0.0"" pp""") -> +32.2 pp
...

Sheet P2_Detailed_Table
A1: Block 2 — Net Funded Advances Detailed (product-level table)
A2: Source: Net Advances Insights.pdf, 'Net Funded Advances Detailed' table | ₹ Cr | Quarter-ends Sep-25, Dec-25, Mar-26, Jun-26 | all actuals
A3: ⚠ DRAFT ONLY — Requires review and approval by a qualified Alvarez and Marsal professional before use.
A5: A. Source data as printed (blue) with line-level live calculations (black)
A6: # | B6: Category | C6: Business line | D6: Product | E6: Sep-25 | F6: Dec-25 | G6: Mar-26 | H6: Jun-26 | I6: QoQ Dec-25 | J6: QoQ Mar-26 | K6: QoQ Jun-26 | L6: 9M Δ (₹ Cr) | M6: 9M growth % | N6: Share of bank Jun-26 (excl Null) | O6: Share of category Jun-26 | P6: Contribution to bank 9M growth | Q6: Rank Jun-26 | R6: Auto-flag
A7: 1 | B7: Wholesale | C7: Commercial Banking | D7: CB (incl Agri & NE) | E7: 11556 | F7: 12413 | G7: 13493 | H7: 15070 | I7: =IF(OR(E7="",F7="",N(E7)=0),"n/a",F7/E7-1) -> 0.074160609 | J7: =IF(OR(F7="",G7="",N(F7)=0),"n/a",G7/F7-1) -> 0.087005559 | K7: =IF(OR(G7="",H7="",N(G7)=0),"n/a",H7/G7-1) -> 0.11687542 | L7: =N(H7)-N(E7) -> 3514 | M7: =IF(OR(E7="",H7="",N(E7)=0),"n/a",H7/E7-1) -> 0.30408446 | N7: =IF(H7="","",H7/$H$62) -> 0.1307717 | O7: =IF(H7="","",H7/SUMIFS($H$7:$H$42,$B$7:$B$42,B7)) -> 0.29523548 | P7: =IF(B7="Null","excl.",L7/($H$62-$E$62)) -> 0.23885264 | Q7: =IF(OR(B7="Null",H7=""),"",RANK(H7,$H$7:$H$41)) -> 3 | R7: =IF(B7="Null","Unmapped Null bucket – excluded from chart totals",IF(COUNT(E7:H7)<4,"Partial-period – column placement inferred",IF(AND(ISNUMBER(M7),ABS(M7)>0.5),"Large 9M swing (>±50%)","")))
A8: 2 | B8: Wholesale | C8: Commercial Banking | D8: CB- BBG | E8: 23 | F8: 145 | G8: 149 | H8: 150 | I8: =IF(OR(E8="",F8="",N(E8)=0),"n/a",F8/E8-1) -> 5.3043478 | J8: =IF(OR(F8="",G8="",N(F8)=0),"n/a",G8/F8-1) -> 0.027586207 | K8: =IF(OR(G8="",H8="",N(G8)=0),"n/a",H8/G8-1) -> 0.0067114094 | L8: =N(H8)-N(E8) -> 127 | M8: =IF(OR(E8="",H8="",N(E8)=0),"n/a",H8/E8-1) -> 5.5217391 | N8: =IF(H8="","",H8/$H$62) -> 0.0013016427 | O8: =IF(H8="","",H8/SUMIFS($H$7:$H$42,$B$7:$B$42,B8)) -> 0.0029386412 | P8: =IF(B8="Null","excl.",L8/($H$62-$E$62)) -> 0.0086324089 | Q8: =IF(OR(B8="Null",H8=""),"",RANK(H8,$H$7:$H$41)) -> 25 | R8: =IF(B8="Null","Unmapped Null bucket – excluded from chart totals",IF(COUNT(E8:H8)<4,"Partial-period – column placement inferred",IF(AND(ISNUMBER(M8),ABS(M8)>0.5),"Large 9M swing (>±50%)",""))) -> Large 9M swing (>±50%)
A9: 3 | B9: Wholesale | C9: Commercial Banking | D9: Supply Chain | E9: 1536 | F9: 1457 | G9: 1626 | H9: 1654 | I9: =IF(OR(E9="",F9="",N(E9)=0),"n/a",F9/E9-1) -> -0.051432292 | J9: =IF(OR(F9="",G9="",N(F9)=0),"n/a",G9/F9-1) -> 0.11599176 | K9: =IF(OR(G9="",H9="",N(G9)=0),"n/a",H9/G9-1) -> 0.017220172 | L9: =N(H9)-N(E9) -> 118 | M9: =IF(OR(E9="",H9="",N(E9)=0),"n/a",H9/E9-1) -> 0.076822917 | N9: =IF(H9="","",H9/$H$62) -> 0.01435278 | O9: =IF(H9="","",H9/SUMIFS($H$7:$H$42,$B$7:$B$42,B9)) -> 0.032403417 | P9: =IF(B9="Null","excl.",L9/($H$62-$E$62)) -> 0.0080206634 | Q9: =IF(OR(B9="Null",H9=""),"",RANK(H9,$H$7:$H$41)) -> 16 | R9: =IF(B9="Null","Unmapped Null bucket – excluded from chart totals",IF(COUNT(E9:H9)<4,"Partial-period – column placement inferred",IF(AND(ISNUMBER(M9),ABS(M9)>0.5),"Large 9M swing (>±50%)","")))
A10: 4 | B10: Wholesale | C10: Corporate Banking | D10: C&IB Agri | F10: 1 | G10: 1 | I10: =IF(OR(E10="",F10="",N(E10)=0),"n/a",F10/E10-1) -> n/a | J10: =IF(OR(F10="",G10="",N(F10)=0),"n/a",G10/F10-1) -> 0 | K10: =IF(OR(G10="",H10="",N(G10)=0),"n/a",H10/G10-1) -> n/a | L10: =N(H10)-N(E10) -> 0 | M10: =IF(OR(E10="",H10="",N(E10)=0),"n/a",H10/E10-1) -> n/a | N10: =IF(H10="","",H10/$H$62) | O10: =IF(H10="","",H10/SUMIFS($H$7:$H$42,$B$7:$B$42,B10)) | P10: =IF(B10="Null","excl.",L10/($H$62-$E$62)) -> 0 | Q10: =IF(OR(B10="Null",H10=""),"",RANK(H10,$H$7:$H$41)) | R10: =IF(B10="Null","Unmapped Null bucket – excluded from chart totals",IF(COUNT(E10:H10)<4,"Partial-period – column placement inferred",IF(AND(ISNUMBER(M10),ABS(M10)>0.5),"Large 9M swing (>±50%)",""))) -> Partial-period – column placement inferred
A11: 5 | B11: Wholesale | C11: Corporate Banking | D11: Corporate Banking (incl G&J) | E11: 17696 | F11: 18438 | G11: 19782 | H11: 21812 | I11: =IF(OR(E11="",F11="",N(E11)=0),"n/a",F11/E11-1) -> 0.04193038 | J11: =IF(OR(F11="",G11="",N(F11)=0),"n/a",G11/F11-1) -> 0.072892938 | K11: =IF(OR(G11="",H11="",N(G11)=0),"n/a",H11/G11-1) -> 0.10261854 | L11: =N(H11)-N(E11) -> 4116 | M11: =IF(OR(E11="",H11="",N(E11)=0),"n/a",H11/E11-1) -> 0.23259494 | N11: =IF(H11="","",H11/$H$62) -> 0.1892762 | O11: =IF(H11="","",H11/SUMIFS($H$7:$H$42,$B$7:$B$42,B11)) -> 0.42731761 | P11: =IF(B11="Null","excl.",L11/($H$62-$E$62)) -> 0.27977162 | Q11: =IF(OR(B11="Null",H11=""),"",RANK(H11,$H$7:$H$41)) -> 1 | R11: =IF(B11="Null","Unmapped Null bucket – excluded from chart totals",IF(COUNT(E11:H11)<4,"Partial-period – column placement inferred",IF(AND(ISNUMBER(M11),ABS(M11)>0.5),"Large 9M swing (>±50%)","")))
A12: 6 | B12: Wholesale | C12: Corporate Banking | D12: FI | E12: 6775 | F12: 6835 | G12: 8195 | H12: 8205 | I12: =IF(OR(E12="",F12="",N(E12)=0),"n/a",F12/E12-1) -> 0.0088560886 | J12: =IF(OR(F12="",G12="",N(F12)=0),"n/a",G12/F12-1) -> 0.19897586 | K12: =IF(OR(G12="",H12="",N(G12)=0),"n/a",H12/G12-1) -> 0.0012202563 | L12: =N(H12)-N(E12) -> 1430 | M12: =IF(OR(E12="",H12="",N(E12)=0),"n/a",H12/E12-1) -> 0.21107011 | N12: =IF(H12="","",H12/$H$62) -> 0.071199854 | O12: =IF(H12="","",H12/SUMIFS($H$7:$H$42,$B$7:$B$42,B12)) -> 0.16074367 | P12: =IF(B12="Null","excl.",L12/($H$62-$E$62)) -> 0.097199565 | Q12: =IF(OR(B12="Null",H12=""),"",RANK(H12,$H$7:$H$41)) -> 6 | R12: =IF(B12="Null","Unmapped Null bucket – excluded from chart totals",IF(COUNT(E12:H12)<4,"Partial-period – column placement inferred",IF(AND(ISNUMBER(M12),ABS(M12)>0.5),"Large 9M swing (>±50%)","")))
A13: 7 | B13: Wholesale | C13: Corporate Banking | D13: FIGU- BBB | F13: 7 | G13: 7 | H13: 0 | I13: =IF(OR(E13="",F13="",N(E13)=0),"n/a",F13/E13-1) -> n/a | J13: =IF(OR(F13="",G13="",N(F13)=0),"n/a",G13/F13-1) -> 0 | K13: =IF(OR(G13="",H13="",N(G13)=0),"n/a",H13/G13-1) -> -1 | L13: =N(H13)-N(E13) -> 0 | M13: =IF(OR(E13="",H13="",N(E13)=0),"n/a",H13/E13-1) -> n/a | N13: =IF(H13="","",H13/$H$62) -> 0 | O13: =IF(H13="","",H13/SUMIFS($H$7:$H$42,$B$7:$B$42,B13)) -> 0 | P13: =IF(B13="Null","excl.",L13/($H$62-$E$62)) -> 0 | Q13: =IF(OR(B13="Null",H13=""),"",RANK(H13,$H$7:$H$41)) -> 32 | R13: =IF(B13="Null","Unmapped Null bucket – excluded from chart totals",IF(COUNT(E13:H13)<4,"Partial-period – column placement inferred",IF(AND(ISNUMBER(M13),ABS(M13)>0.5),"Large 9M swing (>±50%)",""))) -> Partial-period – column placement inferred
A14: 8 | B14: Wholesale | C14: Corporate Banking | D14: Govt. Banking | E14: 3 | I14: =IF(OR(E14="",F14="",N(E14)=0),"n/a",F14/E14-1) -> n/a | J14: =IF(OR(F14="",G14="",N(F14)=0),"n/a",G14/F14-1) -> n/a | K14: =IF(OR(G14="",H14="",N(G14)=0),"n/a",H14/G14-1) -> n/a | L14: =N(H14)-N(E14) -> -3 | M14: =IF(OR(E14="",H14="",N(E14)=0),"n/a",H14/E14-1) -> n/a | N14: =IF(H14="","",H14/$H$62) | O14: =IF(H14="","",H14/SUMIFS($H$7:$H$42,$B$7:$B$42,B14)) | P14: =IF(B14="Null","excl.",L14/($H$62-$E$62)) -> -0.00020391517 | Q14: =IF(OR(B14="Null",H14=""),"",RANK(H14,$H$7:$H$41)) | R14: =IF(B14="Null","Unmapped Null bucket – excluded from chart totals",IF(COUNT(E14:H14)<4,"Partial-period – column placement inferred",IF(AND(ISNUMBER(M14),ABS(M14)>0.5),"Large 9M swing (>±50%)",""))) -> Partial-period – column placement inferred
A15: 9 | B15: Wholesale | C15: Corporate Banking | D15: IFI | E15: 2698 | F15: 2901 | G15: 3540 | H15: 4008 | I15: =IF(OR(E15="",F15="",N(E15)=0),"n/a",F15/E15-1) -> 0.075240919 | J15: =IF(OR(F15="",G15="",N(F15)=0),"n/a",G15/F15-1) -> 0.22026887 | K15: =IF(OR(G15="",H15="",N(G15)=0),"n/a",H15/G15-1) -> 0.13220339 | L15: =N(H15)-N(E15) -> 1310 | M15: =IF(OR(E15="",H15="",N(E15)=0),"n/a",H15/E15-1) -> 0.48554485 | N15: =IF(H15="","",H15/$H$62) -> 0.034779892 | O15: =IF(H15="","",H15/SUMIFS($H$7:$H$42,$B$7:$B$42,B15)) -> 0.078520492 | P15: =IF(B15="Null","excl.",L15/($H$62-$E$62)) -> 0.089042958 | Q15: =IF(OR(B15="Null",H15=""),"",RANK(H15,$H$7:$H$41)) -> 8 | R15: =IF(B15="Null","Unmapped Null bucket – excluded from chart totals",IF(COUNT(E15:H15)<4,"Partial-period – column placement inferred",IF(AND(ISNUMBER(M15),ABS(M15)>0.5),"Large 9M swing (>±50%)","")))
A16: 10 | B16: Wholesale | C16: Corporate Banking | D16: MNC | E16: 108 | F16: 277 | G16: 322 | H16: 145 | I16: =IF(OR(E16="",F16="",N(E16)=0),"n/a",F16/E16-1) -> 1.5648148 | J16: =IF(OR(F16="",G16="",N(F16)=0),"n/a",G16/F16-1) -> 0.16245487 | K16: =IF(OR(G16="",H16="",N(G16)=0),"n/a",H16/G16-1) -> -0.54968944 | L16: =N(H16)-N(E16) -> 37 | M16: =IF(OR(E16="",H16="",N(E16)=0),"n/a",H16/E16-1) -> 0.34259259 | N16: =IF(H16="","",H16/$H$62) -> 0.0012582546 | O16: =IF(H16="","",H16/SUMIFS($H$7:$H$42,$B$7:$B$42,B16)) -> 0.0028406865 | P16: =IF(B16="Null","excl.",L16/($H$62-$E$62)) -> 0.0025149538 | Q16: =IF(OR(B16="Null",H16=""),"",RANK(H16,$H$7:$H$41)) -> 26 | R16: =IF(B16="Null","Unmapped Null bucket – excluded from chart totals",IF(COUNT(E16:H16)<4,"Partial-period – column placement inferred",IF(AND(ISNUMBER(M16),ABS(M16)>0.5),"Large 9M swing (>±50%)","")))
A17: 11 | B17: Retail | C17: Housing Loans | D17: Affordable Housing | E17: 1760 | F17: 1987 | G17: 2307 | H17: 2501 | I17: =IF(OR(E17="",F17="",N(E17)=0),"n/a",F17/E17-1) -> 0.12897727 | J17: =IF(OR(F17="",G17="",N(F17)=0),"n/a",G17/F17-1) -> 0.1610468 | K17: =IF(OR(G17="",H17="",N(G17)=0),"n/a",H17/G17-1) -> 0.084091894 | L17: =N(H17)-N(E17) -> 741 | M17: =IF(OR(E17="",H17="",N(E17)=0),"n/a",H17/E17-1) -> 0.42102273 | N17: =IF(H17="","",H17/$H$62) -> 0.021702722 | O17: =IF(H17="","",H17/SUMIFS($H$7:$H$42,$B$7:$B$42,B17)) -> 0.038959421 | P17: =IF(B17="Null","excl.",L17/($H$62-$E$62)) -> 0.050367047 | Q17: =IF(OR(B17="Null",H17=""),"",RANK(H17,$H$7:$H$41)) -> 13 | R17: =IF(B17="Null","Unmapped Null bucket – excluded from chart totals",IF(COUNT(E17:H17)<4,"Partial-period – column placement inferred",IF(AND(ISNUMBER(M17),ABS(M17)>0.5),"Large 9M swing (>±50%)","")))
A18: 12 | B18: Retail | C18: Housing Loans | D18: Housing Loan CL | E18: 1175 | F18: 1223 | G18: 1186 | H18: 1218 | I18: =IF(OR(E18="",F18="",N(E18)=0),"n/a",F18/E18-1) -> 0.040851064 | J18: =IF(OR(F18="",G18="",N(F18)=0),"n/a",G18/F18-1) -> -0.030253475 | K18: =IF(OR(G18="",H18="",N(G18)=0),"n/a",H18/G18-1) -> 0.02698145 | L18: =N(H18)-N(E18) -> 43 | M18: =IF(OR(E18="",H18="",N(E18)=0),"n/a",H18/E18-1) -> 0.036595745 | N18: =IF(H18="","",H18/$H$62) -> 0.010569339 | O18: =IF(H18="","",H18/SUMIFS($H$7:$H$42,$B$7:$B$42,B18)) -> 0.01897344 | P18: =IF(B18="Null","excl.",L18/($H$62-$E$62)) -> 0.0029227841 | Q18: =IF(OR(B18="Null",H18=""),"",RANK(H18,$H$7:$H$41)) -> 18 | R18: =IF(B18="Null","Unmapped Null bucket – excluded from chart totals",IF(COUNT(E18:H18)<4,"Partial-period – column placement inferred",IF(AND(ISNUMBER(M18),ABS(M18)>0.5),"Large 9M swing (>±50%)","")))
A19: 13 | B19: Retail | C19: Housing Loans | D19: Housing Loan DA | E19: 1008 | F19: 962 | G19: 938 | H19: 890 | I19: =IF(OR(E19="",F19="",N(E19)=0),"n/a",F19/E19-1) -> -0.045634921 | J19: =IF(OR(F19="",G19="",N(F19)=0),"n/a",G19/F19-1) -> -0.024948025 | K19: =IF(OR(G19="",H19="",N(G19)=0),"n/a",H19/G19-1) -> -0.051172708 | L19: =N(H19)-N(E19) -> -118 | M19: =IF(OR(E19="",H19="",N(E19)=0),"n/a",H19/E19-1) -> -0.11706349 | N19: =IF(H19="","",H19/$H$62) -> 0.0077230799 | O19: =IF(H19="","",H19/SUMIFS($H$7:$H$42,$B$7:$B$42,B19)) -> 0.013864008 | P19: =IF(B19="Null","excl.",L19/($H$62-$E$62)) -> -0.0080206634 | Q19: =IF(OR(B19="Null",H19=""),"",RANK(H19,$H$7:$H$41)) -> 20 | R19: =IF(B19="Null","Unmapped Null bucket – excluded from chart totals",IF(COUNT(E19:H19)<4,"Partial-period – column placement inferred",IF(AND(ISNUMBER(M19),ABS(M19)>0.5),"Large 9M swing (>±50%)","")))
A20: 14 | B20: Retail | C20: Housing Loans | D20: Prime Housing | E20: 4553 | F20: 4528 | G20: 4399 | H20: 4321 | I20: =IF(OR(E20="",F20="",N(E20)=0),"n/a",F20/E20-1) -> -0.0054908851 | J20: =IF(OR(F20="",G20="",N(F20)=0),"n/a",G20/F20-1) -> -0.028489399 | K20: =IF(OR(G20="",H20="",N(G20)=0),"n/a",H20/G20-1) -> -0.017731303 | L20: =N(H20)-N(E20) -> -232 | M20: =IF(OR(E20="",H20="",N(E20)=0),"n/a",H20/E20-1) -> -0.050955414 | N20: =IF(H20="","",H20/$H$62) -> 0.037495987 | O20: =IF(H20="","",H20/SUMIFS($H$7:$H$42,$B$7:$B$42,B20)) -> 0.067310538 | P20: =IF(B20="Null","excl.",L20/($H$62-$E$62)) -> -0.01576944 | Q20: =IF(OR(B20="Null",H20=""),"",RANK(H20,$H$7:$H$41)) -> 7 | R20: =IF(B20="Null","Unmapped Null bucket – excluded from chart totals",IF(COUNT(E20:H20)<4,"Partial-period – column placement inferred",IF(AND(ISNUMBER(M20),ABS(M20)>0.5),"Large 9M swing (>±50%)","")))
A21: 15 | B21: Retail | C21: Loan Against Property | D21: LAP - CL | E21: 393 | F21: 462 | G21: 473 | H21: 476 | I21: =IF(OR(E21="",F21="",N(E21)=0),"n/a",F21/E21-1) -> 0.17557252 | J21: =IF(OR(F21="",G21="",N(F21)=0),"n/a",G21/F21-1) -> 0.023809524 | K21: =IF(OR(G21="",H21="",N(G21)=0),"n/a",H21/G21-1) -> 0.0063424947 | L21: =N(H21)-N(E21) -> 83 | M21: =IF(OR(E21="",H21="",N(E21)=0),"n/a",H21/E21-1) -> 0.21119593 | N21: =IF(H21="","",H21/$H$62) -> 0.0041305461 | O21: =IF(H21="","",H21/SUMIFS($H$7:$H$42,$B$7:$B$42,B21)) -> 0.0074149077 | P21: =IF(B21="Null","excl.",L21/($H$62-$E$62)) -> 0.0056416531 | Q21: =IF(OR(B21="Null",H21=""),"",RANK(H21,$H$7:$H$41)) -> 22 | R21: =IF(B21="Null","Unmapped Null bucket – excluded from chart totals",IF(COUNT(E21:H21)<4,"Partial-period – column placement inferred",IF(AND(ISNUMBER(M21),ABS(M21)>0.5),"Large 9M swing (>±50%)","")))
A22: 16 | B22: Retail | C22: Loan Against Property | D22: LAP - DA | E22: 1742 | F22: 2169 | G22: 2103 | H22: 1990 | I22: =IF(OR(E22="",F22="",N(E22)=0),"n/a",F22/E22-1) -> 0.24512055 | J22: =IF(OR(F22="",G22="",N(F22)=0),"n/a",G22/F22-1) -> -0.030428769 | K22: =IF(OR(G22="",H22="",N(G22)=0),"n/a",H22/G22-1) -> -0.053732763 | L22: =N(H22)-N(E22) -> 248 | M22: =IF(OR(E22="",H22="",N(E22)=0),"n/a",H22/E22-1) -> 0.1423651 | N22: =IF(H22="","",H22/$H$62) -> 0.017268459 | O22: =IF(H22="","",H22/SUMIFS($H$7:$H$42,$B$7:$B$42,B22)) -> 0.030999299 | P22: =IF(B22="Null","excl.",L22/($H$62-$E$62)) -> 0.016856987 | Q22: =IF(OR(B22="Null",H22=""),"",RANK(H22,$H$7:$H$41)) -> 14 | R22: =IF(B22="Null","Unmapped Null bucket – excluded from chart totals",IF(COUNT(E22:H22)<4,"Partial-period – column placement inferred",IF(AND(ISNUMBER(M22),ABS(M22)>0.5),"Large 9M swing (>±50%)","")))
A23: 17 | B23: Retail | C23: Loan Against Property | D23: Prime LAP | E23: 8230 | F23: 8942 | G23: 9936 | H23: 10306 | I23: =IF(OR(E23="",F23="",N(E23)=0),"n/a",F23/E23-1) -> 0.086512758 | J23: =IF(OR(F23="",G23="",N(F23)=0),"n/a",G23/F23-1) -> 0.11116081 | K23: =IF(OR(G23="",H23="",N(G23)=0),"n/a",H23/G23-1) -> 0.037238325 | L23: =N(H23)-N(E23) -> 2076 | M23: =IF(OR(E23="",H23="",N(E23)=0),"n/a",H23/E23-1) -> 0.25224787 | N23: =IF(H23="","",H23/$H$62) -> 0.089431529 | O23: =IF(H23="","",H23/SUMIFS($H$7:$H$42,$B$7:$B$42,B23)) -> 0.1605421 | P23: =IF(B23="Null","excl.",L23/($H$62-$E$62)) -> 0.1411093 | Q23: =IF(OR(B23="Null",H23=""),"",RANK(H23,$H$7:$H$41)) -> 4 | R23: =IF(B23="Null","Unmapped Null bucket – excluded from chart totals",IF(COUNT(E23:H23)<4,"Partial-period – column placement inferred",IF(AND(ISNUMBER(M23),ABS(M23)>0.5),"Large 9M swing (>±50%)","")))
A24: 18 | B24: Retail | C24: Loan Against Property | D24: Small LAP | E24: 581 | F24: 750 | G24: 916 | H24: 999 | I24: =IF(OR(E24="",F24="",N(E24)=0),"n/a",F24/E24-1) -> 0.2908778 | J24: =IF(OR(F24="",G24="",N(F24)=0),"n/a",G24/F24-1) -> 0.22133333 | K24: =IF(OR(G24="",H24="",N(G24)=0),"n/a",H24/G24-1) -> 0.090611354 | L24: =N(H24)-N(E24) -> 418 | M24: =IF(OR(E24="",H24="",N(E24)=0),"n/a",H24/E24-1) -> 0.71944923 | N24: =IF(H24="","",H24/$H$62) -> 0.0086689402 | O24: =IF(H24="","",H24/SUMIFS($H$7:$H$42,$B$7:$B$42,B24)) -> 0.01556196 | P24: =IF(B24="Null","excl.",L24/($H$62-$E$62)) -> 0.028412181 | Q24: =IF(OR(B24="Null",H24=""),"",RANK(H24,$H$7:$H$41)) -> 19 | R24: =IF(B24="Null","Unmapped Null bucket – excluded from chart totals",IF(COUNT(E24:H24)<4,"Partial-period – column placement inferred",IF(AND(ISNUMBER(M24),ABS(M24)>0.5),"Large 9M swing (>±50%)",""))) -> Large 9M swing (>±50%)
A25: 19 | B25: Retail | C25: Gold Loans | D25: Gold Loan - BBB | E25: 676 | F25: 933 | G25: 1348 | H25: 1441 | I25: =IF(OR(E25="",F25="",N(E25)=0),"n/a",F25/E25-1) -> 0.38017751 | J25: =IF(OR(F25="",G25="",N(F25)=0),"n/a",G25/F25-1) -> 0.44480171 | K25: =IF(OR(G25="",H25="",N(G25)=0),"n/a",H25/G25-1) -> 0.068991098 | L25: =N(H25)-N(E25) -> 765 | M25: =IF(OR(E25="",H25="",N(E25)=0),"n/a",H25/E25-1) -> 1.1316568 | N25: =IF(H25="","",H25/$H$62) -> 0.012504447 | O25: =IF(H25="","",H25/SUMIFS($H$7:$H$42,$B$7:$B$42,B25)) -> 0.022447231 | P25: =IF(B25="Null","excl.",L25/($H$62-$E$62)) -> 0.051998369 | Q25: =IF(OR(B25="Null",H25=""),"",RANK(H25,$H$7:$H$41)) -> 17 | R25: =IF(B25="Null","Unmapped Null bucket – excluded from chart totals",IF(COUNT(E25:H25)<4,"Partial-period – column placement inferred",IF(AND(ISNUMBER(M25),ABS(M25)>0.5),"Large 9M swing (>±50%)",""))) -> Large 9M swing (>±50%)
A26: 20 | B26: Retail | C26: Gold Loans | D26: Gold Loan DA/CL | E26: 1544 | F26: 2423 | G26: 2907 | H26: 2965 | I26: =IF(OR(E26="",F26="",N(E26)=0),"n/a",F26/E26-1) -> 0.56930052 | J26: =IF(OR(F26="",G26="",N(F26)=0),"n/a",G26/F26-1) -> 0.19975237 | K26: =IF(OR(G26="",H26="",N(G26)=0),"n/a",H26/G26-1) -> 0.01995184 | L26: =N(H26)-N(E26) -> 1421 | M26: =IF(OR(E26="",H26="",N(E26)=0),"n/a",H26/E26-1) -> 0.92033679 | N26: =IF(H26="","",H26/$H$62) -> 0.025729137 | O26: =IF(H26="","",H26/SUMIFS($H$7:$H$42,$B$7:$B$42,B26)) -> 0.046187398 | P26: =IF(B26="Null","excl.",L26/($H$62-$E$62)) -> 0.096587819 | Q26: =IF(OR(B26="Null",H26=""),"",RANK(H26,$H$7:$H$41)) -> 11 | R26: =IF(B26="Null","Unmapped Null bucket – excluded from chart totals",IF(COUNT(E26:H26)<4,"Partial-period – column placement inferred",IF(AND(ISNUMBER(M26),ABS(M26)>0.5),"Large 9M swing (>±50%)",""))) -> Large 9M swing (>±50%)
... A35: 29 | B35: Retail | C35: Retail Others | D35: Education Loan | E35: 24 | F35: 27 | G35: 30 | H35: 33 | I35: =IF(OR(E35="",F35="",N(E35)=0),"n/a",F35/E35-1) -> 0.125 | J35: =IF(OR(F35="",G35="",N(F35)=0),"n/a",G35/F35-1) -> 0.11111111 | K35: =IF(OR(G35="",H35="",N(G35)=0),"n/a",H35/G35-1) -> 0.1 | L35: =N(H35)-N(E35) -> 9 | M35: =IF(OR(E35="",H35="",N(E35)=0),"n/a",H35/E35-1) -> 0.375 | N35: =IF(H35="","",H35/$H$62) -> 0.00028636139 | O35: =IF(H35="","",H35/SUMIFS($H$7:$H$42,$B$7:$B$42,B35)) -> 0.00051405873 | P35: =IF(B35="Null","excl.",L35/($H$62-$E$62)) -> 0.00061174551 | Q35: =IF(OR(B35="Null",H35=""),"",RANK(H35,$H$7:$H$41)) -> 29 | R35: =IF(B35="Null","Unmapped Null bucket – excluded from chart totals",IF(COUNT(E35:H35)<4,"Partial-period – column placement inferred",IF(AND(ISNUMBER(M35),ABS(M35)>0.5),"Large 9M swing (>±50%)","")))
A36: 30 | B36: Retail | C36: Retail Others | D36: LAS | H36: 0 | I36: =IF(OR(E36="",F36="",N(E36)=0),"n/a",F36/E36-1) -> n/a | J36: =IF(OR(F36="",G36="",N(F36)=0),"n/a",G36/F36-1) -> n/a | K36: =IF(OR(G36="",H36="",N(G36)=0),"n/a",H36/G36-1) -> n/a | L36: =N(H36)-N(E36) -> 0 | M36: =IF(OR(E36="",H36="",N(E36)=0),"n/a",H36/E36-1) -> n/a | N36: =IF(H36="","",H36/$H$62) -> 0 | O36: =IF(H36="","",H36/SUMIFS($H$7:$H$42,$B$7:$B$42,B36)) -> 0 | P36: =IF(B36="Null","excl.",L36/($H$62-$E$62)) -> 0 | Q36: =IF(OR(B36="Null",H36=""),"",RANK(H36,$H$7:$H$41)) -> 32 | R36: =IF(B36="Null","Unmapped Null bucket – excluded from chart totals",IF(COUNT(E36:H36)<4,"Partial-period – column placement inferred",IF(AND(ISNUMBER(M36),ABS(M36)>0.5),"Large 9M swing (>±50%)",""))) -> Partial-period – column placement inferred
A37: 31 | B37: Retail | C37: Retail Others | D37: ODFD | E37: 533 | F37: 519 | G37: 663 | H37: 607 | I37: =IF(OR(E37="",F37="",N(E37)=0),"n/a",F37/E37-1) -> -0.026266417 | J37: =IF(OR(F37="",G37="",N(F37)=0),"n/a",G37/F37-1) -> 0.27745665 | K37: =IF(OR(G37="",H37="",N(G37)=0),"n/a",H37/G37-1) -> -0.084464555 | L37: =N(H37)-N(E37) -> 74 | M37: =IF(OR(E37="",H37="",N(E37)=0),"n/a",H37/E37-1) -> 0.13883677 | N37: =IF(H37="","",H37/$H$62) -> 0.005267314 | O37: =IF(H37="","",H37/SUMIFS($H$7:$H$42,$B$7:$B$42,B37)) -> 0.0094555651 | P37: =IF(B37="Null","excl.",L37/($H$62-$E$62)) -> 0.0050299076 | Q37: =IF(OR(B37="Null",H37=""),"",RANK(H37,$H$7:$H$41)) -> 21 | R37: =IF(B37="Null","Unmapped Null bucket – excluded from chart totals",IF(COUNT(E37:H37)<4,"Partial-period – column placement inferred",IF(AND(ISNUMBER(M37),ABS(M37)>0.5),"Large 9M swing (>±50%)","")))
A38: 32 | B38: Retail | C38: Retail Others | D38: Retail - Others | E38: 4391 | F38: 387 | G38: 401 | H38: 410 | I38: =IF(OR(E38="",F38="",N(E38)=0),"n/a",F38/E38-1) -> -0.91186518 | J38: =IF(OR(F38="",G38="",N(F38)=0),"n/a",G38/F38-1) -> 0.036175711 | K38: =IF(OR(G38="",H38="",N(G38)=0),"n/a",H38/G38-1) -> 0.02244389 | L38: =N(H38)-N(E38) -> -3981 | M38: =IF(OR(E38="",H38="",N(E38)=0),"n/a",H38/E38-1) -> -0.90662719 | N38: =IF(H38="","",H38/$H$62) -> 0.0035578233 | O38: =IF(H38="","",H38/SUMIFS($H$7:$H$42,$B$7:$B$42,B38)) -> 0.0063867902 | P38: =IF(B38="Null","excl.",L38/($H$62-$E$62)) -> -0.27059543 | Q38: =IF(OR(B38="Null",H38=""),"",RANK(H38,$H$7:$H$41)) -> 23 | R38: =IF(B38="Null","Unmapped Null bucket – excluded from chart totals",IF(COUNT(E38:H38)<4,"Partial-period – column placement inferred",IF(AND(ISNUMBER(M38),ABS(M38)>0.5),"Large 9M swing (>±50%)",""))) -> Large 9M swing (>±50%)
A39: 33 | B39: Retail | C39: Wheels | D39: Rural Vehicle Finance | E39: 3047 | F39: 3244 | G39: 3372 | H39: 3399 | I39: =IF(OR(E39="",F39="",N(E39)=0),"n/a",F39/E39-1) -> 0.064653758 | J39: =IF(OR(F39="",G39="",N(F39)=0),"n/a",G39/F39-1) -> 0.03945746 | K39: =IF(OR(G39="",H39="",N(G39)=0),"n/a",H39/G39-1) -> 0.0080071174 | L39: =N(H39)-N(E39) -> 352 | M39: =IF(OR(E39="",H39="",N(E39)=0),"n/a",H39/E39-1) -> 0.11552347 | N39: =IF(H39="","",H39/$H$62) -> 0.029495223 | O39: =IF(H39="","",H39/SUMIFS($H$7:$H$42,$B$7:$B$42,B39)) -> 0.052948049 | P39: =IF(B39="Null","excl.",L39/($H$62-$E$62)) -> 0.023926047 | Q39: =IF(OR(B39="Null",H39=""),"",RANK(H39,$H$7:$H$41)) -> 9 | R39: =IF(B39="Null","Unmapped Null bucket – excluded from chart totals",IF(COUNT(E39:H39)<4,"Partial-period – column placement inferred",IF(AND(ISNUMBER(M39),ABS(M39)>0.5),"Large 9M swing (>±50%)","")))
A40: 34 | B40: Retail | C40: Wheels | D40: Two Wheeler | E40: 309 | F40: 364 | G40: 369 | H40: 364 | I40: =IF(OR(E40="",F40="",N(E40)=0),"n/a",F40/E40-1) -> 0.17799353 | J40: =IF(OR(F40="",G40="",N(F40)=0),"n/a",G40/F40-1) -> 0.013736264 | K40: =IF(OR(G40="",H40="",N(G40)=0),"n/a",H40/G40-1) -> -0.013550136 | L40: =N(H40)-N(E40) -> 55 | M40: =IF(OR(E40="",H40="",N(E40)=0),"n/a",H40/E40-1) -> 0.17799353 | N40: =IF(H40="","",H40/$H$62) -> 0.0031586529 | O40: =IF(H40="","",H40/SUMIFS($H$7:$H$42,$B$7:$B$42,B40)) -> 0.0056702235 | P40: =IF(B40="Null","excl.",L40/($H$62-$E$62)) -> 0.0037384448 | Q40: =IF(OR(B40="Null",H40=""),"",RANK(H40,$H$7:$H$41)) -> 24 | R40: =IF(B40="Null","Unmapped Null bucket – excluded from chart totals",IF(COUNT(E40:H40)<4,"Partial-period – column placement inferred",IF(AND(ISNUMBER(M40),ABS(M40)>0.5),"Large 9M swing (>±50%)","")))
A41: 35 | B41: Retail | C41: Wheels | D41: Used Car Loans | E41: 107 | F41: 108 | G41: 107 | H41: 100 | I41: =IF(OR(E41="",F41="",N(E41)=0),"n/a",F41/E41-1) -> 0.0093457944 | J41: =IF(OR(F41="",G41="",N(F41)=0),"n/a",G41/F41-1) -> -0.0092592593 | K41: =IF(OR(G41="",H41="",N(G41)=0),"n/a",H41/G41-1) -> -0.065420561 | L41: =N(H41)-N(E41) -> -7 | M41: =IF(OR(E41="",H41="",N(E41)=0),"n/a",H41/E41-1) -> -0.065420561 | N41: =IF(H41="","",H41/$H$62) -> 0.00086776178 | O41: =IF(H41="","",H41/SUMIFS($H$7:$H$42,$B$7:$B$42,B41)) -> 0.0015577537 | P41: =IF(B41="Null","excl.",L41/($H$62-$E$62)) -> -0.00047580207 | Q41: =IF(OR(B41="Null",H41=""),"",RANK(H41,$H$7:$H$41)) -> 27 | R41: =IF(B41="Null","Unmapped Null bucket – excluded from chart totals",IF(COUNT(E41:H41)<4,"Partial-period – column placement inferred",IF(AND(ISNUMBER(M41),ABS(M41)>0.5),"Large 9M swing (>±50%)","")))
A42: 36 | B42: Null | C42: Retail Others | D42: Null | F42: 1000 | G42: 3700 | H42: 986 | I42: =IF(OR(E42="",F42="",N(E42)=0),"n/a",F42/E42-1) -> n/a | J42: =IF(OR(F42="",G42="",N(F42)=0),"n/a",G42/F42-1) -> 2.7 | K42: =IF(OR(G42="",H42="",N(G42)=0),"n/a",H42/G42-1) -> -0.73351351 | L42: =N(H42)-N(E42) -> 986 | M42: =IF(OR(E42="",H42="",N(E42)=0),"n/a",H42/E42-1) -> n/a | N42: =IF(H42="","",H42/$H$62) -> 0.0085561312 | O42: =IF(H42="","",H42/SUMIFS($H$7:$H$42,$B$7:$B$42,B42)) -> 1 | P42: =IF(B42="Null","excl.",L42/($H$62-$E$62)) -> excl. | Q42: =IF(OR(B42="Null",H42=""),"",RANK(H42,$H$7:$H$41)) | R42: =IF(B42="Null","Unmapped Null bucket – excluded from chart totals",IF(COUNT(E42:H42)<4,"Partial-period – column placement inferred",IF(AND(ISNUMBER(M42),ABS(M42)>0.5),"Large 9M swing (>±50%)",""))) -> Unmapped Null bucket – excluded from chart totals
A45: B. Roll-ups (live SUMIFS) — business line, category, bank; reconciliation to printed Grand Total
A46: # | B46: Category | C46: Business line | E46: Sep-25 | F46: Dec-25 | G46: Mar-26 | H46: Jun-26 | I46: 9M Δ (₹ Cr) | J46: 9M growth % | K46: Share Sep-25 | L46: Share Jun-26 | M46: Share chg (pp) | N46: Contribution to bank 9M growth | O46: Rank Jun-26
A47: 1 | B47: Wholesale | C47: Commercial Banking | E47: =SUMIFS(E$7:E$42,$B$7:$B$42,$B47,$C$7:$C$42,$C47) -> 13115 | F47: =SUMIFS(F$7:F$42,$B$7:$B$42,$B47,$C$7:$C$42,$C47) -> 14015 | G47: =SUMIFS(G$7:G$42,$B$7:$B$42,$B47,$C$7:$C$42,$C47) -> 15268 | H47: =SUMIFS(H$7:H$42,$B$7:$B$42,$B47,$C$7:$C$42,$C47) -> 16874 | I47: =H47-E47 -> 3759 | J47: =IF(E47=0,"n/a",H47/E47-1) -> 0.28661838 | K47: =E47/$E$62 -> 0.13046246 | L47: =H47/$H$62 -> 0.14642612 | M47: =(L47-K47)*100 -> 1.596366 | N47: =IF(B47="Null","excl.",I47/($H$62-$E$62)) -> 0.25550571 | O47: =IF(B47="Null","",RANK(H47,$H$47:$H$56)) -> 3
A48: 2 | B48: Wholesale | C48: Corporate Banking | E48: =SUMIFS(E$7:E$42,$B$7:$B$42,$B48,$C$7:$C$42,$C48) -> 27280 | F48: =SUMIFS(F$7:F$42,$B$7:$B$42,$B48,$C$7:$C$42,$C48) -> 28459 | G48: =SUMIFS(G$7:G$42,$B$7:$B$42,$B48,$C$7:$C$42,$C48) -> 31847 | H48: =SUMIFS(H$7:H$42,$B$7:$B$42,$B48,$C$7:$C$42,$C48) -> 34170 | I48: =H48-E48 -> 6890 | J48: =IF(E48=0,"n/a",H48/E48-1) -> 0.25256598 | K48: =E48/$E$62 -> 0.27136988 | L48: =H48/$H$62 -> 0.2965142 | M48: =(L48-K48)*100 -> 2.514432 | N48: =IF(B48="Null","excl.",I48/($H$62-$E$62)) -> 0.46832518 | O48: =IF(B48="Null","",RANK(H48,$H$47:$H$56)) -> 1
A49: 3 | B49: Retail | C49: Housing Loans | E49: =SUMIFS(E$7:E$42,$B$7:$B$42,$B49,$C$7:$C$42,$C49) -> 8496 | F49: =SUMIFS(F$7:F$42,$B$7:$B$42,$B49,$C$7:$C$42,$C49) -> 8700 | G49: =SUMIFS(G$7:G$42,$B$7:$B$42,$B49,$C$7:$C$42,$C49) -> 8830 | H49: =SUMIFS(H$7:H$42,$B$7:$B$42,$B49,$C$7:$C$42,$C49) -> 8930 | I49: =H49-E49 -> 434 | J49: =IF(E49=0,"n/a",H49/E49-1) -> 0.051082863 | K49: =E49/$E$62 -> 0.084514608 | L49: =H49/$H$62 -> 0.077491127 | M49: =(L49-K49)*100 -> -0.70234809 | N49: =IF(B49="Null","excl.",I49/($H$62-$E$62)) -> 0.029499728 | O49: =IF(B49="Null","",RANK(H49,$H$47:$H$56)) -> 5
A50: 4 | B50: Retail | C50: Loan Against Property | E50: =SUMIFS(E$7:E$42,$B$7:$B$42,$B50,$C$7:$C$42,$C50) -> 10946 | F50: =SUMIFS(F$7:F$42,$B$7:$B$42,$B50,$C$7:$C$42,$C50) -> 12323 | G50: =SUMIFS(G$7:G$42,$B$7:$B$42,$B50,$C$7:$C$42,$C50) -> 13428 | H50: =SUMIFS(H$7:H$42,$B$7:$B$42,$B50,$C$7:$C$42,$C50) -> 13771 | I50: =H50-E50 -> 2825 | J50: =IF(E50=0,"n/a",H50/E50-1) -> 0.25808515 | K50: =E50/$E$62 -> 0.10888617 | L50: =H50/$H$62 -> 0.11949948 | M50: =(L50-K50)*100 -> 1.0613305 | N50: =IF(B50="Null","excl.",I50/($H$62-$E$62)) -> 0.19202012 | O50: =IF(B50="Null","",RANK(H50,$H$47:$H$56)) -> 4
A51: 5 | B51: Retail | C51: Gold Loans | E51: =SUMIFS(E$7:E$42,$B$7:$B$42,$B51,$C$7:$C$42,$C51) -> 2220 | F51: =SUMIFS(F$7:F$42,$B$7:$B$42,$B51,$C$7:$C$42,$C51) -> 3356 | G51: =SUMIFS(G$7:G$42,$B$7:$B$42,$B51,$C$7:$C$42,$C51) -> 4255 | H51: =SUMIFS(H$7:H$42,$B$7:$B$42,$B51,$C$7:$C$42,$C51) -> 4406 | I51: =H51-E51 -> 2186 | J51: =IF(E51=0,"n/a",H51/E51-1) -> 0.98468468 | K51: =E51/$E$62 -> 0.022083619 | L51: =H51/$H$62 -> 0.038233584 | M51: =(L51-K51)*100 -> 1.6149965 | N51: =IF(B51="Null","excl.",I51/($H$62-$E$62)) -> 0.14858619 | O51: =IF(B51="Null","",RANK(H51,$H$47:$H$56)) -> 8
...

Sheet P2_Metrics
A1: Block 2 — Net Funded Advances Detailed: notation and metrics
A2: Format: Notation → Exhaustive metrics table | Example column = live Excel formula on the block sheet (green = cross-sheet)
A3: ⚠ DRAFT ONLY — Requires review and approval by a qualified Alvarez and Marsal professional before use.
A5: Notation
B6: Symbol | C6: Meaning
B7: B(p,q) | C7: Net funded advance of product p at quarter-end q
B8: BL | C8: Business-line subtotal = Σ B(p) within the line
B9: W / R | C9: Wholesale / Retail category subtotals, computed from product lines
B10: NULL | C10: Unmapped 'Null' row (Dec-25, Mar-26, Jun-26)
B11: T | C11: Bank total excl NULL = W + R (chart basis)
B12: GT | C12: Grand Total as printed (includes NULL)
B13: RO | C13: 'Retail - Others' product line
B14: CC | C14: Credit Card excl STPL + STPL
B15: MB | C15: Micro Banking
B16: UNS | C16: Unsecured retail proxy = CC + MB + BIL/SBL (analyst mapping)
B17: PART | C17: Partnership / purchased book = HL CL + HL DA + LAP CL + LAP DA + Gold DA/CL (analyst mapping)
... B24: CC3 / LAP3 | C24: Block-3 labelled retail segments
B25: Values are ₹ Cr as printed; blanks treated as zero; growth in %, share shifts in pp.
A27: Exhaustive metrics table
A28: # | B28: Metric family | C28: Pipeline-ready metric | D28: Definition / formula | E28: Applies to | F28: Example
A29: 1 | B29: Fact lookup | C29: Product balances | D29: B(p,q) | E29: 35 products + NULL × 4 quarter-ends | F29: ="Prime LAP "&TEXT(P2_Detailed_Table!E23,"#,##0;-#,##0;0")&" / "&TEXT(P2_Detailed_Table!F23,"#,##0;-#,##0;0")&" / "&TEXT(P2_Detailed_Table!G23,"#,##0;-#,##0;0")&" / "&TEXT(P2_Detailed_Table!H23,"#,##0;-#,##0;0") -> Prime LAP 8,230 / 8,942 / 9,936 / 10,306
A30: 2 | B30: Fact lookup | C30: Business-line subtotals | D30: BL(q) = Σ B(p,q) in line | E30: 11 lines × 4 | F30: ="Corporate Banking "&TEXT(P2_Detailed_Table!E48,"#,##0;-#,##0;0")&" / "&TEXT(P2_Detailed_Table!F48,"#,##0;-#,##0;0")&" / "&TEXT(P2_Detailed_Table!G48,"#,##0;-#,##0;0")&" / "&TEXT(P2_Detailed_Table!H48,"#,##0;-#,##0;0")&"; Credit Cards "&TEXT(P2_Detailed_Table!E53,"#,##0;-#,##0;0")&" / "&TEXT(P2_Detailed_Table!F53,"#,##0;-#,##0;0")&" / "&TEXT(P2_Detailed_Table!G53,"#,##0;-#,##0;0")&" / "&TEXT(P2_Detailed_Table!H53,"#,##0;-#,##0;0") -> Corporate Banking 27,280 / 28,459 / 31,847 / 34,170; Credit Cards 20,457 / 19,901 / 19,577 / 19,321
A31: 3 | B31: Fact lookup | C31: Category subtotals | D31: W(q), R(q) | E31: 2 × 4 | F31: ="W "&TEXT(P2_Detailed_Table!E59,"#,##0;-#,##0;0")&" / "&TEXT(P2_Detailed_Table!F59,"#,##0;-#,##0;0")&" / "&TEXT(P2_Detailed_Table!G59,"#,##0;-#,##0;0")&" / "&TEXT(P2_Detailed_Table!H59,"#,##0;-#,##0;0")&"; R "&TEXT(P2_Detailed_Table!E60,"#,##0;-#,##0;0")&" / "&TEXT(P2_Detailed_Table!F60,"#,##0;-#,##0;0")&" / "&TEXT(P2_Detailed_Table!G60,"#,##0;-#,##0;0")&" / "&TEXT(P2_Detailed_Table!H60,"#,##0;-#,##0;0") -> W 40,395 / 42,474 / 47,115 / 51,044; R 60,132 / 59,612 / 63,420 / 64,195
A32: 4 | B32: Fact lookup | C32: Null bucket | D32: NULL(q) | E32: Dec-25, Mar-26, Jun-26 | F32: =TEXT(P2_Detailed_Table!F61,"#,##0;-#,##0;0")&" / "&TEXT(P2_Detailed_Table!G61,"#,##0;-#,##0;0")&" / "&TEXT(P2_Detailed_Table!H61,"#,##0;-#,##0;0") -> 1,000 / 3,700 / 986
A33: 5 | B33: Fact lookup | C33: Printed Grand Total | D33: GT(q) | E33: 4 quarter-ends | F33: =TEXT(P2_Detailed_Table!E64,"#,##0;-#,##0;0")&" / "&TEXT(P2_Detailed_Table!F64,"#,##0;-#,##0;0")&" / "&TEXT(P2_Detailed_Table!G64,"#,##0;-#,##0;0")&" / "&TEXT(P2_Detailed_Table!H64,"#,##0;-#,##0;0") -> 100,527 / 103,086 / 114,232 / 116,226
A34: 6 | B34: Roll-up check | C34: Bank total excl NULL | D34: T = W + R | E34: 4 quarter-ends | F34: =TEXT(P2_Detailed_Table!E62,"#,##0;-#,##0;0")&" / "&TEXT(P2_Detailed_Table!F62,"#,##0;-#,##0;0")&" / "&TEXT(P2_Detailed_Table!G62,"#,##0;-#,##0;0")&" / "&TEXT(P2_Detailed_Table!H62,"#,##0;-#,##0;0") -> 100,527 / 102,086 / 110,535 / 115,239
A35: 7 | B35: Roll-up check | C35: Grand Total vs lines | D35: GT − (T + NULL) | E35: 4 quarter-ends | F35: =TEXT(P2_Detailed_Table!E65,"#,##0;-#,##0;0")&" / "&TEXT(P2_Detailed_Table!F65,"#,##0;-#,##0;0")&" / "&TEXT(P2_Detailed_Table!G65,"#,##0;-#,##0;0")&" / "&TEXT(P2_Detailed_Table!H65,"#,##0;-#,##0;0")&" (rounding)" -> 0 / 0 / -3 / 1 (rounding)
A36: 8 | B36: Roll-up check | C36: Grand Total vs chart total | D36: GT − T(Block 1) | E36: 4 quarter-ends | F36: =TEXT(P2_Detailed_Table!E68,"#,##0;-#,##0;0")&" / "&TEXT(P2_Detailed_Table!F68,"#,##0;-#,##0;0")&" / "&TEXT(P2_Detailed_Table!G68,"#,##0;-#,##0;0")&" / "&TEXT(P2_Detailed_Table!H68,"#,##0;-#,##0;0") -> 0 / 1,000 / 3,700 / 986
A37: 9 | B37: Roll-up check | C37: Residual after NULL | D37: GT − T(Block 1) − NULL | E37: 4 quarter-ends | F37: =TEXT(P2_Detailed_Table!E69,"#,##0;-#,##0;0")&" / "&TEXT(P2_Detailed_Table!F69,"#,##0;-#,##0;0")&" / "&TEXT(P2_Detailed_Table!G69,"#,##0;-#,##0;0")&" / "&TEXT(P2_Detailed_Table!H69,"#,##0;-#,##0;0")&" (all tie)" -> 0 / 0 / 0 / 0 (all tie)
A38: 10 | B38: Growth & momentum | C38: Product QoQ growth | D38: B(p,q) ÷ B(p,q−1) − 1 | E38: 35 products × 3 quarters | F38: ="Micro Banking "&TEXT(P2_Detailed_Table!I32,"+0.0%;-0.0%;0.0%")&" / "&TEXT(P2_Detailed_Table!J32,"+0.0%;-0.0%;0.0%")&" / "&TEXT(P2_Detailed_Table!K32,"+0.0%;-0.0%;0.0%")&"; Prime LAP "&TEXT(P2_Detailed_Table!I23,"+0.0%;-0.0%;0.0%")&" / "&TEXT(P2_Detailed_Table!J23,"+0.0%;-0.0%;0.0%")&" / "&TEXT(P2_Detailed_Table!K23,"+0.0%;-0.0%;0.0%") -> Micro Banking +13.7% / +16.1% / +5.7%; Prime LAP +8.7% / +11.1% / +3.7%
A39: 11 | B39: Growth & momentum | C39: Product 9M growth | D39: B(p,Jun-26) ÷ B(p,Sep-25) − 1 | E39: 35 products | F39: ="Gold Loan - BBB "&TEXT(P2_Detailed_Table!M25,"+0.0%;-0.0%;0.0%")&"; Gold Loan DA/CL "&TEXT(P2_Detailed_Table!M26,"+0.0%;-0.0%;0.0%")&"; Small LAP "&TEXT(P2_Detailed_Table!M24,"+0.0%;-0.0%;0.0%")&"; Micro Banking "&TEXT(P2_Detailed_Table!M32,"+0.0%;-0.0%;0.0%")&"; CC excl STPL "&TEXT(P2_Detailed_Table!M30,"+0.0%;-0.0%;0.0%") -> Gold Loan - BBB +113.2%; Gold Loan DA/CL +92.0%; Small LAP +71.9%; Micro Banking +39.6%; CC excl STPL -6.7%
A40: 12 | B40: Growth & momentum | C40: Business-line 9M growth | D40: BL(Jun-26) ÷ BL(Sep-25) − 1 | E40: 11 lines | F40: ="Commercial "&TEXT(P2_Detailed_Table!J47,"+0.0%;-0.0%;0.0%")&"; Corporate "&TEXT(P2_Detailed_Table!J48,"+0.0%;-0.0%;0.0%")&"; Housing "&TEXT(P2_Detailed_Table!J49,"+0.0%;-0.0%;0.0%")&"; LAP "&TEXT(P2_Detailed_Table!J50,"+0.0%;-0.0%;0.0%")&"; Gold "&TEXT(P2_Detailed_Table!J51,"+0.0%;-0.0%;0.0%")&"; Cards "&TEXT(P2_Detailed_Table!J53,"+0.0%;-0.0%;0.0%")&"; Micro "&TEXT(P2_Detailed_Table!J54,"+0.0%;-0.0%;0.0%")&"; Wheels "&TEXT(P2_Detailed_Table!J56,"+0.0%;-0.0%;0.0%") -> Commercial +28.7%; Corporate +25.3%; Housing +5.1%; LAP +25.8%; Gold +98.5%; Cards -5.6%; Micro +39.6%; Wheels +11.6%
A41: 13 | B41: Growth & momentum | C41: Business-line QoQ growth | D41: BL(q) ÷ BL(q−1) − 1 | E41: 11 lines × 3 quarters | F41: ="Corporate "&TEXT(P2_Detailed_Table!F48/P2_Detailed_Table!E48-1,"+0.0%;-0.0%;0.0%")&" / "&TEXT(P2_Detailed_Table!G48/P2_Detailed_Table!F48-1,"+0.0%;-0.0%;0.0%")&" / "&TEXT(P2_Detailed_Table!H48/P2_Detailed_Table!G48-1,"+0.0%;-0.0%;0.0%")&"; Gold "&TEXT(P2_Detailed_Table!F51/P2_Detailed_Table!E51-1,"+0.0%;-0.0%;0.0%")&" / "&TEXT(P2_Detailed_Table!G51/P2_Detailed_Table!F51-1,"+0.0%;-0.0%;0.0%")&" / "&TEXT(P2_Detailed_Table!H51/P2_Detailed_Table!G51-1,"+0.0%;-0.0%;0.0%")&"; Cards "&TEXT(P2_Detailed_Table!F53/P2_Detailed_Table!E53-1,"+0.0%;-0.0%;0.0%")&" / "&TEXT(P2_Detailed_Table!G53/P2_Detailed_Table!F53-1,"+0.0%;-0.0%;0.0%")&" / "&TEXT(P2_Detailed_Table!H53/P2_Detailed_Table!G53-1,"+0.0%;-0.0%;0.0%") -> Corporate +4.3% / +11.9% / +7.3%; Gold +51.2% / +26.8% / +3.5%; Cards -2.7% / -1.6% / -1.3%
A42: 14 | B42: Growth & momentum | C42: Category 9M growth | D42: X(Jun-26) ÷ X(Sep-25) − 1 | E42: W, R, T | F42: ="W "&TEXT(P2_Detailed_Table!H59/P2_Detailed_Table!E59-1,"+0.0%;-0.0%;0.0%")&"; R "&TEXT(P2_Detailed_Table!H60/P2_Detailed_Table!E60-1,"+0.0%;-0.0%;0.0%")&"; T "&TEXT(P2_Detailed_Table!H62/P2_Detailed_Table!E62-1,"+0.0%;-0.0%;0.0%") -> W +26.4%; R +6.8%; T +14.6%
A43: 15 | B43: Growth & momentum | C43: Category QoQ growth | D43: X(q) ÷ X(q−1) − 1 | E43: W, R × 3 quarters | F43: ="W "&TEXT(P2_Detailed_Table!F59/P2_Detailed_Table!E59-1,"+0.0%;-0.0%;0.0%")&" / "&TEXT(P2_Detailed_Table!G59/P2_Detailed_Table!F59-1,"+0.0%;-0.0%;0.0%")&" / "&TEXT(P2_Detailed_Table!H59/P2_Detailed_Table!G59-1,"+0.0%;-0.0%;0.0%")&"; R "&TEXT(P2_Detailed_Table!F60/P2_Detailed_Table!E60-1,"+0.0%;-0.0%;0.0%")&" / "&TEXT(P2_Detailed_Table!G60/P2_Detailed_Table!F60-1,"+0.0%;-0.0%;0.0%")&" / "&TEXT(P2_Detailed_Table!H60/P2_Detailed_Table!G60-1,"+0.0%;-0.0%;0.0%") -> W +5.1% / +10.9% / +8.3%; R -0.9% / +6.4% / +1.2%
A44: 16 | B44: Growth & momentum | C44: Like-for-like retail growth | D44: (R − RO)(Jun-26) ÷ (R − RO)(Sep-25) − 1 | E44: Window | F44: ="Reported "&TEXT(P2_Detailed_Table!H60/P2_Detailed_Table!E60-1,"+0.0%;-0.0%;0.0%")&" vs LFL "&TEXT((P2_Detailed_Table!H60-P2_Detailed_Table!H38)/(P2_Detailed_Table!E60-P2_Detailed_Table!E38)-1,"+0.0%;-0.0%;0.0%") -> Reported +6.8% vs LFL +14.4%
A45: 17 | B45: Growth & momentum | C45: Retail ex-cards growth | D45: (R − CC)(Jun-26) ÷ (R − CC)(Sep-25) − 1 | E45: Window | F45: =TEXT((P2_Detailed_Table!H60-P2_Detailed_Table!H53)/(P2_Detailed_Table!E60-P2_Detailed_Table!E53)-1,"+0.0%;-0.0%;0.0%") -> +13.1%
A46: 18 | B46: Growth & momentum | C46: Largest absolute gainer / decliner | D46: MAX / MIN of ΔB(p,9M) | E46: 35 products | F46: =INDEX(P2_Detailed_Table!D7:D41,MATCH(MAX(P2_Detailed_Table!L7:L41),P2_Detailed_Table!L7:L41,0))&" "&TEXT(MAX(P2_Detailed_Table!L7:L41),"#,##0;-#,##0;0")&"; "&INDEX(P2_Detailed_Table!D7:D41,MATCH(MIN(P2_Detailed_Table!L7:L41),P2_Detailed_Table!L7:L41,0))&" "&TEXT(MIN(P2_Detailed_Table!L7:L41),"#,##0;-#,##0;0") -> Corporate Banking (incl G&J) 4,116; Retail - Others -3,981
A47: 19 | B47: Growth & momentum | C47: Fastest-growing product (Sep-25 base ≥ ₹100 Cr) | D47: MAX of 9M growth where B(p,Sep-25) ≥ 100 | E47: 35 products | F47: =INDEX(P2_Detailed_Table!D7:D41,MATCH(_xlfn.MAXIFS(P2_Detailed_Table!M7:M41,P2_Detailed_Table!E7:E41,">=100"),P2_Detailed_Table!M7:M41,0))&" "&TEXT(_xlfn.MAXIFS(P2_Detailed_Table!M7:M41,P2_Detailed_Table!E7:E41,">=100"),"+0.0%;-0.0%;0.0%") -> Gold Loan - BBB +113.2%
A48: 20 | B48: Growth & momentum | C48: Growth breadth | D48: N(ΔB > 0) ÷ N(ΔB ≠ 0) | E48: 35 products | F48: =TEXT(COUNTIF(P2_Detailed_Table!L7:L41,">0"),"0")&" growing / "&TEXT(COUNTIF(P2_Detailed_Table!L7:L41,"<0"),"0")&" declining = "&TEXT(COUNTIF(P2_Detailed_Table!L7:L41,">0")/(COUNTIF(P2_Detailed_Table!L7:L41,">0")+COUNTIF(P2_Detailed_Table!L7:L41,"<0")),"0.0%") -> 23 growing / 9 declining = 71.9%
...

Sheet P3_Retail_Monthly
A1: Block 3 — Retail Net Advances (monthly stacked chart)
A2: Source: Net Advances Insights.pdf, 'Retail Net Advances' chart | ₹ Cr | Aug-25 to Aug-26 month-ends | only 2 of ~8 segments carry labels
A3: ⚠ DRAFT ONLY — Requires review and approval by a qualified Alvarez and Marsal professional before use.
A5: A. Source data as printed (blue); segment identities inferred by tying to Block 2 (see validation rows)
A6: # | B6: Series | C6: Aug-25 | D6: Sep-25 | E6: Oct-25 | F6: Nov-25 | G6: Dec-25 | H6: Jan-26 | I6: Feb-26 | J6: Mar-26 | K6: Apr-26 | L6: May-26 | M6: Jun-26 | N6: Jul-26 | O6: Aug-26
A7: 1 | B7: Retail total (printed) | C7: 57865 | D7: 60131 | E7: 60659 | F7: 61723 | G7: 59611 | H7: 60959 | I7: 61256 | J7: 63419 | K7: 63272 | L7: 63452 | M7: 64195 | N7: 65077 | O7: 73958
A8: 2 | B8: Olive segment ≈ Credit Cards incl STPL (inferred) | C8: 20351 | D8: 20457 | E8: 20342 | F8: 20178 | G8: 19901 | H8: 19726 | I8: 19832 | J8: 19577 | K8: 19803 | L8: 19263 | M8: 19321 | N8: 18926 | O8: 19635
A9: 3 | B9: Green segment ≈ LAP (inferred; labelled Mar-26 onward) | J9: 13429 | K9: 13313 | L9: 13411 | M9: 13771 | N9: 13889 | O9: 14026
A10: 4 | B10: Unlabelled residual = Total − CC − LAP | C10: =C7-C8-N(C9) -> 37514 | D10: =D7-D8-N(D9) -> 39674 | E10: =E7-E8-N(E9) -> 40317 | F10: =F7-F8-N(F9) -> 41545 | G10: =G7-G8-N(G9) -> 39710 | H10: =H7-H8-N(H9) -> 41233 | I10: =I7-I8-N(I9) -> 41424 | J10: =J7-J8-N(J9) -> 30413 | ... O10: =O7-O8-N(O9) -> 40297
A12: B. Derived series (live formulas)
A13: # | B13: Derived series | C13: Aug-25 | D13: Sep-25 | E13: Oct-25 | F13: Nov-25 | G13: Dec-25 | H13: Jan-26 | I13: Feb-26 | J13: Mar-26 | K13: Apr-26 | L13: May-26 | M13: Jun-26 | N13: Jul-26 | O13: Aug-26
A14: 1 | B14: MoM Δ total (₹ Cr) | C14: – | D14: =D7-C7 -> 2266 | E14: =E7-D7 -> 528 | F14: =F7-E7 -> 1064 | G14: =G7-F7 -> -2112 | H14: =H7-G7 -> 1348 | I14: =I7-H7 -> 297 | J14: =J7-I7 -> 2163 | K14: =K7-J7 -> -147 | ... O14: =O7-N7 -> 8881
A15: 2 | B15: MoM growth total | C15: – | D15: =D7/C7-1 -> 0.039160114 | E15: =E7/D7-1 -> 0.0087808285 | F15: =F7/E7-1 -> 0.017540678 | G15: =G7/F7-1 -> -0.034217391 | H15: =H7/G7-1 -> 0.022613276 | I15: =I7/H7-1 -> 0.0048721272 | J15: =J7/I7-1 -> 0.035310827 | K15: =K7/J7-1 -> -0.0023179173 | ... O15: =O7/N7-1 -> 0.13646911
A16: 3 | B16: Credit Cards share of retail | C16: =C8/C7 -> 0.35169792 | D16: =D8/D7 -> 0.34020721 | E16: =E8/E7 -> 0.33535007 | F16: =F8/F7 -> 0.32691217 | G16: =G8/G7 -> 0.33384778 | H16: =H8/H7 -> 0.32359455 | I16: =I8/I7 -> 0.32375604 | J16: =J8/J7 -> 0.30869298 | ... O16: =O8/O7 -> 0.26548852
